{"op":"mcm","clk":"AKlnAOVaAMFc","pt":1650392754675,"mc":[{"id":"1.197931750","rc":[{"atb":[[4.7,0],[4.4,0],[8.2,12.94],[9.8,8.24]],"atl":[[85,0],[65,0],[10,20.83],[14,15.3]],"bdatb":[[7,8.4,58.69],[8,8.2,33.7],[9,8,46.81],[3,9.2,29.22],[4,9,33.17],[5,8.8,38.28],[0,9.8,8.24],[1,9.6,19.57]],"bdatl":[[1,10.5,32.73],[2,11,67.73],[3,11.5,42.41],[4,12,27.95],[5,12.5,45.4],[7,13.5,79.83],[8,14,25.56],[9,15,12.59],[0,10,20.83]],"id":42930960},{"atb":[[16,2.78],[6.8,0],[6.2,7.69],[13.5,26.11],[15,24.61]],"atl":[[16.5,33.43],[1000,16.31],[240,0],[170,0]],"trd":[[16,94.63]],"bdatb":[[8,12,32.45],[9,11.5,57.52],[0,16,2.78],[3,14.5,16.53],[4,14,25.57],[5,13.5,30.77],[7,12.5,49.64],[2,15,24.61]],"bdatl":[[0,16.5,33.43],[2,17.5,22.2],[6,19.5,15.32],[7,20,10.89],[8,21,24.84],[5,19,18.48],[9,22,4.87]],"tv":539.8,"id":40095374},{"atb":[[9.8,0],[4.6,0],[4.3,31.76],[8.6,13.41],[9.2,21.83],[9.4,41.68]],"atl":[[11,30.34],[10.5,21.83],[9.8,2],[20,2.43],[1000,20.34],[60,0],[85,0],[15.5,18.05],[12.5,29.51],[11.5,39.01]],"trd":[[9.8,54.08]],"bdatb":[[8,8,67.73],[9,7.8,46.55],[0,9.6,16.99],[1,9.4,41.68],[2,9.2,21.83],[3,9,16.7],[4,8.8,23.16],[5,8.6,13.41],[6,8.4,38.77],[7,8.2,22.22]],"bdatl":[[2,10.5,21.83],[3,11,35.31],[4,11.5,44.72],[5,12,27.67],[6,12.5,35.35],[8,13.5,22.52],[9,14,22.53],[0,9.8,2],[1,10,75.47],[7,13,77]],"tv":1534.18,"id":36276560},{"atb":[[8.4,0],[7.6,0],[21,16.37]],"atl":[[440,0],[290,0],[1000,13.49]],"trd":[[21,63.21]],"bdatb":[[0,21,16.37],[2,19.5,18.21],[4,18.5,13.41],[5,18,6.87],[6,17.5,8.91],[8,16.5,10.43],[9,16,31.38]],"bdatl":[[1,24,45.67],[4,27,10.41],[6,29,4.21],[7,30,4.73],[8,32,5.09],[9,34,6.87]],"ltp":21,"tv":325.97,"id":37947503},{"atb":[[1.47,81.9],[1.48,0],[1.45,100.56],[1.46,151.48],[1.31,0],[1.32,261.03],[1.05,64.84],[1.42,1771.95],[1.43,1133.99],[1.2,1.47]],"atl":[[1.53,66.46],[1.51,40.11],[1.5,320.28],[1.48,0],[2.14,0],[2.26,0],[2.08,32.73],[3.6,75.64],[2.82,48.28],[1.49,55.43]],"trd":[[1.48,414.09]],"bdatb":[[0,1.47,81.9],[1,1.46,294.14],[2,1.45,205.73],[3,1.44,210.25],[4,1.43,1155.2],[5,1.42,1907.2],[6,1.41,243.31],[7,1.4,1065.46],[8,1.39,145.84],[9,1.38,317.43]],"bdatl":[[1,1.5,356.78],[2,1.51,111.87],[4,1.53,204.44],[0,1.49,55.43],[3,1.52,214.19],[5,1.54,130.27],[6,1.55,103.96],[7,1.56,276.5],[8,1.57,110.66],[9,1.58,64.12]],"tv":6281.06,"id":39823721},{"atb":[[75,0.73],[18.5,0],[16.5,0],[65,6.01]],"atl":[[420,1],[85,3.01],[75,0],[1000,13],[110,2.84]],"trd":[[75,42.96],[65,37.84]],"bdatb":[[0,65,6.74],[4,48,13.79],[7,40,7.88]],"bdatl":[[1,85,3.01],[5,190,6.87],[9,350,2.15],[0,80,1.31],[2,100,2.23],[3,110,2.84],[4,120,2.84],[6,200,2],[7,220,5],[8,270,2.22]],"ltp":75,"tv":136.64,"id":44331354}],"con":true,"tv":9666.65}]}
{"op":"mcm","clk":"AMZoAO9bALRd","pt":1650392755676,"mc":[{"id":"1.197931750","rc":[{"atb":[[1.08,0.08],[9.2,25.91],[4.9,141.97],[4.6,121.3],[1.01,42846.94],[8,48.13],[9.4,19.27],[8.8,29.12],[9,28.99],[9.6,16.57]],"atl":[[1000,46.71],[10.5,30.46],[20,0.59],[110,4.01],[80,5.53]],"bdatb":[[3,9.2,62.72],[5,8.8,39.84],[7,8.4,27.28],[8,8.2,15.04],[9,8,54.38],[1,9.6,16.57],[2,9.4,19.27],[4,9,28.99]],"bdatl":[[1,10.5,30.46],[3,11.5,41.78],[4,12,25.03],[5,12.5,47.3],[7,13.5,81.76],[8,14,20.91],[9,15,11.55],[6,13,4.47],[2,11,67.98]],"id":42930960},{"atb":[[14.5,16.34],[6.8,75.29],[6.2,91.67],[13,22.9],[1.01,44159.19],[15.5,37.37],[16,3.19],[13.5,20.13]],"atl":[[17.5,20.04],[200,2.2],[290,1.51],[1000,38.05],[18,21.52],[17,14.85],[16.5,33.99]],"trd":[[16,97.95]],"bdatb":[[3,14.5,30.7],[5,13.5,29.78],[7,12.5,47.13],[8,12,22.65],[9,11.5,42.39],[6,13,22.9],[0,16,3.19],[1,15.5,37.37],[4,14,24.17]],"bdatl":[[2,17.5,20.04],[8,21,24.63],[0,16.5,33.99],[1,17,14.85],[3,18,21.52],[4,18.5,15.82],[5,19,18.48],[6,19.5,14.94],[7,20,11.27]],"tv":543.12,"id":40095374},{"atb":[[9.4,38.38],[1.01,46275.67],[9.6,12.87],[4.9,175.88],[4.6,121.3],[9.2,18.83],[8,44.14],[8.8,10.77],[9.8,0],[9,13.7],[8.6,13.41]],"atl":[[11,45.34],[110,4.01],[80,5.53],[1000,55.18],[10.5,17.83],[10,77.18],[11.5,37.78],[9.8,0]],"trd":[[9.6,10.63],[9.8,58.08]],"bdatb":[[1,9.4,38.38],[4,8.8,25.58],[6,8.4,35.04],[8,8,50.65],[0,9.6,12.87],[2,9.2,41.47],[7,8.2,22.22],[9,7.8,29.51],[3,9,13.7],[5,8.6,13.41]],"bdatl":[[2,11,49.98],[3,11.5,43.42],[4,12,25.65],[5,12.5,36.39],[7,13.5,24.45],[8,14,18.56],[6,13,77],[0,10,77.18],[1,10.5,17.83],[9,14.5,11.76]],"ltp":9.6,"tv":1540.42,"id":36276560},{"atb":[[19.5,16.07],[8.4,59.01],[7.8,64.22],[21,16.86],[1.01,44693.07],[17,36.24],[20,21.17],[18,4.38]],"atl":[[25,10.77],[350,1.25],[540,0.81],[1000,32.73],[23,20.34],[28,6.09]],"bdatb":[[2,19.5,26.75],[6,17.5,12.76],[8,16.5,12.65],[9,16,27.13],[0,21,16.86],[7,17,36.24],[1,20,21.17],[5,18,4.38],[4,18.5,12.35]],"bdatl":[[2,25,10.77],[8,32,4.95],[0,23,20.34],[3,26,11.74],[4,27,10.52],[5,28,6.09],[6,29,3.99],[7,30,4.86],[1,24,45.67]],"id":37947503},{"atb":[[1.47,78.81],[1.42,1624.82],[1.31,1408.65],[1.29,1576.62],[1.37,219.99],[1.43,1359.6],[1.01,23850.85],[1.48,0],[1.46,143.8],[1.45,73.65]],"atl":[[1.48,228.78],[1.49,63.32],[1.5,34.73],[2.1,396.98],[2.22,357.93],[1000,238.57],[1.52,112.12],[1.53,59.46],[1.51,33.11]],"trd":[[1.48,471.61]],"bdatb":[[0,1.47,78.81],[3,1.44,119.35],[4,1.43,1530],[6,1.41,228.28],[7,1.4,1036.74],[8,1.39,300.61],[9,1.38,259.55],[5,1.42,1662.87],[2,1.45,252.64],[1,1.46,286.46]],"bdatl":[[0,1.48,228.78],[1,1.49,63.32],[2,1.5,68.76],[5,1.53,144.59],[6,1.54,163.15],[7,1.55,54.64],[8,1.56,258.05],[3,1.51,81.13],[4,1.52,263.76],[9,1.57,98.86]],"tv":6338.58,"id":39823721},{"atb":[[60,5.75],[15.5,30.12],[14,41.28],[1.01,45745.4],[75,0.63],[50,24.23],[3,0]],"atl":[[100,2.22],[95,2.19],[1000,18.45],[90,2.07],[80,4.97],[85,2.85]],"trd":[[80,20.39],[75,43.16]],"bdatb":[[1,60,5.75],[8,38,6.32],[4,48,18.13],[7,40,5.84],[0,65,6.64],[3,50,24.23]],"bdatl":[[3,95,2.19],[4,100,2.22],[2,90,2.07],[5,110,2.84],[6,120,2.84],[7,190,6.87],[8,200,2],[9,220,5],[0,80,4.97],[1,85,2.85]],"tv":136.86,"id":44331354}],"con":true,"tv":9733.95}]}
{"op":"mcm","clk":"AOBpAIJdALhe","pt":1650392756679,"mc":[{"id":"1.197931750","rc":[{"atb":[[8.2,23.31],[9.8,10.28],[9.6,16.17],[9.4,26.79],[1.08,0]],"atl":[[1000,46.71],[12.5,29.11],[10,20.74]],"trd":[[10,26.11],[9.8,44.59]],"bdatb":[[8,8.2,25.98],[0,9.8,10.28],[4,9,28.99],[5,8.8,68.66],[6,8.6,29.41],[7,8.4,34.79],[9,8,52.28],[1,9.6,16.17],[2,9.4,26.79],[3,9.2,25.91]],"bdatl":[[7,13.5,83.82],[2,11,66.64],[3,11.5,36.81],[4,12,40.79],[5,12.5,30.94],[6,13,14.65],[8,14,15.3],[9,14.5,8.48],[0,10,20.74]],"ltp":10,"tv":851.88,"id":42930960},{"atb":[[15,22.43],[14.5,14.14],[13.5,22.13],[1.01,43641.72],[16,0],[15.5,39.37]],"atl":[[16.5,35.97],[17.5,28.16],[17,23.8]],"trd":[[16,107.95]],"bdatb":[[1,15,22.43],[2,14.5,14.14],[3,14,24.17],[4,13.5,37.5],[5,13,33.33],[6,12.5,39.98],[8,11.5,42.8],[9,11,190.04],[0,15.5,39.37],[7,12,27.91]],"bdatl":[[0,16.5,35.97],[5,19,19.12],[6,19.5,13.1],[8,21,25.66],[9,22,11.24],[1,17,23.8],[2,17.5,28.16],[4,18.5,16.93],[7,20,9.59]],"tv":553.12,"id":40095374},{"atb":[[8.2,32.6],[8.6,22.62],[9.4,51.5],[9.6,25.08]],"atl":[[10,64.73],[1000,55.37],[11,31.75],[10.5,19.83]],"trd":[[10,88.97]],"bdatb":[[7,8.2,44.54],[3,9,13.7],[4,8.8,34.35],[5,8.6,38.38],[6,8.4,24.4],[8,8,44.14],[9,7.8,36.58],[0,9.6,25.08],[1,9.4,51.5],[2,9.2,18.83]],"bdatl":[[7,13.5,26.51],[2,11,35.75],[3,11.5,42.72],[5,12.5,30.13],[6,13,87.18],[8,14,12.95],[9,14.5,20.23],[4,12,28.26],[1,10.5,19.83]],"ltp":10,"tv":1565.32,"id":36276560},{"atb":[[21,18.86]],"atl":[[25,21.86],[24,57.9]],"bdatb":[[4,18.5,12.35],[5,18,15.9],[8,16.5,17.6],[7,17,36.24],[2,19.5,16.07],[6,17.5,5.31],[9,16,24.91],[0,21,18.86]],"bdatl":[[5,28,6.53],[6,29,4.25],[8,32,3.85],[9,34,8.54],[3,26,11.74],[4,27,9.52],[1,24,57.9],[2,25,21.86],[7,30,3.87]],"id":37947503},{"atb":[[1.34,250],[1.45,129.95],[1.47,29.91],[1.42,1676.71],[1.43,1133.99],[1.4,997.42],[1.44,85.37],[1.46,150.47],[1.01,23627.28]],"atl":[[1.48,235.13],[1000,238.57],[1.49,65.73],[1.51,35.12],[1.5,36.74]],"trd":[[1.48,482.04],[1.47,178.36]],"bdatb":[[2,1.45,273.02],[0,1.47,29.91],[4,1.43,1180.36],[5,1.42,1802.21],[7,1.4,1174.46],[6,1.41,228.42],[8,1.39,208.78],[9,1.38,352.05],[3,1.44,307.46],[1,1.46,150.47]],"bdatl":[[0,1.48,235.13],[2,1.5,103.91],[3,1.51,137.91],[4,1.52,277.79],[5,1.53,201.33],[6,1.54,129.77],[7,1.55,118],[8,1.56,228.04],[9,1.57,98.86],[1,1.49,65.73]],"ltp":1.48,"tv":6395.93,"id":39823721},{"atb":[[85,0],[80,3.68],[75,10.65],[70,0],[65,8.51],[1.67,0.03],[60,13.66]],"atl":[[1000,17.48],[110,5.12],[95,0],[100,0],[200,0],[90,0],[85,0],[80,0],[440,1],[410,0],[390,0]],"trd":[[85,7.79],[80,31.78],[75,45.97],[110,0.23],[95,4.38],[90,4.63]],"bdatb":[[0,75,14.21],[1,70,3.96],[2,65,12.5],[3,60,13.66],[4,55,7.97],[5,50,24.23],[6,48,18.11],[7,46,12.16],[8,44,8.44],[9,40,5.84]],"bdatl":[[0,110,3.12],[1,120,2.84],[2,190,6.87],[3,220,5],[4,270,2.22],[5,350,2],[6,380,1],[7,400,1],[8,420,1],[9,440,1]],"ltp":75,"tv":166.04,"id":44331354}],"con":true,"tv":9858.26}]}
{"op":"mcm","clk":"AIJrAIdeAMJf","pt":1650392757680,"mc":[{"id":"1.197931750","rc":[{"atb":[[7.6,23.55],[8.2,14.16]],"atl":[[1000,48.71],[12.5,37.81],[11,73.69],[10.5,32.46]],"bdatb":[[2,9.4,37.75],[4,9,36.2],[5,8.8,61.29],[6,8.6,36.37],[8,8.2,18.36],[9,8,49.94],[7,8.4,23.13]],"bdatl":[[2,11,73.69],[3,11.5,39.04],[4,12,39.6],[5,12.5,42.47],[6,13,14.99],[9,15,11.63],[1,10.5,32.46],[8,14,24.08],[7,13.5,79.67]],"id":42930960},{"atb":[[13,23.67],[12,20.59]],"atl":[[19.5,17.92],[18,27.4],[17.5,25.75]],"bdatb":[[1,15,29.29],[3,14,28.81],[4,13.5,25.06],[5,13,42.41],[7,12,25.57],[8,11.5,43.89],[9,11,187.29],[6,12.5,39.58]],"bdatl":[[4,18.5,15.82],[5,19,18.48],[7,20,11.45],[8,21,25.99],[9,22,10.28],[3,18,27.4],[6,19.5,17.92],[2,17.5,25.75]],"id":40095374},{"atb":[[9.4,33.27],[9.2,20.85],[9.8,3.79],[7.6,33.65],[8.2,23.44]],"atl":[[1000,57],[14,5.26],[17.5,6.06],[12.5,38.21],[11.5,47.3],[10,51.09],[14.5,17.18],[11,29.34]],"bdatb":[[2,9.4,44.23],[4,9,20.91],[5,8.8,15.27],[6,8.6,50.94],[9,8,44.5],[3,9.2,20.85],[0,9.8,3.79],[8,8.2,34.95],[1,9.6,25.08],[7,8.4,23.81]],"bdatl":[[2,11,29.34],[3,11.5,56.06],[4,12,25.23],[5,12.5,41.11],[6,13,89.2],[8,14,11.91],[9,14.5,19.23],[0,10,51.09],[7,13.5,22.36]],"id":36276560},{"atb":[[21,16.31],[18,4.94],[16.5,9.69]],"atl":[[23,24.34],[28,9.79],[26,15.74],[25,19.45]],"trd":[[21,63.22]],"bdatb":[[1,20,26.32],[4,18.5,15.86],[5,18,7.13],[8,16.5,24.45],[0,21,16.31]],"bdatl":[[3,26,15.74],[5,28,9.79],[7,30,5.11],[8,32,5.84],[9,34,10.36],[0,23,24.34],[2,25,19.45],[4,27,8.77],[6,29,3.86]],"tv":325.98,"id":37947503},{"atb":[[1.47,0],[1.35,136.91],[1.31,1538.33],[1.39,137.84],[1.38,21.55],[1.45,134.42]],"atl":[[1.47,70.09],[1000,240.57],[1.56,80.15],[1.53,159.46],[1.58,159.14],[1.49,63.32]],"trd":[[1.47,238.18]],"bdatb":[[0,1.46,150.47],[1,1.45,277.48],[2,1.44,296.09],[3,1.43,1160.12],[4,1.42,1708.61],[5,1.41,249.46],[6,1.4,1147.74],[7,1.39,365.86],[8,1.38,186.05],[9,1.37,354.2]],"bdatl":[[0,1.47,70.09],[1,1.48,235.13],[2,1.49,88.23],[3,1.5,182.64],[4,1.51,92.42],[5,1.52,275.35],[6,1.53,172.34],[7,1.54,169.37],[8,1.55,126.14],[9,1.56,140.94]],"ltp":1.47,"tv":6455.75,"id":39823721},{"atb":[[75,8.65],[65,11.43],[48,13.9],[2.06,0],[80,8.94],[60,13.83],[1.01,44835.48],[70,2.38],[34,0.13],[1.67,0]],"atl":[[100,1.66],[110,6.03],[400,0],[1000,17.26],[460,1],[380,0],[95,0.02]],"bdatb":[[1,75,8.65],[3,65,11.43],[4,60,15.55],[7,48,16.08],[0,80,8.94],[2,70,2.38],[5,55,7.97],[6,50,24.23],[8,46,12.16],[9,44,8.44]],"bdatl":[[0,100,1.68],[1,110,6.03],[2,120,2.84],[3,190,6.87],[4,220,5],[5,270,2.22],[6,350,2],[7,420,1],[8,440,1],[9,460,1]],"id":44331354}],"con":true,"tv":9918.09}]}
{"op":"mcm","clk":"AKNsAIpfAMNg","pt":1650392758681,"mc":[{"id":"1.197931750","rc":[{"atb":[[1.8,0.01],[8.2,24.53],[9.8,12.49],[1.01,72693.87]],"atl":[[10,13.57],[1000,80.49]],"trd":[[10,35.95]],"bdatb":[[5,8.8,40.92],[6,8.6,39.95],[8,8.2,58.19],[9,8,50.72],[0,9.8,12.49],[3,9.2,33.37],[2,9.4,26.79],[4,9,28.99]],"bdatl":[[5,12.5,38.02],[6,13,7.45],[7,13.5,85.69],[8,14,21.75],[9,14.5,14.78],[4,12,30.05],[0,10,13.57],[3,11.5,41.17]],"tv":861.72,"id":42930960},{"atb":[[1.8,2.32],[15,23.26],[1.01,74767.21]],"atl":[[1000,58.8]],"bdatb":[[5,13,26.51],[7,12,28.14],[9,11,192.72],[8,11.5,59.44],[4,13.5,27.1],[1,15,23.26],[2,14.5,18.87],[3,14,24.17]],"bdatl":[[9,22,7.63],[6,19.5,21.08],[8,21,22.96],[7,20,9.59]],"id":40095374},{"atb":[[9.8,13.22],[8.2,33.82],[9.6,53.38],[9,11.1],[9.4,34.52],[1.01,76122.61],[6.6,22.73],[9.2,15.38],[8.8,8.74]],"atl":[[10.5,18.53],[10,6.86],[1000,88.78],[11.5,62.14]],"trd":[[10,151.25]],"bdatb":[[5,8.8,12.93],[6,8.6,57.97],[8,8.2,41.45],[9,8,46.73],[0,9.8,13.22],[1,9.6,53.38],[3,9.2,30.12],[4,9,11.1],[2,9.4,34.52]],"bdatl":[[5,12.5,38.99],[6,13,79.98],[7,13.5,28.39],[8,14,7.07],[1,10.5,18.53],[4,12,20.39],[9,14.5,21.65],[0,10,6.86],[3,11.5,67.5]],"tv":1627.6,"id":36276560},{"atb":[[1.8,2.32],[20,17.81],[1.01,76384.48]],"atl":[[1000,47.82]],"bdatb":[[8,16.5,11.92],[5,18,8.66],[1,20,17.81],[2,19.5,19.59],[4,18.5,12.35]],"bdatl":[[9,34,8.65],[6,29,5.98],[8,32,3.85],[7,30,3.87]],"id":37947503},{"atb":[[1.45,48.67],[1.42,1517.04],[1.43,1181.23],[1.46,42.19],[1.01,33718.16],[1.32,263.03],[1.39,135.84],[1.41,262.98],[1.44,83.36]],"atl":[[1000,461.99],[1.47,117.34],[1.49,58.01],[1.52,93.24],[1.51,14.46],[1.48,247.7],[1.5,38.75],[1.57,37.82]],"trd":[[1.47,265.9],[1.46,52.11]],"bdatb":[[1,1.45,95.99],[3,1.43,1270.38],[4,1.42,1667.27],[5,1.41,340.6],[6,1.4,1291.91],[8,1.38,31.36],[2,1.44,129.91],[7,1.39,343.6],[0,1.46,42.19],[9,1.37,354.2]],"bdatl":[[0,1.47,117.34],[2,1.49,140.16],[5,1.52,146.45],[6,1.53,262.42],[7,1.54,192.53],[8,1.55,80.85],[9,1.56,130.91],[4,1.51,181.22],[1,1.48,247.7],[3,1.5,142.23]],"ltp":1.47,"tv":6510.29,"id":39823721},{"atb":[[80,4.83],[48,13.28],[1.01,76002.26],[70,2.22],[85,2.01],[75,10.89],[38,0]],"atl":[[1000,19.91],[120,2.93],[480,1],[420,0],[100,0],[95,0]],"trd":[[100,3.32],[95,4.42]],"bdatb":[[1,80,4.83],[8,48,14.68],[5,60,14.97],[3,70,2.22],[0,85,2.01],[2,75,10.89],[4,65,11.43],[6,55,7.97],[7,50,24.23],[9,46,12.16]],"bdatl":[[9,1000,19.91],[1,120,2.93],[0,110,6.03],[2,190,6.87],[3,220,5],[4,270,2.22],[5,350,2],[6,440,1],[7,460,1],[8,480,1]],"ltp":100,"tv":169.4,"id":44331354}],"con":true,"tv":10048.11}]}
{"op":"mcm","clk":"AMJtAJ9gALhh","pt":1650392759682,"mc":[{"id":"1.197931750","rc":[{"atb":[[8.8,40.78],[9.8,9.04],[1.02,5001.09],[9.6,13.07],[9.4,26.68],[8.4,23.01],[7.4,16.42],[8.2,24.41],[9.2,25.8],[9,28.88],[8.6,29.3],[1.8,0]],"atl":[[1000,80.25],[10.5,30.46],[11.5,39.66],[10,15.7]],"trd":[[9.8,47.07],[10,35.96]],"bdatb":[[0,9.8,9.04],[5,8.8,59],[1,9.6,13.07],[8,8.2,63.32],[9,8,50.1],[2,9.4,26.68],[3,9.2,25.8],[4,9,28.88],[6,8.6,33.27],[7,8.4,23.01]],"bdatl":[[3,11.5,43.72],[4,12,25.16],[5,12.5,43.29],[6,13,14.13],[7,13.5,81.31],[9,14.5,14.3],[1,10.5,30.46],[8,14,15.3],[0,10,15.7],[2,11,81.02]],"ltp":9.8,"tv":864.21,"id":42930960},{"atb":[[14,31.23],[15.5,37.31],[15,23.2],[11.5,44.65],[1.8,0]],"atl":[[16.5,35.4],[21,22.91],[20,9.54],[19.5,17.87],[19,20.98]],"trd":[[16.5,103.11]],"bdatb":[[3,14,31.23],[0,15.5,37.31],[8,11.5,69.2],[9,11,190.37],[1,15,23.2],[5,13,23.93],[7,12,23.43],[4,13.5,33.76],[2,14.5,14.14]],"bdatl":[[0,16.5,35.4],[8,21,23.28],[9,22,6.63],[5,19,20.98],[6,19.5,17.87],[7,20,9.54],[4,18.5,20.18]],"ltp":16.5,"tv":553.13,"id":40095374},{"atb":[[10,12.74],[9,20.46],[9.4,33.43],[9.8,20.74],[9.6,53.18],[8.4,33.78],[8.8,8.63],[7.6,37],[8.2,23.32],[9.2,15.27],[8.6,17.28],[7.4,23.94],[8,44.02]],"atl":[[1000,83.5],[11,34.95],[15,5.43],[12,32.97],[10.5,18.53],[12.5,40.22],[11.5,60.13],[10,0]],"trd":[[10,167.49]],"bdatb":[[0,10,12.74],[5,9,20.46],[1,9.8,20.74],[2,9.6,53.18],[3,9.4,33.43],[7,8.6,54.08],[9,8.2,27.81],[4,9.2,32.33],[6,8.8,9.02],[8,8.4,33.78]],"bdatl":[[3,12,33.63],[4,12.5,44.07],[5,13,82.27],[6,13.5,23.02],[7,14,15.18],[9,15,12.9],[1,11,34.95],[0,10.5,18.53],[8,14.5,17.18],[2,11.5,67.14]],"tv":1643.84,"id":36276560},{"atb":[[21,9.77],[18.5,16.62],[20,17.76],[19,13.12],[16,27.54],[1.8,0]],"atl":[[1000,47.82],[23,22.33]],"trd":[[21,65.22],[23,53.32]],"bdatb":[[0,21,9.77],[4,18.5,16.62],[1,20,17.76],[3,19,13.12],[8,16.5,9.9],[9,16,27.54],[5,18,13.66],[2,19.5,16.07]],"bdatl":[[8,32,4.1],[9,34,8.01],[0,23,22.33],[4,27,11.75],[5,28,9.79],[6,29,3.86]],"ltp":21,"tv":327.99,"id":37947503},{"atb":[[1.43,1354.95],[1.45,38.67],[1.34,366.24],[1.42,1579],[1.4,1038.09],[1.41,296.5],[1.44,150.13],[1.46,55.24]],"atl":[[1000,461.39],[1.49,41.34],[1.52,92.58],[1.47,109.1],[1.48,249.29],[1.51,38.97],[1.5,39.59],[1.54,67.66],[1.55,35.29],[1.56,79.5],[1.53,157.45]],"trd":[[1.47,281.2]],"bdatb":[[3,1.43,1381.19],[1,1.45,38.67],[4,1.42,1777.79],[5,1.41,368.97],[6,1.4,1108.95],[7,1.39,561.95],[8,1.38,33.77],[9,1.37,496.44],[2,1.44,259.15],[0,1.46,55.24]],"bdatl":[[2,1.49,126.84],[3,1.5,97.36],[4,1.51,205.05],[5,1.52,167.28],[6,1.53,329.24],[7,1.54,122.92],[8,1.55,58.41],[9,1.56,203.41],[0,1.47,109.1],[1,1.48,249.29]],"tv":6525.59,"id":39823721},{"atb":[[90,2.35],[80,7.1],[75,11.03],[60,10.75],[55,5.08],[50,24.21],[85,2],[65,12.14],[70,5.12],[1.01,71093.15]],"atl":[[1000,19.77],[120,0.09],[190,4],[500,1]],"trd":[[90,6.63]],"bdatb":[[0,90,2.35],[2,80,7.1],[3,75,11.03],[1,85,2],[5,65,12.14],[6,60,10.75],[7,55,5.08],[8,50,24.21],[4,70,5.12],[9,48,16.55]],"bdatl":[[9,1000,19.77],[1,190,4.12],[2,220,5],[3,270,2.22],[4,350,2],[5,440,1],[6,460,1],[7,480,1],[8,500,1]],"ltp":90,"tv":171.4,"id":44331354}],"con":true,"tv":10086.16}]}
{"op":"mcm","clk":"AM5uAKRhALJi","pt":1650392760684,"mc":[{"id":"1.197931750","rc":[{"atb":[[9.8,9.1],[1.67,0],[7.6,29.81],[8.2,30.13],[2.2,1.09],[9.6,16.07],[1.02,5000]],"atl":[[10,15.67],[10.5,32.46]],"trd":[[10,36.02]],"bdatb":[[5,8.8,59.04],[6,8.6,36.22],[8,8.2,70.93],[9,8,51.79],[0,9.8,9.1],[1,9.6,16.07]],"bdatl":[[2,11,85.88],[3,11.5,40.04],[4,12,29.98],[5,12.5,37.86],[6,13,18.79],[7,13.5,81.89],[8,14,19.89],[0,10,15.67],[9,14.5,7.87],[1,10.5,32.46]],"ltp":10,"tv":864.27,"id":42930960},{"atb":[[13,27.07],[12,24.3],[8.2,59.31],[15.5,39.31]],"atl":[[1000,59.8]],"bdatb":[[5,13,27.38],[7,12,29.26],[9,11,192.23],[4,13.5,33.74],[8,11.5,68.76],[0,15.5,39.31]],"bdatl":[[6,19.5,20.18],[9,22,5.07],[4,18.5,20.64],[8,21,22.91]],"id":40095374},{"atb":[[7.6,31.94],[10,13.85],[8.2,29.04],[6.8,52.65],[9.8,35.52],[1.01,73804.1],[9.4,20.33]],"atl":[[1000,86.34],[11,36.95],[10.5,20.98]],"trd":[[10,167.5]],"bdatb":[[6,8.8,9.09],[7,8.6,56.45],[9,8.2,36.03],[4,9.2,32.3],[0,10,13.85],[1,9.8,35.52],[3,9.4,20.33]],"bdatl":[[2,11.5,71.8],[5,13,77],[6,13.5,25.12],[7,14,18.04],[9,15,10.23],[3,12,32.97],[4,12.5,45.98],[0,10.5,20.98],[1,11,36.95]],"tv":1643.85,"id":36276560},{"atb":[[1.01,90117.32],[21,9.79],[18,7.32],[16.5,12.31],[20,19.76]],"atl":[[23,30.57],[1000,47.82],[65,8.88]],"bdatb":[[8,16.5,12.55],[5,18,16.02],[0,21,9.79],[1,20,19.76]],"bdatl":[[0,23,30.57],[6,29,5.41],[9,34,6.99],[4,27,12.07],[8,32,3.85]],"id":37947503},{"atb":[[1.46,91.88],[1.12,0],[1.36,174],[1.35,184.91],[1.38,46.73],[1.32,311.03],[1.26,178.46],[1.34,366.24],[1.45,49.67]],"atl":[[1.47,109.32],[1.52,90.57],[1.53,155.44],[1.54,65.65],[1.55,33.19],[1000,460.39],[1.48,266.29]],"trd":[[1.47,281.66],[1.46,54.11]],"bdatb":[[0,1.46,91.88],[6,1.4,1285.43],[7,1.39,376.9],[2,1.44,258.96],[3,1.43,1399.38],[4,1.42,1774.27],[5,1.41,388.12],[8,1.38,54.08],[1,1.45,49.67],[9,1.37,508.75]],"bdatl":[[0,1.47,109.32],[5,1.52,166.33],[6,1.53,354.59],[7,1.54,115.95],[8,1.55,36.81],[2,1.49,134.29],[3,1.5,109.55],[1,1.48,266.29],[9,1.56,202.01]],"ltp":1.47,"tv":6528.05,"id":39823721},{"atb":[[1.01,99007.79],[90,4.36],[55,5.08],[60,13.62],[65,11.41],[85,0]],"atl":[[110,8.71],[1000,19.63]],"bdatb":[[0,90,4.36],[6,55,5.08],[5,60,13.62],[4,65,11.41],[1,80,7.1],[2,75,11.03],[3,70,5.12],[7,50,24.21],[8,48,16.55],[9,46,12.16]],"bdatl":[[0,110,8.71],[9,1000,19.63]],"id":44331354}],"con":true,"tv":10088.69}]}
{"op":"mcm","clk":"AOBvAKhiALVj","pt":1650392761685,"mc":[{"id":"1.197931750","rc":[{"bdatb":[[6,8.6,38.53],[8,8.2,68.52],[5,8.8,58.82],[9,8,52.03]],"bdatl":[[2,11,73.69],[3,11.5,39.66],[4,12,29.45],[5,12.5,42.68],[6,13,10.01],[8,14,16.15],[9,14.5,3.16],[7,13.5,79.67]],"id":42930960},{"atb":[[15.5,38.31]],"atl":[[1000,58.8]],"trd":[[15.5,9.42]],"bdatb":[[7,12,30.91],[8,11.5,67.21],[5,13,27.23],[9,11,192.06],[0,15.5,38.31]],"bdatl":[[4,18.5,15.82],[6,19.5,17.87],[8,21,24.19],[9,22,7.69]],"ltp":15.5,"tv":555.14,"id":40095374},{"atb":[[9.4,2.88],[1.04,0.35],[9.8,0],[10,0],[9.6,0],[9.2,24.38]],"atl":[[10.5,22.68],[1000,83.5]],"trd":[[9.4,144.96],[9.8,129.12],[10,195.2],[9.6,116.99]],"bdatb":[[0,9.4,2.88],[1,9.2,41.41],[2,9,20.46],[3,8.8,8.87],[4,8.6,56.68],[5,8.4,33.78],[6,8.2,35.79],[7,8,47.92],[8,7.8,33.41],[9,7.6,39.75]],"bdatl":[[0,10.5,22.68],[7,14,16.92],[9,15,11.27],[2,11.5,70.71],[5,13,77.92],[6,13.5,25.17]],"ltp":9.4,"tv":1883.85,"id":36276560},{"atb":[[19,11],[19.5,14.07]],"bdatb":[[2,19.5,14.07],[3,19,11],[8,16.5,12.44]],"bdatl":[[4,27,8.77],[6,29,3.86],[8,32,4.69],[9,34,6.87]],"id":37947503},{"atb":[[1.43,1352.94],[1.44,147.96],[1.4,938.09],[1.42,1593.08],[1.46,83.29],[1.2,1]],"atl":[[1.47,108]],"trd":[[1.47,284.3],[1.46,71.29]],"bdatb":[[6,1.4,1164.64],[7,1.39,384.98],[2,1.44,256.79],[3,1.43,1409.87],[4,1.42,1775.76],[5,1.41,400.79],[8,1.38,67.03],[0,1.46,83.29]],"bdatl":[[2,1.49,41.34],[3,1.5,57.64],[4,1.51,157.2],[5,1.52,120.68],[6,1.53,314.17],[7,1.54,130.31],[8,1.55,75.99],[9,1.56,125.31],[0,1.47,108]],"ltp":1.47,"tv":6547.87,"id":39823721},{"atb":[[90,8.21],[80,6.23],[55,5.08],[95,0.64]],"atl":[[110,8.61],[140,0.08]],"bdatb":[[0,90,8.85],[1,80,6.23],[6,55,5.08]],"bdatl":[[0,110,8.61],[1,190,4.2]],"id":44331354}],"con":true,"tv":10350.52}]}
{"op":"mcm","clk":"AIFxAMNjANJk","pt":1650392762686,"mc":[{"id":"1.197931750","rc":[{"atb":[[9.8,11.2],[8.8,38.75],[7.8,287.46],[7.2,4.76],[1.01,75525.87]],"atl":[[11.5,49.18],[13.5,5.67],[15,75.09],[11,63.69],[10,8.53]],"trd":[[9.8,47.09],[10,46.02]],"bdatb":[[0,9.8,11.2],[4,9,29.96],[6,8.6,32.17],[8,8.2,40.32],[9,8,56.59],[3,9.2,41.94],[5,8.8,54.87]],"bdatl":[[2,11,65.91],[3,11.5,49.42],[4,12,39.22],[5,12.5,38.56],[6,13,9.28],[7,13.5,8.69],[8,14,17.6],[9,14.5,3.46],[1,10.5,32.46],[0,10,8.53]],"ltp":9.8,"tv":874.29,"id":42930960},{"atb":[[15.5,21],[15,23.2],[14.5,14.14],[13.5,22.13],[16,1.53],[10.5,226.12],[11,5.02],[1.01,77721.21]],"atl":[[1000,58.14]],"trd":[[16,111.27],[15.5,9.99]],"bdatb":[[1,15.5,21],[6,13,38.73],[8,12,26.35],[9,11.5,51.91],[0,16,1.53],[2,15,23.2],[3,14.5,20.02],[5,13.5,26.81],[7,12.5,39.58],[4,14,31.23]],"bdatl":[[5,19,22.42],[8,21,26.02],[9,22,5.65],[4,18.5,15.82],[7,20,9.54],[2,17.5,25.75]],"ltp":16,"tv":559.03,"id":40095374},{"atb":[[9.4,9.86],[9,11.47],[7.4,293.94],[9.6,0],[7,19.23],[1.01,69855.31],[1.04,0],[8.4,31.6],[8.6,29.15],[8.8,10.63],[9.2,13.25]],"atl":[[1000,80.28],[9.8,16.14],[12,29.98],[10.5,32.66],[15,72.43],[11.5,62.13],[13,0],[11,40.97],[9.6,0],[10,14.19]],"trd":[[9.6,134.88]],"bdatb":[[0,9.4,9.86],[2,9,20.96],[4,8.6,56.99],[6,8.2,39.22],[7,8,46.26],[9,7.6,38.49],[1,9.2,13.25],[3,8.8,10.63],[5,8.4,31.6],[8,7.8,29.51]],"bdatl":[[0,9.8,16.14],[2,10.5,34.99],[3,11,41.22],[4,11.5,77.6],[5,12,35.97],[6,12.5,40.22],[7,13,5.61],[8,13.5,26.07],[9,14,13.45],[1,10,14.19]],"ltp":9.6,"tv":1901.74,"id":36276560},{"atb":[[15,3.57],[19,11.6],[19.5,13.49],[1.01,87235.21],[18,4.38],[18.5,16.62],[22,0],[21,9.77]],"atl":[[1000,47.2],[27,6.77],[22,6.75],[23,18.38],[25,21.46],[24,59.9]],"trd":[[22,119.38]],"bdatb":[[2,19.5,13.49],[3,19,16.09],[7,17,40.53],[4,18.5,16.62],[5,18,4.38],[0,21,9.77],[1,20,19.76],[6,17.5,5.31],[8,16.5,20.91],[9,16,27.54]],"bdatl":[[5,27,7.67],[6,28,9.89],[8,30,3.87],[9,32,5.89],[0,22,6.75],[1,23,18.38],[3,25,21.46],[2,24,59.9],[4,26,15.74],[7,29,3.86]],"ltp":22,"tv":332.57,"id":37947503},{"atb":[[1.47,18.53],[1.45,84.86],[1.01,34273.15],[1.44,142.09],[1.46,171.1],[1.42,197.03],[1.38,1545.73],[1.4,1038.09],[1.32,261.03]],"atl":[[1.48,219.41],[1.49,56.04],[1.5,45.15],[1000,441.64],[1.55,678.19],[1.6,32.75],[1.61,65.93],[1.8,4.56],[1.52,92.58],[1.47,0]],"trd":[[1.48,512.12],[1.47,399.42]],"bdatb":[[0,1.47,18.53],[1,1.46,229.55],[2,1.45,135.1],[3,1.44,240.63],[4,1.43,1441.11],[5,1.42,308.26],[6,1.41,553.92],[7,1.4,1142.85],[8,1.39,159.55],[9,1.38,1955.55]],"bdatl":[[0,1.48,219.41],[1,1.49,56.04],[2,1.5,106.95],[3,1.51,113.45],[4,1.52,131.3],[5,1.53,211.63],[6,1.54,172.67],[7,1.55,773.24],[8,1.56,102.44],[9,1.57,143.13]],"ltp":1.48,"tv":6693.07,"id":39823721},{"atb":[[28,3.7],[95,6.71],[90,2.47],[19,0],[55,3.02],[50,22.21],[48,11.22],[36,77.09],[29,0.27],[1.01,109783.98],[70,5.55]],"atl":[[440,0],[340,2],[270,0],[380,3],[220,0],[1000,20.24],[190,6.93]],"bdatb":[[0,95,6.71],[1,90,2.47],[7,55,3.02],[8,50,22.21],[9,48,11.22],[6,60,15.05],[2,80,6.23],[3,75,11.03],[4,70,5.55],[5,65,11.41]],"bdatl":[[2,340,2.22],[3,350,2],[4,380,3],[8,1000,20.27],[5,460,1],[6,480,1],[7,500,1],[9,0,0],[1,190,7.13]],"id":44331354}],"con":true,"tv":10532.1}]}
{"op":"mcm","clk":"AIdyAN1kANll","pt":1650392763688,"mc":[{"id":"1.197931750","rc":[{"atb":[[7.8,280.52],[7.6,18.49]],"atl":[[14.5,5.63]],"bdatb":[[1,9.6,16.07],[2,9.4,26.68],[3,9.2,39.16],[4,9,49.83],[6,8.6,37.1],[7,8.4,27.58],[8,8.2,30.13],[9,8,56.59],[5,8.8,38.75]],"bdatl":[[2,11,71.9],[3,11.5,64.78],[4,12,30.25],[5,12.5,39.17],[6,13,13.71],[8,14,15.78],[9,14.5,8.35],[7,13.5,5.67]],"id":42930960},{"atb":[[14.5,21.73],[16,30.25],[8,19.26],[15.5,25.77],[15,25.38]],"atl":[[16.5,33.42]],"bdatb":[[1,15.5,25.77],[3,14.5,27.62],[4,14,31.23],[5,13.5,24.91],[6,13,41.57],[7,12.5,39.58],[8,12,33.09],[9,11.5,44.65],[2,15,25.38],[0,16,30.25]],"bdatl":[[4,18.5,18.83],[5,19,22.81],[7,20,9.54],[8,21,23.83],[6,19.5,17.87],[9,22,11.88],[0,16.5,33.42]],"id":40095374},{"atb":[[9.2,6.05],[5.1,41.55],[8.4,23.51],[8.8,9.92],[9,23.8],[1.01,66820.2],[9.4,0],[8,37.28],[6.8,61.27],[8.6,19.32],[8.2,22.1]],"atl":[[10.5,39.83],[10,19.34],[9.4,13.07],[9.8,14.28],[11,32.32],[12.5,38.21],[1000,79.18],[13,5.67],[9.6,12.05]],"trd":[[9.4,159.06]],"bdatb":[[0,9.2,6.05],[1,9,23.8],[2,8.8,19.62],[3,8.6,19.32],[4,8.4,50.42],[5,8.2,22.1],[6,8,50.47],[7,7.8,30.7],[8,7.6,39.63],[9,7.4,293.94]],"bdatl":[[3,10,28.38],[4,10.5,41.67],[5,11,53.27],[8,12.5,41.21],[6,11.5,74.05],[7,12,29.98],[9,13,11.92],[0,9.4,13.07],[2,9.8,14.28],[1,9.6,12.05]],"ltp":9.4,"tv":1915.84,"id":36276560},{"atb":[[23,25.91],[17.5,8.34],[15,0],[18,6.87],[21,7.28],[8,2.24]],"atl":[[23,0],[22,0],[1000,45.77]],"trd":[[23,86.08],[22,132.88]],"bdatb":[[0,23,25.91],[1,21,7.28],[2,20,24.02],[3,19.5,13.49],[4,19,11.6],[5,18.5,18.65],[6,18,13.29],[7,17.5,8.34],[8,17,40.53],[9,16.5,12.31]],"bdatl":[[4,28,11.78],[6,30,5.03],[7,32,3.85],[8,34,7.44],[0,24,59.9],[1,25,21.46],[2,26,15.74],[3,27,6.77],[5,29,3.86],[9,36,3.57]],"ltp":23,"tv":378.83,"id":37947503},{"atb":[[1.47,61.49],[1.01,33384.5],[1.44,289.8],[1.43,1243.2],[1.45,94.55]],"atl":[[1.48,210.38],[1000,426.01],[1.49,70.83]],"trd":[[1.47,404.4],[1.48,538.12]],"bdatb":[[0,1.47,61.49],[5,1.42,211.47],[6,1.41,568.95],[8,1.39,293.37],[9,1.38,1612.38],[1,1.46,229.55],[2,1.45,200.21],[3,1.44,420.08],[4,1.43,1330.81],[7,1.4,1159.95]],"bdatl":[[1,1.49,108.16],[2,1.5,184.08],[3,1.51,100.66],[4,1.52,196.28],[6,1.54,146.72],[7,1.55,696.27],[8,1.56,102.55],[9,1.57,112.5],[0,1.48,210.38],[5,1.53,208.53]],"ltp":1.47,"tv":6724.05,"id":39823721},{"atb":[[1.05,297.84],[100,1.97],[95,6.19],[65,8.49],[75,14.36],[48,10.6],[90,0],[8,2.24],[55,5.96]],"atl":[[1000,20.1],[460,0],[520,1],[110,6.61]],"trd":[[100,3.62]],"bdatb":[[0,100,1.97],[1,95,6.19],[2,80,6.23],[5,65,8.49],[6,60,15.05],[8,50,22.21],[9,48,11.39],[3,75,14.36],[4,70,5.55],[7,55,5.96]],"bdatl":[[2,340,2.38],[5,480,1],[6,500,1],[7,520,1],[8,1000,20.1],[0,110,6.61]],"ltp":100,"tv":171.7,"id":44331354}],"con":true,"tv":10623.74}]}
{"op":"mcm","clk":"AJRzAIRmAONm","pt":1650392764690,"mc":[{"id":"1.197931750","rc":[{"atb":[[9.8,3.76]],"atl":[[10,10.58]],"trd":[[9.8,61.94]],"bdatb":[[0,9.8,3.76],[3,9.2,27.99],[4,9,35.86],[5,8.8,46.93],[6,8.6,33.19],[7,8.4,23.01],[8,8.2,37.01],[9,8,55.49]],"bdatl":[[2,11,69.07],[7,13.5,7.98],[5,12.5,50.68],[6,13,4.47],[8,14,21.45],[9,14.5,12.02],[3,11.5,59.61],[4,12,24.39],[0,10,10.58]],"tv":889.14,"id":42930960},{"atb":[[2.06,0.34],[16,28.59],[14.5,15.84]],"atl":[[22,9.63],[18,21.52]],"trd":[[16,114.59]],"bdatb":[[3,14.5,17.22],[4,14,35.72],[7,12.5,43.52],[8,12,27.09],[0,16,28.59],[6,13,27.07],[9,11.5,49.56],[5,13.5,23.83]],"bdatl":[[5,19,22.16],[8,21,23.41],[9,22,14.61],[4,18.5,17.81],[7,20,9.54],[3,18,21.52]],"tv":562.35,"id":40095374},{"atb":[[8.4,23.51],[4.9,173.97],[9.2,7.59],[8.6,31.07],[8.2,32.48]],"atl":[[9.4,2.14],[10,25.24],[11,30.32],[9.6,14.05],[9.8,19.78],[10.5,31.89]],"trd":[[9.4,177.2],[9.2,49.51]],"bdatb":[[0,9.2,7.59],[4,8.4,26.24],[2,8.8,19.35],[6,8,47.61],[7,7.8,36.74],[3,8.6,31.07],[5,8.2,32.48],[8,7.6,39.68]],"bdatl":[[4,10.5,34.03],[8,12.5,47.6],[0,9.4,2.14],[3,10,28.92],[5,11,41.23],[9,13,12.8],[1,9.6,14.05],[2,9.8,19.78],[6,11.5,76.12],[7,12,29.98]],"ltp":9.2,"tv":1936.81,"id":36276560},{"atb":[[23,30.95],[1.41,2.85],[22,12.29],[21,11.63],[19,11.66],[20,26.26],[16.5,9.08],[19.5,15.49]],"atl":[[24,55.25],[32,7.08],[26,9.61],[25,16.99],[1000,43.28],[28,11.8],[27,8.77]],"trd":[[23,93.46]],"bdatb":[[0,23,30.95],[3,20,27.26],[4,19.5,18.71],[1,22,12.29],[6,18.5,16.62],[7,18,8.14],[9,17,36.24],[2,21,11.63],[5,19,11.66],[8,17.5,8.34]],"bdatl":[[6,30,4.62],[8,34,7.18],[4,28,13.12],[0,24,55.25],[7,32,7.08],[1,25,16.99],[2,26,9.61],[3,27,8.77]],"tv":386.21,"id":37947503},{"atb":[[1.47,40.29],[1.42,209.57],[1.44,289.96],[1.46,82.2],[1.45,110.93]],"atl":[[1000,422.93],[1.48,56.06],[1.5,37.58]],"trd":[[1.47,587],[1.46,339.37]],"bdatb":[[0,1.47,40.29],[2,1.45,144.83],[3,1.44,492.5],[5,1.42,266.16],[7,1.4,1188.79],[8,1.39,224],[9,1.38,1644.98],[6,1.41,534.01],[1,1.46,154.69],[4,1.43,1295.17]],"bdatl":[[8,1.56,145.59],[9,1.57,139.53],[1,1.49,117.68],[2,1.5,118.42],[3,1.51,158.38],[4,1.52,149.2],[5,1.53,273.82],[6,1.54,92.06],[7,1.55,779.37],[0,1.48,56.06]],"ltp":1.47,"tv":7174.73,"id":39823721},{"atb":[[1.05,1187.64],[100,1.52],[18,0],[20,5.18],[95,4.19],[80,6.86],[75,12.36],[70,5.4]],"atl":[[130,0.19],[480,0],[110,4.42]],"trd":[[100,4.51],[110,4.23]],"bdatb":[[6,60,13.96],[7,55,7.1],[9,48,10.6],[0,100,1.52],[1,95,4.19],[2,80,6.86],[3,75,12.36],[4,70,5.4]],"bdatl":[[2,340,2.33],[1,190,7.29],[5,500,1],[6,520,1],[7,1000,20.1],[8,0,0],[0,110,4.42]],"ltp":100,"tv":176.59,"id":44331354}],"con":true,"tv":11125.83}]}
{"op":"mcm","clk":"AMx0AItnAO1n","pt":1650392765703,"mc":[{"id":"1.197931750","rc":[{"atb":[[7,156.67],[8.8,34.52],[9.2,27.6],[1.01,71496.01],[9,41.5],[9.4,7.52],[8.2,23.19],[8.6,41.17],[9.6,0],[9.8,0]],"atl":[[11.5,47.17],[12,22.35],[10.5,36.48],[10,18.09],[28,4.45],[9.6,3.55],[27,0],[9.8,12.41],[11,72.85]],"trd":[[9.6,134.84],[9.8,65.27]],"bdatb":[[2,9,26.88],[4,8.6,41.17],[0,9.4,7.52],[1,9.2,28.83],[3,8.8,34.17],[5,8.4,33.32],[6,8.2,23.19],[7,8,55.71],[9,7.6,36.8],[8,7.8,280.52]],"bdatl":[[8,13,11.19],[0,9.6,3.55],[2,10,18.09],[3,10.5,42.29],[4,11,82.95],[5,11.5,61.03],[6,12,22.5],[7,12.5,40.72],[9,13.5,10.65],[1,9.8,12.41]],"ltp":9.6,"tv":909.21,"id":42930960},{"atb":[[16,19.28],[15,25.72],[14,35.51],[2.06,0]],"atl":[[18.5,18.21]],"bdatb":[[0,16,19.28],[2,15,25.72],[4,14,36.1],[5,13.5,22.13],[6,13,33.73],[7,12.5,39.58],[8,12,29.35],[9,11.5,44.65],[3,14.5,15.84]],"bdatl":[[3,18,24.91],[7,20,10.03],[8,21,25.85],[9,22,11.44],[5,19,20.98],[4,18.5,18.21]],"id":40095374},{"atb":[[9.2,14.39],[8.6,35.77]],"atl":[[9.6,16.05],[9.8,13.96],[1000,80.21],[10,23.23],[9.4,0],[10.5,39.79]],"trd":[[9.4,181.48]],"bdatb":[[0,9.2,14.39],[1,9,23.8],[2,8.8,10.86],[3,8.6,35.77],[4,8.4,26.59],[5,8.2,39.89],[6,8,44.86],[7,7.8,29.51],[8,7.6,50.25],[9,7.4,294.57]],"bdatl":[[8,13,5.67],[1,9.8,13.96],[5,11.5,74.15],[0,9.6,16.05],[2,10,29.33],[3,10.5,40.72],[4,11,39.54],[6,12,32.12],[7,12.5,51.44],[9,13.5,28.03]],"ltp":9.4,"tv":1941.09,"id":36276560},{"atb":[[1.41,0],[23,27.27],[22,19.05],[19.5,17.63]],"atl":[[24,45.2],[25,16.55],[28,13.86]],"trd":[[24,4.1],[23,100.82]],"bdatb":[[2,21,11.63],[4,19.5,18.05],[6,18.5,16.62],[7,18,8.3],[9,17,39.82],[0,23,27.27],[3,20,26.26],[1,22,19.05]],"bdatl":[[1,25,16.55],[0,24,45.2],[4,28,16.04],[7,32,7.38],[8,34,8.68],[6,30,3.87]],"ltp":24,"tv":393.6,"id":37947503},{"atb":[[1.47,75.61],[1.48,41.2],[1.45,131.71],[1.44,289.8],[1.46,94.65]],"atl":[[1.66,119.69],[1.51,47.66],[1000,416.55],[1.49,5.54],[1.53,57.45],[1.48,0],[1.5,57.72],[1.52,94.59]],"trd":[[1.49,521.04],[1.48,665.55],[1.46,340.91]],"bdatb":[[2,1.46,201.29],[0,1.48,41.2],[1,1.47,75.61],[3,1.45,227.51],[4,1.44,318.99],[5,1.43,1373.71],[6,1.42,347.88],[7,1.41,453.55],[8,1.4,1140.67],[9,1.39,272.47]],"bdatl":[[9,1.58,189.1],[6,1.55,699.92],[0,1.49,5.54],[1,1.5,104.85],[2,1.51,197.61],[3,1.52,119.73],[4,1.53,208.57],[5,1.54,150.09],[7,1.56,162],[8,1.57,149.93]],"ltp":1.49,"tv":7415.78,"id":39823721},{"atb":[[95,4.07],[85,0.14],[65,8.49],[100,3.52],[19,5.56]],"atl":[[1000,22.41],[230,3.21],[110,2.58],[540,1],[460,0.08]],"trd":[[110,7.91]],"bdatb":[[4,70,5.4],[5,65,8.49],[8,50,22.38],[9,48,10.6],[0,100,3.52],[7,55,5.96],[6,60,13.62]],"bdatl":[[2,230,3.21],[3,340,2.2],[4,350,2],[5,380,3],[6,500,1.08],[7,520,1],[8,540,1],[9,1000,22.41],[0,110,2.58]],"ltp":110,"tv":180.27,"id":44331354}],"con":true,"tv":11402.3}]}
{"op":"mcm","clk":"AOp1AItoAO1o","pt":1650392766728,"mc":[{"id":"1.197931750","rc":[{"atb":[[9.4,0.01],[1.03,2.84],[1.01,68878.15],[8.6,36.32],[8.4,25.02],[8.8,36.98],[9.2,20.87],[9,29.5]],"atl":[[9.4,0],[1000,85.84],[9.8,21.38],[28,0],[10,26.87],[11,61.72],[9.6,5.67],[12.5,29.11],[10.5,44.38]],"trd":[[9.4,349.16]],"bdatb":[[0,9.2,20.88],[4,8.4,25.85],[5,8.2,32.17],[6,8,55.21],[7,7.8,281.11],[8,7.6,36.4],[9,7.4,27.18],[3,8.6,42.87],[1,9,29.5],[2,8.8,36.98]],"bdatl":[[0,9.6,5.67],[1,9.8,28.49],[2,10,26.87],[3,10.5,45.99],[4,11,78.71],[5,11.5,55.67],[6,12,24.75],[7,12.5,31.75],[8,13,19.41],[9,13.5,6.02]],"ltp":9.4,"tv":954.82,"id":42930960},{"atb":[[14,36.33],[11,10.08],[15.5,25.81],[15,26.91],[1.01,74716.34],[14.5,13.78],[16,0]],"atl":[[17.5,27.76],[17,25.8],[16,8.56],[1000,67.78],[18,27.4],[22,4.87],[16.5,32.49]],"trd":[[16,176.59]],"bdatb":[[3,14,36.33],[4,13.5,26.16],[5,13,27.22],[6,12.5,40.14],[7,12,35.15],[8,11.5,45.06],[9,11,22.45],[0,15.5,25.81],[1,15,26.91],[2,14.5,13.78]],"bdatl":[[0,16,8.56],[2,17,25.81],[3,17.5,31.74],[9,21,26.78],[4,18,28.34],[6,19,20.98],[8,20,14.82],[1,16.5,32.49],[5,18.5,18.21],[7,19.5,17.87]],"tv":624.35,"id":40095374},{"atb":[[9.2,7.58],[1.01,66233.68]],"atl":[[1000,88.34],[9.4,6.74],[9.6,14.05],[9.8,22.01],[10,25.49],[11.5,60.13],[11,40.32],[12.5,29.51]],"trd":[[9.4,205.36]],"bdatb":[[3,8.6,42.1],[4,8.4,23.74],[5,8.2,32.48],[6,8,54.44],[0,9.2,7.58],[9,7.4,293.94],[8,7.6,50.45],[7,7.8,29.51],[2,8.8,9.92]],"bdatl":[[0,9.4,6.74],[1,9.6,14.06],[2,9.8,30.84],[4,10.5,49.84],[5,11,47.71],[8,12.5,45.04],[9,13,6.04],[3,10,25.49],[6,11.5,74.01],[7,12,29.98]],"tv":1964.97,"id":36276560},{"atl":[[25,20.56],[29,5.78],[28,11.8]],"bdatb":[[3,20,26.26],[4,19.5,20.42],[6,18.5,16.72],[8,17.5,8.34],[9,17,36.66],[7,18,6.87]],"bdatl":[[1,25,20.56],[4,28,14.29],[5,29,6.36],[7,32,7.08],[8,34,9.97],[6,30,3.87]],"id":37947503},{"atb":[[1.48,126.24],[1.46,136.24],[1.49,58.14],[1.47,108.61],[1.45,279.37],[1.44,247.93],[1.43,1241.19]],"atl":[[1.51,90.9],[1000,472.87],[1.5,37.57],[1.52,92.58],[1.53,59.46],[1.54,67.66],[1.49,0]],"trd":[[1.49,532.12]],"bdatb":[[1,1.48,126.24],[2,1.47,151.71],[3,1.46,273.65],[4,1.45,408.95],[5,1.44,304.04],[6,1.43,1336.47],[7,1.42,441.77],[8,1.41,357.54],[9,1.4,1057.38],[0,1.49,58.14]],"bdatl":[[0,1.5,37.64],[1,1.51,137],[6,1.56,146.28],[7,1.57,97.26],[9,1.59,104.42],[3,1.53,135.36],[5,1.55,711.46],[8,1.58,239.57],[4,1.54,215.21],[2,1.52,233.53]],"tv":7426.86,"id":39823721},{"atb":[[100,3.51],[15,28.57],[18,8.82],[70,5.37]],"atl":[[120,1.4],[1000,20.1],[340,5.01],[560,1],[510,0.06],[460,0]],"trd":[[100,4.53]],"bdatb":[[6,60,13.62],[8,50,23.3],[9,48,10.64],[0,100,3.51],[4,70,5.37],[1,95,4.07],[2,80,7]],"bdatl":[[4,340,5.25],[1,120,1.4],[2,190,7.2],[3,230,3.21],[5,350,2],[6,380,3],[7,500,1],[8,520,1.06],[9,540,1]],"ltp":100,"tv":180.29,"id":44331354}],"con":true,"tv":11544.89}]}
{"op":"mcm","clk":"AJ93AJppAPdp","pt":1650392767729,"mc":[{"id":"1.197931750","rc":[{"atb":[[8.2,23.59],[1.03,0],[8.4,25.02],[9.2,12.48],[9.4,0]],"atl":[[28,0],[10,19.23],[1000,91.28],[9.8,24.23],[9.4,0.01],[10.5,43.3]],"trd":[[9.4,349.18]],"bdatb":[[3,8.6,38.26],[4,8.4,39.44],[6,8,52.59],[7,7.8,293.99],[8,7.6,19.19],[9,7.4,28],[5,8.2,23.59],[0,9.2,12.48],[2,8.8,36.98]],"bdatl":[[5,11.5,51.08],[6,12,24.35],[8,13,18.09],[9,13.5,5.85],[3,10.5,52.31],[4,11,79.91],[7,12.5,36.02],[2,10,19.23],[1,9.8,24.23],[0,9.6,5.68]],"tv":954.84,"id":42930960},{"atb":[[14,36.33],[13.5,28.11],[15.5,23.46],[14.5,12.99],[1.01,73753.54]],"atl":[[17.5,25.47],[17,30.16],[16,10.84],[18.5,16.2]],"bdatb":[[4,13.5,29.34],[5,13,29.98],[6,12.5,46.25],[7,12,25.24],[8,11.5,55.9],[9,11,11.3],[3,14,36.33],[2,14.5,12.99],[0,15.5,23.46]],"bdatl":[[2,17,30.16],[3,17.5,25.47],[4,18,32.65],[8,20,10.56],[9,21,26.73],[0,16,10.84],[5,18.5,16.2]],"id":40095374},{"atb":[[8.4,26.56],[8.8,16.41],[8.6,33.73],[1.8,0],[9,21.68],[8.2,34.5],[1.01,65109.35],[9.2,0]],"atl":[[9.4,15.87],[10.5,46.16],[1000,101.61],[9.8,22.01],[11,38.31],[10,24.36],[9.6,15.23],[11.5,50.61],[9.2,0]],"trd":[[9.4,205.38],[9.2,84.35]],"bdatb":[[1,8.8,16.41],[2,8.6,35.67],[3,8.4,26.56],[4,8.2,39.11],[5,8,47.69],[6,7.8,34.08],[7,7.6,45.76],[8,7.4,295.76],[9,7.2,23.52],[0,9,21.68]],"bdatl":[[0,9.4,15.87],[4,10.5,48.09],[2,9.8,31.66],[5,11,54.66],[6,11.5,58.06],[7,12,35.79],[8,12.5,43.68],[1,9.6,15.23],[3,10,24.36],[9,13,11.72]],"ltp":9.4,"tv":1999.83,"id":36276560},{"atb":[[13.5,4.15],[18.5,14.56]],"atl":[[24,62.21]],"trd":[[23,100.84]],"bdatb":[[4,19.5,18.48],[8,17.5,10.5],[9,17,41.14],[6,18.5,14.56],[3,20,26.26],[7,18,6.87]],"bdatl":[[0,24,62.21],[5,29,9.04],[8,34,7.46],[4,28,11.8]],"ltp":23,"tv":393.62,"id":37947503},{"atb":[[1.4,938.09],[1.08,0.08],[1.49,63.48],[1.47,105.73],[1.44,296.99],[1.42,157.68],[1.45,282.21],[1.46,284.87],[1.48,135.16]],"atl":[[1.51,80.2],[1.5,11.13],[1000,470.03],[1.57,43.7]],"trd":[[1.49,536.66]],"bdatb":[[8,1.41,497.46],[9,1.4,1131.56],[2,1.47,207.16],[3,1.46,382.69],[6,1.43,1428.14],[7,1.42,287.43],[0,1.49,63.48],[4,1.45,414.84],[5,1.44,299.13],[1,1.48,135.21]],"bdatl":[[0,1.5,11.13],[1,1.51,80.2],[4,1.54,238.76],[5,1.55,679.81],[6,1.56,148.88],[7,1.57,116.88],[8,1.58,224.27],[2,1.52,220.97],[3,1.53,169.59],[9,1.59,103.5]],"tv":7431.4,"id":39823721},{"atb":[[60,11.4],[70,3.33],[65,6.49],[17,15.62],[16,0]],"atl":[[500,0],[530,1]],"bdatb":[[8,50,22.55],[4,70,3.33],[5,65,6.49],[6,60,11.4],[9,48,10.6]],"bdatl":[[7,520,1.06],[8,530,1],[4,340,5.01]],"id":44331354}],"con":true,"tv":11584.33}]}
{"op":"mcm","clk":"ANp4AKBqANxq","pt":1650392768729,"mc":[{"id":"1.197931750","rc":[{"atl":[[9.6,9.04],[28,4.17],[10,30.7]],"bdatb":[[3,8.6,36.32],[6,8,54.67],[7,7.8,291.85],[8,7.6,21.38],[9,7.4,25.74]],"bdatl":[[0,9.6,26.1],[2,10,45.15],[3,10.5,70.92],[4,11,74.42],[5,11.5,54.42],[6,12,33.54],[7,12.5,36.35],[8,13,8.93],[9,13.5,20.04]],"id":42930960},{"atb":[[9,18.19]],"atl":[[9.4,14.84],[1000,101.61],[9.8,20.31]],"trd":[[9.4,210.84],[9,35.2]],"bdatb":[[0,9,18.19],[2,8.6,33.73],[3,8.4,26.57],[4,8.2,45.08],[5,8,41.56],[6,7.8,36.22],[7,7.6,43.57],[8,7.4,302.39],[9,7.2,16.71]],"bdatl":[[0,9.4,27.06],[1,9.6,39.86],[2,9.8,21.58],[3,10,26.03],[4,10.5,77.15],[5,11,43.91],[6,11.5,72.42],[7,12,32.32],[8,12.5,44.08],[9,13,11.06]],"tv":2006.98,"id":36276560},{"atl":[[24,68.42]],"bdatb":[[4,19.5,17.63],[8,17.5,13.3],[9,17,38.26]],"bdatl":[[2,26,14.02],[4,28,13.55],[5,29,5.78],[6,30,8.68],[7,32,8.42],[8,34,7.23],[9,36,4.04],[0,24,68.42]],"id":37947503},{"atb":[[1.48,126.16],[1.49,63.46],[1.5,988.95],[1.42,250.91],[1.35,70.34],[1.08,0],[1.31,1408.65]],"atl":[[1.5,0]],"trd":[[1.49,536.69],[1.5,305.02]],"bdatb":[[0,1.5,988.95],[1,1.49,63.46],[2,1.48,126.21],[3,1.47,200.59],[4,1.46,385.02],[5,1.45,419.48],[6,1.44,398.79],[7,1.43,1309.03],[8,1.42,502.77],[9,1.41,386.63]],"bdatl":[[0,1.51,80.2],[1,1.52,200.28],[2,1.53,190.15],[3,1.54,219.96],[4,1.55,696.86],[5,1.56,150.5],[6,1.57,96.84],[7,1.58,244.18],[8,1.59,103.5],[9,1.6,69.02]],"ltp":1.5,"tv":7453.68,"id":39823721},{"atl":[[550,1],[520,0]],"bdatb":[[8,50,22.21]],"bdatl":[[2,190,7.81],[4,340,5.16],[7,530,1.06],[8,540,1],[9,550,1]],"id":44331354},{"bdatb":[[4,13.5,28.11],[5,13,33.75],[6,12.5,42.32],[7,12,25.83],[8,11.5,55.29],[9,11,12.25]],"bdatl":[[2,17,36.92],[3,17.5,28.26],[4,18,27.4],[5,18.5,24.01],[7,19.5,21.58],[8,20,9.54],[9,21,33.28]],"id":40095374}],"con":true,"tv":11613.76}]}
{"op":"mcm","clk":"ALh6AMBrAIts","pt":1650392769732,"mc":[{"id":"1.197931750","rc":[{"atb":[[8.4,28.38],[8.8,34.48],[9,24.08],[1.01,67638.11],[9.2,0]],"atl":[[9.6,14.29],[9.8,27.44],[10.5,49.27],[10,30.7],[9.2,21.81],[9.4,8.96],[11.5,37.65]],"trd":[[9.2,149.95]],"bdatb":[[0,9,24.08],[1,8.8,34.48],[2,8.6,36.32],[3,8.4,28.38],[4,8.2,35.12],[5,8,61.66],[6,7.8,280.52],[7,7.6,37.75],[8,7.4,27.15],[9,7.2,9.78]],"bdatl":[[2,9.6,23.36],[0,9.2,21.81],[3,9.8,27.44],[4,10,45.15],[5,10.5,67.83],[7,11.5,37.81],[8,12,34.95],[1,9.4,8.96],[6,11,85.9],[9,12.5,31.94]],"ltp":9.2,"tv":961.04,"id":42930960},{"atb":[[10.5,231.38],[13,22.9],[15.5,16.69],[15,28.91],[14,30.58]],"atl":[[16.5,34.49],[23,47.48],[19.5,29.02],[16,11.47]],"bdatb":[[3,14,30.58],[4,13.5,35.11],[6,12.5,39.75],[7,12,24.38],[8,11.5,51.7],[9,11,15.92],[5,13,31.07],[0,15.5,16.69],[1,15,28.91]],"bdatl":[[5,18.5,23.21],[7,19.5,29.78],[9,21,32.18],[3,17.5,30.44],[2,17,30.16],[0,16,11.47],[1,16.5,34.49]],"id":40095374},{"atb":[[8.2,24.12],[1.01,64006.76],[6.4,47.2],[9,9.67],[7.6,24.36],[8.6,27.86]],"atl":[[10.5,44.15],[9.2,10.28],[9.4,11.62],[9.8,43.24],[9.6,23.41]],"trd":[[9,37.85]],"bdatb":[[2,8.6,27.86],[4,8.2,46.5],[5,8,39.69],[7,7.6,43.62],[8,7.4,303.79],[9,7.2,18.68],[0,9,9.67],[6,7.8,29.51],[3,8.4,26.56]],"bdatl":[[2,9.6,45.98],[3,9.8,43.24],[4,10,28.56],[5,10.5,69.05],[6,11,58.11],[7,11.5,59.96],[8,12,32.93],[9,12.5,44.72],[0,9.2,10.28],[1,9.4,11.62]],"ltp":9,"tv":2009.63,"id":36276560},{"atb":[[20,26.52],[2.06,0],[23,18.54],[18,6.58]],"bdatb":[[3,20,26.52],[6,18.5,19.67],[7,18,11.52],[9,17,37.25],[0,23,18.54],[4,19.5,17.63],[8,17.5,8.34]],"bdatl":[[6,30,8.19],[7,32,7.54],[9,36,4.33],[4,28,14.91],[2,26,9.61],[0,24,68.42],[8,34,6.87]],"id":37947503},{"atb":[[1.47,354.9],[1.5,1048.22],[1.48,149.43],[1.51,0],[1.45,287.23],[1.44,243.09],[1.49,67.85],[1.43,1195.96],[1.41,114.31],[1.33,121.82],[1.37,328.37]],"atl":[[1.51,0],[1.52,133.42],[1.53,95.67],[1000,504.99],[1.54,75.03],[1.55,682.3],[1.56,81.51]],"trd":[[1.51,1120.93],[1.5,312.96]],"bdatb":[[6,1.44,413.52],[7,1.43,1264.43],[9,1.41,291.61],[0,1.5,1048.22],[1,1.49,131.32],[2,1.48,221.13],[3,1.47,412.18],[4,1.46,474.75],[5,1.45,418.61],[8,1.42,370.23]],"bdatl":[[0,1.52,190.7],[1,1.53,190.07],[2,1.54,201.56],[3,1.55,711.14],[4,1.56,223.35],[5,1.57,44.89],[6,1.58,246.67],[7,1.59,76.94],[8,1.6,39.78],[9,1.61,188.62]],"ltp":1.5,"tv":7684.17,"id":39823721},{"atl":[[570,1],[110,5.11]],"bdatb":[[6,60,11.4],[9,48,12.57],[8,50,22.21]],"bdatl":[[4,340,5.27],[2,190,7.2],[0,110,5.11]],"id":44331354}],"con":true,"tv":11853.1}]}
{"op":"mcm","clk":"AP57ANVsAJxt","pt":1650392770733,"mc":[{"id":"1.197931750","rc":[{"atb":[[8.6,30.32],[8.8,35.63],[1.01,65109.06],[8.2,20.49],[6.4,9.95],[8.4,26.37],[7.6,10.91],[8,50.17],[9,0]],"atl":[[9.6,21.26],[9.4,12.17],[9.8,26.96],[9,8.19],[9.2,13.21],[26,0],[10.5,47.26],[1000,90.52],[10,21.07],[11,59.71],[28,0]],"trd":[[9,108.99]],"bdatb":[[1,8.6,30.32],[0,8.8,35.63],[3,8.2,32.02],[4,8,65.35],[5,7.8,283.5],[6,7.6,34.12],[7,7.4,21.42],[8,7.2,15.67],[9,7,188.29],[2,8.4,26.37]],"bdatl":[[0,9,8.19],[2,9.4,13.86],[3,9.6,24.33],[4,9.8,26.96],[5,10,31.44],[6,10.5,68.04],[7,11,67.44],[8,11.5,55.67],[9,12,36.19],[1,9.2,13.21]],"ltp":9,"tv":985.11,"id":42930960},{"atb":[[14,36.33],[15.5,14.38]],"trd":[[15.5,14.61]],"bdatb":[[3,14,37.4],[4,13.5,34],[5,13,30.65],[6,12.5,41.25],[8,11.5,50.77],[9,11,19.72],[0,15.5,14.38],[7,12,26.24]],"bdatl":[[4,18,30.11],[7,19.5,34.34],[9,21,29.81],[5,18.5,16.2],[1,16.5,34.49],[2,17,31.1],[3,17.5,25.47]],"ltp":15.5,"tv":628.97,"id":40095374},{"atb":[[8.8,17.33],[1.01,63482.36],[8,28.65],[8.4,25.9],[9,1.77],[8.6,34.05],[7.2,20.81],[6.4,37.94]],"atl":[[1000,100.28],[9.4,12.92],[12.5,17],[10,36.63],[9.6,24.65]],"trd":[[9,53.65]],"bdatb":[[1,8.8,17.33],[3,8.4,34.68],[4,8.2,37.51],[5,8,35.62],[8,7.4,304.58],[9,7.2,25.93],[6,7.8,29.51],[7,7.6,47.57],[0,9,1.77],[2,8.6,34.05]],"bdatl":[[2,9.6,31.4],[4,10,52.44],[5,10.5,59.75],[6,11,55.37],[7,11.5,69.87],[8,12,34.07],[9,12.5,20.66],[1,9.4,12.92]],"tv":2025.43,"id":36276560},{"atb":[[23,20.51],[8.2,0]],"bdatb":[[3,20,27.27],[4,19.5,20.64],[6,18.5,15.69],[7,18,11.52],[9,17,36.93],[0,23,20.51]],"bdatl":[[2,26,9.61],[3,27,9.36],[4,28,11.8],[5,29,7.46],[7,32,7.08],[8,34,9.92],[9,36,5.09],[1,25,20.56],[6,30,3.87]],"id":37947503},{"atb":[[1.45,233.33],[1.51,42.86],[1.49,82.64],[1.42,236.83],[1.46,249.07],[1.47,334.13],[1.4,897.42],[1.5,1053.66],[1.48,313.86],[1.43,1022.24],[1.41,164.31],[1.35,20.34]],"atl":[[1000,510.89],[1.52,157.44],[1.53,115.3],[1.57,47.08],[1.54,75.03]],"trd":[[1.51,1320.92],[1.52,705.36]],"bdatb":[[0,1.51,42.86],[1,1.5,1063.66],[2,1.49,136.05],[3,1.48,381.89],[4,1.47,411.93],[5,1.46,432.28],[6,1.45,410.39],[7,1.44,389.4],[8,1.43,1213.47],[9,1.42,252.77]],"bdatl":[[1,1.53,225.42],[2,1.54,169.22],[3,1.55,736.94],[4,1.56,128.59],[5,1.57,164.83],[6,1.58,173.28],[7,1.59,151.04],[8,1.6,52.58],[9,1.61,109.63],[0,1.52,157.44]],"ltp":1.51,"tv":7956.12,"id":39823721},{"atb":[[75,10.12],[1.05,1484.24],[100,0]],"atl":[[100,0.15],[590,1],[560,0],[540,0]],"trd":[[100,11.55]],"bdatb":[[0,95,4.07],[1,80,7],[2,75,12.36],[3,70,3.33],[4,65,6.49],[5,60,11.4],[6,55,7.3],[7,50,22.21],[8,48,11.04],[9,46,12.16]],"bdatl":[[0,110,5.26],[7,530,1.18],[8,550,1],[9,570,1],[2,190,7.2],[3,230,3.29],[4,340,5.01]],"tv":187.31,"id":44331354}],"con":true,"tv":12176.56}]}
{"op":"mcm","clk":"AL19AONtAKJu","pt":1650392771735,"mc":[{"id":"1.197931750","rc":[{"atb":[[8.8,23.92],[6.4,0.69],[8,52.92]],"atl":[[9.4,25.26],[10,29.55],[10.5,45.26],[9.2,15.21]],"bdatb":[[0,8.8,23.92],[1,8.6,30.32],[2,8.4,26.37],[3,8.2,25.1],[4,8,72.14],[5,7.8,286.56],[6,7.6,30.34],[7,7.4,28.45],[8,7.2,8.85],[9,7,193.17]],"bdatl":[[3,9.6,23.37],[5,10,41.26],[7,11,72.49],[8,11.5,45.65],[4,9.8,26.96],[9,12,30.38],[2,9.4,22.71],[6,10.5,73.17],[1,9.2,15.21]],"id":42930960},{"atb":[[14.5,22.71],[15.5,8.86]],"atl":[[16,15.64]],"trd":[[15.5,18.05]],"bdatb":[[1,15,28.91],[2,14.5,12.99],[3,14,37.4],[4,13.5,32.46],[5,13,31.97],[6,12.5,39.58],[7,12,28.23],[8,11.5,57.49],[9,11,13.78],[0,15.5,8.86]],"bdatl":[[4,18,28.52],[7,19.5,35.8],[9,21,25.66],[5,18.5,16.2],[2,17,30.16],[0,16,15.64]],"tv":632.41,"id":40095374},{"atb":[[8.8,19.33],[1.01,62940.27],[9,3.11],[6.8,52.65],[8,39.32]],"atl":[[9.2,4.7],[12,21.55],[9.4,21.37]],"trd":[[9,57.19]],"bdatb":[[0,8.8,17.33],[1,8.6,34.05],[2,8.4,34.68],[3,8.2,38.49],[4,8,42.08],[5,7.8,34.2],[6,7.6,42.26],[7,7.4,309.95],[9,7,55.72],[8,7.2,20.81]],"bdatl":[[2,9.6,26.76],[4,10,48.34],[6,11,51.09],[7,11.5,61.2],[8,12,27.1],[9,12.5,25.12],[0,9.2,4.11],[1,9.4,21.37],[5,10.5,72.06]],"tv":2028.97,"id":36276560},{"atb":[[23,26.99],[8.6,34.57]],"atl":[[1000,44.13]],"bdatb":[[0,23,26.99],[1,22,19.05],[2,21,11.63],[3,20,27.27],[4,19.5,18.79],[6,18.5,16.5],[7,18,13.12],[9,17,36.24]],"bdatl":[[5,29,6.48],[8,34,10.31],[6,30,3.87],[9,36,4],[3,27,8.77]],"id":37947503},{"atb":[[1.48,145.59],[1.51,13.41],[1.5,1055.66],[1.01,33008.8],[1.46,302.97],[1.49,86.36]],"atl":[[1.52,124.02],[1.53,127.31],[1.51,0],[1.54,76.94],[1000,504.99]],"trd":[[1.51,1523.19]],"bdatb":[[0,1.51,13.41],[1,1.5,1065.66],[2,1.49,125.76],[3,1.48,249.98],[4,1.47,462.29],[5,1.46,442.77],[6,1.45,363.07],[7,1.44,501.11],[8,1.43,1074.35],[9,1.42,283.8]],"bdatl":[[0,1.52,126.02],[1,1.53,217.07],[2,1.54,124.45],[3,1.55,824.14],[4,1.56,107.74],[5,1.57,142.27],[6,1.58,185.87],[7,1.59,107.24],[8,1.6,96.1],[9,1.61,65.96]],"tv":8158.39,"id":39823721},{"atb":[[65,10.41],[95,4.53],[85,0],[80,4.37],[1.01,106941.39]],"atl":[[1000,19.97],[110,5.21],[140,0],[130,0.03]],"bdatb":[[3,70,3.33],[4,65,10.41],[5,60,11.4],[6,55,6.64],[7,50,22.21],[8,48,11.35],[0,95,4.53],[1,80,4.37],[2,75,10.12]],"bdatl":[[7,530,1.11],[3,230,3.21],[0,110,5.36],[2,190,6.96]],"id":44331354}],"con":true,"tv":12385.81}]}
{"op":"mcm","clk":"AOZ+AN9uAKhv","pt":1650392772736,"mc":[{"id":"1.197931750","rc":[{"atb":[[1.01,65110.19],[8,55.67],[8.8,18.89],[7.4,24.23]],"atl":[[9.4,27.67],[9.6,42.32]],"bdatb":[[4,8,76.08],[5,7.8,282.58],[6,7.6,34.01],[7,7.4,33.73],[8,7.2,11.02],[9,7,187.97],[2,8.4,26.38],[3,8.2,29.12],[0,8.8,18.89]],"bdatl":[[3,9.6,53.85],[4,9.8,30.3],[5,10,29.55],[6,10.5,72.58],[7,11,70.07],[8,11.5,49.46],[9,12,38.47],[2,9.4,25.26]],"id":42930960},{"atb":[[14,30.58],[15.5,7.14]],"trd":[[15.5,21.49]],"bdatb":[[3,14,31.65],[6,12.5,41.22],[7,12,26.41],[8,11.5,59.12],[9,11,12.38],[2,14.5,22.72],[0,15.5,7.14],[5,13,33.67]],"bdatl":[[4,18,35.37],[7,19.5,29.48],[9,21,23.56],[2,17,30.16],[5,18.5,16.2]],"tv":635.85,"id":40095374},{"atb":[[1.41,2.85],[1.01,62409.07],[8.4,25.9],[8.8,17.33],[8.6,36.05],[9,0],[7.6,31.94]],"atl":[[15,79.57],[17.5,0],[9,0.01],[9.4,20.07],[1000,99.61],[9.2,7.69]],"bdatb":[[4,8,41.88],[5,7.8,31.58],[6,7.6,55.04],[9,7,50.52],[0,8.8,17.33],[1,8.6,36.05],[2,8.4,34.68],[3,8.2,41.19],[7,7.4,309.53],[8,7.2,20.81]],"bdatl":[[0,9.2,7.7],[1,9.4,20.07],[2,9.6,36.18],[3,9.8,46.59],[4,10,36.63],[5,10.5,71.15],[6,11,48.97],[7,11.5,59.67],[9,12.5,21.57],[8,12,35.56]],"id":36276560},{"atb":[[22,23.11],[23,26.14],[8.6,31.66]],"atl":[[1000,43.28]],"trd":[[23,102.53]],"bdatb":[[9,17,37.45],[1,22,23.11],[3,20,27.26],[4,19.5,20.49],[6,18.5,14.71],[0,23,26.14],[7,18,14.35]],"bdatl":[[5,29,9.59],[7,32,8.1],[8,34,6.87],[9,36,3.83],[3,27,8.77],[6,30,3.87]],"tv":395.31,"id":37947503},{"atb":[[1.51,95.03],[1.48,303.23],[1.47,347.74]],"atl":[[1.94,0],[2,100],[1.52,154.02],[1000,497.7],[1.53,125.3],[1.54,74.93]],"trd":[[1.51,1527.19]],"bdatb":[[5,1.46,514.73],[6,1.45,300.29],[7,1.44,540.86],[8,1.43,1054.35],[9,1.42,296.67],[0,1.51,95.03],[3,1.48,422.5],[4,1.47,484.4]],"bdatl":[[0,1.52,154.02],[1,1.53,197.64],[2,1.54,111.01],[8,1.6,91.21],[9,1.61,68.59],[3,1.55,850.53],[4,1.56,104.31],[5,1.57,135.41],[6,1.58,189.06],[7,1.59,129.36]],"tv":8162.39,"id":39823721},{"atb":[[65,7.27]],"atl":[[120,1.57],[510,1.06],[530,0]],"bdatb":[[6,55,7.24],[8,48,10.66],[4,65,7.27]],"bdatl":[[7,510,1.33],[3,230,3.21]],"id":44331354}],"con":true,"tv":12394.94}]}
{"op":"mcm","clk":"AKKAAQDibwCdcA==","pt":1650392773738,"mc":[{"id":"1.197931750","rc":[{"atb":[[3.3,0.01],[8.8,20.02],[1.01,65109.06]],"atl":[[1000,92.83]],"bdatb":[[2,8.4,29.55],[3,8.2,31.98],[4,8,72.33],[5,7.8,280.52],[6,7.6,35.45],[7,7.4,24.94],[9,7,199.97],[8,7.2,20.79],[0,8.8,20.02]],"bdatl":[[3,9.6,42.32],[4,9.8,33.89],[5,10,29.55],[6,10.5,79.68],[7,11,63.39],[8,11.5,56.57],[9,12,28.64],[2,9.4,27.67]],"id":42930960},{"atb":[[15.5,0]],"atl":[[18,27.11],[15.5,7.8],[16.5,42.53]],"trd":[[15.5,35.77]],"bdatb":[[0,15,28.91],[1,14.5,22.71],[2,14,31.65],[3,13.5,32.46],[4,13,33.67],[5,12.5,39.72],[6,12,27.53],[7,11.5,60.87],[8,11,10.55],[9,10.5,242.37]],"bdatl":[[0,15.5,7.8],[1,16,15.64],[2,16.5,42.53],[3,17,30.16],[4,17.5,25.47],[5,18,31.18],[6,18.5,16.2],[7,19,20.98],[8,19.5,33.73],[9,20,9.54]],"tv":650.13,"id":40095374},{"atb":[[1.01,61884.5],[8.4,25.9],[8.8,18.17],[1.41,0],[9,0]],"atl":[[10.5,44.15],[9.2,2.9],[12,19.25],[11.5,48.6],[11,36.3],[9.8,43.24],[9.6,23.47],[1000,98.96],[9,0]],"trd":[[9.2,92.59],[9,57.21]],"bdatb":[[1,8.6,44.62],[2,8.4,31.52],[3,8.2,35.43],[5,7.8,44.5],[6,7.6,41.78],[9,7,82.07],[0,8.8,18.17],[4,8,44.39],[7,7.4,309.53],[8,7.2,20.81]],"bdatl":[[0,9.2,2.9],[2,9.6,23.47],[3,9.8,50.18],[4,10,36.63],[5,10.5,78.57],[6,11,36.99],[7,11.5,67.86],[8,12,27.96],[9,12.5,22.08]],"ltp":9.2,"tv":2037.23,"id":36276560},{"atb":[[1.42,141.59],[1.48,327.28],[1.51,45.03]],"atl":[[1.52,167.25]],"trd":[[1.51,1627.19]],"bdatb":[[1,1.5,1073.45],[2,1.49,149.59],[3,1.48,391.11],[4,1.47,523.52],[5,1.46,570.57],[6,1.45,327.65],[7,1.44,402.47],[8,1.43,1168.37],[9,1.42,244.42],[0,1.51,45.03]],"bdatl":[[1,1.53,125.3],[2,1.54,189.36],[4,1.56,86.37],[5,1.57,151.7],[7,1.59,112.31],[8,1.6,72.46],[9,1.61,102.43],[3,1.55,845.64],[0,1.52,167.25],[6,1.58,195.38]],"tv":8262.39,"id":39823721},{"atb":[[95,4.52]],"atl":[[530,1],[110,7.21]],"trd":[[95,4.44]],"bdatb":[[5,60,11.85],[6,55,5.96],[7,50,23.15],[8,48,10.6],[9,46,13.19],[0,95,4.52]],"bdatl":[[7,510,1.06],[8,530,1],[9,550,1],[0,110,7.36],[3,230,3.21],[1,120,1.57]],"ltp":95,"tv":187.33,"id":44331354},{"bdatb":[[3,20,27.85],[4,19.5,20.04],[6,18.5,17.11],[7,18,11.73],[9,17,36.34]],"bdatl":[[5,29,5.78],[7,32,9.2],[8,34,6.87],[9,36,6.13],[3,27,8.77]],"id":37947503}],"con":true,"tv":12517.5}]}
{"op":"mcm","clk":"ANGBAQDlcACwcQ==","pt":1650392774741,"mc":[{"id":"1.197931750","rc":[{"atb":[[8.8,19.07],[3.3,0]],"atl":[[1000,90.52],[10,27.55],[9,8.18],[9.2,15.38]],"trd":[[8.8,46.11],[9,109.01]],"bdatb":[[3,8.2,25.08],[4,8,64.71],[1,8.6,39.47],[0,8.8,19.07],[2,8.4,31.64],[5,7.8,294.05],[6,7.6,17.6],[7,7.4,39.82],[8,7.2,4.76],[9,7,205.14]],"bdatl":[[4,9.8,39.08],[6,10.5,74.84],[5,10,27.55],[3,9.6,42.32],[7,11,61.39],[9,12,28.93],[8,11.5,55.58],[0,9,8.18],[1,9.2,15.38]],"ltp":8.8,"tv":987.05,"id":42930960},{"atb":[[14,27.61],[13.5,33.15],[14.5,20.65],[13,25.1],[1.01,71794.3]],"atl":[[15.5,10.01],[16,13.47],[17.5,24.82],[17,32.83],[18,25.1],[16.5,46.54]],"bdatb":[[3,13.5,39.59],[4,13,29.3],[6,12,34.26],[7,11.5,47.86],[1,14.5,21.69],[2,14,31.8],[5,12.5,41],[8,11,17.89],[9,10.5,234.19]],"bdatl":[[5,18,31.7],[8,19.5,31.13],[1,16,13.47],[3,17,32.83],[4,17.5,24.82],[2,16.5,46.54],[0,15.5,7.93]],"id":40095374},{"atb":[[8.2,25.51],[1.01,60332.71],[9,0],[8,42.32],[8.4,24.55],[8.6,33.49]],"atl":[[9.4,18.37],[9.6,23.47],[9.2,8.9],[1000,97.66],[9,8.74]],"trd":[[9,59.72]],"bdatb":[[3,8.2,36.74],[0,8.8,18.17],[1,8.6,42.05],[4,8,44.54],[7,7.4,309.53],[8,7.2,20.81],[2,8.4,30.43],[5,7.8,43.05],[6,7.6,38.62],[9,7,67.69]],"bdatl":[[1,9.2,8.9],[4,9.8,55.36],[6,10.5,73.65],[0,9,8.74],[5,10,36.63],[7,11,36.76],[8,11.5,67.42],[9,12,26.17],[2,9.4,20.41],[3,9.6,25.48]],"ltp":9,"tv":2039.74,"id":36276560},{"atb":[[1.47,361.35],[1.51,78.7],[1.42,91.37],[1.49,120.17],[1.46,290.97],[1.44,334],[1.5,1065.66],[1.48,329.75]],"atl":[[1000,500.76],[1.53,102.24],[1.52,153.2]],"trd":[[1.52,707]],"bdatb":[[0,1.51,88.63],[2,1.49,175.13],[3,1.48,449.97],[4,1.47,454.37],[6,1.45,355.28],[8,1.43,1046.08],[9,1.42,247.04],[1,1.5,1108.1],[7,1.44,588.35],[5,1.46,543.54]],"bdatl":[[9,1.61,94.01],[2,1.54,183.88],[3,1.55,850.53],[4,1.56,84.77],[5,1.57,153.84],[6,1.58,190.04],[7,1.59,98.83],[8,1.6,85.86],[1,1.53,102.24],[0,1.52,153.2]],"ltp":1.52,"tv":8264.03,"id":39823721},{"atb":[[80,4.38]],"atl":[[590,0],[120,0.26]],"bdatb":[[8,48,11.39],[3,70,4.38],[5,60,11.49],[7,50,23.1],[9,46,12.16],[1,80,4.38]],"bdatl":[[1,190,7.22],[2,230,3.21],[3,340,5.01],[4,350,2],[5,380,3],[6,510,1.06],[7,530,1],[8,550,1],[9,570,1]],"id":44331354},{"bdatb":[[6,18.5,16.59],[7,18,9.61],[1,22,23.79],[2,21,14.42],[3,20,26.77],[9,17,37.29],[4,19.5,19.9]],"bdatl":[[7,32,10.79],[9,36,4.72],[4,28,11.8]],"id":37947503}],"con":true,"tv":12523.59}]}
{"op":"mcm","clk":"APiCAQDdcQDOcg==","pt":1650392775743,"mc":[{"id":"1.197931750","rc":[{"atb":[[8.8,19.05],[8.4,26.37]],"atl":[[12,20.31],[11.5,35.64],[11,57.7],[10.5,43.25]],"trd":[[8.8,46.14]],"bdatb":[[0,8.8,19.05],[2,8.4,31.06],[3,8.2,20.49],[4,8,63.54],[5,7.8,292.5],[6,7.6,21.17],[7,7.4,27.76],[8,7.2,7.26],[9,7,224.28],[1,8.6,36.46]],"bdatl":[[6,10.5,75.67],[7,11,60.41],[8,11.5,50.58],[9,12,22.88],[4,9.8,33]],"tv":987.08,"id":42930960},{"atb":[[15,26.64],[14.5,10.93]],"atl":[[1000,70.32]],"bdatb":[[0,15,26.64],[3,13.5,36.06],[4,13,25.1],[5,12.5,42.98],[6,12,33.79],[9,10.5,243.05],[7,11.5,44.65],[8,11,19.54],[2,14,30.31],[1,14.5,11.97]],"bdatl":[[5,18,28.39],[8,19.5,34.18],[0,15.5,10.01]],"id":40095374},{"atb":[[8.6,30.93],[8,41.94]],"atl":[[9,5.87],[9.4,20.41],[9.6,25.48],[10,34.37]],"trd":[[9,65.46]],"bdatb":[[2,8.4,26.77],[3,8.2,25.51],[4,8,57.3],[5,7.8,33.81],[6,7.6,45.63],[7,7.4,293.94],[8,7.2,37.83],[1,8.6,39.49],[9,7,71.9]],"bdatl":[[6,10.5,76.57],[7,11,39.01],[8,11.5,63.54],[9,12,23.31],[0,9,5.87],[2,9.4,20.41],[3,9.6,25.48],[4,9.8,49.28],[5,10,34.37]],"tv":2045.48,"id":36276560},{"atb":[[1.51,39.21]],"atl":[[1.52,60.67],[1.53,102.24],[1000,497.7],[1.54,67.56]],"trd":[[1.52,907],[1.51,1706.17]],"bdatb":[[1,1.5,1104.74],[2,1.49,174.92],[3,1.48,445.55],[4,1.47,462.47],[6,1.45,337.47],[8,1.43,1079.94],[0,1.51,49.14],[7,1.44,572.66]],"bdatl":[[0,1.52,60.67],[1,1.53,102.24],[2,1.54,176.41],[3,1.55,831.94],[4,1.56,99.99],[5,1.57,129.7],[6,1.58,205.98],[7,1.59,57.78],[9,1.61,80.42],[8,1.6,137.76]],"ltp":1.52,"tv":8543.01,"id":39823721},{"atb":[[60,13.05],[85,3]],"bdatb":[[6,60,13.4],[8,50,22.59],[1,85,3],[2,80,4.38],[3,75,10.12],[4,70,4.08],[5,65,7.27],[7,55,5.96],[9,48,10.6]],"id":44331354},{"bdatb":[[4,19.5,18.58],[6,18.5,14.56],[7,18,8.94],[9,17,37.45],[2,21,13.43],[3,20,27.56]],"bdatl":[[7,32,8.93],[9,36,6.37]],"id":37947503}],"con":true,"tv":12808.34}]}
{"op":"mcm","clk":"AJKFAQD1cgDlcw==","pt":1650392777045,"mc":[{"id":"1.197931750","rc":[{"atb":[[1.01,63899.6],[8,51.46],[8.4,24.36],[7.8,282.55],[8.2,18.47],[8.6,33.81],[8.8,0]],"atl":[[1000,89.76],[9.2,17.99],[10,30.77],[9,9.18],[9.8,39.51],[12.5,17.11]],"trd":[[8.8,70.13]],"bdatb":[[1,8.4,30.66],[3,8,59.71],[4,7.8,297.79],[5,7.6,23.63],[6,7.4,25.23],[7,7.2,11.94],[0,8.6,38.03],[2,8.2,18.47],[8,7,213.69],[9,6.8,39.6]],"bdatl":[[5,10,30.77],[4,9.8,48.03],[6,10.5,68.29],[0,9,9.18],[7,11,66.27],[8,11.5,47.58],[9,12,20.35],[1,9.2,15.48]],"tv":1011.07,"id":42930960},{"atb":[[12.5,50.62],[15,22.25],[13.5,35.62],[10.5,226.12],[14.5,15.15]],"atl":[[1000,67.78],[17.5,27.43],[27,0.23]],"trd":[[15,8.77]],"bdatb":[[3,13.5,39.54],[6,12,37.29],[9,10.5,236.31],[5,12.5,46.25],[0,15,23.1],[2,14,30.2],[4,13,25.1],[8,11,19.54],[1,14.5,15.15]],"bdatl":[[4,17.5,27.43],[7,19,25.38],[5,18,25.1],[8,19.5,29.02]],"ltp":15,"tv":658.9,"id":40095374},{"atb":[[8,36.74],[1.01,60312.47],[8.8,12.09]],"atl":[[10,38.4],[9,4.03],[9.4,33.16],[11.5,36]],"trd":[[9,71.14]],"bdatb":[[2,8.4,25.33],[4,8,53.72],[5,7.8,35.8],[6,7.6,44.65],[7,7.4,294.94],[8,7.2,35.67],[1,8.6,40.53],[9,7,68.35],[3,8.2,25.51],[0,8.8,12.09]],"bdatl":[[5,10,46.75],[6,10.5,63.89],[7,11,49.93],[0,9,4.03],[4,9.8,43.24],[8,11.5,46.9],[9,12,20.25],[2,9.4,33.16]],"tv":2051.16,"id":36276560},{"atb":[[23,18.57],[20,27.43]],"trd":[[23,104.71]],"bdatb":[[3,20,29.75],[4,19.5,17.96],[7,18,8.19],[0,23,25.13],[2,21,13.35],[9,17,38.42],[6,18.5,14.56],[1,22,23.11]],"bdatl":[[8,34,9.32],[7,32,7.08],[9,36,3.57]],"tv":397.49,"id":37947503},{"atb":[[1.51,60.32],[1.45,276.09],[1.5,1063.66],[1.46,288.96],[1.48,330.52],[1.49,140.86]],"atl":[[1000,497.7],[1.52,58.67],[1.59,55.33],[1.53,120.86]],"trd":[[1.51,1706.18],[1.52,911]],"bdatb":[[6,1.45,461.8],[7,1.44,600.67],[8,1.43,1094.96],[9,1.42,130.78],[0,1.51,55.32],[1,1.5,1118.74],[5,1.46,524.47],[2,1.49,189.57],[3,1.48,476.15],[4,1.47,439.17]],"bdatl":[[0,1.52,58.67],[7,1.59,63.21],[3,1.55,801.24],[4,1.56,133.83],[5,1.57,125.43],[6,1.58,203.88],[8,1.6,75.39],[9,1.61,153.45],[2,1.54,136.68],[1,1.53,120.86]],"ltp":1.51,"tv":8547.02,"id":39823721},{"atb":[[95,3.25],[85,5.1],[1.01,103976.89],[80,4.23]],"atl":[[100,10]],"trd":[[95,7.22]],"bdatb":[[8,50,22.34],[0,95,4.64],[2,80,4.23],[4,70,3.85],[6,60,13.82]],"bdatl":[[0,110,7.21]],"tv":190.11,"id":44331354}],"con":true,"tv":12855.75}]}
{"op":"mcm","clk":"AM6GAQCBdAD8dA==","pt":1650392778046,"mc":[{"id":"1.197931750","rc":[{"atb":[[8.2,18.47],[1.01,63300.14],[8.4,23.01],[8.8,2.53],[6.8,748.26]],"atl":[[25,0],[9,6.95],[1000,88.98]],"trd":[[8.8,84.35]],"bdatb":[[0,8.8,2.53],[1,8.6,33.81],[2,8.4,23.01],[3,8.2,38.31],[4,8,52.59],[5,7.8,286.36],[6,7.6,24.6],[7,7.4,35.28],[8,7.2,50.84],[9,7,224.9]],"bdatl":[[0,9,6.95],[4,9.8,53.07],[7,11,67.69],[6,10.5,51.92],[8,11.5,43.76],[5,10,30.77],[9,12,30.83],[1,9.2,17.99]],"tv":1025.29,"id":42930960},{"atb":[[8,17.02],[10.5,702.31]],"atl":[[17,28.47],[16.5,49.05],[18.5,14.19],[18,23.09],[17.5,25.42]],"bdatb":[[1,14.5,15.15],[2,14,27.61],[3,13.5,40.25],[4,13,25.24],[5,12.5,60.27],[6,12,24.3],[8,11,25.43],[9,10.5,725.61],[0,15,22.25],[7,11.5,53.7]],"bdatl":[[5,18,24.33],[6,18.5,20.17],[8,19.5,29.02],[2,16.5,49.05],[3,17,28.47],[4,17.5,25.42],[7,19,20.98],[9,20,9.54]],"id":40095374},{"atb":[[8.6,30.93],[7.8,31.54],[8.2,23.49],[8.4,26.55],[6.6,780.31],[8.8,0],[1.01,59796.54]],"atl":[[9.2,15.42],[9,7.14],[1000,97.47]],"trd":[[8.8,44.78]],"bdatb":[[0,8.6,28.93],[1,8.4,26.55],[2,8.2,42.41],[3,8,40.46],[4,7.8,37.08],[5,7.6,39.95],[6,7.4,304.99],[7,7.2,93.55],[8,7,60.45],[9,6.8,76.7]],"bdatl":[[2,9.4,35.53],[4,9.8,54.53],[7,11,46.29],[0,9,7.14],[6,10.5,52.82],[8,11.5,44.13],[5,10,38.4],[9,12,29.77]],"ltp":8.8,"tv":2061.61,"id":36276560},{"atb":[[16.5,312.11]],"bdatb":[[1,22,23.11],[3,20,30.56],[4,19.5,17.63],[5,19,11.75],[7,18,11.12],[2,21,11.63],[8,17.5,8.86],[9,17,36.24],[0,23,18.57]],"bdatl":[[6,30,4.61],[8,34,10.12],[9,36,3.57],[7,32,7.08]],"id":37947503},{"atb":[[1.47,3719.95],[1.5,1053.66],[1.52,87.43],[1.51,60.26]],"atl":[[1.53,111.54],[1.52,0],[1.58,59.14],[1000,500.76]],"trd":[[1.52,1028.33],[1.51,1706.3]],"bdatb":[[0,1.52,87.43],[1,1.51,101.68],[2,1.5,1119.39],[3,1.49,195.86],[4,1.48,485.76],[5,1.47,3929.14],[6,1.46,579.2],[7,1.45,383.24],[8,1.44,492.78],[9,1.43,1077.53]],"bdatl":[[0,1.53,120.86],[1,1.54,67.56],[2,1.55,842.79],[3,1.56,122.73],[4,1.57,61.69],[5,1.58,145.1],[6,1.59,77.05],[7,1.6,131.53],[8,1.61,72.12],[9,1.62,193.78]],"ltp":1.52,"tv":8664.47,"id":39823721},{"atb":[[85,5],[1.01,97901.17],[38,131.58],[80,1.01],[75,12.22],[95,0],[70,5.37]],"atl":[[100,11.83],[95,0],[500,1],[510,0.06],[110,5.11],[130,0.12]],"trd":[[100,11.89],[95,11.7]],"bdatb":[[3,70,5.37],[5,60,13.05],[6,55,7.09],[7,50,22.21],[8,48,10.64],[1,80,1.01],[2,75,12.22],[4,65,7.27],[9,46,12.16],[0,85,3]],"bdatl":[[7,500,1.05],[0,100,11.83],[8,530,1.06],[1,110,5.11],[2,190,7.31],[3,230,3.21],[4,340,5.01],[5,350,2],[6,380,3],[9,550,1]],"ltp":100,"tv":194.93,"id":44331354}],"con":true,"tv":13002.69}]}
{"op":"mcm","clk":"APuHAQD9dACQdg==","pt":1650392779048,"mc":[{"id":"1.197931750","rc":[{"atb":[[8.4,25.02],[8.8,2.14],[8.2,21.87],[1.01,62704.53]],"atl":[[25,0],[1000,87.47],[9,9.25],[9.4,26.46]],"trd":[[8.8,90.81],[9,115.68]],"bdatb":[[0,8.8,2.14],[1,8.6,36.21],[2,8.4,33.9],[3,8.2,26.15],[4,8,51.46],[5,7.8,298.33],[6,7.6,18.45],[7,7.4,50.29],[8,7.2,21.88],[9,7,217.21]],"bdatl":[[4,9.8,41.56],[5,10,35.3],[6,10.5,55.03],[7,11,70.86],[0,9,9.25],[8,11.5,54.74],[9,12,22.21],[2,9.4,26.46]],"ltp":8.8,"tv":1038.42,"id":42930960},{"atb":[[13.5,37.62]],"atl":[[17.5,31.3],[15.5,6.14]],"trd":[[15.5,39.64]],"bdatb":[[1,14.5,16.57],[2,14,32.09],[3,13.5,40.41],[4,13,25.83],[5,12.5,60.1],[6,12,24.68],[7,11.5,58.56],[8,11,18.28],[9,10.5,714.05]],"bdatl":[[5,18,24.14],[7,19,21.05],[8,19.5,29.02],[9,20,11.81],[4,17.5,31.3],[0,15.5,6.14],[6,18.5,14.19]],"ltp":15.5,"tv":662.77,"id":40095374},{"atb":[[8.2,25.51],[8.8,2.29],[5.1,43.42],[8.6,34.1]],"atl":[[9.4,33.16],[10,44.68],[9.6,24.23],[9.2,10.9],[9,2.29],[1000,97.03],[10.5,42.14]],"trd":[[9,77.81]],"bdatb":[[0,8.8,2.29],[1,8.6,43.78],[2,8.4,27.98],[3,8.2,27.76],[4,8,51.55],[5,7.8,32.14],[6,7.6,39.48],[7,7.4,320],[8,7.2,76.39],[9,7,50.13]],"bdatl":[[0,9,2.29],[1,9.2,10.9],[2,9.4,31.12],[3,9.6,22.23],[4,9.8,45.16],[5,10,45.06],[6,10.5,53.92],[7,11,49.46],[8,11.5,55.1],[9,12,21.15]],"ltp":9,"tv":2068.28,"id":36276560},{"atb":[[8.6,31.66],[23,25.05]],"atl":[[25,18.55],[24,65.92]],"trd":[[24,6.6]],"bdatb":[[1,22,24.04],[3,20,30.56],[5,19,13.02],[7,18,7.1],[8,17.5,8.34],[0,23,25.05],[4,19.5,18.24],[6,18.5,14.56],[9,17,36.24]],"bdatl":[[7,32,7.67],[8,34,6.9],[9,36,3.57],[0,24,65.92],[6,30,3.87]],"ltp":24,"tv":399.99,"id":37947503},{"atb":[[1.51,119.45],[1.49,140.86],[1.33,0],[1.48,330.51],[1.01,32647.27],[1.47,3719.95],[1.5,1069.16],[1.46,290.97],[1.52,0],[1.44,164.22]],"atl":[[1.57,49.09],[1.53,92.48],[1.52,85.71],[1000,490.67],[1.54,162.45],[1.55,689.53],[1.6,132.75],[1.56,83.68]],"trd":[[1.51,1866.56],[1.52,1142.77]],"bdatb":[[0,1.51,138.79],[1,1.5,1118.91],[3,1.48,441.73],[6,1.45,413.54],[7,1.44,306.45],[8,1.43,1111.39],[2,1.49,396.38],[4,1.47,3865.15],[5,1.46,581.21],[9,1.42,102.98]],"bdatl":[[5,1.57,187.96],[0,1.52,85.71],[2,1.54,174.68],[3,1.55,877.13],[4,1.56,86.07],[6,1.58,69.64],[7,1.59,80.37],[8,1.6,209.6],[9,1.61,84.44],[1,1.53,80.48]],"ltp":1.51,"tv":8939.17,"id":39823721},{"atb":[[90,3.26],[85,7],[1.01,96539.14],[80,0.87],[75,12.38],[70,6.09]],"atl":[[1000,19.5],[100,9.34],[95,0],[110,2.58],[130,0.03]],"trd":[[100,12.49],[95,16.76]],"bdatb":[[0,85,7.73],[2,70,6.38],[4,60,14.1],[7,48,11.14],[5,55,5.96],[6,50,22.45],[1,75,13.25],[3,65,7.27],[8,46,12.16],[9,44,8.44]],"bdatl":[[0,100,9.34],[1,110,2.58],[2,190,7.22],[3,230,3.21],[4,340,5.01],[5,350,2],[6,380,3],[7,500,1],[8,530,1.06],[9,550,1]],"tv":200.59,"id":44331354}],"con":true,"tv":13309.22}]}
{"op":"mcm","clk":"AJ+JAQCZdgCndw==","pt":1650392780050,"mc":[{"id":"1.197931750","rc":[{"atb":[[8.8,0],[8.4,23.01],[8.2,19.85],[1.01,62121.84],[8.6,31.81]],"atl":[[9.2,20.05]],"trd":[[8.8,94.99]],"bdatb":[[0,8.6,31.81],[7,7.2,44.95],[8,7,211.51],[1,8.4,23.01],[2,8.2,26.74],[3,8,64.13],[4,7.8,286.85],[5,7.6,21.5],[6,7.4,42.62],[9,6.8,785.21]],"bdatl":[[4,9.8,48.54],[5,10,39.96],[7,11,64.2],[8,11.5,51.85],[9,12,23.36],[1,9.2,20.05],[6,10.5,53.98]],"tv":1042.6,"id":42930960},{"atb":[[15,22.08]],"atl":[[15.5,3.64],[21,11.12],[18.5,17.12]],"trd":[[15.5,44.64],[15,9.1]],"bdatb":[[8,11,16.98],[9,10.5,722.64],[2,14,27.61],[3,13.5,37.62],[4,13,31.51],[5,12.5,56.59],[6,12,27.1],[7,11.5,63.48],[1,14.5,15.15],[0,15,22.08]],"bdatl":[[5,18,23.09],[7,19,25.64],[9,20,14.14],[0,15.5,3.64],[6,18.5,17.12]],"ltp":15.5,"tv":668.1,"id":40095374},{"atb":[[8.8,6.81],[4.9,176.07],[8.6,32.1]],"atl":[[1000,96.39],[9.4,31.12],[9.6,22.23],[9.2,20.81],[9,0],[10,38.22]],"bdatb":[[0,8.8,10.06],[1,8.6,32.1],[2,8.4,33.27],[3,8.2,28.77],[4,8,46.07],[5,7.8,45.63],[6,7.6,32.5],[7,7.4,312.33],[8,7.2,92.29],[9,7,41.89]],"bdatl":[[1,9.4,31.12],[2,9.6,22.23],[3,9.8,43.24],[4,10,56.26],[5,10.5,51.02],[6,11,41.54],[7,11.5,47.8],[8,12,28.37],[9,12.5,21.28],[0,9.2,20.81]],"id":36276560},{"atl":[[25,20.08]],"bdatb":[[2,21,11.63],[3,20,27.43],[5,19,14.64],[6,18.5,15.77],[7,18,6.82],[8,17.5,12.61],[1,22,23.11],[4,19.5,17.63]],"bdatl":[[7,32,7.08],[8,34,9.47],[1,25,20.08]],"id":37947503},{"atb":[[1.48,323.42],[1.51,0],[1.35,135.2],[1.39,238.66],[1.44,73.31],[1.5,1053.66],[1.37,219.99]],"atl":[[1.53,91.19],[1.51,219.19],[1.54,160.44],[1.55,687.52],[1.52,0],[1000,493.73]],"trd":[[1.51,2105.46],[1.52,1195.53]],"bdatb":[[3,1.48,476.65],[4,1.47,3865.15],[5,1.46,553.91],[7,1.44,207.71],[8,1.43,1065.58],[1,1.5,1109.16],[2,1.49,264.68],[6,1.45,433.69],[9,1.42,128.13],[0,1.51,119.45]],"bdatl":[[1,1.54,162.45],[3,1.56,120.64],[4,1.57,135.48],[5,1.58,112.33],[6,1.59,78.38],[7,1.6,159.07],[8,1.61,169.67],[9,1.62,116.71],[0,1.53,103.19],[2,1.55,866.04]],"ltp":1.51,"tv":9230.83,"id":39823721},{"atb":[[85,2],[80,2.37],[1.01,95201.99],[75,12.9],[65,6.49]],"atl":[[95,0.83],[1000,19.2]],"bdatb":[[6,60,13.05],[7,55,5.96],[9,48,11.78],[4,70,6.09],[1,85,2],[2,80,2.37],[8,50,22.21],[3,75,12.9],[5,65,6.49],[0,90,3.26]],"bdatl":[[0,100,10.17]],"id":44331354}],"con":true,"tv":13610.39}]}
{"op":"mcm","clk":"AMGKAQCSdwC8eA==","pt":1650392781051,"mc":[{"id":"1.197931750","rc":[{"atb":[[1.01,61535.02],[8.8,2.75],[8.4,25.02],[8.2,21.85]],"atl":[[9.2,17.69],[1000,85.97],[9,10.37]],"trd":[[8.8,99.32]],"bdatb":[[0,8.8,2.75],[3,8.2,37.13],[4,8,62.59],[6,7.6,21.22],[7,7.4,42.48],[8,7.2,21.17],[9,7,194.97],[1,8.6,45.87],[2,8.4,25.33],[5,7.8,292.23]],"bdatl":[[1,9.2,17.69],[0,9,10.37],[9,12,25.41],[5,10,39.84],[6,10.5,62.52],[7,11,72.65],[8,11.5,51.64],[4,9.8,39.51]],"tv":1046.93,"id":42930960},{"atb":[[13,22.9],[1.01,69860.37],[14,30.58],[13.5,36.78],[14.5,17.21],[15.5,5.85],[15,24.16]],"atl":[[16,15.55],[17,28.9],[16.5,40.53],[1000,65.14],[18,25.1],[17.5,33.31],[15.5,0]],"trd":[[15.5,49.07]],"bdatb":[[5,13,33.1],[6,12.5,57.16],[3,14,30.77],[4,13.5,36.78],[8,11.5,51.47],[9,11,22.36],[1,15,30.38],[2,14.5,19.11],[7,12,30.59],[0,15.5,5.85]],"bdatl":[[1,16.5,40.53],[2,17,28.9],[7,19.5,30.26],[9,21,18.6],[0,16,15.55],[3,17.5,33.31],[4,18,25.1],[5,18.5,17.12],[6,19,20.98],[8,20,9.54]],"tv":672.53,"id":40095374},{"atb":[[8,47.41],[8.4,27.9],[8.2,24.12],[1.01,59287.9],[8.8,20.62]],"atl":[[9.2,13.14],[1000,95.75]],"bdatb":[[3,8.2,40.29],[4,8,57.63],[8,7.2,43.87],[9,7,33.81],[2,8.4,27.9],[5,7.8,51.28],[0,8.8,31.22],[1,8.6,35.61],[6,7.6,31.94],[7,7.4,328.17]],"bdatl":[[4,10,40.64],[5,10.5,67.75],[7,11.5,40.77],[8,12,34.19],[9,12.5,18.24],[0,9.2,13.14],[6,11,50.85]],"id":36276560},{"atb":[[8.6,34.36],[23,27.05]],"atl":[[25,18.55]],"bdatb":[[8,17.5,8.76],[9,17,41.05],[7,18,13.53],[1,22,27.35],[2,21,11.63],[3,20,28.81],[4,19.5,17.76],[5,19,11.66],[0,23,27.05],[6,18.5,14.56]],"bdatl":[[8,34,7.58],[9,36,5.42],[1,25,18.55]],"id":37947503},{"atb":[[1.46,239.08],[1.45,327.98],[1.47,3727.67],[1.43,1115.26],[1.01,31923.4],[1.48,165.8]],"atl":[[1000,483.5],[1.53,100.6],[1.55,682.3],[1.56,81.67],[1.51,81.82],[1.52,141.01],[1.54,164.46]],"trd":[[1.51,2460.2]],"bdatb":[[4,1.46,438.19],[5,1.45,590.51],[6,1.44,150.17],[8,1.42,213.3],[9,1.41,355.35],[1,1.49,245.21],[2,1.48,277.04],[7,1.43,1131.98],[3,1.47,3872.87],[0,1.5,1115.88]],"bdatl":[[2,1.53,116.42],[3,1.54,207.63],[4,1.55,815.92],[5,1.56,181.24],[6,1.57,84.02],[7,1.58,131.45],[8,1.59,96.18],[9,1.6,142.44],[0,1.51,81.82],[1,1.52,141.01]],"tv":9585.57,"id":39823721},{"atb":[[65,6.49],[80,2.23],[75,13.06]],"bdatb":[[4,70,7.42],[5,65,6.49],[6,60,13.51],[8,50,22.27],[9,48,10.6],[1,85,2],[2,80,2.23],[3,75,13.06]],"id":44331354}],"con":true,"tv":13973.89}]}
{"op":"mcm","clk":"APOLAQCaeADEeQ==","pt":1650392782053,"mc":[{"id":"1.197931750","rc":[{"atb":[[8.4,23.01],[7.8,26.55],[8.2,19.85],[1.01,60956.5],[8.6,31.8],[8.8,0],[6.8,1042.26]],"atl":[[10,28.51],[15,8.09],[12.5,97.11]],"trd":[[8.6,22.31]],"bdatb":[[0,8.6,31.8],[1,8.4,23.01],[2,8.2,38.22],[4,7.8,36.04],[8,7,165.03],[9,6.8,1052.89],[3,8,63.73],[5,7.6,10.91],[6,7.4,58.04],[7,7.2,12.79]],"bdatl":[[5,10,33.83],[6,10.5,64.1],[7,11,78.15],[8,11.5,50.76],[9,12,26.61],[2,9.4,26.46],[3,9.6,44.5]],"ltp":8.6,"tv":1046.95,"id":42930960},{"atb":[[15.5,4.78],[15,29.59]],"atl":[[18,30.81],[16.5,42.53],[23,4.48],[22,49.87]],"trd":[[15.5,52.51]],"bdatb":[[0,15.5,4.78],[4,13.5,41.02],[6,12.5,59.26],[7,12,29.64],[8,11.5,60.48],[9,11,16.28],[1,15,29.59],[3,14,37.25],[5,13,22.9],[2,14.5,17.21]],"bdatl":[[4,18,30.81],[1,16.5,42.53],[3,17.5,33.31],[6,19,22.08],[9,21,18.76],[7,19.5,29.02]],"tv":675.97,"id":40095374},{"atb":[[1.01,58803.17],[9,0],[6.8,346.65],[7.4,23.94]],"atl":[[1000,95.14],[9.6,23.47],[15,12.57],[13,82.67],[9.2,28.12]],"trd":[[9,80.05]],"bdatb":[[9,7,27.58],[0,8.8,20.62],[1,8.6,32.1],[2,8.4,39.01],[3,8.2,31.1],[4,8,59.69],[5,7.8,41.04],[6,7.6,31.94],[7,7.4,57.75],[8,7.2,28.84]],"bdatl":[[5,10.5,66.2],[6,11,53.87],[7,11.5,49.52],[8,12,19.87],[9,12.5,28.03],[2,9.6,23.47],[3,9.8,45.37],[0,9.2,28.12],[4,10,38.22]],"tv":2070.52,"id":36276560},{"atb":[[8.6,31.66],[15.5,22.39],[14.5,138.14]],"atl":[[25,20.04],[46,38],[44,3.09]],"bdatb":[[5,19,14.68],[8,17.5,13.95],[1,22,23.11],[3,20,32.1],[7,18,6.58],[9,17,36.67],[4,19.5,17.63]],"bdatl":[[1,25,20.04],[9,36,5.05],[3,27,8.77],[5,29,5.78],[7,32,7.73],[8,34,6.87]],"id":37947503},{"atb":[[1.48,167.81],[1.51,13.84],[1.38,96.73],[1.42,1499.37]],"atl":[[1000,473.24],[1.52,99.07],[1.53,112.6],[1.54,162.45],[1.56,83.84],[1.61,686.93],[1.51,0],[1.55,37.3]],"trd":[[1.51,2653.84]],"bdatb":[[4,1.47,3853.18],[5,1.46,418.01],[6,1.45,368.11],[7,1.44,374.12],[0,1.51,13.84],[3,1.48,335.87],[8,1.43,1213.56],[9,1.42,1499.98],[1,1.5,1115.88],[2,1.49,250.12]],"bdatl":[[2,1.54,210.56],[3,1.55,165.95],[4,1.56,201.75],[5,1.57,87.63],[6,1.58,125.12],[7,1.59,99.11],[8,1.6,180.05],[9,1.61,762.77],[0,1.52,99.07],[1,1.53,112.6]],"tv":9779.21,"id":39823721},{"atb":[[85,5],[38,184.58],[36,21.09]],"atl":[[1000,19.2],[100,6.89],[95,0],[380,0],[350,5]],"trd":[[100,17.39]],"bdatb":[[1,85,5],[9,48,11.8],[4,70,6.09],[7,55,7.65],[6,60,13.05],[8,50,22.21]],"bdatl":[[0,100,6.89],[3,230,3.21],[6,500,1],[5,350,5],[7,530,1.06],[8,550,1],[9,570,1]],"tv":205.49,"id":44331354}],"con":true,"tv":14178.13}]}
{"op":"mcm","clk":"AJCNAQCieQDMeg==","pt":1650392783054,"mc":[{"id":"1.197931750","rc":[{"atb":[[1.01,60959.34],[8.6,34.27]],"atl":[[9,11.84]],"trd":[[9,116.21],[8.6,26.31]],"bdatb":[[4,7.8,44.74],[5,7.6,14.91],[6,7.4,50.58],[7,7.2,12.85],[0,8.6,34.27],[3,8,51.46],[8,7,164.93],[9,6.8,1061.49]],"bdatl":[[0,9,11.84],[5,10,28.51],[6,10.5,63.91],[8,11.5,44.7],[9,12,28.58],[3,9.6,42.32],[7,11,85.07]],"ltp":9,"tv":1051.48,"id":42930960},{"atb":[[8,19.26]],"atl":[[16,15.25],[19.5,21.37],[19,29.07],[18.5,8.8],[17.5,27.43]],"trd":[[16,176.89]],"bdatb":[[3,14,30.58],[4,13.5,44.67],[7,12,26.23],[8,11.5,47.29],[9,11,27.83],[1,15,29.59],[5,13,26.29],[6,12.5,60.12]],"bdatl":[[0,16,15.25],[9,21,11.12],[3,17.5,27.43],[5,18.5,8.8],[6,19,29.07],[7,19.5,21.37]],"ltp":16,"tv":676.27,"id":40095374},{"atb":[[7.8,31.51],[8.2,22.1],[1.01,58312.55],[8.8,0],[8.6,33.64]],"atl":[[9.2,4.57],[9.6,22.23]],"trd":[[8.8,82.55],[8.6,58.56],[9.2,97.21]],"bdatb":[[6,7.4,58.17],[8,7,26.42],[9,6.8,358.48],[0,8.6,33.64],[1,8.4,40.59],[2,8.2,29.49],[3,8,59.09],[4,7.8,39.62],[5,7.6,31.94],[7,7.2,28.84]],"bdatl":[[0,9.4,31.12],[1,9.6,23.47],[2,9.8,43.24],[3,10,38.22],[4,10.5,62.8],[5,11,60.95],[6,11.5,47.67],[7,12,21.64],[8,12.5,26.33],[9,13,105.36]],"ltp":8.6,"tv":2114.59,"id":36276560},{"atb":[[23,25.05],[8.6,34.36]],"atl":[[24,65.72]],"trd":[[24,6.8]],"bdatb":[[3,20,27.43],[5,19,17.27],[1,22,23.11],[7,18,9.02],[8,17.5,8.34],[9,17,36.24]],"bdatl":[[0,24,65.72],[9,36,3.57],[7,32,7.08]],"tv":400.19,"id":37947503},{"atb":[[1.48,173.46],[1.51,91.58],[1.01,31405.52],[1.36,166.22],[1.46,290.97],[1.45,276.09],[1.47,3719.95]],"atl":[[1.52,84.79],[1.54,164.46],[1.51,0],[1.57,47.08]],"trd":[[1.51,2688.68]],"bdatb":[[0,1.5,1053.66],[1,1.49,304.62],[2,1.48,361.87],[3,1.47,3873.4],[4,1.46,581.06],[5,1.45,316.27],[6,1.44,298.27],[7,1.43,1194.51],[9,1.41,284.67],[8,1.42,1611.68]],"bdatl":[[2,1.54,164.46],[0,1.52,99.07],[1,1.53,112.6],[3,1.55,223.94],[4,1.56,87.34],[5,1.57,189.25],[6,1.58,62.76],[7,1.59,135.31],[8,1.6,176.89],[9,1.61,715.52]],"tv":9814.05,"id":39823721},{"atb":[[55,3.67],[90,2.41]],"atl":[[500,0],[480,1],[100,6.84]],"trd":[[100,17.44],[90,8.32]],"bdatb":[[7,55,3.67],[9,48,12.82],[4,70,6.09],[0,90,2.41]],"bdatl":[[0,100,6.84],[6,480,1]],"ltp":100,"tv":207.23,"id":44331354}],"con":true,"tv":14263.81}]}
{"op":"mcm","clk":"ALiOAQCfegDmew==","pt":1650392784055,"mc":[{"id":"1.197931750","rc":[{"atb":[[8.6,34.84],[1.01,60956.5]],"atl":[[25,4.68],[9,12.09]],"bdatb":[[3,8,64.72],[4,7.8,33.57],[1,8.4,27.03],[2,8.2,32.55],[0,8.6,34.84],[8,7,164.27],[9,6.8,1053.67],[7,7.2,12.79],[6,7.4,58.04],[5,7.6,10.91]],"bdatl":[[3,9.6,47.94],[4,9.8,41.56],[7,11,85.07],[8,11.5,40.36],[9,12,34.58],[5,10,36.07],[0,9,12.09],[6,10.5,49.66]],"id":42930960},{"atl":[[20,22.31]],"bdatb":[[2,14.5,19.54],[3,14,35.94],[8,11.5,63.91],[9,11,12.69],[4,13.5,38.94],[6,12.5,61.31],[7,12,26.57],[5,13,22.9]],"bdatl":[[6,19,31.91],[8,20,27.1]],"id":40095374},{"atb":[[8.8,11.34],[1.01,57833.89],[8.6,31.26],[8.2,24.12],[8.4,26.55],[8,36.74]],"atl":[[9.4,31.12],[10,28.97],[9.2,25.48],[9.6,22.24],[9,3.75],[9.8,43.24],[1000,94.34],[10.5,44.15]],"trd":[[9.2,98.15],[9,86.13]],"bdatb":[[0,8.8,6.13],[1,8.6,31.26],[3,8.2,27.67],[4,8,50],[5,7.8,38.54],[9,7,26.82],[7,7.4,57.75],[2,8.4,39.51],[6,7.6,31.94],[8,7.2,28.84]],"bdatl":[[1,9.2,25.48],[2,9.4,31.12],[3,9.6,22.24],[5,10,36.53],[0,9,3.75],[4,9.8,50.8],[6,10.5,50.56],[7,11,61.39],[8,11.5,42.9],[9,12,26.21]],"ltp":9.2,"tv":2121.61,"id":36276560},{"atb":[[23,24.88],[8.6,31.66]],"trd":[[23,105.05]],"bdatb":[[8,17.5,14.4],[9,17,37.67],[0,23,24.88],[2,21,13.23],[3,20,31.18],[5,19,13.2],[7,18,6.58]],"bdatl":[[7,32,8.76],[8,34,7.46]],"ltp":23,"tv":400.53,"id":37947503},{"atb":[[1.51,111.1],[1.01,31061.84],[1.48,323.43],[1.46,288.96]],"atl":[[1.52,90.72],[1000,459.88],[1.54,162.45],[1.53,105.19]],"trd":[[1.52,1198.61]],"bdatb":[[2,1.49,247.81],[3,1.48,493.82],[8,1.43,1150.6],[9,1.42,1577.67],[4,1.47,3814.97],[5,1.46,483.35],[7,1.44,383.48],[1,1.5,1126.2],[0,1.51,99.1],[6,1.45,308.29]],"bdatl":[[2,1.54,197.47],[3,1.55,195.82],[4,1.56,98.65],[5,1.57,171.43],[6,1.58,76.74],[7,1.59,124.48],[8,1.6,187.65],[9,1.61,701.79],[0,1.52,90.72],[1,1.53,105.19]],"ltp":1.52,"tv":9817.13,"id":39823721},{"atb":[[80,2.37],[75,12.9]],"atl":[[500,1],[100,6.6],[130,0.12]],"trd":[[100,17.69]],"bdatb":[[6,60,13.61],[7,55,5.04],[9,48,11.21],[2,80,2.37],[3,75,12.9]],"bdatl":[[7,500,1],[8,530,1.06],[9,550,1],[0,100,6.6],[2,190,7.31]],"tv":207.48,"id":44331354}],"con":true,"tv":14274.5}]}
{"op":"mcm","clk":"AOGPAQCmewD4fA==","pt":1650392785056,"mc":[{"id":"1.197931750","rc":[{"atl":[[25,0]],"bdatb":[[3,8,52.6],[4,7.8,47.12],[8,7,162.04],[9,6.8,1055.97],[1,8.4,23.01],[2,8.2,36.67]],"bdatl":[[4,9.8,47.26],[5,10,30.28],[8,11.5,46.42],[9,12,33.41],[3,9.6,50.04],[6,10.5,47.93]],"id":42930960},{"atb":[[14.5,19.39]],"atl":[[21,4.63],[17,40.76]],"bdatb":[[8,11.5,56.13],[9,11,20.82],[2,14.5,19.39],[7,12,27.29],[3,14,38.35]],"bdatl":[[6,19,36.97],[8,20,23.2],[2,17,40.76],[9,21,4.63]],"id":40095374},{"atb":[[8.8,17.05]],"atl":[[1000,93.93],[9.4,31.12],[9.2,15.98],[9.6,22.24],[9,0]],"trd":[[9.2,113.14],[9,93.63]],"bdatb":[[0,8.8,17.05],[5,7.8,39.66],[9,7,25.58]],"bdatl":[[4,10,38.33],[5,10.5,48.84],[0,9.2,15.98],[1,9.4,31.12],[2,9.6,22.24],[9,12.5,28.48],[3,9.8,50.8],[6,11,61.39],[7,11.5,42.9],[8,12,26.21]],"tv":2144.1,"id":36276560},{"atb":[[1.51,111.08]],"atl":[[1.53,110.9],[1000,462.94]],"trd":[[1.51,2688.72]],"bdatb":[[0,1.51,111.08],[3,1.48,455.57],[4,1.47,3865.22],[5,1.46,488.07],[7,1.44,334.47],[8,1.43,1262.7],[2,1.49,231.6],[9,1.42,1514.49]],"bdatl":[[4,1.56,160.29],[5,1.57,110.18],[9,1.61,712.12],[2,1.54,210.56],[3,1.55,182.81],[6,1.58,93.52],[7,1.59,107.8],[8,1.6,222.4],[1,1.53,110.9]],"ltp":1.51,"tv":9817.17,"id":39823721},{"atl":[[570,0],[550,0],[520,1],[530,0]],"bdatb":[[6,60,13.05],[7,55,5.65]],"bdatl":[[8,520,1.06],[9,1000,19.2]],"id":44331354},{"bdatb":[[8,17.5,8.86],[2,21,11.63],[3,20,32.87],[9,17,36.24]],"bdatl":[[8,34,9.1],[7,32,9.39]],"id":37947503}],"con":true,"tv":14297.03}]}
{"op":"mcm","clk":"AIKRAQCbfACWfg==","pt":1650392786057,"mc":[{"id":"1.197931750","rc":[{"atl":[[9.8,50.87],[9,9.62],[11,47.7]],"bdatb":[[0,8.6,38.76],[1,8.4,23.74],[2,8.2,40.16],[3,8,52.93],[4,7.8,29.86],[5,7.6,30.24],[6,7.4,37.16],[7,7.2,26.65],[9,6.8,1061.49],[8,7,164.93]],"bdatl":[[4,9.8,58.43],[5,10,29.15],[6,10.5,64.95],[7,11,71.7],[8,11.5,55.37],[9,12,23.51],[0,9,9.62],[2,9.4,26.46],[3,9.6,42.32]],"id":42930960},{"atb":[[9,12.36],[8,45.37],[8.8,25.9],[8.4,28.56],[8.6,33.65]],"atl":[[1000,92.76],[9.4,14.37],[9.8,42.38],[9.6,27.18],[9.2,3.66]],"bdatb":[[0,9,8.94],[1,8.8,30.42],[2,8.6,33.65],[3,8.4,34.12],[4,8.2,40.17],[5,8,48.6],[6,7.8,50.35],[7,7.6,31.94],[9,7.2,24.58],[8,7.4,58.17]],"bdatl":[[0,9.2,3.66],[1,9.4,18.37],[2,9.6,29.19],[3,9.8,44.4],[4,10,28.97],[5,10.5,64.81],[6,11,61.39],[7,11.5,42.9],[8,12,26.21],[9,12.5,28.48]],"id":36276560},{"atb":[[8.6,34.36]],"bdatb":[[1,22,24.64],[3,20,27.74],[4,19.5,17.63],[5,19,14.12],[7,18,13.23],[8,17.5,9.02],[9,17,36.24]],"bdatl":[[8,34,9.04],[9,36,3.75],[5,29,5.78],[7,32,7.08]],"id":37947503},{"atb":[[1.01,30399.52],[1.39,84.56],[1.48,163.32],[1.46,290.97],[1.35,20.34],[1.51,0],[1.26,101.15],[1.43,1022.24],[1.36,96.78]],"atl":[[1.52,117.32],[1.51,26.39],[1.53,112.91],[1.54,164.46],[1000,459.88]],"trd":[[1.51,2874.46]],"bdatb":[[0,1.5,1076.11],[2,1.48,192.39],[4,1.46,581.11],[5,1.45,321.04],[6,1.44,229.24],[7,1.43,1278.17],[8,1.42,1568.13],[9,1.41,173.48],[1,1.49,256.75],[3,1.47,3889.16]],"bdatl":[[0,1.51,26.39],[1,1.52,117.32],[3,1.54,216.71],[4,1.55,184.32],[5,1.56,202.15],[6,1.57,97.64],[7,1.58,75.24],[8,1.59,182.02],[9,1.6,156.8],[2,1.53,112.91]],"tv":10002.91,"id":39823721},{"atb":[[90,4.41],[65,9.89],[80,2.23],[75,13.06]],"atl":[[540,1],[100,6.71],[130,0.03]],"bdatb":[[4,70,6.57],[6,60,13.15],[8,50,22.21],[9,48,11.58],[5,65,13.29],[7,55,3.67],[2,80,2.23],[3,75,13.06]],"bdatl":[[9,540,1],[6,480,1],[0,100,6.71],[2,190,7.22]],"id":44331354},{"bdatb":[[1,15,31.84],[2,14.5,19.82],[3,14,30.58],[4,13.5,40.24],[5,13,32.12],[6,12.5,51.56],[7,12,26.9],[8,11.5,56.96],[9,11,19.82]],"bdatl":[[7,19.5,25.5],[9,21,15.07],[4,18,30.81],[6,19,29.07],[8,20,22.31]],"id":40095374}],"con":true,"tv":14482.77}]}
{"op":"mcm","clk":"ALmSAQCOfQCffw==","pt":1650392787060,"mc":[{"id":"1.197931750","rc":[{"atb":[[7.2,7.51],[8.6,30.37],[7.8,24.52],[8.4,25.02],[8.8,7.97],[8.2,20.49]],"atl":[[10.5,47.28],[9,6.5],[12,29.4],[1000,85.24],[25,4.84],[9.8,39.51]],"bdatb":[[8,7.2,24.66],[1,8.6,36.32],[5,7.8,27.83],[0,8.8,7.97],[2,8.4,25.02],[3,8.2,40.85],[4,8,51.46],[7,7.4,41.77],[6,7.6,30.24],[9,7,164.93]],"bdatl":[[6,10.5,73.41],[0,9,6.5],[7,11,61.91],[8,11.5,57.03],[9,12,35.17],[4,9.8,47.07],[5,10,33.36]],"id":42930960},{"atb":[[13,24.33]],"atl":[[19,31.83]],"bdatb":[[5,13,30.89],[3,14,31.1],[4,13.5,42.29],[6,12.5,50.86],[7,12,25.89],[8,11.5,57.74],[1,15,33],[2,14.5,19.39],[9,11,21.88]],"bdatl":[[6,19,35.52],[9,21,14.57],[7,19.5,24.06]],"id":40095374},{"atb":[[7.6,34.52],[1.01,57370.99],[8.8,24.61],[9,13.62]],"atl":[[9.4,14.72],[11,41.26],[9.2,14.44],[9.8,44.4],[9.6,29.19]],"bdatb":[[7,7.6,34.52],[3,8.4,29.43],[4,8.2,43.59],[5,8,45.76],[6,7.8,53.26],[0,9,13.62],[1,8.8,30.43]],"bdatl":[[6,11,58.23],[7,11.5,39.07],[8,12,32.28],[5,10.5,69.03],[9,12.5,24.17],[0,9.2,14.44],[4,10,35.98],[1,9.4,11.45],[2,9.6,29.19],[3,9.8,44.4]],"id":36276560},{"atb":[[19,12.61],[23,24.05]],"atl":[[29,8.53]],"trd":[[23,106.71]],"bdatb":[[5,19,16.52],[0,23,24.05],[3,20,27.8],[1,22,25.43],[7,18,11.32],[8,17.5,8.34]],"bdatl":[[5,29,8.53],[7,32,9.27],[8,34,6.98],[9,36,4.92]],"tv":402.19,"id":37947503},{"atb":[[1.5,1040.85],[1.42,1567.45],[1.49,133.36],[1.46,290.97],[1.47,3727.67]],"atl":[[1.6,143.63],[1000,453.33],[1.56,81.67],[1.52,109.85],[1.51,33.91]],"bdatb":[[8,1.42,1587.76],[0,1.5,1092.66],[1,1.49,242.62],[2,1.48,178.67],[7,1.43,1234.15],[3,1.47,3915.92],[4,1.46,582.11],[5,1.45,304.42],[6,1.44,252.93],[9,1.41,257.75]],"bdatl":[[9,1.6,186.91],[6,1.57,69.53],[7,1.58,106.8],[4,1.55,177.01],[5,1.56,196.31],[2,1.53,158.74],[3,1.54,198.53],[0,1.51,33.91],[1,1.52,109.85],[8,1.59,162.66]],"id":39823721},{"atb":[[80,2.37],[75,12.9]],"bdatb":[[7,55,3.81],[9,48,12.15],[4,70,6.82],[6,60,13.05],[2,80,2.37],[3,75,12.9],[0,90,4.41],[5,65,9.89]],"id":44331354}],"con":true,"tv":14484.43}]}
{"op":"mcm","clk":"APOTAQCqfgDOgAE=","pt":1650392788218,"mc":[{"id":"1.197931750","rc":[{"atb":[[8,62.42],[8.8,22.9],[8.4,25.02],[8.6,29.8]],"atl":[[10,33.87],[9.4,21.22],[9.2,12.99],[9.6,41.55],[1000,84.53],[9,0]],"trd":[[9,122.71]],"bdatb":[[1,8.8,24.85],[2,8.6,32.83],[3,8.4,29.12],[4,8.2,20.49],[5,8,79.32],[7,7.6,23.35],[8,7.4,32.04],[9,7.2,13.29],[6,7.8,36.47],[0,9,1.26]],"bdatl":[[4,10,33.87],[8,12,43.66],[9,12.5,99.6],[0,9.2,12.99],[1,9.4,21.22],[2,9.6,41.55],[5,10.5,61.57],[6,11,54.55],[7,11.5,50.55],[3,9.8,39.51]],"tv":1057.98,"id":42930960},{"atb":[[14,36.33],[13,28.5],[15.5,9.68],[12,19.75]],"atl":[[60,4.91],[16,6.99],[65,0]],"trd":[[16,180.55]],"bdatb":[[2,14.5,26.85],[3,14,31.89],[4,13.5,39.33],[5,13,29.43],[6,12.5,61.39],[7,12,20.34],[8,11.5,60.98],[9,11,15.33],[0,15.5,10.41],[1,15,29.59]],"bdatl":[[0,16,6.99],[6,19,31.83],[7,19.5,21.37],[9,21,4.63]],"tv":679.93,"id":40095374},{"atb":[[8.2,25.25],[7.6,39.76],[7.4,23.94],[8,43.52],[1.01,51778.69],[7.8,18.52],[6,22.57],[8.4,0],[8.8,0],[9,0],[8.6,0]],"atl":[[8.4,18.88],[8.8,23.45],[8.6,17.25],[1000,92.66],[11,31.26],[9,15.86],[9.2,32.36],[9.6,23.96],[10,32.38],[9.8,43.24],[9.4,21.89],[12.5,8.97],[12,11.21],[11.5,33.99],[10.5,42.14]],"trd":[[8.4,371.93],[8.8,137.59],[8.6,125.84],[9,123.11]],"bdatb":[[0,8.2,28.2],[1,8,56.08],[3,7.6,39.76],[4,7.4,70.11],[6,7,25.17],[7,6.8,359.77],[2,7.8,26.27],[5,7.2,28.84],[9,6.4,52.54],[8,6.6,791.51]],"bdatl":[[0,8.4,16.41],[6,9.6,36.28],[9,10.5,56.34],[1,8.6,5.41],[2,8.8,16.11],[3,9,10.36],[4,9.2,23.66],[5,9.4,21.89],[7,9.8,46.49],[8,10,39.92]],"ltp":8.4,"tv":2423.68,"id":36276560},{"atb":[[23,26.05],[8.6,31.66]],"atl":[[28,8.37],[26,6.17],[25,18.55],[24,63.28]],"trd":[[24,9.24]],"bdatb":[[2,21,16.41],[3,20,27.81],[4,19.5,18.57],[5,19,12.61],[6,18.5,16.42],[8,17.5,8.34],[9,17,36.95],[7,18,6.58],[0,23,26.55],[1,22,23.11]],"bdatl":[[1,25,18.55],[2,26,6.17],[0,24,63.28],[7,32,7.08],[8,34,6.87],[9,36,3.57]],"ltp":24,"tv":404.63,"id":37947503},{"atb":[[1.48,320.96],[1.47,3719.95],[1.51,149.27],[1.42,1541.63],[1.5,1079.08]],"atl":[[1.52,0],[1.53,112.6],[1.54,162.45],[1000,443.78],[1.56,83.84],[1.51,0]],"trd":[[1.51,2908.4],[1.52,1203.4]],"bdatb":[[0,1.51,228.43],[1,1.5,1097.67],[2,1.49,228.51],[3,1.48,359.39],[4,1.47,3937.94],[5,1.46,348.18],[6,1.45,397.29],[7,1.44,330.81],[8,1.43,1066.14],[9,1.42,1788.56]],"bdatl":[[2,1.54,221.86],[5,1.57,190.05],[6,1.58,181.63],[7,1.59,65.79],[8,1.6,152.7],[9,1.61,757.31],[1,1.53,105.19],[4,1.56,104.26],[0,1.52,7.47],[3,1.55,113.55]],"ltp":1.51,"tv":10041.64,"id":39823721},{"atl":[[100,6.02],[130,0.12],[510,1.06],[480,0]],"trd":[[100,18.27]],"bdatb":[[5,65,11.43],[6,60,13.18],[7,55,3.67],[8,50,22.58],[0,90,4.53],[1,85,5],[2,80,2.37],[3,75,12.9],[4,70,6.09],[9,48,10.6]],"bdatl":[[6,500,1],[7,510,1.06],[8,520,1],[0,100,6.13]],"tv":208.06,"id":44331354}],"con":true,"tv":14815.92}]}
{"op":"mcm","clk":"AJiVAQC9fwDdgQE=","pt":1650392789219,"mc":[{"id":"1.197931750","rc":[{"atb":[[9,4.23],[8.4,27.03],[8.6,31.8]],"atl":[[9.4,13.47],[1000,83.83]],"trd":[[9,122.82]],"bdatb":[[1,8.8,31.46],[2,8.6,37.94],[4,8.2,22.9],[5,8,90.83],[8,7.4,38.37],[9,7.2,11.15],[0,9,4.23],[3,8.4,27.03],[7,7.6,18.09],[6,7.8,24.52]],"bdatl":[[5,10.5,60.04],[6,11,60.91],[7,11.5,44.1],[9,12.5,101.13],[1,9.4,13.47],[4,10,45.63],[8,12,29.4]],"tv":1058.09,"id":42930960},{"atb":[[14.5,22.55]],"atl":[[16,4.71]],"bdatb":[[2,14.5,30.79],[3,14,36.94],[4,13.5,38.24],[5,13,36.05],[6,12.5,58.5],[7,12,22.29],[9,11,19.59],[8,11.5,49.4],[0,15.5,9.68]],"bdatl":[[9,21,10.44],[0,16,4.71],[7,19.5,25.45],[5,18.5,10.86],[8,20,22.31]],"id":40095374},{"atb":[[8.2,7.21],[6.2,116.62],[7.2,12.75],[7.6,39.76],[7.4,26.91],[8,35.29],[6.6,789.24]],"atl":[[9.2,35.56],[8.4,17.61],[8.6,22.88],[9.4,18.89],[8.8,21.56],[10,30.37],[9.6,35.59]],"trd":[[8.2,148.48]],"bdatb":[[0,8.2,14.35],[1,8,44.71],[2,7.8,25.29],[5,7.2,20.33],[7,6.8,352.74],[8,6.6,794.65],[9,6.4,52.54],[3,7.6,39.76],[4,7.4,60.3],[6,7,37.91]],"bdatl":[[5,9.4,28.41],[6,9.6,36.85],[7,9.8,43.24],[8,10,44.9],[9,10.5,51.41],[0,8.4,17.61],[1,8.6,22.88],[4,9.2,44.53],[3,9,20.09],[2,8.8,21.56]],"ltp":8.2,"tv":2426.8,"id":36276560},{"atb":[[8.6,35.27]],"atl":[[36,0],[28,13.52],[26,11.33]],"bdatb":[[2,21,15.21],[3,20,29.64],[4,19.5,18.07],[7,18,7.67],[9,17,42.02],[6,18.5,14.56],[0,23,26.05]],"bdatl":[[9,40,3.14],[2,26,11.33],[4,28,13.52],[8,34,9.21],[6,30,5.14]],"id":37947503},{"atb":[[1.47,3757.83],[1.48,320.96],[1.51,153.15],[1.49,311.44],[1.46,239.08],[1.52,165.52],[1.01,30074.84]],"atl":[[1.53,76.35],[1.57,47.83],[1.55,42.52],[1.58,89.93],[1000,437.78],[1.61,653.4],[1.54,160.44]],"trd":[[1.53,1438.53]],"bdatb":[[3,1.49,497.34],[5,1.47,3847.88],[0,1.52,165.52],[1,1.51,239.81],[2,1.5,1163.47],[4,1.48,417.42],[6,1.46,352],[7,1.45,398.55],[8,1.44,224.92],[9,1.43,1125.77]],"bdatl":[[0,1.53,83.76],[2,1.55,111.1],[3,1.56,104.6],[6,1.59,75.09],[7,1.6,177.81],[9,1.62,95.59],[5,1.58,132.66],[8,1.61,774.46],[4,1.57,206.33],[1,1.54,160.44]],"ltp":1.53,"tv":10045.9,"id":39823721},{"atl":[[500,0],[530,1]],"bdatb":[[5,65,11.05],[6,60,13.79],[8,50,22.39],[0,90,4.41]],"bdatl":[[6,510,1.06],[7,520,1],[8,530,1],[0,100,6.02],[2,190,7.31]],"id":44331354}],"con":true,"tv":14823.41}]}
{"op":"mcm","clk":"AK6WAQDQgAEA7IIB","pt":1650392790220,"mc":[{"id":"1.197931750","rc":[{"atb":[[9,4.8],[8.8,22.33]],"atl":[[9.2,14.35]],"bdatb":[[0,9,4.8],[1,8.8,30.89],[9,7.2,11.02],[2,8.6,36.62],[4,8.2,27.84],[5,8,85.77],[6,7.8,25.79],[7,7.6,18.27],[8,7.4,41.9]],"bdatl":[[6,11,50.66],[7,11.5,56.08],[9,12.5,98.59],[5,10.5,70.7],[0,9.2,14.35],[4,10,33.87]],"id":42930960},{"atb":[[8,34.79],[7.8,32.51],[1.01,51340.35],[8.2,0]],"atl":[[9.4,22.78],[8.8,24.09],[8.4,21.08],[9.2,24.78]],"trd":[[8.2,162.9]],"bdatb":[[0,8,44.21],[1,7.8,37.83],[2,7.6,41.76],[3,7.4,58.25],[4,7.2,21.91],[5,7,37.91],[6,6.8,352.74],[7,6.6,794.35],[8,6.4,60.14],[9,6.2,130.81]],"bdatl":[[3,9,20.66],[4,9.2,36.4],[5,9.4,32.32],[6,9.6,36.24],[2,8.8,24.09],[9,10.5,53.25],[8,10,45.48],[0,8.4,21.08]],"tv":2441.22,"id":36276560},{"atl":[[24,61.28]],"trd":[[24,13.24]],"bdatb":[[5,19,13.41],[7,18,9.08],[9,17,41.04],[3,20,29.5],[4,19.5,17.63]],"bdatl":[[8,34,8.14],[9,36,2.97],[0,24,61.28],[6,30,3.87]],"tv":408.63,"id":37947503},{"atb":[[1.51,177.25],[1.49,286.54],[1.52,161.73]],"trd":[[1.52,1214.98]],"bdatb":[[1,1.51,264.68],[3,1.49,506.17],[5,1.47,3864.79],[6,1.46,287.58],[7,1.45,423.77],[8,1.44,220.92],[9,1.43,1112.54],[0,1.52,161.73],[4,1.48,417.4]],"bdatl":[[5,1.58,238.55],[6,1.59,67.14],[8,1.61,741],[9,1.62,87.78],[4,1.57,129.56],[7,1.6,185.65],[2,1.55,42.52],[3,1.56,180.02],[0,1.53,76.35]],"ltp":1.52,"tv":10057.48,"id":39823721},{"atl":[[550,1]],"bdatb":[[9,48,10.92],[6,60,13.74],[8,50,22.21]],"id":44331354},{"bdatb":[[3,14,37.41],[4,13.5,40.12],[5,13,34.77],[6,12.5,59.04],[2,14.5,30.6],[7,12,20.57],[8,11.5,49.52],[9,11,21.97]],"bdatl":[[7,19.5,23.58],[9,21,13.99],[5,18.5,8.8]],"id":40095374}],"con":true,"tv":14853.41}]}
{"op":"mcm","clk":"ANCXAQDggQEAgYQB","pt":1650392791221,"mc":[{"id":"1.197931750","rc":[{"atb":[[9,6.8]],"atl":[[9.2,12.35],[9.4,11.33]],"bdatb":[[1,8.8,24.52],[3,8.4,33.7],[5,8,68.88],[7,7.6,21.33],[8,7.4,31.2],[2,8.6,31.8],[4,8.2,37.48],[6,7.8,32.96],[9,7.2,17.94],[0,9,6.8]],"bdatl":[[0,9.2,12.35],[7,11.5,38.07],[8,12,40.37],[1,9.4,11.33],[5,10.5,75.32],[6,11,60.42],[9,12.5,97.53]],"id":42930960},{"atb":[[7.8,21.52],[7.2,15.81],[8,36.79]],"atl":[[8.4,25.56]],"bdatb":[[0,8,39.21],[1,7.8,28.71],[3,7.4,47.55],[7,6.6,798.92],[8,6.4,50.16],[2,7.6,44.79],[6,6.8,357.7],[4,7.2,24.97]],"bdatl":[[5,9.4,34.23],[6,9.6,50.1],[7,9.8,47.06],[8,10,30.37],[9,10.5,57.34],[3,9,22.66],[4,9.2,34.44],[0,8.4,25.56]],"id":36276560},{"atl":[[24,60.81],[27,9.19]],"bdatb":[[2,21,12.54],[4,19.5,20.5],[5,19,14.63],[7,18,12.19],[9,17,36.56],[3,20,27.43]],"bdatl":[[0,24,60.81],[3,27,9.19],[8,34,8.66],[9,36,2.47]],"id":37947503},{"atb":[[1.52,285.73],[1.46,237.07]],"atl":[[1.53,12.61]],"trd":[[1.53,1450.55]],"bdatb":[[1,1.51,252.49],[3,1.49,554.24],[4,1.48,420.46],[8,1.44,168.04],[9,1.43,1165.8],[2,1.5,1150.06],[0,1.52,285.73],[5,1.47,3839.19],[6,1.46,311.34]],"bdatl":[[0,1.53,12.61],[5,1.58,196.18],[6,1.59,98.69],[7,1.6,186.13],[9,1.62,33.63],[8,1.61,752.18],[4,1.57,139.75]],"ltp":1.53,"tv":10069.5,"id":39823721},{"atl":[[570,1],[540,0],[520,0]],"bdatb":[[5,65,10.19],[8,50,23.33],[9,48,11.4],[6,60,13.05]],"bdatl":[[7,530,1],[8,550,1],[9,570,1]],"id":44331354},{"bdatb":[[2,14.5,23.88],[3,14,43.06],[6,12.5,54.32],[8,11.5,51.54],[9,11,14.77],[4,13.5,44.27],[5,13,28.91],[7,12,25.24]],"bdatl":[[9,21,13.99],[7,19.5,24.51]],"id":40095374}],"con":true,"tv":14865.43}]}
{"op":"mcm","clk":"APaYAQCFgwEAg4UB","pt":1650392792222,"mc":[{"id":"1.197931750","rc":[{"atb":[[9,6.7]],"trd":[[9,123.02]],"bdatb":[[4,8.2,32.1],[5,8,68.29],[7,7.6,21.99],[8,7.4,30.07],[6,7.8,35.15],[9,7.2,18.38],[2,8.6,37.92],[3,8.4,29.73],[1,8.8,22.33],[0,9,6.7]],"bdatl":[[3,9.8,39.51],[5,10.5,70],[6,11,67.3],[7,11.5,40.05],[8,12,36.82]],"tv":1058.29,"id":42930960},{"atb":[[13.5,34.78]],"bdatb":[[4,13.5,39],[5,13,32.11],[8,11.5,51.97],[9,11,14.01],[6,12.5,50.62],[7,12,26.66],[2,14.5,26.18],[3,14,40.68]],"bdatl":[[4,18,30.81],[7,19.5,24.46]],"id":40095374},{"atb":[[1.01,50858.71],[7.8,28.27],[8,35.54]],"atl":[[8.8,28.05],[9,14.6],[8.4,14.04],[8.6,24.89],[9.8,31.76],[8.2,6.42]],"trd":[[8.4,386.02]],"bdatb":[[3,7.4,40.95],[7,6.6,803.77],[8,6.4,45.65],[0,8,35.54],[1,7.8,37.93],[4,7.2,27.33],[5,7,37.43],[6,6.8,358.16]],"bdatl":[[1,8.4,14.04],[2,8.6,24.89],[3,8.8,26.76],[8,9.8,51.9],[0,8.2,6.42],[4,9,22.56],[5,9.2,34.54],[6,9.4,34.14],[7,9.6,35.59],[9,10,30.37]],"ltp":8.4,"tv":2455.31,"id":36276560},{"atl":[[25,19.89]],"bdatb":[[7,18,9.74],[9,17,39.01],[2,21,14.13],[4,19.5,18.79]],"bdatl":[[1,25,19.89],[5,29,8.53],[8,34,8.64],[9,36,2.49]],"id":37947503},{"atb":[[1.49,278.93],[1.5,1256.19],[1.48,320.96],[1.52,298.77],[1.53,0],[1.51,177.67],[1.45,110.09]],"atl":[[1.54,140.25],[1000,432.06],[1.55,53.51],[1.58,91.94],[1.56,81.67],[1.57,49.84],[1.53,0],[1.6,128.63]],"trd":[[1.54,629.49],[1.53,1475.77]],"bdatb":[[4,1.48,418.21],[5,1.47,3841.46],[6,1.46,309.05],[7,1.45,257.77],[8,1.44,170.36],[9,1.43,1163.46],[2,1.5,1319.6],[3,1.49,554.24],[0,1.52,333.41],[1,1.51,218.05]],"bdatl":[[0,1.54,141.25],[1,1.55,53.51],[2,1.56,177.85],[3,1.57,117.83],[4,1.58,248.97],[5,1.59,71.3],[8,1.62,60.52],[9,1.63,121.34],[6,1.6,171.69],[7,1.61,751.62]],"ltp":1.54,"tv":10096.72,"id":39823721},{"atb":[[90,2.65]],"trd":[[90,11.84]],"bdatb":[[0,90,2.65],[6,60,13.93],[8,50,22.67],[5,65,9.89]],"bdatl":[[6,510,1.06]],"ltp":90,"tv":211.58,"id":44331354}],"con":true,"tv":14910.46}]}
{"op":"mcm","clk":"AJGaAQCUhAEAgoYB","pt":1650392793223,"mc":[{"id":"1.197931750","rc":[{"atb":[[8,60.09]],"bdatb":[[3,8.4,40.78],[4,8.2,22.15],[5,8,62.89],[6,7.8,32.28],[7,7.6,27.68],[8,7.4,27.75],[9,7.2,14.76]],"bdatl":[[6,11,49.69],[7,11.5,46.41],[8,12,35.63],[9,12.5,110.91],[5,10.5,63.12]],"id":42930960},{"atl":[[16,10.51]],"bdatb":[[4,13.5,39.83],[5,13,28.5],[6,12.5,52.41],[7,12,24.79],[8,11.5,55.73],[9,11,10.08]],"bdatl":[[0,16,10.51],[9,21,9.68]],"id":40095374},{"atb":[[7.6,56.38],[8,20.78]],"atl":[[8.4,18.04],[8.8,25.52],[9.2,22.75]],"bdatb":[[2,7.6,63.55],[1,7.8,42.84],[3,7.4,28.75],[9,6.2,146.15],[0,8,20.78],[7,6.6,803.23],[8,6.4,46.73]],"bdatl":[[6,9.4,26.83],[7,9.6,42.74],[8,9.8,31.76],[9,10,35.9],[1,8.4,18.04],[3,8.8,25.52],[5,9.2,32.51],[4,9,21.3]],"id":36276560},{"atb":[[23,8.18]],"trd":[[23,111.25]],"bdatb":[[0,23,8.18],[4,19.5,20.75],[5,19,12.61],[6,18.5,17.51],[7,18,7.33],[9,17,37.56]],"ltp":23,"tv":413.17,"id":37947503},{"atb":[[1.51,163.75],[1.5,1270.91],[1.48,320.96],[1.52,205.29]],"atl":[[1.59,88.86],[1.54,118.05],[1.58,58.41]],"bdatb":[[1,1.51,240.25],[2,1.5,1305.53],[9,1.43,1174.69],[3,1.49,546.62],[4,1.48,425.85],[5,1.47,3900.24],[6,1.46,328.84],[7,1.45,165.37],[8,1.44,175.47],[0,1.52,239.93]],"bdatl":[[7,1.61,717.09],[8,1.62,103.18],[9,1.63,74.82],[4,1.58,115.68],[5,1.59,170.64],[6,1.6,258.06],[3,1.57,60.19],[0,1.54,118.05]],"id":39823721},{"atb":[[1.01,95203.63]],"atl":[[510,0.06],[480,1],[100,8.02]],"bdatb":[[8,50,23.43],[9,48,10.6]],"bdatl":[[6,480,1],[7,530,1.06],[0,100,8.02]],"id":44331354}],"con":true,"tv":14915}]}
{"op":"mcm","clk":"ANGbAQCHhQEAkocB","pt":1650392794224,"mc":[{"id":"1.197931750","rc":[{"atb":[[9,1.69],[8.8,29.45]],"atl":[[26,7.14],[1000,86.14],[9.4,14.21],[25,0]],"trd":[[9,123.22]],"bdatb":[[0,9,1.69],[7,7.6,28.72],[9,7.2,16.64],[1,8.8,35.43],[2,8.6,37.48],[3,8.4,27.03],[4,8.2,32.1],[5,8,68.84],[6,7.8,25.12],[8,7.4,34.38]],"bdatl":[[4,10,45.93],[5,10.5,47.85],[6,11,54.18],[9,12.5,105.2],[2,9.6,41.55],[7,11.5,56.57],[8,12,31.46],[1,9.4,14.21]],"tv":1058.49,"id":42930960},{"atb":[[15.5,7.78]],"atl":[[16,12.29]],"bdatb":[[0,15.5,7.78],[8,11.5,56.43],[1,15,33.1],[3,14,39.81],[4,13.5,35.68],[5,13,34.73],[6,12.5,56.38],[7,12,20.14],[9,11,10.08],[2,14.5,22.55]],"bdatl":[[6,19,32.63],[8,20,27.88],[3,17.5,27.43],[0,16,12.29],[9,21,4.63],[7,19.5,21.37]],"id":40095374},{"atb":[[7.8,34.04],[7,31.59],[8,24.72]],"atl":[[8.4,25.48],[8.6,32.66]],"bdatb":[[5,7,50.93],[8,6.4,48.68],[9,6.2,143.61],[1,7.8,47.05],[2,7.6,57.98],[3,7.4,38.13],[4,7.2,26.19],[6,6.8,357.7],[7,6.6,803.71],[0,8,24.72]],"bdatl":[[3,8.8,27.24],[4,9,26.31],[5,9.2,23.4],[6,9.4,22.78],[7,9.6,50.99],[9,10,46.79],[2,8.6,32.66],[1,8.4,25.48]],"id":36276560},{"atb":[[19.5,17.63],[22,20.16],[21,20.41],[1.01,89699],[20,21.5],[19,14.73],[23,0]],"atl":[[26,17.89],[24,64.2],[32,3.85],[28,11.51],[27,8.77],[25,21.9],[23,8.46]],"bdatb":[[1,21,22.91],[3,19.5,20.13],[4,19,14.73],[6,18,7.25],[7,17.5,13.08],[8,17,39.22],[0,22,20.16],[5,18.5,14.56],[2,20,21.5],[9,16.5,312.11]],"bdatl":[[6,29,9.05],[8,32,7.14],[9,34,7.04],[3,26,17.89],[1,24,64.2],[5,28,11.51],[4,27,8.77],[0,23,8.46],[7,30,3.87],[2,25,21.9]],"id":37947503},{"atb":[[1.51,258.74],[1.49,274.91],[1.54,0],[1.47,3709.29],[1.53,82.69],[1.46,74.68],[1.48,307.96],[1.5,1250.62],[1.44,123.31],[1.38,46.73]],"atl":[[1000,418.78],[1.56,86.78],[1.54,65.89],[1.57,47.83],[1.55,109.6],[1.58,60.42],[1.59,90.92]],"trd":[[1.54,909.49]],"bdatb":[[2,1.51,313.72],[4,1.49,529.53],[7,1.46,140.21],[8,1.45,246.71],[0,1.53,117.1],[1,1.52,245.41],[3,1.5,1297.3],[5,1.48,478.49],[6,1.47,3800.97],[9,1.44,154.51]],"bdatl":[[2,1.56,96.51],[3,1.57,164.15],[4,1.58,108.86],[5,1.59,209.76],[6,1.6,181.47],[7,1.61,663.71],[8,1.62,201.09],[9,1.63,81.89],[0,1.54,65.89],[1,1.55,109.6]],"tv":10376.72,"id":39823721},{"atb":[[80,2.23],[75,13.06],[1.01,95202.15]],"atl":[[100,8.13],[130,0.03],[500,1]],"bdatb":[[2,80,2.23],[3,75,13.06],[4,70,6.84],[7,55,4.56],[8,50,22.21],[6,60,13.05]],"bdatl":[[0,100,8.13],[2,190,7.22],[3,230,3.21],[7,500,1],[8,530,1.06],[9,550,1]],"id":44331354}],"con":true,"tv":15195.2}]}
{"op":"mcm","clk":"APucAQCGhgEAs4gB","pt":1650392795225,"mc":[{"id":"1.197931750","rc":[{"atb":[[8.8,28.83],[1.01,59843.29],[8.4,25.02],[9,0],[8.6,29.8],[8,62.13]],"atl":[[9.4,14.21],[1000,83.15],[10,33.87],[9.6,41.55],[9,0],[9.2,10.35]],"trd":[[8.8,99.34],[9,126.6],[9.2,153.95]],"bdatb":[[2,8.4,34.92],[3,8.2,27.26],[4,8,69.12],[5,7.8,37.1],[6,7.6,10.91],[9,7,173.06],[0,8.8,28.83],[1,8.6,29.8],[7,7.4,34.38],[8,7.2,20.77]],"bdatl":[[6,11,51.78],[7,11.5,54.82],[9,12.5,102.84],[1,9.4,14.21],[2,9.6,41.55],[4,10,33.87],[5,10.5,63.12],[8,12,30.41],[0,9.2,10.35],[3,9.8,39.51]],"ltp":8.8,"tv":1065.89,"id":42930960},{"atb":[[14.5,20.49],[14,28.42],[13,30.7],[1.01,68033.09],[15.5,0]],"atl":[[1000,64.52],[17.5,47.04],[15.5,0]],"trd":[[15.5,53.81]],"bdatb":[[2,14,34.36],[3,13.5,35.68],[4,13,34.04],[6,12,27.26],[7,11.5,50.21],[8,11,10.48],[9,10.5,718.13],[1,14.5,20.49],[0,15,29.59],[5,12.5,50.62]],"bdatl":[[3,17.5,47.04],[9,21,6.77],[0,16,12.29],[1,16.5,42.53],[2,17,40.76],[4,18,30.81],[5,18.5,8.8],[6,19,31.83],[7,19.5,21.37],[8,20,30.63]],"ltp":15.5,"tv":681.23,"id":40095374},{"atb":[[8,20.78]],"atl":[[8.2,10.14],[8.8,38.62],[11.5,25.36],[11,19.5],[9,23.75]],"bdatb":[[3,7.4,32.78],[4,7.2,23.87],[5,7,45.32],[1,7.8,34.04],[2,7.6,68.91],[6,6.8,357.7],[9,6.2,124.01],[0,8,20.78],[8,6.4,60.52]],"bdatl":[[0,8.2,10.14],[5,9.2,45.71],[7,9.6,40.03],[8,9.8,31.76],[9,10,40.42],[4,9,23.75],[3,8.8,38.62]],"id":36276560},{"atb":[[19.5,25.96],[20,30.13],[21,14.21],[22,16.1],[15.5,17.24],[19,18.88]],"atl":[[24,74.11]],"bdatb":[[3,19.5,25.96],[2,20,30.13],[4,19,23.26],[6,18,7.25],[7,17.5,10.82],[1,21,14.21],[0,22,16.1],[8,17,36.24]],"bdatl":[[9,34,11.76],[8,32,3.85],[1,24,74.11],[6,29,8.53]],"id":37947503},{"atb":[[1.53,138.02],[1.51,378.15],[1.48,359.85],[1.47,3657.4],[1.01,29485.65],[1.52,200.25],[1.49,276.92]],"atl":[[1.55,89.44],[1.74,107.18],[1.57,47.83],[1.6,28.63],[1.56,98.78],[1.54,0]],"bdatb":[[0,1.53,192.36],[1,1.52,208.19],[3,1.5,1317.64],[4,1.49,498.72],[5,1.48,555.98],[6,1.47,3790.02],[7,1.46,87.54],[8,1.45,263.09],[9,1.44,263.33],[2,1.51,445.32]],"bdatl":[[0,1.55,89.44],[3,1.58,115.77],[4,1.59,202.89],[6,1.61,694.5],[8,1.63,64.24],[9,1.64,96.38],[7,1.62,159.56],[5,1.6,36.18],[1,1.56,98.78],[2,1.57,153.74]],"id":39823721},{"atb":[[80,2.37],[1.01,95201.99],[75,12.9]],"atl":[[570,0],[550,0],[520,1],[530,0],[100,7.97]],"trd":[[100,18.6]],"bdatb":[[8,50,23.88],[6,60,13.05],[2,80,2.37],[3,75,12.9],[4,70,6.09],[7,55,3.67]],"bdatl":[[8,520,1.06],[9,1000,19.2],[0,100,7.97]],"ltp":100,"tv":211.91,"id":44331354}],"con":true,"tv":15204.23}]}
{"op":"mcm","clk":"AJ+eAQCAhwEAzokB","pt":1650392796227,"mc":[{"id":"1.197931750","rc":[{"atb":[[8.4,46.9]],"atl":[[9.2,12.35],[9.4,21.41],[13,81.47],[12.5,17.11]],"bdatb":[[3,8.2,32.92],[4,8,63.52],[6,7.6,32.06],[8,7.2,16.55],[9,7,161.01],[1,8.6,29.8],[2,8.4,53.87],[5,7.8,37.46],[7,7.4,35.91]],"bdatl":[[5,10.5,53.03],[6,11,57.1],[7,11.5,43.26],[9,12.5,18.81],[0,9.2,12.35],[3,9.8,39.51],[8,12,45.43],[1,9.4,21.41]],"id":42930960},{"atb":[[14,28.42],[13.5,34.78],[14.5,17.33],[10.5,512.31],[10,210.61]],"atl":[[15.5,0],[16,12.12],[17.5,27.43]],"trd":[[15.5,55.47],[16,180.89]],"bdatb":[[2,14,32.6],[3,13.5,38.86],[4,13,34.3],[6,12,29.09],[7,11.5,58.63],[9,10.5,526.74],[1,14.5,17.33],[8,11,10.08]],"bdatl":[[8,20,25.33],[9,21,9.56],[0,16,12.12],[5,18.5,8.8],[3,17.5,27.43]],"ltp":16,"tv":683.23,"id":40095374},{"atb":[[7.8,24.5],[8,7.55],[7.6,38.27],[6.8,52.65],[6,355.57]],"atl":[[1000,94.97],[8.2,7.14],[8.6,36.31],[13,5.67],[10.5,137.14]],"trd":[[8.2,168.9],[8,57.58]],"bdatb":[[0,8,7.55],[1,7.8,24.5],[3,7.4,33.24],[4,7.2,20.46],[5,7,65.79],[7,6.6,801],[8,6.4,56.12],[9,6.2,124.05],[2,7.6,53.22],[6,6.8,65.37]],"bdatl":[[5,9.2,40.56],[7,9.6,44.96],[0,8.2,7.14],[3,8.8,38.62],[2,8.6,36.31]],"ltp":8.2,"tv":2476.15,"id":36276560},{"atb":[[14.5,0.14],[16,152.54],[19.5,22.24]],"atl":[[23,7.46],[46,16],[44,26.09]],"trd":[[23,113.25]],"bdatb":[[7,17.5,11.02],[2,20,30.13],[4,19,21.96],[6,18,9.63],[3,19.5,22.24]],"bdatl":[[9,34,8.64],[7,30,3.87],[0,23,7.46]],"tv":415.17,"id":37947503},{"atb":[[1.53,107.05],[1.51,377.74],[1.52,198.25],[1.54,0],[1.48,318.65],[1.42,133.63],[1.43,2421.24]],"atl":[[1.55,103.51],[1.57,55.06],[1.56,174.91],[1000,413.48],[1.61,32.4],[1.65,606]],"trd":[[1.55,356.55],[1.53,1502.75],[1.54,942.51]],"bdatb":[[0,1.53,145.32],[2,1.51,430.91],[5,1.48,453.21],[6,1.47,3665.47],[7,1.46,221.07],[1,1.52,234.48],[3,1.5,1331.24],[4,1.49,544.61],[8,1.45,317.75],[9,1.44,208.29]],"bdatl":[[2,1.57,93.51],[3,1.58,181.37],[4,1.59,92.34],[9,1.64,51.81],[0,1.55,103.51],[5,1.6,147.46],[8,1.63,77.69],[1,1.56,174.91],[7,1.62,117.79],[6,1.61,73.5]],"ltp":1.55,"tv":10437.55,"id":39823721},{"atb":[[80,2.37],[75,12.9]],"atl":[[100,5.97],[540,1]],"bdatb":[[2,80,2.37],[3,75,12.9],[6,60,13.05],[8,50,23.38]],"bdatl":[[0,100,5.97],[9,540,1]],"id":44331354}],"con":true,"tv":15289.9}]}
{"op":"mcm","clk":"ALmfAQD+hwEA2IoB","pt":1650392797229,"mc":[{"id":"1.197931750","rc":[{"atb":[[8.2,30.87],[8.8,22.32],[8.4,48.91],[8.6,31.84],[9,3.08]],"atl":[[9.4,21.17],[9.2,0],[1000,82.13]],"trd":[[9.4,349.42],[9.2,164.3]],"bdatb":[[2,8.6,31.84],[3,8.4,60.16],[4,8.2,31.11],[5,8,68.73],[6,7.8,47.12],[7,7.6,23.62],[9,7.2,7.94],[1,8.8,22.32],[0,9,3.08],[8,7.4,34.38]],"bdatl":[[0,9.4,21.17],[1,9.6,41.55],[2,9.8,39.51],[3,10,33.87],[4,10.5,47.28],[5,11,47.7],[6,11.5,55.71],[7,12,29.4],[8,12.5,31.24],[9,13,81.47]],"ltp":9.4,"tv":1076.48,"id":42930960},{"atb":[[15,32.22]],"atl":[[16,6.03]],"trd":[[16,186.98]],"bdatb":[[1,14.5,17.33],[2,14,28.42],[3,13.5,40.27],[4,13,32.27],[5,12.5,55],[6,12,23.88],[7,11.5,64.06],[8,11,10.08],[9,10.5,519.75],[0,15,32.22]],"bdatl":[[0,16,6.03],[5,18.5,8.8],[8,20,22.31],[9,21,4.63]],"tv":689.32,"id":40095374},{"atb":[[7.4,38.58],[7.8,16.33],[7.6,36.85],[1.01,49562.23],[8,0]],"atl":[[8,0],[8.8,37.34],[8.2,11.52],[1000,92.06],[9,21.75],[8.6,25.13],[8.4,27.52],[9.6,26.48]],"trd":[[8,74.73]],"bdatb":[[1,7.6,36.85],[2,7.4,51.62],[3,7.2,23.15],[4,7,70.57],[6,6.6,789.71],[7,6.4,53.17],[8,6.2,139.12],[9,6,365.72],[0,7.8,16.33],[5,6.8,63.7]],"bdatl":[[0,8.2,11.52],[1,8.4,27.52],[2,8.6,25.13],[3,8.8,37.34],[4,9,21.75],[5,9.2,22.75],[6,9.4,25.73],[7,9.6,46.95],[8,9.8,32.44],[9,10,30.37]],"ltp":8,"tv":2493.3,"id":36276560},{"atb":[[21,11.63]],"atl":[[23,3.22]],"trd":[[23,117.49]],"bdatb":[[2,20,30.13],[3,19.5,22.24],[5,18.5,19.67],[7,17.5,8.45],[8,17,39.35],[4,19,18.88],[1,21,11.63],[6,18,6.58]],"bdatl":[[0,23,3.22],[7,30,3.87],[9,34,6.87]],"tv":419.41,"id":37947503},{"atb":[[1.52,151.86],[1.48,316.64],[1.53,0],[1.54,0]],"atl":[[1.61,62.14],[1.55,96.34],[1.57,47.83]],"trd":[[1.52,1219.34],[1.53,1778.62],[1.54,957.25]],"bdatb":[[0,1.52,214.03],[1,1.51,379.05],[2,1.5,1403.4],[3,1.49,459.6],[4,1.48,463.95],[5,1.47,3694.43],[6,1.46,208.74],[7,1.45,287.78],[8,1.44,238.46],[9,1.43,2652.47]],"bdatl":[[8,1.63,109.56],[9,1.64,49.06],[3,1.58,123.47],[4,1.59,151.82],[5,1.6,143.16],[6,1.61,109.28],[7,1.62,100.83],[0,1.55,96.34],[2,1.57,65.49]],"ltp":1.52,"tv":10732.52,"id":39823721},{"atl":[[100,5]],"trd":[[100,19.57]],"bdatb":[[5,65,9.89],[7,55,3.67],[9,48,12.15],[8,50,22.21]],"bdatl":[[0,100,5]],"tv":212.88,"id":44331354}],"con":true,"tv":15623.91}]}
{"op":"mcm","clk":"AO2gAQCLiQEA7osB","pt":1650392798232,"mc":[{"id":"1.197931750","rc":[{"atb":[[8.8,32.74],[8.2,21.82],[1.01,59843.29],[8.6,33.88],[9.2,3.12],[8.4,27.03],[9,12.54]],"atl":[[9.4,7.5],[9.8,50.29],[10,37.01],[1000,81.16],[9.6,48.42],[10.5,49.29]],"bdatb":[[2,8.8,34.62],[3,8.6,34.69],[5,8.2,30.18],[6,8,74.6],[7,7.8,39.16],[8,7.6,34.37],[1,9,18.16],[4,8.4,27.94],[9,7.4,24.23],[0,9.2,3.12]],"bdatl":[[0,9.4,7.5],[2,9.8,50.29],[3,10,37.01],[4,10.5,58.55],[5,11,54.1],[7,12,40.96],[8,12.5,28.11],[6,11.5,41.8],[1,9.6,48.42],[9,13,81.47]],"id":42930960},{"atb":[[1.01,66285.5],[13.5,34.78],[13,30.7],[15.5,11.89],[14,36.33],[14.5,19.33]],"atl":[[17.5,29.78],[17,38.33],[1000,62.72],[16,3.16],[18.5,10.81],[18,32.82],[16.5,40.53]],"trd":[[16,188.98]],"bdatb":[[1,15,36.69],[2,14.5,19.57],[3,14,36.58],[4,13.5,35.35],[5,13,30.7],[6,12.5,64.08],[8,11.5,66.42],[9,11,13.92],[0,15.5,11.89],[7,12,19.75]],"bdatl":[[8,20,25.74],[2,17,38.33],[3,17.5,29.78],[0,16,3.16],[1,16.5,40.53],[4,18,32.82],[5,18.5,10.81],[6,19,33.34],[7,19.5,21.37],[9,21,4.63]],"tv":691.32,"id":40095374},{"atb":[[7.8,12.46],[1.01,48716.94],[7.2,25.07]],"atl":[[1000,90.85],[8.2,10.14],[9,37.16],[8,8.39],[8.4,25.48],[8.6,43.1],[10.5,126.61]],"trd":[[8,75.87],[7.8,159.78]],"bdatb":[[0,7.8,12.46],[1,7.6,46.13],[2,7.4,40.09],[3,7.2,48.45],[9,6,358.13],[4,7,67.35],[5,6.8,58.86],[6,6.6,800.62],[8,6.2,131.34],[7,6.4,52.85]],"bdatl":[[0,8,8.39],[1,8.2,10.14],[5,9,40.05],[9,9.8,39.46],[2,8.4,25.48],[3,8.6,46.44],[4,8.8,50.16],[6,9.2,22.75],[7,9.4,24.56],[8,9.6,44.18]],"ltp":8,"tv":2514.45,"id":36276560},{"atb":[[8,0]],"atl":[[28,11.03],[26,17.11]],"bdatb":[[2,20,30.96],[4,19,19.06],[5,18.5,15.16],[7,17.5,8.34],[8,17,40.28],[1,21,14.03],[3,19.5,22.24],[6,18,6.58],[9,16.5,312.11]],"bdatl":[[8,32,5.99],[6,29,8.53],[7,30,4.82],[3,26,17.11],[5,28,11.03]],"id":37947503},{"atb":[[1.51,241.71],[1.5,1250.62],[1.53,109.55],[1.52,228.42],[1.54,0],[1.01,28919.03],[1.48,318.65]],"atl":[[1.55,108.62],[1000,405.62],[1.54,53.04],[1.57,47.83],[1.56,187.51],[1.6,62.16],[1.59,57.39]],"trd":[[1.53,1780.02],[1.54,1081.75]],"bdatb":[[1,1.52,241.54],[2,1.51,294.53],[3,1.5,1393.3],[4,1.49,515.23],[5,1.48,383.87],[6,1.47,3801.83],[7,1.46,327.92],[8,1.45,110.37],[9,1.44,417.1],[0,1.53,142.59]],"bdatl":[[1,1.55,108.62],[3,1.57,91.46],[4,1.58,115.54],[6,1.6,109.34],[7,1.61,166.89],[8,1.62,69.62],[9,1.63,54.48],[0,1.54,53.04],[2,1.56,205.91],[5,1.59,164.25]],"ltp":1.53,"tv":10858.42,"id":39823721},{"atb":[[80,2.23],[75,13.06]],"atl":[[100,5],[130,0.03],[510,1.06],[480,0]],"bdatb":[[2,80,2.23],[3,75,13.73],[5,65,10.14],[8,50,22.28],[9,48,10.68],[7,55,3.67],[6,60,13.05]],"bdatl":[[0,100,5],[2,190,7.22],[6,500,1],[7,510,1.06],[8,520,1]],"id":44331354}],"con":true,"tv":15772.96}]}
{"op":"mcm","clk":"AO+hAQCnigEA/YwB","pt":1650392799291,"mc":[{"id":"1.197931750","rc":[{"atb":[[7.8,31.87],[7,148.34],[8.2,32.19]],"bdatb":[[6,8,78.94],[7,7.8,51.06],[8,7.6,30.11],[1,9,16.2],[2,8.8,34.74],[5,8.2,37.77],[3,8.6,36.62]],"bdatl":[[8,12.5,28.58],[5,11,54.33],[6,11.5,41.58],[7,12,37.65]],"id":42930960},{"atb":[[14.5,24.21]],"bdatb":[[2,14.5,26.8],[6,12.5,65.03],[8,11.5,64.4],[9,11,16.31],[1,15,34.42]],"id":40095374},{"atb":[[7.6,31.63]],"atl":[[8.4,33.83],[8.6,24.88],[8,4.12],[9.8,29.74],[8.2,11.52],[10,28.36],[9,35.16],[9.6,24.47]],"trd":[[8,81.58]],"bdatb":[[3,7.2,50.1],[4,7,64.03],[5,6.8,62.74],[8,6.2,127.79],[9,6,358.69],[7,6.4,55.82],[1,7.6,40.91],[6,6.6,801.1]],"bdatl":[[2,8.4,33.83],[3,8.6,28.21],[0,8,4.12],[5,9,38.33],[7,9.4,24.29],[1,8.2,11.52],[8,9.6,42.17],[9,9.8,37.44]],"tv":2520.16,"id":36276560},{"atb":[[1.52,204.53],[1.51,245.04],[1.53,111.19],[1.5,1258.19]],"atl":[[1.55,116.28],[1.58,72.42],[1.59,55.33],[1.57,49.84],[1.56,189.52]],"bdatb":[[1,1.52,229.23],[2,1.51,282.76],[3,1.5,1447.66],[4,1.49,420.51],[5,1.48,439.53],[6,1.47,3759.21],[7,1.46,291.4],[8,1.45,198.18],[9,1.44,328.69],[0,1.53,132.74]],"bdatl":[[1,1.55,116.28],[4,1.58,127.54],[5,1.59,151.74],[2,1.56,207.92],[3,1.57,93.47],[6,1.6,119.73],[8,1.62,45.11],[9,1.63,78.84]],"id":39823721},{"atb":[[75,12.9],[80,2.37]],"atl":[[100,4.89],[130,0.12]],"bdatb":[[3,75,13.34],[6,60,13.35],[2,80,2.37],[5,65,9.89],[8,50,22.61]],"bdatl":[[0,100,4.89],[2,190,7.31]],"id":44331354},{"bdatb":[[1,21,13.2],[2,20,31.01],[8,17,38.94],[4,19,19.93]],"id":37947503}],"con":true,"tv":15778.67}]}
{"op":"mcm","clk":"ANijAQC4iwEA+o0B","pt":1650392800293,"mc":[{"id":"1.197931750","rc":[{"atb":[[9.2,4.15],[9,19.8],[8,60.09]],"atl":[[9.4,2],[9.6,40.1]],"trd":[[9.4,351.62]],"bdatb":[[0,9.2,7.4],[1,9,22.41],[4,8.4,27.31],[5,8.2,44.78],[6,8,80.57],[7,7.8,56.25],[8,7.6,33.48],[9,7.4,26.39],[2,8.8,34.36],[3,8.6,33.88]],"bdatl":[[1,9.6,40.1],[7,12,33.11],[8,12.5,21.47],[0,9.4,5.3],[4,10.5,49.29],[5,11,56.54],[6,11.5,47.93],[9,13,82.75]],"tv":1078.68,"id":42930960},{"atb":[[16,6.46],[13,28.5]],"atl":[[16,0],[17.5,27.77],[17,36.33],[20,9.54],[19.5,29.24],[19,23.74],[18,27.11],[18.5,16.36]],"trd":[[16,194.01]],"bdatb":[[4,13.5,34.95],[5,13,36.44],[6,12.5,63.72],[7,12,27.9],[8,11.5,52.69],[9,11,27.13],[1,15,35.54],[2,14.5,25.44],[3,14,36.33]],"bdatl":[[2,17,36.33],[3,17.5,27.77],[9,21,6.45],[0,16,1.87],[6,19,23.74],[8,20,9.54],[4,18,27.11],[7,19.5,29.24],[5,18.5,16.36]],"tv":696.35,"id":40095374},{"atb":[[7.8,15.46]],"atl":[[8.4,31.79],[8.2,8.52],[8.6,22.12],[8,0]],"trd":[[8,87.23]],"bdatb":[[3,7.4,52.85],[4,7.2,61.41],[5,7,69.3],[6,6.8,55],[7,6.6,821.5],[8,6.4,50.86],[9,6.2,129.25],[0,8,3.74],[1,7.8,15.47],[2,7.6,33.5]],"bdatl":[[0,8.2,8.52],[1,8.4,31.79],[2,8.6,22.12],[4,9,39.4],[5,9.2,38.64],[6,9.4,26.2],[7,9.6,31.42],[9,10,35.47],[3,8.8,37.34],[8,9.8,29.74]],"tv":2525.81,"id":36276560},{"atl":[[23,2.32]],"trd":[[23,118.39]],"bdatb":[[5,18.5,14.68],[7,17.5,14.24],[1,21,14],[2,20,31.02],[4,19,18.88],[8,17,36.24]],"bdatl":[[9,34,7.99],[0,23,2.32],[7,30,3.87],[8,32,3.85]],"tv":420.31,"id":37947503},{"atb":[[1.51,220.26],[1.5,1106.78],[1.52,186.23],[1.53,0],[1.34,361.63],[1.43,2384.91],[1.36,92.7]],"atl":[[1.55,335.6],[1.56,191.69],[1.54,68.55],[1.53,44.15],[1.59,88.86],[1.6,28.63]],"trd":[[1.53,1922.34],[1.54,1114.09]],"bdatb":[[0,1.52,219],[1,1.51,292.05],[2,1.5,1434.23],[3,1.49,404.58],[4,1.48,491.85],[5,1.47,3706.53],[7,1.45,196.71],[8,1.44,330.17],[9,1.43,2538.55],[6,1.46,291.4]],"bdatl":[[1,1.54,68.55],[2,1.55,349.4],[3,1.56,213.99],[4,1.57,87.44],[5,1.58,147.85],[6,1.59,165.08],[7,1.6,132.96],[8,1.61,120.41],[0,1.53,44.15],[9,1.62,45.11]],"ltp":1.53,"tv":11033.08,"id":39823721},{"atl":[[100,4.68],[550,1],[500,0],[530,1]],"trd":[[100,19.78]],"bdatb":[[2,80,2.75],[3,75,12.9],[4,70,6.37],[6,60,13.11],[7,55,3.93],[8,50,22.21],[9,48,10.6]],"bdatl":[[0,100,4.68],[6,510,1.06],[7,520,1],[8,530,1]],"tv":213.09,"id":44331354}],"con":true,"tv":15967.32}]}
{"op":"mcm","clk":"AIilAQCkjAEAgo8B","pt":1650392801294,"mc":[{"id":"1.197931750","rc":[{"atb":[[8.8,31.61],[9,29.01],[9.2,11.24],[1.01,63056.29],[9.4,0]],"atl":[[9.8,48.29],[10,46.14],[9.4,7.43],[1000,82.22],[9.6,17.15],[11,49.71],[10.5,51.3]],"trd":[[9.4,363.28]],"bdatb":[[0,9.2,11.24],[1,9,36.94],[2,8.8,35.36],[3,8.6,41.26],[5,8.2,48.53],[6,8,63.58],[8,7.6,13.62],[9,7.4,37.97],[4,8.4,27.03],[7,7.8,78.57]],"bdatl":[[0,9.4,7.43],[1,9.6,17.15],[2,9.8,46.27],[3,10,43.88],[4,10.5,51.3],[5,11,62.69],[6,11.5,43.97],[7,12,34.76],[8,12.5,23.53],[9,13,81.47]],"tv":1090.34,"id":42930960},{"atb":[[15,38.8],[14.5,17.93],[13.5,34.98],[1.01,70469.42],[14,35.51],[16,0],[15.5,12.54]],"atl":[[21,16.76],[18,21.86],[17,35.66],[1000,61.61],[22,54.63]],"trd":[[16,200.67]],"bdatb":[[1,15,42.71],[2,14.5,17.93],[3,14,36.32],[5,13,37.15],[6,12.5,52.33],[7,12,22.07],[8,11.5,76.33],[9,11,19.5],[4,13.5,38.84],[0,15.5,12.54]],"bdatl":[[8,21,21.69],[9,22,56.42],[7,20,9.54],[1,17,35.66],[3,18,21.86],[0,16.5,40.53],[2,17.5,27.77],[4,18.5,16.36],[5,19,23.74],[6,19.5,29.24]],"tv":703.01,"id":40095374},{"atb":[[7.8,18.3]],"atl":[[8.2,7.14],[8.4,26.83],[8.6,42.36],[1000,90.23]],"bdatb":[[0,7.8,27.25],[1,7.6,38.49],[2,7.4,53.78],[3,7.2,28.05],[4,7,90.57],[5,6.8,67.6],[6,6.6,793.49],[7,6.4,77.21],[8,6.2,129.03],[9,6,374.86]],"bdatl":[[0,8.2,7.14],[4,9,46.65],[5,9.2,32.64],[6,9.4,34.32],[7,9.6,24.47],[8,9.8,34.98],[9,10,31.2],[1,8.4,26.83],[3,8.8,37.34],[2,8.6,42.36]],"id":36276560},{"atb":[[1.5,1146.78],[1.52,199.23],[1.51,217.98],[1.43,2379.12],[1.49,340.97],[1.01,28505.22]],"atl":[[1.54,86.99],[1.55,331.93],[1.56,179.09],[1.53,79.73],[1.58,72.42],[1.81,0],[1.6,128.63],[1.74,7.18]],"trd":[[1.53,2042.34]],"bdatb":[[0,1.52,234.33],[1,1.51,221.41],[4,1.48,345.48],[5,1.47,3732.61],[6,1.46,299.54],[7,1.45,224.85],[8,1.44,381.83],[9,1.43,2414.92],[2,1.5,1297.02],[3,1.49,585.47]],"bdatl":[[1,1.54,86.99],[3,1.56,245.38],[4,1.57,74.89],[5,1.58,206.26],[6,1.59,106.68],[7,1.6,263.5],[8,1.61,105.79],[9,1.62,42.13],[2,1.55,331.93],[0,1.53,79.73]],"tv":11153.08,"id":39823721},{"atl":[[540,0],[520,0],[570,1]],"bdatb":[[4,70,6.85],[6,60,13.14],[7,55,3.67],[8,50,22.44],[9,48,10.6],[2,80,2.37]],"bdatl":[[7,530,1],[8,550,1],[9,570,1]],"id":44331354},{"bdatb":[[1,21,14.41],[2,20,30.13],[3,19.5,22.82],[4,19,21.63],[7,17.5,14.77],[9,16.5,313.41],[5,18.5,14.56]],"bdatl":[[9,34,9.91],[8,32,3.85]],"id":37947503}],"con":true,"tv":16105.64}]}
{"op":"mcm","clk":"AJamAQChjQEA/48B","pt":1650392802295,"mc":[{"id":"1.197931750","rc":[{"atb":[[9,4],[8.8,29.61],[8.2,34.21],[1.01,60997.19],[8.6,31.84],[9.2,0]],"atl":[[10.5,49.29],[9.6,24.58],[9.4,15.5],[9.8,53.49],[10,36.13],[9.2,42.52],[1000,79.91],[27,4.8],[26,0]],"trd":[[9.2,189.05]],"bdatb":[[6,7.8,76.04],[7,7.6,13.51],[9,7.2,25.52],[0,9,13.21],[4,8.2,49.47],[5,8,71.2],[1,8.8,29.61],[2,8.6,38.05],[3,8.4,29],[8,7.4,27.01]],"bdatl":[[1,9.4,15.5],[2,9.6,21.67],[3,9.8,53.49],[4,10,36.13],[6,11,54.79],[7,11.5,41.14],[9,12.5,26.33],[5,10.5,62.67],[0,9.2,42.52],[8,12,39.5]],"ltp":9.2,"tv":1115.09,"id":42930960},{"atb":[[15,40.98],[14.5,19.99],[16,0]],"atl":[[1000,61.08]],"bdatb":[[7,12,31.88],[8,11.5,52.62],[9,11,20.66],[3,14,44.45],[5,13,35.34],[0,15.5,12.54],[1,15,44.54],[2,14.5,21.13],[4,13.5,34.98],[6,12.5,59.19]],"bdatl":[[7,20,15.49],[8,21,16.78],[9,22,54.63]],"id":40095374},{"atb":[[7.8,15.3]],"atl":[[8.4,25.48],[8.2,8.52]],"bdatb":[[3,7.2,45.3],[4,7,44.68],[5,6.8,69.76],[6,6.6,813.43],[1,7.6,50.27],[2,7.4,65.09],[7,6.4,50.16],[8,6.2,143.62],[9,6,370.77],[0,7.8,22.14]],"bdatl":[[4,9,41.41],[6,9.4,24.82],[3,8.8,50.85],[8,9.8,32.32],[5,9.2,22.75],[7,9.6,41.12],[9,10,28.36],[0,8.2,8.52],[1,8.4,25.48]],"id":36276560},{"atb":[[1.53,110.35],[1.52,197.23],[1.48,266.76],[1.49,340.97],[1.5,1141.22],[1.51,232.54],[1.47,3709.29]],"atl":[[1000,390.15],[1.55,279.64],[1.54,126.62],[1.56,176.92],[1.57,49.84],[1.53,0],[1.59,57.39],[1.58,105.95]],"trd":[[1.53,2238.91],[1.54,1303.94],[1.55,423.11]],"bdatb":[[0,1.53,114.53],[1,1.52,243.21],[3,1.5,1309.82],[4,1.49,429.54],[5,1.48,344.28],[6,1.47,3840.76],[8,1.45,342.56],[9,1.44,183.3],[2,1.51,374.27],[7,1.46,291.4]],"bdatl":[[1,1.55,279.64],[0,1.54,126.62],[6,1.6,144.42],[7,1.61,198.09],[9,1.63,62.75],[2,1.56,176.92],[3,1.57,125.85],[4,1.58,153.44],[5,1.59,157.91],[8,1.62,58.76]],"ltp":1.53,"tv":11606.06,"id":39823721},{"atb":[[80,2.37],[75,12.9]],"atl":[[100,4.68],[130,0.12]],"bdatb":[[2,80,2.37],[3,75,12.9],[9,48,13.21],[1,85,5],[6,60,13.94],[7,55,3.97],[8,50,22.21],[4,70,6.09]],"bdatl":[[0,100,4.68],[2,190,7.31]],"id":44331354},{"bdatb":[[4,19,25.47],[7,17.5,13.42],[9,16.5,318.61],[0,22,16.1],[2,20,33.63],[8,17,36.24],[1,21,11.63],[3,19.5,22.24]],"bdatl":[[8,32,7.56],[7,30,3.87],[9,34,6.87]],"id":37947503}],"con":true,"tv":16583.37}]}
{"op":"mcm","clk":"AL2nAQCZjgEA/ZAB","pt":1650392803297,"mc":[{"id":"1.197931750","rc":[{"atb":[[8.8,32.11],[6.6,34.42],[7.8,24.52],[1.01,59961.33],[8.4,46.05],[8.6,29.8],[8,62.13],[9,0],[8.2,23.84]],"atl":[[9.8,39.55],[9.4,13.61],[9,1],[27,0],[9.6,28.9]],"bdatb":[[0,8.8,32.11],[4,8,82.26],[5,7.8,64.9],[7,7.4,26.34],[8,7.2,23.36],[2,8.4,52.32],[3,8.2,30.29],[1,8.6,36.01],[6,7.6,15.35],[9,7,164.43]],"bdatl":[[7,11,52.41],[8,11.5,45.34],[4,9.8,39.55],[2,9.4,13.61],[6,10.5,58.55],[9,12,37.65],[0,9,1],[1,9.2,42.52],[3,9.6,28.9],[5,10,36.13]],"id":42930960},{"atb":[[1.01,69672.61],[15,38.8],[14.5,17.93]],"bdatb":[[5,13,40.89],[6,12.5,57.02],[2,14.5,21.57],[3,14,39.3],[7,12,30.41],[8,11.5,53.96],[0,15.5,13.12],[1,15,41.76],[9,11,20.69]],"bdatl":[[8,21,21.39],[7,20,9.54]],"id":40095374},{"atb":[[7.8,12.46]],"atl":[[8.4,25.48],[8.2,12.93]],"bdatb":[[0,7.8,19.3],[3,7.2,42.83],[4,7,46.88],[5,6.8,76.68],[6,6.6,806.3],[2,7.4,71.17],[9,6,379.66],[8,6.2,135.08],[1,7.6,45.53],[7,6.4,51.94]],"bdatl":[[4,9,49.26],[6,9.4,29.96],[7,9.6,33.66],[8,9.8,29.74],[9,10,35.52],[1,8.4,25.48],[0,8.2,12.93],[3,8.8,37.34]],"id":36276560},{"atb":[[1.53,82.94],[1.48,316.64],[1.52,207.55],[1.47,3657.4],[1.51,221.42],[1.49,575.97],[1.5,1298.19],[1.01,27954.09]],"atl":[[1.75,100],[1.6,28.63],[1.59,90.92],[1.55,307.14],[1.58,72.42],[1.54,103.25],[1.57,57.07]],"trd":[[1.53,2278.91],[1.54,1307.94]],"bdatb":[[0,1.53,88.82],[2,1.51,363.15],[3,1.5,1436.85],[4,1.49,680.88],[5,1.48,393.74],[6,1.47,3803.29],[9,1.44,261.17],[1,1.52,271.4],[8,1.45,265.23]],"bdatl":[[5,1.59,146.41],[6,1.6,62.99],[7,1.61,187.19],[8,1.62,81.79],[3,1.57,118.98],[4,1.58,133.92],[9,1.63,76.32],[1,1.55,307.14],[0,1.54,103.25]],"ltp":1.53,"tv":11650.06,"id":39823721},{"bdatb":[[7,17.5,17.54],[9,16.5,316.97],[2,20,34.99],[4,19,21.67],[1,21,12.05]],"bdatl":[[8,32,3.85]],"id":37947503},{"bdatb":[[7,55,4.63],[9,48,11.71],[4,70,6.22],[6,60,13.79]],"id":44331354}],"con":true,"tv":16627.37}]}
{"op":"mcm","clk":"AO6oAQCUjwEAo5IB","pt":1650392804299,"mc":[{"id":"1.197931750","rc":[{"atb":[[8.8,23.22]],"atl":[[9,0],[1000,79.28],[9.4,20.75],[9.6,31.43],[9.8,42.89]],"trd":[[9,127.6]],"bdatb":[[1,8.6,35.47],[3,8.2,30.85],[4,8,81.69],[5,7.8,65.49],[6,7.6,14.74],[8,7.2,23.3],[9,7,165.89],[0,8.8,23.22]],"bdatl":[[0,9.2,43.01],[1,9.4,20.75],[2,9.6,31.43],[3,9.8,42.89],[4,10,36.13],[5,10.5,49.29],[6,11,58.55],[7,11.5,47.93],[8,12,34.51],[9,12.5,20.13]],"ltp":9,"tv":1116.09,"id":42930960},{"atl":[[16.5,39.99]],"trd":[[16.5,103.66]],"bdatb":[[0,15.5,12.82],[3,14,39.62],[5,13,40.53],[8,11.5,48.52],[9,11,20.24],[7,12,36]],"bdatl":[[0,16.5,40.25],[8,21,16.76]],"ltp":16.5,"tv":703.56,"id":40095374},{"atl":[[8.2,11.83]],"trd":[[8.2,170]],"bdatb":[[0,7.8,18.71],[1,7.6,46.13],[2,7.4,70.55],[4,7,37.95],[5,6.8,75.95],[6,6.6,807.85],[7,6.4,54.47],[3,7.2,52.15]],"bdatl":[[0,8.2,12.37],[9,10,34.49],[4,9,35.16],[6,9.4,43.46],[7,9.6,25.51],[8,9.8,33.23]],"ltp":8.2,"tv":2526.91,"id":36276560},{"atl":[[23,1.93]],"trd":[[23,118.78]],"bdatb":[[1,21,11.84],[4,19,21.91],[7,17.5,17.28]],"bdatl":[[0,23,2.12]],"tv":420.7,"id":37947503},{"atb":[[1.53,0],[1.5,1141.22],[1.48,318.65],[1.52,197.23],[1.51,224.76]],"atl":[[1.53,89.65],[1.57,49.84],[1.54,110.62],[1.56,180.27]],"trd":[[1.53,2453.62]],"bdatb":[[3,1.5,1479.58],[5,1.48,395.47],[0,1.53,2.88],[1,1.52,261.08],[4,1.49,635.84],[6,1.47,3803.57],[8,1.45,350.89],[9,1.44,174.92],[2,1.51,366.49]],"bdatl":[[3,1.57,129.3],[2,1.56,180.27],[5,1.59,97.16],[6,1.6,111.93],[7,1.61,138.55],[8,1.62,130.12]],"tv":11824.77,"id":39823721},{"atl":[[100,4.59]],"trd":[[100,19.87]],"bdatb":[[4,70,6.15],[9,48,11.8]],"bdatl":[[0,100,4.63]],"tv":213.18,"id":44331354}],"con":true,"tv":16805.21}]}
{"op":"mcm","clk":"AKCqAQD6jwEAvpMB","pt":1650392805300,"mc":[{"id":"1.197931750","rc":[{"atb":[[8.2,23.84],[8.4,46.05],[8.6,29.8],[8.8,26.62]],"atl":[[11,47.7],[9.2,44.56],[26,4.37],[9.4,19.54],[9.8,44.05]],"bdatb":[[3,8.2,44.36],[4,8,67.84],[7,7.4,34.47],[8,7.2,12.83],[9,7,183.04],[5,7.8,69.23],[6,7.6,12.96],[1,8.6,34.96],[2,8.4,52.32],[0,8.8,26.62]],"bdatl":[[0,9.2,44.56],[6,11,52.66],[7,11.5,35.64],[8,12,52.23],[9,12.5,19.3],[5,10.5,67.8],[1,9.4,19.54],[3,9.8,44.05]],"id":42930960},{"atb":[[14.5,17.93],[15,38.8]],"bdatb":[[6,12.5,58.53],[8,11.5,57.63],[3,14,47.53],[5,13,32.01],[9,11,10.84],[1,15,41.76],[2,14.5,21.56],[4,13.5,34.98],[7,12,35.05],[0,15.5,12.54]],"bdatl":[[8,21,27.42],[0,16.5,39.99]],"id":40095374},{"atb":[[7.6,42.95],[7.8,28.69]],"bdatb":[[2,7.4,58.13],[4,7,54.1],[9,6,372.56],[1,7.6,72.02],[5,6.8,58.29],[6,6.6,826.05],[0,7.8,34.38],[3,7.2,50.58],[7,6.4,50.16],[8,6.2,135.08]],"bdatl":[[6,9.4,23.23],[7,9.6,25.56],[8,9.8,29.74],[9,10,38.89],[4,9,56.75],[5,9.2,27.09],[0,8.2,11.83]],"id":36276560},{"atb":[[21,27.32]],"atl":[[28,13.04],[26,14.98],[25,19.89]],"bdatb":[[9,16.5,318.11],[4,19,27.74],[7,17.5,10.95],[2,20,34.99],[5,18.5,14.56],[0,22,16.1],[1,21,27.32]],"bdatl":[[2,25,19.89],[3,26,14.98],[5,28,13.04],[0,23,1.93]],"id":37947503},{"atb":[[1.53,162.67],[1.49,575.97],[1.5,1290.62],[1.51,235.89],[1.01,27432.73],[1.52,180.23]],"atl":[[1000,380.42],[1.54,172.29],[1.55,313.45],[1.56,180.27],[1.53,0]],"trd":[[1.53,2618.46],[1.54,1493.12],[1.52,1253.34]],"bdatb":[[3,1.5,1479],[4,1.49,630.84],[8,1.45,363.86],[9,1.44,161.86],[0,1.53,162.67],[1,1.52,244.07],[2,1.51,377.61],[5,1.48,395.76],[6,1.47,3803.28],[7,1.46,291.4]],"bdatl":[[0,1.54,172.29],[6,1.6,188.82],[7,1.61,99.21],[8,1.62,169.45],[9,1.63,87.92],[1,1.55,313.45],[2,1.56,180.27],[3,1.57,173.64],[4,1.58,91.05],[5,1.59,97.49]],"ltp":1.54,"tv":12208.79,"id":39823721},{"atb":[[70,3.19],[80,6.07]],"bdatb":[[9,48,14.11],[6,60,13.79],[7,55,4.63],[1,85,5],[4,70,3.19],[2,80,6.07]],"bdatl":[[0,100,4.59]],"id":44331354}],"con":true,"tv":17189.23}]}
{"op":"mcm","clk":"ANmrAQD9kAEAy5QB","pt":1650392806301,"mc":[{"id":"1.197931750","rc":[{"atb":[[9,11.77],[8.2,34.21],[8.8,16.83],[8.4,48.05],[8.6,31.84]],"atl":[[9.2,34.12],[1000,77.99],[9.4,25.14],[10,39.48]],"trd":[[9.2,192.56]],"bdatb":[[0,9,12.39],[2,8.6,42.3],[3,8.4,72.83],[5,8,79.49],[6,7.8,48.24],[8,7.4,40.45],[9,7.2,9.4],[4,8.2,34.21],[7,7.6,10.91],[1,8.8,16.83]],"bdatl":[[0,9.2,34.12],[5,10.5,60.82],[6,11,55.07],[7,11.5,44.12],[8,12,33.82],[9,12.5,20.61],[1,9.4,25.14],[4,10,39.48]],"ltp":9.2,"tv":1119.6,"id":42930960},{"atb":[[15,40.84],[14.5,20.13],[16,12.63]],"atl":[[1000,60.56],[16.5,38.02]],"trd":[[16.5,105.62]],"bdatb":[[0,16,12.63],[1,15.5,12.9],[2,15,40.84],[3,14.5,26.34],[4,14,50.38],[6,13,37.2],[7,12.5,60.47],[9,11.5,51.89],[5,13.5,35.74],[8,12,26.19]],"bdatl":[[0,16.5,38.02],[9,22,59.45],[8,21,16.76]],"tv":705.52,"id":40095374},{"atb":[[8,15.13],[7.8,29.69],[7,39.92],[6.2,107]],"atl":[[1000,87.93],[8.4,11.37],[11,29.5],[9,25.92],[8.8,34.67],[9.2,25.68],[8.6,40.35],[8.2,0]],"trd":[[8.2,184.29]],"bdatb":[[0,8,15.81],[1,7.8,67.91],[2,7.6,44.3],[3,7.4,80.95],[4,7.2,25.09],[5,7,58.48],[6,6.8,53.2],[7,6.6,832.37],[8,6.4,49.67],[9,6.2,124.95]],"bdatl":[[4,9.2,37.2],[5,9.4,33.01],[6,9.6,27.31],[7,9.8,32.26],[8,10,28.36],[9,10.5,140.18],[0,8.4,11.37],[3,9,25.92],[1,8.6,40.35],[2,8.8,34.67]],"tv":2541.2,"id":36276560},{"atb":[[23,9.97],[20,32.7],[19.5,21.66]],"atl":[[24,70.38],[1000,42.16],[25,14.45],[23,0],[27,12.11]],"trd":[[24,13.58],[23,119.83]],"bdatb":[[0,23,9.97],[1,22,16.35],[3,20,37.2],[4,19.5,32.33],[9,17,43.81],[7,18,7.14],[2,21,27.32],[5,19,18.88],[6,18.5,14.56],[8,17.5,8.34]],"bdatl":[[0,24,70.38],[9,36,2.94],[1,25,14.45],[2,26,14.98],[3,27,12.11],[4,28,13.04],[5,29,8.53],[6,30,3.87],[7,32,3.85],[8,34,6.87]],"ltp":24,"tv":422.09,"id":37947503},{"atb":[[1.51,198.43],[1.48,326.31],[1.47,3659.41],[1.49,421.51],[1.5,1139.22],[1.01,26932.01],[1.52,0],[1.53,0]],"atl":[[1.52,3.66],[1.53,194.84],[1.57,47.83],[1.59,88.86],[1000,375.05],[1.54,210.32],[1.58,70.41],[1.6,128.63],[1.75,0],[1.55,86.22],[1.56,182.44]],"trd":[[1.52,1366.97],[1.53,2943.8]],"bdatb":[[0,1.51,261.68],[2,1.49,545.59],[3,1.48,407.52],[4,1.47,3730.38],[5,1.46,324.83],[7,1.44,294.9],[8,1.43,2386.67],[9,1.42,388.03],[6,1.45,257.77],[1,1.5,1370.57]],"bdatl":[[0,1.52,3.66],[3,1.55,154.56],[4,1.56,244.08],[5,1.57,71.03],[6,1.58,142.66],[7,1.59,116.41],[8,1.6,245.54],[9,1.61,121.5],[1,1.53,194.84],[2,1.54,210.32]],"ltp":1.52,"tv":12647.76,"id":39823721},{"atb":[[70,3.19]],"atl":[[100,4.27]],"trd":[[100,20.19]],"bdatb":[[2,80,6.13],[6,60,14.55],[8,50,26.38],[4,70,3.19],[1,85,5],[5,65,9.89],[9,48,10.6],[7,55,3.67]],"bdatl":[[0,100,4.27]],"tv":213.5,"id":44331354}],"con":true,"tv":17649.67}]}
{"op":"mcm","clk":"AImtAQD1kQEA45UB","pt":1650392807302,"mc":[{"id":"1.197931750","rc":[{"atb":[[1.01,58415.52],[8,60.09],[8.4,27.02],[8.8,24.4],[8.2,23.84]],"atl":[[1000,76.73],[26,4.72],[9.2,40.19]],"bdatb":[[4,8.2,46.9],[5,8,67.99],[1,8.8,31.38],[3,8.4,40.3],[6,7.8,44.86],[7,7.6,23.33],[8,7.4,33.45],[9,7.2,17.32],[0,9,22.38],[2,8.6,31.84]],"bdatl":[[5,10.5,58.79],[6,11,53.4],[7,11.5,41.46],[8,12,49.32],[9,12.5,21.88],[0,9.2,40.19]],"id":42930960},{"atb":[[16,14.81],[14.5,25.67],[15.5,18.77],[13.5,32.78]],"atl":[[16.5,27.73]],"bdatb":[[0,16,14.81],[2,15,44.94],[4,14,43.48],[5,13.5,40.29],[6,13,38.86],[7,12.5,58.74],[8,12,24.5],[9,11.5,52.86],[3,14.5,25.67],[1,15.5,24.94]],"bdatl":[[9,22,56.56],[0,16.5,27.73],[7,20,12.41]],"id":40095374},{"atb":[[1.01,47091.44],[8.2,8.21],[7.8,39.23],[8,13.13]],"atl":[[1000,85.69],[8.8,44.85],[8.6,20.11]],"bdatb":[[8,6.6,805.05],[9,6.4,66.1],[0,8.2,26.13],[2,7.8,73.86],[3,7.6,53.14],[4,7.4,52.31],[5,7.2,46.1],[6,7,49.67],[1,8,13.13],[7,6.8,72.31]],"bdatl":[[4,9.2,36.52],[5,9.4,22.78],[6,9.6,25.12],[7,9.8,42.33],[8,10,29.13],[9,10.5,154.33],[1,8.6,20.11],[2,8.8,44.85]],"id":36276560},{"atb":[[22,22.05],[21,33.3],[20,27.43],[1.01,88445.68],[19,16.76],[16,147.56]],"atl":[[32,7.07],[1000,41.59],[26,11.76]],"bdatb":[[8,17.5,13.36],[9,17,39],[1,22,26.4],[2,21,36.22],[3,20,27.43],[4,19.5,27.38],[6,18.5,20.03],[5,19,16.76],[7,18,6.58]],"bdatl":[[9,36,1.18],[7,32,7.07],[8,34,8.55],[2,26,11.76]],"id":37947503},{"atb":[[1.51,66.03],[1.37,269.99],[1.44,73.31],[1.49,446.41]],"atl":[[1.52,103.23],[1.53,227.16],[1.54,208.62]],"trd":[[1.52,1386.97]],"bdatb":[[0,1.51,129.28],[5,1.46,189.31],[6,1.45,305.31],[7,1.44,236.47],[8,1.43,2485.74],[9,1.42,280.82],[1,1.5,1322.05],[2,1.49,605],[3,1.48,397.09],[4,1.47,3785.65]],"bdatl":[[4,1.56,261.53],[5,1.57,53.69],[7,1.59,126.33],[8,1.6,213.33],[0,1.52,103.23],[1,1.53,227.16],[2,1.54,245.86],[9,1.61,143.7],[6,1.58,215.91],[3,1.55,117.56]],"tv":12667.76,"id":39823721},{"bdatb":[[5,65,10.83],[8,50,24.44],[2,80,7.26],[6,60,13.05]],"id":44331354}],"con":true,"tv":17669.67}]}
{"op":"mcm","clk":"ALuuAQCCkwEA7JYB","pt":1650392808303,"mc":[{"id":"1.197931750","rc":[{"atb":[[9.2,10.77],[1.01,60200.52],[9,26.66],[8.8,31.54],[8.6,33.88],[7.8,31.87],[6.8,306.97],[8.2,37.56],[6.6,25.49]],"atl":[[1000,76.41],[9.8,39.99],[11,49.71],[10,37.22],[9.6,21.35],[9.4,0],[10.5,51.3],[9.2,0]],"trd":[[9.4,371.93],[9.2,232.75]],"bdatb":[[2,8.8,31.54],[3,8.6,53.8],[4,8.4,44.14],[6,8,80.65],[8,7.6,24.99],[9,7.4,24.23],[0,9.2,5.86],[1,9,16.36],[5,8.2,37.56],[7,7.8,37.85]],"bdatl":[[3,10.5,53.87],[4,11,52.71],[5,11.5,42.45],[6,12,45.24],[8,13,89.93],[0,9.6,23.35],[1,9.8,42.03],[2,10,39.48],[7,12.5,17.11],[9,13.5,5.67]],"ltp":9.4,"tv":1168.44,"id":42930960},{"atb":[[1.01,68916.88],[15.5,18.77],[15,41.6],[14.5,24.89],[16.5,0],[10.5,36.12]],"atl":[[18,22.13],[17,40.67],[17.5,23.41],[1000,59.54],[18.5,13.96],[19,25.74],[16.5,0]],"trd":[[16.5,132.94]],"bdatb":[[1,15.5,18.77],[2,15,41.6],[3,14.5,24.89],[4,14,47.75],[5,13.5,36.7],[7,12.5,54.66],[8,12,33.12],[9,11.5,52.2],[6,13,35.49],[0,16,14.81]],"bdatl":[[1,17.5,23.41],[6,20,10.89],[7,21,18.05],[9,23,5.7],[0,17,38.66],[3,18.5,13.96],[2,18,19.85],[4,19,25.74],[5,19.5,29.24],[8,22,54.63]],"tv":732.84,"id":40095374},{"atb":[[7.8,3.45],[7.6,7.25],[6.8,64.74],[7.4,36.27],[6.6,31.66],[6,365.57],[1.01,45536.74],[7.2,37.12],[7,33.85],[8.2,0],[8,0]],"atl":[[8,5.42],[1000,86.66],[8.2,20.89],[9,24.66],[8.4,23.15],[8.8,47.52],[8.6,28.77]],"trd":[[7.8,286.48],[7.6,267.94],[8,116.53],[8.2,219.85]],"bdatb":[[0,7.8,3.45],[1,7.6,7.25],[8,6.2,111.66],[2,7.4,78.86],[3,7.2,37.12],[4,7,79.31],[5,6.8,65.14],[6,6.6,51],[7,6.4,79.67],[9,6,387.38]],"bdatl":[[0,8.2,20.89],[3,8.8,59.62],[4,9,24.66],[5,9.2,30.12],[8,9.8,38.11],[2,8.6,35.03],[6,9.4,26.59],[7,9.6,39.2],[9,10,28.36],[1,8.4,23.15]],"ltp":7.8,"tv":2795.8,"id":36276560},{"atb":[[8,2.24],[16.5,9.08],[23,16.45]],"atl":[[25,13.11],[42,5.84],[24,51.59]],"trd":[[24,32.37]],"bdatb":[[5,19,25.78],[7,18,9.51],[4,19.5,21.66],[9,17,41.59],[6,18.5,14.56],[0,23,16.45],[1,22,22.05],[2,21,33.3],[8,17.5,8.34]],"bdatl":[[7,32,7.91],[9,38,1.49],[1,25,13.11],[0,24,51.59],[8,34,6.87]],"tv":440.88,"id":37947503},{"atb":[[1.48,266.76],[1.49,600.87],[1.52,105.5],[1.47,258.05],[1.36,50.69],[1.51,198.69],[1.46,126.57]],"atl":[[1000,373.27],[1.56,189.71],[1.53,205.97],[1.59,85.71],[1.54,206.61],[1.57,83.37],[1.55,84.12],[1.52,0]],"trd":[[1.53,3140.14],[1.52,1506.2],[1.51,2952.4]],"bdatb":[[0,1.52,105.5],[2,1.5,1253.41],[4,1.48,505.31],[5,1.47,332.73],[7,1.45,134.96],[8,1.44,202.71],[9,1.43,2597.73],[1,1.51,198.69],[3,1.49,578.93],[6,1.46,396.96]],"bdatl":[[2,1.55,101.49],[3,1.56,207.01],[4,1.57,177.18],[6,1.59,157.07],[7,1.6,208.82],[8,1.61,92.72],[9,1.62,85.22],[0,1.53,205.97],[5,1.58,93.05],[1,1.54,206.61]],"ltp":1.53,"tv":13027.33,"id":39823721},{"atb":[[85,5.14],[80,4.82],[1.01,110127.92],[70,2.47],[95,2.55],[38,53],[90,1.82]],"atl":[[510,0.06],[1000,20.27],[350,8.99],[110,4.36],[100,0]],"trd":[[110,8.13],[100,24.46],[90,13.5]],"bdatb":[[2,85,5.14],[3,80,4.82],[9,50,25.64],[8,55,3.67],[5,70,2.47],[0,95,2.55],[1,90,1.82],[4,75,12.9],[6,65,9.89],[7,60,13.05]],"bdatl":[[4,350,8.99],[9,1000,20.27],[0,110,4.36],[1,190,7.31],[2,230,3.21],[3,340,5.01],[5,510,1.06],[6,530,1],[7,550,1],[8,570,1]],"ltp":110,"tv":219.65,"id":44331354}],"con":true,"tv":18384.94}]}
{"op":"mcm","clk":"AOKvAQCAlAEAlpgB","pt":1650392809304,"mc":[{"id":"1.197931750","rc":[{"atb":[[9.4,5.63],[9,24.4],[8.8,42.74],[9.2,10.94],[6.8,12.97],[7.2,285.51],[1.01,59720.44],[8.2,35.54]],"atl":[[9.8,32.61],[9.6,8.92],[10,31],[14,86.3],[13,4.47],[1000,74.42],[10.5,52.38]],"trd":[[9.2,234.45]],"bdatb":[[0,9.2,15.66],[3,8.6,47.28],[5,8.2,46.11],[6,8,80.4],[7,7.8,40.72],[8,7.6,11.14],[9,7.4,41.62],[1,9,24.4],[2,8.8,56.2],[4,8.4,27.02]],"bdatl":[[5,11.5,49.63],[6,12,31.41],[7,12.5,32.57],[8,13,10.59],[0,9.6,8.92],[2,10,31],[4,11,49.71],[1,9.8,38.83],[3,10.5,52.38]],"ltp":9.2,"tv":1170.14,"id":42930960},{"atb":[[1.01,67424.51],[15.5,22.84],[14.5,20.67],[11,192.08],[10,10.61]],"atl":[[17,64.75],[60,0],[19,31.13],[1000,58.58],[24,52.55],[22,9.63]],"bdatb":[[1,15.5,25.65],[2,15,44.41],[3,14.5,25.93],[4,14,35.51],[5,13.5,41.32],[6,13,35.16],[7,12.5,58.81],[8,12,24.75],[9,11.5,50.66]],"bdatl":[[4,19,31.13],[7,21,16.76],[9,23,8.86],[8,22,9.63],[0,17,36.38],[2,18,22.13],[6,20,9.54]],"id":40095374},{"atb":[[7.6,9.64],[7.4,25],[7,44.19],[1.01,43306.17],[5.9,359.41],[6,32.57],[7.2,40.12],[7.8,0]],"atl":[[1000,87.52],[8.4,30.61],[7.8,10.89],[8.8,41.29],[8.2,26.65],[9.2,29.75],[8.6,38.02],[8,14.81],[9,21.75],[11,19.5]],"trd":[[7.6,294.74],[7.4,131.6],[7.8,293.38]],"bdatb":[[0,7.4,62.46],[2,7,79.78],[3,6.8,74.89],[5,6.4,45.82],[6,6.2,146.6],[1,7.2,40.12],[4,6.6,51.42],[7,6,54.38],[8,5.9,373.9],[9,5.8,139.85]],"bdatl":[[5,8.8,53.46],[7,9.2,38.03],[0,7.8,5.57],[3,8.4,27.77],[8,9.4,31.64],[9,9.6,30.53],[1,8,14.81],[4,8.6,49.73],[2,8.2,24.62],[6,9,21.75]],"ltp":7.4,"tv":2855.66,"id":36276560},{"atb":[[14.5,138.14],[16,22.56]],"atl":[[27,8.6],[46,38],[44,3.09]],"bdatb":[[2,21,35.37],[3,20,29.54],[5,19,20.78],[7,18,12.98],[9,17,41.34]],"bdatl":[[3,27,8.6],[9,40,2.52],[7,32,7.07]],"id":37947503},{"atb":[[1.52,105.83],[1.34,250.43],[1.44,1512.31],[1.37,219.99],[1.49,575.97],[1.5,1164.12],[1.43,980.12],[1.01,26807.08],[1.51,196.69]],"atl":[[1000,370.27],[1.53,181.15],[1.65,0],[1.63,664.53]],"trd":[[1.52,1509.55]],"bdatb":[[0,1.52,105.83],[8,1.44,1573.49],[1,1.51,253.4],[2,1.5,1349.57],[3,1.49,644.68],[4,1.48,355.19],[5,1.47,379.89],[6,1.46,227.88],[7,1.45,326.64],[9,1.43,1122.67]],"bdatl":[[4,1.57,201.23],[5,1.58,103.27],[7,1.6,188.34],[8,1.61,134.88],[9,1.62,94.83],[0,1.53,181.15],[3,1.56,189.71],[6,1.59,174.63],[2,1.55,84.12]],"ltp":1.52,"tv":13030.68,"id":39823721},{"atb":[[70,2.47],[40,55.84],[38,0],[95,4.55],[90,0]],"atl":[[590,1],[530,0],[390,3],[350,5.99]],"bdatb":[[4,70,3.09],[7,55,4.44],[8,50,23.74],[0,95,4.55],[1,85,5.14],[2,80,4.82],[3,75,12.9],[5,65,9.89],[6,60,13.05],[9,48,10.6]],"bdatl":[[6,550,1.06],[7,570,1],[8,590,1],[4,350,5.99],[5,390,3],[9,1000,20.27]],"id":44331354}],"con":true,"tv":18449.85}]}
{"op":"mcm","clk":"AKmxAQCrlQEAyJkB","pt":1650392810518,"mc":[{"id":"1.197931750","rc":[{"atb":[[1.01,59259.53],[9.2,24.37],[8.6,37.48],[9,41.09],[8.4,35.11],[8.8,32.26],[9.4,8.69],[9.6,8.29],[8.2,32.3]],"atl":[[10,32.19],[1000,72.47],[13,12.8],[9.8,15.98],[11.5,37.65],[11,51.72],[10.5,39.84],[9.6,0]],"trd":[[9.6,145.58],[9.4,379.87]],"bdatb":[[4,8.8,48.93],[6,8.4,35.11],[1,9.4,8.69],[3,9,44.49],[0,9.6,8.29],[2,9.2,35.14],[5,8.6,32.42],[7,8.2,57.68],[9,7.8,32.01],[8,8,68.72]],"bdatl":[[6,12.5,26.2],[7,13,19.27],[0,9.8,15.98],[1,10,34.24],[2,10.5,39.84],[3,11,54.66],[4,11.5,48.83],[5,12,37.67],[9,14,91.23],[8,13.5,5.67]],"ltp":9.6,"tv":1188.82,"id":42930960},{"atl":[[21,4.63],[20,17.2],[19.5,21.37],[18.5,15.01],[70,2.86]],"bdatb":[[3,14.5,22.48],[4,14,44.12],[5,13.5,32.78],[6,13,31.65],[7,12.5,65.09],[8,12,19.75],[9,11.5,53.03],[2,15,50.29],[1,15.5,22.84]],"bdatl":[[8,22,13.32],[9,23,4.48],[7,21,19.01],[5,19.5,30.9],[6,20,9.54],[3,18.5,20.56],[0,17,64.75]],"id":40095374},{"atb":[[6.8,70.1],[1.01,42244.58],[7.6,4.25],[7.4,30.78],[6.6,38.32],[7.2,37.06]],"atl":[[9.2,26.82],[10.5,117.72],[8.6,33.9],[8.4,17.73],[7.8,16.72],[1000,85.32],[8.2,33.94],[8,23.47]],"trd":[[7.8,302.48],[7.6,314.61]],"bdatb":[[1,7.4,51.95],[2,7.2,53.8],[3,7,75.89],[4,6.8,66.54],[5,6.6,51.05],[7,6.2,137.92],[8,6,62.99],[0,7.6,4.25],[6,6.4,58.31],[9,5.9,359.41]],"bdatl":[[7,9.2,39.56],[8,9.4,24.87],[9,9.6,33.23],[3,8.4,36.88],[4,8.6,33.9],[5,8.8,41.33],[6,9,30.16],[0,7.8,16.72],[2,8.2,33.94],[1,8,23.47]],"ltp":7.8,"tv":2884.63,"id":36276560},{"atb":[[23,16.25]],"atl":[[28,16.39]],"trd":[[23,120.22]],"bdatb":[[0,23,16.25],[5,19,18.14],[6,18.5,21.07],[8,17.5,8.34],[9,17,38.66],[3,20,33.95],[2,21,33.3],[7,18,6.58]],"bdatl":[[9,38,2.14],[8,34,8.26],[6,30,4.94],[4,28,16.39]],"ltp":23,"tv":441.27,"id":37947503},{"atb":[[1.32,224.9],[1.47,307.93],[1.46,74.68]],"atl":[[1.58,103.94],[1.57,49.84]],"bdatb":[[5,1.47,457.01],[3,1.49,697.37],[4,1.48,285.17],[6,1.46,192.45],[7,1.45,192.57],[8,1.44,1764.61],[9,1.43,1040.28],[1,1.51,283.06],[2,1.5,1289.28]],"bdatl":[[3,1.56,272.38],[4,1.57,112.8],[5,1.58,163.43],[6,1.59,134.86],[8,1.61,203.52],[9,1.62,80.27],[2,1.55,104.96],[7,1.6,187.8]],"id":39823721},{"atl":[[610,1]],"bdatb":[[8,50,22.74],[6,60,15.23],[4,70,2.47],[7,55,3.67]],"id":44331354}],"con":true,"tv":18497.89}]}
{"op":"mcm","clk":"AMyyAQC3lgEAyJoB","pt":1650392811519,"mc":[{"id":"1.197931750","rc":[{"atb":[[9.2,31.8],[9,29.5],[9.4,7.48]],"atl":[[12.5,29.49],[9.8,5.65],[10.5,38.76]],"bdatb":[[1,9.4,11.5],[4,8.8,39.16],[5,8.6,52.24],[7,8.2,45.85],[9,7.8,46.26],[2,9.2,51.22],[3,9,29.5],[8,8,70.1]],"bdatl":[[4,11.5,39.59],[5,12,36.94],[6,12.5,36.66],[7,13,15.46],[8,13.5,18.47],[9,14,86.3],[0,9.8,5.65],[2,10.5,38.76],[3,11,51.72],[1,10,32.19]],"id":42930960},{"atb":[[15,40.84]],"atl":[[22,21.19],[18,21.5]],"bdatb":[[0,16,17.17],[2,15,42.02],[3,14.5,31.77],[4,14,39.85],[6,13,36.2],[7,12.5,52.76],[8,12,26.04],[9,11.5,54.72]],"bdatl":[[7,21,5.69],[8,22,21.19],[9,23,6.97],[2,18,21.5],[5,19.5,21.37],[3,18.5,15.01],[6,20,17.2]],"id":40095374},{"atb":[[7,55.02],[7.4,3.01],[1.01,42207.09],[7.2,25.01],[5.7,10.64],[6.6,29.39],[7.6,0]],"atl":[[7.6,4.97],[8.4,35.2],[1000,85.05],[7.8,22.9],[8.2,37.01]],"trd":[[7.4,171.6],[7.6,323.11]],"bdatb":[[0,7.4,10.5],[2,7,69.32],[1,7.2,55.81],[3,6.8,89.81],[4,6.6,42.12],[6,6.2,116.46],[7,6,83.28],[5,6.4,58.31],[8,5.9,359.41],[9,5.8,161.18]],"bdatl":[[0,7.6,4.97],[1,7.8,22.9],[2,8,23.47],[3,8.2,37.01],[4,8.4,48.63],[5,8.6,33.9],[6,8.8,45.51],[7,9,31.42],[8,9.2,41.69],[9,9.4,26.61]],"ltp":7.4,"tv":2933.13,"id":36276560},{"atb":[[20,26.86]],"atl":[[24,50.22],[26,11.33]],"trd":[[24,35.1]],"bdatb":[[1,22,23.77],[3,20,27.75],[4,19.5,29.91],[6,18.5,17.84],[9,17,42.13],[5,19,16.76]],"bdatl":[[8,34,7.52],[9,40,1.43],[2,26,11.33],[6,30,3.87]],"ltp":24,"tv":444,"id":37947503},{"atb":[[1.52,74.18]],"atl":[[1.56,182.44]],"trd":[[1.52,1557.91]],"bdatb":[[0,1.52,99.03],[2,1.5,1271.39],[3,1.49,593.98],[4,1.48,341.82],[6,1.46,224.66],[7,1.45,272.01],[8,1.44,1592.29],[9,1.43,1128.77],[1,1.51,314.98],[5,1.47,490.99]],"bdatl":[[3,1.56,196.72],[4,1.57,131.13],[5,1.58,137.13],[6,1.59,193.52],[8,1.61,152.19],[9,1.62,104.24],[7,1.6,171.58],[2,1.55,84.12]],"tv":13079.04,"id":39823721},{"atb":[[85,5]],"atl":[[130,0.03]],"bdatb":[[2,80,5.3],[6,60,13.35],[7,55,6.6],[8,50,22.21],[1,85,5]],"bdatl":[[1,190,7.22],[9,610,1]],"id":44331354}],"con":true,"tv":18597.48}]}
{"op":"mcm","clk":"ANuzAQC1lwEA0psB","pt":1650392812521,"mc":[{"id":"1.197931750","rc":[{"atb":[[9.4,19.76],[9.2,33.81],[8.8,31.85],[9.8,4.45],[8,57.34],[9.6,9.34],[8.2,39.24],[7.4,16.42]],"atl":[[1000,71.49],[26,0],[12,47.34],[11.5,41.99],[11,49.71],[10.5,44.22],[9.8,0]],"trd":[[9.8,76.58]],"bdatb":[[2,9.4,28.57],[3,9.2,51.38],[5,8.8,34.53],[6,8.6,58.43],[8,8.2,47.42],[0,9.8,4.45],[1,9.6,9.34],[4,9,29.5],[7,8.4,35.11],[9,8,66.21]],"bdatl":[[1,10.5,44.22],[2,11,49.71],[3,11.5,41.99],[4,12,56.11],[0,10,32.19],[5,12.5,34.9],[6,13,17.73],[7,13.5,17.91],[8,14,86.3],[9,14.5,7.7]],"ltp":9.8,"tv":1200.13,"id":42930960},{"atl":[[19,27]],"bdatb":[[1,15.5,28.18],[4,14,37.2],[7,12.5,60.71],[8,12,22.37],[0,16,14.81],[6,13,32.64],[9,11.5,53.92],[2,15,40.84],[3,14.5,31.82]],"bdatl":[[4,19,27],[8,22,23.17],[9,23,7.16],[7,21,4.63]],"id":40095374},{"atb":[[1.01,41523.47],[6.4,47.71],[6,32.57],[7.2,24.01],[7,58.02],[7.4,0],[6.6,35.11]],"atl":[[7.6,10.89],[9.4,35.4],[8.8,38.62],[10,16.09],[7.8,20.72],[8.6,29.9],[8.2,29.48],[12,9.01],[8,25.47]],"trd":[[7.6,324.25]],"bdatb":[[5,6.2,118.24],[6,6,81.43],[4,6.4,68.08],[8,5.8,149.27],[9,5.7,25.35],[0,7.2,61.23],[1,7,65.72],[2,6.8,97.96],[3,6.6,46.45],[7,5.9,359.41]],"bdatl":[[0,7.6,10.89],[7,9,30.87],[8,9.2,32.77],[6,8.8,50.4],[9,9.4,38.43],[3,8.2,34.8],[4,8.4,42.54],[5,8.6,33.16],[1,7.8,20.72],[2,8,25.47]],"ltp":7.6,"tv":2934.27,"id":36276560},{"atl":[[24,48.32]],"trd":[[24,38.9]],"bdatb":[[2,21,37.24],[6,18.5,15.83],[1,22,22.05],[9,17,39.41],[3,20,26.86],[4,19.5,29.95]],"bdatl":[[0,24,48.32],[9,36,1.21],[8,34,6.87]],"tv":447.8,"id":37947503},{"atb":[[1.52,69.23]],"atl":[[1000,373.27],[1.53,175.15]],"trd":[[1.53,3152.14],[1.52,1567.81]],"bdatb":[[1,1.51,358.53],[2,1.5,1215.79],[3,1.49,660.69],[4,1.48,312.1],[5,1.47,492.28],[6,1.46,211.22],[7,1.45,230.26],[8,1.44,1632.61],[9,1.43,1104.19],[0,1.52,69.23]],"bdatl":[[0,1.53,175.15],[3,1.56,210.4],[4,1.57,132.17],[7,1.6,256.9],[8,1.61,69.61],[9,1.62,194.18],[5,1.58,144.51],[6,1.59,171.74]],"ltp":1.53,"tv":13100.94,"id":39823721},{"bdatb":[[5,65,11.16],[2,80,4.82],[6,60,13.05],[7,55,6.61]],"id":44331354}],"con":true,"tv":18635.63}]}
{"op":"mcm","clk":"APe0AQDDmAEA3pwB","pt":1650392813522,"mc":[{"id":"1.197931750","rc":[{"atb":[[8.6,33.44],[9.6,12.34],[9.4,29.13],[7.8,20.88],[9.8,4.34],[9.2,28.38]],"atl":[[10,18.46],[10.5,46.22],[12,34],[30,7.34]],"trd":[[9.8,82.16]],"bdatb":[[6,8.6,56.51],[1,9.6,12.34],[0,9.8,4.34],[2,9.4,41.85],[3,9.2,44.5],[5,8.8,33.35],[7,8.4,39.35],[8,8.2,46.62],[9,8,58.64]],"bdatl":[[0,10,18.46],[3,11.5,42.45],[4,12,42.32],[5,12.5,32.58],[6,13,19.97],[1,10.5,46.22]],"tv":1205.71,"id":42930960},{"atb":[[6.6,52.31],[7.4,0.72],[6.4,69.76],[4.3,1.46],[7,45.57],[7.2,19.23]],"atl":[[1000,84.54],[15,5.43],[12,18.1],[8.6,21.73],[7.6,15.74],[8,36.81]],"trd":[[7.4,175.06]],"bdatb":[[0,7.2,45.58],[1,7,57.49],[2,6.8,105.88],[3,6.6,46.45],[4,6.4,82.84],[5,6.2,114.53],[6,6,93.04],[7,5.9,359.41],[8,5.8,140.16],[9,5.7,29.89]],"bdatl":[[5,8.6,28.21],[6,8.8,47.25],[9,9.4,38.59],[0,7.6,15.74],[2,8,36.81],[3,8.2,34.66],[4,8.4,42.67],[7,9,36.95],[8,9.2,29.92]],"ltp":7.4,"tv":2937.73,"id":36276560},{"atl":[[24,46.12]],"trd":[[24,43.3]],"bdatb":[[4,19.5,24.99],[7,18,11.21],[9,17,36.24],[2,21,38.99],[6,18.5,14.56]],"bdatl":[[0,24,46.12],[7,32,7.23],[9,36,1.03]],"tv":452.2,"id":37947503},{"bdatb":[[3,14.5,25.15],[5,13.5,38.96],[6,13,29.52],[7,12.5,66.48],[1,15.5,30.56],[4,14,35.51],[8,12,22.71],[9,11.5,50.82]],"bdatl":[[6,20,17.47],[8,22,22.88],[9,23,7.21]],"id":40095374},{"bdatb":[[1,1.51,318.91],[3,1.49,795.27],[5,1.47,371.96],[6,1.46,369.78],[7,1.45,118.68],[8,1.44,1642.08],[9,1.43,1127.25],[2,1.5,1164.12],[4,1.48,310.3]],"bdatl":[[2,1.55,87.56],[3,1.56,206.29],[4,1.57,114.34],[5,1.58,162.9],[7,1.6,146.11],[8,1.61,141.79],[6,1.59,210.13]],"id":39823721},{"bdatb":[[7,55,4.85],[5,65,11.73]],"id":44331354}],"con":true,"tv":18649.07}]}
{"op":"mcm","clk":"AK22AQDsmQEA3J0B","pt":1650392814523,"mc":[{"id":"1.197931750","rc":[{"atb":[[8.8,31.85],[9,42.27],[9.6,0],[1.01,58401.46],[9.4,29.46],[9.2,20.96],[9.8,0],[8,54.59]],"atl":[[9.6,5.55],[10,27.97],[11,51.72],[10.5,48.23],[9.8,7.77],[11.5,51.51],[13,4.47]],"trd":[[9.6,160.18]],"bdatb":[[2,9.2,20.96],[4,8.8,44.25],[5,8.6,51.77],[6,8.4,35.11],[7,8.2,50.9],[8,8,54.59],[9,7.8,30.5],[0,9.6,12.74],[1,9.4,29.46],[3,9,32.17]],"bdatl":[[1,10,27.97],[2,10.5,48.23],[3,11,61.18],[4,11.5,57.3],[5,12,55.03],[6,12.5,29.49],[7,13,22.38],[8,13.5,28.69],[9,14,87.77],[0,9.8,7.77]],"ltp":9.6,"tv":1220.31,"id":42930960},{"atb":[[16,0],[1.01,66674.81],[14.5,15.13]],"atl":[[19,25],[17,59.72],[18,23.51],[17.5,25.42],[16.5,11.32]],"bdatb":[[0,15.5,22.84],[1,15,40.84],[2,14.5,15.13],[3,14,37.29],[4,13.5,32.78],[5,13,40.62],[6,12.5,50.62],[7,12,27.71],[8,11.5,51.18],[9,11,192.32]],"bdatl":[[5,19,25.9],[6,19.5,25.83],[1,17,59.72],[0,16.5,11.32],[2,17.5,25.42],[3,18,23.51],[8,21,5.5],[9,22,23.39],[4,18.5,15.01],[7,20,17.2]],"id":40095374},{"atb":[[7.2,5.2],[1.01,40854.73],[5.7,19.78],[7.4,0],[6.4,47.71],[6.6,35.11],[3.9,34.48],[6.8,82.98]],"atl":[[7.8,22.72],[7.4,3.36],[8,46.42],[8.4,26.66],[7.6,20.74],[8.2,43.37],[9.6,12.84]],"trd":[[7.4,180.48]],"bdatb":[[1,7,45.57],[2,6.8,94.18],[3,6.6,65.71],[4,6.4,59.44],[5,6.2,107.43],[6,6,74.49],[7,5.9,359.41],[8,5.8,152.56],[9,5.7,24.08],[0,7.2,14.45]],"bdatl":[[0,7.4,3.36],[2,7.8,22.72],[3,8,61.71],[4,8.2,71.62],[5,8.4,32.04],[6,8.6,44.15],[9,9.2,36.07],[1,7.6,20.74],[7,8.8,45.86],[8,9,46.83]],"tv":2943.15,"id":36276560},{"atb":[[23,7.42]],"atl":[[25,14.42],[24,44.89]],"trd":[[24,45.76]],"bdatb":[[3,20,26.86],[5,19,18.07],[6,18.5,14.56],[8,17.5,11.27],[9,17,42.5],[0,23,7.42],[7,18,6.58],[2,21,33.3],[4,19.5,21.66]],"bdatl":[[5,29,8.53],[7,32,10.32],[8,34,6.87],[9,40,6.27],[1,25,14.42],[4,28,16.39],[0,24,44.89]],"tv":454.66,"id":37947503},{"atb":[[1.53,206.14],[1.51,379.04],[1.55,164.2],[1.36,52.48],[1.49,613.85],[1.54,729.12],[1.01,26320.3],[1.52,79.12],[1.47,256.04],[1.48,264.75],[1.5,1172.84]],"atl":[[1.55,0],[1.6,62.16],[1000,355.33],[1.58,72.54],[1.57,47.83],[1.59,87.77],[1.56,178.26],[1.53,0],[1.54,0]],"trd":[[1.55,458.53],[1.53,3502.43],[1.54,1906.34],[1.52,1613.96]],"bdatb":[[0,1.54,729.12],[1,1.53,182.39],[2,1.52,182.82],[3,1.51,460.1],[5,1.49,865.7],[6,1.48,267.56],[7,1.47,342.44],[8,1.46,228.41],[9,1.45,264.55],[4,1.5,1172.84]],"bdatl":[[0,1.56,178.26],[1,1.57,114.12],[2,1.58,84.1],[3,1.59,233.49],[4,1.6,90.4],[5,1.61,76.93],[6,1.62,134.18],[7,1.63,842.17],[8,1.64,75.48],[9,1.65,12.5]],"ltp":1.55,"tv":13946.02,"id":39823721},{"atb":[[95,0.18]],"atl":[[110,6.36]],"trd":[[95,20.4]],"bdatb":[[0,85,5.18],[1,80,4.82],[2,75,12.9],[3,70,2.47],[4,65,9.89],[5,60,13.05],[6,55,3.67],[7,50,22.71],[8,48,10.6],[9,46,12.16]],"bdatl":[[0,110,6.36],[1,190,7.22],[3,340,5.01]],"ltp":95,"tv":223.29,"id":44331354}],"con":true,"tv":19520.27}]}
{"op":"mcm","clk":"AN+3AQD8mgEA154B","pt":1650392815525,"mc":[{"id":"1.197931750","rc":[{"atb":[[7,156.67],[1.01,55830.42],[8.2,32.3],[9,40.27],[8.6,25.65],[9.4,7.48],[9.2,27.11]],"atl":[[1000,69.48],[11.5,49.5],[11,61.72],[9.8,11.48],[12,24.91],[10.5,50.24],[10,30.23]],"bdatb":[[2,9,52.68],[3,8.8,36.45],[4,8.6,25.65],[5,8.4,43.39],[6,8.2,45.51],[7,8,54.59],[8,7.8,23.65],[9,7.6,25.55],[0,9.4,7.48],[1,9.2,27.11]],"bdatl":[[3,10.5,50.24],[4,11,76.84],[5,11.5,54.83],[6,12,29.28],[9,13.5,19.3],[8,13,33.37],[1,9.8,11.48],[2,10,30.23],[7,12.5,29.49],[0,9.6,5.55]],"id":42930960},{"atb":[[15.5,10.73],[14.5,12.93],[13.5,34.98],[15,38.8],[1.01,65925.1]],"atl":[[18,29.39],[22,16.43],[18.5,15.01],[16.5,16.73]],"bdatb":[[0,15.5,10.73],[1,15,42.36],[2,14.5,16.96],[3,14,38.41],[5,13,29.55],[6,12.5,55.09],[7,12,28.77],[8,11.5,46.54],[9,11,202.19],[4,13.5,34.98]],"bdatl":[[3,18,29.39],[4,18.5,15.01],[7,20,20.72],[9,22,19.02],[0,16.5,16.73],[6,19.5,21.37],[8,21,9.41],[5,19,25]],"id":40095374},{"atb":[[7.2,0],[1.07,0.33],[7,32.52],[6.8,90.04],[1.01,40175.95],[6.4,56.49],[6.6,41.23]],"atl":[[8.2,37.93],[7.2,15.51],[1000,85.49],[7.8,35.88],[8.8,31.37],[7.4,14.87],[8.4,23.82],[7.6,14.25],[8,28.25],[11.5,23.12]],"trd":[[7.2,60.68],[7,23.18]],"bdatb":[[0,7,32.52],[1,6.8,112.42],[2,6.6,43.3],[3,6.4,85.53],[4,6.2,124.95],[5,6,56.37],[6,5.9,359.41],[7,5.8,143.86],[8,5.7,33.21],[9,5.6,7.42]],"bdatl":[[0,7.2,15.51],[1,7.4,14.87],[2,7.6,14.25],[3,7.8,44.89],[4,8,40.25],[5,8.2,51.81],[6,8.4,23.82],[7,8.6,26.33],[8,8.8,69.56],[9,9,24.67]],"ltp":7.2,"tv":3002.65,"id":36276560},{"atb":[[8.6,31.66]],"atl":[[27,14.81]],"bdatb":[[2,21,35.83],[3,20,29.78],[5,19,18.89],[8,17.5,9.12],[9,17,39.53],[6,18.5,14.56]],"bdatl":[[7,32,7.07],[9,36,1.95],[5,29,8.53],[8,34,6.87],[3,27,14.81]],"id":37947503},{"atb":[[1.49,519.05],[1.34,255.16],[1.01,25871.1],[1.55,180.75],[1.52,247.18],[1.53,240.58],[1.51,348.65],[1.5,1147.94],[1.54,741.78]],"atl":[[1000,343.17],[1.6,30.63],[1.65,66.16],[1.56,97.54],[1.57,127.08],[1.58,70.41],[1.59,89.83],[1.73,100]],"trd":[[1.55,484.63]],"bdatb":[[1,1.54,814.29],[2,1.53,312.5],[3,1.52,282.93],[4,1.51,475.8],[6,1.49,695.75],[7,1.48,335.36],[8,1.47,364.71],[9,1.46,178.29],[5,1.5,1147.94],[0,1.55,180.75]],"bdatl":[[2,1.58,70.41],[3,1.59,134.05],[4,1.6,93.34],[5,1.61,97.55],[6,1.62,151.64],[8,1.64,119.8],[9,1.65,66.16],[7,1.63,822.33],[0,1.56,97.54],[1,1.57,127.08]],"tv":13972.12,"id":39823721},{"atb":[[80,6.64],[65,10.67],[95,0],[85,5],[1.01,106860.36]],"bdatb":[[3,70,3.23],[5,60,14.03],[6,55,3.67],[7,50,23.02],[1,80,6.64],[4,65,10.67],[0,85,5],[9,46,12.16]],"id":44331354}],"con":true,"tv":19605.87}]}
{"op":"mcm","clk":"AI25AQD3mwEA5J8B","pt":1650392816527,"mc":[{"id":"1.197931750","rc":[{"atb":[[8.4,37.12],[8.8,29.85],[9,50.08],[9.4,1.66],[9.2,22.75],[1.01,54986.79]],"atl":[[1000,68.49],[10,38.98]],"trd":[[9.4,391.51]],"bdatb":[[5,8.4,46.92],[6,8.2,34.84],[7,8,70.47],[8,7.8,26.89],[9,7.6,23.1],[0,9.4,1.66],[2,9,56.43],[3,8.8,40.08],[1,9.2,22.75]],"bdatl":[[3,10.5,56.48],[4,11,67.12],[5,11.5,53.09],[6,12,43.11],[7,12.5,29.49],[8,13,24.85],[9,13.5,6.13],[2,10,38.98]],"ltp":9.4,"tv":1231.95,"id":42930960},{"atb":[[1.01,65175.39]],"atl":[[17.5,27.43],[17,33.35],[16.5,40.69],[16,11.76]],"bdatb":[[6,12.5,54.22],[7,12,21.48],[8,11.5,55.7],[9,11,196.35],[1,15,38.8],[3,14,43.49],[2,14.5,12.93],[5,13,32.66]],"bdatl":[[7,19.5,23.93],[9,21,7.46],[0,16,2.45],[1,16.5,45.1],[2,17,31.35],[3,17.5,25.42],[4,18,29.39],[5,18.5,15.86],[6,19,25],[8,20,17.2]],"id":40095374},{"atb":[[7,12.86],[6.8,72.38],[1.02,5002],[6.6,63.64],[1.01,39170.09],[1.07,0]],"atl":[[7.2,16.8],[8.2,31.1],[7.4,13.4],[7.8,38.5],[7.6,25.63],[1000,84.96]],"trd":[[7,63.17]],"bdatb":[[3,6.4,86.62],[6,5.9,360.29],[7,5.8,160.24],[8,5.7,21.24],[9,5.6,8.1],[1,6.8,82.92],[2,6.6,82.81],[4,6.2,129.51],[5,6,41.27],[0,7,17.86]],"bdatl":[[3,7.8,44.9],[4,8,40.84],[6,8.4,42.84],[8,8.8,62.18],[2,7.6,27.68],[5,8.2,38.25],[9,9,25.95],[1,7.4,13.4],[7,8.6,21.73]],"ltp":7,"tv":3042.64,"id":36276560},{"atb":[[1.53,377.85],[1.49,455],[1.54,741.78],[1.56,0],[1.36,30.84],[1.47,97.1],[1.5,1143.96],[1.55,205.9],[1.01,25647.02],[1.52,243.9]],"atl":[[1000,335.43],[1.58,62.87],[1.57,147.54],[1.61,97.81],[1.6,32.64],[1.59,87.77],[1.56,0]],"trd":[[1.56,311.6]],"bdatb":[[0,1.56,42.02],[1,1.55,231.19],[2,1.54,792.12],[3,1.53,421.88],[4,1.52,372.04],[5,1.51,448],[6,1.5,1244.13],[7,1.49,538.75],[8,1.48,397.61],[9,1.47,200.02]],"bdatl":[[0,1.57,147.54],[1,1.58,80.4],[2,1.59,97.58],[3,1.6,101],[7,1.64,50.45],[8,1.65,99.31],[9,1.66,255.57],[4,1.61,126.18],[5,1.62,186.83],[6,1.63,802.36]],"ltp":1.56,"tv":14148.7,"id":39823721},{"bdatb":[[9,17,38.89],[3,20,28.82],[4,19.5,22.38],[2,21,33.3],[5,19,19.84],[8,17.5,11.43]],"bdatl":[[8,34,8.33],[9,38,1.56],[6,30,4.39]],"id":37947503},{"bdatb":[[5,60,13.71],[6,55,3.93],[3,70,2.47],[7,50,23.38]],"bdatl":[[8,590,1.03]],"id":44331354}],"con":true,"tv":19834.08}]}
{"op":"mcm","clk":"AJW6AQDvnAEA4qAB","pt":1650392817528,"mc":[{"id":"1.197931750","rc":[{"atb":[[9.4,13.04],[8.8,35.67],[9.2,18.96],[9,52.08],[8.2,30.28],[8,52.55]],"atl":[[1000,68.49],[12,20.31],[9.6,3.79],[9.8,8.96]],"trd":[[9.6,161.94]],"bdatb":[[1,9.2,18.96],[2,9,52.08],[3,8.8,35.67],[4,8.6,28.83],[5,8.4,37.12],[6,8.2,47.67],[7,8,72.26],[8,7.8,33.95],[9,7.6,24.45],[0,9.4,13.04]],"bdatl":[[4,11,74.44],[5,11.5,51.52],[6,12,20.57],[7,12.5,34.33],[8,13,37],[9,13.5,7.72],[0,9.6,3.79],[1,9.8,8.96],[3,10.5,50.24]],"ltp":9.6,"tv":1233.71,"id":42930960},{"atb":[[15,32.22],[14.5,26.25],[1.01,64425.68]],"atl":[[18.5,15.01],[17.5,25.42],[17,31.35],[16,1.39],[1000,58.08],[16.5,48.99]],"trd":[[16,201.73]],"bdatb":[[1,15,32.22],[2,14.5,26.25],[3,14,35.51],[4,13.5,37],[5,13,29.2],[6,12.5,57.64],[7,12,23.55],[8,11.5,58.37],[9,11,201.35],[0,15.5,10.73]],"bdatl":[[9,21,5.46],[8,20,23.34],[2,17,31.35],[3,17.5,25.42],[5,18.5,15.01],[0,16,1.39],[1,16.5,48.99],[7,19.5,21.37]],"ltp":16,"tv":733.9,"id":40095374},{"atb":[[7,23.3],[6.6,66.64],[6.8,75.62],[1.01,38846.55],[1.02,5000],[6,41.46]],"atl":[[7.6,3.59],[7.4,0],[7.2,0]],"trd":[[7.6,403.75],[7.4,207.28],[7.2,104.3],[7,90.75]],"bdatb":[[0,7,26.48],[3,6.4,110.25],[4,6.2,109.98],[5,6,65.27],[7,5.8,135.41],[8,5.7,21.13],[9,5.6,26.5],[1,6.8,90.61],[2,6.6,73.56],[6,5.9,368.26]],"bdatl":[[2,8,30.41],[3,8.2,34.31],[4,8.4,31.02],[5,8.6,29.9],[6,8.8,71.43],[0,7.6,3.59],[1,7.8,54.22],[7,9,28.68],[8,9.2,32.67],[9,9.4,63.53]],"ltp":7.6,"tv":3220.14,"id":36276560},{"atb":[[23,9.86]],"atl":[[24,44.18]],"trd":[[24,46.47]],"bdatb":[[1,22,22.05],[2,21,33.3],[3,20,26.86],[4,19.5,21.66],[5,19,17.93],[6,18.5,14.83],[7,18,6.58],[8,17.5,8.86],[9,17,36.24],[0,23,9.86]],"bdatl":[[9,36,3.41],[0,24,44.18],[6,30,3.87],[8,34,6.87]],"tv":455.37,"id":37947503},{"atb":[[1.47,147.1],[1.55,90.28],[1.36,41.8],[1.41,114.31],[1.01,25236.12],[1.53,335.45],[1.51,400.54],[1.54,764.89],[1.52,318.96],[1.5,1092.07]],"atl":[[1.57,165.39],[1000,331.73],[1.56,108.91],[1.62,63.36],[1.58,65.12],[1.59,89.83],[1.61,85.75]],"trd":[[1.55,689.58],[1.56,335.84]],"bdatb":[[0,1.55,90.28],[8,1.47,283.24],[1,1.54,764.89],[2,1.53,353.3],[3,1.52,324.93],[4,1.51,593.39],[5,1.5,1216.36],[6,1.49,481.54],[7,1.48,437.05],[9,1.46,97.19]],"bdatl":[[4,1.6,57.96],[5,1.61,125.28],[7,1.63,819.34],[8,1.64,44.74],[1,1.57,165.39],[3,1.59,166.94],[9,1.65,98.76],[6,1.62,185.72],[0,1.56,108.91],[2,1.58,65.12]],"ltp":1.55,"tv":14377.89,"id":39823721},{"atb":[[1.01,102079.47],[70,2.47]],"atl":[[1000,19.79],[95,0]],"trd":[[95,25.89]],"bdatb":[[0,85,5],[3,70,2.47],[5,60,13.05],[6,55,3.67],[7,50,22.66],[9,46,12.28]],"bdatl":[[0,110,6.36],[1,190,7.22],[2,230,3.21],[3,340,5.01],[4,350,5.99],[5,390,3],[6,550,1.06],[7,570,1],[8,590,1],[9,610,1]],"tv":228.78,"id":44331354}],"con":true,"tv":20249.79}]}
{"op":"mcm","clk":"AK67AQD+nQEA3KEB","pt":1650392818529,"mc":[{"id":"1.197931750","rc":[{"atb":[[9.2,32.06],[8.8,31.88],[9,49.7],[8.6,29]],"atl":[[28,4.82],[9.8,12.23],[30,0],[9.6,8.5],[10,47.16]],"bdatb":[[4,8.6,51.1],[6,8.2,30.81],[7,8,89.77],[8,7.8,22.65],[9,7.6,25.3],[5,8.4,37.12],[2,9,49.7],[1,9.2,32.06],[3,8.8,31.88]],"bdatl":[[1,9.8,12.23],[3,10.5,54.42],[4,11,70.14],[6,12,40.66],[7,12.5,35.52],[8,13,17.21],[5,11.5,53.35],[9,13.5,27.19],[0,9.6,8.5],[2,10,47.16]],"id":42930960},{"atb":[[14,35.51],[15.5,14.42]],"atl":[[18,27.11],[17,35.78],[16,1.39],[16.5,37.08],[17.5,27.43]],"bdatb":[[5,13,36.84],[6,12.5,50.96],[7,12,20.34],[8,11.5,69.93],[9,11,193.34],[3,14,35.51],[0,15.5,14.42],[2,14.5,26.25],[4,13.5,41.03]],"bdatl":[[2,17,35.78],[4,18,27.11],[0,16,1.39],[3,17.5,29.49],[5,18.5,15.44],[6,19,25],[8,20,21.14],[1,16.5,37.08],[9,21,5.29]],"id":40095374},{"atb":[[7,51.98],[7.4,4.86],[7.2,13.96],[6,41.42],[6.2,107],[6.4,56.49],[6.8,88.5],[5.6,12.83]],"atl":[[7.6,25.58],[1000,81.55],[8,25.47],[7.8,39.95],[8.2,31.65],[7.4,0],[8.4,26.61]],"trd":[[7.4,217.84]],"bdatb":[[2,7,55.16],[3,6.8,113.18],[4,6.6,68.36],[5,6.4,121.16],[6,6.2,110.02],[7,6,52.35],[8,5.9,365.45],[9,5.8,139.38],[0,7.4,4.86],[1,7.2,13.96]],"bdatl":[[0,7.6,25.58],[1,7.8,45.58],[3,8.2,48.35],[2,8,25.47],[4,8.4,31.69],[5,8.6,44.3],[6,8.8,59.6],[7,9,26.28],[8,9.2,44.01],[9,9.4,59.07]],"ltp":7.4,"tv":3230.7,"id":36276560},{"atb":[[8.6,31.66],[23,7.86],[20,28.87]],"bdatb":[[8,17.5,14.54],[5,19,17.93],[6,18.5,17.77],[2,21,33.3],[3,20,28.87],[9,17,36.24],[0,23,7.86]],"bdatl":[[3,27,16.15],[7,32,7.32],[9,36,2.19]],"id":37947503},{"atb":[[1.34,226.88],[1.52,339.5],[1.53,410.35],[1.54,742.09],[1.55,28.31],[1.51,361.9],[1.01,25034.26],[1.5,1143.96],[1.47,83.49],[1.39,134.56],[1.44,1487.59]],"atl":[[1.57,192.43],[1.58,77.98],[1.55,0],[1.61,119.28],[1.62,29.83],[1.56,121.84]],"trd":[[1.55,748.78]],"bdatb":[[3,1.52,413.7],[5,1.5,1255.31],[6,1.49,479.64],[7,1.48,281.96],[0,1.55,28.31],[1,1.54,742.09],[2,1.53,463.68],[4,1.51,568.27],[8,1.47,304.65],[9,1.46,170.74]],"bdatl":[[1,1.57,215.33],[2,1.58,132.83],[5,1.61,291.26],[6,1.62,29.83],[7,1.63,791.17],[9,1.65,154.38],[3,1.59,98.55],[4,1.6,86.99],[0,1.56,121.84],[8,1.64,175.96]],"tv":14437.09,"id":39823721},{"atl":[[500,1],[550,0]],"bdatb":[[7,50,22.66],[9,46,13.46],[4,65,10.67],[6,55,3.67],[5,60,13.05]],"bdatl":[[6,500,1],[7,570,1.06],[1,190,7.41]],"id":44331354}],"con":true,"tv":20319.55}]}
{"op":"mcm","clk":"ANO8AQD4ngEA96IB","pt":1650392819530,"mc":[{"id":"1.197931750","rc":[{"atb":[[9.4,12.49]],"bdatb":[[8,7.8,47.03],[9,7.6,18.93],[0,9.4,12.49],[2,9,50.82],[3,8.8,45.62],[4,8.6,29.36],[6,8.2,55.93],[7,8,65.21]],"bdatl":[[7,12.5,41.09],[8,13,9.82],[5,11.5,50.47],[6,12,41.78],[4,11,72.66],[9,13.5,19.56],[3,10.5,53.67]],"id":42930960},{"atb":[[15.5,10.08],[14.5,12.93]],"atl":[[18,32.82],[16.5,42.46],[1000,57.59],[16,0.63],[17.5,25.42],[17,33.78]],"bdatb":[[0,15.5,10.08],[2,14.5,18.56],[5,13,28.74],[6,12.5,56],[7,12,31.66],[8,11.5,53.46],[9,11,210.62],[3,14,39.04],[4,13.5,34.98]],"bdatl":[[0,16.5,43.09],[7,20,21.28],[8,21,7.01],[1,17,33.78],[2,17.5,25.42],[3,18,27.11],[4,18.5,15.01],[5,19,26.89],[6,19.5,21.37],[9,22,16.43]],"id":40095374},{"atb":[[7.4,0],[6.6,66.64],[7,57.52],[7.2,18.25],[1.01,38246.86]],"atl":[[13.5,29.06],[7.6,19.77],[7.4,2.86],[8,37.1]],"bdatb":[[4,6.6,88.31],[5,6.4,107.82],[6,6.2,113.08],[7,6,52.36],[2,7,74.79],[1,7.2,19.65],[9,5.8,166.17],[3,6.8,98.86],[8,5.9,359.41]],"bdatl":[[5,8.6,49.84],[6,8.8,57.18],[8,9.2,45.44],[9,9.4,38.86],[0,7.6,17.65],[2,8,37.1],[3,8.2,50.71],[4,8.4,28.33],[7,9,23.56],[1,7.8,39.95]],"id":36276560},{"atb":[[8.6,34.51],[23,7.42]],"bdatb":[[2,21,33.78],[3,20,32.45],[8,17.5,8.52],[0,23,7.42],[5,19,19.36],[6,18.5,14.56]],"bdatl":[[9,36,2.26],[3,27,14.81],[7,32,8.19]],"id":37947503},{"atb":[[1.32,187.36],[1.49,506.89],[1.5,1092.07],[1.53,395.45],[1.54,727.86],[1.52,195.85],[1.01,24836.12],[1.55,0]],"atl":[[1.6,64.17],[1.61,85.75],[1.59,112.2],[1.57,194.44],[1.58,80.11],[1.56,136.84],[1000,328.1],[1.55,84.52]],"trd":[[1.54,1908.86],[1.55,805.4]],"bdatb":[[5,1.49,546.01],[9,1.45,168.31],[4,1.5,1243.58],[1,1.53,448.78],[0,1.54,727.86],[2,1.52,230.41],[6,1.48,272.33],[7,1.47,299.67],[8,1.46,170.74],[3,1.51,568.27]],"bdatl":[[5,1.6,66.23],[3,1.58,131.68],[4,1.59,143.59],[6,1.61,333.77],[9,1.64,147.89],[8,1.63,717.22],[1,1.56,136.84],[2,1.57,217.34],[7,1.62,29.83],[0,1.55,84.52]],"ltp":1.54,"tv":14496.23,"id":39823721},{"atl":[[520,1]],"bdatb":[[4,65,10.82],[6,55,4.97],[7,50,23.2],[9,46,12.16]],"bdatl":[[1,190,7.22]],"id":44331354}],"con":true,"tv":20378.69}]}
{"op":"mcm","clk":"AIG+AQDwnwEA/6MB","pt":1650392820532,"mc":[{"id":"1.197931750","rc":[{"atb":[[9.4,9.98],[9,53.04]],"atl":[[1000,68.31],[9.6,7.68],[10,49.56]],"trd":[[9.4,396.53],[9.6,163.58]],"bdatb":[[2,9,67.95],[3,8.8,36.49],[6,8.2,37.3],[7,8,54.39],[8,7.8,47.85],[0,9.4,9.98],[5,8.4,62.54],[9,7.6,18.86],[4,8.6,29]],"bdatl":[[3,10.5,54.67],[4,11,73.86],[8,13,4.47],[9,13.5,17.2],[7,12.5,45.45],[5,11.5,62.18],[6,12,28.57],[0,9.6,7.68],[2,10,49.56]],"ltp":9.4,"tv":1240.37,"id":42930960},{"atb":[[15.5,0],[14,29.77],[1.01,63011.33],[15,36.41]],"atl":[[19,33.09],[16.5,20.63],[1000,57.12],[17.5,27.43],[17,35.78],[16,28.78],[18.5,18.36]],"bdatb":[[0,15.5,3],[3,14,39.83],[4,13.5,37.99],[8,11.5,49.66],[9,11,212.55],[2,14.5,18.02],[6,12.5,52.12],[7,12,35.97],[1,15,36.41],[5,13,28.5]],"bdatl":[[6,19,29.94],[7,19.5,25.31],[9,21,5.08],[0,16,28.78],[2,17,35.78],[3,17.5,27.43],[1,16.5,26.01],[4,18,32.82],[5,18.5,18.36],[8,20,17.2]],"id":40095374},{"atb":[[7.2,18.25],[7,42.66],[6,41.42],[7.4,24.33],[6.2,107.04],[1.01,37378.59]],"atl":[[14.5,15.37],[1000,80.22],[7.6,17.65],[7.8,39.95],[8,44.29],[7.4,0],[8.8,29.35],[13.5,21.06],[9,19.75],[8.6,19.72]],"bdatb":[[2,7,57.1],[0,7.4,24.33],[6,6.2,113.85],[7,6,49.07],[1,7.2,30.49],[3,6.8,119.9],[4,6.6,77.59],[5,6.4,92.21],[8,5.9,378.47],[9,5.8,146.78]],"bdatl":[[3,8.2,43.1],[4,8.4,35.76],[6,8.8,52.52],[7,9,26.77],[8,9.2,40.34],[9,9.4,44.54],[0,7.6,17.65],[5,8.6,45.08],[1,7.8,39.95],[2,8,44.29]],"id":36276560},{"atb":[[19.5,25.01]],"bdatb":[[3,20,31.89],[6,18.5,16.75],[2,21,36.81],[8,17.5,9.42],[4,19.5,25.01],[5,19,16.76]],"bdatl":[[7,32,8.52],[8,34,8.26],[9,36,2.4]],"id":37947503},{"atb":[[1.53,411.94],[1.52,220.75]],"atl":[[1.61,83.61],[1.57,180.07],[1.55,112.75],[1.58,67.25]],"bdatb":[[1,1.53,499.61],[2,1.52,259.85],[3,1.51,538.67],[4,1.5,1244.5],[7,1.47,199.59],[8,1.46,181.78],[5,1.49,537.81],[6,1.48,369.1],[9,1.45,250.88]],"bdatl":[[2,1.57,209.69],[3,1.58,145.83],[6,1.61,249.33],[7,1.62,49.48],[8,1.63,683.75],[9,1.64,151.87],[4,1.59,118.11],[5,1.6,155.29],[0,1.55,112.75]],"id":39823721},{"atb":[[65,17.36]],"atl":[[610,0],[590,0],[570,0],[540,1]],"bdatb":[[6,55,4.77],[8,48,11.45],[4,65,18.5],[7,50,22.21]],"bdatl":[[7,520,1.06],[8,570,1],[9,590,1]],"id":44331354}],"con":true,"tv":20385.35}]}
{"op":"mcm","clk":"AKy/AQCSoQEAhaUB","pt":1650392821692,"mc":[{"id":"1.197931750","rc":[{"atb":[[9.6,3.85],[9.4,9.15],[8.4,35.11]],"atl":[[9.6,0],[9.8,9.77]],"trd":[[9.6,173]],"bdatb":[[0,9.4,16.32],[5,8.4,47.74],[6,8.2,30.28],[7,8,83.47],[8,7.8,20.99],[2,9,64.67],[3,8.8,47.16],[9,7.6,18.59]],"bdatl":[[6,12,35.6],[8,13,7.14],[0,9.6,4.71],[1,9.8,9.77],[4,11,66.74],[5,11.5,65.66],[9,13.5,11.55],[7,12.5,29.49],[3,10.5,50.24]],"ltp":9.6,"tv":1249.79,"id":42930960},{"atb":[[15.5,15.54],[13,30.7],[14.5,13.13],[14,29.61],[1.01,61603.63],[15,32.22]],"atl":[[16,19.08],[20,22.31],[1000,56.17],[70,0],[22,4.87],[19,27.7]],"trd":[[16,206.13]],"bdatb":[[6,12.5,59.1],[7,12,38.41],[9,11,194.21],[0,15.5,6.48],[1,15,33.7],[2,14.5,13.13],[3,14,34.86],[4,13.5,37.28],[5,13,41.04],[8,11.5,44.65]],"bdatl":[[8,20,21.5],[9,21,11.34],[0,16,23.68],[6,19,27.7],[7,19.5,21.37],[1,16.5,20.63]],"tv":738.3,"id":40095374},{"atb":[[1.01,37410.06],[7.4,32.56],[7,48.62],[7.2,30.3]],"atl":[[8.2,14.98],[8.6,22.58],[8,42.29],[7.8,16.69],[15.5,15.25],[7.6,1.81],[9.8,41.1]],"trd":[[7.6,417.86]],"bdatb":[[2,7,78.16],[3,6.8,93.47],[4,6.6,100.57],[5,6.4,60.14],[6,6.2,119.19],[7,6,94.23],[9,5.8,154.72],[0,7.4,38.67],[1,7.2,47.91],[8,5.9,359.41]],"bdatl":[[6,8.8,46.86],[7,9,24.58],[9,9.4,47.53],[0,7.6,8.87],[4,8.4,33.18],[5,8.6,39.67],[1,7.8,30.65],[8,9.2,26.82],[3,8.2,17.76]],"ltp":7.6,"tv":3244.81,"id":36276560},{"atb":[[23,16.34]],"atl":[[25,13.11],[24,42.82]],"trd":[[24,49.19]],"bdatb":[[9,17,40.5],[0,23,11.83],[1,22,23.06],[3,20,32.55],[4,19.5,26.6],[6,18.5,14.56],[7,18,14.05],[2,21,33.3],[8,17.5,8.34]],"bdatl":[[9,36,1.53],[8,34,6.87],[7,32,7.07]],"tv":458.09,"id":37947503},{"atb":[[1.52,208.71],[1.53,270.33],[1.5,1326.76],[1.51,213.27],[1.49,508.9],[1.01,24637.43],[1.54,0]],"atl":[[1.55,143.08],[1.54,138.47],[1.59,110.14],[1.56,138.84],[1.57,182.08]],"trd":[[1.53,3566.74],[1.54,3186.48]],"bdatb":[[0,1.53,321.48],[1,1.52,347.89],[2,1.51,370.79],[3,1.5,1413.28],[4,1.49,525.22],[5,1.48,315],[6,1.47,284.07],[7,1.46,166.46],[8,1.45,134.64],[9,1.44,1641.18]],"bdatl":[[1,1.55,155.21],[3,1.57,236.85],[4,1.58,158.65],[0,1.54,111.69],[2,1.56,158.55],[5,1.59,118.85],[6,1.6,200.52],[7,1.61,132.89],[8,1.62,136.92],[9,1.63,718.19]],"ltp":1.53,"tv":15838.16,"id":39823721},{"atb":[[90,0],[80,6.64],[1.01,100773.03],[70,2.47]],"atl":[[110,4.36],[560,1],[1000,19.64]],"trd":[[90,17.5]],"bdatb":[[2,80,8.72],[4,70,2.47],[0,90,3.06],[3,75,13.2],[6,60,14.28],[8,50,22.83],[9,48,10.6],[1,85,5],[5,65,17.36],[7,55,3.67]],"bdatl":[[9,1000,19.64],[8,540,1]],"ltp":90,"tv":232.78,"id":44331354}],"con":true,"tv":21761.93}]}
{"op":"mcm","clk":"AM7AAQCvogEAkqYB","pt":1650392822694,"mc":[{"id":"1.197931750","rc":[{"atb":[[9.6,4.12],[8.6,26.96],[9.2,37.81],[9,52.5]],"atl":[[9.8,7.86],[1000,67.57],[11.5,51.51],[10.5,48.23],[10,47.3]],"trd":[[9.8,85.98],[9.6,177.2]],"bdatb":[[0,9.6,4.12],[7,8.2,45.47],[8,8,52.55],[9,7.8,41.63],[3,9,54.03],[5,8.6,33],[4,8.8,51.21],[6,8.4,35.11],[2,9.2,37.81],[1,9.4,9.15]],"bdatl":[[8,13.5,12.21],[9,14,96],[4,11.5,55.98],[5,12,39.97],[6,12.5,30.35],[7,13,4.47],[0,9.8,7.86],[2,10.5,48.23],[3,11,73.58],[1,10,47.3]],"ltp":9.8,"tv":1257.81,"id":42930960},{"atb":[[14,27.61],[1.01,60243.24],[15,27.85],[14.5,16.2],[15.5,0]],"atl":[[60,0],[18.5,16.35],[16,21.37]],"bdatb":[[2,14,28.59],[0,15,27.85],[1,14.5,16.2],[6,12,30.12],[7,11.5,58.73],[8,11,194.6],[9,10.5,41.41],[3,13.5,39.67],[4,13,38.92],[5,12.5,54.77]],"bdatl":[[4,18,35.02],[6,19,32.22],[7,19.5,21.62],[9,21,4.63],[5,18.5,16.35],[0,16,21.37],[1,16.5,20.63],[8,20,22.31]],"id":40095374},{"atb":[[7.4,24.57],[7.2,34.27]],"atl":[[8.2,28.87],[8,42.29],[7.6,1.81],[7.8,21.82],[9.8,29.74]],"trd":[[7.4,227.84]],"bdatb":[[0,7.4,24.57],[3,6.8,106.82],[4,6.6,95.37],[5,6.4,63.84],[6,6.2,120.81],[8,5.9,365.06],[9,5.8,135.8],[1,7.2,44.97],[2,7,71.3],[7,6,70.47]],"bdatl":[[9,9.4,40.03],[3,8.2,44.18],[4,8.4,27.19],[5,8.6,22.58],[6,8.8,62.01],[8,9.2,32.08],[2,8,42.29],[7,9,20.55],[0,7.6,1.81],[1,7.8,21.82]],"ltp":7.4,"tv":3254.81,"id":36276560},{"atb":[[8.6,34.27],[23,13.9]],"atl":[[25,16.42],[24,40.59]],"trd":[[24,53.65]],"bdatb":[[5,19,20.09],[7,18,12.51],[3,20,29.56],[9,17,39.3],[0,23,13.9],[1,22,22.05],[4,19.5,25.01],[2,21,33.3]],"bdatl":[[7,32,8.3],[8,34,9.39],[9,42,7.2],[5,29,8.53],[0,24,40.59],[1,25,16.42]],"tv":462.55,"id":37947503},{"atb":[[1.53,252.62],[1.51,364.04],[1.52,223.76],[1.5,1326.76],[1.54,84.67],[1.01,24261.62],[1.56,0]],"atl":[[1.55,52.14],[1000,314.62],[1.56,79.83],[1.57,156.17],[1.58,67.13],[1.59,112.2],[1.61,85.75],[1.6,66.18],[1.54,0]],"trd":[[1.55,1341.36],[1.53,3566.76],[1.56,722.93],[1.54,3463.42]],"bdatb":[[1,1.53,261.61],[6,1.48,374.19],[7,1.47,229.84],[9,1.45,193.08],[3,1.51,468.73],[4,1.5,1465.43],[5,1.49,540.48],[8,1.46,131.03],[0,1.54,84.67],[2,1.52,335.7]],"bdatl":[[2,1.57,181.36],[3,1.58,157.15],[4,1.59,198.93],[5,1.6,134.19],[6,1.61,113.59],[7,1.62,140.49],[8,1.63,735.82],[9,1.64,131.58],[1,1.56,79.83],[0,1.55,152.14]],"ltp":1.55,"tv":17038.17,"id":39823721},{"atb":[[1.01,97901.18]],"atl":[[100,5.97],[110,2.36]],"bdatb":[[8,48,11.92],[6,55,3.92],[2,75,12.9],[5,60,13.05],[7,50,22.21],[9,46,12.16],[0,85,5],[1,80,6.64],[3,70,2.47],[4,65,17.36]],"bdatl":[[0,100,5.97],[1,110,2.36],[4,340,5.01],[2,190,7.22],[3,230,3.21],[5,350,5.99],[6,390,3],[7,500,1],[8,520,1.06],[9,540,1]],"id":44331354}],"con":true,"tv":22984.42}]}
{"op":"mcm","clk":"APXBAQCtowEAkKcB","pt":1650392823696,"mc":[{"id":"1.197931750","rc":[{"atb":[[9.4,8.58],[9.2,34.08],[9,48.97]],"atl":[[11.5,54.86],[10.5,61.18],[10,39.12]],"bdatb":[[7,8.2,40.04],[8,8,67.19],[9,7.8,39.63],[4,8.8,32.02],[6,8.4,55.22],[1,9.4,8.58],[2,9.2,34.08],[3,9,56.09],[5,8.6,26.96]],"bdatl":[[4,11.5,60.95],[3,11,67.21],[5,12,27.8],[6,12.5,37.44],[7,13,12.57],[8,13.5,10.92],[9,14,88.09],[2,10.5,61.18],[1,10,39.12]],"id":42930960},{"atl":[[1000,55.7],[16,26.96]],"bdatb":[[6,12,26.42],[7,11.5,58.04],[9,10.5,47.59],[3,13.5,35.07],[4,13,30.7],[5,12.5,64.13],[8,11,192.08],[2,14,32.19]],"bdatl":[[6,19,28.79],[8,20,25.31],[7,19.5,21.37],[9,21,5.12],[0,16,26.96]],"id":40095374},{"atb":[[7.4,8.16],[7.2,22.22],[7,39.36]],"atl":[[8.4,39.01],[9.8,17.7],[8.2,31.85],[8,44.3],[7.6,8.43]],"trd":[[7.4,237.83]],"bdatb":[[3,6.8,123.39],[4,6.6,89.96],[5,6.4,73.59],[6,6.2,124.15],[7,6,70.23],[8,5.9,360.35],[9,5.8,140.6],[0,7.4,8.16],[1,7.2,31.29],[2,7,41.03]],"bdatl":[[4,8.4,40.23],[2,8,44.3],[3,8.2,46.51],[9,9.4,44.67],[0,7.6,8.43],[8,9.2,27.77]],"tv":3264.8,"id":36276560},{"atb":[[2.06,1],[20,28.61],[21,35.52]],"bdatb":[[3,20,31.82],[2,21,35.52],[5,19,16.83],[7,18,6.58],[8,17.5,9.01],[9,17,45.49]],"bdatl":[[8,34,7.48],[9,38,1.57]],"id":37947503},{"atb":[[1.52,273.76],[1.53,255.26]],"atl":[[1.56,159.59],[1000,317.51],[1.57,167.8],[1.55,42.14]],"trd":[[1.55,1361.36]],"bdatb":[[9,1.45,290.18],[6,1.48,435.56],[7,1.47,168.06],[1,1.53,297.13],[2,1.52,385.7],[8,1.46,168.15],[3,1.51,494.64],[4,1.5,1351.3],[5,1.49,595.35]],"bdatl":[[1,1.56,159.59],[3,1.58,80.3],[4,1.59,212.8],[5,1.6,128.28],[6,1.61,156.58],[7,1.62,68.18],[8,1.63,760.7],[9,1.64,158.88],[0,1.55,42.14],[2,1.57,192.99]],"tv":17058.17,"id":39823721},{"bdatb":[[8,48,10.63],[6,55,4.84]],"id":44331354}],"con":true,"tv":23014.41}]}
{"op":"mcm","clk":"AJzDAQC8pAEAqagB","pt":1650392824697,"mc":[{"id":"1.197931750","rc":[{"atl":[[16,17.19]],"bdatb":[[9,10.5,48.53]],"bdatl":[[0,16,17.19],[6,19,29.36],[8,20,24.76]],"id":40095374},{"atb":[[7.4,9.63]],"trd":[[7.4,247.83]],"bdatb":[[6,6.2,110.01],[7,6,81.63],[0,7.4,9.63],[5,6.4,76.61],[8,5.9,363.88],[9,5.8,137.01]],"tv":3274.8,"id":36276560},{"atb":[[2.06,0.25],[21,35.77]],"bdatb":[[2,21,35.77]],"bdatl":[[8,34,7.8],[9,38,1.29]],"id":37947503},{"atb":[[1.36,19.67],[1.52,292.42]],"atl":[[1.57,181.07]],"bdatb":[[3,1.51,391.06],[4,1.5,1455.56],[9,1.45,188.09],[2,1.52,404.37]],"bdatl":[[3,1.58,87.2],[5,1.6,121.47],[7,1.62,74.9],[8,1.63,754.02],[2,1.57,206.26]],"id":39823721},{"atl":[[500,0],[470,1]],"bdatl":[[7,470,1]],"id":44331354},{"bdatb":[[8,8,52.55],[9,7.8,56.05]],"bdatl":[[3,11,68.2],[4,11.5,60],[5,12,28.71],[6,12.5,36.57],[8,13.5,11.72],[9,14,87.31]],"id":42930960}],"con":true,"tv":23024.41}]}
{"op":"mcm","clk":"AMHEAQDFpQEAtqkB","pt":1650392825699,"mc":[{"id":"1.197931750","rc":[{"atb":[[9.6,1.75]],"bdatb":[[0,9.6,1.75],[9,7.8,55.29],[8,8,54.14],[2,9.2,34.23],[4,8.8,39],[7,8.2,38.03],[3,9,48.97],[5,8.6,28.52],[6,8.4,48.13]],"bdatl":[[6,12.5,29.49],[7,13,16.34],[9,14,88.96],[3,11,74.39],[4,11.5,55.69],[5,12,30.46],[8,13.5,14.14]],"id":42930960},{"atb":[[11,197.08],[13,32.8],[1.01,59571.76]],"atl":[[15.5,0.42],[16,11.6],[18,30.81],[17,37.78],[16.5,22.63]],"trd":[[15.5,64.63]],"bdatb":[[4,13,32.8],[2,14,27.71],[3,13.5,39.62],[6,12,25.04],[7,11.5,63.6],[9,10.5,43.07],[5,12.5,60.44]],"bdatl":[[5,18,31.74],[8,19.5,23.52],[1,16,11.6],[7,19,31.94],[9,20,22.31],[2,16.5,22.63],[3,17,37.78],[0,15.5,5],[4,17.5,27.43],[6,18.5,16.35]],"ltp":15.5,"tv":747.46,"id":40095374},{"atb":[[7.2,25.21],[7,43.71],[7.4,18.83]],"atl":[[9.8,29.06],[8.2,17.96],[7.8,15.74]],"bdatb":[[5,6.4,66.37],[6,6.2,123.58],[7,6,71.16],[2,7,54.58],[0,7.4,18.83],[1,7.2,18.45],[3,6.8,113.93],[4,6.6,99.65],[8,5.9,359.41],[9,5.8,153.67]],"bdatl":[[3,8.2,29.85],[4,8.4,45.13],[6,8.8,59.13],[7,9,20.5],[8,9.2,27.61],[9,9.4,47.57],[1,7.8,15.74]],"id":36276560},{"atb":[[23,7.42],[21,36.02],[2.06,0],[8.6,31.66]],"atl":[[28,19.74]],"bdatb":[[0,23,7.42],[2,21,36.09],[4,19.5,28.22],[7,18,7.3],[3,20,28.61],[5,19,16.76],[8,17.5,8.37],[9,17,42.68]],"bdatl":[[7,32,7.59],[9,36,1.16],[4,28,19.74],[8,34,9.24]],"id":37947503},{"atb":[[1.52,436.08],[1.54,96.67],[1.34,168.31]],"atl":[[1.57,179.06],[1.58,64.88],[1000,328.78],[1.55,0.91]],"trd":[[1.55,1443.82]],"bdatb":[[2,1.52,508.33],[3,1.51,414.54],[4,1.5,1463.52],[6,1.48,326.58],[7,1.47,306.43],[9,1.45,226.06],[0,1.54,96.67],[8,1.46,139.3],[1,1.53,305.6]],"bdatl":[[1,1.57,189.76],[2,1.58,142.41],[3,1.59,131.92],[4,1.6,128.7],[5,1.61,177.11],[6,1.62,127.9],[8,1.64,145.01],[9,1.65,179.78],[7,1.63,711.13],[0,1.56,160.5]],"tv":17140.63,"id":39823721},{"atl":[[140,3.35],[490,1]],"bdatb":[[4,65,17.38],[7,50,23.47],[6,55,3.67],[8,48,10.6]],"bdatl":[[2,140,3.64],[3,190,6.93],[4,230,3.21],[5,340,5.01],[6,350,5.99],[7,390,3],[8,470,1],[9,490,1]],"id":44331354}],"con":true,"tv":23116.03}]}
{"op":"mcm","clk":"AOHFAQDNpgEAw6oB","pt":1650392826700,"mc":[{"id":"1.197931750","rc":[{"atb":[[9.2,34.08],[8.6,38.83],[9,48.97],[9.4,13.54],[9.6,2.3],[1.01,54404.45]],"atl":[[1000,66.9],[9.8,5.86]],"trd":[[9.4,406.53]],"bdatb":[[3,9,56.09],[4,8.8,36.7],[6,8.4,44.67],[8,8,54.36],[9,7.8,38.03],[0,9.6,2.3],[1,9.4,13.54],[2,9.2,32.06],[5,8.6,29],[7,8.2,49.09]],"bdatl":[[2,10.5,61.42],[3,11,69.8],[7,13,10.28],[8,13.5,22.73],[4,11.5,63.48],[5,12,27.17],[9,14,86.3],[0,9.8,5.86]],"ltp":9.4,"tv":1267.81,"id":42930960},{"atb":[[15.5,14.83],[14,35.51],[13,45.03],[14.5,18.4],[1.01,59257.6]],"atl":[[1000,54.58],[60,3.36],[16,9.31],[15.5,0],[18,32.82],[17,35.78],[16.5,20.63]],"trd":[[15.5,65.47]],"bdatb":[[5,13,50.5],[6,12.5,57.04],[7,12,33.8],[9,11,205.55],[2,14.5,18.4],[3,14,33.87],[0,15.5,12.3],[1,15,27.85],[4,13.5,35.47],[8,11.5,44.65]],"bdatl":[[4,18,32.96],[7,19.5,22.37],[0,16,9.31],[6,19,27.7],[9,21,7.93],[1,16.5,20.63],[2,17,35.78],[3,17.5,27.43],[5,18.5,16.35],[8,20,22.31]],"tv":748.3,"id":40095374},{"atb":[[7.4,12.36]],"atl":[[8.6,19.72]],"bdatb":[[2,7,50.73],[3,6.8,122.99],[4,6.6,68.83],[5,6.4,71.04],[6,6.2,134.51],[8,5.9,389.51],[9,5.8,135.55],[0,7.4,12.36],[7,6,71.03],[1,7.2,33.19]],"bdatl":[[2,8,44.62],[3,8.2,20.34],[6,8.8,47.29],[8,9.2,37.23],[4,8.4,54.17],[5,8.6,24.52],[7,9,19.75],[9,9.4,35.4]],"id":36276560},{"atb":[[23,9.86],[21,35.52],[8.6,34.27]],"bdatb":[[7,18,8.94],[9,17,38.74],[0,23,9.86],[2,21,35.52],[3,20,31.49],[4,19.5,25.35],[6,18.5,14.56],[8,17.5,8.34]],"bdatl":[[5,29,8.62],[8,34,7.44],[7,32,7.07],[9,36,1.93]],"id":37947503},{"atb":[[1.52,290.18],[1.51,361.86],[1.54,0],[1.53,226.13],[1.49,508.89],[1.5,1328.76],[1.01,24073.47],[1.32,94.02]],"atl":[[1.61,183.61],[1.58,80.15],[1000,328.44],[1.55,68.74],[1.73,0],[1.57,167.8],[1.56,159.59],[1.54,0],[1.6,64.17]],"trd":[[1.55,1481.74],[1.54,3663.42]],"bdatb":[[0,1.54,1.67],[2,1.52,352.54],[3,1.51,242.75],[9,1.45,119.64],[1,1.53,263.66],[5,1.49,571.05],[4,1.5,1503.3],[6,1.48,364.28],[7,1.47,306.43],[8,1.46,125.88]],"bdatl":[[0,1.55,68.74],[9,1.64,129.13],[1,1.56,159.59],[2,1.57,226.03],[3,1.58,149.09],[4,1.59,160.89],[5,1.6,93.03],[6,1.61,273.64],[7,1.62,29.83],[8,1.63,746.16]],"ltp":1.55,"tv":17378.55,"id":39823721},{"atl":[[100,3.41],[510,1.06],[560,0],[540,0],[520,0]],"bdatb":[[0,85,5],[4,65,17.36],[6,55,4.72],[7,50,22.35],[9,46,12.16]],"bdatl":[[5,340,5.02],[0,100,3.41]],"id":44331354}],"con":true,"tv":23364.79}]}
{"op":"mcm","clk":"APvGAQDXpwEAyasB","pt":1650392827701,"mc":[{"id":"1.197931750","rc":[{"atb":[[8.4,33.1],[8.8,28.94],[9.8,3.81],[10,6.81],[8.6,36.79],[9.4,17.75],[7.6,273.91],[9.2,36.1],[1.01,54019.91],[9,48.97],[7.2,7.51],[9.6,11.62],[8.2,37.22],[7,148.34]],"atl":[[10,0],[10.5,46.22],[1000,66.02],[14.5,74.63],[14,15.3],[12,22.35],[11,59.71],[9.8,0]],"trd":[[10,80.95],[9.8,92.97]],"bdatb":[[0,9.6,17.35],[1,9.4,24.12],[2,9.2,36.1],[3,9,71.16],[4,8.8,38.59],[5,8.6,38.83],[6,8.4,67.15],[7,8.2,41.75],[8,8,61.11],[9,7.8,27.35]],"bdatl":[[0,10,11.88],[1,10.5,46.22],[4,12,30.51],[5,12.5,29.7],[6,13,24.8],[8,14,16.09],[9,14.5,92.34],[2,11,59.71],[7,13.5,5.67],[3,11.5,54.86]],"ltp":10,"tv":1309.73,"id":42930960},{"atb":[[15.5,23.14],[15,30.03],[14.5,23.31],[16,9.28],[11,10.08],[10.5,226.12],[13,34.77]],"atl":[[18,26.94],[16.5,17.34],[1000,53.72],[17.5,25.42],[17,33.78],[24,10.55],[22,49.87],[18.5,18.36],[16,0]],"trd":[[16.5,150.12],[16,214.84]],"bdatb":[[5,13.5,34.98],[0,16,6.28],[1,15.5,18.38],[2,15,31.84],[3,14.5,21.11],[4,14,35.79],[6,13,53.62],[7,12.5,50.62],[8,12,39.77],[9,11.5,47.16]],"bdatl":[[1,17,35.78],[2,17.5,27.43],[9,22,49.87],[0,16.5,12.15],[3,18,32.82],[5,19,27.7],[6,19.5,21.37],[7,20,22.31],[4,18.5,18.36],[8,21,4.63]],"ltp":16.5,"tv":774.19,"id":40095374},{"atb":[[7,13.99],[6.8,78.62],[6,41.42],[6.2,112.89],[5.9,20.41],[5.7,370.78],[1.01,36310.54],[7.4,0],[7.2,0]],"atl":[[7.2,106.92],[7.6,35.15],[7.4,17.05],[8.2,28.87],[1000,107],[9.8,17.7],[10.5,22.72],[9.6,116.84],[8.4,36.22],[7.8,31.36],[8,46.83]],"trd":[[7.2,254],[7,108.41],[7.4,272.55]],"bdatb":[[0,7,21.85],[1,6.8,87.42],[2,6.6,67.23],[3,6.4,94.77],[4,6.2,151.65],[5,6,46.23],[6,5.9,26.71],[7,5.8,147.22],[8,5.7,383.09],[9,5.6,32.15]],"bdatl":[[1,7.4,19.49],[0,7.2,109.59],[2,7.6,43.88],[5,8.2,42.48],[6,8.4,56.09],[7,8.6,25.76],[8,8.8,33.26],[3,7.8,31.36],[4,8,46.83],[9,9,20.97]],"ltp":7.2,"tv":3466.88,"id":36276560},{"atb":[[8.6,34.39],[19.5,28.35],[23,16.34]],"atl":[[24,24.98],[28,23.08],[27,8.6]],"trd":[[24,70.69]],"bdatb":[[5,19,16.76],[1,22,24.55],[2,21,38.37],[3,20,28.61],[4,19.5,28.55],[7,18,11.11],[8,17.5,14.86],[9,17,38.34],[0,23,16.34]],"bdatl":[[3,27,8.6],[0,24,27.92],[9,40,2.45],[8,34,6.87],[5,29,8.53]],"tv":479.59,"id":37947503},{"atb":[[1.52,221.52],[1.51,215.39],[1.49,508.89],[1.54,0],[1.43,2379.12],[1.01,23517.61],[1.44,98.59],[1.53,238.43],[1.3,150.05]],"atl":[[1.54,41.62],[1000,318.24],[1.59,145.22],[1.65,672.16],[1.55,74.09],[1.63,51.53],[1.76,100],[1.56,159.59],[1.61,83.61],[1.57,171.41],[1.58,66.88]],"trd":[[1.54,4053.67],[1.55,1524.77]],"bdatb":[[0,1.54,35.71],[1,1.53,280.11],[2,1.52,426.02],[3,1.51,385.51],[4,1.5,1452.07],[5,1.49,576.14],[6,1.48,441.63],[7,1.47,206.16],[8,1.46,93.82],[9,1.45,263.55]],"bdatl":[[0,1.55,74.09],[6,1.61,144.1],[3,1.58,128.87],[4,1.59,120.74],[5,1.6,168.47],[7,1.62,188.32],[8,1.63,51.53],[9,1.64,162.92],[1,1.56,159.59],[2,1.57,171.41]],"ltp":1.54,"tv":17811.83,"id":39823721},{"atb":[[85,8.99],[40,5.84],[36,77.09],[70,2.47]],"atl":[[1000,19.36],[100,0],[390,0],[300,3],[530,1]],"trd":[[100,27.87]],"bdatb":[[7,50,22.21],[3,70,4.11],[0,85,8.99],[6,55,3.74],[1,80,6.64],[5,60,13.05]],"bdatl":[[0,110,2.91],[1,140,3.64],[2,190,6.93],[3,230,3.21],[4,300,3],[7,470,1],[8,490,1],[9,510,1.06],[5,340,5.01]],"ltp":100,"tv":236.19,"id":44331354}],"con":true,"tv":24078.41}]}
{"op":"mcm","clk":"AKnIAQDfqAEA2KwB","pt":1650392828702,"mc":[{"id":"1.197931750","rc":[{"atb":[[9,49.46],[9.8,5.81],[9.6,15.93],[8.8,19.86],[1.01,52338.96],[9.2,31.57],[9.4,19.76],[10,9.88]],"atl":[[10.5,44.22],[1000,62.36],[13.5,13.67],[12,24.35],[32,7.11],[11,49.7],[12.5,31.5],[11.5,52.85],[28,0]],"trd":[[10,83.19]],"bdatb":[[5,9,77.49],[1,9.8,14.27],[2,9.6,15.93],[8,8.4,64.73],[9,8.2,37.22],[6,8.8,19.86],[7,8.6,37.56],[3,9.4,34.62],[4,9.2,31.57],[0,10,9.88]],"bdatl":[[4,12.5,44.16],[5,13,5.67],[6,13.5,27.07],[7,14,25.31],[8,14.5,74.63],[0,10.5,44.22],[3,12,26.1],[9,15,10.73],[1,11,49.7],[2,11.5,52.85]],"tv":1311.97,"id":42930960},{"atb":[[15,29.89],[14.5,28.85],[16,12.18],[13.5,34.78],[1.01,58629.28]],"atl":[[65,3.21],[60,0],[16.5,13.67],[23,9.03]],"trd":[[16,237.54]],"bdatb":[[0,16,12.18],[2,15,35.42],[3,14.5,28.85],[1,15.5,23.14],[4,14,45.49],[5,13.5,34.78],[6,13,53.37],[7,12.5,51.46],[8,12,20.3],[9,11.5,67.75]],"bdatl":[[0,16.5,13.67],[8,21,5.63],[9,22,49.87],[1,17,33.78],[2,17.5,25.42],[3,18,26.94]],"ltp":16,"tv":796.89,"id":40095374},{"atb":[[7,3],[5.9,31.74]],"atl":[[11,18.22],[8.6,23.86],[8,28.01],[7.4,28.3]],"trd":[[7,125.32]],"bdatb":[[3,6.4,94.26],[4,6.2,114.6],[5,6,86.8],[6,5.9,31.74],[1,6.8,90.81],[2,6.6,87.79],[7,5.8,153.63],[8,5.7,370.78],[9,5.6,36.22],[0,7,3]],"bdatl":[[4,8,35.12],[5,8.2,31.74],[6,8.4,38.08],[7,8.6,37.09],[9,9,22.14],[3,7.8,44.02],[8,8.8,50.46],[1,7.4,28.3],[2,7.6,35.15],[0,7.2,106.92]],"ltp":7,"tv":3483.79,"id":36276560},{"atl":[[24,20.06],[25,15.11]],"trd":[[24,80.53]],"bdatb":[[4,19.5,35.51],[6,18.5,14.56],[7,18,6.74],[8,17.5,21.98],[2,21,39.47],[3,20,28.61],[9,17,36.24],[1,22,22.05]],"bdatl":[[9,40,2.53],[0,24,20.06],[1,25,15.11],[4,28,23.08]],"tv":489.43,"id":37947503},{"atb":[[1.52,221.52],[1.34,116.24],[1.53,117.17],[1.51,215.39],[1.3,2.51],[1.32,11.03],[1.01,23169.27],[1.36,0]],"atl":[[1000,308.86],[1.54,53.84],[1.55,90.09],[1.59,143.16],[1.56,161.76],[1.57,173.42]],"trd":[[1.53,3620.73]],"bdatb":[[1,1.52,526.99],[2,1.51,226.78],[3,1.5,1520.97],[6,1.47,102.01],[7,1.46,235.89],[9,1.44,187.34],[4,1.49,568.92],[5,1.48,348.9],[0,1.53,117.17],[8,1.45,278.76]],"bdatl":[[4,1.58,152.16],[5,1.59,239.33],[7,1.61,193.95],[8,1.62,31.16],[6,1.6,106.15],[9,1.63,192.15],[0,1.54,53.84],[1,1.55,90.09],[2,1.56,161.76],[3,1.57,186.8]],"ltp":1.53,"tv":17865.8,"id":39823721},{"atb":[[85,8.89],[70,2.47]],"atl":[[110,4.36]],"trd":[[85,7.99]],"bdatb":[[0,85,8.89],[7,50,25.01],[8,48,10.6],[3,70,3.65],[5,60,13.05],[6,55,3.67]],"bdatl":[[0,110,4.36]],"ltp":85,"tv":236.39,"id":44331354}],"con":true,"tv":24184.27}]}
{"op":"mcm","clk":"ANPJAQDxqQEA160B","pt":1650392829704,"mc":[{"id":"1.197931750","rc":[{"atb":[[1.01,55379.34],[9.8,12.19],[10,10.88],[9.6,22.13]],"atl":[[10.5,47.42],[11,54.83],[11.5,77.75]],"bdatb":[[9,8.2,63.22],[3,9.4,37.91],[4,9.2,31.57],[5,9,57.86],[6,8.8,33.09],[7,8.6,51.06],[2,9.6,30.63],[8,8.4,36.48],[1,9.8,12.19],[0,10,10.88]],"bdatl":[[2,11.5,77.75],[3,12,39.29],[8,14.5,75.92],[4,12.5,31.5],[9,15,8.09],[1,11,54.83],[6,13.5,34.67],[7,14,15.3],[5,13,8.56]],"id":42930960},{"atb":[[16,12.18],[14.5,20.87],[15.5,25.69]],"atl":[[16.5,26.92],[17.5,27.77],[17,31.35],[1000,53.31]],"bdatb":[[3,14.5,26.5],[6,13,40.59],[7,12.5,61.54],[9,11.5,51.61],[2,15,29.89],[4,14,35.51],[5,13.5,47.41],[8,12,23.99],[1,15.5,25.69],[0,16,14.53]],"bdatl":[[0,16.5,26.92],[7,20,22.31],[9,22,54.82],[1,17,31.35],[2,17.5,27.77],[8,21,4.63]],"id":40095374},{"atb":[[1.01,36037.23],[7,0],[6.4,62.89]],"atl":[[7.2,112.29],[9.8,8.83],[8.2,37.57],[7.6,53.44],[7.4,34.91]],"trd":[[7.2,260.74]],"bdatb":[[5,5.9,72.43],[6,5.8,136.84],[1,6.6,92.47],[2,6.4,92.89],[3,6.2,116.15],[7,5.7,389.32],[8,5.6,17.8],[9,5.5,9.38],[0,6.8,90.62],[4,6,63.25]],"bdatl":[[0,7.2,112.29],[5,8.2,43.75],[6,8.4,36.53],[9,9,27.49],[3,7.8,54.34],[4,8,28.01],[7,8.6,48.08],[8,8.8,37.9],[1,7.4,34.91],[2,7.6,53.44]],"ltp":7.2,"tv":3490.53,"id":36276560},{"atb":[[8.8,2.65],[19.5,23.53],[22,25.4],[21,41.3],[17.5,5.31],[24,9.58],[8.6,31.66],[16.5,4.26]],"atl":[[27,9.94],[1000,40.58],[29,10.56],[28,25.09],[26,9.2],[25,13.11],[24,0]],"trd":[[24,88.42]],"bdatb":[[2,22,25.4],[3,21,45.18],[5,19.5,40],[9,17.5,6.46],[7,18.5,14.56],[8,18,17.24],[0,24,9.58],[1,23,16.34],[4,20,28.61],[6,19,16.76]],"bdatl":[[2,27,9.94],[0,25,13.11],[1,26,9.2],[3,28,25.09],[4,29,10.56],[8,40,2.72],[5,30,3.87],[6,32,7.07],[7,34,6.87],[9,42,5.84]],"tv":497.32,"id":37947503},{"atb":[[1.01,22997.88],[1.48,316.64],[1.49,457]],"atl":[[1.54,52.14],[1.59,176.69],[1.6,30.64],[1.56,219.96],[1.57,158.18],[1.55,110.02]],"trd":[[1.54,4057.06]],"bdatb":[[4,1.49,637.17],[5,1.48,416.97],[7,1.46,352.43],[8,1.45,278.76],[9,1.44,254.19],[1,1.52,513.72],[2,1.51,228.74],[3,1.5,1397.13],[6,1.47,140.4]],"bdatl":[[0,1.54,52.99],[2,1.56,219.96],[3,1.57,227.48],[6,1.6,89.32],[7,1.61,127.78],[8,1.62,45.24],[4,1.58,142.52],[5,1.59,310.29],[9,1.63,227.13],[1,1.55,110.02]],"ltp":1.54,"tv":17869.19,"id":39823721},{"atb":[[85,6.89]],"trd":[[85,11.99]],"bdatb":[[8,48,14.16],[5,60,14.41],[3,70,2.47],[7,50,22.21],[0,85,6.89]],"tv":240.39,"id":44331354}],"con":true,"tv":24206.29}]}
{"op":"mcm","clk":"AO3KAQCAqwEA964B","pt":1650392830705,"mc":[{"id":"1.197931750","rc":[{"atb":[[10,10.05],[8.6,34.75]],"trd":[[10,84.85]],"bdatb":[[0,10,10.05],[7,8.6,51.86],[2,9.6,30.22],[5,9,58.29],[9,8.2,63.7],[8,8.4,33.1]],"bdatl":[[2,11.5,78.78],[3,12,38.29],[8,14.5,77.68],[0,10.5,47.42],[5,13,8.37],[6,13.5,34.86]],"tv":1313.63,"id":42930960},{"atl":[[18.5,23.91]],"bdatb":[[3,14.5,26.23],[6,13,40.89],[9,11.5,51.27],[0,16,12.18],[7,12.5,64.23],[8,12,21.19]],"bdatl":[[7,20,22.91],[9,22,53.9],[4,18.5,23.91]],"id":40095374},{"atb":[[7,1.7],[1.01,36034.39],[6.8,80.62],[6,45.09],[6.6,67.03]],"bdatb":[[0,7,1.7],[1,6.8,92.04],[2,6.6,92.87],[3,6.4,93.5],[4,6.2,121.57],[5,6,60.66],[6,5.9,73.84],[7,5.8,135.41],[8,5.7,389.32],[9,5.6,18.51]],"bdatl":[[5,8.2,42.54],[6,8.4,37.4],[7,8.6,47.41],[8,8.8,38.84]],"id":36276560},{"atb":[[2.06,0],[23,17.38],[22,28.7],[21,33.09],[20,31.24]],"atl":[[26,14.36]],"bdatb":[[3,21,36.79],[8,18,17.46],[1,23,17.38],[2,22,28.7],[4,20,31.24],[5,19.5,32.28],[9,17.5,7.34]],"bdatl":[[8,40,2.54],[1,26,14.36]],"id":37947503},{"atb":[[1.01,22996.19],[1.51,222.63]],"atl":[[1.54,50.44],[1000,311.8]],"trd":[[1.54,4060.45]],"bdatb":[[3,1.5,1464.17],[5,1.48,326.32],[2,1.51,258.24],[6,1.47,163.26],[7,1.46,329.42]],"bdatl":[[2,1.56,227.6],[3,1.57,214.61],[6,1.6,110.45],[7,1.61,104.08],[8,1.62,45.33],[0,1.54,50.44],[9,1.63,229.7]],"tv":17872.58,"id":39823721},{"bdatb":[[5,60,14.35]],"id":44331354}],"con":true,"tv":24211.34}]}
{"op":"mcm","clk":"AJ7MAQCJrAEAirAB","pt":1650392831706,"mc":[{"id":"1.197931750","rc":[{"atb":[[10,12.32],[9.6,30.05],[8.8,30.05],[9.8,22.38]],"atl":[[10.5,43.06]],"bdatb":[[0,10,15.46],[2,9.6,34.06],[5,9,57.35],[6,8.8,53.2],[7,8.6,42.7],[8,8.4,33.1],[9,8.2,67],[1,9.8,22.38]],"bdatl":[[3,12,39.03],[5,13,8.6],[6,13.5,34.63],[8,14.5,76.13],[0,10.5,43.06],[2,11.5,77.75]],"id":42930960},{"atl":[[16.5,32.23],[20,9.54],[19.5,29.24],[19,19.61],[18,21.23]],"bdatb":[[3,14.5,23.53],[6,13,40.24],[7,12.5,61.87],[9,11.5,50.6],[8,12,25],[1,15.5,27.72]],"bdatl":[[0,16.5,32.23],[9,22,55.47],[7,20,9.54],[3,18,21.23],[5,19,19.61],[6,19.5,29.24]],"id":40095374},{"atb":[[1.01,34931.54],[6.4,65.88],[7,0],[6.8,78.62]],"atl":[[7.2,110.61],[7.6,64.34],[7.4,43.03],[8,24.01],[7,4.49],[1000,106.56]],"trd":[[7,128.72]],"bdatb":[[0,6.8,88.91],[2,6.4,98.95],[4,6,57.15],[5,5.9,73.84],[8,5.6,21.07],[3,6.2,122.43],[9,5.5,21.17],[1,6.6,92.87],[6,5.8,135.41],[7,5.7,389.32]],"bdatl":[[1,7.2,110.61],[7,8.4,49.63],[8,8.6,43.67],[2,7.4,43.03],[3,7.6,64.34],[4,7.8,53.95],[6,8.2,44.12],[9,8.8,37.61],[5,8,24.01],[0,7,4.49]],"ltp":7,"tv":3493.93,"id":36276560},{"atb":[[19.5,20.12],[23,25.01],[21,33.34]],"atl":[[25,12.46]],"trd":[[25,1.3]],"bdatb":[[3,21,35.18],[8,18,18.34],[5,19.5,28.87],[1,23,26.38],[9,17.5,5.31]],"bdatl":[[0,25,12.46],[8,40,3.08]],"ltp":25,"tv":498.62,"id":37947503},{"atb":[[1.49,489.91],[1.53,115.17]],"atl":[[1.54,45.43]],"trd":[[1.54,4071.27],[1.53,3624.74]],"bdatb":[[3,1.5,1465.55],[4,1.49,670.08],[5,1.48,385.61],[6,1.47,145.38],[7,1.46,409.58],[8,1.45,278.76],[9,1.44,146.92],[0,1.53,135.71],[1,1.52,498.32],[2,1.51,240.8]],"bdatl":[[0,1.54,45.43],[3,1.57,236.65],[4,1.58,134.43],[7,1.61,143.47],[9,1.63,149.83],[5,1.59,368.33],[6,1.6,30.64],[8,1.62,144.51],[2,1.56,219.96]],"ltp":1.54,"tv":17887.41,"id":39823721},{"bdatb":[[5,60,13.69],[1,80,7.04]],"id":44331354}],"con":true,"tv":24230.87}]}
{"op":"mcm","clk":"ANDNAQCXrQEAnrEB","pt":1650392832723,"mc":[{"id":"1.197931750","rc":[{"atb":[[8.8,28.02],[9,47.46]],"bdatb":[[5,9,56.6],[6,8.8,37.51],[0,10,14.26],[2,9.6,31.3],[3,9.4,36.63],[7,8.6,55.38],[9,8.2,67.51]],"bdatl":[[5,13,8.61],[6,13.5,34.62]],"id":42930960},{"atb":[[16,14.38]],"atl":[[21,16.76],[16.5,21.56]],"bdatb":[[0,16,14.38],[6,13,41.1],[7,12.5,65.01],[1,15.5,26.95],[3,14.5,21.7],[5,13.5,46.52],[9,11.5,46.21]],"bdatl":[[8,21,16.76],[0,16.5,21.56]],"id":40095374},{"atb":[[1.05,0],[6.8,88.83]],"atl":[[7,4.09],[1000,105.67],[7.6,46.05],[7.4,53.59],[8,21.48]],"trd":[[7,129.52]],"bdatb":[[0,6.8,81.48],[2,6.4,91.77],[3,6.2,128.45],[4,6,58.58],[8,5.6,13.11],[9,5.5,25.46]],"bdatl":[[6,8.2,44.14],[7,8.4,49.61],[2,7.4,53.59],[3,7.6,46.05],[5,8,21.48]],"tv":3494.73,"id":36276560},{"atl":[[25,10.89]],"trd":[[25,4.44]],"bdatb":[[1,23,25.86],[3,21,33.92],[5,19.5,28.25],[8,18,15.78],[9,17.5,10.82]],"bdatl":[[0,25,10.89]],"tv":501.76,"id":37947503},{"atl":[[1.54,12.62]],"bdatb":[[3,1.5,1457.67],[4,1.49,653.12],[9,1.44,213.84],[1,1.52,434.85],[2,1.51,286.51],[5,1.48,380.9],[6,1.47,247.17],[7,1.46,314.4],[8,1.45,235.93]],"bdatl":[[4,1.58,134.53],[5,1.59,368.23],[0,1.54,12.62]],"id":39823721},{"bdatb":[[1,80,6.89],[5,60,13.25],[8,48,13.91]],"id":44331354}],"con":true,"tv":24234.81}]}
{"op":"mcm","clk":"AI/PAQDCrgEAzLIB","pt":1650392833728,"mc":[{"id":"1.197931750","rc":[{"atb":[[10,11.75]],"atl":[[12,42.38]],"bdatb":[[0,10,13.5],[2,9.6,31.21],[3,9.4,36.72],[5,9,51.06],[7,8.6,60.59],[9,8.2,68.08],[6,8.8,38.07]],"bdatl":[[3,12,61.54],[4,12.5,31.52],[5,13,6.13],[6,13.5,38.61],[8,14.5,77.1]],"id":42930960},{"atb":[[13.5,32.78]],"atl":[[16.5,18.72]],"bdatb":[[1,15.5,26.82],[3,14.5,21.64],[5,13.5,44.59],[6,13,37.27],[9,11.5,46.04],[7,12.5,69.15]],"bdatl":[[0,16.5,18.72],[9,22,55.21]],"id":40095374},{"atb":[[6.8,91.77]],"atl":[[7.4,56.94],[7.2,112.96]],"bdatb":[[0,6.8,94.35],[2,6.4,84.76],[4,6,58.26],[5,5.9,74.64],[7,5.7,384.46],[8,5.6,17.77],[9,5.5,25.24],[3,6.2,136]],"bdatl":[[2,7.4,56.94],[4,7.8,60.83],[5,8,21.5],[6,8.2,40.2],[7,8.4,46.37],[8,8.6,53.1],[9,8.8,29.35],[0,7,4.09],[1,7.2,112.96]],"id":36276560},{"atl":[[25,8.82]],"trd":[[25,8.58]],"bdatb":[[1,23,25.77],[3,21,33.87],[5,19.5,28.3],[8,18,13.29],[9,17.5,13.5]],"bdatl":[[0,25,8.82],[8,40,2.94]],"tv":505.9,"id":37947503},{"atb":[[1.53,155.34],[1.01,23000.19],[1.51,218.73]],"atl":[[1.54,37.6],[1.55,149.35],[1.57,161.18]],"trd":[[1.53,3643.01],[1.54,4072.97]],"bdatb":[[0,1.53,183.2],[1,1.52,405.9],[2,1.51,313.61],[3,1.5,1423.17],[4,1.49,656.46],[5,1.48,412.5],[6,1.47,273.62],[7,1.46,281.23],[8,1.45,210.23],[9,1.44,210.4]],"bdatl":[[0,1.54,11.37],[3,1.57,236.03],[4,1.58,138.12],[7,1.61,86.24],[8,1.62,142.68],[9,1.63,208.18],[5,1.59,400.32],[6,1.6,54.64]],"ltp":1.53,"tv":17907.38,"id":39823721},{"bdatb":[[1,80,6.86],[5,60,13.24],[8,48,13.92]],"id":44331354}],"con":true,"tv":24258.92}]}
{"op":"mcm","clk":"AK7QAQC6rwEA37MB","pt":1650392834729,"mc":[{"id":"1.197931750","rc":[{"atb":[[6,48.76],[6.6,63.7],[5.5,19.87]],"bdatb":[[1,6.6,77.88],[2,6.4,80.02],[3,6.2,156.13],[7,5.7,370.78],[8,5.6,31.7],[0,6.8,91.77],[5,5.9,31.74],[6,5.8,179.04],[4,6,61.28],[9,5.5,37.66]],"bdatl":[[5,8,30.56],[6,8.2,41.74],[7,8.4,58.16],[8,8.6,35.97],[3,7.6,61.51],[4,7.8,45.79],[9,8.8,29.68]],"id":36276560},{"atb":[[22,34.4],[20,19.84],[24,9.58],[8.8,0],[25,11.65],[18.5,10.29],[21,33.09],[2.06,1],[19.5,27.78]],"atl":[[36,2.86],[1000,39.65],[30,2.56],[29,12.59],[28,14.71],[27,7.94],[26,3.6],[25,0]],"trd":[[25,26.22]],"bdatb":[[1,24,9.58],[0,25,11.65],[3,22,30.84],[5,20,21.84],[8,18.5,10.29],[4,21,33.81],[2,23,25.6],[6,19.5,35.76],[7,19,16.76],[9,18,13.51]],"bdatl":[[7,36,2.86],[8,40,2.94],[9,42,5.84],[0,26,3.6],[1,27,7.94],[2,28,14.71],[3,29,12.59],[4,30,2.56],[5,32,7.07],[6,34,6.87]],"tv":523.54,"id":37947503},{"atb":[[1.53,197.86],[1.01,22996.19],[1.51,225.27]],"atl":[[1000,311.8],[1.54,8.82],[1.55,110.02]],"trd":[[1.53,3653.01],[1.54,4078.06]],"bdatb":[[0,1.53,197.86],[1,1.52,283.09],[2,1.51,462.74],[3,1.5,1347.05],[4,1.49,733.07],[5,1.48,412.53],[6,1.47,132.14],[7,1.46,217.13],[8,1.45,196.03],[9,1.44,255.1]],"bdatl":[[5,1.59,333.15],[6,1.6,54.64],[4,1.58,205.72],[0,1.54,8.82],[9,1.63,194.7],[1,1.55,110.02]],"ltp":1.53,"tv":17922.47,"id":39823721},{"bdatb":[[4,9.2,38.63],[5,9,57.51],[6,8.8,42.11],[7,8.6,34.85],[8,8.4,59.1],[3,9.4,19.76],[9,8.2,37.22],[0,10,13.11],[2,9.6,31.61]],"bdatl":[[4,12.5,37.31],[5,13,21.27],[6,13.5,21.29],[9,15,8.83],[3,12,61.55],[8,14.5,74.93]],"id":42930960},{"bdatb":[[5,13.5,37.59],[6,13,41.74],[7,12.5,60.53],[8,12,31.76],[9,11.5,51.18],[1,15.5,25.69],[2,15,30.8],[3,14.5,20.87],[4,14,36.59]],"bdatl":[[9,22,63.11]],"id":40095374},{"bdatb":[[9,46,13.58],[1,80,6.64],[3,70,2.66],[5,60,13.05],[6,55,3.95],[8,48,10.6]],"id":44331354}],"con":true,"tv":24291.65}]}
{"op":"mcm","clk":"AOHRAQDDsAEA7LQB","pt":1650392835730,"mc":[{"id":"1.197931750","rc":[{"atl":[[12,44.76]],"bdatb":[[4,9.2,35.89],[5,9,59.28],[6,8.8,40.3],[7,8.6,36.69],[2,9.6,32.58]],"bdatl":[[3,12,63.93],[6,13.5,20.43],[8,14.5,75.72]],"id":42930960},{"atb":[[15,33.24]],"bdatb":[[2,15,34.15],[5,13.5,35.73],[6,13,42.96],[7,12.5,59.26],[8,12,33.08],[4,14,37.25]],"id":40095374},{"atb":[[6.8,90.07],[6.4,75.34]],"atl":[[7,5.42]],"bdatb":[[1,6.6,75.48],[2,6.4,91.96],[0,6.8,90.07]],"bdatl":[[0,7,5.42]],"id":36276560},{"atb":[[2.06,0.24],[21,34.42],[22,31.34],[18.5,8.78],[23,28.21]],"atl":[[26,2.99]],"trd":[[26,1.22]],"bdatb":[[4,21,35.58],[3,22,31.34],[8,18.5,8.78],[6,19.5,35.28],[2,23,28.8],[5,20,19.84]],"bdatl":[[0,26,2.99]],"ltp":26,"tv":524.76,"id":37947503},{"atb":[[1.51,232.52]],"atl":[[1000,308.86]],"bdatb":[[1,1.52,272.66],[2,1.51,480.48],[8,1.45,178.67],[9,1.44,272.58],[7,1.46,223.51]],"bdatl":[[6,1.6,47.41],[7,1.61,93.43],[9,1.63,187.6]],"id":39823721},{"bdatb":[[9,46,13.03],[6,55,4.12]],"id":44331354}],"con":true,"tv":24292.87}]}
{"op":"mcm","clk":"AIvTAQDHsQEA+7UB","pt":1650392836732,"mc":[{"id":"1.197931750","rc":[{"atb":[[6.4,72.35],[6.6,87.83]],"atl":[[11.5,17.09]],"bdatb":[[2,6.4,88.97],[1,6.6,99.61]],"id":36276560},{"atb":[[22,31.1],[21,35.75],[2.06,0],[18.5,7.27]],"bdatb":[[3,22,31.1],[4,21,36.91],[8,18.5,7.27]],"id":37947503},{"atl":[[1.6,28.63],[1.59,174.63]],"bdatl":[[5,1.59,290.54],[6,1.6,85.7],[9,1.63,245.26]],"id":39823721},{"atb":[[85,4.13]],"atl":[[300,8.34]],"trd":[[85,17.51]],"bdatb":[[0,85,4.13]],"bdatl":[[4,300,8.34]],"tv":245.91,"id":44331354},{"bdatl":[[5,13,8.19],[6,13.5,33.03]],"id":42930960}],"con":true,"tv":24298.39}]}
{"op":"mcm","clk":"ALnUAQDusgEAkLcB","pt":1650392837733,"mc":[{"id":"1.197931750","rc":[{"atb":[[9.8,14.95],[10,0]],"trd":[[9.8,112.62],[10,108.35]],"bdatb":[[1,9.8,24.77]],"bdatl":[[3,12,61.26],[4,12.5,39.87],[6,13.5,31.83],[7,14,16.46],[8,14.5,74.63],[9,15,9.89]],"ltp":9.8,"tv":1356.78,"id":42930960},{"atb":[[16,12.38]],"atl":[[17,28.49],[16.5,0]],"trd":[[17,60.94],[16.5,187.56],[16,241.54]],"bdatb":[[0,16,12.38]],"ltp":17,"tv":844.05,"id":40095374},{"atb":[[6.8,77.81],[6.6,97.29],[6.4,62.89]],"trd":[[6.8,24.52]],"bdatb":[[1,6.6,109.07],[2,6.4,79.51]],"bdatl":[[4,7.8,41.68],[5,8,34.56],[8,8.6,32.6],[9,8.8,34.25],[6,8.2,43.46],[7,8.4,56.48]],"ltp":6.8,"tv":3519.25,"id":36276560},{"atb":[[25,0.33]],"trd":[[25,48.86]],"ltp":25,"tv":547.4,"id":37947503},{"atl":[[1.54,0],[1.55,0],[1.56,9.44]],"trd":[[1.54,4095.7],[1.55,1744.81],[1.56,1143.98]],"bdatl":[[9,1.63,229.7],[4,1.58,214.68],[5,1.59,281.62],[7,1.61,106.14],[8,1.62,144.51]],"ltp":1.56,"tv":18581.2,"id":39823721},{"atb":[[85,0.17]],"trd":[[85,25.43]],"tv":253.83,"id":44331354}],"con":true,"tv":25102.51}]}
{"op":"mcm","clk":"AM/VAQCPtAEAsLgB","pt":1650392838735,"mc":[{"id":"1.197931750","marketDefinition":{"bspMarket":true,"turnInPlayEnabled":false,"persistenceEnabled":false,"marketBaseRate":5,"eventId":"31389771","eventTypeId":"4339","numberOfWinners":1,"bettingType":"ODDS","marketType":"WIN","marketTime":"2022-04-19T18:26:00.000Z","suspendTime":"2022-04-19T18:26:00.000Z","bspReconciled":true,"complete":true,"inPlay":false,"crossMatching":true,"runnersVoidable":false,"numberOfActiveRunners":6,"betDelay":0,"status":"SUSPENDED","runners":[{"status":"ACTIVE","sortPriority":1,"bsp":85,"id":44331354},{"status":"ACTIVE","sortPriority":2,"bsp":25,"id":37947503},{"status":"ACTIVE","sortPriority":3,"bsp":6.8,"id":36276560},{"status":"ACTIVE","sortPriority":4,"bsp":9.9089325297506,"id":42930960},{"status":"ACTIVE","sortPriority":5,"bsp":16.56625524822389,"id":40095374},{"status":"ACTIVE","sortPriority":6,"bsp":1.556124059615065,"id":39823721}],"regulators":["MR_INT"],"venue":"Sheffield","countryCode":"GB","discountAllowed":true,"timezone":"Europe/London","openDate":"2022-04-19T17:19:00.000Z","version":4497298499,"priceLadderDefinition":{"type":"CLASSIC"}},"rc":[{"atb":[[3.65,0],[1.05,0],[6.6,0],[8.8,0],[9.8,0],[7.6,0],[1.25,0],[4.6,0],[5.1,0],[9.4,0],[8.4,0],[7.8,0],[6.8,0],[5.3,0],[1.01,0],[4.3,0],[9,0],[1.12,0],[8,0],[7,0],[2.2,0],[5.7,0],[6,0],[1.02,0],[5.5,0],[6.2,0],[8.6,0],[7.2,0],[4,0],[9.6,0],[5.9,0],[4.9,0],[7.4,0],[8.2,0],[1.43,0],[9.2,0],[6.4,0]],"atl":[[110,0],[80,0],[19,0],[290,0],[18.5,0],[17.5,0],[17,0],[16.5,0],[16,0],[1000,0],[15.5,0],[990,0],[15,0],[14.5,0],[14,0],[13.5,0],[13,0],[12.5,0],[12,0],[11.5,0],[11,0],[10.5,0],[20,0],[32,0]],"bdatb":[[0,0,0],[1,0,0],[2,0,0],[3,0,0],[4,0,0],[5,0,0],[6,0,0],[7,0,0],[8,0,0],[9,0,0]],"bdatl":[[0,0,0],[1,0,0],[2,0,0],[3,0,0],[4,0,0],[5,0,0],[6,0,0],[7,0,0],[8,0,0],[9,0,0]],"id":42930960},{"atb":[[1.05,0],[1.25,0],[5.6,0],[16,0],[15.5,0],[15,0],[8.4,0],[14.5,0],[14,0],[13.5,0],[13,0],[12.5,0],[6.8,0],[12,0],[11.5,0],[11,0],[10.5,0],[10,0],[1.01,0],[9,0],[1.12,0],[8,0],[5.7,0],[1.02,0],[5.5,0],[6.2,0],[8.6,0],[5.9,0],[1.43,0],[6.4,0],[8.2,0]],"atl":[[30,0],[27,0],[26,0],[25,0],[24,0],[23,0],[22,0],[21,0],[20,0],[19.5,0],[19,0],[290,0],[18.5,0],[18,0],[17.5,0],[17,0],[1000,0],[990,0],[200,0],[44,0],[34,0],[540,0],[32,0],[28,0],[65,0]],"bdatb":[[0,0,0],[1,0,0],[2,0,0],[3,0,0],[4,0,0],[5,0,0],[6,0,0],[7,0,0],[8,0,0],[9,0,0]],"bdatl":[[0,0,0],[1,0,0],[2,0,0],[3,0,0],[4,0,0],[5,0,0],[6,0,0],[7,0,0],[8,0,0],[9,0,0]],"id":40095374},{"atb":[[3.9,0],[6.6,0],[5.7,0],[5.2,0],[6,0],[1.02,0],[5.5,0],[6.2,0],[1.25,0],[4.6,0],[5.1,0],[5.6,0],[5.9,0],[4.9,0],[3.8,0],[6.8,0],[5.3,0],[1.43,0],[5.8,0],[1.01,0],[6.4,0],[4.3,0],[1.12,0],[4.8,0]],"atl":[[480,0],[8.8,0],[9.8,0],[7.6,0],[20,0],[18.5,0],[16.5,0],[15.5,0],[9.4,0],[15,0],[14.5,0],[8.4,0],[14,0],[7.8,0],[13.5,0],[13,0],[12.5,0],[12,0],[11.5,0],[11,0],[10.5,0],[10,0],[9,0],[8,0],[7,0],[110,0],[80,0],[8.6,0],[7.2,0],[9.6,0],[1000,0],[7.4,0],[8.2,0],[9.2,0]],"bdatb":[[0,0,0],[1,0,0],[2,0,0],[3,0,0],[4,0,0],[5,0,0],[6,0,0],[7,0,0],[8,0,0],[9,0,0]],"bdatl":[[0,0,0],[1,0,0],[2,0,0],[3,0,0],[4,0,0],[5,0,0],[6,0,0],[7,0,0],[8,0,0],[9,0,0]],"id":36276560},{"atb":[[9.8,0],[25,0],[24,0],[23,0],[22,0],[21,0],[1.25,0],[20,0],[19,0],[19.5,0],[18,0],[18.5,0],[17,0],[17.5,0],[16,0],[16.5,0],[15.5,0],[8.4,0],[14.5,0],[7.8,0],[13.5,0],[13,0],[12.5,0],[12,0],[11.5,0],[11,0],[5.8,0],[10,0],[1.01,0],[1.12,0],[8,0],[1.02,0],[8.6,0],[7.4,0],[1.43,0]],"atl":[[30,0],[29,0],[28,0],[27,0],[26,0],[360,0],[350,0],[70,0],[65,0],[1000,0],[60,0],[230,0],[55,0],[210,0],[50,0],[190,0],[46,0],[44,0],[170,0],[42,0],[36,0],[34,0],[540,0],[32,0]],"bdatb":[[0,0,0],[1,0,0],[2,0,0],[3,0,0],[4,0,0],[5,0,0],[6,0,0],[7,0,0],[8,0,0],[9,0,0]],"bdatl":[[0,0,0],[1,0,0],[2,0,0],[3,0,0],[4,0,0],[5,0,0],[6,0,0],[7,0,0],[8,0,0],[9,0,0]],"id":37947503},{"atb":[[1.05,0],[1.47,0],[1.29,0],[1.3,0],[1.32,0],[1.5,0],[1.25,0],[1.35,0],[1.34,0],[1.39,0],[1.48,0],[1.1,0],[1.51,0],[1.14,0],[1.23,0],[1.37,0],[1.01,0],[1.44,0],[1.38,0],[1.52,0],[1.31,0],[1.13,0],[1.42,0],[1.49,0],[1.06,0],[1.02,0],[1.16,0],[1.27,0],[1.4,0],[1.41,0],[1.53,0],[1.43,0],[1.45,0],[1.46,0],[1.18,0],[1.2,0],[1.26,0]],"atl":[[450,0],[1.57,0],[1.79,0],[1.72,0],[1.76,0],[1.69,0],[1.62,0],[2.22,0],[1.58,0],[1.6,0],[1.59,0],[2.82,0],[1.64,0],[1.61,0],[1.66,0],[1.65,0],[1.86,0],[1.91,0],[1.9,0],[1.88,0],[1.74,0],[1.63,0],[1.92,0],[1.56,0],[1000,0],[2.08,0],[2.1,0],[2.58,0],[1.96,0],[2.5,0],[6.4,0],[3.6,0],[2,0],[20,0],[1.8,0]],"bdatb":[[0,0,0],[1,0,0],[2,0,0],[3,0,0],[4,0,0],[5,0,0],[6,0,0],[7,0,0],[8,0,0],[9,0,0]],"bdatl":[[0,0,0],[1,0,0],[2,0,0],[3,0,0],[4,0,0],[5,0,0],[6,0,0],[7,0,0],[8,0,0],[9,0,0]],"id":39823721},{"atb":[[1.05,0],[29,0],[28,0],[27,0],[1.25,0],[20,0],[19,0],[18,0],[17,0],[15.5,0],[15,0],[14.5,0],[14,0],[12,0],[1.01,0],[1.12,0],[8,0],[1.02,0],[85,0],[80,0],[4.5,0],[75,0],[70,0],[65,0],[60,0],[55,0],[50,0],[48,0],[46,0],[44,0],[1.43,0],[40,0],[36,0],[34,0],[32,0]],"atl":[[510,0],[490,0],[120,0],[470,0],[110,0],[350,0],[340,0],[300,0],[1000,0],[230,0],[190,0],[140,0],[530,0],[130,0]],"bdatb":[[0,0,0],[1,0,0],[2,0,0],[3,0,0],[4,0,0],[5,0,0],[6,0,0],[7,0,0],[8,0,0],[9,0,0]],"bdatl":[[0,0,0],[1,0,0],[2,0,0],[3,0,0],[4,0,0],[5,0,0],[6,0,0],[7,0,0],[8,0,0],[9,0,0]],"id":44331354}],"con":true}]}
{"op":"mcm","clk":"5649827878","pt":1650392996470,"mc":[{"id":"1.197931750","marketDefinition":{"bspMarket":true,"turnInPlayEnabled":false,"persistenceEnabled":false,"marketBaseRate":5.0,"eventId":"31389771","eventTypeId":"4339","numberOfWinners":1,"bettingType":"ODDS","marketType":"WIN","marketTime":"2022-04-19T18:26:00.000Z","suspendTime":"2022-04-19T18:26:00.000Z","bspReconciled":true,"complete":true,"inPlay":false,"crossMatching":false,"runnersVoidable":false,"numberOfActiveRunners":0,"betDelay":0,"status":"CLOSED","settledTime":"2022-04-19T18:29:41.000Z","runners":[{"status":"LOSER","sortPriority":1,"bsp":85.0,"id":44331354,"name":"1. Paradise Mission"},{"status":"WINNER","sortPriority":2,"bsp":25.0,"id":37947503,"name":"2. Sandwood Jet"},{"status":"LOSER","sortPriority":3,"bsp":6.8,"id":36276560,"name":"3. Kirabilly Kathy"},{"status":"LOSER","sortPriority":4,"bsp":9.9,"id":42930960,"name":"4. Gurtnacrehyblake"},{"status":"LOSER","sortPriority":5,"bsp":16.56,"id":40095374,"name":"5. Castlehill Jil"},{"status":"LOSER","sortPriority":6,"bsp":1.55,"id":39823721,"name":"6. Coolavanny Galiv"}],"regulators":["MR_INT"],"venue":"Sheffield","countryCode":"GB","discountAllowed":true,"timezone":"Europe/London","openDate":"2022-04-19T17:19:00.000Z","version":4497303953,"name":"OR 280m","eventName":"Sheffield 19th Apr"}}]}
