{"op":"mcm","clk":"AAAAAAAA","pt":1650392673420,"mc":[{"id":"1.197931751","marketDefinition":{"bspMarket":true,"turnInPlayEnabled":false,"persistenceEnabled":false,"marketBaseRate":5,"eventId":"31389771","eventTypeId":"4339","numberOfWinners":2,"bettingType":"ODDS","marketType":"PLACE","marketTime":"2022-04-19T18:26:00.000Z","suspendTime":"2022-04-19T18:26:00.000Z","bspReconciled":false,"complete":true,"inPlay":false,"crossMatching":true,"runnersVoidable":false,"numberOfActiveRunners":6,"betDelay":0,"status":"OPEN","runners":[{"status":"ACTIVE","sortPriority":1,"id":44331354},{"status":"ACTIVE","sortPriority":2,"id":37947503},{"status":"ACTIVE","sortPriority":3,"id":36276560},{"status":"ACTIVE","sortPriority":4,"id":42930960},{"status":"ACTIVE","sortPriority":5,"id":40095374},{"status":"ACTIVE","sortPriority":6,"id":39823721}],"regulators":["MR_INT"],"venue":"Sheffield","countryCode":"GB","discountAllowed":true,"timezone":"Europe/London","openDate":"2022-04-19T17:19:00.000Z","version":4495990895,"priceLadderDefinition":{"type":"CLASSIC"}},"rc":[{"atb":[[2.62,30.34],[2.56,18.63],[2.7,2.21],[2.24,200.5],[2.28,116.54],[2.32,75.34],[2.34,3.23],[2.36,29.25],[2.68,7.53],[2.12,89.29],[2.6,15.56],[2.66,5.47],[2.64,5.75],[1.85,135],[2.52,13.55],[1.02,1.99],[1.23,250],[2.22,5.59],[1.08,50],[1.01,5644.04]],"atl":[[2.78,9.54],[2.76,2.04],[2.8,9.86],[2.84,2.17],[5.1,60.98],[2.82,3.14],[4.9,38.46],[4.7,27.03],[4.5,11.43],[2.86,10.14],[2.96,13.77],[3.15,13.91],[3.25,3.48],[4,3.14],[2.94,2.71],[3.35,2.92],[3.1,3.2],[3.05,14.06],[4.3,30.3],[1000,5]],"trd":[[2.68,89.95],[2.7,18.12],[2.72,21.42],[2.6,2],[2.64,78.99],[2.66,21]],"bdatb":[[8,2.42,4.96],[9,2.36,39.33],[4,2.62,30.34],[6,2.56,18.63],[7,2.52,13.55],[0,2.7,2.21],[3,2.64,5.75],[1,2.68,7.53],[2,2.66,5.47],[5,2.6,15.56]],"bdatl":[[8,3.05,17.39],[9,3.1,3.2],[1,2.78,9.54],[0,2.76,2.04],[2,2.8,9.86],[3,2.82,3.14],[4,2.84,2.17],[5,2.86,10.14],[6,2.94,2.71],[7,2.96,13.77]],"ltp":2.68,"tv":231.48,"id":42930960},{"atb":[[4.4,11.79],[4.5,23.74],[4.7,10.21],[4,10.1],[4.6,2.45],[1.02,1.54],[2.14,219.3],[3.95,2.19],[4.1,9.09],[2.18,127.12],[2.22,81.97],[2.26,31.75],[2.72,30.77],[2.64,95],[3.85,17.48],[4.3,8.56],[3.5,2.5],[3.7,5.19],[1.23,250],[2.84,4.37],[3.3,5],[3.1,10],[1.08,50],[2.24,6.7],[1.01,5644.04]],"atl":[[5.1,15.36],[1000,5],[5,7.16],[5.2,5.21],[6.4,7.41],[10,11.11],[7.8,36.76],[7.4,23.44],[7,16.67],[5.3,5.24],[7.2,2.31]],"trd":[[4.9,5.36],[4.8,3.16],[3.6,1.2],[3.5,8.32],[3.55,3.32]],"bdatb":[[6,4,11.51],[7,3.95,3.8],[9,3.8,5.17],[8,3.85,17.61],[3,4.4,11.79],[5,4.1,9.09],[2,4.5,23.74],[0,4.7,10.21],[1,4.6,2.45],[4,4.3,8.56]],"bdatl":[[5,6.4,11.98],[6,6.8,1.94],[9,7.4,27.25],[4,5.8,1],[7,7,17.83],[8,7.2,4.05],[0,5,7.16],[1,5.1,15.36],[2,5.2,5.21],[3,5.3,5.24]],"ltp":4.9,"tv":21.36,"id":40095374},{"atb":[[2.64,14.12],[2.58,32.57],[2.66,2.18],[2.56,4.86],[2.6,9.11],[2.5,19.36],[2.62,11.4],[1.84,254.06],[1.86,174.42],[1.88,113.64],[2.36,3.49],[1.9,44.44],[1.81,123.46],[1.94,8.76],[2.38,14.18],[1.02,3.47],[1.92,130],[1.23,250],[1.71,7.25],[1.08,50],[1.01,5644.04]],"atl":[[2.78,2.46],[2.74,4.38],[2.76,8.19],[1000,5],[3.7,89.97],[3.2,42.25],[3.6,56.06],[3.5,38.87],[3.4,16.19],[2.96,13.54],[2.88,13.83],[3.05,13.22],[3.15,2.48],[2.94,6.77]],"trd":[[2.68,5.44],[2.66,0.22],[3.1,15.64],[3.05,7.4],[2.98,0.08],[2.88,0.4],[2.92,3.6],[2.64,21.06],[1.7,1.64]],"bdatb":[[7,2.4,5.21],[9,2.36,11.82],[1,2.64,14.12],[4,2.58,32.57],[0,2.66,2.18],[2,2.62,11.4],[3,2.6,9.11],[5,2.56,4.86],[6,2.5,19.36],[8,2.38,14.18]],"bdatl":[[0,2.74,4.38],[1,2.76,8.19],[2,2.78,2.46],[3,2.88,13.83],[4,2.94,6.77],[5,2.96,13.54],[6,2.98,2],[7,3,1.39],[8,3.05,13.22],[9,3.1,7.93]],"ltp":2.68,"tv":55.48,"id":36276560},{"atb":[[4.8,12.23],[4.7,12.44],[4.5,9.29],[3.1,47.62],[3,83],[1.02,3.54],[5,6.95],[4.9,6.87],[4.2,3.82],[3.75,90.91],[3.85,52.63],[3.95,33.9],[4.1,12.9],[3.9,6.79],[1.23,250],[3.3,3.76],[1.08,50],[1.01,5644.04]],"atl":[[5.4,7.16],[5.8,6.34],[9.8,4.55],[5.5,2.18],[6.4,7.47],[5.6,4.12],[5.7,2.11],[6,15.44],[5.9,2.03],[6.8,2.62],[8.4,2.5],[6.2,4.57],[7.4,6.32],[12.5,21.74],[11.5,14.29],[10.5,10.53],[8.2,13.89],[1000,5]],"bdatb":[[4,4.5,9.29],[5,4.2,6.68],[6,4.1,13.02],[7,4,5.53],[8,3.95,34.2],[9,3.9,8.24],[2,4.8,12.23],[3,4.7,12.44],[1,4.9,6.87],[0,5,6.95]],"bdatl":[[9,6.8,5.6],[7,6.2,4.57],[8,6.4,8.41],[0,5.4,7.16],[4,5.8,6.34],[1,5.5,2.18],[2,5.6,4.12],[3,5.7,2.11],[5,5.9,2.03],[6,6,15.44]],"id":37947503},{"atb":[[1.2,199.79],[1.23,133.59],[1.21,74.2],[1.19,63.17],[1.24,8.18],[1.22,121.88],[1.08,50],[1.16,22.52],[1.09,729],[1.1,2.5],[1.03,250],[1.05,250],[1.07,250],[1.01,5656.32],[1.02,1.99]],"atl":[[1.25,10],[1.27,24.18],[1.26,49.66],[1000,5],[1.53,75.37],[1.52,178.57],[1.6,250],[1.29,10],[1.58,250],[1.56,178.57],[46,5.38]],"trd":[[1.24,22.4],[1.23,86.08],[1.22,151.1],[1.21,20],[1.2,110.92],[1.18,15.66]],"bdatb":[[6,1.17,27.48],[7,1.16,25.67],[8,1.15,4.91],[9,1.13,16.2],[5,1.19,63.17],[4,1.2,199.79],[1,1.23,133.59],[3,1.21,74.2],[0,1.24,8.18],[2,1.22,121.88]],"bdatl":[[0,1.25,10],[5,1.32,21.8],[6,1.33,4.48],[7,1.34,5.29],[2,1.27,24.18],[8,1.35,5.99],[9,1.36,2.48],[4,1.31,4.55],[1,1.26,49.66],[3,1.29,10]],"ltp":1.24,"tv":406.16,"id":39823721},{"atb":[[13,9.04],[13.5,3.54],[4,83.33],[4.2,46.88],[4.4,29.41],[4.6,11.11],[10,1.13],[1.02,3.44],[6,20],[10.5,3.08],[11,2.47],[7,36],[11.5,3.07],[9.6,1.24],[1.23,250],[6.2,2],[1.08,50],[1.01,5644.04]],"atl":[[26,8.07],[42,2.44],[29,5.52],[32,3.23],[28,13.58],[40,6.41],[27,2.98],[36,10.2],[1000,5]],"bdatb":[[2,11.5,3.07],[3,11,3.56],[5,10,3.1],[6,9.6,1.49],[7,8,1.91],[8,7.8,1.17],[4,10.5,3.13],[9,7.6,1.17],[1,13,9.04],[0,13.5,3.54]],"bdatl":[[8,1000,5.72],[4,32,3.43],[0,26,8.07],[5,36,10.31],[6,40,6.41],[1,27,2.98],[3,29,5.52],[2,28,13.58],[7,42,2.44],[9,0,0]],"id":44331354}],"img":true,"tv":714.48}]}
{"op":"mcm","clk":"AKABAI4BAJIB","pt":1650392674421,"mc":[{"id":"1.197931751","rc":[{"atb":[[2.64,6.97],[1.01,5644.04],[2.62,12.41]],"bdatb":[[3,2.64,6.97],[8,2.42,5.17],[9,2.38,7.88],[4,2.62,12.41]],"bdatl":[[8,3.05,25.45],[9,3.1,7.41]],"id":42930960},{"atb":[[4.5,15.44]],"bdatb":[[6,4,11.51],[7,3.95,3.93],[8,3.85,22.35],[9,3.75,5.18],[2,4.5,15.44]],"bdatl":[[9,6.6,1.71],[5,5.9,1],[6,6,2.38],[7,6.2,1.39],[8,6.4,9.45],[4,5.8,1.03]],"id":40095374},{"atb":[[2.68,2.36],[2.6,10.36],[1.02,3.47],[2.66,4.47],[2.54,18.87],[2.58,14.18],[2.62,16.36]],"atl":[[2.74,11.4]],"bdatb":[[3,2.6,10.36],[0,2.66,4.47],[6,2.54,18.87],[7,2.5,19.36],[8,2.4,5.21],[9,2.38,14.18],[4,2.58,14.18],[2,2.62,16.36]],"bdatl":[[7,3,6.73],[8,3.05,16.04],[9,3.1,4.21],[0,2.74,11.4]],"id":36276560},{"atb":[[4.8,4.59]],"bdatb":[[2,4.8,4.59],[5,4.2,6.8],[6,4.1,17.47],[7,4,1.14],[8,3.95,38.47],[9,3.9,8.3]],"bdatl":[[8,6.4,9.33],[9,6.6,4.36]],"id":37947503},{"atb":[[1.04,0],[1.25,7.26],[1.2,211.93],[1.22,123.9],[1.24,68.76]],"atl":[[1.25,0],[1.34,8.33],[1.27,51.96]],"trd":[[1.25,40]],"bdatb":[[2,1.22,123.9],[4,1.2,221.93],[0,1.24,68.76],[7,1.16,28.14],[8,1.15,13.21],[9,1.14,6]],"bdatl":[[2,1.27,51.96],[7,1.34,13.77],[8,1.35,8.23],[9,1.37,6.8],[4,1.31,9.08],[5,1.32,17.31],[0,1.25,10],[1,1.26,49.66],[3,1.29,10],[6,1.33,4.48]],"ltp":1.25,"tv":446.16,"id":39823721},{"bdatb":[[3,11,3.61],[4,10.5,3.08],[5,10,3.1],[6,9.6,1.61],[7,9,1.63],[8,8.6,1.05],[9,7.6,1.15]],"bdatl":[[8,1000,5.43],[4,32,3.62],[5,36,10.59],[6,40,6.62]],"id":44331354}],"con":true,"tv":754.48}]}
{"op":"mcm","clk":"AMICALUCAI8C","pt":1650392675423,"mc":[{"id":"1.197931751","rc":[{"atb":[[2.58,18.38]],"atl":[[2.78,13.33],[2.76,9.02]],"bdatb":[[6,2.58,18.38],[7,2.56,18.63],[8,2.52,13.55],[9,2.38,5.29]],"bdatl":[[7,2.96,15.79],[8,3,2.12],[9,3.05,16],[1,2.78,13.33],[0,2.76,9.02]],"id":42930960},{"atb":[[4.5,23.74]],"bdatb":[[2,4.5,23.74],[8,3.9,3.23],[9,3.85,17.48],[6,4,10.1],[7,3.95,2.19]],"bdatl":[[5,5.8,1.09],[6,6.2,3.65],[7,6.4,8.34],[8,6.6,2.79],[9,6.8,1.37],[4,5.5,1.08]],"id":40095374},{"atb":[[2.56,23.49]],"atl":[[2.78,2.46]],"bdatb":[[6,2.56,23.49],[0,2.68,2.36],[1,2.66,4.47],[2,2.64,14.12],[3,2.62,16.36],[4,2.6,10.36],[5,2.58,14.18],[7,2.54,18.87],[8,2.5,19.36]],"bdatl":[[2,2.78,2.46],[6,2.96,13.54],[7,2.98,2.13],[8,3.05,20.58],[9,3.1,1.92],[4,2.92,2.04],[5,2.94,6.77]],"id":36276560},{"atb":[[4.8,12.23]],"bdatb":[[2,4.8,12.23],[9,3.9,11.42],[8,3.95,35.05],[6,4.1,15.97],[7,4,4.66],[5,4.2,3.82]],"bdatl":[[6,6,15.44],[7,6.2,4.62],[8,6.4,8.41],[9,6.6,2.1],[5,5.9,3.04]],"id":37947503},{"atb":[[1.2,189.79],[1.04,1],[1.21,212.54],[1.22,121.88],[1.25,9.85]],"atl":[[1.27,47.23],[1.34,0],[1.26,10]],"trd":[[1.26,47.84]],"bdatb":[[5,1.2,189.79],[9,1.15,8.73],[4,1.21,212.54],[3,1.22,121.88],[7,1.17,30.6],[8,1.16,35.32],[0,1.25,9.85],[1,1.24,68.76],[2,1.23,133.59],[6,1.19,63.17]],"bdatl":[[1,1.27,47.23],[4,1.32,15.29],[5,1.33,6.46],[6,1.34,9.88],[7,1.35,8.23],[8,1.37,6.8],[9,1.38,21.7],[0,1.26,10],[2,1.29,10],[3,1.3,4.59]],"ltp":1.26,"tv":494,"id":39823721},{"atb":[[13.5,0.44]],"bdatb":[[0,13,9.48],[1,11.5,3.07],[2,11,2.47],[3,10.5,4.28],[4,10,1.13],[5,9.8,1.26],[6,9.6,1.9],[7,8.8,2.16],[8,8.4,1.18],[9,7.4,1.61]],"bdatl":[[0,26,8.34],[1,27,3.21],[3,29,5.52],[4,32,3.41],[5,36,10.42],[8,1000,5.45]],"id":44331354}],"con":true,"tv":802.32}]}
{"op":"mcm","clk":"AIEEANkDAI4D","pt":1650392676427,"mc":[{"id":"1.197931751","rc":[{"atb":[[2.62,16.82],[2.7,9.14],[2.6,33.72],[2.58,0]],"atl":[[2.84,6.52],[2.8,9.86],[2.78,2.6],[2.76,0]],"bdatb":[[0,2.7,9.14],[8,2.48,4.74],[9,2.46,8.05],[5,2.6,33.72],[6,2.56,18.63],[7,2.52,13.55]],"bdatl":[[0,2.78,2.6],[8,3.1,14.4],[9,3.15,16.53],[1,2.8,16.47],[7,3.05,14.06],[2,2.82,3.14],[3,2.84,2.17],[4,2.86,10.14],[5,2.94,2.71],[6,2.96,13.77]],"id":42930960},{"atb":[[4.5,27.33]],"atl":[[5.2,8.8],[5.4,6.13],[5,2.35]],"bdatb":[[5,4.1,10.85],[6,4,17.97],[7,3.95,5.23],[8,3.9,2.39],[9,3.85,17.48],[2,4.5,23.74]],"bdatl":[[5,6,4.11],[6,6.2,2.95],[7,6.4,7.41],[8,6.8,1.71],[9,7,17.61],[2,5.2,5.21],[4,5.4,6.13],[0,5,2.35]],"id":40095374},{"atb":[[2.5,23.86],[2.56,4.36],[2.58,0],[2.52,2.62],[2.54,21.46],[2.6,0],[2.62,0],[2.64,0],[2.68,0],[2.66,0]],"atl":[[2.94,0],[2.62,13.23],[2.58,12.23],[2.66,23.52],[2.6,20.18],[2.72,11.66],[3.05,0],[2.74,7.02],[2.68,4.5],[2.78,2.02],[2.64,7.81],[2.82,0],[3.1,1.71]],"trd":[[2.6,2.5],[2.62,13.78],[2.64,30.6],[2.68,10.16],[2.66,9.16]],"bdatb":[[0,2.54,21.46],[1,2.52,2.62],[2,2.5,19.36],[3,2.38,14.18],[4,2.36,3.49],[5,2.32,3.11],[6,2.3,1.97],[7,2.28,11.81],[8,2.26,6.48],[9,2.24,2.97]],"bdatl":[[0,2.58,12.23],[1,2.6,20.18],[2,2.62,13.23],[3,2.64,7.81],[4,2.66,23.52],[5,2.68,4.5],[6,2.72,11.66],[7,2.74,7.02],[8,2.76,8.19],[9,2.78,2.02]],"ltp":2.6,"tv":94.96,"id":36276560},{"atb":[[4.9,10.34],[4.8,12.23]],"atl":[[5.6,7.66]],"bdatb":[[5,4.4,1.64],[6,4.3,1.05],[7,4.2,13.72],[8,4.1,14.52],[9,4,6.01],[2,4.8,12.23]],"bdatl":[[9,6.6,6.51],[8,6.4,7.47],[7,6.2,4.57],[5,5.9,2.03],[6,6,15.44]],"id":37947503},{"atb":[[1.07,251],[1.21,218.36],[1.26,34.11],[1.25,36.17],[1.04,0],[1.24,82.94],[1.2,175.6],[1.23,142.29]],"atl":[[1.28,70.3],[1.29,10],[1.26,0]],"trd":[[1.26,67.84]],"bdatb":[[0,1.26,34.11],[1,1.25,36.17],[2,1.24,82.94],[3,1.23,142.29],[4,1.22,121.88],[5,1.21,202.62],[6,1.2,185.39],[7,1.19,85.79],[8,1.18,12.42],[9,1.17,17.44]],"bdatl":[[0,1.27,47.23],[1,1.28,58.09],[2,1.29,10],[3,1.34,25.93],[4,1.35,7.49],[5,1.36,2.3],[6,1.37,4.75],[7,1.38,3.45],[8,1.39,1.33],[9,1.4,5.23]],"tv":514,"id":39823721},{"atb":[[13.5,3.51]],"bdatb":[[1,13,9.04],[2,11.5,5.78],[3,11,3.12],[4,10.5,4.22],[5,10,2.06],[6,9.6,1.24],[7,9,1.5],[8,8.8,1.17],[9,8,1.62],[0,13.5,3.51]],"bdatl":[[5,36,10.93],[6,40,6.68],[8,1000,5.33],[4,32,3.23],[1,27,2.98],[3,29,5.52],[0,26,8.07]],"id":44331354}],"con":true,"tv":861.8}]}
{"op":"mcm","clk":"ALQFAN8EAKAE","pt":1650392677428,"mc":[{"id":"1.197931751","rc":[{"atb":[[2.64,24.68],[2.7,13.62]],"bdatb":[[8,2.5,2.69],[9,2.48,2.02],[3,2.64,24.68],[0,2.7,13.62],[4,2.62,16.82]],"bdatl":[[9,3.15,16.7],[8,3.1,6.82],[7,3.05,14.06],[1,2.8,9.86],[3,2.84,6.52]],"id":42930960},{"atb":[[4.6,10.52],[2.86,30.77],[2.72,0]],"atl":[[6.4,0],[6.6,7.14]],"bdatb":[[5,4.1,10.85],[6,4,12.94],[7,3.95,7.28],[9,3.85,19.21],[1,4.6,10.52],[8,3.9,1.28],[2,4.5,27.33]],"bdatl":[[6,6.2,1.42],[7,6.6,7.87],[8,7,16.67],[9,7.2,3.69],[5,6,1.87],[2,5.2,8.8]],"id":40095374},{"atb":[[2.48,7.55],[2.46,2.75],[2.5,4.5],[2.38,35.23],[2.52,0],[2.54,0],[1.81,0],[1.72,50],[2.56,0]],"atl":[[2.68,2.36],[2.62,11.65],[2.52,2.67],[2.54,2.65],[2.64,4.23],[2.58,20.77],[2.66,18.85],[2.56,2]],"trd":[[2.52,12.48],[2.54,10.7],[2.56,8.72]],"bdatb":[[2,2.46,2.75],[3,2.38,35.23],[4,2.36,3.49],[5,2.28,5.15],[6,2.26,10.21],[7,2.24,1.72],[8,2.22,5.26],[9,2.16,11.53],[0,2.5,4.5],[1,2.48,2.75]],"bdatl":[[0,2.52,2.67],[1,2.54,2.65],[2,2.56,2],[3,2.58,20.77],[4,2.6,20.18],[5,2.62,11.65],[6,2.64,4.23],[7,2.66,18.85],[8,2.68,2.36],[9,2.72,11.66]],"ltp":2.52,"tv":126.86,"id":36276560},{"atb":[[4.9,17.79]],"bdatb":[[5,4.4,1.64],[6,4.3,1.05],[7,4.2,5.45],[8,4.1,19.02],[9,4,1.67],[1,4.9,17.79]],"bdatl":[[9,6.6,2.74],[8,6.4,7.47],[7,6.2,4.57],[2,5.6,7.66]],"id":37947503},{"atb":[[1.22,81.84],[1.23,268.6],[1.26,34.24],[1.27,15.78],[1.07,250],[1.24,100.28],[1.25,88.09]],"atl":[[1.29,19.3],[1.28,39.33],[1.52,178.57],[1.3,2.05],[1.27,0]],"trd":[[1.28,63.33],[1.27,20]],"bdatb":[[6,1.21,228.07],[7,1.2,181.29],[8,1.19,80.05],[4,1.23,268.6],[5,1.22,81.84],[9,1.18,19.92],[0,1.27,15.78],[1,1.26,34.24],[2,1.25,88.09],[3,1.24,100.28]],"bdatl":[[0,1.28,39.33],[1,1.29,19.3],[4,1.36,9.99],[5,1.39,7.13],[9,1.44,8.55],[3,1.35,8.33],[6,1.4,8.99],[7,1.42,17.02],[8,1.43,17.39],[2,1.3,2.05]],"ltp":1.28,"tv":597.33,"id":39823721},{"bdatb":[[2,11.5,4.18],[3,11,2.94],[4,10.5,4.63],[6,9.6,1.92],[7,9,1.31],[8,8.8,1.13],[9,7,36.69],[5,10,2.02]],"bdatl":[[8,1000,5.15],[5,36,10.53],[6,40,6.58],[4,32,3.23],[2,28,13.58],[7,42,2.44],[9,0,0]],"id":44331354}],"con":true,"tv":977.03}]}
{"op":"mcm","clk":"AOwGAPoFAKYF","pt":1650392678429,"mc":[{"id":"1.197931751","rc":[{"atb":[[2.58,18.38],[2.7,9.14],[2.68,3],[2.6,15.56],[2.64,6.97]],"atl":[[2.78,9.53]],"bdatb":[[6,2.58,18.38],[7,2.56,18.63],[8,2.52,13.55],[9,2.44,2.76],[0,2.7,9.14],[1,2.68,3],[3,2.64,6.97],[5,2.6,15.56]],"bdatl":[[7,3.05,14.06],[8,3.1,5.07],[9,3.15,16.01],[0,2.78,9.53]],"id":42930960},{"atb":[[4.6,2.45]],"bdatb":[[5,4.1,9.09],[6,4,11.79],[7,3.95,3.49],[8,3.9,3.76],[9,3.85,20.64],[1,4.6,2.45]],"bdatl":[[5,6.2,2.03],[6,6.6,7.14],[7,6.8,1.8],[8,7,17.82],[9,7.2,2.59]],"id":40095374},{"atb":[[2.46,7.92],[2.5,0],[2.48,0],[2.4,2.93],[2.32,22.01],[1.86,173.41],[2.38,14.18]],"atl":[[2.6,20.8],[1000,5],[3.5,40],[2.52,0]],"bdatb":[[0,2.46,5.05],[1,2.4,2.93],[2,2.38,14.18],[3,2.36,3.49],[4,2.32,22.01],[5,2.26,5.2],[6,2.24,6.59],[7,2.22,5.48],[8,2.2,2.2],[9,2.18,3.28]],"bdatl":[[3,2.6,20.8],[0,2.54,2.65],[1,2.56,2],[2,2.58,20.77],[4,2.62,11.65],[5,2.64,4.23],[6,2.66,18.85],[7,2.68,2.36],[8,2.72,11.66],[9,2.74,7.02]],"id":36276560},{"atb":[[4.6,0],[4.9,10.34],[4.8,4.59]],"bdatb":[[8,4,4.25],[9,3.95,36.58],[6,4.2,6.62],[7,4.1,16.5],[4,4.6,5.66],[5,4.5,9.29],[1,4.9,10.34],[2,4.8,4.59]],"bdatl":[[7,6.2,4.57],[9,6.8,4.47]],"id":37947503},{"atb":[[1.23,230.53],[1.28,4.55],[1.26,87.93],[1.25,106.37],[1.19,31.16],[1.27,40.18]],"atl":[[1.31,11.6],[1.29,43.02],[1.3,9.23],[1.28,0]],"bdatb":[[5,1.23,230.53],[0,1.28,4.55],[1,1.27,40.18],[2,1.26,87.93],[3,1.25,106.37],[4,1.24,100.28],[6,1.22,81.84],[7,1.21,228.07],[8,1.2,187.9],[9,1.19,51.46]],"bdatl":[[2,1.31,9.39],[4,1.38,5.1],[5,1.39,9.54],[8,1.43,4.11],[9,1.44,4.2],[0,1.29,33.72],[1,1.3,9.23],[3,1.36,9.13],[6,1.4,1.45],[7,1.41,8.93]],"id":39823721},{"bdatb":[[8,8.2,1.07],[9,7,36.61],[6,9.6,1.74],[7,8.8,1.17],[2,11.5,3.66],[3,11,2.93],[4,10.5,3.09],[5,10,3.81]],"bdatl":[[3,29,5.52],[5,36,10.36],[8,1000,5.35],[6,40,6.41]],"id":44331354}],"con":true}]}
{"op":"mcm","clk":"AJQIAI0HALUG","pt":1650392679431,"mc":[{"id":"1.197931751","rc":[{"atb":[[2.54,18.87],[2.56,0],[2.7,2.21],[2.58,0]],"bdatb":[[8,2.42,2.12],[9,2.38,2.79],[6,2.54,18.87],[0,2.7,2.21],[7,2.52,13.55]],"bdatl":[[7,3.05,16.11],[9,3.15,22.96],[8,3.1,3.2]],"id":42930960},{"atb":[[2.44,4.63],[2.36,24.85],[2.46,5.68],[2.42,4.67],[2.48,10.33]],"atl":[[2.54,0],[2.6,21.42],[1000,5]],"bdatb":[[2,2.44,4.63],[3,2.42,4.67],[4,2.4,2.93],[5,2.38,14.18],[6,2.36,24.85],[7,2.32,22.01],[8,2.26,2.67],[9,2.22,2.58],[1,2.46,5.68],[0,2.48,10.33]],"bdatl":[[0,2.56,2],[1,2.58,20.77],[2,2.6,21.42],[3,2.62,11.65],[4,2.64,4.23],[5,2.66,18.85],[6,2.68,2.36],[7,2.72,11.66],[8,2.74,7.02],[9,2.76,8.19]],"id":36276560},{"atb":[[1.24,211.51],[1.27,93.81],[1.28,4.87],[1.05,250],[1.26,103.11],[1.2,30.35]],"atl":[[1.53,75.37],[1.31,14.18],[1.29,4.67],[1.3,33.4]],"trd":[[1.29,10.66]],"bdatb":[[1,1.27,93.81],[7,1.21,222.59],[8,1.2,48.17],[0,1.28,4.87],[4,1.24,203.98],[2,1.26,103.11]],"bdatl":[[2,1.31,14.18],[0,1.29,4.67],[1,1.3,33.4],[6,1.39,8.79],[7,1.41,2.79],[8,1.42,5.89],[9,1.43,2.06],[3,1.36,10.3],[4,1.37,10.62],[5,1.38,4.48]],"ltp":1.29,"tv":607.99,"id":39823721},{"bdatb":[[6,4,10.1],[7,3.95,3.49],[8,3.85,17.71],[9,3.8,8.59]],"bdatl":[[9,7,18.49],[6,6.2,1.29],[5,5.9,1.01],[7,6.4,1.81],[8,6.6,8.52]],"id":40095374},{"bdatb":[[5,4.2,5.04],[6,4.1,13.12],[7,4,5.12],[8,3.95,39.71],[9,3.9,6.79],[4,4.5,9.29]],"bdatl":[[8,6.4,8.41],[9,6.8,3.8]],"id":37947503},{"bdatb":[[2,11.5,3.07],[3,11,2.94],[4,10.5,3.17],[5,10,1.7],[6,9.6,2.78],[9,8.2,1.11],[7,9.4,1.29],[8,9.2,1.17]],"bdatl":[[8,1000,5.65],[5,36,10.21],[4,32,3.42]],"id":44331354}],"con":true,"tv":987.69}]}
{"op":"mcm","clk":"ALcJALYIAMwH","pt":1650392680432,"mc":[{"id":"1.197931751","rc":[{"atb":[[2.7,9.15]],"atl":[[2.78,2.6]],"bdatb":[[9,2.4,6.95],[8,2.46,2.08],[0,2.7,9.15]],"bdatl":[[7,3.05,14.06],[8,3.1,7.78],[9,3.15,17.53],[0,2.78,2.6]],"id":42930960},{"atb":[[4.2,0],[4.7,0],[4.6,3.09],[4.4,3.25],[4.3,17.36],[4.5,21.5]],"atl":[[5.4,0],[4.9,4.45],[4.7,0],[5.1,17.41],[5,9.19]],"trd":[[4.7,11.76]],"bdatb":[[4,4.1,9.09],[5,4,10.1],[6,3.95,3.49],[7,3.85,17.71],[8,3.8,7.58],[9,3.75,1.03],[0,4.6,3.09],[1,4.5,21.5],[2,4.4,3.25],[3,4.3,17.36]],"bdatl":[[5,5.9,4.19],[6,6.4,1.29],[7,6.6,8.18],[8,6.8,1.13],[9,7,17.18],[0,4.9,4.45],[1,5,9.19],[2,5.1,17.41],[3,5.2,8.8],[4,5.3,5.24]],"ltp":4.7,"tv":33.12,"id":40095374},{"atb":[[2.34,21.68],[2.42,9.42],[2.36,3.49]],"atl":[[2.62,18.53],[2.6,21.42],[2.58,13.34],[3.6,57.69]],"bdatb":[[8,2.32,22.01],[9,2.28,2.64],[7,2.34,21.68],[3,2.42,9.42],[6,2.36,3.49]],"bdatl":[[2,2.6,21.42],[3,2.62,18.53],[1,2.58,13.34]],"id":36276560},{"atb":[[4.8,6.83]],"bdatb":[[7,4.1,16.75],[8,4,3.25],[5,4.3,1.19],[6,4.2,4.04],[9,3.95,36.14],[2,4.8,6.83]],"bdatl":[[8,6.4,7.47],[9,6.6,2.15]],"id":37947503},{"atb":[[1.28,24.1],[1.23,202.55],[1.16,4.28]],"atl":[[1.31,58.06],[1.39,8.33]],"bdatb":[[0,1.28,24.1],[6,1.22,81.84],[7,1.21,224.32],[8,1.2,53.35],[5,1.23,202.55],[9,1.19,35.13],[4,1.24,211.51]],"bdatl":[[3,1.37,18.03],[4,1.39,15.56],[5,1.4,3.47],[6,1.41,5.49],[7,1.42,12.93],[8,1.43,5.59],[9,1.44,8.15],[2,1.31,58.06]],"id":39823721},{"bdatb":[[5,10,2.59],[6,9.8,1.33],[9,8.2,1.54],[1,13,9.04],[2,11.5,3.52],[3,11,2.56],[4,10.5,3.19],[7,9.6,1.64],[8,8.8,1.21]],"bdatl":[[4,32,3.23],[6,40,6.78],[8,1000,5.41],[7,42,2.44],[5,36,10.2]],"id":44331354}],"con":true,"tv":999.45}]}
{"op":"mcm","clk":"ANcKANkJAM8I","pt":1650392681433,"mc":[{"id":"1.197931751","rc":[{"atb":[[2.66,7.75],[2.7,13.16],[2.64,24.68]],"atl":[[2.78,0.6],[2.84,2.17],[2.8,2.93]],"bdatb":[[2,2.66,7.75],[0,2.7,13.16],[3,2.64,24.68],[8,2.48,2.06],[9,2.42,2.84]],"bdatl":[[0,2.8,3.53],[1,2.82,3.14],[2,2.84,2.17],[3,2.86,10.14],[4,2.94,2.71],[5,2.96,13.77],[6,3.05,14.06],[7,3.1,7.78],[8,3.15,19.19],[9,3.25,4.69]],"id":42930960},{"atb":[[4.5,8.31],[4.4,11.79]],"atl":[[5.3,0],[5.4,0],[4.9,9.4],[5,11.19],[5.1,15.36],[4.8,2.5]],"bdatb":[[6,3.95,2.61],[7,3.85,18.6],[8,3.8,1.01],[1,4.5,8.31],[2,4.4,11.79],[9,3.75,2.36]],"bdatl":[[7,6.8,1.82],[8,7,18.28],[5,5.9,5.23],[6,6.6,9.68],[9,7.2,4.31],[1,4.9,9.4],[2,5,11.19],[3,5.1,15.36],[0,4.8,2.5],[4,5.2,8.8]],"id":40095374},{"atb":[[2.42,29.88],[2.46,11.08],[2.48,13.08]],"atl":[[2.62,11.65]],"bdatb":[[9,2.28,2.64],[3,2.42,29.88],[1,2.46,11.08],[0,2.48,13.08]],"bdatl":[[3,2.62,11.65]],"id":36276560},{"atb":[[4.8,14.48]],"bdatb":[[5,4.3,1.19],[6,4.2,4.04],[7,4.1,14.36],[8,4,3.22],[9,3.95,37.61],[2,4.8,14.48]],"id":37947503},{"atb":[[1.24,203.98],[1.21,80.02]],"atl":[[1.39,0]],"bdatb":[[4,1.24,203.98],[6,1.22,83.2],[7,1.21,88.57],[8,1.2,41.07],[9,1.19,43.49]],"bdatl":[[5,1.39,6.35],[7,1.41,5.75],[8,1.42,3.16],[9,1.43,14.85],[3,1.37,23.68],[4,1.38,1.67],[6,1.4,5.73]],"id":39823721},{"bdatb":[[2,11.5,3.59],[3,11,2.47],[4,10.5,3.65],[5,10,1.8],[7,9.4,1.47],[8,9,1.19],[9,7.6,1.08],[6,9.6,1.87]],"bdatl":[[8,1000,5.53]],"id":44331354}],"con":true}]}
{"op":"mcm","clk":"AOMLAPIKAOYJ","pt":1650392682434,"mc":[{"id":"1.197931751","rc":[{"atb":[[2.6,15.56],[2.66,13.81],[2.12,0],[2.22,87.56]],"bdatb":[[5,2.6,15.56],[8,2.5,2.41],[9,2.46,2.15],[2,2.66,13.81]],"bdatl":[[9,3.25,4.69]],"id":42930960},{"atl":[[5.2,9.04],[1000,5],[6.6,0],[8.8,12.82],[6,8],[10,0]],"bdatb":[[6,3.95,3.3],[7,3.85,18.83],[8,3.8,1.35],[9,3.7,11.19],[5,4,10.52]],"bdatl":[[7,6.6,2.54],[8,6.8,1.82],[6,6,8],[9,7,18.28]],"id":40095374},{"atb":[[2.42,37.18],[2.48,13.08]],"atl":[[3.7,92.59],[2.54,4.45]],"bdatb":[[0,2.48,13.08]],"bdatl":[[0,2.54,4.45],[1,2.56,2],[2,2.58,13.34],[3,2.6,21.42],[4,2.62,11.65],[5,2.64,4.23],[6,2.66,18.85],[7,2.68,2.36],[8,2.72,11.66],[9,2.74,7.02]],"id":36276560},{"bdatb":[[5,4.4,1.37],[6,4.2,5.08],[7,4.1,14.15],[8,4,2.11],[9,3.95,40.12]],"id":37947503},{"bdatb":[[6,1.22,89.92],[7,1.21,81.79],[9,1.19,52.83]],"bdatl":[[3,1.37,23.68],[4,1.38,1.67],[5,1.39,6.35],[6,1.4,5.73],[7,1.41,5.75],[8,1.42,7.96],[9,1.43,10.09]],"id":39823721},{"bdatb":[[2,11.5,3.9],[3,11,2.6],[4,10.5,3.15],[8,9.2,1.17]],"bdatl":[[8,1000,5.53]],"id":44331354}],"con":true}]}
{"op":"mcm","clk":"AIYNAIcMAPoK","pt":1650392683435,"mc":[{"id":"1.197931751","rc":[{"atb":[[2.62,16.82],[2.66,22.97],[2.74,2.12],[2.72,6.89]],"atl":[[2.94,6.98],[2.84,0]],"bdatb":[[9,2.52,15.94],[4,2.66,22.97],[6,2.62,16.82],[0,2.74,2.12],[1,2.72,6.89],[2,2.7,13.16],[3,2.68,3],[5,2.64,24.68],[7,2.6,15.56],[8,2.54,18.87]],"bdatl":[[7,3.15,18.01],[8,3.2,1.66],[9,3.25,4.19],[2,2.86,10.14],[3,2.94,6.98],[4,2.96,13.77],[5,3.05,14.06],[6,3.1,7.78]],"id":42930960},{"atb":[[4.4,15.51]],"atl":[[1000,5.24],[4.8,7.46],[5.2,3.83]],"bdatb":[[5,4,11.61],[6,3.95,2.44],[7,3.85,20.41],[8,3.7,10.68],[9,3.65,2.48],[2,4.4,15.51]],"bdatl":[[5,5.7,1.03],[7,6,8.44],[8,6.2,1.23],[9,6.4,2.32],[0,4.8,7.46],[6,5.8,3.23],[4,5.2,3.83]],"id":40095374},{"atl":[[2.52,2.79]],"bdatb":[[3,2.42,37.18]],"bdatl":[[0,2.52,2.79],[1,2.54,4.45],[2,2.56,2],[3,2.58,13.34],[4,2.6,21.42],[5,2.62,11.65],[6,2.64,4.23],[7,2.66,18.85],[8,2.68,2.36],[9,2.72,11.66]],"id":36276560},{"atb":[[4.6,5.66]],"bdatb":[[5,4.5,9.66],[6,4.3,1.22],[7,4.2,6.51],[8,4.1,14.15],[9,4,3.09],[4,4.6,5.66]],"bdatl":[[7,6.2,4.93],[8,6.4,9.34],[9,6.6,1.57]],"id":37947503},{"atb":[[1.28,21.2],[1.26,119.5]],"atl":[[1000,5]],"trd":[[1.28,69.13]],"bdatb":[[0,1.28,21.2],[5,1.23,203.9],[6,1.22,88.57],[8,1.2,44.59],[9,1.19,41.17],[2,1.26,119.5],[7,1.21,87.34]],"bdatl":[[3,1.35,1.69],[4,1.36,8.77],[5,1.37,13.31],[6,1.38,1.67],[7,1.39,12.12],[8,1.4,5.79],[9,1.42,7.95]],"ltp":1.28,"tv":613.79,"id":39823721},{"atb":[[14,0.16],[1.02,3.44]],"bdatb":[[0,13.5,3.67],[1,13,9.17],[2,11.5,3.75],[3,11,3.24],[4,10.5,3.12],[5,10,1.6],[6,9.8,1.26],[9,7.8,1.28],[7,9.6,1.24],[8,9.2,1.29]],"bdatl":[[8,1000,5.37],[4,32,3.41],[5,36,10.45],[6,40,6.67]],"id":44331354}],"con":true,"tv":1005.25}]}
{"op":"mcm","clk":"AL4OAJwNAI0M","pt":1650392684436,"mc":[{"id":"1.197931751","rc":[{"atb":[[2.74,8.98]],"atl":[[2.8,0]],"bdatb":[[0,2.74,8.98]],"bdatl":[[0,2.82,3.74],[1,2.86,10.14],[2,2.94,6.98],[3,2.96,13.77],[4,3.05,14.06],[5,3.1,7.78],[6,3.15,18.01],[7,3.2,1.66],[8,3.25,4.19],[9,3.3,4.51]],"id":42930960},{"atb":[[4.4,6.97]],"atl":[[4.9,12.98],[6.4,18.52],[5.2,4.07],[1000,5]],"bdatb":[[2,4.4,6.97],[6,3.95,2.19],[7,3.85,18.64],[8,3.75,2.09],[9,3.7,10.68]],"bdatl":[[1,4.9,12.98],[7,6.4,21.21],[5,5.7,4.33],[6,6,9.32],[8,6.6,1.53],[9,6.8,2.82],[4,5.2,4.07]],"id":40095374},{"atb":[[4.6,0]],"bdatb":[[6,4.2,4.65],[7,4.1,16.06],[9,3.95,34.84],[4,4.5,9.66],[5,4.3,1.22],[8,4,3.09]],"bdatl":[[9,6.6,1.96]],"id":37947503},{"atl":[[1000,7],[1.31,82.67]],"bdatb":[[6,1.22,86.25],[7,1.21,89.36],[8,1.2,44.91],[9,1.19,34.28]],"bdatl":[[4,1.36,16.41],[5,1.37,5.72],[6,1.38,7.9],[7,1.39,5.93],[9,1.41,8.01],[2,1.31,82.67]],"id":39823721},{"bdatb":[[2,11.5,3.51],[3,11,2.79],[4,10.5,3.83],[5,10,1.64],[8,8.4,1.58],[9,7.8,1.07]],"bdatl":[[4,32,3.67],[5,36,10.48],[6,40,6.47],[8,1000,5.36]],"id":44331354}],"con":true}]}
{"op":"mcm","clk":"AOAPAKUOALAN","pt":1650392685438,"mc":[{"id":"1.197931751","rc":[{"atb":[[2.54,0],[2.68,20.29]],"atl":[[3.1,8.87],[2.82,0]],"bdatb":[[3,2.68,20.29],[9,2.52,16.11]],"bdatl":[[0,2.86,10.74],[1,2.94,6.98],[2,2.96,13.77],[3,3.05,14.06],[4,3.1,7.78],[5,3.15,18.01],[6,3.2,1.66],[7,3.25,4.19],[8,3.3,4.51],[9,3.35,3.51]],"id":42930960},{"atb":[[4.1,19.33]],"atl":[[7,0],[7.8,0],[7.4,0]],"bdatb":[[4,4.1,19.33],[5,4,10.52],[7,3.9,1.23],[8,3.85,17.48],[9,3.75,3.17]],"bdatl":[[9,6.8,3.72]],"id":40095374},{"atb":[[2.44,10.37]],"bdatb":[[9,2.24,2.85],[2,2.44,10.37]],"id":36276560},{"atl":[[1.29,4.99],[1000,5]],"bdatb":[[6,1.22,81.84],[7,1.21,93.8],[8,1.2,40.62],[9,1.19,35.48]],"bdatl":[[0,1.29,4.99],[9,1.41,13.6]],"id":39823721},{"bdatb":[[5,4.3,1.11],[6,4.2,3.96],[7,4.1,16.91],[8,4,1.8],[9,3.95,33.9]],"id":37947503},{"bdatb":[[2,11.5,3.49],[3,11,2.53],[4,10.5,4.16],[6,9.6,1.97],[7,8.4,2.23],[8,7.6,5.53],[9,7,36.23]],"bdatl":[[8,1000,5.37]],"id":44331354}],"con":true}]}
{"op":"mcm","clk":"AIMRALkPAL4O","pt":1650392686440,"mc":[{"id":"1.197931751","rc":[{"atb":[[2.68,24.87]],"atl":[[2.86,3.19],[2.94,2.71]],"bdatb":[[8,2.52,13.55],[9,2.5,2.57],[3,2.68,24.87]],"bdatl":[[0,2.86,3.79],[5,3.15,13.91],[6,3.2,8.04],[7,3.25,5.27],[8,3.35,8.33],[9,3.4,1.99],[4,3.1,8.87],[1,2.94,2.71]],"id":42930960},{"atb":[[4.5,5.72],[4.6,0],[4.3,12.42]],"atl":[[6.8,25.86],[4.9,12.98],[4.8,10.86]],"trd":[[4.6,6.18]],"bdatb":[[6,3.85,18.72],[7,3.75,1.16],[8,3.7,5.19],[9,3.6,2.21],[0,4.5,5.72],[1,4.4,6.97],[2,4.3,12.42],[3,4.1,19.33],[4,4,10.52],[5,3.95,2.19]],"bdatl":[[5,5.9,4.17],[6,6,9.16],[9,6.8,29.58],[7,6.4,21.35],[8,6.6,1.39],[0,4.8,10.86],[1,4.9,12.98]],"ltp":4.6,"tv":39.3,"id":40095374},{"atb":[[2.48,12.72]],"atl":[[2.52,0],[2.56,11.19]],"bdatb":[[0,2.48,12.72]],"bdatl":[[0,2.54,4.45],[1,2.56,11.19],[2,2.58,13.34],[3,2.6,21.42],[4,2.62,11.65],[5,2.64,4.23],[6,2.66,18.85],[7,2.68,2.36],[8,2.72,11.66],[9,2.74,7.02]],"id":36276560},{"atb":[[1.28,0],[1.22,14.29],[1.19,0],[1.21,29.92],[1.2,2]],"bdatb":[[0,1.27,93.81],[1,1.26,119.5],[2,1.25,106.37],[3,1.24,203.98],[4,1.23,202.55],[5,1.22,15.65],[6,1.21,37.46],[7,1.2,2],[8,1.19,23.44],[9,1.18,10.16]],"bdatl":[[4,1.38,5.04],[5,1.39,8.49],[6,1.4,9.31],[7,1.41,1.72],[8,1.42,14.13],[9,1.43,4.58],[3,1.36,18.09]],"id":39823721},{"bdatb":[[4,4.5,9.29],[5,4.2,5.34],[6,4.1,13.96],[7,3.95,34.03],[8,3.9,14.13],[9,3.85,55.2]],"bdatl":[[8,6.4,7.47],[9,6.8,6.24],[7,6.2,4.57]],"id":37947503},{"bdatb":[[1,13,9.04],[2,11.5,3.2],[3,11,2.91],[4,10.5,3.49],[5,10,1.13],[6,9.6,1.29],[7,9,3.02],[8,8.6,1.3],[9,7.6,1.25]],"bdatl":[[5,36,10.2],[6,40,6.41],[8,1000,5.79],[4,32,3.23]],"id":44331354}],"con":true,"tv":1011.43}]}
{"op":"mcm","clk":"AK4SAMMQANQP","pt":1650392687441,"mc":[{"id":"1.197931751","rc":[{"atb":[[2.7,50.09],[2.64,24.68]],"atl":[[2.96,18.07],[3.1,3.2]],"bdatb":[[2,2.7,50.09],[5,2.64,24.68],[8,2.52,15.2],[9,2.5,2.84]],"bdatl":[[4,3.1,3.26],[5,3.15,14.57],[2,2.96,18.07],[8,3.3,1.6],[9,3.35,3.43],[6,3.2,7.32],[7,3.25,6.26]],"id":42930960},{"atb":[[4.1,17.83],[4.4,3.25]],"atl":[[5.8,8.33]],"bdatb":[[3,4.1,17.83],[1,4.4,3.25],[6,3.85,19.84],[7,3.7,5.32],[8,3.65,1.96],[4,4,10.52],[5,3.95,2.19],[9,3.55,5.7]],"bdatl":[[5,5.8,10.09],[6,5.9,2.45],[7,6,9.69],[8,6.2,1.13],[9,6.4,19.75]],"id":40095374},{"atb":[[2.42,29.88],[2.44,4.63],[2.5,4.07]],"atl":[[2.52,1.65],[2.5,0],[2.54,2.8]],"bdatb":[[4,2.42,29.88],[3,2.44,4.63],[0,2.5,4.07],[1,2.48,12.72],[2,2.46,11.08],[5,2.4,2.93],[6,2.38,14.18],[7,2.36,3.49],[8,2.34,21.68],[9,2.32,22.01]],"bdatl":[[0,2.52,1.65],[1,2.54,2.8],[2,2.56,11.19],[3,2.58,13.34],[4,2.6,21.42],[5,2.62,11.65],[6,2.64,4.23],[7,2.66,18.85],[8,2.68,2.36],[9,2.72,11.66]],"id":36276560},{"atb":[[1.23,202.55],[1.28,0.16],[1.25,106.37],[1.05,251],[1.26,103.11],[1.27,84.36]],"atl":[[1.29,14.29]],"bdatb":[[0,1.27,84.52],[4,1.23,203.9],[2,1.25,106.37],[5,1.22,14.29],[6,1.21,37.46],[7,1.2,2],[8,1.19,23.44],[9,1.18,10.16],[1,1.26,103.11]],"bdatl":[[6,1.39,3.8],[7,1.4,2.38],[8,1.41,18.18],[9,1.42,7.96],[3,1.35,1.69],[4,1.36,16.41],[5,1.38,7.35],[0,1.29,14.29]],"id":39823721},{"bdatb":[[4,4.5,9.66],[5,4.2,5.98],[9,3.9,12.3],[6,4.1,12.9],[7,4,1.91],[8,3.95,33.9]],"bdatl":[[8,6.4,7.51],[9,6.8,6.21]],"id":37947503},{"bdatb":[[9,8,1.39],[1,13,9.17],[2,11.5,3.29],[3,11,3.08],[4,10.5,3.08],[5,10,1.18],[6,9.6,1.97],[7,9,2.24],[8,8.6,1.39],[0,13.5,3.67]],"bdatl":[[4,32,3.24],[8,1000,5.52],[6,40,6.66]],"id":44331354}],"con":true}]}
{"op":"mcm","clk":"ANATAMgRANAQ","pt":1650392688443,"mc":[{"id":"1.197931751","rc":[{"atl":[[5.2,4.07],[5.1,4.27],[4.9,15.03],[4.7,5.08]],"bdatb":[[6,3.85,18.71],[7,3.75,1.16],[8,3.7,5.19],[9,3.6,2.21]],"bdatl":[[5,5.2,4.07],[4,5.1,4.27],[2,4.9,15.03],[0,4.7,5.08],[1,4.8,10.86],[3,5,11.19],[6,5.8,10.09],[7,5.9,2.45],[8,6,9.69],[9,6.2,1.13]],"id":40095374},{"atb":[[2.46,14.72]],"bdatb":[[2,2.46,14.72],[9,2.32,22.73]],"id":36276560},{"atb":[[4.6,5.66]],"bdatb":[[4,4.6,6.02],[5,4.5,9.29],[6,4.3,1.1],[7,4.2,4.85],[8,4.1,12.9],[9,4,1.99]],"bdatl":[[8,6.4,7.54],[9,6.8,6.18]],"id":37947503},{"atb":[[1.05,251],[1.25,121.31],[1.28,0.32]],"atl":[[1.29,4.99]],"bdatb":[[2,1.25,121.31],[0,1.27,84.68],[5,1.22,16.34],[6,1.21,35.39],[7,1.2,8.64],[8,1.19,16.74]],"bdatl":[[0,1.29,4.99],[8,1.41,24.52],[9,1.42,5.28]],"id":39823721},{"bdatb":[[9,2.52,14.46],[8,2.54,1.64]],"bdatl":[[4,3.1,3.33],[5,3.15,14.5]],"id":42930960},{"bdatb":[[2,11.5,3.48],[3,11,2.87],[4,10.5,3.08],[5,10,1.18],[6,9.6,2.02],[8,8.6,1.3],[9,8,2.8],[0,13.5,3.79],[1,13,9.04],[7,9,2.19]],"bdatl":[[6,40,6.65]],"id":44331354}],"con":true}]}
{"op":"mcm","clk":"AOUUANQSAMwR","pt":1650392689446,"mc":[{"id":"1.197931751","rc":[{"atb":[[1.07,0]],"atl":[[2.78,0]],"trd":[[2.78,1.2]],"bdatb":[[9,2.48,2.6],[8,2.52,13.55]],"bdatl":[[3,3.05,14.27],[4,3.1,3.2],[5,3.15,15.65],[6,3.2,6.13],[0,2.86,3.19],[9,3.35,5.78]],"ltp":2.78,"tv":232.68,"id":42930960},{"atb":[[4.3,16.2],[4.1,9.09]],"atl":[[6,20],[5,16.9]],"bdatb":[[7,3.75,1.72],[8,3.7,5.91],[9,3.5,10.93],[5,3.95,2.19],[4,4,10.1],[6,3.85,17.48],[2,4.3,16.2],[3,4.1,9.09]],"bdatl":[[6,5.7,1.08],[7,5.8,11.52],[8,5.9,1.7],[9,6,20.01],[3,5,16.9]],"id":40095374},{"atb":[[2.52,2.42],[2.42,37.18],[2.5,11.42]],"atl":[[2.6,28.69],[2.56,0],[2.58,4.8],[2.54,0],[2.52,0]],"trd":[[2.52,15.78]],"bdatb":[[0,2.52,2.42],[1,2.5,11.42],[2,2.48,12.72],[3,2.46,14.72],[4,2.44,4.63],[5,2.42,37.18],[6,2.4,2.93],[7,2.38,14.18],[8,2.36,3.49],[9,2.34,21.68]],"bdatl":[[0,2.58,4.8],[1,2.6,28.69],[2,2.62,11.65],[3,2.64,4.23],[4,2.66,18.85],[5,2.68,2.36],[6,2.72,11.66],[7,2.74,7.02],[8,2.76,8.19],[9,2.78,2.24]],"tv":130.16,"id":36276560},{"atb":[[4.6,0]],"bdatb":[[7,3.95,34.73],[8,3.9,8],[9,3.85,54.4],[5,4.2,5.35],[6,4.1,13.56],[4,4.5,9.29]],"bdatl":[[7,6.2,4.67],[8,6.4,7.73],[9,6.8,6.09]],"id":37947503},{"atb":[[1.05,251],[1.25,119.3],[1.28,0.48]],"bdatb":[[8,1.19,6.7],[9,1.18,18.29],[5,1.22,14.29],[7,1.2,2],[2,1.25,119.3],[4,1.23,202.55],[6,1.21,37.46],[0,1.27,84.84]],"bdatl":[[3,1.35,4.52],[4,1.36,14.43],[5,1.37,6.52],[6,1.39,3.86],[7,1.4,6.85],[8,1.41,25.4],[9,1.42,11.96]],"id":39823721},{"bdatb":[[2,11.5,3.07],[3,11,3.06],[7,9,1.62],[1,13,9.04],[5,10,1.4],[4,10.5,3.08],[6,9.6,1.24],[8,8.6,1.72],[9,8.4,1.33],[0,13.5,3.67]],"bdatl":[[3,29,5.54],[4,32,3.23],[5,36,10.35],[6,40,6.87],[8,1000,5.3]],"id":44331354}],"con":true,"tv":1015.93}]}
{"op":"mcm","clk":"APwVANsTAOMS","pt":1650392690447,"mc":[{"id":"1.197931751","rc":[{"atb":[[2.38,3.18],[2.7,33]],"atl":[[2.86,0]],"bdatb":[[2,2.7,33],[9,2.48,6.73]],"bdatl":[[8,3.4,7.07],[9,3.5,2.36],[2,3.05,14.4],[4,3.15,21.39],[5,3.25,6.62],[6,3.3,1.6],[7,3.35,6.83],[0,2.94,2.71],[1,2.96,18.07],[3,3.1,3.2]],"id":42930960},{"atb":[[2.44,24.81],[2.46,5.68],[2.42,29.88],[2.52,9.75],[1.86,174.42]],"atl":[[2.62,11.65],[3.1,0],[2.66,25.27],[2.6,21.42],[2.58,6.47]],"bdatb":[[3,2.46,5.68],[4,2.44,24.81],[5,2.42,29.88],[0,2.52,9.75]],"bdatl":[[2,2.62,11.65],[4,2.66,25.27],[1,2.6,21.42],[9,2.78,2.39],[0,2.58,6.47]],"id":36276560},{"atb":[[1.27,59.96],[1.25,119.3],[1.28,0.8],[1.05,250]],"atl":[[1.31,87.04],[1.29,38.66],[1.3,47.58]],"bdatb":[[0,1.27,60.76],[2,1.25,119.3],[8,1.19,14.04],[9,1.18,18.61],[6,1.21,29.92]],"bdatl":[[2,1.31,87.04],[9,1.42,9.31],[0,1.29,38.66],[1,1.3,47.58],[3,1.35,18.2],[4,1.37,7.43],[5,1.38,3.82],[6,1.39,2.4],[7,1.4,6.98],[8,1.41,22.91]],"id":39823721},{"bdatb":[[8,3.65,2.18],[9,3.6,2.43],[7,3.7,5.19]],"bdatl":[[6,5.7,4.32],[7,5.8,8.34],[8,5.9,1.72],[9,6,21.43]],"id":40095374},{"bdatb":[[9,3.9,13.45],[7,4,4.18],[8,3.95,35.72],[5,4.2,3.82],[6,4.1,12.9]],"bdatl":[[7,6.2,4.73],[8,6.4,7.67],[9,6.6,3.38]],"id":37947503},{"bdatb":[[7,9,2.4],[8,8.8,1.27],[9,8.2,1.41],[5,10,1.93],[6,9.6,2.13],[3,11,2.47]],"bdatl":[[8,1000,5.39],[3,29,5.56],[5,36,10.85],[6,40,6.41]],"id":44331354}],"con":true}]}
{"op":"mcm","clk":"AKYXAOAUAPkT","pt":1650392691448,"mc":[{"id":"1.197931751","rc":[{"atb":[[2.66,23.57],[1.04,0],[2.34,0]],"atl":[[3.1,3.2],[3.15,21.19],[3,2.29]],"bdatb":[[4,2.66,23.57]],"bdatl":[[4,3.1,3.2],[3,3.05,14.47],[5,3.15,28.6],[9,3.4,7.13],[2,3,2.29],[6,3.25,6.62],[7,3.3,1.6],[8,3.35,6.83]],"id":42930960},{"atb":[[4.3,18.82]],"atl":[[6.4,27.78]],"bdatb":[[2,4.3,18.82]],"bdatl":[[6,5.7,4.33]],"id":40095374},{"atl":[[2.66,18.85]],"bdatl":[[4,2.66,18.85],[9,2.78,2.46]],"id":36276560},{"atb":[[1.25,121.31],[1.05,250.16],[1.28,0.96],[1.24,82.94]],"atl":[[1.31,82.67]],"bdatb":[[2,1.25,121.31],[0,1.27,60.92],[3,1.24,82.94]],"bdatl":[[2,1.31,82.67]],"id":39823721},{"bdatl":[[7,6.2,4.77],[8,6.4,7.64]],"id":37947503},{"bdatl":[[3,29,5.57],[5,36,10.84]],"id":44331354}],"con":true}]}
{"op":"mcm","clk":"AL0YAOoVAPoU","pt":1650392692449,"mc":[{"id":"1.197931751","rc":[{"atb":[[2.7,13.16],[2.78,6.34],[2.66,24.17],[2.64,27.68],[2.72,32.1],[1.04,0],[2.62,9.85],[2.76,10.82],[2.74,20.88]],"atl":[[3.25,0],[2.94,9.35],[2.92,2.14],[3,0]],"bdatb":[[9,2.48,9.63],[0,2.74,20.88]],"bdatl":[[0,2.92,2.14],[1,2.94,9.35],[2,2.96,18.07],[3,3.05,14.06],[4,3.1,3.2],[5,3.15,21.91],[6,3.2,3.86],[7,3.25,7.88],[8,3.35,4.7],[9,3.4,2.57]],"id":42930960},{"atb":[[4,10.1],[4.3,10.02],[4.2,10.13],[4.5,3.25]],"atl":[[5.8,0],[5.7,8.51]],"bdatb":[[2,4.3,10.02],[9,3.65,9.24],[3,4.2,10.13],[4,4.1,9.09],[5,4,10.1],[6,3.95,2.19],[7,3.85,17.48],[8,3.7,5.19],[0,4.5,3.25]],"bdatl":[[6,5.7,8.91],[7,5.8,1.36],[8,5.9,4.16],[9,6,20]],"id":40095374},{"atb":[[2.46,5.68],[2.52,0],[2.42,25.21],[2.5,0],[2.44,20.18],[2.32,0],[2.48,9.97],[2.54,0],[2.4,0]],"atl":[[2.56,0],[2.58,15.65],[2.62,4.3]],"bdatb":[[3,2.44,20.18],[8,2.24,2.79],[9,2.22,7.95],[0,2.5,4.07],[1,2.48,9.97],[2,2.46,5.68],[4,2.42,29.88],[5,2.38,14.18],[6,2.36,3.49],[7,2.34,21.68]],"bdatl":[[0,2.58,15.65],[1,2.6,21.42],[2,2.62,4.3],[3,2.64,4.23],[4,2.66,18.85],[5,2.68,2.36],[6,2.72,11.66],[7,2.74,7.02],[8,2.76,8.19],[9,2.78,2.02]],"id":36276560},{"atb":[[1.26,94.1],[1.25,147.99],[1.27,0],[1.24,82.94],[1.05,250],[1.28,0]],"atl":[[1000,12],[1.39,8.33]],"trd":[[1.27,84.83],[1.28,71.68]],"bdatb":[[0,1.27,34.37],[2,1.25,119.3],[7,1.2,2],[8,1.19,28.35],[9,1.18,5.64],[3,1.24,113.25],[1,1.26,103.11],[4,1.23,202.55],[5,1.22,14.29],[6,1.21,29.92]],"bdatl":[[7,1.39,8.45],[8,1.4,10.5],[9,1.41,5.39],[3,1.35,1.69],[4,1.36,9.08],[5,1.37,10.44],[6,1.38,4.21]],"ltp":1.27,"tv":681.17,"id":39823721},{"bdatb":[[6,4.1,14.42],[7,4,4.41],[8,3.95,38.08],[9,3.9,9.22]],"bdatl":[[8,6.4,7.47],[9,6.8,4.79],[7,6.2,4.57]],"id":37947503},{"bdatb":[[5,10,3.52],[6,9.6,2.26],[7,8.8,1.8],[8,8.2,3.18],[9,7.8,1.44]],"bdatl":[[8,1000,5.45],[4,32,3.23],[6,40,6.66],[1,27,2.98],[5,36,10.2],[3,29,5.52]],"id":44331354}],"con":true,"tv":1083.31}]}
{"op":"mcm","clk":"AM0ZAOEWAJAW","pt":1650392693450,"mc":[{"id":"1.197931751","rc":[{"atb":[[2.64,6.97],[2.74,20.88],[2.68,24.87],[2.8,0],[2.72,23.78],[2.82,1.97]],"atl":[[2.94,11.58],[3.15,13.91]],"bdatb":[[3,2.74,20.88],[8,2.64,6.97],[1,2.78,6.34],[2,2.76,10.82],[4,2.72,23.78],[5,2.7,13.16],[6,2.68,24.87],[7,2.66,24.17],[9,2.62,9.85],[0,2.82,1.97]],"bdatl":[[1,2.94,11.58],[7,3.35,4.09],[8,3.4,3.06],[9,3.45,1.04],[6,3.3,4.44],[5,3.15,13.91]],"id":42930960},{"atb":[[4.2,19.21]],"bdatb":[[8,3.7,6.7],[9,3.65,9.06],[3,4.2,19.21]],"bdatl":[[7,6,22.72],[8,6.2,2.25],[9,6.4,28.13],[6,5.7,8.91]],"id":40095374},{"atb":[[2.42,4.75],[2.48,7.47],[2.44,0]],"atl":[[2.56,2.19],[2.6,28.67],[2.72,2.16],[2.58,35.64]],"bdatb":[[2,2.42,4.75],[8,2.2,6.72],[9,2.18,5.5],[0,2.48,7.47],[1,2.46,5.68],[3,2.38,14.18],[4,2.36,3.49],[5,2.34,21.68],[6,2.24,2.79],[7,2.22,7.95]],"bdatl":[[0,2.56,2.19],[1,2.58,35.64],[2,2.6,28.67],[3,2.62,4.3],[4,2.64,4.23],[5,2.66,18.85],[6,2.68,2.36],[7,2.72,2.16],[8,2.74,7.02],[9,2.76,8.19]],"id":36276560},{"atb":[[1.28,0.16],[1.05,250],[1.24,82.94],[1.09,730],[1.25,111.78]],"atl":[[1.29,39.78],[1000,5.16],[1.39,0]],"bdatb":[[6,1.2,6.67],[7,1.19,27.78],[9,1.17,36.64],[2,1.24,82.94],[8,1.18,10.16],[1,1.25,111.78],[3,1.23,202.55],[4,1.22,14.29],[5,1.21,29.92],[0,1.26,94.1]],"bdatl":[[0,1.29,39.78],[6,1.37,3.4],[7,1.38,4.16],[8,1.39,2.57],[9,1.4,1.6],[3,1.34,1.7],[4,1.35,9.14],[5,1.36,2.87]],"id":39823721},{"bdatb":[[8,3.95,40.84],[6,4.1,14.42],[7,4,4.41],[9,3.9,6.79]],"bdatl":[[9,6.8,4.79]],"id":37947503},{"bdatb":[[4,10.5,3.61],[5,10,2.96],[8,8.4,3.01],[9,8,2.19],[6,9.6,2.78],[7,9,1.33]],"bdatl":[[8,1000,5.39],[6,40,6.55]],"id":44331354}],"con":true}]}
{"op":"mcm","clk":"AOgaAOcXAMkX","pt":1650392694451,"mc":[{"id":"1.197931751","rc":[{"atb":[[2.62,5.43],[2.74,41.91]],"bdatb":[[3,2.74,41.91],[9,2.62,5.43]],"bdatl":[[6,3.3,4.45],[5,3.15,13.91],[7,3.35,6.03],[8,3.4,1.14],[9,3.45,1.69]],"id":42930960},{"atb":[[4.2,23.02],[4.3,6.23]],"bdatb":[[3,4.2,23.02],[2,4.3,6.23]],"bdatl":[[7,6,23.81],[8,6.2,1.56],[9,6.4,28.45]],"id":40095374},{"atb":[[2.42,0],[2.48,10.1],[2.4,20.75]],"atl":[[2.6,90.37]],"bdatb":[[2,2.4,20.75],[3,2.38,14.18],[4,2.36,3.49],[5,2.34,21.68],[6,2.24,2.79],[7,2.22,7.95],[8,2.2,6.72],[9,2.18,5.5],[0,2.48,10.1]],"bdatl":[[9,2.76,8.23],[2,2.6,90.37],[7,2.72,2.16]],"id":36276560},{"atb":[[4.9,17.79]],"bdatb":[[8,3.95,40.89],[1,4.9,17.79]],"bdatl":[[8,6.4,7.49],[9,6.8,4.77],[6,6,15.44]],"id":37947503},{"atb":[[1.04,0],[1.24,84.96],[1.27,0.09],[1.09,729],[1.25,106.37],[1.28,0]],"atl":[[1000,6],[1.29,39.94]],"trd":[[1.28,72]],"bdatb":[[2,1.24,84.96],[0,1.26,94.19],[1,1.25,106.37]],"bdatl":[[9,1.41,9.93],[0,1.29,39.94],[5,1.36,6.29],[6,1.37,1.37],[7,1.38,2.81],[8,1.39,7.27]],"ltp":1.28,"tv":681.49,"id":39823721},{"atb":[[13.5,5.98],[11,0]],"bdatb":[[0,13.5,6.14],[3,10.5,3.61],[4,10,2.96],[5,9.6,2.78],[6,9,1.33],[7,8.4,3.02],[8,8,2.19],[9,7.2,1.67]],"bdatl":[[0,26,8.07],[6,40,6.55],[8,1000,5.41]],"id":44331354}],"con":true,"tv":1083.63}]}
{"op":"mcm","clk":"AIMcAOsYANQY","pt":1650392695452,"mc":[{"id":"1.197931751","rc":[{"atb":[[2.76,6.71],[2.78,2.04],[2.74,46.52],[2.82,0],[2.66,6.67],[2.7,6.22]],"atl":[[2.96,7.81],[3.15,22.87],[2.9,2.37],[2.82,2.44],[2.92,22.46],[2.94,4.94]],"trd":[[2.82,3.94]],"bdatb":[[0,2.82,1.97],[7,2.66,6.67],[5,2.7,6.22]],"bdatl":[[0,2.92,22.46],[6,3.2,4.05],[7,3.3,4.44],[8,3.35,3.31],[9,3.4,1.71],[5,3.15,13.91],[1,2.94,4.94],[2,2.96,4.3]],"ltp":2.82,"tv":236.62,"id":42930960},{"atb":[[2.48,14.84],[2.52,5.14],[2.38,14.18],[2.4,25.68],[2.46,10.14],[2.5,5.86]],"atl":[[2.56,0],[2.64,11.02],[2.62,4.3],[2.58,15.65],[2.6,28.67]],"trd":[[2.52,26.5]],"bdatb":[[0,2.52,5.14],[8,2.3,5.34],[9,2.26,5.14],[1,2.5,5.86],[2,2.48,10.1],[3,2.46,10.14],[4,2.4,25.68],[5,2.38,14.18],[6,2.36,3.49],[7,2.34,21.68]],"bdatl":[[0,2.58,15.65],[1,2.6,28.67],[2,2.62,4.3],[3,2.64,11.02],[4,2.66,18.85],[5,2.68,2.36],[6,2.72,2.16],[7,2.74,7.02],[8,2.76,8.19],[9,2.78,2.02]],"tv":140.88,"id":36276560},{"atb":[[4.9,10.34]],"bdatb":[[7,4.1,13],[8,4,4.02],[9,3.95,40.28],[5,4.3,2.86],[6,4.2,6.58],[1,4.9,10.34]],"bdatl":[[8,6.4,8.34],[9,6.6,1.12],[7,6.2,4.57]],"id":37947503},{"atb":[[1.04,0],[1.24,99.32],[1.27,0]],"atl":[[1000,7],[1.32,9.34],[1.28,9.38],[1.29,67.27],[1.27,9.67]],"trd":[[1.27,85.49]],"bdatb":[[6,1.2,2],[7,1.19,32.49],[9,1.17,25.17],[8,1.18,10.16],[2,1.24,99.32],[0,1.26,94.1]],"bdatl":[[1,1.28,9.38],[5,1.32,9.34],[6,1.33,4.18],[7,1.34,5.53],[8,1.35,1.23],[9,1.36,9.55],[2,1.29,67.27],[0,1.27,9.67],[3,1.3,47.58],[4,1.31,82.67]],"ltp":1.27,"tv":682.15,"id":39823721},{"atb":[[10,4.92],[13.5,2.92],[13,6.05]],"bdatb":[[2,11.5,4.14],[4,10.5,3.12],[5,10,4.92],[6,9.8,1.47],[7,9.6,1.24],[8,9.2,1.3],[9,9,1.66],[3,11,1.06],[0,13.5,3.08],[1,13,6.05]],"bdatl":[[4,32,3.4],[6,40,6.6],[7,42,2.48],[8,1000,5.36],[5,36,10.2],[2,28,13.58]],"id":44331354},{"bdatb":[[7,3.85,20.67],[8,3.75,3.2],[9,3.7,5.19]],"bdatl":[[6,5.7,10.8],[7,5.8,1.76],[8,6,21.94],[9,6.2,1.11]],"id":40095374}],"con":true,"tv":1098.95}]}
{"op":"mcm","clk":"AJsdAPEZAOAZ","pt":1650392696454,"mc":[{"id":"1.197931751","rc":[{"atb":[[2.78,2.04],[2.74,29.83],[2.36,26.4]],"atl":[[3.15,13.91],[2.84,2.41],[2.88,2.4],[4,0],[2.92,26.01],[2.9,5.58],[2.82,0]],"trd":[[2.78,5.28]],"bdatb":[[0,2.78,2.04],[1,2.76,6.71],[2,2.74,29.83],[3,2.72,23.78],[4,2.7,6.22],[5,2.68,24.87],[6,2.66,6.67],[7,2.64,6.97],[8,2.62,5.43],[9,2.6,15.56]],"bdatl":[[8,3.15,15.06],[0,2.84,2.41],[1,2.88,2.4],[2,2.9,5.58],[3,2.92,26.01],[4,2.94,4.94],[5,2.96,7.81],[6,3.05,14.06],[7,3.1,3.2],[9,3.2,2.92]],"ltp":2.78,"tv":240.7,"id":42930960},{"atb":[[3.85,7.36],[4.3,16.24]],"bdatb":[[9,3.8,1.46],[2,4.3,16.24],[7,3.9,1.75],[8,3.85,7.36],[5,4,10.1]],"bdatl":[[6,5.7,9.53],[7,5.8,1.26],[8,5.9,1.9],[9,6,21.76]],"id":40095374},{"atb":[[2.44,20.18],[2.5,10.77]],"atl":[[2.58,4.8],[2.72,6.66],[2.62,0],[2.64,0],[2.6,20.41]],"bdatb":[[9,2.32,2.95],[7,2.36,3.49],[1,2.5,10.77],[4,2.44,20.18],[5,2.4,25.68],[6,2.38,14.18],[8,2.34,21.68],[2,2.48,14.84]],"bdatl":[[0,2.58,4.8],[4,2.72,6.66],[8,2.82,1.28],[9,2.88,17.65],[1,2.6,20.41],[2,2.66,18.85],[3,2.68,2.36],[5,2.74,7.02],[6,2.76,8.19],[7,2.78,2.02]],"id":36276560},{"atb":[[1.09,729.09],[1.25,108.38],[1.27,2.84],[1.26,96.42],[1.22,146.34],[1.23,76.25]],"atl":[[1.28,45.24],[1000,5],[1.27,0],[1.32,0]],"trd":[[1.27,104.83]],"bdatb":[[7,1.2,7.76],[8,1.19,13.59],[2,1.25,108.38],[6,1.21,35.58],[9,1.18,17.57],[0,1.27,2.84],[1,1.26,96.42],[3,1.24,99.32],[4,1.23,76.25],[5,1.22,146.34]],"bdatl":[[0,1.28,45.24],[4,1.34,4.23],[5,1.35,6.63],[6,1.36,7.02],[7,1.37,3.46],[1,1.29,67.27],[2,1.3,47.58],[3,1.31,82.67],[8,1.38,4.21],[9,1.39,4.97]],"tv":701.49,"id":39823721},{"atb":[[10,1.13]],"bdatb":[[2,11.5,4.13],[3,10.5,4.17],[7,9,1.61],[8,8.2,1.29],[9,8,2.19],[5,9.8,1.22],[6,9.6,1.24],[4,10,2.61],[0,13.5,3.08]],"bdatl":[[8,1000,5.39],[4,32,3.35],[6,40,6.46],[7,42,2.61]],"id":44331354},{"bdatb":[[8,4,7],[9,3.95,35.81],[5,4.3,1.59],[6,4.2,7.88],[7,4.1,14.37],[4,4.5,9.29]],"bdatl":[[7,6.2,4.93],[8,6.4,7.68],[9,6.8,4.25]],"id":37947503}],"con":true,"tv":1122.37}]}
{"op":"mcm","clk":"AMgeAOcaAPEa","pt":1650392697455,"mc":[{"id":"1.197931751","rc":[{"atb":[[2.62,17.35],[2.72,28.19],[2.78,8.81],[2.74,17.93]],"atl":[[2.84,0],[2.92,5.69]],"bdatb":[[8,2.62,17.35],[3,2.72,28.19],[0,2.78,8.81],[2,2.74,17.93]],"bdatl":[[9,3.25,1.76],[6,3.1,7.75],[7,3.15,14.07],[8,3.2,2.68],[0,2.88,2.4],[1,2.9,5.58],[2,2.92,5.69],[3,2.94,4.94],[4,2.96,7.81],[5,3.05,14.06]],"id":42930960},{"atl":[[5.7,0],[5.8,8.33]],"bdatb":[[8,3.8,1.63],[9,3.7,6.86],[7,3.85,7.36]],"bdatl":[[7,5.8,11.29],[8,6,20.44],[9,6.2,4.98],[6,5.5,4.22]],"id":40095374},{"atb":[[2.52,10.4],[2.5,12.77],[2.54,5.56]],"atl":[[2.66,34.1],[3.15,4.19],[2.6,13.16]],"bdatb":[[1,2.52,10.4],[2,2.5,12.77],[0,2.54,5.56],[3,2.48,14.84],[4,2.46,10.14],[5,2.44,20.18],[6,2.4,25.68],[7,2.38,14.18],[8,2.36,3.49],[9,2.34,21.68]],"bdatl":[[8,2.82,5.19],[9,2.86,3],[2,2.66,34.1],[1,2.6,13.16]],"id":36276560},{"atb":[[4.7,12.44],[4.6,5.66],[4.8,16.66],[5,4.64]],"atl":[[5.4,7.16],[5.5,2.18],[6.4,2.93]],"bdatb":[[3,4.7,12.44],[6,4.2,5.3],[7,4.1,14.41],[8,4,2.88],[4,4.6,5.66],[5,4.5,9.29],[9,3.95,37.9],[2,4.8,16.66],[0,5,4.64],[1,4.9,10.34]],"bdatl":[[9,6.6,2.17],[7,6.2,6.84],[8,6.4,3.01],[0,5.4,7.16],[1,5.5,2.18]],"id":37947503},{"atb":[[1.25,90.1],[1.27,62.56],[1.24,84.96],[1.09,729],[1.23,202.55]],"atl":[[1000,6],[1.28,4.84],[1.31,50.58],[1.29,42.9]],"trd":[[1.28,83.46],[1.27,114.51]],"bdatb":[[0,1.27,62.56],[2,1.25,90.1],[6,1.21,29.92],[7,1.2,12.32],[8,1.19,9.67],[9,1.18,19.25],[3,1.24,84.96],[4,1.23,202.55]],"bdatl":[[0,1.28,4.84],[7,1.36,4.21],[8,1.37,8.33],[9,1.39,22.98],[6,1.35,6.35],[4,1.33,1.71],[5,1.34,9.21],[1,1.29,42.9],[3,1.31,50.58]],"ltp":1.28,"tv":722.63,"id":39823721},{"bdatb":[[2,11.5,3.61],[3,10.5,3.67],[4,10,2.28],[8,8,1.34],[9,7.6,1.91],[6,9.4,1.57],[7,8.4,1.36],[5,9.6,1.24]],"bdatl":[[8,1000,5.67],[2,28,14.08],[4,32,3.25],[5,36,10.43],[6,40,6.41],[7,42,2.47]],"id":44331354}],"con":true,"tv":1143.51}]}
{"op":"mcm","clk":"ANofANYbAIYc","pt":1650392698457,"mc":[{"id":"1.197931751","rc":[{"atb":[[2.72,11.3],[2.32,68.59]],"atl":[[2.88,0],[4.1,3.22],[2.9,2.37]],"bdatb":[[3,2.72,11.3]],"bdatl":[[0,2.9,2.37],[1,2.92,5.69],[2,2.94,4.94],[3,2.96,7.81],[4,3.05,14.81],[5,3.1,7.18],[6,3.15,16.63],[7,3.2,1.79],[8,3.25,3.91],[9,3.3,3.3]],"id":42930960},{"atb":[[4.1,17.35],[4.3,6.23]],"bdatb":[[4,4.1,17.35],[8,3.7,5.22],[9,3.65,1.85],[2,4.3,6.23]],"bdatl":[[6,5.4,1.39],[7,5.5,2.86],[8,5.7,3.48],[9,5.8,9.97]],"id":40095374},{"atb":[[2.34,0],[2.46,17.92],[2.56,2.91],[2.54,17.75]],"atl":[[2.78,0],[2.62,2.85],[2.58,0],[2.66,19.92]],"bdatb":[[5,2.46,17.92],[0,2.56,2.91],[1,2.54,17.75],[2,2.52,10.4],[3,2.5,12.77],[4,2.48,14.84],[6,2.44,20.18],[7,2.4,25.68],[8,2.38,14.18],[9,2.36,3.49]],"bdatl":[[7,2.82,5.19],[8,2.86,3],[9,2.88,14.27],[1,2.62,2.85],[2,2.66,19.92],[3,2.68,2.36],[4,2.72,6.66],[5,2.74,7.02],[6,2.76,8.19],[0,2.6,13.16]],"id":36276560},{"atb":[[5,6.72],[4.9,6.87],[4.6,0],[4.8,9.01]],"atl":[[5.4,11.8],[5.6,16.9]],"bdatb":[[5,4.2,3.85],[8,3.95,37.72],[6,4.1,12.9],[7,4,2.07],[9,3.9,6.89],[4,4.5,9.29],[1,4.9,6.87],[2,4.8,9.01]],"bdatl":[[6,6,15.82],[7,6.2,6.56],[2,5.6,16.9],[8,6.4,4.47],[9,6.8,5.36]],"id":37947503},{"atb":[[1.05,251.16],[1.27,89.37],[1.25,90.1],[1.23,136.2],[1.24,82.94]],"atl":[[1.28,0],[1.31,50.58],[1000,5],[1.29,6.43]],"trd":[[1.28,93.32]],"bdatb":[[4,1.23,136.2],[3,1.24,82.94],[7,1.2,2],[8,1.19,20.08],[9,1.18,11.97],[2,1.25,88.09]],"bdatl":[[0,1.29,6.52],[2,1.31,50.58],[3,1.33,5.6],[4,1.34,5.35],[9,1.4,16.44],[1,1.3,47.58],[5,1.35,7.3],[6,1.36,3.26],[7,1.37,10.27],[8,1.38,9.23]],"tv":732.49,"id":39823721},{"bdatb":[[3,10.5,3.09],[6,9.4,1.6],[4,10,1.96],[5,9.6,1.24],[7,8.8,1.21],[8,7.8,2.04],[9,7.6,1.38],[2,11.5,3.07]],"bdatl":[[0,26,8.37],[2,28,13.84],[8,1000,5.57],[4,32,3.5],[5,36,10.23],[6,40,6.52],[7,42,2.44]],"id":44331354}],"con":true,"tv":1153.37}]}
{"op":"mcm","clk":"APYgAM4cAKod","pt":1650392699472,"mc":[{"id":"1.197931751","rc":[{"atb":[[2.62,5.43],[2.72,11.3]],"bdatb":[[8,2.62,5.43],[3,2.72,11.3]],"bdatl":[[8,3.3,4.27],[9,3.35,7.49],[4,3.05,14.82],[6,3.15,18.45],[7,3.25,3.91]],"id":42930960},{"atb":[[4.2,12.89],[4.1,9.09]],"atl":[[6.8,43.1]],"bdatb":[[8,3.75,1.83],[9,3.7,5.57],[3,4.2,12.89],[4,4.1,9.09]],"bdatl":[[6,5.4,4.74],[7,5.5,1.39],[9,5.8,13.17],[4,5.1,4.35],[8,5.7,1.65]],"id":40095374},{"atb":[[2.56,10.14],[2.46,31.86]],"atl":[[2.66,19.92]],"bdatb":[[0,2.56,10.14],[5,2.46,31.86]],"bdatl":[[2,2.66,19.92],[5,2.74,7.17],[7,2.82,5.05],[8,2.86,3.45],[9,2.88,15.37]],"id":36276560},{"atb":[[4.9,10.49]],"atl":[[5.2,2.34],[6.8,0],[5.9,0],[5.3,2.04]],"bdatb":[[1,4.9,10.49],[5,4.2,3.82],[8,3.95,37.75],[0,5,6.72]],"bdatl":[[0,5.2,2.34],[1,5.3,2.04],[2,5.4,11.8],[3,5.5,2.18],[4,5.6,16.9],[5,5.7,2.11],[6,5.8,6.41],[7,6,15.75],[8,6.2,6.56],[9,6.4,4.7]],"id":37947503},{"atb":[[1.05,251],[1.25,92.88],[1.28,0.32]],"bdatb":[[7,1.2,21.15],[8,1.18,12.74],[9,1.17,19.76],[2,1.25,92.88],[0,1.27,89.69]],"bdatl":[[3,1.33,11],[4,1.34,7.36],[5,1.35,3.29],[9,1.39,11.02],[0,1.29,6.43],[6,1.36,3.44],[7,1.37,6.85]],"id":39823721},{"bdatb":[[3,10.5,3.84],[4,10,1.52],[5,9.6,2.37],[6,8.8,1.26],[7,8,3.31],[8,7.4,1.22],[9,7,36.84]],"bdatl":[[0,26,8.66],[2,28,13.58],[3,29,5.86],[4,32,3.28],[5,36,10.28],[8,1000,5.71],[6,40,6.41],[7,42,2.55]],"id":44331354}],"con":true}]}
{"op":"mcm","clk":"AJciAM4dAMYe","pt":1650392700473,"mc":[{"id":"1.197931751","rc":[{"atb":[[2.76,10.68],[2.62,7.43],[2.28,106.1],[2.7,23.31]],"atl":[[2.88,4.08]],"bdatb":[[8,2.62,7.43],[4,2.7,23.31]],"bdatl":[[0,2.88,2],[1,2.9,2.37],[2,2.92,5.69],[3,2.94,4.94],[4,2.96,7.81],[5,3.05,14.81],[6,3.1,7.18],[7,3.15,16.63],[8,3.2,1.79],[9,3.25,3.91]],"id":42930960},{"atb":[[3.7,7.19]],"atl":[[5,13.19]],"bdatb":[[7,3.9,1.48],[8,3.85,8.11],[9,3.75,1.07]],"bdatl":[[3,5,13.19],[8,5.8,10.73],[9,6,22.36],[4,5.1,4.27],[6,5.4,4.3],[7,5.7,3.48]],"id":40095374},{"atb":[[2.44,22.27],[2.5,10.77]],"atl":[[2.92,2]],"bdatb":[[6,2.44,22.27],[3,2.5,10.77]],"bdatl":[[5,2.74,7.02],[7,2.82,5.19],[8,2.86,3],[9,2.88,14.27]],"id":36276560},{"atb":[[4.9,6.87],[4.8,9.01],[5,4.64]],"atl":[[5.4,13.8],[5.7,0],[5.2,4.38]],"bdatb":[[1,4.9,6.87],[5,4.2,5.87],[8,3.95,35.67],[9,3.9,6.79],[2,4.8,9.01],[0,5,4.64]],"bdatl":[[5,5.8,6.34],[6,6,15.82],[0,5.2,4.38],[2,5.4,13.8],[7,6.2,6.56],[8,6.4,4.7],[9,6.8,2.52]],"id":37947503},{"atb":[[1.05,251],[1.25,92.88],[1.21,38.46],[1.28,0]],"atl":[[1.31,57.2],[1.28,6.73]],"trd":[[1.28,94.28]],"bdatb":[[2,1.25,92.88],[0,1.27,89.37],[6,1.21,43.22],[7,1.2,17.11],[8,1.19,8.15],[9,1.18,6.86]],"bdatl":[[0,1.28,6.73],[1,1.29,6.43],[2,1.3,47.58],[3,1.31,50.58],[4,1.33,11],[5,1.34,6.4],[6,1.35,2.05],[7,1.36,2.18],[8,1.37,10.27],[9,1.38,9.23]],"tv":733.45,"id":39823721},{"bdatb":[[2,11.5,3.8],[3,10.5,3.86],[4,10,1.72],[5,9.6,1.36],[6,9,1.06],[7,8.2,1.19],[8,8,2.89],[9,7.4,1.23]],"bdatl":[[8,1000,5.68],[3,29,5.82],[4,32,3.23],[6,40,6.48],[7,42,2.44]],"id":44331354}],"con":true,"tv":1154.33}]}
{"op":"mcm","clk":"ANkjAMMeAN4f","pt":1650392701474,"mc":[{"id":"1.197931751","rc":[{"atb":[[2.72,28.19]],"atl":[[2.94,6.4]],"bdatb":[[3,2.72,28.19],[1,2.76,10.68]],"bdatl":[[7,3.15,18.45],[8,3.25,3.91],[9,3.3,4.27],[5,3.05,14.81],[6,3.1,7.18],[3,2.94,6.4],[0,2.88,4.08]],"id":42930960},{"atb":[[3.75,2],[4.5,3.25]],"atl":[[4.8,22.11],[4.7,11.93]],"trd":[[4.5,6.5]],"bdatb":[[7,3.9,3.01],[8,3.85,7.58],[9,3.75,3.48],[0,4.5,3.25],[1,4.4,3.25],[2,4.3,6.23],[3,4.2,12.89],[4,4.1,9.09],[5,4,10.1],[6,3.95,2.19]],"bdatl":[[6,5.4,4.82],[7,5.5,1.36],[8,5.7,3.6],[9,5.8,10.6],[1,4.8,22.11],[0,4.7,11.93]],"ltp":4.5,"tv":45.8,"id":40095374},{"atb":[[2.48,15.82],[2.54,20.56]],"atl":[[2.6,0.01],[2.66,4.67]],"trd":[[2.6,16.45]],"bdatb":[[1,2.54,20.56],[4,2.48,15.82]],"bdatl":[[8,2.86,3.45],[9,2.88,15.37],[2,2.66,4.67],[0,2.6,6.98],[7,2.82,5.19]],"ltp":2.6,"tv":154.83,"id":36276560},{"atb":[[5,6.69]],"bdatb":[[0,5,6.69],[5,4.2,6.82],[6,4.1,12.9],[7,4,3.25],[9,3.9,9.26],[8,3.95,33.9]],"bdatl":[[6,6,15.82],[7,6.2,6.56],[8,6.4,4.7],[9,6.8,4.13]],"id":37947503},{"atb":[[1.22,154.67],[1.25,94.88],[1.27,66.96],[1.05,250],[1.24,203.98]],"atl":[[1000,7],[1.3,54.47],[1.29,47.19],[1.28,9.84],[1.31,50.58]],"trd":[[1.28,122.48]],"bdatb":[[5,1.22,154.67],[0,1.27,66.96],[2,1.25,94.88],[7,1.2,11.19],[8,1.19,2.39],[9,1.18,8.16],[3,1.24,203.98],[6,1.21,48.17]],"bdatl":[[1,1.29,47.19],[5,1.34,7.36],[6,1.35,3.29],[7,1.36,3.33],[8,1.37,14.96],[0,1.28,9.84],[2,1.3,47.58],[3,1.31,50.58],[4,1.33,11],[9,1.38,1.29]],"tv":761.65,"id":39823721},{"bdatb":[[9,7.6,2.27],[2,11.5,4.13],[3,10.5,3.63],[6,9.2,1.03],[7,8.8,1.03],[8,8.2,1.43],[4,10,1.83],[5,9.6,1.24]],"bdatl":[[3,29,5.86],[4,32,3.28],[6,40,6.41],[7,42,2.55],[8,1000,5.64],[0,26,8.66],[5,36,10.28]],"id":44331354}],"con":true,"tv":1202.98}]}
{"op":"mcm","clk":"AI0lAMQfAOUg","pt":1650392702475,"mc":[{"id":"1.197931751","rc":[{"atb":[[2.78,0],[2.62,12.68],[2.7,6.22],[2.72,11.3],[2.76,3.97],[2.74,11.07],[2.24,182.54]],"atl":[[2.86,7.59],[2.8,2],[2.82,2.12],[2.84,2],[2.9,6.87],[2.88,15.67]],"trd":[[2.78,9.36]],"bdatb":[[0,2.76,3.97],[1,2.74,11.07],[2,2.72,11.3],[3,2.7,6.22],[4,2.68,24.87],[5,2.66,6.67],[6,2.64,6.97],[7,2.62,12.68],[8,2.6,15.56],[9,2.52,13.55]],"bdatl":[[3,2.86,7.59],[0,2.8,2],[1,2.82,2.12],[2,2.84,2],[4,2.88,15.67],[5,2.9,6.87],[6,2.92,5.69],[7,2.94,6.4],[8,2.96,7.81],[9,3.05,14.81]],"tv":244.78,"id":42930960},{"atb":[[4.4,6.67],[3.85,9.36],[4.5,0],[4,16.37],[4.2,3.81],[3.8,2]],"atl":[[4.7,23.7],[5.1,4.27],[4.8,22.11],[4.6,5.12],[5.8,0],[5.6,8.7],[5,8.35]],"trd":[[4.5,19.5]],"bdatb":[[0,4.4,6.67],[6,3.85,9.36],[7,3.8,3.47],[8,3.75,3.39],[9,3.7,7.67],[1,4.3,6.23],[2,4.2,3.81],[3,4.1,9.09],[4,4,16.37],[5,3.95,2.19]],"bdatl":[[1,4.7,23.7],[5,5.1,4.27],[6,5.2,4.51],[7,5.3,5.76],[8,5.5,1.55],[9,5.6,8.76],[2,4.8,22.11],[0,4.6,5.12],[3,4.9,15.03],[4,5,8.35]],"tv":58.8,"id":40095374},{"atb":[[2.6,12.63],[2.52,8.4],[2.5,26.96],[2.4,4.93],[2.48,5.72],[2.58,10.26],[1.79,50],[1.72,0],[2.56,16.28]],"atl":[[2.72,15.44],[2.7,10.41],[2.66,0],[2.68,5.32],[2.62,0],[2.64,0],[2.6,0],[2.9,2]],"trd":[[2.6,16.47]],"bdatb":[[0,2.6,12.63],[4,2.52,8.4],[9,2.4,4.93],[5,2.5,26.96],[1,2.58,10.26],[2,2.56,16.28],[3,2.54,20.56],[6,2.48,5.72],[7,2.46,31.86],[8,2.44,22.27]],"bdatl":[[2,2.72,15.44],[5,2.88,17.64],[6,2.9,8.34],[7,2.92,2],[8,2.94,1.4],[9,2.96,13.54],[0,2.68,5.32],[1,2.7,10.41],[3,2.74,7.02],[4,2.76,8.19]],"tv":154.85,"id":36276560},{"atb":[[4.8,20.25]],"atl":[[5.2,0],[5.6,7.66],[5.4,9.16]],"trd":[[5.2,4.68]],"bdatb":[[7,4,2.33],[8,3.95,33.9],[5,4.2,6.82],[6,4.1,13.31],[9,3.9,11.61],[2,4.8,20.25]],"bdatl":[[5,6,15.82],[6,6.2,8.93],[7,6.4,3.47],[8,6.6,1.28],[9,6.8,2.18],[0,5.3,2.04],[1,5.4,9.16],[2,5.5,2.18],[3,5.6,7.66],[4,5.8,6.34]],"ltp":5.2,"tv":4.68,"id":37947503},{"atb":[[1.24,82.94]],"atl":[[1000,5.32],[1.29,40.46]],"bdatb":[[8,1.19,10.07],[9,1.18,15.93],[6,1.21,43.09],[7,1.2,6.98],[3,1.24,82.94]],"bdatl":[[4,1.33,1.71],[5,1.34,20.2],[6,1.35,3.04],[7,1.36,5.76],[8,1.37,10.84],[9,1.38,2.29],[1,1.29,40.46],[2,1.3,54.47]],"id":39823721},{"bdatb":[[5,9.6,1.9],[6,9.2,1.67],[7,8.8,2.42],[8,8.2,1.43],[9,8,1.48],[2,11.5,4],[3,10.5,3.25],[4,10,1.6]],"bdatl":[[0,26,8.07],[1,27,3.39],[2,28,14.24],[3,29,5.52],[5,36,10.3],[6,40,6.43],[8,1000,5.66],[4,32,3.23],[7,42,2.44]],"id":44331354}],"con":true,"tv":1224.76}]}
{"op":"mcm","clk":"AK8mAMUgAIki","pt":1650392703476,"mc":[{"id":"1.197931751","rc":[{"atb":[[2.74,2.12],[2.68,23.34],[2.72,0],[2.76,0],[2.62,5.05],[2.7,0],[2.66,4.38],[2.78,0]],"atl":[[2.78,2],[2.76,6.08],[2.88,19.9],[2.92,3.55],[2.94,4.17],[2.8,4.07]],"trd":[[2.72,35.21],[2.76,4.16],[2.78,13.44]],"bdatb":[[0,2.68,23.34],[1,2.66,4.38],[2,2.64,6.97],[3,2.62,5.05],[4,2.6,15.56],[5,2.52,13.55],[6,2.5,4.16],[7,2.44,1.57],[8,2.42,2.87],[9,2.38,15.18]],"bdatl":[[1,2.78,2],[2,2.8,4.07],[3,2.82,2.12],[4,2.84,2],[5,2.86,7.59],[6,2.88,19.9],[7,2.9,6.87],[8,2.92,3.55],[9,2.94,4.17],[0,2.76,6.08]],"ltp":2.72,"tv":266.81,"id":42930960},{"atb":[[4.1,25.2],[4.2,0],[4,10.1]],"atl":[[4.8,20.09]],"bdatb":[[9,3.65,3.43],[2,4.1,25.2],[4,3.95,4.82],[5,3.85,9.92],[6,3.8,2.44],[7,3.75,2.67],[8,3.7,8.39],[3,4,10.1]],"bdatl":[[6,5.2,4.51],[7,5.4,5.79],[8,5.6,10.16],[9,5.7,3.67],[4,5,8.35],[5,5.1,4.27],[2,4.8,20.09]],"id":40095374},{"atb":[[2.58,15.68],[2.64,2.82],[2.54,7.53],[2.62,10.07],[2.44,2.09],[2.4,0],[2.52,28.76],[2.56,20.85]],"atl":[[2.7,13.16],[2.72,15.44]],"bdatb":[[0,2.64,2.82],[1,2.62,10.07],[2,2.6,12.63],[3,2.58,15.68],[4,2.56,20.85],[5,2.54,7.53],[6,2.52,28.76],[7,2.5,26.96],[8,2.48,5.72],[9,2.46,31.86]],"bdatl":[[1,2.7,13.16],[5,2.88,13.83],[7,2.92,2.78],[8,2.94,9.21],[2,2.72,15.44],[6,2.9,2],[9,2.96,13.54]],"id":36276560},{"atb":[[4.7,7.85],[4.6,0],[5.1,6.57],[4.8,18.01]],"atl":[[5.2,2]],"bdatb":[[9,4,4.04],[4,4.7,7.85],[5,4.5,9.29],[6,4.3,2.93],[7,4.2,4.82],[8,4.1,14.55],[0,5.1,6.57],[3,4.8,18.01],[1,5,6.69],[2,4.9,6.87]],"bdatl":[[7,6.2,4.93],[8,6.4,7.16],[9,6.8,1.81],[6,6,15.44],[5,5.8,6.34],[0,5.2,2],[1,5.3,2.04],[2,5.4,9.16],[3,5.5,2.18],[4,5.6,7.66]],"id":37947503},{"atl":[[1.29,40.78],[1000,5]],"bdatb":[[6,1.21,47.4],[7,1.2,3.96],[8,1.19,13.57],[5,1.22,163.19],[9,1.18,23.21]],"bdatl":[[4,1.33,1.71],[5,1.34,20.2],[6,1.35,3.07],[7,1.36,6],[9,1.39,4.61],[8,1.37,10.59],[3,1.31,50.58],[1,1.29,40.78]],"id":39823721},{"bdatb":[[3,10.5,3.7],[4,10,2.15],[6,9.2,1.08],[7,9,1.71],[8,8.2,2.11],[9,8,1.14],[0,13.5,3.85],[2,11.5,3.61],[5,9.6,1.85],[1,13,6.05]],"bdatl":[[0,26,8.07],[1,27,3.26],[4,32,3.96],[5,36,10.31],[6,40,6.42],[8,1000,5.6],[2,28,13.58],[7,42,2.44]],"id":44331354}],"con":true,"tv":1246.79}]}
{"op":"mcm","clk":"ANUnAMshAKAj","pt":1650392704478,"mc":[{"id":"1.197931751","rc":[{"atb":[[2.68,18.04],[2.7,9.13],[2.66,1.2],[2.62,5.05],[2.64,8.97],[2.74,0]],"atl":[[2.76,7.1],[2.74,6.13],[2.9,4.5]],"trd":[[2.74,4.24]],"bdatb":[[1,2.68,18.04],[7,2.5,9.43],[8,2.46,10.53],[9,2.42,9.5],[0,2.7,9.13],[2,2.66,1.2],[3,2.64,8.97],[4,2.62,5.05],[5,2.6,15.56],[6,2.52,13.55]],"bdatl":[[1,2.76,7.1],[0,2.74,6.13],[2,2.78,2],[3,2.8,4.07],[4,2.82,2.12],[5,2.84,2],[6,2.86,7.59],[7,2.88,19.9],[8,2.9,4.5],[9,2.92,3.55]],"ltp":2.74,"tv":271.05,"id":42930960},{"atb":[[4.2,13.92],[4.1,18.46]],"atl":[[6.8,0],[5.8,20.83]],"bdatb":[[2,4.2,13.92],[9,3.75,3.03],[4,4,13.67],[5,3.95,2.83],[6,3.9,5.02],[8,3.8,3.98],[7,3.85,10.81],[3,4.1,18.46]],"bdatl":[[6,5.2,4.51],[7,5.4,4.16],[9,5.6,8.83],[8,5.5,1.5],[5,5.1,4.27],[4,5,8.35]],"id":40095374},{"atb":[[2.64,2.75],[2.56,16.92],[1.04,0],[2.46,11.97],[2.6,17.18],[2.54,26.4]],"trd":[[2.64,36.24]],"bdatb":[[0,2.64,2.75],[1,2.62,10.07],[2,2.6,17.18],[3,2.58,15.68],[4,2.56,16.92],[5,2.54,26.4],[6,2.52,28.76],[7,2.5,26.96],[8,2.48,5.72],[9,2.46,18.8]],"bdatl":[[8,2.94,7.6],[9,2.96,15.13],[6,2.9,2.79],[5,2.88,13.83],[7,2.92,2]],"ltp":2.64,"tv":160.49,"id":36276560},{"atb":[[4.8,13.42],[5.2,6.33]],"atl":[[5.5,4.18],[5.6,9.69],[5.4,9.16],[5.3,0],[5.2,0]],"trd":[[5.3,4.5],[5.2,8.68]],"bdatb":[[8,4.4,4.45],[9,4.3,3.12],[6,4.6,3.1],[7,4.5,9.86],[4,4.8,13.42],[0,5.2,6.33],[1,5.1,6.57],[2,5,6.69],[3,4.9,6.87],[5,4.7,7.85]],"bdatl":[[6,6.4,3.29],[7,6.6,3.39],[8,7,1.3],[9,7.2,3.13],[1,5.5,4.18],[2,5.6,9.69],[0,5.4,9.16],[3,5.8,6.34],[4,6,15.44],[5,6.2,4.57]],"ltp":5.3,"tv":13.18,"id":37947503},{"atb":[[1.25,116.05],[1.23,18.04],[1.27,0]],"atl":[[1.28,19.22],[1.29,16.37],[1.27,180.39]],"trd":[[1.27,248.43]],"bdatb":[[1,1.25,116.05],[6,1.2,17.32],[7,1.19,6.59],[9,1.17,22.89],[4,1.22,166.36],[5,1.21,46.15],[3,1.23,18.04],[8,1.18,12.9],[0,1.26,96.42],[2,1.24,82.94]],"bdatl":[[5,1.32,1.73],[6,1.33,16.81],[7,1.34,3.51],[8,1.35,3.17],[9,1.36,16.56],[1,1.28,19.22],[0,1.27,180.39],[2,1.29,16.37],[3,1.3,54.47],[4,1.31,50.58]],"ltp":1.27,"tv":895.57,"id":39823721},{"atb":[[13,3.63]],"atl":[[28,0],[27,16.82],[24,0.95],[25,4.47]],"bdatb":[[6,9.6,3.49],[7,9,2.69],[8,8.8,1.78],[9,7.4,1.01],[1,13,3.82],[4,10.5,4.13],[5,10,2.3],[0,13.5,4.13],[2,12,1.61],[3,11.5,3.56]],"bdatl":[[0,25,4.47],[2,27,3.25],[4,29,6.12],[5,32,3.38],[6,36,10.2],[7,40,6.5],[9,1000,5.72],[1,26,8.07],[3,28,13.58],[8,42,2.44]],"id":44331354}],"con":true,"tv":1399.09}]}
{"op":"mcm","clk":"AJgpAOciAK4k","pt":1650392705480,"mc":[{"id":"1.197931751","rc":[{"atb":[[2.64,8.97],[2.68,7.85],[2.66,17.74]],"bdatb":[[3,2.64,8.97],[1,2.68,7.85],[6,2.52,16.06],[7,2.5,6.9],[8,2.46,7.44],[9,2.44,3.12],[2,2.66,17.74]],"id":42930960},{"atb":[[2.58,10.26],[2.56,28.96],[1.04,0],[2.64,9.67]],"atl":[[3.6,114.19],[2.68,2.36]],"trd":[[2.64,41.74]],"bdatb":[[3,2.58,10.26],[4,2.56,28.96],[0,2.64,9.67],[1,2.62,10.07],[2,2.6,17.18],[5,2.54,26.4],[6,2.52,28.76],[7,2.5,26.96],[8,2.48,5.72],[9,2.46,21.24]],"bdatl":[[0,2.68,2.36]],"tv":165.99,"id":36276560},{"atb":[[1.4,0.05],[5,13.95]],"bdatb":[[6,4.6,1.37],[7,4.5,12.95],[9,4.3,1.29],[2,5,13.95],[8,4.4,3.09]],"bdatl":[[9,7.2,1.43],[7,6.6,3.52],[8,7,2.32],[6,6.4,3.29]],"id":37947503},{"atb":[[1.25,123.49]],"atl":[[1000,7.9],[1.27,189.84]],"bdatb":[[4,1.22,159.85],[5,1.21,52.71],[6,1.2,17.24],[7,1.19,6.4],[8,1.18,13.17],[9,1.17,18.55],[1,1.25,123.49]],"bdatl":[[9,1.36,7.55],[6,1.33,17.49],[7,1.34,2.84],[5,1.32,1.73],[8,1.35,9.11],[0,1.27,189.84]],"id":39823721},{"atb":[[1.02,2.15],[9.8,0],[7.2,1.45],[12.5,2.52]],"atl":[[27,15.28],[26,6.47]],"bdatb":[[7,9.6,3.19],[8,9,2.13],[9,8.8,2.57],[0,13.5,3.54],[1,13,4.43],[4,11.5,3.55],[5,10.5,4.14],[2,12.5,3.06],[3,12,1.07],[6,10,2.3]],"bdatl":[[8,1000,5.84],[2,27,16.2],[3,29,5.55],[4,32,3.35],[5,36,10.2],[6,40,6.5],[1,26,6.47],[0,25,5.42],[7,42,2.44],[9,0,0]],"id":44331354},{"bdatb":[[4,4,11.69],[5,3.95,6.36],[7,3.85,10.78],[8,3.8,4],[6,3.9,3.49]],"bdatl":[[7,5.3,4.22],[8,5.5,1.51],[9,5.6,10.26],[6,5.2,4.51]],"id":40095374}],"con":true,"tv":1404.59}]}
{"op":"mcm","clk":"AKYqAOUjAK8l","pt":1650392706481,"mc":[{"id":"1.197931751","rc":[{"atb":[[2.62,27.54]],"bdatb":[[8,2.46,12.07],[9,2.44,2.38],[7,2.48,2.59],[6,2.52,13.55],[4,2.62,27.54]],"id":42930960},{"atb":[[4.2,3.77],[4.4,4]],"atl":[[4.6,7.85],[5,6.35],[5.1,2.27],[6,30]],"bdatb":[[0,4.4,4],[2,4.2,3.77],[5,3.95,3.82],[6,3.9,2.66],[7,3.85,14.45],[8,3.8,3.46],[9,3.75,2.84],[4,4,10.1]],"bdatl":[[0,4.6,7.85],[5,5.1,3.53],[6,5.2,7.58],[7,5.3,1.3],[8,5.5,2.26],[9,5.6,12.71],[4,5,6.35]],"id":40095374},{"atb":[[2.58,0],[2.68,2.39],[2.64,14.32],[2.56,26.05],[2.66,9.45],[2.6,26.74]],"atl":[[2.7,0],[2.76,1.14],[2.74,12.96],[2.88,15.83],[2.72,2.36],[2.68,0],[3.6,56.5]],"trd":[[2.68,14.88],[2.64,49.08]],"bdatb":[[5,2.56,26.05],[6,2.54,26.4],[7,2.52,28.76],[8,2.5,26.96],[9,2.48,5.72],[0,2.68,2.39],[1,2.66,9.45],[2,2.64,14.32],[3,2.62,10.07],[4,2.6,26.74]],"bdatl":[[0,2.72,2.36],[1,2.74,12.96],[2,2.76,1.14],[3,2.88,15.83],[4,2.9,3.57],[5,2.92,2],[6,2.94,4.44],[7,2.96,13.54],[8,2.98,2.36],[9,3,2.75]],"ltp":2.68,"tv":178.05,"id":36276560},{"atb":[[1.4,0]],"atl":[[5.5,6.25],[5.4,9.11]],"trd":[[5.4,0.1]],"bdatb":[[7,4.4,6.75],[8,4.2,5.2],[9,4.1,13.66],[6,4.5,10.72]],"bdatl":[[5,6.2,5.6],[6,6.4,4.68],[7,6.6,1.07],[8,6.8,2.84],[9,7.4,8.54],[1,5.5,6.25],[0,5.4,9.11]],"ltp":5.4,"tv":13.28,"id":37947503},{"atb":[[1.26,91.21]],"atl":[[1.29,30.55],[1000,5]],"trd":[[1.26,73.64]],"bdatb":[[7,1.19,4.67],[8,1.18,2.65],[9,1.16,16.57],[5,1.21,52.34],[6,1.2,18.33],[0,1.26,91.21],[4,1.22,154.67]],"bdatl":[[4,1.31,54.06],[5,1.32,9.88],[6,1.33,10.48],[7,1.34,1.01],[8,1.35,8.52],[9,1.37,11.56],[2,1.29,30.55]],"ltp":1.26,"tv":901.37,"id":39823721},{"atb":[[14,0.33],[1.02,3.44],[7.2,0]],"atl":[[24,4.13]],"bdatb":[[3,12,2.48],[5,10.5,3.91],[6,10,1.13],[7,9.6,1.24],[8,8.6,1.64],[9,8.2,2.94],[1,13,3.63],[4,11.5,3.07],[2,12.5,3.04],[0,13.5,3.25]],"bdatl":[[0,24,4.4],[1,25,4.92],[3,27,15.28],[4,29,5.77],[5,32,3.45],[6,36,10.24],[7,40,6.7],[9,1000,5.48],[2,26,6.47],[8,42,2.44]],"id":44331354}],"con":true,"tv":1422.55}]}
{"op":"mcm","clk":"AMQrAPskALYm","pt":1650392707484,"mc":[{"id":"1.197931751","rc":[{"atb":[[2.62,39.46],[2.32,66.63]],"atl":[[2.76,6.08],[2.74,7.16]],"bdatb":[[7,2.46,3.88],[9,2.4,8.41],[8,2.44,2.62]],"bdatl":[[0,2.74,7.16],[1,2.76,6.08]],"id":42930960},{"atb":[[4.2,4.95],[4.3,5.8]],"atl":[[8.8,0],[7.6,15.15],[5.3,9.3],[5.6,0],[4.7,23.7],[4.8,22.11]],"bdatb":[[6,3.85,11.85],[8,3.75,2.98],[9,3.7,11.72],[7,3.8,3.68],[2,4.2,4.95],[1,4.3,5.8],[5,3.95,2.19]],"bdatl":[[5,5.1,3.53],[6,5.2,7.58],[7,5.3,10.6],[8,5.5,2.26],[9,5.6,4.01],[1,4.7,23.7],[2,4.8,22.11]],"id":40095374},{"atb":[[1.85,50],[1.79,0],[2.68,2.39],[2.62,15.65],[2.6,17.78],[2.64,18.81],[2.5,7.6]],"atl":[[2.78,11.57],[3.5,38.27],[2.76,3.46],[2.88,43.73],[2.82,10.16],[2.74,0],[2.72,0]],"trd":[[2.68,19.66]],"bdatb":[[0,2.68,2.39],[1,2.66,9.45],[2,2.64,18.81],[3,2.62,15.65],[4,2.6,17.78],[5,2.56,26.05],[6,2.54,26.4],[7,2.52,28.76],[8,2.5,7.6],[9,2.48,5.72]],"bdatl":[[0,2.76,3.46],[2,2.82,10.16],[3,2.88,43.73],[4,2.9,3.57],[5,2.92,2],[6,2.94,4.44],[7,2.96,13.54],[8,2.98,2.36],[9,3,2.75],[1,2.78,2.3]],"tv":182.83,"id":36276560},{"atb":[[5,6.69]],"bdatb":[[7,4.4,2.17],[8,4.3,1.49],[9,4.2,8.62],[2,5,6.69],[6,4.5,9.29]],"bdatl":[[5,6.2,5.6],[6,6.4,4.68],[9,7.4,9.14],[8,6.8,2.63]],"id":37947503},{"atb":[[1.22,22.62],[1.24,97.5]],"bdatb":[[6,1.2,15.29],[7,1.19,16.96],[8,1.18,4.95],[9,1.17,2.25],[4,1.22,22.62],[5,1.21,38.46],[2,1.24,97.5]],"bdatl":[[4,1.31,54.06],[5,1.32,9.88],[6,1.33,10.48],[7,1.34,1.01],[8,1.35,7.15],[9,1.36,2.31]],"id":39823721},{"atb":[[4,81.6]],"atl":[[29,3.02],[40,0],[36,5.91],[32,0],[28,3.7]],"bdatb":[[3,11.5,4.43],[4,10.5,4.98],[5,10,1.16],[6,9.6,2.08],[7,8.6,1.69],[8,8.2,2.94],[9,7.8,6.94],[2,12.5,2.52]],"bdatl":[[8,1000,5.56],[0,24,4.4],[1,25,4.92],[6,36,6.17],[5,29,3.27],[7,42,2.68],[9,0,0],[4,28,3.7]],"id":44331354}],"con":true,"tv":1427.33}]}
{"op":"mcm","clk":"APosAPklAMcn","pt":1650392708486,"mc":[{"id":"1.197931751","rc":[{"atb":[[2.7,11.14],[2.68,18.76],[2.66,1.2],[2.72,11.26],[2.62,27.54]],"atl":[[2.74,0.8]],"trd":[[2.74,16.96]],"bdatb":[[2,2.68,18.76],[3,2.66,1.2],[0,2.72,11.26],[1,2.7,9.13],[4,2.64,8.97],[5,2.62,27.54],[6,2.6,15.56],[7,2.52,13.55],[8,2.46,6.45],[9,2.44,8.3]],"bdatl":[[0,2.74,2.92]],"tv":283.77,"id":42930960},{"atb":[[4.2,8.72]],"bdatb":[[2,4.2,8.72],[7,3.85,9.8],[8,3.8,4.07],[9,3.75,5.86],[6,3.9,1.62]],"bdatl":[[4,5,7.26],[5,5.1,7.38],[6,5.2,4.23],[7,5.3,9.57],[8,5.4,2.04],[9,5.5,2.06]],"id":40095374},{"atb":[[2.68,2.36],[2.46,14.01],[2.6,35.94]],"atl":[[2.82,14.25],[2.88,20.05],[2.8,13.98],[2.74,2.31]],"trd":[[2.68,24.44]],"bdatb":[[0,2.68,2.36],[1,2.66,9.45],[2,2.64,18.81],[3,2.62,15.65],[4,2.6,35.94],[5,2.56,26.05],[6,2.54,26.4],[7,2.52,28.76],[8,2.5,7.6],[9,2.48,5.72]],"bdatl":[[4,2.82,14.25],[3,2.8,13.98],[5,2.88,21.63],[6,2.9,6.5],[7,2.92,2],[8,2.96,17.94],[9,3.05,3.92],[0,2.74,2.31],[1,2.76,3.46],[2,2.78,11.57]],"tv":187.61,"id":36276560},{"atb":[[5,13.95]],"bdatb":[[7,4.4,1.82],[9,4.2,6.52],[8,4.3,3.9],[2,5,13.95]],"bdatl":[[9,7.2,5.09],[4,6,16.2],[5,6.2,6.67],[6,6.4,2.93],[7,6.6,2.1],[8,6.8,1.63]],"id":37947503},{"atb":[[1.22,154.67]],"bdatb":[[8,1.18,9.82],[9,1.17,4.85],[6,1.2,9.96],[7,1.19,17.01],[5,1.21,43.69],[4,1.22,154.67]],"bdatl":[[9,1.36,16.51],[4,1.31,55.41],[5,1.32,8.54],[6,1.33,11.5],[7,1.34,7.2],[8,1.35,1.03]],"id":39823721},{"bdatb":[[3,11.5,4.43],[4,11,1.31],[5,10.5,3.63],[6,10,1.69],[7,9.6,1.88],[8,8.8,3.06],[9,8.4,1.41]],"bdatl":[[8,1000,5.93],[0,24,4.89],[1,25,4.47],[3,27,15.77],[5,29,3.05],[6,36,6.21],[7,42,2.44]],"id":44331354}],"con":true,"tv":1444.83}]}
{"op":"mcm","clk":"AK8uAIonANoo","pt":1650392709488,"mc":[{"id":"1.197931751","rc":[{"atb":[[2.7,24.8],[2.68,2],[2.3,50.23],[2.64,5.57],[2.72,15.44],[2.74,6.86],[2.66,3.2],[2.28,103.06]],"atl":[[2.84,6.91],[2.76,0],[2.78,0],[2.74,0]],"trd":[[2.76,10.08]],"bdatb":[[2,2.7,24.8],[3,2.68,2],[1,2.72,15.44],[5,2.64,5.57],[0,2.74,6.86],[4,2.66,3.2],[6,2.62,27.54],[7,2.6,15.56],[8,2.52,13.55],[9,2.5,2.53]],"bdatl":[[2,2.84,6.91],[0,2.8,4.07],[1,2.82,2.12],[3,2.86,7.59],[4,2.88,19.9],[5,2.9,4.5],[6,2.92,3.55],[7,2.94,5.72],[8,2.96,8.41],[9,2.98,3.78]],"ltp":2.76,"tv":289.69,"id":42930960},{"atb":[[3.5,35.51]],"atl":[[6,0],[5.8,0],[6.4,0],[5.5,22.22]],"bdatb":[[9,3.7,9.61],[6,3.85,9.36],[7,3.8,5],[8,3.75,3.2]],"bdatl":[[3,4.9,15.96],[4,5,6.7],[5,5.1,7.2],[6,5.2,4.35],[8,5.4,3.13],[9,5.5,23.23],[7,5.3,11.38]],"id":40095374},{"atb":[[2.24,51.58],[2.68,2.36]],"atl":[[3.6,54.17]],"trd":[[2.68,29.16]],"bdatb":[[9,2.48,5.72],[0,2.68,2.36],[1,2.66,9.45],[2,2.64,18.81],[3,2.62,15.65],[4,2.6,35.94],[5,2.56,26.05],[6,2.54,26.4],[7,2.52,28.76],[8,2.5,7.6]],"bdatl":[[5,2.86,1.59],[6,2.88,24.58],[7,2.9,2],[8,2.92,2],[9,2.96,18.7]],"tv":192.33,"id":36276560},{"atb":[[4.1,41.08]],"bdatb":[[8,4.2,7.03],[9,4.1,43.83],[7,4.3,2.65],[6,4.5,9.29]],"bdatl":[[4,6,16.5],[5,6.2,6.39],[8,7,2.61],[9,7.2,2.55],[6,6.4,3.12],[7,6.6,3.6]],"id":37947503},{"atb":[[1.19,97.09]],"bdatb":[[7,1.19,108.4],[8,1.18,10.29],[9,1.17,10.43],[5,1.21,38.46],[6,1.2,11.5]],"bdatl":[[3,1.3,57.98],[4,1.31,60.53],[7,1.35,13.53],[8,1.36,13.48],[9,1.37,1.45],[5,1.33,11.51],[6,1.34,7.2]],"id":39823721},{"atb":[[10,12.68]],"atl":[[24,5.87],[27,2.98],[25,0],[26,21.99],[22,1.13],[23,4.78],[30,5.17]],"bdatb":[[6,10,14.7],[7,9.6,1.33],[8,9.4,1.17],[9,8.8,1.21],[3,11.5,3.07],[4,11,1.04],[5,10.5,3.51]],"bdatl":[[2,24,5.87],[4,27,3.45],[0,22,1.94],[6,29,3.07],[9,42,2.9],[3,26,22.04],[5,28,3.7],[7,30,5.17],[8,36,6.21],[1,23,4.78]],"id":44331354}],"con":true,"tv":1455.47}]}
{"op":"mcm","clk":"AOsvAJQoAPgp","pt":1650392710489,"mc":[{"id":"1.197931751","rc":[{"atb":[[2.74,8.98],[2.24,177.49],[2.66,20.7]],"atl":[[2.9,4.5],[2.8,2]],"bdatb":[[0,2.74,8.98],[8,2.52,15.12],[9,2.48,2.26],[4,2.66,20.7]],"bdatl":[[8,2.96,9.35],[9,3.05,20.7],[5,2.9,4.5],[7,2.94,4.17],[0,2.8,2]],"id":42930960},{"atb":[[2.6,25.75],[2.7,2.17],[2.68,7.06]],"atl":[[2.74,0],[2.8,24.11]],"trd":[[2.68,33.7]],"bdatb":[[0,2.7,2.17],[1,2.68,7.06],[2,2.66,9.45],[3,2.64,18.81],[4,2.62,15.65],[5,2.6,28.8],[6,2.56,26.05],[7,2.54,26.4],[8,2.52,28.76],[9,2.5,7.6]],"bdatl":[[9,2.98,2.35],[4,2.88,20.05],[5,2.9,2],[6,2.92,3.56],[7,2.94,4.44],[8,2.96,13.54],[0,2.76,3.46],[1,2.78,11.57],[2,2.8,24.11],[3,2.82,14.25]],"tv":196.87,"id":36276560},{"atb":[[4.9,14.32],[5,6.69]],"atl":[[5.8,1.83],[5.4,6.97]],"bdatb":[[7,4.3,1.29],[8,4.2,8.41],[2,5,6.69],[3,4.9,14.32]],"bdatl":[[5,6.2,5.51],[6,6.4,4.76],[7,6.6,1.09],[8,6.8,2.61],[9,7.2,1.03],[3,5.8,1.83],[4,6,15.44],[0,5.4,6.97]],"id":37947503},{"atb":[[1.26,38.38],[1.24,99.52],[1.25,95.41],[1.22,22.62],[1.21,176.8]],"atl":[[1.26,0],[1.27,189.83],[1.28,94.76],[1.29,77.16],[1.31,36.4]],"trd":[[1.26,217.9],[1.27,248.45]],"bdatb":[[0,1.25,95.41],[1,1.24,99.52],[2,1.23,18.04],[3,1.22,22.62],[4,1.21,176.8],[5,1.2,6.67],[6,1.19,113.27],[7,1.18,9.54],[8,1.17,4.78],[9,1.16,62.49]],"bdatl":[[3,1.29,77.16],[4,1.3,58.98],[5,1.31,45.36],[6,1.32,5.43],[7,1.33,13.36],[8,1.34,1.03],[9,1.35,16.64],[0,1.26,3.13],[1,1.27,189.84],[2,1.28,33.4]],"ltp":1.27,"tv":1045.65,"id":39823721},{"bdatb":[[6,3.9,1.01],[7,3.85,9.36],[8,3.8,2.44],[9,3.75,3.05]],"bdatl":[[4,5,7.26],[5,5.1,2.52],[6,5.2,7.71],[7,5.3,10.83],[9,5.5,23.31],[3,4.9,15.03],[8,5.4,2.04]],"id":40095374},{"bdatb":[[3,11.5,3.42],[4,10.5,3.61],[5,10,14.85],[6,9.6,1.74],[7,8.8,1.87],[8,8.6,2.22],[9,8.4,4.43]],"bdatl":[[1,23,5.03],[2,24,6.36],[5,28,3.95],[7,30,5.18],[8,36,6.16],[0,22,1.13],[4,27,2.98],[9,42,2.69],[3,26,21.99],[6,29,3.02]],"id":44331354}],"con":true,"tv":1604.29}]}
{"op":"mcm","clk":"AIoxAJcpAJUr","pt":1650392711492,"mc":[{"id":"1.197931751","rc":[{"atl":[[2.84,7.49],[2.94,2.71]],"bdatb":[[8,2.54,1.24],[9,2.52,16.09]],"bdatl":[[7,2.94,2.71],[8,2.96,7.81],[9,2.98,1.53],[2,2.84,7.49],[5,2.9,4.5]],"id":42930960},{"atb":[[4.4,0]],"atl":[[4.6,17.73],[4.5,7.72],[4.8,12.88],[4.9,10.08],[4.7,20.9],[5.7,31.91]],"trd":[[4.4,8]],"bdatb":[[0,4.3,5.8],[1,4.2,8.72],[2,4.1,18.46],[3,4,10.1],[4,3.95,2.19],[5,3.85,10.81],[6,3.8,3.04],[7,3.75,2.54],[8,3.7,7.3],[9,3.6,7.12]],"bdatl":[[1,4.6,17.73],[0,4.5,7.72],[3,4.8,12.88],[4,4.9,10.08],[2,4.7,20.9],[5,5,7.5],[6,5.1,5.97],[7,5.2,5.67],[8,5.3,11.38],[9,5.4,4.07]],"ltp":4.4,"tv":66.8,"id":40095374},{"atb":[[2.64,14.32],[2.62,5.58],[2.72,2.11],[2.7,9.3],[2.68,13.08],[2.48,4.74],[2.66,15.04],[2.52,9.64]],"atl":[[2.78,2.3],[2.8,0],[3.5,36.92],[2.76,1.14]],"trd":[[2.7,4]],"bdatb":[[9,2.52,11.86],[4,2.64,14.32],[0,2.72,2.11],[1,2.7,9.3],[2,2.68,13.08],[3,2.66,15.04],[5,2.62,5.58],[6,2.6,25.75],[7,2.56,26.05],[8,2.54,26.4]],"bdatl":[[5,2.92,2],[6,2.96,15.08],[7,2.98,6.73],[8,3.05,2.72],[9,3.1,3.56],[1,2.78,2.3],[2,2.82,14.25],[3,2.88,20.05],[4,2.9,2],[0,2.76,1.14]],"ltp":2.7,"tv":200.87,"id":36276560},{"atb":[[1.07,250.13],[1.25,74.36],[1.24,105.44],[1.23,18.04],[1.26,0]],"atl":[[1000,8],[1.28,137.05],[1.26,9.52],[1.27,171.69],[1.31,36.4]],"trd":[[1.26,313.7],[1.25,76.86],[1.27,304.72]],"bdatb":[[7,1.18,19.63],[8,1.17,12.81],[9,1.16,23.49],[0,1.25,74.36],[5,1.2,9.95],[6,1.19,98.8],[2,1.23,18.04],[1,1.24,105.44],[3,1.22,22.62],[4,1.21,176.8]],"bdatl":[[2,1.28,137.05],[0,1.26,9.52],[1,1.27,171.69],[3,1.29,77.16],[4,1.3,57.98],[5,1.31,51.71],[6,1.33,6.22],[7,1.34,21.38],[8,1.35,3.23],[9,1.37,18.39]],"ltp":1.27,"tv":1234.58,"id":39823721},{"atl":[[26,23.24],[29,0],[22,5.14]],"bdatb":[[9,8,4.98],[2,12.5,2.77],[3,11.5,3.62],[4,10.5,3.31],[5,10,14.77],[6,9.6,1.43],[7,9,1.65],[8,8.4,2.65]],"bdatl":[[0,22,5.14],[1,23,4.78],[2,24,6.11],[3,26,23.97],[4,27,3],[6,30,5.17],[7,36,6.14],[8,42,3.16],[9,1000,5.35],[5,28,3.7]],"id":44331354},{"bdatb":[[6,4.5,10.54],[7,4.3,1.47],[8,4.2,3.82],[9,4.1,46.63]],"bdatl":[[4,6,15.44],[5,6.2,5.3],[6,6.4,6.06],[7,7,5.3],[8,7.4,7.01],[9,7.6,3.22]],"id":37947503}],"con":true,"tv":1805.22}]}
{"op":"mcm","clk":"ALwyALUqAKMs","pt":1650392712494,"mc":[{"id":"1.197931751","rc":[{"atb":[[2.7,11.14],[2.78,2.04],[2.62,36.41],[2.66,26.35],[2.72,18.73],[2.76,2.01],[2.6,12.49],[2.74,23.36]],"atl":[[2.8,4.15]],"bdatb":[[2,2.72,4.18],[7,2.62,24.49],[0,2.76,2.01],[1,2.74,23.36],[3,2.7,24.8],[4,2.68,2],[5,2.66,20.7],[6,2.64,5.57],[8,2.6,12.49],[9,2.52,15.81]],"bdatl":[[0,2.8,4.15],[8,2.96,9.35],[9,3,6.74],[7,2.94,2.71]],"id":42930960},{"atb":[[4.2,7.24],[4.1,9.09],[4,19.79]],"atl":[[5.2,13.59],[4.6,15.72],[7.2,0]],"bdatb":[[1,4.2,7.24],[8,3.7,12.6],[9,3.6,6.37],[2,4.1,9.09],[5,3.85,9.36],[7,3.75,5.18],[6,3.8,3.5],[3,4,19.79]],"bdatl":[[3,4.8,13.83],[4,4.9,10.28],[5,5,10.2],[8,5.3,13.54],[9,5.5,22.24],[6,5.1,3.86],[7,5.2,15.72],[1,4.6,15.72]],"id":40095374},{"atb":[[2.64,30.56],[2.46,9.31],[2.74,2.08],[2.72,7.01],[2.68,17.53]],"atl":[[2.84,42.98],[2.82,12.2],[2.76,0],[2.78,0],[2.8,2.03]],"trd":[[2.76,2.28],[2.72,4]],"bdatb":[[5,2.64,30.56],[0,2.74,2.08],[1,2.72,7.01],[2,2.7,9.3],[3,2.68,17.53],[4,2.66,15.04],[6,2.62,5.58],[7,2.6,25.75],[8,2.56,26.05],[9,2.54,26.4]],"bdatl":[[1,2.82,12.2],[2,2.84,42.98],[6,2.94,1.55],[7,2.96,13.87],[8,2.98,6.51],[9,3.05,2.61],[0,2.8,2.03],[4,2.9,2]],"ltp":2.76,"tv":207.15,"id":36276560},{"atb":[[5,13.95]],"bdatb":[[8,4.3,5.38],[9,4.2,4.8],[6,4.5,9.29],[7,4.4,2.64],[2,5,13.95]],"bdatl":[[8,7,1.66],[9,7.2,1.55],[4,6,16.2],[5,6.2,4.75],[6,6.4,5.94],[7,6.6,2.88]],"id":37947503},{"atb":[[1.23,43.47],[1.25,53.19],[1.26,0],[1.07,250],[1.24,126.15]],"atl":[[1.26,169.13],[1.27,91.88],[1000,5]],"trd":[[1.26,313.96]],"bdatb":[[9,1.16,44.37],[2,1.23,20.06],[5,1.2,6.74],[6,1.19,107.1],[8,1.17,19.6],[7,1.18,16.99],[0,1.25,53.19],[1,1.24,126.15]],"bdatl":[[0,1.26,169.13],[8,1.34,4.06],[9,1.35,10.54],[1,1.27,91.88],[3,1.29,80.69],[4,1.3,55.35],[5,1.31,51.08],[6,1.32,6.02],[7,1.33,12.78],[2,1.28,137.05]],"ltp":1.26,"tv":1234.84,"id":39823721},{"atb":[[13,3.63]],"bdatb":[[5,10.5,4.71],[6,10,12.97],[7,9.6,1.49],[8,9.4,2.18],[9,9.2,1.24],[2,12.5,2.52],[4,11,1.08],[1,13,3.63],[3,11.5,3.57]],"bdatl":[[8,42,2.58],[9,1000,5.43],[0,22,5.4],[1,23,4.79],[2,24,6.67],[4,27,2.98],[6,30,5.44],[7,36,6.41],[3,26,23.25]],"id":44331354}],"con":true,"tv":1811.76}]}
{"op":"mcm","clk":"AOozAMYrAMst","pt":1650392713496,"mc":[{"id":"1.197931751","rc":[{"atb":[[2.66,5.41],[2.7,2],[2.64,12.29],[2.72,3.23],[2.68,4.18],[2.36,25.35],[2.74,0],[2.62,24.49],[2.78,0],[2.76,0]],"atl":[[2.76,16.14],[2.74,12.9],[2.78,6.97],[2.84,7.49],[2.82,4.87],[2.8,15.96],[2.86,5.51]],"trd":[[2.72,62.17],[2.74,45.9],[2.78,17.52]],"bdatb":[[0,2.72,10.75],[1,2.7,6.22],[2,2.68,4.18],[3,2.66,3.2],[7,2.52,27.21],[8,2.46,1.31],[9,2.44,10.73],[5,2.62,24.49],[6,2.6,12.49],[4,2.64,13.05]],"bdatl":[[1,2.76,13.1],[2,2.78,2.05],[4,2.82,4.87],[5,2.84,7.49],[0,2.74,5.88],[3,2.8,15.96],[6,2.86,5.51],[7,2.88,19.9],[8,2.9,4.5],[9,2.92,3.55]],"ltp":2.72,"tv":349.67,"id":42930960},{"atb":[[4.2,2.29],[4.1,14.81]],"bdatb":[[3,4,19.79],[4,3.95,5.63],[5,3.85,15.57],[6,3.8,2.03],[7,3.75,5.9],[8,3.7,10.31],[9,3.6,2.27],[1,4.2,2.29],[2,4.1,14.81]],"bdatl":[[7,5.2,18.06],[8,5.3,9.99],[9,5.4,2.04],[6,5.1,3.45],[4,4.9,10.08],[5,5,6.35],[3,4.8,12.88]],"id":40095374},{"atb":[[2.72,12.44],[2.74,9.05],[2.76,2.18],[2.66,5.59],[2.68,13.08]],"atl":[[2.86,2.16],[2.82,0],[2.84,0],[2.8,0],[3.4,15.13]],"trd":[[2.74,4]],"bdatb":[[1,2.74,9.05],[0,2.76,2.18],[2,2.72,7.01],[3,2.7,9.3],[4,2.68,13.08],[5,2.66,5.59],[6,2.64,30.56],[7,2.62,5.58],[8,2.6,30.98],[9,2.56,34.29]],"bdatl":[[0,2.82,12.2],[1,2.84,10.36],[2,2.88,20.05],[3,2.9,2],[4,2.92,2],[5,2.96,13.54],[6,3.05,1.5],[7,3.1,6.57],[8,3.15,6.72],[9,3.2,42.77]],"ltp":2.74,"tv":211.15,"id":36276560},{"atb":[[1.22,24.64],[1.23,41.45],[1.25,0]],"atl":[[1000,5.13]],"bdatb":[[4,1.2,17.52],[5,1.19,99.53],[6,1.18,22.19],[7,1.17,33.18],[8,1.16,16.12],[9,1.15,8.58],[1,1.23,41.45],[2,1.22,24.64],[3,1.21,190.11],[0,1.24,126.15]],"bdatl":[[6,1.32,4.44],[7,1.33,2.82],[8,1.34,6.99],[9,1.35,4.41],[4,1.3,59.1],[5,1.31,50.84],[3,1.29,77.16]],"id":39823721},{"atl":[[24,4.13],[23,3.64],[22,7.04],[26,7.72],[20,0.68],[21,1.14]],"bdatb":[[1,13,3.63],[2,12.5,3.81],[3,12,1.52],[4,11.5,3.1],[5,10.5,4.73],[6,10,13.84],[7,9.6,2.09],[8,9.4,3.26],[9,8.8,1.54]],"bdatl":[[8,36,6.08],[9,42,2.49],[6,28,4.38],[0,21,1.82],[2,23,5.46],[3,24,20.95],[4,26,7.95],[7,30,5.17],[1,22,5.14],[5,27,2.98]],"id":44331354},{"bdatb":[[5,4.7,7.85],[6,4.6,3.5],[8,4.3,5.39],[9,4.2,5.22],[7,4.5,13.43]],"bdatl":[[8,7,1.39],[9,7.4,7.59],[6,6.4,3.87],[7,6.6,2.87],[5,6.2,4.57],[4,6,15.44]],"id":37947503}],"con":true,"tv":1875.74}]}
{"op":"mcm","clk":"AKY1ANwsAOQu","pt":1650392714498,"mc":[{"id":"1.197931751","rc":[{"atb":[[2.68,8.6],[2.72,0],[2.62,6.56],[2.64,5.57],[2.36,23.23]],"atl":[[2.72,2.22],[2.78,2.05],[2.8,10.92],[2.76,11.11],[2.96,3.51],[2.74,18.64],[2.82,9.28]],"bdatb":[[5,2.62,6.56],[8,2.5,4.97],[9,2.46,9.06],[4,2.64,5.57],[2,2.68,2],[0,2.72,3.23],[1,2.7,2],[3,2.66,5.41],[7,2.52,13.55]],"bdatl":[[2,2.78,2.05],[3,2.8,10.92],[0,2.74,18.64],[1,2.76,11.11],[4,2.82,9.28]],"id":42930960},{"atb":[[4.1,18.34]],"atl":[[5.4,22.73]],"bdatb":[[6,3.85,11.27],[7,3.8,8.3],[9,3.7,15.98],[5,3.9,1.6],[8,3.75,2.03],[2,4.1,18.34],[4,3.95,2.19]],"bdatl":[[9,5.4,23.66],[6,5.1,3.16],[7,5.2,14.41],[8,5.3,11.33]],"id":40095374},{"atb":[[2.76,0],[2.48,6.74],[2.74,8.97],[2.68,30.37],[2.54,7.53]],"atl":[[2.86,2.16],[2.84,2.2],[2.9,11.63]],"trd":[[2.76,6.28]],"bdatb":[[0,2.74,8.97],[1,2.72,12.44],[2,2.7,9.3],[3,2.68,30.37],[4,2.66,5.59],[5,2.64,30.56],[6,2.62,5.58],[7,2.6,30.98],[8,2.58,8.19],[9,2.56,26.05]],"bdatl":[[1,2.86,2.16],[0,2.84,2.2],[2,2.88,20.05],[3,2.9,11.63],[4,2.92,2],[5,2.96,13.54],[6,3.05,1.5],[7,3.1,3.1],[8,3.15,7.61],[9,3.2,44.74]],"ltp":2.76,"tv":215.15,"id":36276560},{"atb":[[1.23,50.12]],"bdatb":[[6,1.18,27.57],[7,1.17,14.76],[8,1.16,21.2],[9,1.15,9.52],[3,1.21,181.96],[4,1.2,25.74],[1,1.23,50.12],[5,1.19,99.53]],"bdatl":[[6,1.32,7.87],[7,1.33,6.26],[4,1.3,57.98],[5,1.31,43.74],[9,1.36,10.36],[8,1.35,1.24]],"id":39823721},{"atb":[[13,6.05]],"atl":[[24,4.13]],"bdatb":[[6,9.6,2.25],[7,9.2,2.4],[8,8.2,1.67],[3,11.5,6.07],[9,8,1.03],[1,13,6.05],[4,10.5,4.64],[5,10,14.77],[2,12.5,2.52]],"bdatl":[[4,26,7.72],[6,28,4.01],[8,36,6.21],[9,42,2.45],[3,24,9.2],[1,22,7.04],[2,23,3.64],[7,30,5.35]],"id":44331354},{"bdatb":[[7,4.5,10.93],[8,4.4,4.8],[6,4.6,1.36],[9,4.3,3.8]],"bdatl":[[6,6.4,3.64],[7,6.6,1.46],[9,7.4,7.54],[8,7,1.56]],"id":37947503}],"con":true,"tv":1879.74}]}
{"op":"mcm","clk":"AOk2AOEtAPgv","pt":1650392715500,"mc":[{"id":"1.197931751","rc":[{"atb":[[2.32,59.84],[2.68,8.85],[2.7,0],[2.6,30.65]],"atl":[[2.78,4.05],[2.74,12.9],[2.72,6.04]],"trd":[[2.7,22.12]],"bdatb":[[0,2.68,8.85],[7,2.46,4.01],[8,2.44,5.09],[9,2.42,1.16],[1,2.66,5.41],[2,2.64,5.57],[3,2.62,6.56],[4,2.6,30.65],[5,2.52,13.55],[6,2.5,4.97]],"bdatl":[[3,2.78,4.05],[0,2.72,6.04],[1,2.74,12.9],[2,2.76,11.11],[4,2.8,10.92],[5,2.82,9.28],[6,2.84,7.49],[7,2.86,5.51],[8,2.88,19.9],[9,2.9,4.5]],"ltp":2.7,"tv":353.67,"id":42930960},{"atb":[[2.7,12.9]],"atl":[[3.6,51.92]],"bdatb":[[2,2.7,12.9],[8,2.58,2.28],[9,2.56,30.9],[6,2.62,10.77],[7,2.6,26.84]],"bdatl":[[8,3.2,44.74],[9,3.3,1.59],[6,3.1,1.47],[7,3.15,10.66]],"id":36276560},{"atl":[[5.4,4.13]],"trd":[[5.4,5.77]],"bdatb":[[6,4.6,2.7],[7,4.5,10.18],[8,4.4,4.16],[9,4.3,3.96]],"bdatl":[[7,6.8,3.49],[8,7.4,7.79],[9,7.8,1.22],[0,5.4,4.13],[6,6.4,2.93]],"tv":18.95,"id":37947503},{"atb":[[1.2,2],[1.04,0.25]],"atl":[[1.3,54.47],[1.27,92.01],[1000,5]],"bdatb":[[4,1.2,10.24],[5,1.19,107.53],[6,1.18,18.61],[7,1.17,31.63],[8,1.16,15.81],[9,1.15,3.36],[3,1.21,187.07]],"bdatl":[[4,1.3,54.47],[7,1.33,6.26],[8,1.34,1.24],[9,1.35,2.63],[1,1.27,92.01],[5,1.31,39.88],[6,1.32,15.16]],"id":39823721},{"atl":[[24,8.48]],"bdatb":[[3,11.5,4.45],[4,11,1.13],[5,10.5,4.7],[6,10,13.17],[7,9.8,1.38],[8,9.6,2.52],[9,9.4,1.2],[2,12.5,3.02]],"bdatl":[[8,36,6.63],[3,24,8.48],[7,30,5.17],[9,42,2.45],[6,28,3.7]],"id":44331354},{"bdatb":[[7,3.8,3.55],[8,3.75,6.06],[9,3.7,12.36],[4,3.95,3.77],[5,3.9,1.89],[6,3.85,10.1]],"bdatl":[[8,5.3,13.78],[9,5.4,22.89],[7,5.2,13.59],[6,5.1,2.27]],"id":40095374}],"con":true,"tv":1889.41}]}
{"op":"mcm","clk":"AKY4AIsvAJEx","pt":1650392716502,"mc":[{"id":"1.197931751","rc":[{"atb":[[2.64,31.93],[2.68,15.11]],"atl":[[2.7,0],[2.84,2.58],[2.82,4.41],[2.8,8.91]],"bdatb":[[6,2.5,7.8],[7,2.48,2.49],[8,2.46,3.29],[9,2.42,1.55],[0,2.68,2.25],[2,2.64,24.18]],"bdatl":[[0,2.7,2.26],[1,2.72,6.04],[2,2.74,12.9],[3,2.76,11.11],[4,2.78,4.05],[5,2.8,8.91],[6,2.82,9.28],[7,2.84,7.49],[8,2.86,5.51],[9,2.88,19.9]],"id":42930960},{"atb":[[4.1,27.71]],"atl":[[5.2,10],[4.6,16.52],[4.7,18.85],[4.5,7.51],[5.7,0],[5.5,0],[5.3,0],[5.6,32.61]],"bdatb":[[3,4,21.32],[4,3.95,4.09],[5,3.9,2.29],[6,3.85,10.19],[7,3.8,4.17],[8,3.75,2.96],[9,3.7,15.5],[2,4.1,27.71]],"bdatl":[[6,5.1,3.16],[7,5.2,13.88],[8,5.3,2.72],[9,5.4,22.81],[0,4.5,7.51],[1,4.6,12.99],[2,4.7,18.85]],"id":40095374},{"atb":[[2.74,2.12],[2.72,5.54]],"atl":[[2.88,94.44],[2.86,11.57],[2.82,2.2],[2.84,6.87]],"bdatb":[[0,2.74,2.12],[1,2.72,5.54],[7,2.6,29.19],[8,2.58,4.37],[9,2.56,26.05],[5,2.64,32.88],[6,2.62,8.44]],"bdatl":[[0,2.84,6.87],[1,2.86,2.16],[2,2.88,20.05],[3,2.9,11.63],[4,2.92,2],[5,2.96,13.54],[6,3.05,1.98],[7,3.1,4.64],[8,3.15,5.63],[9,3.2,44.56]],"id":36276560},{"atl":[[5.4,6.28]],"bdatb":[[5,4.7,9.15],[6,4.6,2.92],[7,4.5,10.67],[8,4.4,1.84],[9,4.3,5.6]],"bdatl":[[0,5.4,6.28],[6,6.4,3.64],[7,6.8,2.34],[8,7.4,7.97],[9,8,1.46]],"id":37947503},{"atb":[[1.23,52.14],[1.25,58.72],[1.22,34.27],[1.04,0]],"atl":[[1000,6]],"trd":[[1.25,77.36]],"bdatb":[[0,1.25,25.88],[1,1.24,126.15],[2,1.23,52.14],[3,1.22,34.27],[4,1.21,192.92],[5,1.2,13.9],[6,1.19,97.2],[7,1.18,29.13],[8,1.17,21.59],[9,1.16,24.62]],"bdatl":[[6,1.32,1.11],[7,1.33,14.22],[8,1.34,5.93],[9,1.35,1.23]],"ltp":1.25,"tv":1235.34,"id":39823721},{"atb":[[12.5,8.78]],"atl":[[30,0]],"bdatb":[[1,13,6.52],[2,12.5,9.85],[3,11.5,4.3],[4,10.5,5.38],[5,10,13.72],[6,9.8,1.54],[7,9.6,1.77],[8,9,1.22],[9,8.8,1.97]],"bdatl":[[6,28,3.91],[7,36,6.38],[8,42,2.54],[9,1000,5.29]],"id":44331354}],"con":true,"tv":1889.91}]}
{"op":"mcm","clk":"AMM5ALcwALoy","pt":1650392717503,"mc":[{"id":"1.197931751","rc":[{"atb":[[2.62,15.94],[2.64,37.7],[2.32,60.96],[2.68,2.25],[2.7,0],[2.58,18.38],[2.6,12.49]],"atl":[[2.76,6.95],[2.72,2.25],[2.78,4.05],[2.7,0],[2.74,5.88]],"trd":[[2.72,69.91]],"bdatb":[[8,2.46,9.53],[9,2.44,9.34],[7,2.48,9.24],[2,2.64,37.7],[5,2.58,18.38],[6,2.52,19.01],[0,2.68,2.25],[1,2.66,5.41],[3,2.62,6.56],[4,2.6,12.49]],"bdatl":[[2,2.76,6.95],[0,2.72,2.25],[1,2.74,5.88],[3,2.78,4.05],[4,2.8,8.91],[5,2.82,4.41],[6,2.84,2.58],[7,2.86,5.51],[8,2.88,19.9],[9,2.9,4.5]],"ltp":2.72,"tv":361.41,"id":42930960},{"atb":[[3.95,9.9],[3.9,15.31],[4.5,3.25],[4.4,2.44],[4.1,23.46],[4.3,10.86],[4.2,12.44]],"atl":[[5.4,0],[4.7,16.54],[4.9,8.03],[4.5,0],[4.8,10.86],[1000,6.65],[5.2,0.48],[5.5,8.89],[5.1,0],[4.6,18.81]],"bdatb":[[0,4.5,3.25],[1,4.4,2.44],[2,4.3,10.86],[3,4.2,12.44],[4,4.1,23.46],[5,4,23.23],[6,3.95,2.36],[7,3.9,17.31],[8,3.85,13.14],[9,3.8,3.22]],"bdatl":[[5,5.2,1.36],[6,5.4,1.13],[7,5.5,9.7],[8,5.6,33.57],[9,5.7,4.05],[0,4.6,18.81],[1,4.7,16.54],[2,4.8,10.86],[3,4.9,8.03],[4,5,6.35]],"id":40095374},{"atb":[[2.7,12.9],[2.68,7.06],[2.66,17.5],[2.64,24.57],[2.72,0],[2.74,0],[1.9,155.55],[1.85,0]],"atl":[[2.78,2.19],[2.84,34.97],[2.8,12.63],[2.82,19.38],[2.88,51.62],[3.7,83.33]],"bdatb":[[0,2.72,5.54],[1,2.7,17.74],[2,2.68,13.08],[3,2.66,23.09],[4,2.64,30.56],[5,2.62,5.58],[6,2.6,28.1],[7,2.58,2.96],[8,2.56,26.05],[9,2.54,7.8]],"bdatl":[[7,2.96,15.08],[8,3.05,3.31],[9,3.1,1.87],[0,2.8,13.13],[1,2.82,19.38],[2,2.84,17.23],[3,2.86,11.57],[4,2.88,51.62],[5,2.9,11.63],[6,2.92,2]],"id":36276560},{"atb":[[4.8,22.13],[5.3,2]],"atl":[[5.6,10.74],[5.5,0],[5.7,4],[5.4,0]],"trd":[[5.4,18.35]],"bdatb":[[5,4.8,24.99],[6,4.7,7.85],[7,4.6,1.84],[8,4.5,13.56],[9,4.4,8.23],[4,4.9,14.32],[0,5.3,2],[1,5.2,6.33],[2,5.1,6.57],[3,5,13.95]],"bdatl":[[0,5.6,10.74],[5,6.4,3.87],[6,6.6,1.3],[7,7,1.54],[8,7.4,11.4],[9,8,1.14],[1,5.7,4],[2,5.8,1.83],[3,6,15.44],[4,6.2,4.57]],"tv":31.53,"id":37947503},{"atb":[[1.24,58.35],[1.21,38.46],[1.23,68.13],[1.25,0],[1.22,24.64]],"atl":[[1.3,34.57],[1.26,169.38],[1000,5],[1.25,11],[1.27,106.19]],"trd":[[1.25,258.06]],"bdatb":[[7,1.17,7.62],[8,1.16,9.4],[9,1.15,4.26],[4,1.2,32.56],[5,1.19,110.54],[6,1.18,21.14],[2,1.22,24.64],[3,1.21,38.46],[0,1.24,51.39],[1,1.23,68.13]],"bdatl":[[4,1.29,80.69],[5,1.3,39.22],[6,1.31,39.47],[7,1.32,4.39],[8,1.33,17.35],[9,1.34,14.54],[1,1.26,169.38],[0,1.25,11],[2,1.27,106.19],[3,1.28,137.05]],"tv":1416.04,"id":39823721},{"atb":[[13.5,4.37],[1.02,1.99]],"atl":[[21,0],[20,2.79],[22,5.14],[19,0.76],[19.5,1.14],[26,9.72]],"bdatb":[[5,10,14.55],[6,9.8,1.79],[7,9.6,1.24],[8,8.8,1.35],[9,7.8,6.4],[2,12.5,9.27],[3,11.5,3.71],[4,10.5,5.68],[0,13.5,4.7],[1,13,6.05]],"bdatl":[[5,24,8.73],[6,26,9.9],[8,28,3.7],[1,20,2.79],[2,21,2],[3,22,5.14],[4,23,3.64],[7,27,2.98],[9,36,6.06],[0,19.5,1.9]],"id":44331354}],"con":true,"tv":2090.93}]}
{"op":"mcm","clk":"APQ6AN8xAN8z","pt":1650392718503,"mc":[{"id":"1.197931751","rc":[{"atb":[[2.62,6.56],[2.6,30.65]],"bdatb":[[8,2.5,5.44],[9,2.48,1.14],[3,2.62,18.48],[7,2.52,20.29],[4,2.6,30.65],[6,2.54,2.4]],"id":42930960},{"atb":[[3.9,0],[4.1,17.74],[3.95,2.19],[4.2,21.52]],"atl":[[1000,5.13],[4.6,15.28],[4.7,18.88]],"bdatb":[[7,3.9,4.21],[8,3.85,9.36],[9,3.8,2.5],[4,4.1,19.23],[5,4,23.83],[6,3.95,2.4],[3,4.2,21.52]],"bdatl":[[0,4.6,15.28],[5,5.2,1.64],[6,5.3,2.4],[7,5.5,11.69],[8,5.6,36.01],[9,5.9,2.35],[1,4.7,18.88]],"id":40095374},{"atb":[[2.62,15.2],[2.48,2],[2.46,4.85],[2.52,4.38],[2.5,2.69],[2.54,2.58],[2.66,0],[2.72,6.9],[2.7,12.73]],"atl":[[2.78,3.91],[3.15,2.48],[2.82,21.1],[2.8,22.87]],"bdatb":[[4,2.62,15.2],[8,2.54,7.93],[9,2.52,5.51],[3,2.64,24.57],[5,2.6,28.1],[6,2.58,3.22],[7,2.56,29.42],[0,2.72,6.9],[1,2.7,12.73],[2,2.68,7.06]],"bdatl":[[1,2.8,22.87],[2,2.82,21.1],[8,2.96,15.57],[9,3,2.87],[0,2.78,2.19],[3,2.84,34.97],[4,2.86,11.57],[5,2.88,51.62],[6,2.9,11.63],[7,2.92,2]],"id":36276560},{"atb":[[4.9,9.78],[5.3,6.44],[5.1,10.04],[4.8,13.42]],"atl":[[5.8,3.83],[5.6,4.12]],"bdatb":[[6,4.7,12.58],[7,4.5,12.84],[2,5.1,10.04],[0,5.3,6.44],[4,4.9,11.02],[5,4.8,15.16],[8,4.4,4.01],[9,4.3,1.7]],"bdatl":[[2,5.8,3.83],[0,5.6,4.12],[5,6.4,5.22],[6,7,1.56],[7,7.2,3.86],[8,7.4,6.48],[9,7.8,2.28]],"id":37947503},{"atb":[[1.22,37.4],[1.23,55.63],[1.24,43.79],[1.2,147.25]],"atl":[[1.25,31.6],[1.26,270.34],[1.3,31.06]],"bdatb":[[6,1.18,18.83],[7,1.17,1.9],[0,1.24,43.79],[4,1.2,161.41],[5,1.19,116.25],[8,1.16,21.3],[9,1.15,6.37],[1,1.23,55.63],[2,1.22,37.4],[3,1.21,43.49]],"bdatl":[[0,1.25,31.6],[9,1.34,14.11],[1,1.26,270.34],[4,1.29,81.83],[5,1.3,37.67],[6,1.31,44.59],[7,1.32,6.63],[8,1.33,14.31]],"id":39823721},{"atb":[[11,5.74],[12.5,11.08],[14,7.29]],"atl":[[25,0]],"bdatb":[[6,11,7.23],[7,10.5,3.26],[9,9.6,2.85],[0,14,7.29],[1,13.5,4.37],[2,13,6.52],[3,12.5,11.08],[4,12,1.34],[5,11.5,3.15],[8,10,13.81]],"bdatl":[[4,24,8.73],[5,25,4.76],[6,26,10.05],[7,27,2.98],[8,28,3.7],[9,36,6.23],[2,22,5.14],[3,23,3.64]],"id":44331354}],"con":true}]}
{"op":"mcm","clk":"AJU8AIozAIo1","pt":1650392719505,"mc":[{"id":"1.197931751","rc":[{"atb":[[2.28,94.29]],"atl":[[4.4,11.76],[4.5,0]],"bdatb":[[6,2.52,16.19],[7,2.5,4.35],[8,2.48,2.23],[9,2.46,9.27],[3,2.62,6.56]],"id":42930960},{"atb":[[4.1,12.62],[4.5,3.12]],"atl":[[4.7,21.24],[4.8,12.87],[1000,5],[5.7,21.28]],"trd":[[4.5,19.76]],"bdatb":[[4,4.1,12.62],[5,4,21.45],[6,3.95,4.95],[7,3.9,1.2],[8,3.85,9.58],[9,3.8,6.83],[0,4.5,3.12]],"bdatl":[[1,4.7,21.24],[2,4.8,12.87],[9,5.7,21.48]],"ltp":4.5,"tv":67.06,"id":40095374},{"atb":[[1.9,111.11],[2,40],[2.64,6.86],[2.62,5.58]],"atl":[[3.4,0],[3.6,13.85],[2.82,19.38],[2.76,2.41]],"bdatb":[[5,2.6,25.75],[6,2.56,28.44],[7,2.54,5.86],[8,2.52,7.81],[9,2.5,8.13],[3,2.64,6.86],[4,2.62,5.58]],"bdatl":[[3,2.82,19.38],[0,2.76,2.41],[1,2.78,3.91],[2,2.8,22.87],[4,2.84,34.97],[5,2.86,11.57],[6,2.88,51.62],[7,2.9,11.63],[8,2.92,2],[9,2.96,15.57]],"id":36276560},{"atb":[[4.7,0],[5.1,17.12]],"atl":[[9.8,0],[6,9.59]],"bdatb":[[4,4.9,9.78],[5,4.8,14.69],[6,4.7,1.77],[7,4.6,1.69],[8,4.5,16.06],[9,4.4,4.01],[2,5.1,17.12]],"bdatl":[[3,6,9.59],[5,6.4,5.12],[7,7.2,3.94],[9,7.8,2.2]],"id":37947503},{"atl":[[1.26,169.38],[1.25,0]],"trd":[[1.25,321.26]],"bdatb":[[3,1.21,43.96],[4,1.2,160.94]],"bdatl":[[0,1.26,270.34],[1,1.27,106.19],[2,1.28,137.05],[3,1.29,81.83],[4,1.3,37.22],[5,1.31,44.59],[6,1.32,7.07],[7,1.33,14.31],[8,1.34,13.68],[9,1.36,13.75]],"tv":1479.24,"id":39823721},{"atb":[[11,0],[12.5,8.78],[13.5,6.69]],"atl":[[28,0],[22,9.9]],"bdatb":[[1,13.5,6.69],[2,13,6.05],[3,12.5,8.78],[4,11.5,4.57],[5,10.5,5.34],[6,10,13.81],[7,9.6,2.85],[8,8.8,1.07],[9,8.4,1.47]],"bdatl":[[7,36,6.24],[8,42,2.44],[9,1000,5.74],[5,26,10.03],[2,22,9.9],[6,27,2.98]],"id":44331354}],"con":true,"tv":2154.39}]}
{"op":"mcm","clk":"ALs9AKM0AJk2","pt":1650392720507,"mc":[{"id":"1.197931751","rc":[{"atl":[[2.84,2]],"bdatl":[[6,2.84,2],[8,2.88,20.01]],"id":42930960},{"atb":[[4.3,16.51]],"atl":[[5.9,30.61]],"bdatb":[[2,4.3,16.51]],"bdatl":[[5,5.3,1.62],[6,5.4,2.66],[7,5.5,11.38],[8,5.6,32.66],[9,5.7,24.6]],"id":40095374},{"atb":[[2.72,0],[2.62,23.51]],"bdatb":[[0,2.7,12.73],[1,2.68,7.06],[2,2.64,6.86],[3,2.62,23.51],[4,2.6,25.75],[5,2.56,28.44],[6,2.54,5.86],[7,2.52,7.81],[8,2.5,8.13],[9,2.48,3.91]],"bdatl":[[8,2.92,2.11],[9,2.96,15.47]],"id":36276560},{"atl":[[9.6,4.65]],"bdatl":[[4,6.2,4.62],[5,6.4,3.82],[6,6.6,1.21],[7,7,1.56],[8,7.2,1.33],[9,7.4,8.88]],"id":37947503},{"atb":[[1.25,0.25],[1.04,0],[1.22,35.38]],"bdatb":[[0,1.24,44.04],[9,1.15,4.94],[2,1.22,35.38]],"bdatl":[[3,1.29,77.16],[4,1.3,41.86],[7,1.34,14.31],[8,1.35,13.42],[9,1.36,17.92],[0,1.26,169.38]],"id":39823721},{"atb":[[13.5,6.25]],"atl":[[22,9.05]],"bdatb":[[1,13.5,6.25]],"bdatl":[[2,22,9.06],[5,26,9.94],[4,24,8.48],[7,36,6.52],[9,1000,5.6]],"id":44331354}],"con":true}]}
{"op":"mcm","clk":"AIM/AMM1AJo3","pt":1650392721605,"mc":[{"id":"1.197931751","rc":[{"atb":[[2.28,172.42],[2.24,162.22],[2.62,6.56],[2.6,12.49]],"bdatb":[[3,2.62,6.56],[4,2.6,12.49],[5,2.58,20.96],[6,2.56,2.09],[7,2.52,15.75],[8,2.5,3.22],[9,2.48,4.36]],"bdatl":[[8,2.88,19.9]],"id":42930960},{"atb":[[3.45,40.82],[3.9,2],[4.5,1.52]],"trd":[[4.5,22.96]],"bdatb":[[2,4.3,16.51],[3,4.2,22.98],[4,4.1,14.06],[7,3.9,2.86],[8,3.85,13.48],[9,3.8,3.83],[5,4,21.17],[6,3.95,3.38],[0,4.5,1.52]],"bdatl":[[9,5.9,30.62],[7,5.7,22.02],[8,5.8,1.63],[5,5.5,10.47],[6,5.6,35.18]],"tv":70.26,"id":40095374},{"atb":[[2.3,76.92],[2.62,5.58],[2.64,6.86],[1.98,102.04],[2.7,9.13],[2.68,12.66]],"atl":[[3.7,33.33],[2.8,22.87],[3.5,0]],"bdatb":[[2,2.64,6.86],[3,2.62,7.92],[4,2.6,28.01],[5,2.56,27.33],[6,2.54,5.31],[7,2.52,5.71],[8,2.5,9.02],[9,2.48,4.81],[0,2.7,9.13],[1,2.68,12.66]],"bdatl":[[2,2.8,22.87],[9,2.96,13.54],[8,2.92,2]],"id":36276560},{"atb":[[5.2,13.24],[3.95,67.8],[4.9,9.78],[4.8,5.77]],"atl":[[5.6,4.57]],"bdatb":[[5,4.8,5.77],[1,5.2,6.33],[2,5.1,17.12],[3,5,15.28],[4,4.9,19],[8,4.5,13.64],[9,4.4,2.12],[6,4.7,1.18],[7,4.6,5.19]],"bdatl":[[9,7.8,1.78],[6,7,1.01],[8,7.4,6.7],[5,6.4,2.93],[7,7.2,1.49],[0,5.6,4.57],[4,6.2,4.57]],"id":37947503},{"atb":[[1.08,51],[1.14,714.29],[1.22,35.38],[1.21,40.48],[1.23,27.8],[1.24,0],[1.25,0]],"atl":[[1.29,44.74],[1.27,142.98],[1000,5.25],[1.24,0],[1.3,31.06],[1.25,9.6],[1.28,144.26],[1.26,138.04]],"trd":[[1.24,326.88],[1.26,313.98],[1.25,321.76]],"bdatb":[[6,1.16,21.29],[7,1.15,23.16],[8,1.14,10.05],[9,1.13,25.06],[1,1.22,42.42],[2,1.21,47.89],[0,1.23,27.8],[3,1.2,153.96],[4,1.19,116.25],[5,1.18,18.58]],"bdatl":[[0,1.25,9.6],[3,1.28,144.26],[4,1.29,60.73],[5,1.3,36.32],[1,1.26,138.04],[7,1.32,5.36],[8,1.33,7.11],[9,1.34,18.26],[2,1.27,106.19],[6,1.31,44.59]],"ltp":1.26,"tv":1784.24,"id":39823721},{"atb":[[13.5,8.99],[7.4,15.63],[14,7.6]],"atl":[[20,0.68],[19.5,2.16],[18,0.85],[18.5,1.14],[24,10.65],[19,1.29]],"bdatb":[[8,8.6,1.29],[9,8.4,1.01],[0,14,7.6],[1,13.5,6.7],[2,13,6.09],[3,12.5,9.21],[4,11.5,3.56],[5,10.5,5.34],[6,10,13.81],[7,9.6,3.08]],"bdatl":[[0,18.5,1.99],[2,19.5,2.16],[3,22,9.73],[4,23,3.64],[5,24,10.65],[6,26,9.72],[7,27,2.98],[8,36,6.12],[9,42,2.7],[1,19,1.29]],"id":44331354}],"con":true,"tv":2462.59}]}
{"op":"mcm","clk":"AJRAAOw2AJk4","pt":1650392722607,"mc":[{"id":"1.197931751","rc":[{"atb":[[2.62,6.56],[2.64,25.24]],"atl":[[2.94,0],[2.96,0]],"bdatb":[[3,2.62,6.56],[6,2.56,4.25],[7,2.54,3.17],[8,2.52,13.62],[9,2.48,4.29],[2,2.64,25.24]],"id":42930960},{"atb":[[2.86,0],[2.96,30.77]],"atl":[[5.4,9.09],[5.5,0]],"bdatb":[[4,4.1,15.41],[5,4,21.8],[6,3.95,2.23],[7,3.9,2],[8,3.85,13.43]],"bdatl":[[5,5.4,9.57],[6,5.5,1.1],[7,5.6,35.18],[8,5.7,22.02],[9,5.8,1.63]],"id":40095374},{"atb":[[1.84,4.06]],"bdatb":[[4,2.6,29.28],[5,2.58,2.69],[6,2.56,27.35],[7,2.54,2.65],[8,2.52,4.38],[9,2.5,8.96]],"id":36276560},{"atb":[[1.08,50.1],[1.23,84.7],[1.22,22.62]],"atl":[[1.25,20.6],[1.26,131.43],[1000,5]],"bdatb":[[0,1.23,84.7],[6,1.17,6.25],[7,1.16,19.89],[8,1.15,18.27],[9,1.14,724.28],[1,1.22,27.64],[2,1.21,49.91]],"bdatl":[[0,1.25,20.6],[1,1.26,131.43],[2,1.27,142.98],[4,1.29,44.74]],"id":39823721},{"atb":[[12.5,12.16]],"atl":[[23,0],[19.5,0],[19,3.51],[21,0]],"bdatb":[[3,12.5,13.03],[4,11.5,3.76],[5,10.5,4.59],[1,13.5,9.44]],"bdatl":[[1,19,3.51],[2,22,9.73],[3,24,10.65],[4,26,9.72],[5,27,2.98],[6,36,6.12],[7,42,2.7],[8,1000,5.59],[9,0,0]],"id":44331354},{"bdatb":[[4,4.9,12],[5,4.8,6.75],[6,4.6,4.16],[7,4.5,15.71],[8,4.4,1.66],[9,4.3,2.89],[1,5.2,13.24]],"bdatl":[[9,7.8,4.91]],"id":37947503}],"con":true}]}
{"op":"mcm","clk":"AMFBAPc3AKI5","pt":1650392723607,"mc":[{"id":"1.197931751","rc":[{"atb":[[1.84,311.94],[2.06,247.19],[2.62,24.49]],"bdatb":[[8,2.52,17.84],[9,2.5,1.24],[3,2.62,24.49]],"id":42930960},{"atb":[[2.96,164.46],[2.5,174.69]],"bdatb":[[6,3.95,5.71],[8,3.85,9.86]],"bdatl":[[5,5.4,9.59],[6,5.5,1.07]],"id":40095374},{"atb":[[2.08,242.62],[1.86,479.1],[1.96,156.25]],"atl":[[3.8,48.21]],"bdatb":[[7,2.54,8.06],[9,2.5,3.46]],"bdatl":[[9,2.96,13.58]],"id":36276560},{"atb":[[3.4,109.18],[5,19.13],[2.82,143.97],[5.2,6.33]],"bdatb":[[3,5,20.46],[6,4.7,3.67],[7,4.5,16.13],[1,5.2,6.33]],"bdatl":[[5,6.4,2.95],[6,7.2,2.48],[7,7.4,6.7],[8,7.8,4.91],[9,8,2.26]],"id":37947503},{"atb":[[1.13,2015.6],[1.16,1641.95],[1.22,22.62],[1.24,0.1],[1.08,50]],"atl":[[1000,7.9],[1.25,31.6]],"bdatb":[[7,1.16,1657.56],[1,1.22,27.64],[0,1.23,84.8]],"bdatl":[[0,1.25,31.6]],"id":39823721},{"atb":[[1.02,2.15],[4.2,128.77],[5.5,58.23],[12.5,8.78]],"bdatb":[[5,11,1.27],[6,10.5,3.26],[7,10,13.81],[8,9.6,3.08],[9,8.6,1.29],[3,12.5,9.65]],"bdatl":[[8,1000,5.53],[4,26,9.73],[6,36,6.11]],"id":44331354}],"con":true}]}
{"op":"mcm","clk":"ANxCAJQ5ALA6","pt":1650392724607,"mc":[{"id":"1.197931751","rc":[{"atb":[[2.62,18.48],[2.64,47.62],[2.68,11.47]],"bdatb":[[3,2.62,19.8],[6,2.56,7.39],[7,2.54,6.85],[8,2.52,13.55],[9,2.5,1.49],[2,2.64,47.62],[0,2.68,11.47],[5,2.58,19.62]],"id":42930960},{"atb":[[2.14,217.79]],"atl":[[5.6,21.74]],"bdatb":[[4,4.1,17.37],[5,4,24.14],[6,3.95,2.19],[7,3.9,2.95],[8,3.85,9.8],[9,3.8,3.13],[2,4.3,17.32],[3,4.2,22.15]],"bdatl":[[6,5.5,2.98],[7,5.6,23.89],[8,5.7,21.87],[9,5.8,1.9],[5,5.4,9.99]],"id":40095374},{"atb":[[2.64,24.57],[1.94,258.76],[2.7,6.92],[1.86,304.68]],"atl":[[3.9,77.58],[2.78,14.4],[2.88,30.46],[2.8,38.77]],"bdatb":[[3,2.64,24.57],[5,2.6,31.95],[6,2.58,1.3],[7,2.56,32.23],[8,2.54,3.19],[9,2.52,4.38],[0,2.7,6.92],[2,2.66,1.31],[4,2.62,6.59]],"bdatl":[[1,2.78,14.4],[2,2.8,38.77],[6,2.88,30.46],[9,2.96,13.54]],"id":36276560},{"atb":[[5,13.95]],"bdatb":[[4,4.9,12.95],[5,4.8,10.1],[6,4.6,2.11],[7,4.5,13.21],[9,4.3,4.21],[1,5.2,6.99],[3,5,14.59]],"bdatl":[[8,7.4,8.1],[6,6.8,1.02],[7,7,1.53],[9,7.6,1.89],[5,6.4,2.93]],"id":37947503},{"atb":[[1.19,249.99],[1.2,2],[1.22,24.64],[1.24,0]],"atl":[[1000,6],[1.24,2.8]],"trd":[[1.24,327.08]],"bdatb":[[3,1.2,22.39],[4,1.19,255.01],[2,1.21,53.79],[5,1.18,15.19],[6,1.17,6],[7,1.16,1671.15],[8,1.15,38.06],[9,1.14,717.12],[1,1.22,29.66],[0,1.23,84.7]],"bdatl":[[7,1.31,45.44],[8,1.32,11.69],[9,1.33,8.29],[0,1.24,2.8],[1,1.25,31.6],[2,1.26,131.43],[3,1.27,142.98],[4,1.28,144.26],[5,1.29,46.51],[6,1.3,34.57]],"ltp":1.24,"tv":1784.44,"id":39823721},{"atb":[[14.5,0.16],[1.02,1.99]],"atl":[[27,0],[18,3.92],[26,3.72],[20,5.94]],"bdatb":[[3,12.5,10.03],[4,11.5,4.73],[5,10.5,3.58],[6,10,13.28],[7,9.6,3.08],[8,8.6,2.28],[9,8.2,2.6],[0,14,8],[1,13.5,9.19]],"bdatl":[[0,18,3.92],[1,18.5,1.14],[2,19,3.51],[3,20,5.94],[4,22,9.05],[5,24,10.65],[6,26,3.72],[9,1000,5.58],[8,42,2.72],[7,36,6.12]],"id":44331354}],"con":true,"tv":2462.79}]}
{"op":"mcm","clk":"AOpDAKQ6AK07","pt":1650392725608,"mc":[{"id":"1.197931751","rc":[{"atb":[[2.62,6.56]],"bdatb":[[2,2.64,47.62],[3,2.62,7.88],[4,2.6,12.49],[5,2.58,21.26],[6,2.56,9.85],[7,2.52,16.33],[8,2.48,1.77],[9,2.46,9.28]],"id":42930960},{"atl":[[5.9,0],[5.7,0],[5.8,31.25]],"bdatb":[[1,4.4,2.44],[2,4.3,17.32],[3,4.2,23.28],[4,4.1,15.39],[8,3.85,10.5],[9,3.8,3.37],[5,4,24.59],[6,3.95,2.62],[7,3.9,2]],"bdatl":[[8,5.8,33.16],[9,5.9,3.71],[5,5.4,13.04],[6,5.5,2.19],[7,5.6,22.34]],"id":40095374},{"atb":[[2.72,6.88],[2.62,0],[1.88,0]],"atl":[[2.76,0],[2.82,12.49],[2.8,13.07],[2.78,3.91]],"bdatb":[[0,2.72,6.88],[1,2.7,6.92],[2,2.68,13.95],[3,2.64,25.58],[4,2.62,3.83],[5,2.6,33.42],[6,2.56,28.12],[7,2.54,3.24],[8,2.52,4.38],[9,2.5,6.52]],"bdatl":[[0,2.78,3.91],[1,2.8,13.07],[2,2.82,12.49],[3,2.84,34.97],[4,2.86,11.57],[5,2.88,30.46],[6,2.9,11.63],[7,2.92,2],[8,2.96,13.54],[9,3.05,2.25]],"id":36276560},{"atl":[[5.8,5.85],[5.6,6.67]],"bdatb":[[0,5.3,6.44],[1,5.2,6.99],[2,5.1,17.12],[3,5,15.44],[4,4.9,12.09],[6,4.6,1.31],[7,4.5,14.37],[9,4.3,2.89],[5,4.8,9.77],[8,4.4,1.66]],"bdatl":[[0,5.6,6.67],[2,5.8,5.85],[6,6.6,1.04],[7,6.8,1.58],[8,7.2,1.83],[9,7.4,7.22]],"id":37947503},{"atb":[[1.19,249.99]],"atl":[[1.25,31.7],[1000,5]],"bdatb":[[1,1.22,29.66],[2,1.21,53.79],[4,1.19,265.73],[5,1.18,8.62],[6,1.17,16.87],[7,1.16,1646.85],[8,1.15,48.59],[9,1.14,730.53],[3,1.2,17.99]],"bdatl":[[5,1.29,50.04],[6,1.3,39.32],[7,1.31,46.45],[8,1.32,2.55],[1,1.25,31.7]],"id":39823721},{"atb":[[13.5,6.52]],"atl":[[19,1.29],[18.5,2.29],[26,2.92],[17,0.95],[17.5,1.14]],"bdatb":[[1,13.5,6.52],[0,14,8.01],[2,13,6.26],[3,12.5,9.16],[4,11.5,5.34],[5,10.5,3.6],[6,10,13.64],[7,9.6,2],[8,9.4,1.08],[9,8.8,1.39]],"bdatl":[[2,18.5,2.29],[3,19,1.29],[4,20,5.94],[5,22,9.05],[6,24,10.65],[7,26,2.92],[8,36,6.47],[9,42,2.47],[0,17.5,2.09],[1,18,3.92]],"id":44331354}],"con":true}]}
{"op":"mcm","clk":"AJRFAJ47AKs8","pt":1650392726609,"mc":[{"id":"1.197931751","rc":[{"atb":[[2.62,18.48]],"bdatb":[[3,2.62,19.8]],"id":42930960},{"atb":[[14,10.08]],"bdatb":[[0,14,10.48]],"id":44331354}],"con":true}]}
{"op":"mcm","clk":"ALZGAL48ALU9","pt":1650392727611,"mc":[{"id":"1.197931751","rc":[{"atb":[[2.62,6.56],[2.64,63.66]],"bdatb":[[5,2.58,18.38],[6,2.54,4.28],[7,2.52,24.05],[8,2.5,4.05],[3,2.62,6.56],[9,2.48,8.48],[2,2.64,63.66]],"bdatl":[[9,2.9,5.29]],"id":42930960},{"atb":[[4.2,12.44]],"atl":[[6,50]],"bdatb":[[3,4.2,21.52],[4,4.1,14.12],[5,4,27.6],[6,3.95,3.22],[2,4.3,16.51],[7,3.9,3.56],[8,3.85,10.71],[9,3.8,3.97]],"bdatl":[[7,5.4,9.57],[8,5.6,21.88],[9,5.7,1.83],[5,5.2,4.08],[6,5.3,2.27]],"id":40095374},{"atb":[[2.7,9.56]],"bdatb":[[3,2.64,24.57],[4,2.6,28.1],[5,2.58,6.24],[6,2.56,31.95],[7,2.54,4.18],[2,2.68,12.66],[8,2.52,8.85],[9,2.5,5.68],[1,2.7,9.56]],"bdatl":[[8,2.96,15.86],[9,3.05,3.52]],"id":36276560},{"atb":[[1.25,31.7],[1.24,26.88],[1.22,22.62],[1.21,62.67]],"atl":[[1.26,117.24],[1.25,0],[1.24,0]],"trd":[[1.26,314],[1.25,385.15],[1.24,332.68]],"bdatb":[[0,1.24,26.88],[2,1.22,27.64],[3,1.21,88.47],[1,1.23,84.7],[4,1.2,10.45],[5,1.19,267.67],[6,1.18,7.71],[7,1.17,10.62],[8,1.16,1646.85],[9,1.15,48.59]],"bdatl":[[0,1.26,117.24],[1,1.27,142.98],[2,1.28,144.26],[3,1.29,50.04],[4,1.3,39.32],[5,1.31,46.45],[6,1.32,2.55],[7,1.33,8.29],[8,1.34,24.86],[9,1.35,7.5]],"ltp":1.26,"tv":1853.45,"id":39823721},{"atb":[[13.5,4.19]],"atl":[[19,3.51],[26,0],[17,4.03],[18.5,0]],"bdatb":[[2,13,6.05],[3,12.5,8.78],[4,11.5,4],[5,11,1.03],[6,10.5,4.91],[7,10,13.81],[8,9.6,2],[9,9.4,1.08],[0,14,10.24]],"bdatl":[[3,19,3.51],[8,42,2.5],[9,1000,5.47],[0,17,4.03],[1,17.5,1.14],[2,18,3.92],[4,20,5.94],[5,22,9.05],[6,24,10.94],[7,36,6.66]],"id":44331354},{"bdatb":[[3,5,13.95],[4,4.9,11.02],[5,4.8,9.13],[6,4.7,4.08],[7,4.6,2.45],[8,4.5,13.21],[9,4.4,2.82],[1,5.2,6.33]],"bdatl":[[7,7,2.26],[8,7.4,7.83],[9,7.8,4.35],[4,6.2,4.93],[5,6.4,3.64],[6,6.6,1.63]],"id":37947503}],"con":true,"tv":2531.8}]}
{"op":"mcm","clk":"ANtHAM49AMI+","pt":1650392728612,"mc":[{"id":"1.197931751","rc":[{"atb":[[2.68,9.24],[2.6,15.73],[2.62,24.49]],"atl":[[2.76,9.82],[2.8,17.25],[2.74,0],[2.72,0]],"bdatb":[[4,2.6,15.73],[6,2.54,4.73],[7,2.52,13.55],[8,2.5,2.08],[9,2.48,8.12],[0,2.68,9.24],[3,2.62,24.49]],"bdatl":[[4,2.84,2.8],[5,2.86,8.47],[7,2.9,5.98],[9,2.96,1.24],[0,2.76,2.83],[2,2.8,17.25],[1,2.78,4.05],[3,2.82,4.41],[6,2.88,19.9],[8,2.92,3.55]],"id":42930960},{"atb":[[4.1,22],[4.3,20.17],[4.4,3.42],[4,23.68],[4.2,14.91],[4.5,0]],"atl":[[5,8.26],[4.5,2.67],[4.8,10.86],[4.7,23.85]],"trd":[[4.5,26]],"bdatb":[[0,4.4,3.42],[1,4.3,16.51],[2,4.2,14.91],[3,4.1,24.04],[4,4,23.68],[5,3.95,3.79],[6,3.9,4.79],[7,3.85,9.85],[8,3.8,6.81],[9,3.75,10.01]],"bdatl":[[0,4.5,2.67],[3,4.8,10.86],[4,4.9,10.22],[5,5,8.26],[6,5.1,2.75],[8,5.4,11.04],[9,5.5,1.06],[1,4.6,15.28],[2,4.7,23.85],[7,5.2,2.28]],"tv":73.3,"id":40095374},{"atb":[[2.64,27.84]],"atl":[[2.84,44.48],[2.86,14.6],[2.76,2.29]],"bdatb":[[4,2.6,25.75],[6,2.54,7.31],[7,2.52,4.38],[8,2.5,5.51],[9,2.48,9.37],[3,2.64,27.84],[5,2.56,26.05]],"bdatl":[[6,2.88,31.25],[7,2.9,14.55],[9,2.96,14.99],[4,2.84,44.48],[5,2.86,14.6],[8,2.92,2],[0,2.76,2.29],[1,2.78,3.91],[2,2.8,13.07],[3,2.82,12.49]],"id":36276560},{"atb":[[5.1,19.55]],"atl":[[5.7,8.96],[5.8,8.23]],"bdatb":[[4,4.9,9.78],[5,4.8,7.09],[6,4.7,1.21],[7,4.6,1.13],[8,4.5,17.43],[2,5.1,19.55],[9,4.4,3.35]],"bdatl":[[1,5.7,8.96],[3,6,11.38],[5,6.4,3.6],[6,6.6,1.47],[8,7,1.6],[9,7.4,10.12],[2,5.8,8.23],[4,6.2,4.57],[7,6.8,2.12]],"id":37947503},{"atb":[[1.07,251],[1.26,8.53],[1.24,37.39],[1.21,176.8]],"atl":[[1.29,44.74],[1.27,72.56],[1.26,0],[1.28,152.89]],"trd":[[1.26,315.98]],"bdatb":[[0,1.26,8.53],[1,1.25,31.7],[2,1.24,37.39],[3,1.23,84.7],[4,1.22,29.03],[5,1.21,184.56],[6,1.2,18.78],[7,1.19,276.19],[8,1.18,11.7],[9,1.17,5.25]],"bdatl":[[0,1.27,82.56],[3,1.3,42.64],[4,1.31,43.81],[7,1.34,25.32],[8,1.35,5.63],[9,1.36,42.14],[1,1.28,152.89],[2,1.29,46.76],[5,1.32,7.08],[6,1.33,7.83]],"tv":1855.43,"id":39823721},{"atb":[[13.5,3.78]],"atl":[[22,11.43]],"bdatb":[[4,11.5,3.07],[5,10.5,4.19],[6,10,13.39],[7,9.6,3.14],[9,9.2,1.48],[1,13.5,3.78],[8,9.4,1.75]],"bdatl":[[5,22,9.56],[6,24,10.83],[7,36,6.69],[8,42,2.57],[9,1000,5.62]],"id":44331354}],"con":true,"tv":2536.82}]}
{"op":"mcm","clk":"APlIAOw+AOo/","pt":1650392729613,"mc":[{"id":"1.197931751","rc":[{"atb":[[2.62,36.41],[2.68,2.25]],"atl":[[2.78,8.74]],"bdatb":[[3,2.62,36.41],[6,2.52,16.06],[7,2.5,2.28],[8,2.46,2.11],[9,2.44,8.25],[0,2.68,2.25]],"bdatl":[[5,2.86,5.88],[7,2.9,8.53],[1,2.78,8.74],[0,2.76,9.82]],"id":42930960},{"atb":[[4.3,16.51],[4,19.79]],"atl":[[5,4]],"bdatb":[[5,3.95,2.27],[6,3.9,2],[7,3.85,13.75],[8,3.8,4.61],[9,3.75,4.73],[4,4,19.79],[1,4.3,16.51],[3,4.1,22]],"bdatl":[[4,4.9,8.71],[5,5,4],[6,5.1,3.01],[8,5.4,10.73],[9,5.6,22.02],[7,5.3,3.39]],"id":40095374},{"atl":[[2.86,14.6],[2.84,34.97]],"bdatb":[[6,2.54,2.71],[7,2.52,9.02],[8,2.5,2.69],[9,2.48,8.09]],"bdatl":[[7,2.9,12],[8,2.92,2],[9,2.96,14.44],[5,2.86,14.6],[4,2.84,34.97]],"id":36276560},{"atl":[[5.7,16.93]],"bdatb":[[5,4.8,5.84],[6,4.6,2.54],[7,4.5,10.45],[8,4.4,7.78],[9,4.3,7.19]],"bdatl":[[1,5.7,16.93],[3,6,10.15],[4,6.2,4.57],[5,6.4,4.76],[6,7,4.03],[7,7.4,11.12],[9,8,5.41],[8,7.6,1]],"id":37947503},{"atb":[[1.24,69.64],[1.26,2.66],[1.22,154.67],[1.07,250],[1.23,90.53]],"atl":[[1.3,31.06],[1.27,0.26],[1.28,143.51]],"trd":[[1.26,327.98]],"bdatb":[[0,1.26,2.66],[2,1.24,69.64],[8,1.18,14.74],[9,1.17,28.95],[4,1.22,164.52],[3,1.23,90.53],[6,1.2,22.25],[7,1.19,275.96],[5,1.21,189.28]],"bdatl":[[2,1.3,35.7],[0,1.28,143.77],[1,1.29,44.74],[3,1.31,46.08],[4,1.32,11.66],[5,1.33,7.83],[6,1.34,25.32],[7,1.35,5.63],[8,1.36,42.14],[9,1.37,3.89]],"tv":1867.43,"id":39823721},{"atb":[[13.5,9.25]],"bdatb":[[1,13.5,9.25],[5,10.5,3.68],[6,10,13.25],[7,9.6,2.8],[8,9.4,1.09],[9,9,1.56]],"bdatl":[[5,22,11.59],[6,24,10.76],[7,36,6.85],[8,42,2.66],[9,1000,5.67]],"id":44331354}],"con":true,"tv":2548.82}]}
{"op":"mcm","clk":"APlJAIZAAPBA","pt":1650392730614,"mc":[{"id":"1.197931751","rc":[{"atb":[[2.66,8.59],[2.6,33.89],[2.64,47.62],[2.48,101],[1.02,5001.99],[2.7,5.88],[2.68,2.25],[2.62,6.56]],"atl":[[2.78,11.91],[2.96,42]],"bdatb":[[2,2.66,8.59],[3,2.64,47.62],[5,2.6,33.89],[7,2.54,1.89],[8,2.52,16.42],[9,2.48,110.38],[0,2.7,5.88],[1,2.68,2.25],[4,2.62,6.56],[6,2.58,18.38]],"bdatl":[[1,2.78,11.91],[9,2.96,44.38],[5,2.86,6.31],[6,2.88,24.58],[7,2.9,8.4],[4,2.84,2]],"id":42930960},{"atb":[[1.02,5001.54],[3.7,75.19],[4.4,6.15]],"atl":[[5.5,23],[4.6,13.91]],"bdatb":[[0,4.4,6.15],[5,3.95,2.19],[6,3.9,8.95],[7,3.85,11.48],[8,3.8,2],[9,3.75,2.55]],"bdatl":[[7,5.3,1.48],[8,5.4,9.09],[9,5.5,23.97],[1,4.6,13.91],[4,4.9,11.24],[5,5,4.02],[6,5.1,3.58]],"id":40095374},{"atb":[[2.74,12.59],[1.02,5003.47],[2.52,103.38],[2.68,17.78]],"atl":[[2.78,1.72],[2.98,42],[2.82,12.49],[2.76,0],[2.84,28.1]],"bdatb":[[8,2.52,109.38],[0,2.74,5.75],[1,2.72,6.88],[2,2.7,9.56],[3,2.68,17.78],[4,2.64,27.84],[5,2.6,25.75],[6,2.56,26.05],[7,2.54,7.31],[9,2.5,5.95]],"bdatl":[[0,2.78,1.72],[2,2.82,12.49],[7,2.92,2.78],[8,2.94,4.62],[9,2.96,15.57],[1,2.8,13.07],[3,2.84,28.1],[4,2.86,14.6],[5,2.88,30.46],[6,2.9,11.63]],"id":36276560},{"atb":[[1.02,5003.54],[4.3,58]],"atl":[[7.2,17],[5.8,11.83]],"bdatb":[[9,4.4,1.39],[5,4.8,5.77],[6,4.7,2.56],[7,4.6,3.28],[8,4.5,11.1]],"bdatl":[[7,7,1.48],[8,7.2,19.16],[9,7.4,8.9],[3,6,9.97],[4,6.2,6.76],[5,6.4,4.68],[6,6.6,1.12],[2,5.8,11.83]],"id":37947503},{"atb":[[1.24,32.25],[1.17,214],[1.09,730],[1.23,98.88],[1.26,0],[1.25,31.52]],"atl":[[1000,6],[1.35,93],[1.27,27.77],[1.29,63.88]],"trd":[[1.26,333.3],[1.25,385.51]],"bdatb":[[1,1.24,32.25],[3,1.22,158.6],[4,1.21,195.25],[5,1.2,13.89],[6,1.19,279.08],[7,1.18,27.56],[8,1.17,235.64],[9,1.16,1661.4],[2,1.23,98.88],[0,1.25,31.52]],"bdatl":[[7,1.35,100.31],[2,1.29,76.09],[3,1.3,35.79],[4,1.31,45.71],[5,1.33,19.68],[6,1.34,28.19],[8,1.36,26.05],[9,1.37,12.66],[0,1.27,27.77],[1,1.28,143.51]],"ltp":1.25,"tv":1873.11,"id":39823721},{"atb":[[1.02,5001.99],[9.6,27.24],[13.5,6.93]],"atl":[[17,4.29],[24,20],[19,2.98]],"bdatb":[[5,10.5,4.21],[8,8.8,2.81],[9,8.6,1.84],[7,9.6,27.24],[1,13.5,6.93],[6,10,15.01]],"bdatl":[[7,36,6.5],[8,42,2.44],[9,1000,5.78],[6,24,20.25],[3,19,2.98],[5,22,12.19]],"id":44331354}],"con":true,"tv":2554.5}]}
{"op":"mcm","clk":"AKBLAIxBAIxC","pt":1650392731615,"mc":[{"id":"1.197931751","rc":[{"atb":[[2.66,7.39],[2.62,24.49],[2.38,0]],"atl":[[2.78,8.74]],"bdatb":[[2,2.66,7.39],[4,2.62,24.49],[7,2.52,15.96],[8,2.5,2.38],[9,2.48,101.1]],"bdatl":[[1,2.78,8.74],[6,2.88,28.5],[7,2.9,4.5],[9,2.94,2.4]],"id":42930960},{"atb":[[4.2,18.85],[4.3,10.86]],"atl":[[5.2,0]],"bdatb":[[6,3.9,3.55],[8,3.8,5.91],[9,3.75,4.19],[1,4.3,10.86],[2,4.2,18.85],[7,3.85,10.98]],"bdatl":[[7,5.2,1.02],[8,5.4,9.09],[9,5.5,23],[4,4.9,11.27],[5,5,5.21],[6,5.1,2.39]],"id":40095374},{"atb":[[2.56,24.77],[2.66,17.5]],"atl":[[2.78,0.01],[2.84,17.74],[2.82,2.2],[2.8,2.16]],"trd":[[2.78,3.44]],"bdatb":[[7,2.56,24.77],[4,2.66,17.5],[5,2.64,27.84],[6,2.6,25.75],[8,2.54,7.31],[9,2.52,109.38],[0,2.74,12.59]],"bdatl":[[0,2.8,2.17],[1,2.82,2.2],[2,2.84,17.74],[3,2.86,14.6],[4,2.88,30.46],[5,2.9,11.63],[6,2.92,2.78],[7,2.94,4.62],[8,2.96,15.57],[9,2.98,43.73]],"ltp":2.78,"tv":218.59,"id":36276560},{"atb":[[1.23,109.87],[1.22,22.62],[1.24,0],[1.09,729]],"atl":[[1.31,11.79],[1.27,27.81],[1000,5]],"trd":[[1.27,304.9]],"bdatb":[[1,1.23,109.87],[2,1.22,22.64],[3,1.21,186.71],[5,1.19,279.84],[6,1.18,11.33],[4,1.2,14.58],[7,1.17,244.89],[8,1.16,1660.66],[9,1.15,47.18]],"bdatl":[[4,1.31,17.17],[5,1.32,5.64],[6,1.33,19.14],[9,1.36,19.29],[0,1.27,27.81],[7,1.34,5.04],[8,1.35,132.2],[2,1.29,76.19],[3,1.3,39.66]],"ltp":1.27,"tv":1873.29,"id":39823721},{"atb":[[12.5,8.78],[11,0],[13.5,1.45]],"bdatb":[[3,12.5,8.78],[5,10.5,4.22],[6,10,12.71],[7,9.6,28.79],[8,9,1.09],[9,8.6,1.64],[1,13.5,1.45]],"bdatl":[[9,1000,5.47],[8,42,2.44],[0,17,4.29],[5,22,12.46],[6,24,20.22],[7,36,6.33]],"id":44331354},{"bdatb":[[6,4.7,1.29],[7,4.6,1.29],[8,4.5,12.65],[9,4.4,1.86]],"bdatl":[[7,7.2,17.3],[8,7.4,7.9],[9,7.6,2.7],[4,6.2,7.73],[5,6.4,3.74],[6,6.6,1.87]],"id":37947503}],"con":true,"tv":2558.12}]}
{"op":"mcm","clk":"ALNMAKFCAJ1D","pt":1650392732617,"mc":[{"id":"1.197931751","rc":[{"atb":[[2.62,24.49],[2.68,2.25]],"bdatb":[[4,2.62,28.27],[1,2.68,2.25],[7,2.52,13.55],[8,2.5,2.48],[9,2.48,103.34]],"id":42930960},{"atl":[[5.4,0],[5.3,9.3]],"bdatb":[[6,3.9,2],[8,3.8,7.5]],"bdatl":[[8,5.3,9.3],[5,5,5.21],[6,5.1,2.39],[7,5.2,1.02],[9,5.5,23]],"id":40095374},{"atb":[[2.68,12.18]],"atl":[[2.86,15.47],[2.8,0],[2.78,0]],"bdatb":[[3,2.68,12.18]],"bdatl":[[2,2.86,15.47],[7,2.96,15.57],[8,2.98,43.73],[9,3.05,2.31],[0,2.82,2.2],[1,2.84,17.74],[3,2.88,30.46],[4,2.9,11.63],[5,2.92,2.78],[6,2.94,4.62]],"id":36276560},{"atl":[[1000,6],[1.28,155.27]],"bdatb":[[9,1.15,47.18],[5,1.19,274.74],[6,1.18,16.47],[2,1.22,22.62],[3,1.21,186.73]],"bdatl":[[3,1.3,39.66],[4,1.31,17.17],[5,1.32,5.64],[6,1.33,19.14],[7,1.34,5.04],[8,1.35,121.08],[1,1.28,155.27],[9,1.36,30.33]],"id":39823721},{"atb":[[13,11.58]],"bdatb":[[2,13,11.58],[5,10.5,3.67],[6,10,13.26],[7,9.6,28.81]],"bdatl":[[5,22,12.46],[6,24,20.22],[7,36,6.33],[9,1000,5.47]],"id":44331354},{"bdatb":[[6,4.6,2.61],[7,4.5,12.65],[8,4.4,1.86],[9,4.3,61.74]],"bdatl":[[4,6.2,7.73],[5,6.4,3.74],[6,6.6,1.87],[7,7.2,17.3],[8,7.4,7.9],[9,7.6,2.7]],"id":37947503}],"con":true}]}
{"op":"mcm","clk":"AMhNAM9DAJtE","pt":1650392733620,"mc":[{"id":"1.197931751","rc":[{"atb":[[2.64,33.63],[1.02,5000],[1.01,5642.04],[2.68,15.1]],"bdatb":[[9,2.48,112.56],[1,2.68,15.1],[4,2.62,24.49]],"id":42930960},{"atb":[[4.4,3.42],[1.01,5642.04],[4.3,5.8],[4.2,22.51]],"atl":[[4.7,25.9],[4.6,24.28],[4.5,7.75]],"bdatb":[[1,4.3,5.8],[2,4.2,22.51]],"bdatl":[[0,4.5,7.75],[5,5,7.65],[6,5.2,1.02],[7,5.3,9.3],[8,5.5,26.08],[9,5.6,22.46]],"id":40095374},{"atb":[[2.76,6.81],[2.68,5.21],[2.74,6.84],[1.02,5001.48],[1.01,5642.04],[2.7,11.79],[2.72,9.52]],"bdatb":[[8,2.54,16.31],[9,2.52,103.38],[1,2.72,9.52],[2,2.7,11.79]],"bdatl":[[7,2.96,17.31],[8,2.98,42],[9,3,2.35]],"id":36276560},{"atb":[[1.02,5001.55],[1.01,5642.04]],"bdatb":[[6,4.6,5.89],[7,4.5,11.01],[8,4.3,61.84],[9,4.2,13.68]],"bdatl":[[6,7.2,19.49],[7,7.4,6.91],[8,7.8,4.61],[4,6.2,8.56],[5,6.4,4.09],[9,8,4.08]],"id":37947503},{"atb":[[1.02,0],[1.01,5654.32]],"atl":[[1000,5.09]],"bdatb":[[3,1.21,199.21],[4,1.2,8.46],[5,1.19,268.23],[6,1.18,35.83],[7,1.17,225.36],[9,1.15,47.57]],"bdatl":[[5,1.32,13.26],[6,1.33,6.31],[7,1.34,11.64],[9,1.36,15.94],[3,1.3,45.09],[4,1.31,12.08],[8,1.35,129.19]],"id":39823721},{"atb":[[1.02,5000],[1.01,5642.04]],"bdatb":[[6,10,15.55],[7,9.6,27.24],[8,8.6,1.91],[9,8.2,5.77]],"bdatl":[[9,1000,5.57],[5,22,12.7],[6,24,20],[7,36,6.36]],"id":44331354}],"con":true}]}
{"op":"mcm","clk":"AN1OANZEAKdF","pt":1650392734622,"mc":[{"id":"1.197931751","rc":[{"atb":[[2.68,17.26],[2.66,4.21]],"atl":[[2.74,2.03],[2.78,29.19],[2.9,11.33]],"bdatb":[[1,2.68,17.26],[2,2.66,4.21],[3,2.64,33.63]],"bdatl":[[0,2.74,2.03],[1,2.76,9.82],[2,2.78,29.19],[3,2.8,17.25],[4,2.82,4.41],[5,2.84,2.8],[6,2.86,9.97],[7,2.88,19.9],[8,2.9,12.63],[9,2.92,3.55]],"id":42930960},{"atb":[[4.1,22]],"atl":[[1000,8.58],[4.7,30.11]],"bdatb":[[6,3.9,3.43],[7,3.85,9.53],[8,3.8,8.97],[9,3.75,2.7],[3,4.1,22],[0,4.4,3.42]],"bdatl":[[4,4.9,11.4],[5,5,7.06],[6,5.2,1.03],[7,5.3,9.3],[8,5.5,27.13],[9,5.6,22.61],[2,4.7,30.11],[1,4.6,24.28],[3,4.8,11.33]],"id":40095374},{"atb":[[2.76,6.81],[2.72,14.66]],"atl":[[2.96,20.23],[2.86,15.47],[2.84,20.3]],"bdatb":[[0,2.76,6.81],[8,2.56,26.94],[9,2.54,14.12],[2,2.72,14.66],[1,2.74,6.84],[3,2.7,11.79],[4,2.68,5.21],[5,2.66,17.5],[6,2.64,27.84],[7,2.6,25.75]],"bdatl":[[7,2.96,20.23],[2,2.86,15.47],[1,2.84,20.3],[6,2.94,4.34],[8,2.98,42.28],[9,3,6.08]],"id":36276560},{"atl":[[5.9,3.36]],"bdatb":[[6,4.7,1.18],[7,4.6,5.89],[8,4.5,9.78],[9,4.3,64.74]],"bdatl":[[3,5.9,3.75],[4,6,11.72],[5,6.2,4.7],[6,6.4,6.32],[7,7.2,17.36],[8,7.4,9.31],[9,7.6,1.47]],"id":37947503},{"atb":[[1.22,24.68],[1.07,251]],"atl":[[1.28,155.36],[1000,5],[1.34,14.78]],"bdatb":[[3,1.21,203.81],[4,1.2,3.82],[8,1.16,1666.1],[9,1.15,18.64],[5,1.19,281.92],[6,1.18,51.69],[7,1.17,224.86],[2,1.22,24.68]],"bdatl":[[1,1.28,157.14],[4,1.31,14.41],[5,1.32,1.85],[6,1.33,20.31],[7,1.34,22.56],[8,1.35,126.91],[9,1.36,8.31],[2,1.29,73.78],[3,1.3,45.73]],"id":39823721},{"bdatb":[[9,8.4,5.95],[8,8.6,3.35]],"bdatl":[[6,24,20.12],[7,36,6.7],[8,42,2.44],[9,1000,5.61],[4,20,6.71],[5,22,11.47]],"id":44331354}],"con":true}]}
{"op":"mcm","clk":"AP9PAOZFAL5G","pt":1650392735623,"mc":[{"id":"1.197931751","rc":[{"atb":[[2.62,9.76],[2.58,0],[2.6,57.82],[2.54,6.88],[2.64,7.9],[2.68,0],[2.66,0],[2.7,0]],"atl":[[2.68,2.41],[2.78,32.51],[2.74,4.03],[2.82,4.41],[2.76,12.4],[2.72,1.67],[2.7,18.44]],"trd":[[2.68,124.46],[2.66,29.42],[2.7,33.88]],"bdatb":[[0,2.64,7.9],[2,2.6,75.98],[1,2.62,24.49],[3,2.58,18.38],[4,2.52,13.55],[5,2.5,2.48],[6,2.48,112.56],[7,2.42,1.02],[8,2.4,11.04],[9,2.38,12.17]],"bdatl":[[0,2.68,2.41],[1,2.7,18.44],[2,2.72,1.67],[3,2.74,4.03],[4,2.76,12.4],[5,2.78,32.51],[6,2.8,17.31],[7,2.82,4.41],[8,2.84,2.75],[9,2.86,7.54]],"ltp":2.66,"tv":416.1,"id":42930960},{"atb":[[4.4,1.84]],"atl":[[4.9,10.03],[1000,7]],"trd":[[4.4,11.16]],"bdatb":[[4,4,21.4],[5,3.95,9.5],[8,3.8,6.98],[9,3.75,3.21],[6,3.9,2],[7,3.85,9.89],[0,4.4,1.84]],"bdatl":[[4,4.9,10.06],[5,5,4.42],[8,5.3,10.33],[6,5.1,3.64],[7,5.2,2.55],[9,5.5,23],[3,4.8,10.86]],"ltp":4.4,"tv":76.46,"id":40095374},{"atb":[[2.56,6.14],[2.7,17.47],[2.52,99],[2.74,9.46],[2.72,16.87]],"bdatb":[[7,2.62,2.47],[8,2.6,36.68],[9,2.56,6.32],[3,2.7,17.47],[1,2.74,9.46],[2,2.72,16.87]],"bdatl":[[5,2.92,2.06],[7,2.98,42.71],[9,3.05,4.18],[6,2.96,20.23],[8,3,1.94]],"id":36276560},{"atb":[[5.1,29.77]],"bdatb":[[4,4.9,11.04],[5,4.8,5.83],[6,4.7,6.04],[7,4.5,14.04],[8,4.4,1.73],[9,4.3,64.73],[2,5.1,29.77]],"bdatl":[[4,6,9.62],[5,6.2,4.91],[9,7.2,17.93],[7,6.6,1.93],[8,6.8,1.79],[6,6.4,3.84],[3,5.9,3.36]],"id":37947503},{"atb":[[1.26,0.13],[1.07,250]],"bdatb":[[0,1.25,31.65],[1,1.23,114.92],[2,1.22,48.17],[3,1.21,194.47],[4,1.2,8.33],[5,1.19,285.47],[6,1.18,23.54],[7,1.17,256.23],[8,1.16,1658.49],[9,1.15,28.65]],"bdatl":[[4,1.31,21.53],[5,1.32,9.23],[7,1.35,110.49],[8,1.36,27.17],[2,1.29,63.88],[3,1.3,37.29],[6,1.34,40.14],[9,1.37,11.53],[1,1.28,155.36]],"id":39823721},{"atl":[[18,5.02]],"bdatb":[[4,11.5,3.64],[5,11,2.58],[8,9.6,29.42],[9,8.8,1.73],[6,10.5,3.12],[7,10,12.68]],"bdatl":[[5,22,11.44],[6,24,20.33],[7,36,6.76],[9,1000,5.39],[8,42,2.47],[4,20,5.94],[2,18,5.02]],"id":44331354}],"con":true,"tv":2615.97}]}
{"op":"mcm","clk":"AI5RAIBHAOZH","pt":1650392736626,"mc":[{"id":"1.197931751","rc":[{"atb":[[2.62,7.71],[2.56,18.63],[2.54,0]],"atl":[[2.76,21.88],[2.88,15.67]],"bdatb":[[1,2.62,7.71],[3,2.56,18.63],[4,2.52,13.55],[5,2.5,2.48],[6,2.48,112.56],[7,2.42,1.02],[8,2.4,11.04],[9,2.38,12.17],[2,2.6,57.82]],"bdatl":[[4,2.76,21.88]],"id":42930960},{"atb":[[2.7,20.67],[2.68,22.5]],"bdatb":[[3,2.7,20.67],[4,2.68,22.5]],"id":36276560},{"atb":[[1.24,0],[1.23,111.89],[1.22,156.73]],"atl":[[1.28,143.6]],"bdatb":[[1,1.23,116.94],[2,1.22,180.22],[3,1.21,194.47],[4,1.2,8.33],[5,1.19,287.17],[6,1.18,21.82],[7,1.17,256.23],[8,1.16,1675.58],[9,1.15,11.41]],"bdatl":[[6,1.34,23.52],[7,1.35,126.99],[9,1.37,13.76],[1,1.28,143.6]],"id":39823721},{"atb":[[13.5,1.45],[13,15.36]],"bdatb":[[1,13.5,1.45],[2,13,15.36]],"bdatl":[[9,1000,5.24]],"id":44331354},{"bdatl":[[9,5.5,23]],"id":40095374}],"con":true}]}
{"op":"mcm","clk":"AKJSAIJIAP1I","pt":1650392737627,"mc":[{"id":"1.197931751","rc":[{"atb":[[2.56,29.31],[2.6,88.77],[2.32,59.02]],"atl":[[2.78,24.5],[2.76,16.47],[2.68,1.7],[3.9,21.22],[4.3,0],[2.72,0],[2.74,9.89]],"bdatb":[[6,2.44,1.97],[7,2.42,10.57],[8,2.4,2.34],[9,2.38,1.9],[4,2.52,13.55],[2,2.6,88.77],[5,2.48,105.84]],"bdatl":[[3,2.76,16.53],[6,2.82,5.16],[7,2.84,2.5],[8,2.86,8.69],[9,2.88,16.86],[4,2.78,27.82],[0,2.68,1.7],[2,2.74,9.89],[5,2.8,17.25]],"id":42930960},{"atb":[[4.4,0]],"atl":[[4.4,0],[4.6,24.28],[4.9,7.58],[4.7,30.11],[5.2,9.52],[5.3,0],[4.5,2.67]],"trd":[[4.4,14.84]],"bdatb":[[4,3.95,3.26],[5,3.9,4.07],[6,3.85,16.01],[3,4,20.93],[0,4.3,5.8],[1,4.2,22.51],[2,4.1,22],[7,3.8,3.48],[8,3.75,2],[9,3.7,76.9]],"bdatl":[[2,4.7,30.15],[3,4.8,11.3],[4,4.9,9.72],[5,5,4.68],[6,5.2,14.03],[7,5.5,23.27],[8,5.6,22.36],[9,5.7,1.02],[0,4.5,2.67],[1,4.6,24.28]],"tv":80.14,"id":40095374},{"atb":[[2.6,7.59],[2.72,16.87],[2.8,1.32],[2.74,14.64],[2.68,22.5],[2.78,3.27],[1.95,105.26],[1.9,0],[2.76,11.49]],"atl":[[2.9,2],[2.86,3.07],[2.88,15.2],[2.84,0],[2.8,0],[2.82,0]],"trd":[[2.8,2]],"bdatb":[[0,2.8,1.32],[4,2.72,16.87],[6,2.68,22.5],[8,2.64,29.57],[9,2.62,2.85],[3,2.74,14.64],[1,2.78,3.27],[2,2.76,11.49],[5,2.7,20.67],[7,2.66,17.5]],"bdatl":[[0,2.86,3.07],[1,2.88,15.2],[2,2.9,6.94],[4,2.96,20.29],[6,3.05,6.8],[8,3.15,7.12],[3,2.92,2],[5,2.98,42],[7,3.1,1.32],[9,3.2,42.25]],"ltp":2.8,"tv":220.59,"id":36276560},{"atb":[[4.9,9.78],[5.4,3]],"atl":[[6.2,4.57],[5.6,4.57],[5.7,18.94],[5.5,3.06]],"bdatb":[[7,4.7,1.87],[8,4.5,17.99],[9,4.4,1.03],[5,4.9,9.78],[6,4.8,5.77],[0,5.4,3],[1,5.3,6.44],[2,5.2,6.33],[3,5.1,29.77],[4,5,13.95]],"bdatl":[[5,6,9.62],[6,6.2,4.91],[7,6.4,4.57],[8,6.6,1.84],[9,7,2.09],[1,5.6,4.57],[0,5.5,3.06],[2,5.7,18.94],[3,5.8,11.83],[4,5.9,3.36]],"id":37947503},{"atb":[[1.26,0.13],[1.07,250],[1.23,95.69]],"atl":[[1000,5.13],[1.27,37.81]],"trd":[[1.26,333.56]],"bdatb":[[0,1.25,31.65],[3,1.21,180.78],[4,1.2,33.26],[5,1.19,265.39],[6,1.18,7.43],[7,1.17,250.13],[8,1.16,1664.94],[9,1.15,59.64],[1,1.23,95.69],[2,1.22,166.58]],"bdatl":[[3,1.3,41.77],[4,1.31,15.34],[5,1.32,15.29],[9,1.36,8.12],[7,1.34,39.33],[8,1.35,119.86],[1,1.28,143.6],[2,1.29,65.65],[6,1.33,6.97],[0,1.27,37.81]],"ltp":1.26,"tv":1873.55,"id":39823721},{"atb":[[13.5,3.78]],"bdatb":[[5,10.5,3.77],[6,10,15.72],[8,8.6,2.82],[9,8,1.07],[3,12.5,8.78],[4,11.5,3.47],[7,9.6,27.82]],"bdatl":[[3,19,2.99],[5,22,11.59],[6,24,20.4],[7,36,6.76],[9,1000,5.34],[4,20,5.94],[8,42,2.44]],"id":44331354}],"con":true,"tv":2621.91}]}
{"op":"mcm","clk":"ALZTAJdJAKVK","pt":1650392738627,"mc":[{"id":"1.197931751","rc":[{"atb":[[2.28,170.17],[2.68,4.93],[2.6,46.68],[2.64,14.04],[2.54,7.88]],"atl":[[2.7,7.26],[2.76,19.3],[2.72,2.64],[2.8,11.88],[2.68,0]],"trd":[[2.7,51.6],[2.68,155.42]],"bdatb":[[0,2.68,4.93],[1,2.64,14.04],[3,2.6,46.68],[5,2.54,7.88],[6,2.52,13.55],[7,2.5,1.14],[8,2.48,104.7],[9,2.44,1.97],[2,2.62,7.71],[4,2.56,29.31]],"bdatl":[[0,2.7,7.26],[1,2.72,2.64],[2,2.74,9.89],[3,2.76,19.3],[4,2.78,24.5],[5,2.8,12.7],[6,2.82,4.6],[7,2.84,3.3],[8,2.86,8.69],[9,2.88,15.88]],"ltp":2.7,"tv":464.78,"id":42930960},{"atb":[[4.2,14.91],[4.1,31.23]],"atl":[[5.4,22.73]],"bdatb":[[6,3.85,10.08],[7,3.8,7.53],[8,3.75,2.48],[9,3.7,76.27],[3,4,20.5],[4,3.95,3.75],[1,4.2,14.91],[2,4.1,31.23],[5,3.9,4]],"bdatl":[[3,4.8,12.25],[4,4.9,8.07],[5,5,4.12],[6,5.1,4.55],[7,5.2,9.52],[8,5.4,24.74],[9,5.5,23.01],[1,4.6,24.78],[2,4.7,31.01]],"id":40095374},{"atb":[[2.74,16.66],[2.76,18.58],[2.72,12.02],[2.82,1]],"atl":[[2.88,10.97],[2.92,5],[2.84,1],[2.86,2.16]],"bdatb":[[9,2.64,27.84],[4,2.74,16.66],[0,2.82,1],[1,2.8,1.32],[2,2.78,3.27],[3,2.76,18.58],[5,2.72,12.02],[6,2.7,20.67],[7,2.68,22.5],[8,2.66,17.5]],"bdatl":[[6,2.98,45.67],[7,3.05,3.85],[8,3.1,4.66],[9,3.15,2.48],[5,2.96,21.01],[2,2.88,10.97],[4,2.92,5],[0,2.84,1],[1,2.86,2.16],[3,2.9,2]],"id":36276560},{"atb":[[1.23,95.69],[1.26,0]],"atl":[[1000,5.13],[1.27,37.94]],"trd":[[1.26,333.82]],"bdatb":[[4,1.2,21.83],[5,1.19,254.86],[6,1.18,12.36],[7,1.17,265.17],[8,1.16,1667.38],[9,1.15,50.58],[1,1.23,95.69],[2,1.22,166.58],[0,1.25,31.52]],"bdatl":[[2,1.29,71.94],[3,1.3,33.36],[4,1.31,18.46],[5,1.32,19.22],[1,1.28,145.81],[6,1.33,12.47],[7,1.34,26.95],[9,1.36,41.02],[0,1.27,37.94],[8,1.35,96.24]],"tv":1873.81,"id":39823721},{"atb":[[13,11.58]],"bdatb":[[6,10,13.44],[7,9.6,27.97],[8,9.4,1.47],[9,8.4,1.52],[4,11.5,3.32],[5,10.5,3.93],[2,13,11.58],[1,13.5,3.78]],"bdatl":[[5,22,11.75],[6,24,20.1],[7,36,6.7],[9,1000,5.53],[3,19,3.13],[4,20,6.13]],"id":44331354},{"bdatb":[[8,4.5,13.22],[9,4.4,4.46],[6,4.8,5.77],[7,4.7,1.92]],"bdatl":[[6,6.2,6.24],[7,6.4,3.3],[8,6.6,1.41],[9,6.8,2.13],[4,5.9,3.75],[5,6,9.68]],"id":37947503}],"con":true,"tv":2670.85}]}
{"op":"mcm","clk":"ANVUAIpKAKhL","pt":1650392739628,"mc":[{"id":"1.197931751","rc":[{"atb":[[2.54,0],[2.62,33.05],[2.58,18.38]],"atl":[[2.7,1.24]],"trd":[[2.7,63.64]],"bdatb":[[6,2.54,1.12],[7,2.52,13.74],[8,2.5,3.49],[9,2.48,101],[2,2.62,33.05],[4,2.58,18.38],[5,2.56,29.31]],"bdatl":[[0,2.7,1.24],[5,2.8,11.88],[6,2.82,4.41],[7,2.84,2.8],[8,2.86,8.91],[9,2.88,15.67]],"tv":476.82,"id":42930960},{"atb":[[4.1,21.85]],"atl":[[6,0]],"bdatb":[[2,4.1,22.55],[3,4,19.91],[4,3.95,2.2],[5,3.9,3.84],[6,3.85,11.02],[7,3.8,7.05],[8,3.75,2],[9,3.7,75.6]],"bdatl":[[1,4.6,24.28],[2,4.7,30.11],[3,4.8,13.36],[4,4.9,7.58],[5,5,4.24],[6,5.1,1.66],[7,5.2,10.23],[8,5.3,2.8],[9,5.4,24.59]],"id":40095374},{"atb":[[2.7,30.83],[2.82,7.69],[2.76,11.49],[2.78,7.61]],"atl":[[2.86,0],[2.96,29.35]],"bdatb":[[0,2.82,7.69],[6,2.7,30.83],[7,2.68,23.73],[9,2.64,27.86],[3,2.76,11.49],[2,2.78,7.61]],"bdatl":[[1,2.88,10.97],[2,2.9,2],[3,2.92,5],[4,2.96,29.35],[5,2.98,42],[6,3.05,3.95],[7,3.15,6.59],[8,3.2,47.02],[9,3.25,3.1]],"id":36276560},{"atb":[[5.2,13.24],[5,9.31],[5.4,7.45]],"atl":[[5.6,2.43],[5.7,16.93],[5.5,0.6]],"trd":[[5.5,4.92]],"bdatb":[[5,4.9,10.35],[6,4.8,5.88],[7,4.7,1.53],[8,4.5,14.97],[9,4.3,62.35],[4,5,9.31],[0,5.4,7.45]],"bdatl":[[0,5.6,3.03],[3,5.9,3.36],[4,6,9.59],[5,6.2,6.5],[6,6.4,2.93],[7,6.8,1.9],[8,7.2,20],[9,7.4,6.83],[1,5.7,16.93],[2,5.8,11.83]],"ltp":5.5,"tv":36.45,"id":37947503},{"atb":[[1.24,9.68],[1.07,250.13],[1.22,10.5],[1.25,0]],"atl":[[1.26,28.65],[1.27,143.63],[1000,5]],"trd":[[1.25,448.55]],"bdatb":[[0,1.24,9.68],[2,1.22,13.2],[3,1.21,182.77],[4,1.2,7.31],[5,1.19,267.41],[6,1.18,14.58],[7,1.17,264.06],[8,1.16,1666.35],[9,1.15,36.13]],"bdatl":[[0,1.26,28.65],[1,1.27,143.63],[2,1.28,153.93],[3,1.29,70.45],[4,1.3,33.9],[5,1.31,23.11],[6,1.32,25.84],[7,1.33,2.95],[8,1.34,21.73],[9,1.35,119.92]],"ltp":1.25,"tv":1936.85,"id":39823721},{"atb":[[13.5,1.45]],"bdatb":[[3,12.5,9.01],[4,11.5,3.11],[5,10.5,3.88],[6,10,13.17],[7,9.8,1.79],[8,9.6,27.41],[9,8.6,2.17],[1,13.5,1.45]],"bdatl":[[3,19,2.98],[4,20,5.94],[5,22,12],[6,24,20],[7,36,6.37],[8,42,2.81],[9,1000,5.78]],"id":44331354}],"con":true,"tv":2750.85}]}
{"op":"mcm","clk":"APdVAJ1LAMhM","pt":1650392740631,"mc":[{"id":"1.197931751","rc":[{"atb":[[2.24,158.36]],"atl":[[2.78,4.05],[2.76,21.68],[2.72,0]],"bdatb":[[6,2.54,2.09],[7,2.52,14.84],[8,2.48,103.04],[9,2.46,1.46],[4,2.58,19.49],[5,2.56,29.49]],"bdatl":[[3,2.78,4.05],[7,2.86,8.91],[8,2.88,15.67],[1,2.74,9.89],[2,2.76,21.68],[4,2.8,11.88],[5,2.82,4.41],[6,2.84,2.8],[9,2.9,11.33]],"id":42930960},{"atl":[[5.6,32.61],[4.5,7.74]],"bdatb":[[4,3.95,4.34],[6,3.85,10.68],[1,4.2,15.59],[2,4.1,21.97],[3,4,19.8],[5,3.9,2],[7,3.8,2.95],[8,3.75,4.66],[9,3.7,77.89]],"bdatl":[[6,5.1,1.66],[7,5.2,10.23],[8,5.3,2.8],[9,5.4,24.59],[3,4.8,13.36],[4,4.9,7.58],[5,5,4.24],[0,4.5,7.74]],"id":40095374},{"atb":[[2.82,7.69],[2.74,14.64]],"atl":[[2.88,2],[2.92,13.92],[2.9,4.34]],"bdatb":[[0,2.82,7.69],[4,2.74,14.64],[8,2.66,20.69],[5,2.72,13.23],[6,2.7,30.85],[7,2.68,22.5],[9,2.64,27.84]],"bdatl":[[1,2.88,2],[3,2.92,13.92],[2,2.9,4.34]],"id":36276560},{"atl":[[5.7,8.96],[5.8,9.81]],"bdatb":[[6,4.8,6.87],[7,4.6,2.72],[8,4.5,12.33],[4,5,9.88],[5,4.9,9.88],[9,4.4,1.27],[2,5.2,13.24]],"bdatl":[[1,5.7,8.96],[8,7.2,20],[9,7.4,6.82],[2,5.8,9.81],[7,6.8,1.9],[5,6.2,6.5],[6,6.4,2.93]],"id":37947503},{"atb":[[1.21,42.78],[1.22,26.7],[1.07,250]],"atl":[[1000,6],[1.29,44.74],[1.26,167.25],[1.3,31.06],[1.25,9.47]],"trd":[[1.25,448.81]],"bdatb":[[7,1.17,238.33],[8,1.16,1671.76],[9,1.15,17.24],[3,1.21,42.82],[6,1.18,26.59],[2,1.22,29.41],[4,1.2,13.29],[5,1.19,261.37]],"bdatl":[[1,1.26,167.25],[4,1.29,51.32],[5,1.3,33.9],[6,1.31,23.1],[7,1.32,25.84],[8,1.33,2.97],[9,1.34,21.72],[0,1.25,9.47],[3,1.28,153.93],[2,1.27,143.63]],"tv":1937.11,"id":39823721},{"atl":[[17,1.21]],"bdatb":[[9,8.4,4.7],[5,10.5,3.85],[6,10,13.61],[7,9.6,28.64],[8,9,3],[1,13.5,1.66],[3,12.5,8.82],[4,11.5,3.07]],"bdatl":[[7,36,6.37],[8,42,2.81],[9,1000,5.84],[5,22,12],[6,24,20],[0,17,1.21]],"id":44331354}],"con":true,"tv":2751.11}]}
{"op":"mcm","clk":"AIpXAJBMANpN","pt":1650392741633,"mc":[{"id":"1.197931751","rc":[{"atl":[[2.72,2.42],[2.76,25.06]],"bdatb":[[4,2.58,18.38],[5,2.56,29.31],[6,2.52,14.86],[7,2.5,5.44],[8,2.48,106.11],[9,2.44,1.27]],"bdatl":[[1,2.72,2.42],[2,2.74,9.89],[3,2.76,25.06],[4,2.78,4.05],[5,2.8,11.88],[6,2.82,4.41],[7,2.84,2],[8,2.86,5.51],[9,2.88,15.67]],"id":42930960},{"atb":[[4.1,16.55]],"atl":[[5.8,52.08]],"bdatb":[[1,4.2,14.91],[2,4.1,16.55],[3,4,20.63],[4,3.95,3.86],[5,3.9,3.79],[6,3.85,10.3],[7,3.8,4.39],[8,3.75,2.83],[9,3.7,75.83]],"bdatl":[[4,4.9,10.27],[5,5,4],[6,5.1,3.48],[7,5.2,11.3],[8,5.3,1.15],[9,5.4,29.75],[3,4.8,10.86],[2,4.7,30.11]],"id":40095374},{"atb":[[2.64,10.13],[2.78,19.16],[2.84,0],[2.74,12.02],[2.82,9.66]],"atl":[[2.96,86.87],[2.9,2],[2.92,2.27],[2.94,0.81],[2.88,0],[2.84,0]],"trd":[[2.84,2]],"bdatb":[[3,2.76,11.49],[4,2.74,12.02],[5,2.72,13.23],[6,2.7,30.85],[7,2.68,24.96],[8,2.66,20.12],[9,2.64,11.49],[2,2.78,19.16],[0,2.82,9.66],[1,2.8,1.32]],"bdatl":[[1,2.96,77.86],[2,2.98,42],[3,3.1,4.26],[4,3.15,6.2],[5,3.2,47.02],[6,3.25,3.1],[7,3.3,11.3],[0,2.92,11.19],[8,3.4,4.88],[9,3.45,9.44]],"ltp":2.84,"tv":222.59,"id":36276560},{"atb":[[5.3,8.64]],"bdatb":[[4,5,9.31],[5,4.9,9.78],[6,4.8,6.47],[7,4.7,3.65],[8,4.6,1.97],[9,4.5,10.46],[1,5.3,8.64]],"bdatl":[[6,6.4,4.99],[7,6.6,1.78],[8,7.2,20.54],[9,7.4,10.9],[5,6.2,4.57],[4,6,9.59]],"id":37947503},{"atb":[[1.08,51],[1.22,26.7],[1.23,84.7],[1.21,44.85],[1.24,0],[1.2,147.25]],"atl":[[1000,5],[1.24,0],[1.27,173.28],[1.28,114.46],[1.25,23.65],[1.26,167.38]],"bdatb":[[2,1.21,47.58],[3,1.2,158.58],[4,1.19,265.06],[7,1.16,1658.04],[8,1.15,18.84],[9,1.14,728.87],[0,1.23,84.7],[1,1.22,26.7],[5,1.18,1.86],[6,1.17,273.12]],"bdatl":[[0,1.25,23.65],[1,1.26,167.38],[2,1.27,173.28],[3,1.28,124.78],[4,1.29,53.83],[5,1.3,42.81],[6,1.31,16.42],[7,1.32,30.11],[8,1.33,1.16],[9,1.34,35.94]],"id":39823721},{"atb":[[1.02,5000],[14.5,3.19],[13,14.17]],"bdatb":[[3,13,14.17],[5,11.5,3.35],[6,10.5,5.55],[7,10,12.68],[8,9.6,27.79],[9,8.8,3.76],[0,14.5,3.19],[1,14,10.08],[2,13.5,1.45],[4,12.5,8.78]],"bdatl":[[5,22,11.43],[7,34,1.02],[8,36,6.01],[9,42,2.67],[4,20,5.94],[6,24,20]],"id":44331354}],"con":true,"tv":2753.11}]}
{"op":"mcm","clk":"AJlYAJBNAOlO","pt":1650392742634,"mc":[{"id":"1.197931751","rc":[{"atb":[[1.84,0],[2.06,0],[2.62,51.57]],"bdatb":[[5,2.56,30.66],[6,2.52,13.9],[7,2.48,104.26],[8,2.46,4.04],[9,2.44,4.37],[2,2.62,51.57],[3,2.6,46.68],[4,2.58,18.38]],"id":42930960},{"atb":[[2.96,30.77],[2.5,0]],"bdatb":[[2,4.1,17.4],[3,4,19.79],[4,3.95,2.78],[5,3.9,2.05],[7,3.8,5.27],[8,3.75,4.85],[6,3.85,10.39],[1,4.2,14.91],[9,3.7,75.19]],"bdatl":[[7,5.2,10.14],[8,5.4,23.85],[9,5.5,24.52]],"id":40095374},{"atb":[[2.08,0],[1.86,0],[2.74,28.71]],"atl":[[2.98,44.87],[2.96,45.63],[2.9,2],[2.94,3.38],[2.88,0]],"bdatb":[[7,2.68,22.82],[8,2.66,18.11],[9,2.64,11.63],[5,2.72,12.07],[3,2.76,11.49],[4,2.74,29.94],[6,2.7,30.83]],"bdatl":[[0,2.9,2],[1,2.92,2.27],[2,2.94,3.38],[3,2.96,45.63],[4,2.98,42],[5,3.1,4.26],[6,3.15,6.2],[7,3.2,45.14],[8,3.25,1.85],[9,3.3,3.05]],"id":36276560},{"atb":[[3.4,0],[2.82,0]],"atl":[[5.8,13.83],[5.7,6.96],[5.5,0],[5.6,1.07]],"trd":[[5.5,6.12],[5.6,2.72]],"bdatb":[[6,4.8,6.26],[7,4.6,3.58],[8,4.5,11.66],[9,4.3,58.92],[5,4.9,9.8],[3,5.1,29.77],[4,5,9.98]],"bdatl":[[8,7.2,18.31],[9,7.4,6.32],[2,5.8,13.83],[1,5.7,6.96],[0,5.6,1.07]],"ltp":5.6,"tv":40.37,"id":37947503},{"atb":[[1.13,0],[1.22,48.26],[1.16,4.28],[1.23,27.8],[1.19,253.74],[1.08,50]],"atl":[[1000,6],[1.24,2.8]],"trd":[[1.24,332.88]],"bdatb":[[2,1.21,47.62],[3,1.2,149.45],[4,1.19,267.51],[5,1.18,10.57],[9,1.14,723.33],[0,1.23,27.8],[7,1.16,1657.49],[8,1.15,24.55],[6,1.17,269.21],[1,1.22,36.88]],"bdatl":[[0,1.24,2.8],[1,1.25,23.65],[2,1.26,167.38],[3,1.27,173.28],[4,1.28,124.78],[5,1.29,53.83],[6,1.3,42.81],[7,1.31,18.16],[8,1.32,28.38],[9,1.33,1.16]],"ltp":1.24,"tv":1937.31,"id":39823721},{"atb":[[4.2,46.88],[5.5,0],[13,11.58],[14.5,3.35],[13.5,7.59]],"atl":[[19.5,2.16],[19,0.76],[18,4.17],[17,0.26]],"bdatb":[[5,11.5,3.29],[6,10.5,3.71],[7,10,14.74],[9,8.8,1.41],[2,13.5,7.59],[4,12.5,9.05],[3,13,11.58],[0,14.5,3.35],[8,9.6,27.24]],"bdatl":[[2,19.5,2.92],[3,20,5.94],[4,22,11.43],[5,24,20],[6,34,1.02],[7,36,6.01],[8,42,2.52],[9,1000,5.63],[0,17.5,1.4],[1,18,4.17]],"id":44331354}],"con":true,"tv":2757.23}]}
{"op":"mcm","clk":"AKpZAJFOAJJQ","pt":1650392743635,"mc":[{"id":"1.197931751","rc":[{"atb":[[4.1,25.92]],"bdatb":[[2,4.1,26.77]],"id":40095374},{"atb":[[2.66,0]],"bdatb":[[9,2.62,8.82],[8,2.64,12.25]],"bdatl":[[4,2.98,44.87]],"id":36276560},{"atb":[[5.3,6.44]],"bdatb":[[9,4.3,59.62],[1,5.3,6.44]],"id":37947503},{"atb":[[1.22,36.07],[1.19,249.99],[1.2,2]],"atl":[[1000,5.1]],"bdatb":[[5,1.18,12.42],[6,1.17,273.12],[7,1.16,13.99],[9,1.14,724.58],[1,1.22,36.07],[3,1.2,4.19],[4,1.19,263.76]],"bdatl":[[8,1.32,19.51],[9,1.33,9.96]],"id":39823721},{"atb":[[12,4.81],[14,12.31]],"atl":[[21,5],[17.5,2.04]],"bdatb":[[5,12,4.82],[6,11.5,3.28],[7,10.5,3.71],[8,10,14.74],[9,9.6,27.24],[1,14,12.31]],"bdatl":[[4,21,5],[5,22,11.43],[6,24,20],[7,34,1.02],[8,36,6.01],[9,42,2.52],[0,17.5,2.3]],"id":44331354}],"con":true}]}
{"op":"mcm","clk":"AM9aAKxPAK1R","pt":1650392744643,"mc":[{"id":"1.197931751","rc":[{"atb":[[2.1,297.76],[1.94,348.44]],"bdatb":[[9,2.44,1.33],[7,2.48,107.3]],"id":42930960},{"atb":[[2.66,197.31],[3,163.77]],"bdatb":[[8,3.75,2.87],[4,3.95,2.83],[5,3.9,3.01],[6,3.85,10.25],[7,3.8,6.36]],"id":40095374},{"atb":[[2.76,28],[2.18,277.57],[2,367.53]],"atl":[[2.96,32.09],[2.9,4.6]],"bdatb":[[9,2.62,8.87],[3,2.76,28]],"bdatl":[[3,2.96,32.09],[0,2.9,4.6]],"id":36276560},{"atb":[[3.05,159.77],[3.5,131.01]],"bdatb":[[8,4.5,10.02],[9,4.3,59.59],[6,4.8,7.12],[7,4.6,4.33]],"id":37947503},{"atb":[[1.22,24.68],[1.17,2140.67],[1.15,2183.56]],"atl":[[2.98,91.38],[1.74,39.13],[2.36,57.69],[1.25,23.75],[1000,5]],"bdatb":[[9,1.14,718.71],[1,1.22,24.68],[3,1.2,7.49],[4,1.19,266.78],[5,1.18,6.03],[6,1.17,2199.79],[8,1.15,2208.11]],"bdatl":[[1,1.25,23.75]],"id":39823721},{"atb":[[14,11.99],[6,85.51],[7.4,66.81]],"atl":[[24,9.13],[22,4.29],[20,0.68]],"bdatb":[[1,14,11.99],[8,10,14],[6,11.5,3.29],[7,10.5,4.4]],"bdatl":[[3,21,5.68],[4,22,4.29],[5,24,9.13],[6,34,1.02],[7,36,6.01],[8,42,2.52],[9,1000,5.49]],"id":44331354}],"con":true}]}
{"op":"mcm","clk":"AIVcAMVQAMBS","pt":1650392745644,"mc":[{"id":"1.197931751","rc":[{"atb":[[2.08,13.61]],"bdatb":[[6,2.52,14.48],[7,2.48,103.67],[8,2.46,8.43],[9,2.38,9.68]],"bdatl":[[9,2.88,24.33]],"id":42930960},{"atb":[[2.86,5.99]],"bdatb":[[6,3.85,10.01],[7,3.8,7.46],[8,3.75,2],[9,3.7,76.23]],"bdatl":[[5,5,8.2],[6,5.2,10.68],[7,5.4,23.49],[8,5.5,24.08],[9,5.6,35.12]],"id":40095374},{"atb":[[2.78,38.18],[2.82,14.41]],"atl":[[2.9,2]],"bdatb":[[0,2.82,14.41],[2,2.78,38.18],[7,2.68,23.44],[8,2.66,1.48],[9,2.64,18.93]],"bdatl":[[0,2.9,2],[5,3.05,4.33],[6,3.1,3.78],[7,3.15,5.42],[8,3.2,42.25],[9,3.25,1.85]],"id":36276560},{"atl":[[13,3.08]],"bdatb":[[6,4.8,6.26],[7,4.7,1.41],[8,4.6,4.51],[9,4.5,9.29]],"bdatl":[[8,6.8,1.36],[9,7.2,17.9]],"id":37947503},{"atb":[[1.21,55.85]],"bdatb":[[3,1.2,4.19],[4,1.19,263.76],[5,1.18,12.42],[7,1.16,21.24],[8,1.15,2201.53],[9,1.14,728.87],[2,1.21,58.61]],"bdatl":[[5,1.29,54.17],[6,1.3,33.79],[7,1.31,19.14],[8,1.32,26.81],[9,1.33,1.43],[3,1.27,183.68],[4,1.28,123.62]],"id":39823721},{"atb":[[12.5,11.79],[15,2.47],[12,0],[14,9.52]],"atl":[[17,3.31],[23,6.82]],"bdatb":[[5,12.5,12.06],[0,15,2.47],[1,14.5,3.35],[2,14,9.52],[3,13.5,7.59],[4,13,11.58],[7,10.5,3.71],[8,10,14.75]],"bdatl":[[8,34,1.22],[9,36,5.91],[0,17,3.31],[1,17.5,2.04],[2,18,4.17],[3,19.5,2.92],[4,21,5.68],[5,22,4.29],[6,23,6.82],[7,24,9.13]],"id":44331354}],"con":true}]}
{"op":"mcm","clk":"AJddAPdRAMRT","pt":1650392746646,"mc":[{"id":"1.197931751","rc":[{"atb":[[2.68,5.35],[2.6,21.88],[2.64,30.24],[2.62,53.61],[2.66,9.01],[2.7,0.72]],"atl":[[2.7,0],[1000,5]],"trd":[[2.7,66.62],[2.68,161.57]],"bdatb":[[0,2.68,6.07],[2,2.64,30.24],[4,2.6,21.88],[1,2.66,9.01],[3,2.62,53.61],[5,2.58,18.38],[6,2.56,30.66],[7,2.52,14.48],[8,2.48,103.67],[9,2.46,8.43]],"bdatl":[[0,2.72,2.42],[1,2.74,9.89],[2,2.76,25.06],[3,2.78,4.05],[4,2.8,11.88],[5,2.82,4.41],[6,2.84,2],[7,2.86,5.51],[8,2.88,24.33],[9,2.9,11.33]],"ltp":2.7,"tv":485.95,"id":42930960},{"atb":[[4.2,4.76]],"bdatb":[[1,4.2,4.76],[5,3.9,2.15],[6,3.85,10.88],[9,3.7,75.33]],"bdatl":[[5,5,5.39],[6,5.2,10.68],[7,5.4,23],[4,4.9,12.74],[8,5.5,23.68],[9,5.6,35.99],[3,4.8,11.26]],"id":40095374},{"atb":[[1.95,0],[2,467.53],[2.8,6.48],[2.82,9.66]],"atl":[[3.15,15.67]],"bdatb":[[4,2.74,28.71],[5,2.72,13.3],[8,2.64,20.43],[9,2.6,7.59],[1,2.8,6.48],[0,2.82,9.66]],"bdatl":[[5,3.05,5.34],[6,3.1,2.79],[8,3.2,43.16],[9,3.3,2.39],[7,3.15,18.61]],"id":36276560},{"atb":[[1.2,6.54]],"bdatb":[[3,1.2,11.52],[2,1.21,55.85],[5,1.18,10.57],[6,1.17,2198.8],[7,1.16,24.12],[9,1.14,725.93]],"bdatl":[[3,1.27,186.1],[4,1.28,121.23],[5,1.29,54.17],[6,1.3,33.48],[7,1.31,15.37],[8,1.33,56.5],[9,1.34,38.02]],"id":39823721},{"atb":[[1.14,0],[14.5,0.31],[12.5,8.78]],"atl":[[17,3.28],[25,10.42]],"trd":[[17,0.04]],"bdatb":[[4,12.5,8.78],[5,11.5,3.57],[9,8.8,1.42],[1,14,9.83],[2,13.5,7.59],[3,13,11.58],[6,10.5,3.71],[7,10,14.75],[8,9.6,27.24]],"bdatl":[[8,25,10.99],[9,36,6.51],[0,17,3.28],[6,23,6.9]],"ltp":17,"tv":0.04,"id":44331354},{"bdatb":[[4,5,9.31],[5,4.9,10.48]],"bdatl":[[7,6.8,1.37],[8,7.2,17.84],[9,7.4,6.51],[6,6.4,6.52],[5,6.2,4.88]],"id":37947503}],"con":true,"tv":2766.4}]}
{"op":"mcm","clk":"ALpeAKdTANhU","pt":1650392747648,"mc":[{"id":"1.197931751","rc":[{"atb":[[2.5,10],[2.62,43.46],[2.58,18.38],[2.7,3.78],[2.6,40.04]],"atl":[[2.78,4.05],[2.76,15.58],[2.8,11.88],[2.74,4.03],[2.72,0]],"bdatb":[[6,2.58,19.73],[7,2.56,29.31],[8,2.52,14.55],[9,2.5,12.58],[4,2.62,43.46],[0,2.7,3.78],[1,2.68,5.35],[2,2.66,9.01],[3,2.64,30.24],[5,2.6,40.04]],"bdatl":[[2,2.78,4.05],[7,2.88,22.29],[1,2.76,15.58],[3,2.8,11.88],[0,2.74,4.03],[4,2.82,4.41],[5,2.84,2],[6,2.86,5.51],[8,2.9,11.33],[9,2.92,3.55]],"id":42930960},{"atb":[[3.05,22.32],[2.26,91.99],[1.79,152.13],[3.95,7.27],[4.3,4.43],[4.2,2.29],[4,19.79]],"atl":[[6.4,10.64],[4.6,26.29],[4.5,10.27],[5.2,0],[5,14],[1000,7]],"trd":[[4.3,2.74]],"bdatb":[[6,3.85,11.04],[7,3.8,3.68],[8,3.75,9.16],[0,4.3,4.43],[4,3.95,7.86],[1,4.2,2.29],[9,3.7,77.45],[3,4,20.66],[2,4.1,25.92],[5,3.9,2.05]],"bdatl":[[0,4.5,10.27],[1,4.6,26.29],[5,5,15.39],[6,5.2,1.16],[7,5.4,24.27],[8,5.5,23.75],[9,5.6,34.7],[3,4.8,12.99],[4,4.9,11.06]],"ltp":4.3,"tv":82.88,"id":40095374},{"atb":[[2.6,16.97],[2.78,32.34],[2.8,9.06]],"bdatb":[[9,2.62,13.22],[5,2.72,13.3],[6,2.7,30.83],[1,2.8,9.06],[2,2.78,32.34],[8,2.64,12.99],[7,2.68,22.5]],"bdatl":[[5,3.05,6.25],[6,3.1,1.77],[7,3.15,16.98],[8,3.2,43.98],[9,3.3,1.83]],"id":36276560},{"atb":[[2.84,47.94],[3.85,70.31],[2.24,121.57],[5,13.06]],"atl":[[8,8.51]],"bdatb":[[9,4.5,14.59],[6,4.8,6.26],[7,4.7,1.41],[8,4.6,2.16],[4,5,13.06]],"bdatl":[[6,6.4,4.31],[7,6.6,1.24],[8,7,1],[9,7.2,17],[5,6.2,6.21]],"id":37947503},{"atl":[[1.31,0],[1.25,55.63]],"bdatb":[[7,1.16,32.96],[8,1.15,2207.29],[5,1.18,23.23],[6,1.17,2156.98],[4,1.19,260.77],[9,1.14,731.68]],"bdatl":[[3,1.27,188.28],[4,1.28,118.76],[5,1.29,47.94],[6,1.3,37.55],[1,1.25,55.63],[7,1.31,3.48],[8,1.32,8.3],[9,1.33,56.94]],"id":39823721},{"atb":[[12.5,6.26]],"atl":[[20,3.82],[18,6.18],[17.5,0.9],[19.5,0],[18.5,2.29],[16.5,1.14]],"bdatb":[[8,9.6,29.67],[9,8.8,2.21],[6,10.5,3.79],[7,10,13.81],[4,12.5,6.26],[5,11.5,3.36]],"bdatl":[[2,18,7.08],[3,18.5,2.29],[4,20,4.58],[5,21,5],[6,22,4.29],[7,23,7.26],[8,24,9.13],[9,25,10.77],[0,16.5,1.14],[1,17,3.28]],"id":44331354}],"con":true,"tv":2769.14}]}
{"op":"mcm","clk":"AM9fALJUAOFV","pt":1650392748650,"mc":[{"id":"1.197931751","rc":[{"atb":[[2.62,61.39]],"atl":[[2.78,12.33]],"bdatb":[[8,2.52,17.19],[9,2.5,12.94],[4,2.62,61.39]],"bdatl":[[6,2.86,9.52],[7,2.88,18.3],[2,2.78,12.33]],"id":42930960},{"atb":[[4.1,19.27]],"atl":[[5.2,23.81]],"bdatb":[[2,4.1,20.12],[7,3.8,5.01],[8,3.75,8.03],[9,3.7,76.66],[3,4,20.42],[4,3.95,8.55],[5,3.9,2.41],[6,3.85,11.28]],"bdatl":[[6,5.2,24.97],[3,4.8,13.25],[4,4.9,10.8],[7,5.3,1.58],[8,5.4,23.48],[9,5.5,25.12]],"id":40095374},{"atb":[[2.68,5.21],[2.78,35.6]],"atl":[[2.94,13.43],[2.9,4.61]],"bdatb":[[7,2.68,6.15],[8,2.66,1.9],[9,2.64,10.74],[2,2.78,35.6]],"bdatl":[[2,2.94,13.43],[0,2.9,4.61],[5,3,3.4],[6,3.05,2.9],[7,3.1,1.77],[8,3.15,16.98],[9,3.2,43.98]],"id":36276560},{"atb":[[5,23.88]],"bdatb":[[4,5,24.58],[8,4.6,5.7],[9,4.5,11.03],[5,4.9,9.78],[6,4.8,7.68],[7,4.7,1.57]],"bdatl":[[5,6.2,6.42],[6,6.4,4.11]],"id":37947503},{"atb":[[15.5,0.74],[14.5,2.46]],"atl":[[19.5,5.41],[17,3.28],[18.5,5.45],[18,4.17],[20,0.68],[16,0.79]],"bdatb":[[8,10,15.91],[9,9.6,27.3],[0,15,3.21],[7,10.5,4.01],[1,14.5,2.46],[2,14,9.52],[3,13.5,7.59],[4,13,11.58],[5,12.5,6.26],[6,11.5,3.36]],"bdatl":[[4,19.5,6.17],[5,21,5.68],[1,17,3.28],[3,18.5,5.45],[2,18,5.07],[0,16.5,1.93]],"id":44331354},{"bdatb":[[6,1.17,2175.77],[7,1.16,33.87],[8,1.15,2199.31],[4,1.19,265.79],[5,1.18,12.52],[9,1.14,728.11],[3,1.2,17.07]],"bdatl":[[9,1.33,25.08],[6,1.3,39.95],[7,1.31,6.38],[8,1.32,19.51]],"id":39823721}],"con":true}]}
{"op":"mcm","clk":"AN9gALxVANlW","pt":1650392749652,"mc":[{"id":"1.197931751","rc":[{"atb":[[2.48,0],[2.5,110]],"atl":[[2.94,43],[2.96,0],[2.76,12.2]],"bdatb":[[6,2.58,20.7],[7,2.56,32.19],[8,2.54,4.63],[9,2.52,19.03]],"bdatl":[[1,2.76,12.2],[6,2.86,12.17],[7,2.88,15.67],[9,2.92,5.09]],"id":42930960},{"atb":[[2.86,0],[4.1,11.81],[3.65,68],[3.7,7.19]],"atl":[[5.8,0]],"bdatb":[[2,4.1,13.27],[3,4,21.64],[4,3.95,10.24],[5,3.9,5.54],[6,3.85,9.36],[7,3.8,3.32],[9,3.7,10.92],[8,3.75,2.46]],"bdatl":[[8,5.4,24.89],[9,5.5,23],[3,4.8,15.77],[4,4.9,8.33],[7,5.3,2.34]],"id":40095374},{"atb":[[2.62,95],[2.52,0]],"atl":[[3.25,38],[2.98,2.87]],"bdatb":[[5,2.72,14.22],[6,2.7,32.71],[7,2.68,15.61],[8,2.64,10.13],[9,2.62,97.22]],"bdatl":[[4,2.98,2.87]],"id":36276560},{"atb":[[4.4,57],[4.3,0]],"bdatb":[[4,5,26.09],[5,4.9,11.6],[6,4.8,9.72],[7,4.6,1.26],[8,4.5,9.62],[9,4.4,64.45]],"bdatl":[[5,6.2,7.64],[6,6.4,3.63],[7,7,1.56],[8,7.2,17],[9,7.4,8.25]],"id":37947503},{"atb":[[1.17,1926.67],[1.15,2400.56]],"atl":[[1.24,31.39],[1.35,0],[1.32,95]],"bdatb":[[7,1.16,44.67],[8,1.15,2417.8],[6,1.17,1954.7],[9,1.14,729.5],[3,1.2,17.68],[4,1.19,275.67],[5,1.18,1.94]],"bdatl":[[0,1.24,31.39],[8,1.32,113.54],[9,1.33,10.2],[7,1.31,9.47]],"id":39823721},{"atb":[[15,4.47],[14.5,6.46],[13,6.05],[10.5,27.08],[9.6,1.24],[15.5,1.52]],"atl":[[25,0],[17.5,6.91],[17,5.05],[18.5,2.29],[24,4.13],[22,10.29],[16,1.57]],"bdatb":[[7,11.5,4.01],[8,10.5,29.72],[9,10,13.26],[1,15,4.47],[2,14.5,6.46],[5,13,6.05],[0,15.5,1.52],[3,14,9.52],[4,13.5,7.59],[6,12.5,6.26]],"bdatl":[[2,17,5.05],[3,17.5,6.91],[5,18.5,2.29],[8,22,10.29],[4,18,4.17],[6,19.5,6.17],[7,21,5.68],[9,23,7.26],[0,16,1.57],[1,16.5,1.14]],"id":44331354}],"con":true}]}
{"op":"mcm","clk":"APdhAMVWANpX","pt":1650392750653,"mc":[{"id":"1.197931751","rc":[{"atb":[[2.68,2.25],[2.64,49.09],[2.7,0.72]],"atl":[[2.74,4.05],[2.86,0],[2.76,5.21]],"bdatb":[[0,2.68,6.07],[1,2.66,9.01],[2,2.64,30.24],[3,2.62,61.39],[4,2.6,40.04],[5,2.58,20.63],[6,2.56,29.38],[7,2.54,7.53],[8,2.52,19.03],[9,2.5,110]],"bdatl":[[6,2.86,6.66],[0,2.74,2],[1,2.76,5.21],[9,2.92,4.63]],"id":42930960},{"atb":[[4,28.02]],"atl":[[5.4,34.09]],"bdatb":[[3,4,28.15],[2,4.1,13.15],[4,3.95,10.78],[5,3.9,3.35],[6,3.85,12.95],[9,3.7,8.87],[7,3.8,2],[8,3.75,3.8]],"bdatl":[[3,4.8,14.25],[4,4.9,8.78],[5,5,14.27],[6,5.2,27.02],[7,5.3,1.28],[8,5.4,34.09],[9,5.5,24.02]],"id":40095374},{"atl":[[2.9,2]],"bdatb":[[5,2.72,14.04],[6,2.7,31.02],[7,2.68,10.39],[8,2.66,7.17],[9,2.64,10.13]],"bdatl":[[5,3.05,6.26],[6,3.1,1.01],[7,3.15,15.67],[8,3.2,44.27],[9,3.25,41.55],[0,2.9,2]],"id":36276560},{"atb":[[1.8,2.01]],"bdatb":[[4,5,24.98],[5,4.9,11.19],[6,4.8,7.32],[7,4.7,4.06],[8,4.6,1.09],[9,4.5,9.8]],"bdatl":[[5,6.2,7.19],[6,6.4,3.36],[7,7,1.21],[8,7.2,17.2],[9,7.4,7.89]],"id":37947503},{"atb":[[1.21,40.11],[1.22,20.34],[1.23,18.04]],"atl":[[1.25,197.77],[1.27,143.63]],"bdatb":[[2,1.21,40.11],[9,1.14,732.57],[3,1.2,11.52],[4,1.19,266.07],[5,1.18,17.88],[6,1.17,1933.44],[8,1.15,2421.68],[1,1.22,20.34],[7,1.16,48.57],[0,1.23,18.04]],"bdatl":[[1,1.25,197.77],[3,1.27,156.45],[4,1.28,120.15],[5,1.29,48.7]],"id":39823721},{"atb":[[1.14,1.66]],"atl":[[21,7.5]],"bdatb":[[7,11.5,3.56],[8,10.5,28.42],[9,10,14.59]],"bdatl":[[9,23,6.9],[7,21,8.18]],"id":44331354}],"con":true}]}
{"op":"mcm","clk":"AJNjANlXAPFY","pt":1650392751654,"mc":[{"id":"1.197931751","rc":[{"atb":[[2.64,30.24],[2.62,69.44],[2.7,1.72],[2.6,56.96],[2.56,10.68]],"atl":[[2.72,1]],"bdatb":[[4,2.62,69.44],[0,2.7,1.72],[1,2.68,2.25],[2,2.66,9.01],[3,2.64,49.09],[5,2.6,56.96],[6,2.58,20.63],[7,2.56,10.73],[8,2.54,2.56],[9,2.52,16.09]],"bdatl":[[6,2.84,5.77],[7,2.86,2.91],[0,2.72,1],[1,2.74,4.05],[2,2.76,5.21],[3,2.78,12.33],[4,2.8,11.88],[5,2.82,4.41],[8,2.88,15.67],[9,2.9,11.33]],"id":42930960},{"atb":[[3.95,20.43]],"atl":[[5.6,54.35]],"bdatb":[[2,4.1,12.47],[3,4,28.83],[4,3.95,22.43],[5,3.9,3.28],[6,3.85,14.59],[8,3.75,3.79],[9,3.7,8.89]],"bdatl":[[2,4.7,31.1],[3,4.8,12.13],[4,4.9,9.92],[5,5,15.01],[6,5.1,1.38],[7,5.2,24.95],[8,5.3,1.28],[9,5.4,34.09]],"id":40095374},{"atb":[[2.8,20.6],[2.74,46.23]],"bdatb":[[4,2.74,47.23],[5,2.72,13.2],[6,2.7,33.76],[7,2.68,7.07],[8,2.66,3.53],[9,2.64,14.19]],"bdatl":[[4,2.98,4.43],[5,3,2.01],[6,3.05,2.75],[7,3.1,1.01],[8,3.15,15.67],[9,3.2,44.27]],"id":36276560},{"atb":[[5.1,19.55],[5,35.08],[1.8,0]],"atl":[[5.6,1.06]],"trd":[[5.6,2.74]],"bdatb":[[3,5.1,19.55],[4,5,35.63],[5,4.9,11.76],[6,4.8,7.1],[7,4.7,4.28],[8,4.5,10.92],[9,4.4,60.7]],"bdatl":[[4,6,10.36],[5,6.2,5.55],[6,6.4,4.23],[7,6.8,1.22],[9,7.4,7.13],[0,5.6,1.06]],"tv":40.39,"id":37947503},{"atb":[[1.23,0],[1.2,43.59],[1.19,283.61]],"trd":[[1.23,122.16]],"bdatb":[[2,1.21,42.36],[3,1.2,9.21],[4,1.19,294.43],[5,1.18,23.23],[6,1.17,1940.57],[7,1.16,43.68],[8,1.15,2415.89],[9,1.14,740.3]],"bdatl":[[2,1.26,171.07],[3,1.27,148.41],[4,1.28,127.38],[5,1.29,45.84],[9,1.33,18.26],[6,1.3,35.66],[7,1.31,13.73]],"ltp":1.23,"tv":1973.39,"id":39823721},{"atb":[[15.5,4.21],[14.5,6.46],[14,11.68],[16,0],[1.14,0]],"atl":[[17.5,7.52],[17,3.05],[16.5,1.79],[18,6.18],[16,0],[23,11.36]],"trd":[[16,3.14]],"bdatb":[[0,15.5,2.19],[2,14.5,8.66],[8,10.5,29.17],[9,10,13.75],[7,11.5,3.57]],"bdatl":[[2,17.5,5.51],[3,18,6.18],[0,16.5,1.14],[1,17,5.05],[4,18.5,2.29],[5,19.5,6.17],[6,21,8.18],[7,22,10.29],[8,23,11.56],[9,24,4.13]],"ltp":16,"tv":3.18,"id":44331354}],"con":true,"tv":2808.38}]}
{"op":"mcm","clk":"AMJkANJYAIVa","pt":1650392752655,"mc":[{"id":"1.197931751","rc":[{"atb":[[2.66,9.01],[2.62,43.46]],"atl":[[2.74,2],[2.72,0],[2.8,19.76]],"trd":[[2.72,71.9]],"bdatb":[[5,2.6,59.19],[6,2.58,18.43],[7,2.56,13.06],[8,2.52,13.72],[9,2.5,120.6],[2,2.66,9.01],[4,2.62,43.46],[3,2.64,30.24]],"bdatl":[[8,2.92,3.55],[0,2.74,2],[1,2.76,5.21],[2,2.78,12.33],[3,2.8,19.76],[4,2.82,4.41],[5,2.84,2],[6,2.88,15.67],[7,2.9,11.33],[9,2.94,43]],"ltp":2.72,"tv":487.94,"id":42930960},{"atb":[[4.3,0]],"atl":[[4.4,2.73]],"bdatb":[[0,4.2,2.29],[1,4.1,11.81],[2,4,29.51],[3,3.95,21.64],[4,3.9,2.44],[5,3.85,16.25],[6,3.8,2],[7,3.75,3.79],[8,3.7,8.89],[9,3.65,75.35]],"bdatl":[[0,4.4,2.73],[1,4.5,10.27],[2,4.6,26.29],[3,4.7,30.11],[4,4.8,10.86],[5,4.9,8.53],[6,5,18.01],[7,5.2,24.3],[8,5.3,1.39],[9,5.4,35.12]],"id":40095374},{"atl":[[3.45,33.33],[3.2,0]],"bdatb":[[3,2.76,29.99],[4,2.74,46.4],[5,2.72,12.02],[6,2.7,33.09],[7,2.68,5.21],[8,2.66,2.95],[9,2.64,17.35],[1,2.8,20.6]],"bdatl":[[5,3.15,18.72],[6,3.25,42.64],[7,3.3,3.02],[8,3.35,1.66],[9,3.4,5.24],[4,2.98,2.87]],"id":36276560},{"atb":[[1.21,97.76],[1.22,20.23],[1.06,1],[1.19,288.39],[1.2,41.59]],"atl":[[1.27,151.02]],"bdatb":[[1,1.21,102.55],[2,1.2,45.7],[3,1.19,289.82],[4,1.18,33.46],[5,1.17,1932.07],[6,1.16,59.17],[9,1.11,21.37],[0,1.22,20.23],[7,1.15,2405.5],[8,1.14,738.74]],"bdatl":[[3,1.27,151.02],[5,1.29,58.41],[7,1.31,13.61],[8,1.32,107.34],[4,1.28,121.98],[6,1.3,41.03],[9,1.33,30.19],[2,1.26,167.38]],"id":39823721},{"atb":[[14.5,11.12],[14,9.52],[13.5,3.78]],"atl":[[18,4.17],[17,4],[19.5,2.16],[18.5,0],[16.5,0.65],[17.5,5.51]],"bdatb":[[6,12.5,6.7],[7,11.5,3.64],[8,10.5,27.83],[9,10,14.59],[3,14,9.52],[4,13.5,3.78],[0,15.5,4.21],[2,14.5,6.46]],"bdatl":[[0,17,4.65],[8,36,6.19],[9,42,2.44],[1,17.5,5.51],[2,18,6.18],[3,19.5,2.92],[4,21,8.18],[5,22,10.29],[6,23,11.36],[7,24,4.13]],"id":44331354},{"bdatb":[[3,5.1,20.62],[4,5,35.15],[5,4.9,11.04],[6,4.8,5.86],[8,4.5,12.68],[9,4.4,57.93],[7,4.7,5.64]],"bdatl":[[6,6.4,2.93],[7,6.8,1.43],[8,7.2,19.1],[9,7.4,6.32],[5,6.2,4.57],[4,6,9.59]],"id":37947503}],"con":true,"tv":2810.37}]}
{"op":"mcm","clk":"AO1lAN5ZAKBb","pt":1650392753657,"mc":[{"id":"1.197931751","rc":[{"atb":[[2.1,0],[1.94,0],[2.62,61.39]],"atl":[[2.8,11.88]],"bdatb":[[7,2.56,13.06],[8,2.52,17.82],[9,2.5,116.46],[4,2.62,61.39]],"bdatl":[[7,2.9,11.39],[3,2.8,11.88]],"id":42930960},{"atb":[[2.66,0],[3,0],[2.84,10.51]],"atl":[[4.7,18.66],[4.5,21.9],[4.4,2.73],[4.6,24.28],[4.9,7.58]],"bdatb":[[3,3.95,22.08],[4,3.9,3.91],[5,3.85,14.32],[9,3.65,77.73]],"bdatl":[[1,4.5,21.9],[3,4.7,30.15],[5,4.9,9.72],[6,5,16.75],[7,5.2,24.36],[0,4.4,2.73],[2,4.6,24.28]],"id":40095374},{"atb":[[2.18,0],[2,140]],"bdatb":[[6,2.7,33.09],[7,2.68,8.14],[8,2.66,1.09],[9,2.64,16.25]],"bdatl":[[7,3.25,42.56],[8,3.3,3.1],[5,3.1,1.5],[6,3.15,17.25],[9,3.35,1.66]],"id":36276560},{"atb":[[3.05,0],[3.5,0]],"bdatb":[[9,4.4,65.33],[5,4.9,11.04],[6,4.8,7.41],[7,4.7,4.06]],"bdatl":[[5,6.2,4.6],[7,6.6,1.43],[8,7.2,19.07]],"id":37947503},{"atb":[[1.23,0.15],[1.22,19.85],[1.06,0],[1.2,63.41],[1.17,0],[1.15,217],[1.21,83.58]],"atl":[[1.24,143.64],[1000,7.15]],"trd":[[1.22,151.86]],"bdatb":[[0,1.22,20],[5,1.17,33.24],[6,1.16,16.97],[7,1.15,234.64],[2,1.2,68.59],[3,1.19,294.98],[4,1.18,27.17],[8,1.14,736.09],[9,1.13,4.25],[1,1.21,88.37]],"bdatl":[[3,1.27,154.68],[4,1.28,118.35]],"ltp":1.22,"tv":1974.15,"id":39823721},{"atb":[[16,0.77],[6,20],[7.4,15.63]],"atl":[[17.5,5.51],[21,5],[18,6.18],[16.5,1.38]],"bdatb":[[7,11.5,3.64],[8,10.5,27.83],[9,10,14.59],[0,15.5,4.98],[2,14.5,11.12]],"bdatl":[[3,18,6.18],[5,21,5.68],[2,17.5,7.52],[0,16.5,1.38],[1,17,4],[4,19.5,2.92],[6,22,10.29],[7,23,11.36],[8,24,4.13],[9,36,6.19]],"id":44331354}],"con":true,"tv":2811.13}]}
{"op":"mcm","clk":"AKlnAOVaAMFc","pt":1650392754675,"mc":[{"id":"1.197931751","rc":[{"atb":[[2.62,18.12],[2.66,36.07]],"atl":[[2.78,5.43],[2.82,9],[2.76,1.21],[2.74,0],[2.8,17.97]],"trd":[[2.76,18.08],[2.74,49.9]],"bdatb":[[2,2.66,36.07],[4,2.62,18.12],[7,2.56,17.26],[8,2.54,4.69],[9,2.52,13.55]],"bdatl":[[1,2.78,5.43],[3,2.82,9],[0,2.76,1.21],[2,2.8,17.97],[4,2.84,2],[5,2.88,15.67],[6,2.9,11.33],[7,2.92,3.55],[8,2.94,43],[9,2.96,3.25]],"ltp":2.76,"tv":499.94,"id":42930960},{"atb":[[4.1,9.09],[4,32.37]],"atl":[[4.4,7.88],[4.9,5.58],[4.8,8.86]],"bdatb":[[5,3.85,10.92],[6,3.8,9.15],[8,3.7,17.7],[9,3.65,68.91],[2,4,33.82],[3,3.95,20.46],[4,3.9,3.67],[7,3.75,3.68],[1,4.1,9.09]],"bdatl":[[0,4.4,7.88],[9,5.4,40.41],[4,4.8,8.86],[5,4.9,7.76],[8,5.3,2.45],[3,4.7,18.66],[6,5,16.71],[7,5.2,24.39]],"id":40095374},{"atb":[[2.68,0.09],[2.6,11.82],[2.72,6.88],[2.56,0]],"bdatb":[[7,2.68,6.38],[8,2.66,4.48],[9,2.64,10.13],[3,2.76,28],[4,2.74,47.45],[5,2.72,7.83],[6,2.7,30.83]],"bdatl":[[8,3.3,4.85],[9,3.35,1.99],[7,3.25,42.5]],"id":36276560},{"atb":[[1.2,77.6],[1.01,5657.32],[1.19,135.49],[1.23,0]],"atl":[[1000,5],[1.24,170.11],[1.26,150.8]],"trd":[[1.23,122.46]],"bdatb":[[2,1.2,79.75],[3,1.19,149.64],[4,1.18,19.36],[5,1.17,38.62],[6,1.16,12.05],[7,1.15,246.06],[8,1.14,726.28],[1,1.21,86.34],[9,1.13,7.57],[0,1.22,19.85]],"bdatl":[[7,1.31,20.95],[8,1.32,103.03],[9,1.33,43.79],[2,1.26,150.8],[0,1.24,170.11],[6,1.3,46.16]],"ltp":1.23,"tv":1974.45,"id":39823721},{"atl":[[23,6.82]],"bdatb":[[8,10.5,29.79],[9,10,13.77],[6,12.5,6.26],[7,11.5,3.57]],"bdatl":[[7,23,6.82],[2,17.5,5.51]],"id":44331354},{"bdatb":[[5,4.9,11.63],[6,4.8,7.03],[7,4.7,3.46],[8,4.6,3.75],[9,4.5,18.67],[3,5.1,19.55],[4,5,35.75]],"bdatl":[[5,6.2,4.57],[7,6.6,1.46],[8,7.2,19.04]],"id":37947503}],"con":true,"tv":2823.43}]}
{"op":"mcm","clk":"AMZoAO9bALRd","pt":1650392755676,"mc":[{"id":"1.197931751","rc":[{"atb":[[2.74,1.12],[2.72,1],[2.62,14.92],[2.66,40.76],[2.68,4.25],[2.64,47.95],[2.32,60.33]],"atl":[[2.74,0],[2.82,4.59]],"trd":[[2.74,51.9]],"bdatb":[[0,2.74,1.12],[1,2.72,1],[2,2.7,1.72],[3,2.68,4.25],[4,2.66,42.95],[5,2.64,48],[6,2.62,17.4],[7,2.6,60.94],[8,2.58,23],[9,2.56,11.42]],"bdatl":[[0,2.76,1.21],[1,2.78,5.43],[2,2.8,17.97],[3,2.82,4.59],[4,2.84,2],[5,2.88,15.67],[6,2.9,11.33],[7,2.92,3.55],[8,2.94,43],[9,2.96,3.25]],"ltp":2.74,"tv":501.94,"id":42930960},{"atb":[[2.26,60.24],[2.2,33.1],[4.1,12.02],[4,35.14]],"atl":[[4.8,3.9]],"bdatb":[[0,4.2,2.29],[1,4.1,13.43],[2,4,36.79],[3,3.95,21.95],[4,3.9,6.65],[8,3.7,15.24],[5,3.85,9.36],[6,3.8,4.38],[9,3.65,69.56]],"bdatl":[[3,4.7,19.31],[5,4.9,6.91],[4,4.8,4.47],[6,5,16.38]],"id":40095374},{"atb":[[1.17,232.75],[1.48,92],[2,174.04]],"atl":[[4.1,16.61],[3.55,14.12],[3.6,0]],"bdatb":[[1,2.8,20.6],[2,2.78,36.8],[3,2.76,28.94],[4,2.74,50.8],[5,2.72,8.48],[9,2.6,20.72],[6,2.7,35.25],[7,2.64,10.93],[8,2.62,98.45]],"bdatl":[[5,3.05,1.01],[6,3.1,2.11],[7,3.15,15.93],[8,3.2,3.56],[9,3.25,38.74]],"id":36276560},{"atl":[[9.4,4.76],[9.6,0]],"bdatb":[[2,5.2,13.88],[3,5.1,20.03],[4,5,37.61],[5,4.9,13.09],[8,4.5,15.91],[6,4.8,5.77],[7,4.6,3.74],[9,4.4,58.29]],"bdatl":[[6,6.4,3.83],[7,7,2.33],[8,7.2,17.33],[9,7.4,6.32]],"id":37947503},{"atb":[[1.21,93.5],[1.2,79.61],[1.01,5654.32],[1.18,161.39]],"atl":[[1.28,114.46],[1.52,255.39],[1.53,0],[1000,6],[1.24,171.41],[1.23,29.73]],"trd":[[1.24,334.88]],"bdatb":[[1,1.21,96.26],[2,1.2,81.76],[3,1.19,149.64],[5,1.17,30.84],[6,1.16,12.13],[7,1.15,253.89],[4,1.18,180.75]],"bdatl":[[3,1.26,153.24],[4,1.27,156.18],[5,1.28,115.1],[6,1.29,57.78],[0,1.23,29.73],[1,1.24,171.41],[2,1.25,197.77],[7,1.3,55.4],[8,1.31,11.78],[9,1.32,103.03]],"ltp":1.24,"tv":1976.45,"id":39823721},{"atb":[[1.05,0],[5.5,8.7],[4.6,0]],"bdatb":[[3,14,9.52],[4,13.5,4.02],[5,13,6.24],[7,11.5,4.14],[8,11,1.48],[6,12.5,6.27],[9,10.5,27.26]],"bdatl":[[9,36,6.23]],"id":44331354}],"con":true,"tv":2827.43}]}
{"op":"mcm","clk":"AOBpAIJdALhe","pt":1650392756679,"mc":[{"id":"1.197931751","rc":[{"atb":[[1.01,21240.7],[2.62,32.84],[2.66,31.44],[2.28,171.46],[2.64,30.24]],"atl":[[1000,94.14],[2.8,19.54],[2.84,11.84],[2.76,1.39],[2.78,4.05]],"bdatb":[[8,2.58,20.92],[9,2.56,19.36],[5,2.64,30.24],[6,2.62,35.11],[7,2.6,56.96],[4,2.66,31.44]],"bdatl":[[6,2.9,14.65],[7,2.92,3.55],[8,2.94,43.88],[9,3,2.13],[2,2.8,19.54],[4,2.84,11.84],[0,2.76,1.39],[1,2.78,4.05]],"id":42930960},{"atb":[[2.16,85.61],[2.22,0],[1.01,24751.64]],"atl":[[4.3,2.79],[1000,64.9]],"bdatb":[[3,3.95,21.63],[4,3.9,3.13],[8,3.7,8.9],[9,3.65,76.44],[1,4.1,12.02],[2,4,36.62],[5,3.85,14.94],[6,3.8,2],[7,3.75,4.41]],"bdatl":[[2,4.6,24.95],[3,4.7,20.22],[4,4.8,4.27],[5,4.9,6.88],[6,5,14.65],[7,5.1,3.61],[8,5.2,30.37],[9,5.3,5.87]],"id":40095374},{"atb":[[2.84,6.55],[2.5,4.69],[2.82,14.41],[2.78,32.34],[1.01,21836],[2.8,23.85]],"atl":[[2.92,4.27],[2.96,25.63],[2.9,0],[1000,92.06]],"trd":[[2.9,4]],"bdatb":[[0,2.84,6.55],[1,2.82,14.41],[2,2.8,23.85],[3,2.78,32.34],[4,2.76,29.39],[5,2.74,47],[6,2.72,8.63],[7,2.7,32.47],[8,2.68,7.4],[9,2.64,10.85]],"bdatl":[[0,2.92,4.27],[2,2.96,25.63],[7,3.2,3],[8,3.25,43.66],[9,3.3,5.66],[4,3.05,1.9],[5,3.1,1.24],[6,3.15,16.49],[1,2.94,13.43],[3,2.98,2.87]],"ltp":2.9,"tv":226.59,"id":36276560},{"atb":[[5,24.26],[1.01,26015.09]],"atl":[[9.8,11.36],[1000,50.27]],"bdatb":[[5,4.9,11.54],[6,4.8,10.4],[7,4.5,17.08],[8,4.4,67.59],[9,4.2,7.82],[3,5.1,19.55],[4,5,25.03],[2,5.2,13.24]],"bdatl":[[5,6.2,5.5],[6,6.4,3.53],[7,7,1.76],[8,7.2,22.15],[9,7.4,6.32]],"id":37947503},{"atb":[[1.22,10.01],[1.19,288.39],[1.01,10227.86]],"atl":[[1.54,184.94],[1.24,171.56],[1000,208.26]],"bdatb":[[3,1.19,295.64],[4,1.18,180.21],[5,1.17,14.77],[6,1.16,59.83],[7,1.15,225.19],[8,1.14,720.8],[9,1.13,2.79],[2,1.2,82.8],[1,1.21,93.5],[0,1.22,10.01]],"bdatl":[[2,1.25,200.22],[3,1.26,156],[4,1.27,151.66],[5,1.28,137.73],[1,1.24,171.56],[6,1.29,59.22],[7,1.3,42.93],[8,1.31,23.77],[9,1.32,123.57]],"id":39823721},{"atb":[[14,14.46],[16,5.16],[5.3,22.77],[17,13.37],[15.5,4.21],[13,9.53],[15,6.65],[14.5,17],[1.01,28986.16]],"atl":[[17.5,0],[19,0],[18,5.96],[1000,19.37],[25,10.42],[19.5,2.73],[18.5,0],[17,0],[16.5,0]],"trd":[[17.5,2.44],[17,16.19],[16.5,3.82]],"bdatb":[[1,16,5.16],[5,14,14.46],[0,17,13.37],[2,15.5,4.21],[7,13,9.83],[9,11.5,3.85],[3,15,6.65],[4,14.5,17],[6,13.5,3.78],[8,12.5,6.42]],"bdatl":[[0,18,6.57],[1,19.5,2.73],[2,21,5.68],[3,22,10.29],[4,23,6.82],[5,24,4.13],[6,25,10.42],[7,36,6.28],[8,42,2.48],[9,1000,20.01]],"ltp":17.5,"tv":25.59,"id":44331354}],"con":true,"tv":2853.84}]}
{"op":"mcm","clk":"AIJrAIdeAMJf","pt":1650392757680,"mc":[{"id":"1.197931751","rc":[{"atb":[[2.7,5.61],[2.48,13.51],[2.54,12.99],[2.24,160.56]],"atl":[[2.8,23],[2.78,5.43],[2.76,0],[3,10],[3.1,12.72],[3.2,9.09],[2.84,15.01],[2.82,6.98]],"bdatb":[[9,2.56,20.1],[2,2.7,5.61],[4,2.66,31.44],[5,2.64,32.49],[8,2.58,18.57],[6,2.62,35.16]],"bdatl":[[1,2.8,23],[0,2.78,5.43],[2,2.82,6.98],[3,2.84,15.01],[4,2.88,16.51],[5,2.9,12.32],[6,2.92,5.41],[7,2.94,43.51],[8,3,15.7],[9,3.05,17.64]],"id":42930960},{"atb":[[3.9,6.62],[1.01,23883.75],[3.85,9.36],[2.12,133],[4.2,0],[3.75,4.93],[3.95,30.27],[4,25.45]],"atl":[[4.5,21.9],[1000,64.01],[4.4,22.05],[4.6,17.78],[4.8,1.4]],"bdatb":[[3,3.9,7.75],[4,3.85,13.36],[7,3.7,11.35],[8,3.65,75.55],[0,4.1,12.02],[1,4,26.93],[2,3.95,31.48],[5,3.8,3.6],[6,3.75,4.93],[9,3.6,5.47]],"bdatl":[[2,4.5,22.58],[9,5.2,26.28],[3,4.6,18.37],[4,4.7,20.02],[5,4.8,1.4],[6,4.9,9.07],[7,5,14.6],[8,5.1,1.55],[1,4.4,22.05],[0,4.3,2.79]],"id":40095374},{"atb":[[2.9,0.83],[2.78,13.32],[1.01,21578.72],[2.88,1],[2.74,46.23],[2.82,24.84],[2.86,1.9],[2.72,0],[2.8,20.6]],"atl":[[3.3,4.96],[1000,89.89],[2.9,0]],"trd":[[2.9,6]],"bdatb":[[9,2.68,8.1],[7,2.74,46.72],[8,2.7,31.98],[0,2.88,1.83],[4,2.8,20.6],[5,2.78,15.45],[1,2.86,1.9],[2,2.84,6.55],[3,2.82,24.84],[6,2.76,29.72]],"bdatl":[[8,3.3,7.71],[9,3.35,1.14],[0,2.92,4.27],[1,2.94,13.43],[2,2.96,25.63],[3,2.98,2.87],[4,3.1,1.87],[5,3.15,17.71],[6,3.2,6.29],[7,3.25,40.43]],"tv":228.59,"id":36276560},{"atl":[[10.5,15.79],[12.5,0]],"bdatb":[[8,4.6,6.72],[9,4.5,16.34],[5,4.9,9.87],[6,4.8,9.53],[2,5.2,13.24],[3,5.1,21.64],[7,4.7,1.3],[4,5,24.53]],"bdatl":[[3,5.9,3.36],[4,6,9.99],[5,6.2,5.03],[6,6.4,3.78],[7,6.8,1.51],[8,7,1.63],[9,7.2,19.35]],"id":37947503},{"atb":[[1.21,33.78],[1.19,155.49],[1.18,181.39]],"atl":[[1.6,0],[1.56,250],[1.26,170.8],[1.27,171.02],[1.28,134.46]],"bdatb":[[5,1.17,28.96],[6,1.16,29.71],[7,1.15,240.81],[8,1.14,714.29],[9,1.12,7.4],[1,1.21,33.78],[3,1.19,157],[4,1.18,209.48],[2,1.2,88.5]],"bdatl":[[2,1.25,199.69],[3,1.26,173.49],[4,1.27,182.95],[5,1.28,149.53],[6,1.29,51.76],[7,1.3,50.33],[8,1.31,31.78],[9,1.32,121.6]],"id":39823721},{"atb":[[15,8.47],[5.1,36.37],[16.5,0.65],[1.01,28638.6],[4.2,0],[4.4,0],[4,0],[15.5,11.96],[14,9.52],[13.5,1.45],[13,3.63]],"atl":[[19,2],[18.5,2],[21,2],[19.5,2.01],[1000,18.94],[18,1.1],[17.5,0.61],[22,10.29],[20,1.21]],"trd":[[17.5,7.66]],"bdatb":[[3,15,8.47],[7,13,4.09],[8,12.5,6.26],[9,11.5,3.34],[4,14.5,17],[5,14,9.52],[6,13.5,1.89],[1,16,5.81],[2,15.5,11.96]],"bdatl":[[1,18.5,2],[2,19,2],[3,19.5,2.01],[4,20,1.21],[5,21,2],[6,22,10.29],[7,23,6.82],[8,24,4.13],[9,25,10.52],[0,18,1.71]],"tv":30.81,"id":44331354}],"con":true,"tv":2861.06}]}
{"op":"mcm","clk":"AKNsAIpfAMNg","pt":1650392758681,"mc":[{"id":"1.197931751","rc":[{"atb":[[2.64,32.73],[2.5,10],[2.54,110.99],[1.01,37119.21],[1.95,34.91],[1.14,238.87]],"atl":[[2.94,0],[2.78,12.41],[2.98,42],[1000,184.35],[3.9,38.68],[5.3,25.69],[2.82,14.23],[2.8,19.74]],"bdatb":[[5,2.64,34.94],[6,2.62,32.88],[9,2.56,16.4],[7,2.6,59.3],[8,2.58,18.38]],"bdatl":[[0,2.78,12.41],[6,2.92,4.92],[7,2.96,1.16],[8,2.98,42.97],[9,3,10.6],[2,2.82,14.23],[1,2.8,19.74],[4,2.88,19.91],[5,2.9,11.33]],"id":42930960},{"atb":[[3.65,0],[2.08,229.88],[3.55,70],[1.01,42855.48],[2.14,0],[3.9,2],[2.18,0],[3.6,2.93]],"atl":[[5.5,0],[5.3,24],[1000,123.28]],"bdatb":[[3,3.9,7.31],[4,3.85,9.36],[8,3.65,2.15],[9,3.6,15.19],[7,3.7,7.51],[1,4,25.45],[2,3.95,31.77],[5,3.8,4.61],[6,3.75,4.93]],"bdatl":[[4,4.7,19.51],[5,4.8,2.39],[6,4.9,6.27],[7,5,15.6],[8,5.1,1.46],[9,5.2,23.81],[1,4.4,22.74],[2,4.5,23.93],[3,4.6,17.78]],"id":40095374},{"atb":[[2.7,123.83],[2.62,0],[2.82,27.08],[2.78,25.3],[1.01,37922.28],[2.9,6.77],[2.74,39.39],[2.8,23.14]],"atl":[[3.3,38],[3.25,0],[1000,173.13],[2.94,10.86],[2.96,18.77],[2.92,2]],"trd":[[2.9,7.14]],"bdatb":[[4,2.82,27.08],[9,2.7,129.26],[6,2.78,25.3],[0,2.9,6.77],[7,2.76,30.15],[8,2.74,41.61],[1,2.88,1],[2,2.86,1.9],[3,2.84,6.55],[5,2.8,23.14]],"bdatl":[[7,3.2,2.73],[8,3.25,3.5],[9,3.3,40.26],[1,2.94,10.86],[2,2.96,18.77],[4,3.05,1.01],[5,3.1,2.95],[6,3.15,15.67],[0,2.92,2]],"tv":229.73,"id":36276560},{"atb":[[5.4,3],[1.01,46388.14]],"atl":[[11.5,23.81],[1000,95.54]],"bdatb":[[0,5.4,3],[8,4.5,21.11],[9,4.4,57.81],[3,5.1,19.55],[4,5,26.66],[6,4.8,8.82],[7,4.7,2.11],[5,4.9,9.78]],"bdatl":[[8,7.2,18.65],[9,7.4,7.24],[4,6,10.55],[5,6.2,5.6],[6,6.4,4.09],[7,6.8,1.24]],"id":37947503},{"atb":[[1.14,933.29],[1.15,0],[1.18,186.44],[1.2,87.74],[1.01,14801.4],[1.19,155.49],[1.21,22.78]],"atl":[[1.31,95],[1.32,0],[1000,411.52]],"bdatb":[[2,1.2,92.61],[4,1.18,205.5],[5,1.17,26.79],[7,1.15,7.44],[8,1.14,933.29],[6,1.16,27.99],[9,1.13,6.29],[1,1.21,22.78],[3,1.19,160.66]],"bdatl":[[3,1.26,181.8],[4,1.27,174.71],[5,1.28,140.71],[6,1.29,57.88],[7,1.3,31.86],[8,1.31,147.55],[9,1.32,24.18],[2,1.25,202.4]],"id":39823721},{"atb":[[4.9,63.73],[12,21],[10.5,3.08],[1.01,52136.15],[7,74.9],[8.8,15.47],[17.5,1.39],[16,8.59]],"atl":[[28,4],[23,4.55],[22,4.29],[21,4],[1000,32.76],[26,2.84],[19,0],[18,1.48],[17.5,0],[18.5,0]],"trd":[[17.5,8.88]],"bdatb":[[0,17.5,1.39],[1,17,13.37],[2,16,9.24],[3,15.5,11.96],[4,15,8.47],[5,14.5,17],[6,14,9.52],[7,13.5,1.89],[8,13,3.63],[9,12.5,6.74]],"bdatl":[[4,22,4.29],[5,23,4.55],[9,28,4.23],[3,21,4],[0,18,1.48],[1,19.5,2.01],[2,20,1.21],[6,24,4.13],[7,25,10.54],[8,26,2.94]],"tv":32.03,"id":44331354}],"con":true,"tv":2863.42}]}
{"op":"mcm","clk":"AMJtAJ9gALhh","pt":1650392759682,"mc":[{"id":"1.197931751","rc":[{"atb":[[2.64,50.44]],"atl":[[2.78,10.41]],"trd":[[2.78,21.52]],"bdatb":[[5,2.64,52.66],[9,2.56,16.4],[6,2.62,32.88],[7,2.6,59.3],[8,2.58,18.38]],"bdatl":[[0,2.78,10.41]],"ltp":2.78,"tv":505.94,"id":42930960},{"atb":[[4,35.14],[3.75,2],[3.6,0],[3.95,32.56]],"bdatb":[[1,4,35.14],[5,3.8,4.3],[6,3.75,2.32],[7,3.7,7.19],[8,3.65,5.68],[3,3.9,7.31],[9,3.6,6.15],[2,3.95,34.06],[4,3.85,9.36]],"id":40095374},{"atb":[[1.01,37754.84],[2.8,20.6]],"atl":[[3.15,22.82],[2.94,10.05]],"bdatb":[[9,2.7,129.26],[7,2.76,30.15],[8,2.74,41.61],[5,2.8,20.6]],"bdatl":[[6,3.15,22.82],[1,2.94,10.05]],"id":36276560},{"atb":[[5.2,6.33]],"atl":[[5.6,1.06],[5.7,9.01]],"bdatb":[[2,5.2,6.33],[7,4.7,1.86],[8,4.5,19.08],[9,4.4,59.62],[6,4.8,8.82]],"bdatl":[[0,5.6,1.06],[1,5.7,9.01]],"id":37947503},{"atb":[[1.2,100.07]],"bdatb":[[2,1.2,104.93],[4,1.18,200.79],[5,1.17,31.54],[6,1.16,25.93],[7,1.15,7.44],[8,1.14,933.29],[9,1.13,8.4],[3,1.19,160.66]],"bdatl":[[8,1.31,145.12],[9,1.32,48.95]],"id":39823721},{"atb":[[1.01,49811],[16,9.77],[14,7.29],[16.5,3.64]],"atl":[[25,6.25],[18,1.48],[1000,31.37],[20,0.68],[21,4.5]],"trd":[[18,1.18]],"bdatb":[[3,16,9.77],[7,14,7.29],[9,13,3.63],[2,16.5,3.64],[4,15.5,11.96],[5,15,8.47],[6,14.5,17],[8,13.5,1.89]],"bdatl":[[6,25,6.37],[0,18,1.48],[1,19.5,2.01],[2,21,5.18],[3,22,4.29],[4,23,4.55],[5,24,4.13],[7,26,2.94],[8,28,4.23],[9,36,6.02]],"ltp":18,"tv":33.21,"id":44331354}],"con":true,"tv":2868.6}]}
{"op":"mcm","clk":"AM5uAKRhALJi","pt":1650392760684,"mc":[{"id":"1.197931751","rc":[{"atb":[[2.64,32.73]],"bdatb":[[5,2.64,34.94]],"bdatl":[[6,2.92,3.68],[7,2.94,1.22],[8,2.98,42.96],[9,3,15.91]],"id":42930960},{"atb":[[4,25.45]],"bdatb":[[1,4,25.45]],"bdatl":[[6,4.9,7.9],[7,5,15.49],[8,5.2,24.28],[9,5.3,25.52]],"id":40095374},{"atb":[[2.7,106.75],[2.88,6.16],[2.9,6.57]],"trd":[[2.9,7.54]],"bdatb":[[9,2.7,112.17],[1,2.88,6.16],[0,2.9,6.57]],"bdatl":[[7,3.2,1.25],[8,3.25,4.96]],"tv":230.13,"id":36276560},{"bdatl":[[6,6.4,2.99],[7,6.6,1.26],[8,6.8,2.33],[9,7.2,17.42]],"id":37947503},{"atb":[[1.02,4.8]],"atl":[[1.29,14.12],[1.3,6.89],[1.5,0.21],[1.27,65.46],[1.28,73.1],[1000,411.52]],"bdatl":[[3,1.26,179.07],[4,1.27,78.16],[5,1.28,80.84],[6,1.29,19.58],[7,1.3,15.77],[8,1.31,137.09],[9,1.32,26.6]],"id":39823721},{"atb":[[1.05,220],[17.5,0.72]],"atl":[[27,9.62]],"trd":[[17.5,10.22]],"bdatb":[[0,17,14.09],[1,16.5,3.64],[2,16,9.77],[3,15.5,11.96],[4,15,8.47],[5,14.5,17],[6,14,7.29],[7,13.5,1.89],[8,13,3.63],[9,12.5,6.74]],"bdatl":[[8,27,9.62],[9,28,4.23]],"ltp":17.5,"tv":34.55,"id":44331354}],"con":true,"tv":2870.34}]}
{"op":"mcm","clk":"AOBvAKhiALVj","pt":1650392761685,"mc":[{"id":"1.197931751","rc":[{"atb":[[2.8,36.73]],"bdatb":[[5,2.8,36.73],[6,2.78,27.53],[7,2.76,30.1],[9,2.72,3.94],[8,2.74,39.39]],"bdatl":[[4,3.05,1.01],[5,3.1,1.73],[6,3.15,22.82],[7,3.2,3.91],[8,3.3,41.46],[9,3.35,1.09]],"id":36276560},{"atb":[[4.9,13.4],[1.01,44116.58],[5.4,0],[5.2,8.33],[5.3,4.44]],"atl":[[6.2,11.12],[5.6,7.07],[5.4,1.15],[5.7,9.01],[5.5,3]],"trd":[[5.4,26.34]],"bdatb":[[4,4.9,15.84],[7,4.6,8.5],[9,4.4,60.75],[3,5,24.26],[0,5.3,4.44],[1,5.2,8.33],[2,5.1,19.55],[5,4.8,5.77],[6,4.7,4.98],[8,4.5,9.29]],"bdatl":[[2,5.6,7.07],[7,6.2,11.12],[0,5.4,1.15],[1,5.5,3],[3,5.7,9.01],[4,5.8,14.36],[5,5.9,3.82],[6,6,10.03],[8,6.4,4.78],[9,6.8,2.31]],"ltp":5.4,"tv":48.38,"id":37947503},{"atb":[[1.02,0],[1.2,39.18],[1.22,6.9]],"atl":[[1.23,60.54],[1.25,211.38]],"trd":[[1.23,122.78],[1.22,158.08]],"bdatb":[[8,1.13,12.53],[9,1.12,47.59],[2,1.2,44.36],[3,1.19,169.36],[6,1.16,17.47],[7,1.14,933.29],[4,1.18,197.18],[5,1.17,41.73],[0,1.22,6.9]],"bdatl":[[0,1.23,60.54],[2,1.25,216.01],[3,1.26,182.3],[4,1.27,68.01],[5,1.28,83.48],[6,1.29,23.79]],"ltp":1.23,"tv":1982.99,"id":39823721},{"atb":[[18.5,0.58],[17,9.05],[18,0.53],[1.05,440.8],[17.5,0.05],[1.01,49151.75]],"atl":[[1000,29.53],[19,0],[18,0]],"trd":[[18,4.14],[17.5,11.56]],"bdatb":[[0,18,1.11],[1,17,9.1],[2,16.5,3.64],[3,16,9.77],[4,15.5,11.96],[5,15,8.47],[6,14.5,17.4],[7,14,7.31],[8,13.5,1.88],[9,13,3.63]],"bdatl":[[0,19.5,2.01],[5,25,6.25],[6,26,2.84],[7,27,9.73],[9,36,6.08],[1,21,5.18],[2,22,4.29],[3,23,4.55],[4,24,4.13],[8,28,4]],"ltp":18,"tv":38.85,"id":44331354},{"bdatb":[[4,2.66,33.64],[5,2.64,32.87],[6,2.62,35.05],[8,2.58,22.54],[9,2.56,15.63],[7,2.6,56.96]],"bdatl":[[4,2.88,18.6],[5,2.9,11.33],[6,2.92,3.55],[7,2.94,3.62],[8,2.98,42.7],[9,3,10.79]],"id":42930960},{"bdatb":[[6,3.75,8.16],[7,3.7,10.48],[8,3.6,2.71],[1,4,26.91],[2,3.95,32.65],[3,3.9,6.23],[5,3.8,4.7],[9,3.55,74.31],[4,3.85,10.98]],"bdatl":[[2,4.5,23.09],[3,4.6,17.78],[4,4.7,20.92],[5,4.8,1.79],[6,4.9,6.1],[7,5,15.76],[1,4.4,22.74],[8,5.2,24.69],[9,5.3,25.03]],"id":40095374}],"con":true,"tv":2889.17}]}
{"op":"mcm","clk":"AIFxAMNjANJk","pt":1650392762686,"mc":[{"id":"1.197931751","rc":[{"atb":[[2.68,12.24],[2.7,1.72],[2.64,50.44]],"atl":[[2.8,22.94],[3.3,8.7],[3,0]],"bdatb":[[3,2.68,13.11],[2,2.7,4.02],[5,2.64,50.44],[8,2.58,19.33],[9,2.56,13.92],[1,2.72,1],[6,2.62,34.16],[4,2.66,31.44]],"bdatl":[[1,2.8,22.94],[7,2.96,3.22],[8,2.98,42.36],[9,3.05,17.28],[4,2.88,15.67],[6,2.92,3.55]],"id":42930960},{"atb":[[3.95,37.36],[4,35.14]],"bdatb":[[2,3.95,37.94],[5,3.8,12.8],[6,3.75,3.19],[1,4,35.72],[7,3.7,7.19],[8,3.65,1.12],[9,3.55,70],[0,4.1,13.53],[3,3.9,5.05]],"bdatl":[[8,5.2,28.21],[9,5.3,24.9],[5,4.8,1.59],[6,4.9,5.61],[7,5,15.96],[2,4.5,21.9],[3,4.6,18.45],[4,4.7,20.03],[1,4.4,22.05]],"id":40095374},{"atb":[[2.76,33.01],[2.84,8.48],[2.64,5.6],[1.01,35904.55],[2.78,19.59],[2.52,2],[2.86,0],[2.9,0],[2.8,15.44],[2.82,22.33],[2.88,0]],"atl":[[1000,167.72],[2.94,2],[2.86,0],[2.88,2.97],[2.92,0],[3.1,13.11]],"trd":[[2.94,0.36],[2.86,7.44],[2.9,9.86],[2.88,14.4]],"bdatb":[[0,2.84,8.48],[4,2.76,35.11],[9,2.64,5.6],[8,2.68,17.08],[1,2.82,22.33],[2,2.8,17.66],[3,2.78,19.59],[5,2.74,39.39],[6,2.72,3.94],[7,2.7,109.05]],"bdatl":[[7,3.3,44.91],[8,3.35,1.42],[5,3.15,24.29],[6,3.25,3.07],[1,2.94,2],[0,2.88,2.97],[9,3.45,33.71],[4,3.1,14.98]],"ltp":2.94,"tv":254.25,"id":36276560},{"atb":[[1.01,42310.86],[5.3,2],[4.9,9.78],[5.1,12.46]],"atl":[[5.7,16.98],[5.8,19.31],[1000,89.3],[5.6,10.64],[5.9,3.36],[6.2,4.57]],"bdatb":[[0,5.3,2],[6,4.7,3.6],[7,4.6,9.9],[8,4.5,9.29],[9,4.4,57.93],[2,5.1,14.14],[4,4.9,10.48],[3,5,24.26]],"bdatl":[[3,5.7,16.98],[8,6.4,3.94],[9,6.6,1.65],[4,5.8,19.31],[2,5.6,10.64],[5,5.9,3.36],[6,6,9.59],[7,6.2,5.06]],"id":37947503},{"atb":[[1.2,93.21],[1.22,16.74],[1.17,14.18]],"atl":[[1.52,76.82],[1.47,184.94],[1.25,168.48]],"bdatb":[[2,1.2,95.11],[9,1.13,50.21],[7,1.15,26.48],[8,1.14,942.23],[3,1.19,158.52],[4,1.18,198.73],[5,1.17,56.59],[6,1.16,4.28],[1,1.21,29.85],[0,1.22,16.74]],"bdatl":[[4,1.27,70.55],[5,1.28,73.93],[6,1.29,39.42],[7,1.3,11.54],[8,1.31,123.83],[9,1.32,30.18],[2,1.25,168.48],[3,1.26,173.24]],"id":39823721},{"atb":[[17,11.05],[17.5,0],[7,91.57],[6,0],[1.01,44316.11],[1.05,643.2],[18.5,0]],"atl":[[1000,27.43],[60,2],[24,5.87],[23,0],[21,2.5],[42,0],[19.5,9.12],[20,0.68],[19,0.57]],"trd":[[18.5,1.16]],"bdatb":[[0,17,11.58],[9,12.5,6.45],[1,16.5,3.64],[2,16,10.16],[4,15,8.63],[6,14,7.29],[7,13.5,1.71],[5,14.5,17],[3,15.5,11.96],[8,13,3.63]],"bdatl":[[0,19.5,9.69],[1,21,3.18],[3,24,5.87],[4,25,6.25],[5,26,2.84],[6,27,9.62],[7,28,4],[8,36,6.07],[9,60,2.3],[2,22,4.29]],"ltp":18.5,"tv":40.01,"id":44331354}],"con":true,"tv":2914.45}]}
{"op":"mcm","clk":"AIdyAN1kANll","pt":1650392763688,"mc":[{"id":"1.197931751","rc":[{"atb":[[2.68,4.25]],"atl":[[2.78,3.43],[2.8,19.74]],"bdatb":[[3,2.68,4.25],[4,2.66,37.65],[5,2.64,53.07],[7,2.6,70.61],[8,2.58,21.21],[9,2.56,10.68],[6,2.62,32.84]],"bdatl":[[7,2.98,42],[8,3,3.53],[9,3.05,17.28],[1,2.8,19.74]],"id":42930960},{"atb":[[4.1,13.41],[4,40.37]],"atl":[[1000,121.51],[4.4,19.29],[4.5,19.37],[4.3,1.39]],"trd":[[4.3,8.32]],"bdatb":[[8,3.7,18.03],[9,3.65,7.32],[0,4.2,1.48],[1,4.1,16.04],[2,4,36.87],[3,3.95,46.34],[4,3.9,3.87],[5,3.85,9.36],[6,3.8,4.59],[7,3.75,2.52]],"bdatl":[[8,5.3,25.87],[0,4.4,22.05],[1,4.5,21.9],[2,4.6,17.78],[3,4.7,19.31],[4,4.8,1.97],[5,4.9,6.56],[6,5,15.96],[7,5.2,24.08],[9,5.4,35.77]],"tv":88.46,"id":40095374},{"atb":[[1.01,33656.53],[2.82,0],[2.84,0],[2.8,1.32],[2.54,4.58],[2.72,16.89],[2.74,17.52],[2.76,16.5],[2.78,3.27]],"atl":[[2.96,30.8],[2.84,2.03],[2.86,9.95],[1000,159.66],[2.92,20.27],[2.98,16.19],[2.88,12.32],[2.94,0],[2.9,9.21]],"trd":[[2.82,13.54],[2.84,28.65]],"bdatb":[[0,2.82,9.93],[1,2.8,1.32],[2,2.78,3.27],[3,2.76,18.75],[4,2.74,17.52],[5,2.72,22.96],[6,2.7,109.05],[7,2.68,16.32],[8,2.64,5.6],[9,2.62,3.76]],"bdatl":[[3,2.92,20.27],[0,2.84,10.44],[1,2.88,12.32],[2,2.9,9.21],[4,2.96,20.77],[5,2.98,16.19],[6,3.1,14.1],[7,3.15,25.16],[8,3.25,3.07],[9,3.3,38.42]],"ltp":2.82,"tv":294.44,"id":36276560},{"atb":[[1.01,40284.01]],"atl":[[1000,83.09]],"bdatb":[[8,4.4,69.28],[9,4.3,3.7],[2,5.1,14.58],[3,5,28.03],[4,4.9,17.02],[5,4.8,7.29],[6,4.6,4.22],[7,4.5,10.44]],"bdatl":[[8,6.4,3.41],[9,6.6,1.12],[7,6.2,4.57]],"id":37947503},{"atb":[[1.19,308.39],[1.2,95.23]],"atl":[[1.25,166.46],[1.23,58.88]],"trd":[[1.23,126.1]],"bdatb":[[5,1.17,41.95],[6,1.16,41.04],[7,1.15,18.87],[8,1.14,939.33],[9,1.13,43.73],[1,1.21,27.91],[2,1.2,114.16],[3,1.19,338.81],[4,1.18,209.07]],"bdatl":[[7,1.3,21.49],[8,1.31,101.47],[4,1.27,67.88],[5,1.28,78.86],[6,1.29,22.95],[9,1.32,3.5],[3,1.26,170.8],[2,1.25,166.46],[0,1.23,58.88]],"tv":1986.31,"id":39823721},{"atb":[[18,0],[1.01,41900.76]],"atl":[[26,6.84],[1000,26.02],[20,0]],"bdatb":[[2,16,9.77],[3,15.5,12.36],[4,15,9.57],[5,14.5,17],[6,14,7.73],[7,13.5,1.51],[8,13,6.36],[9,12.5,6.84],[0,17,11.05]],"bdatl":[[1,21,2.5],[8,36,5.99],[9,60,2.18]],"id":44331354}],"con":true,"tv":2963.54}]}
{"op":"mcm","clk":"AJRzAIRmAONm","pt":1650392764690,"mc":[{"id":"1.197931751","rc":[{"atb":[[2.58,31.04],[2.48,0],[2.66,52.63]],"atl":[[2.82,14.23]],"bdatb":[[8,2.6,65.74],[9,2.58,32.43],[1,2.74,2.97],[2,2.72,1.25],[3,2.7,4.11],[4,2.68,4.25],[5,2.66,54.9],[6,2.64,56.69],[7,2.62,34.94],[0,2.76,2.08]],"bdatl":[[2,2.82,14.23],[8,3.05,17.54],[9,3.1,15.88],[0,2.78,3.43]],"id":42930960},{"atb":[[3.95,37.36],[1.01,41714.14]],"atl":[[1000,119.74],[4.8,0],[4.6,19.79],[4.5,22],[4.3,4.18],[4.7,16.61]],"bdatb":[[4,3.9,3.03],[5,3.85,10.29],[6,3.8,2],[7,3.75,6.38],[8,3.7,15.06],[0,4.2,2.27],[1,4.1,16.94],[2,4,44.5],[3,3.95,43.51],[9,3.65,8.12]],"bdatl":[[5,4.9,6.76],[6,5,14.93],[7,5.1,1.96],[8,5.2,23.81],[9,5.3,24.26],[0,4.3,4.18],[2,4.5,22],[3,4.6,19.79],[4,4.7,16.61],[1,4.4,19.29]],"id":40095374},{"atb":[[1.01,32783.99],[2.78,9.87],[2.66,17.5],[2.76,18.59],[2.72,0],[2.8,0]],"atl":[[2.86,12.06],[2.94,0],[1000,155.79],[2.84,2.03],[2.9,10.04],[3.15,9.63],[2.92,33.78],[2.82,2.04],[2.88,14.87]],"bdatb":[[7,2.66,19.01],[8,2.64,6.96],[9,2.6,11.82],[0,2.8,3.41],[1,2.78,10.33],[2,2.76,21.18],[3,2.74,17.52],[4,2.72,2.22],[5,2.7,112.86],[6,2.68,9.15]],"bdatl":[[9,3.15,11.97],[2,2.86,12.06],[3,2.88,14.87],[4,2.9,10.04],[5,2.92,33.78],[6,2.96,30.8],[7,2.98,16.19],[8,3.1,14.1],[1,2.84,2.03],[0,2.82,2.04]],"id":36276560},{"atb":[[5.2,16.55],[5.1,14.84],[1.01,39610.17]],"atl":[[5.6,5.06],[5.4,4.45],[5.7,14.93],[5.8,8.21]],"bdatb":[[7,4.5,9.76],[9,4.3,10.5],[4,4.9,19.33],[5,4.8,7.36],[6,4.6,6.61],[8,4.4,66.69],[1,5.2,17.28],[2,5.1,15.23],[3,5,25.55],[0,5.3,3.09]],"bdatl":[[2,5.6,5.06],[0,5.4,4.45],[9,6.8,1.54],[3,5.7,14.93],[4,5.8,8.21],[8,6.4,2.93]],"id":37947503},{"atb":[[1.22,16.74],[1.19,155.49],[1.2,93.21]],"atl":[[1.3,26.89],[1.25,168.48],[1.26,150.8]],"bdatb":[[7,1.15,45.14],[8,1.14,946.44],[9,1.13,7.95],[0,1.22,24.56],[1,1.21,29.75],[2,1.2,112],[3,1.19,175.9],[6,1.16,31.64],[4,1.18,218.66],[5,1.17,27.1]],"bdatl":[[7,1.3,39.84],[8,1.31,116.03],[9,1.32,31.58],[6,1.29,19.96],[2,1.25,168.48],[3,1.26,150.8],[5,1.28,75.5],[4,1.27,65.46]],"id":39823721},{"atb":[[17,13.9]],"atl":[[28,9.56],[20,4],[19.5,7.12]],"bdatb":[[9,12.5,6.58],[0,17,14.45],[1,16.5,3.76],[2,16,10.18],[3,15.5,11.96],[4,15,8.47],[5,14.5,17.41],[6,14,8.46],[8,13,5.5],[7,13.5,1.45]],"bdatl":[[8,28,9.56],[1,20,4],[0,19.5,7.69],[2,21,2.5],[3,22,4.29],[4,24,5.87],[5,25,6.25],[6,26,6.84],[7,27,9.62],[9,36,5.91]],"id":44331354}],"con":true}]}
{"op":"mcm","clk":"AMx0AItnAO1n","pt":1650392765703,"mc":[{"id":"1.197931751","rc":[{"atb":[[2.68,47.56],[2.66,6.28],[2.46,13.7],[1.01,35502.34],[2.7,5.65],[2.1,9.81],[2.58,18.38],[2.6,50.81],[2.64,44.3],[2.72,0],[2.08,0],[2.74,0],[2.56,0]],"atl":[[3.05,23.82],[2.76,1.39],[2.78,9.03],[3.3,0],[2.72,3.09],[2.8,19.54]],"trd":[[2.72,73.9],[2.74,56.01],[2.76,20.16]],"bdatb":[[0,2.7,5.65],[2,2.66,11.88],[3,2.64,46.08],[5,2.6,53.12],[6,2.58,24.63],[7,2.54,121.78],[8,2.52,27.55],[9,2.5,10.15],[4,2.62,32.84],[1,2.68,45.53]],"bdatl":[[1,2.76,1.39],[2,2.78,9.03],[3,2.8,19.54],[4,2.82,14.23],[5,2.84,15.01],[6,2.88,15.67],[7,2.9,11.33],[8,2.92,3.55],[9,2.98,42],[0,2.72,3.09]],"ltp":2.72,"tv":514.13,"id":42930960},{"atb":[[3.95,39.36]],"atl":[[4.5,22],[4.3,1.65]],"trd":[[4.3,10.85]],"bdatb":[[3,3.9,6.55],[6,3.75,11.44],[8,3.65,2.63],[9,3.6,9.18],[4,3.85,11.05],[5,3.8,7.09],[1,4,41.33],[2,3.95,39.58],[0,4.1,15.46],[7,3.7,18.03]],"bdatl":[[9,5.3,24],[4,4.7,16.61],[5,4.9,7.74],[6,5,14.93],[7,5.1,7.21],[8,5.2,24.56],[2,4.5,22],[0,4.3,1.65]],"tv":90.99,"id":40095374},{"atb":[[2.74,34.07],[2.72,22.32],[2.76,8.9]],"atl":[[1000,151.72],[2.86,0.84],[2.9,21.76],[2.88,9.32],[2.84,0],[2.82,0]],"trd":[[2.84,30.46],[2.82,15.58]],"bdatb":[[6,2.66,24.26],[7,2.64,8.06],[8,2.62,7.38],[9,2.6,25.39],[4,2.72,23.73],[5,2.7,107.07],[0,2.8,2.53],[1,2.78,9.87],[2,2.76,9.38],[3,2.74,28.89]],"bdatl":[[0,2.88,10.16],[1,2.9,21.76],[5,3.1,16.53],[6,3.15,11.1],[7,3.2,12.42],[8,3.3,38.28],[9,3.35,12.17],[2,2.92,33.78],[3,2.96,30.8],[4,2.98,16.19]],"ltp":2.84,"tv":298.29,"id":36276560},{"atb":[[5.1,20.79]],"atl":[[5.5,3.23],[5.6,4.61],[5.4,2.43]],"trd":[[5.4,28.37]],"bdatb":[[5,4.8,10.11],[6,4.7,1.72],[7,4.6,11.87],[8,4.5,9.38],[9,4.4,75.75],[1,5.2,16.55],[2,5.1,22.18],[3,5,24.26],[4,4.9,10.04],[0,5.3,2]],"bdatl":[[1,5.5,3.23],[8,6.4,2.93],[9,6.6,1.63],[2,5.6,4.61],[0,5.4,2.43]],"tv":50.41,"id":37947503},{"atb":[[1.2,138.31],[1.23,0],[1.18,166.44],[1.22,45.81],[1.21,36.96]],"atl":[[1.31,115],[1000,394.24],[1.26,152.82],[1.25,166.46],[1.27,45.46],[1.23,0]],"trd":[[1.23,188.54]],"bdatb":[[0,1.22,51.62],[1,1.21,38.05],[3,1.19,162.3],[4,1.18,212.72],[5,1.17,48.56],[6,1.16,41.04],[2,1.2,135.67],[7,1.15,14.03],[8,1.14,933.3],[9,1.13,28.49]],"bdatl":[[8,1.32,34.6],[1,1.25,166.46],[2,1.26,152.82],[3,1.27,45.46],[9,1.33,27.33],[0,1.24,171.56],[4,1.28,81.38],[5,1.29,27.17],[6,1.3,48.08],[7,1.31,95.21]],"tv":2048.75,"id":39823721},{"atb":[[15,8.47],[1.01,41405.25],[17.5,2.61],[14.5,14.85],[18.5,0.58],[15.5,13.34],[16.5,4.93],[18,2.47]],"atl":[[30,8.62],[1000,25.24],[19.5,7.34],[19,0],[27,0],[25,0]],"trd":[[19,0.57]],"bdatb":[[1,17.5,2.61],[3,16.5,4.93],[5,15.5,13.34],[7,14.5,14.85],[8,14,7.29],[2,17,14.04],[4,16,10.07],[6,15,8.56],[9,13.5,1.74],[0,18,3.05]],"bdatl":[[8,60,2.18],[0,19.5,7.34],[9,1000,25.66],[5,26,6.84],[6,28,9.56],[7,36,5.91]],"ltp":19,"tv":40.58,"id":44331354}],"con":true,"tv":3043.15}]}
{"op":"mcm","clk":"AOp1AItoAO1o","pt":1650392766728,"mc":[{"id":"1.197931751","rc":[{"atb":[[2.64,22.1],[2.68,21.79],[2.1,0],[2.6,32.65],[1.01,35153.93],[2.7,0],[2.62,14.92]],"atl":[[2.76,6.09],[2.7,0],[2.78,13.95],[2.74,2.11],[1000,179.63]],"trd":[[2.7,80.12]],"bdatb":[[2,2.64,24.79],[0,2.68,21.79],[4,2.6,36.75],[8,2.52,25.1],[9,2.5,11.66],[6,2.56,8.49],[7,2.54,121.91],[1,2.66,6.28],[3,2.62,14.92],[5,2.58,19.96]],"bdatl":[[2,2.76,6.09],[0,2.72,3.09],[1,2.74,2.11],[3,2.78,13.95],[4,2.8,19.54],[5,2.82,14.23],[6,2.84,15.01],[7,2.88,15.67],[8,2.9,11.33],[9,2.92,3.55]],"ltp":2.7,"tv":527.63,"id":42930960},{"atl":[[4.4,22.15]],"bdatb":[[2,3.95,40.39],[3,3.9,4.35],[4,3.85,12.63],[6,3.75,9.76],[7,3.7,13.7],[8,3.65,5.11],[9,3.6,5.96],[0,4.1,15.46],[1,4,42.71],[5,3.8,9.3]],"bdatl":[[5,4.8,2.21],[6,4.9,5.86],[7,5,14],[8,5.1,8.18],[9,5.2,24.71],[1,4.4,22.15]],"id":40095374},{"atb":[[2.7,123.83],[2.72,5.43],[2.76,14.29],[2.78,5.14],[1.01,32188.26]],"atl":[[2.88,17.18],[2.9,20.29],[2.92,37.42],[2.86,7.63]],"bdatb":[[3,2.72,5.91],[4,2.7,125.98],[6,2.66,22.48],[7,2.64,10.36],[8,2.62,10],[9,2.6,23.59],[1,2.76,16.86],[0,2.78,5.14],[5,2.68,1.42],[2,2.74,34.07]],"bdatl":[[6,3.1,16.57],[7,3.15,10.03],[8,3.2,13.43],[9,3.25,1.05],[1,2.88,17.18],[2,2.9,20.29],[3,2.92,37.42],[0,2.86,7.63],[4,2.96,30.8],[5,2.98,16.19]],"id":36276560},{"atb":[[5.1,22.85]],"atl":[[5.7,9.97],[5.4,0]],"bdatb":[[4,4.9,12.51],[5,4.8,15.76],[6,4.6,7.55],[7,4.5,14.98],[8,4.4,67.71],[9,4.2,10.95],[2,5.1,24.24],[1,5.2,16.55],[3,5,24.52]],"bdatl":[[8,6.6,1.82],[9,7,5.98],[2,5.7,9.97],[0,5.5,3.23],[1,5.6,4.61],[3,5.8,8.21],[4,5.9,3.36],[5,6,9.59],[6,6.2,4.57],[7,6.4,2.93]],"id":37947503},{"atb":[[1.18,166.44],[1.23,9.76],[1.19,308.39],[1.21,81.13],[1.2,113.97]],"atl":[[1.26,152.82],[1.25,179.01],[1.24,142.97]],"trd":[[1.23,208.06]],"bdatb":[[5,1.18,195.9],[0,1.23,9.76],[1,1.22,51.62],[2,1.21,86.99],[3,1.2,127.98],[4,1.19,340.97],[6,1.17,36.07],[7,1.16,34],[8,1.15,33.85],[9,1.14,950.5]],"bdatl":[[2,1.26,152.82],[9,1.33,31.74],[6,1.3,58.19],[7,1.31,117.62],[8,1.32,24.88],[1,1.25,179.01],[5,1.29,25.2],[4,1.28,73.1],[0,1.24,142.97]],"tv":2068.27,"id":39823721},{"atb":[[18,4.47],[17,17.66],[16.5,1.94]],"atl":[[19.5,7.34]],"bdatb":[[0,18,5.05],[3,16.5,1.94],[4,16,10.22],[7,14.5,14.94],[8,14,7.7],[9,13.5,1.72],[1,17.5,2.61],[2,17,17.66],[5,15.5,13.34],[6,15,8.47]],"bdatl":[[9,60,2.24],[0,19.5,7.34],[7,30,8.62],[8,36,5.91]],"id":44331354}],"con":true,"tv":3076.17}]}
{"op":"mcm","clk":"AJ93AJppAPdp","pt":1650392767729,"mc":[{"id":"1.197931751","rc":[{"atb":[[2.08,0],[2.68,4.28],[2.62,21.03],[2.66,5.47],[2.64,10.39]],"atl":[[2.72,0],[4.1,0],[2.96,4.65],[2.8,13.45]],"bdatb":[[0,2.68,4.28],[1,2.66,5.47],[2,2.64,13.08],[3,2.62,21.03],[7,2.54,115.48],[8,2.52,23.14],[9,2.5,19.39]],"bdatl":[[9,2.96,4.65],[0,2.74,2.11],[1,2.76,6.09],[2,2.78,13.95],[3,2.8,13.45],[4,2.82,14.23],[5,2.84,15.01],[6,2.88,15.67],[7,2.9,11.33],[8,2.92,3.55]],"id":42930960},{"atb":[[2.72,22.32]],"atl":[[2.9,29.57],[2.88,19.89],[2.92,33.78]],"bdatb":[[1,2.76,14.29],[2,2.74,36.18],[4,2.7,123.83],[5,2.68,4.07],[6,2.66,19.32],[7,2.64,13.55],[9,2.6,14.28],[3,2.72,22.8],[8,2.62,4.35]],"bdatl":[[2,2.9,29.57],[6,3.1,13.11],[7,3.15,12.99],[8,3.2,4.82],[9,3.25,8.44],[1,2.88,19.89],[3,2.92,33.78]],"id":36276560},{"atl":[[5.7,2]],"bdatb":[[8,4.5,16.98],[9,4.4,65.67],[2,5.1,23.99],[3,5,24.53],[4,4.9,12.78],[5,4.8,14.01],[6,4.7,3.78],[7,4.6,5.53]],"bdatl":[[8,6.8,1.69],[9,7.2,22.84],[2,5.7,2]],"id":37947503},{"atb":[[1.23,0]],"bdatb":[[0,1.22,45.81],[1,1.21,86.99],[2,1.2,126.88],[3,1.19,335.59],[4,1.18,203.78],[5,1.17,18.89],[6,1.16,34.12],[7,1.15,35.49],[8,1.14,953.97],[9,1.13,4.19]],"bdatl":[[5,1.29,23.01],[6,1.3,38.08],[7,1.31,136.16],[8,1.33,32.28],[9,1.34,44.83]],"id":39823721},{"atl":[[26,4.44],[24,4.13]],"bdatb":[[4,16,9.77],[6,15,8.86],[8,14,7.29],[9,13.5,2.24]],"bdatl":[[4,24,4.13],[5,26,4.44],[9,60,2]],"id":44331354},{"bdatb":[[9,3.6,4.65],[0,4.1,13.41],[1,4,44.81],[3,3.9,2.2],[4,3.85,14.81],[5,3.8,6.68],[6,3.75,6.73],[7,3.7,12.57],[8,3.65,6.41]],"bdatl":[[5,4.9,7.74],[6,5,14.03],[7,5.2,26.77],[8,5.3,29.18],[9,5.4,34.54]],"id":40095374}],"con":true}]}
{"op":"mcm","clk":"ANp4AKBqANxq","pt":1650392768729,"mc":[{"id":"1.197931751","rc":[{"atb":[[1.01,34810.26],[2.68,2],[2.62,32.84],[2.7,0],[2.1,9.19]],"atl":[[2.7,2.26],[1000,177.59],[2.72,3.25],[2.76,9.76],[2.78,33.76]],"trd":[[2.7,82.12]],"bdatb":[[0,2.68,2],[3,2.62,32.84],[1,2.66,5.47],[2,2.64,13.08],[4,2.6,36.75],[5,2.58,19.96],[6,2.56,8.49],[7,2.54,115.48],[8,2.52,23.14],[9,2.5,19.39]],"bdatl":[[0,2.7,2.26],[1,2.72,3.25],[2,2.74,2.11],[3,2.76,9.76],[4,2.78,33.76],[5,2.8,13.45],[6,2.82,14.23],[7,2.84,15.01],[8,2.88,15.67],[9,2.9,11.33]],"tv":529.63,"id":42930960},{"atb":[[1.22,60.17],[1.21,64.37]],"atl":[[1.26,150.8]],"bdatb":[[0,1.22,65.98],[1,1.21,73.17],[2,1.2,135.49],[3,1.19,317.97],[6,1.16,53.21],[7,1.15,21.19],[4,1.18,208.45],[5,1.17,29.47],[8,1.14,937.44],[9,1.13,16.59]],"bdatl":[[5,1.29,22.34],[6,1.3,34.05],[7,1.31,140.83],[9,1.34,44.83],[8,1.33,32.28],[4,1.28,73.1],[2,1.26,150.8]],"id":39823721},{"atl":[[28,7.7]],"bdatb":[[3,16.5,2.31],[4,16,9.84],[6,15,8.47],[7,14.5,15.39],[8,14,7.49],[9,13.5,1.67]],"bdatl":[[6,28,7.7],[9,60,2]],"id":44331354},{"bdatb":[[0,4.1,17.05],[1,4,41.82],[2,3.95,39.64],[3,3.9,7.57],[4,3.85,10.43],[5,3.8,10.28],[9,3.6,9.48],[6,3.75,8.26],[7,3.7,12.55],[8,3.65,5.68]],"bdatl":[[5,4.9,6.67],[6,5,15.05],[7,5.2,25.61],[9,5.4,38.92]],"id":40095374},{"bdatb":[[0,2.78,7.33],[1,2.76,14.65],[2,2.74,34.07],[3,2.72,25.21],[4,2.7,124.87],[5,2.68,1.2],[6,2.66,26.08],[7,2.64,7.15],[8,2.62,2.79],[9,2.6,30.14]],"bdatl":[[8,3.2,2.91],[6,3.1,13.11],[7,3.15,12.99],[9,3.25,8.44]],"id":36276560},{"bdatb":[[1,5.2,17.72],[2,5.1,23.05],[3,5,25.83],[4,4.9,11.18],[7,4.6,8.04],[8,4.5,17.24],[9,4.4,57],[5,4.8,17.71],[6,4.7,5.41]],"bdatl":[[8,7,2.07],[9,7.2,21.59]],"id":37947503}],"con":true,"tv":3078.17}]}
{"op":"mcm","clk":"ALh6AMBrAIts","pt":1650392769732,"mc":[{"id":"1.197931751","rc":[{"atb":[[2.5,23.33],[2.66,2.35],[1.01,34465.07],[2.54,98],[2.68,0],[2.62,14.92]],"atl":[[2.72,7.92],[2.76,5.06],[2.78,28.84],[2.7,7.28],[2.68,0],[2.74,18.29],[3.15,0]],"trd":[[2.7,84.21],[2.68,165.57]],"bdatb":[[3,2.6,33.21],[4,2.58,20.57],[5,2.56,1.95],[8,2.5,27.79],[9,2.48,14.71],[6,2.54,108.16],[7,2.52,18.08],[0,2.66,2.35],[1,2.64,10.39],[2,2.62,14.92]],"bdatl":[[1,2.72,7.92],[3,2.76,5.06],[4,2.78,28.84],[0,2.7,7.28],[2,2.74,18.29],[5,2.8,13.45],[6,2.82,14.23],[7,2.84,15.01],[8,2.88,15.67],[9,2.9,11.33]],"ltp":2.7,"tv":535.72,"id":42930960},{"atl":[[4.3,0.34]],"trd":[[4.3,12.16]],"bdatb":[[2,3.95,45.9],[3,3.9,2.85],[4,3.85,11.47],[5,3.8,4.93],[6,3.75,10.24],[7,3.7,10.96],[8,3.65,3.14],[9,3.6,5.76],[0,4.1,13.41],[1,4,43.4]],"bdatl":[[4,4.8,1.3],[5,4.9,6.47],[6,5,14.88],[7,5.2,32.69],[8,5.3,24],[9,5.4,36.24],[0,4.4,22.49],[1,4.5,22],[2,4.6,19.79],[3,4.7,16.61]],"tv":92.3,"id":40095374},{"atb":[[2.76,2.08],[2.74,28.89],[2.72,16.89],[2.78,0]],"atl":[[2.84,2.5],[2.86,18.65],[2.9,13.08]],"trd":[[2.76,24.92],[2.78,15.75]],"bdatb":[[0,2.76,2.08],[1,2.74,29.42],[2,2.72,16.89],[5,2.66,24.35],[6,2.64,6.85],[7,2.62,3.09],[8,2.6,27.99],[9,2.58,2.17],[3,2.7,127.77],[4,2.68,2.92]],"bdatl":[[0,2.84,2.5],[1,2.86,18.65],[2,2.88,19.89],[3,2.9,13.08],[4,2.92,33.78],[5,2.96,30.8],[6,2.98,16.19],[7,3.05,3.48],[8,3.1,14.52],[9,3.15,9.63]],"ltp":2.76,"tv":329.24,"id":36276560},{"atl":[[5.5,2.2]],"trd":[[5.5,7.15]],"bdatb":[[2,5.1,23.14],[3,5,25.39],[4,4.9,12.34],[5,4.8,14.27],[6,4.7,8.18],[7,4.6,1.39],[8,4.5,16.45],[9,4.4,67.9],[0,5.3,2],[1,5.2,16.55]],"bdatl":[[7,6.4,3.83],[8,6.8,1.38],[9,7,2.67],[0,5.5,2.2]],"ltp":5.5,"tv":51.44,"id":37947503},{"atb":[[1.24,12.08],[1.22,87.34],[1.2,90.89],[1.23,37.54]],"atl":[[1.25,185.2],[1.24,0],[1.26,152.82]],"trd":[[1.24,339.43]],"bdatb":[[1,1.23,38.73],[2,1.22,96.05],[3,1.21,85.71],[4,1.2,100.39],[5,1.19,348.41],[6,1.18,168.11],[7,1.17,30.27],[8,1.16,53.04],[0,1.24,12.08],[9,1.15,20.53]],"bdatl":[[8,1.33,22.5],[9,1.34,23.56],[0,1.25,185.2],[1,1.26,152.82],[2,1.27,45.46],[3,1.28,73.1],[4,1.29,14.12],[5,1.3,35.04],[6,1.31,132.62],[7,1.32,16.14]],"ltp":1.24,"tv":2072.82,"id":39823721},{"atl":[[30,5.17],[19.5,7.05]],"trd":[[19.5,0.29]],"bdatb":[[5,15.5,13.43],[6,15,8.47],[7,14.5,15.24],[8,14,7.64],[1,17.5,2.61],[3,16.5,1.94],[9,13.5,1.45],[4,16,9.77]],"bdatl":[[7,30,5.17],[9,60,2.2],[0,19.5,7.05]],"ltp":19.5,"tv":40.87,"id":44331354}],"con":true,"tv":3122.39}]}
{"op":"mcm","clk":"AP57ANVsAJxt","pt":1650392770733,"mc":[{"id":"1.197931751","rc":[{"atb":[[2.58,18.38],[2.56,32.81],[2.62,4.5],[2.6,20.16],[2.1,0],[2.64,8.04]],"atl":[[2.72,24.84],[2.78,41.96],[2.74,39.92],[2.7,6.75],[2.96,0],[2.98,52.1],[3.2,0],[2.82,6.98]],"trd":[[2.7,84.75]],"bdatb":[[5,2.56,32.81],[8,2.5,38.31],[9,2.48,4.25],[0,2.66,4.36],[1,2.64,10.11],[2,2.62,4.96],[4,2.58,2.15],[3,2.6,20.16],[6,2.54,103.75],[7,2.52,13.55]],"bdatl":[[2,2.74,39.92],[4,2.78,41.96],[0,2.7,6.75],[1,2.72,14.92],[7,2.84,15.01],[6,2.82,6.98]],"tv":536.26,"id":42930960},{"atb":[[4.2,1],[1.01,41161.3]],"atl":[[4.3,3.79],[4.4,22.17],[4.6,19.79],[4.8,6.7],[4.5,24.01],[1000,118]],"trd":[[4.3,12.5]],"bdatb":[[5,3.85,16.28],[6,3.8,4.85],[7,3.75,4.81],[8,3.7,8.17],[9,3.65,6.55],[0,4.2,1.27],[1,4.1,15.15],[2,4,41.81],[3,3.95,42.89],[4,3.9,2]],"bdatl":[[1,4.4,22.17],[3,4.6,19.79],[5,4.8,8],[0,4.3,2.79],[2,4.5,24.01],[4,4.7,16.61],[6,4.9,6.94],[7,5,16.91],[8,5.1,4.11],[9,5.2,23.81]],"tv":92.64,"id":40095374},{"atb":[[2.64,23.31],[2.74,22.73],[2.72,14.04],[2.7,120.46],[1.01,31021.37],[2.66,0],[2.82,0],[2.56,2],[2.76,4.69]],"atl":[[2.86,16.5],[1000,150.86],[2.88,23.88],[2.92,36.84],[2.82,2.53],[2.8,1.91],[2.84,3.5]],"trd":[[2.8,2.52],[2.82,17.58]],"bdatb":[[2,2.72,14.04],[3,2.7,122.51],[4,2.66,5.58],[5,2.64,5.6],[6,2.62,10.16],[7,2.6,20.03],[8,2.58,1.4],[9,2.56,2],[0,2.76,8.6],[1,2.74,31.93]],"bdatl":[[3,2.86,16.5],[4,2.88,23.88],[6,2.92,36.84],[9,3.1,21.97],[1,2.82,2.53],[2,2.84,3.5],[5,2.9,13.08],[7,2.96,30.8],[8,2.98,16.19],[0,2.8,1.91]],"ltp":2.8,"tv":331.76,"id":36276560},{"atb":[[5.3,1],[5,38.27],[5.1,20.79],[5.2,14.93],[1.01,38829.29]],"atl":[[5.4,3],[1000,83.09],[5.8,8.27],[6.2,11.12],[5.9,4.66],[13,0],[5.7,0],[5.3,0],[5.6,2.61],[5.5,1.23]],"trd":[[5.3,15.16]],"bdatb":[[2,5.1,20.79],[3,5,42.94],[5,4.8,15.61],[6,4.7,3.01],[7,4.6,5.6],[8,4.5,15.71],[9,4.4,65.62],[0,5.3,1.01],[1,5.2,16.21],[4,4.9,10.63]],"bdatl":[[3,5.8,8.27],[6,6.2,11.12],[4,5.9,4.66],[0,5.4,2],[1,5.5,1.23],[2,5.6,2.61],[5,6,9.59],[7,6.4,3.91],[8,6.6,1.01],[9,6.8,3.87]],"ltp":5.3,"tv":62.1,"id":37947503},{"atb":[[1.21,81.48],[1.2,235.52],[1.24,39.07],[1.19,288.39]],"atl":[[1.26,63.1],[1.25,58.71],[1.27,142.79],[1.31,106.41],[1.32,11.41],[1.3,18.3],[1000,378.36],[1.28,53.1]],"trd":[[1.25,449.98]],"bdatb":[[3,1.21,93.56],[4,1.2,257.71],[5,1.19,329.46],[6,1.18,168.01],[7,1.17,61.77],[8,1.16,18.88],[9,1.15,30.81],[0,1.24,47.78],[1,1.23,38.51],[2,1.22,91.89]],"bdatl":[[5,1.3,23.11],[6,1.31,122.61],[7,1.32,32.25],[0,1.25,67.01],[1,1.26,175.6],[8,1.33,17.04],[9,1.34,25.25],[3,1.28,53.1]],"ltp":1.25,"tv":2073.99,"id":39823721},{"atb":[[9.6,0]],"atl":[[34,7.58],[19.5,6.98]],"trd":[[19.5,0.36]],"bdatb":[[0,18,5.35],[2,17,17.98],[3,16.5,1.94],[4,16,9.85],[5,15.5,13.34],[6,15,8.51],[7,14.5,15.2],[8,14,7.29],[9,13.5,1.5],[1,17.5,2.61]],"bdatl":[[8,34,7.58],[9,36,5.91],[0,19.5,6.98]],"tv":40.94,"id":44331354}],"con":true,"tv":3137.69}]}
{"op":"mcm","clk":"AL19AONtAKJu","pt":1650392771735,"mc":[{"id":"1.197931751","rc":[{"atb":[[2.5,10],[2.62,6.87],[2.6,77.83],[2.64,7.73],[2.66,0]],"atl":[[2.74,34.32],[2.78,22.15],[2.72,27.71]],"bdatb":[[0,2.64,7.73],[1,2.62,6.87],[2,2.6,79.89],[3,2.58,18.93],[4,2.56,35.05],[5,2.54,99.5],[6,2.52,13.55],[7,2.5,25.36],[8,2.48,4.6],[9,2.46,32.3]],"bdatl":[[2,2.74,34.32],[6,2.82,8.47],[8,2.86,2.28],[9,2.88,16.11],[1,2.72,27.71],[4,2.78,22.15]],"id":42930960},{"atb":[[3.9,2]],"atl":[[4.8,0],[1000,116.3]],"bdatb":[[1,4.1,13.41],[2,4,42.06],[3,3.95,40.81],[4,3.9,3.47],[5,3.85,10.18],[6,3.8,5],[7,3.75,14.2],[8,3.7,10.57],[9,3.65,4.11],[0,4.2,1]],"bdatl":[[6,5,14.9],[7,5.1,6.83],[4,4.7,19.16],[5,4.9,6.37],[8,5.2,24.81],[9,5.3,24],[0,4.3,3.79]],"id":40095374},{"atb":[[2.68,9.05],[1.01,30440.6]],"atl":[[3.15,0],[2.9,19.31],[1000,145.2],[2.88,17.18],[2.84,7.06],[2.86,20.46]],"bdatb":[[4,2.68,9.05],[1,2.74,22.73],[2,2.72,14.04],[3,2.7,122.96],[5,2.66,3.59],[6,2.64,23.31],[7,2.62,1.93],[8,2.6,11.82],[9,2.58,4.42],[0,2.76,4.69]],"bdatl":[[7,2.94,1.43],[8,2.96,30.8],[9,2.98,16.19],[5,2.9,19.31],[4,2.88,17.18],[2,2.84,7.06],[3,2.86,20.46]],"id":36276560},{"atb":[[5.3,5.33],[5.2,12.55],[5,24.26]],"atl":[[12.5,1.12],[5.8,7.89],[5.7,2],[1000,81.29],[6.2,4.57],[5.4,0]],"trd":[[5.4,34.37]],"bdatb":[[1,5.2,12.55],[9,4.4,69.73],[0,5.3,3],[2,5.1,21.84],[3,5,25.69],[4,4.9,10.55],[5,4.8,9.16],[6,4.7,12.45],[8,4.5,15.23],[7,4.6,4.95]],"bdatl":[[9,7,2.97],[5,6,10.29],[7,6.4,4.15],[8,6.8,3.88],[6,6.2,4.57],[3,5.8,7.89],[2,5.7,2],[4,5.9,4.66],[0,5.5,1.23],[1,5.6,2.61]],"ltp":5.4,"tv":68.1,"id":37947503},{"atb":[[1.21,219.82],[1.25,0],[1.22,72.98],[1.23,51.48]],"atl":[[1000,363.72],[1.28,55.19],[1.25,0],[1.26,164.06]],"trd":[[1.25,503.64]],"bdatb":[[9,1.16,28.69],[0,1.25,9.6],[1,1.24,39.07],[2,1.23,61.63],[3,1.22,76.11],[4,1.21,94.9],[5,1.2,273.85],[6,1.19,311.51],[7,1.18,173.03],[8,1.17,56.72]],"bdatl":[[5,1.31,112.11],[6,1.32,37.81],[8,1.34,31.19],[9,1.35,23.9],[0,1.26,164.06],[1,1.27,142.79],[2,1.28,53.1],[3,1.29,17.38],[4,1.3,25.03],[7,1.33,2.95]],"tv":2127.65,"id":39823721},{"atb":[[18,2.47]],"atl":[[19.5,8.98]],"bdatb":[[2,17,17.66],[4,16,9.77],[5,15.5,13.69],[6,15,8.47],[7,14.5,14.94],[8,14,7.7],[9,13.5,1.74],[0,18,3.05],[3,16.5,1.94]],"bdatl":[[8,34,7.71],[9,36,5.91],[0,19.5,8.98]],"id":44331354}],"con":true,"tv":3197.35}]}
{"op":"mcm","clk":"AOZ+AN9uAKhv","pt":1650392772736,"mc":[{"id":"1.197931751","rc":[{"atb":[[2.58,29.86],[2.6,30.62],[2.44,102],[2.54,0],[2.66,1],[2.64,5.71],[2.38,14.49]],"atl":[[2.74,41.43],[2.82,4.59],[2.98,10.1],[2.9,54.33],[2.68,1]],"bdatb":[[4,2.58,32.48],[3,2.6,30.62],[6,2.54,3.61],[0,2.66,1],[1,2.64,5.71],[2,2.62,6.87],[5,2.56,32.96],[7,2.52,13.55],[8,2.5,12.03],[9,2.48,4.6]],"bdatl":[[7,2.82,8.47],[9,2.86,2.28],[0,2.68,1],[1,2.7,6.75],[2,2.72,27.71],[3,2.74,39.35],[4,2.76,5.06],[5,2.78,22.15],[6,2.8,13.45],[8,2.84,15.01]],"id":42930960},{"atb":[[3.55,0],[3.6,69]],"bdatb":[[7,3.75,16.12],[8,3.7,9.06],[9,3.65,7.54],[4,3.9,5.53],[5,3.85,9.49],[3,3.95,39.46]],"bdatl":[[3,4.6,20.37],[4,4.7,18.59],[5,4.9,6.75],[6,5,16.1],[7,5.1,4.51],[8,5.2,24.58],[9,5.3,24.98]],"id":40095374},{"atb":[[2.7,44.55],[2.72,16.31],[2.68,18.01],[2.56,100],[2.74,13.97]],"atl":[[3.3,0],[3,42],[2.8,0]],"bdatb":[[4,2.68,18.01],[3,2.7,28.96],[2,2.72,15.03],[1,2.74,13.97],[7,2.62,1.93]],"bdatl":[[5,2.92,37.75],[6,2.96,31.32],[7,2.98,16.19],[8,3,44.18],[9,3.1,18.77],[0,2.82,2.53],[1,2.84,7.06],[2,2.86,20.46],[3,2.88,17.18],[4,2.9,19.31]],"id":36276560},{"atb":[[4.4,0],[5.3,5.33],[4.3,58]],"atl":[[5.8,10.32],[7,18],[7.2,0],[5.6,2.61],[12.5,0]],"bdatb":[[0,5.3,5.33],[9,4.4,15.66],[2,5.1,21.32],[3,5,25.15],[4,4.9,11.65],[5,4.8,8.04],[7,4.6,6.11],[8,4.5,14.04]],"bdatl":[[3,5.8,10.32],[4,5.9,5.12],[5,6,9.85],[6,6.2,4.57],[7,6.4,4.15],[8,6.8,3.49],[9,7,20.21],[1,5.6,2.61]],"id":37947503},{"atb":[[1.23,69.77],[1.14,714.29],[1.25,9.6],[1.16,220.28],[1.2,235.52]],"atl":[[1.27,158.63],[1.28,55.19],[1.34,107.78],[1.31,11.41]],"bdatb":[[5,1.2,284.28],[6,1.19,312.02],[7,1.18,171.8],[8,1.17,63.36],[0,1.25,9.6],[1,1.24,39.07],[2,1.23,57.28],[3,1.22,80.49],[4,1.21,228.82],[9,1.16,244.69]],"bdatl":[[2,1.28,55.19],[5,1.31,23.09],[6,1.32,28.82],[8,1.34,130.35],[9,1.35,8.52],[7,1.33,5.98]],"id":39823721},{"atb":[[13,22.63],[12,0]],"atl":[[26,2.84],[25,1.67],[28,3.7],[36,8.91]],"bdatb":[[5,15.5,13.51],[7,14.5,15.13],[8,14,7.31],[9,13.5,2.13]],"bdatl":[[5,25,1.67],[6,26,4.44],[7,28,3.7],[8,30,5.26],[9,34,7.63]],"id":44331354}],"con":true}]}
{"op":"mcm","clk":"AKKAAQDibwCdcA==","pt":1650392773738,"mc":[{"id":"1.197931751","rc":[{"atb":[[2.58,18.38]],"bdatb":[[4,2.58,21]],"bdatl":[[7,2.82,4.59],[9,2.86,1.47],[3,2.74,41.43]],"id":42930960},{"atb":[[5.3,5.33]],"atl":[[5.8,7.89]],"bdatb":[[0,5.3,5.33],[9,4.4,16.26]],"bdatl":[[3,5.8,7.89],[4,5.9,4.66],[5,6,9.59],[6,6.2,5],[7,6.4,3.17],[8,6.6,1.32],[9,6.8,3.35]],"id":37947503},{"atb":[[1.23,114.6],[1.25,0],[1.21,192.41]],"atl":[[1.28,53.1]],"bdatb":[[1,1.23,120.4],[4,1.2,278.3],[5,1.19,311.51],[6,1.18,173.03],[7,1.17,56.72],[9,1.15,16.31],[0,1.24,39.07],[2,1.22,80.49],[3,1.21,201.41],[8,1.16,244.69]],"bdatl":[[5,1.31,23.09],[6,1.32,28.82],[8,1.34,133.4],[9,1.35,5.49],[2,1.28,53.1],[1,1.27,158.63]],"id":39823721},{"bdatb":[[7,3.75,14.2],[8,3.7,9.13],[9,3.65,5.57]],"bdatl":[[6,4.9,7.01],[7,5,16.1],[8,5.1,3.96],[3,4.6,19.79],[4,4.7,16.61],[5,4.8,2.24],[9,5.2,23.81]],"id":40095374},{"bdatb":[[2,2.72,17.3],[3,2.7,46.05]],"bdatl":[[5,2.92,36.84],[6,2.96,30.8],[7,2.98,17.08],[8,3,42.51],[9,3.05,2.14]],"id":36276560},{"bdatl":[[8,30,5.17],[9,34,7.58],[6,26,2.84]],"id":44331354}],"con":true}]}
{"op":"mcm","clk":"ANGBAQDlcACwcQ==","pt":1650392774741,"mc":[{"id":"1.197931751","rc":[{"atl":[[2.74,49.12]],"bdatl":[[3,2.74,49.12]],"id":42930960},{"atl":[[5.9,6.94]],"bdatb":[[9,4.4,8.05]],"bdatl":[[4,5.9,6.94]],"id":37947503},{"atl":[[1.26,135.4]],"bdatb":[[5,1.19,318.05],[6,1.18,171.22],[7,1.17,63.36]],"bdatl":[[0,1.26,135.4]],"id":39823721},{"bdatb":[[9,3.65,9.25]],"id":40095374}],"con":true}]}
{"op":"mcm","clk":"APiCAQDdcQDOcg==","pt":1650392775743,"mc":[{"id":"1.197931751","rc":[{"atb":[[17.5,0.61],[18,1.4],[18.5,0]],"trd":[[18.5,2.32],[18,6.28]],"bdatb":[[1,17,18.27],[2,16.5,1.94],[3,16,9.77],[4,15.5,13.51],[5,15,8.47],[6,14.5,15.13],[7,14,7.31],[8,13.5,2.13],[9,13,22.63],[0,18,1.4]],"ltp":18,"tv":44.24,"id":44331354},{"bdatl":[[9,2.88,17.13]],"id":42930960},{"bdatl":[[5,4.9,9.2],[6,5,16.1],[7,5.1,1.47],[8,5.2,26.25],[9,5.3,24]],"id":40095374},{"bdatl":[[7,2.98,16.19],[8,3,42.89],[9,3.1,20.41]],"id":36276560},{"bdatl":[[9,6.8,1.82]],"id":37947503},{"bdatl":[[6,1.32,17.08],[7,1.33,17.62],[9,1.35,1.54]],"id":39823721}],"con":true,"tv":3200.65}]}
{"op":"mcm","clk":"AJKFAQD1cgDlcw==","pt":1650392777045,"mc":[{"id":"1.197931751","rc":[{"atb":[[2.62,6.58],[2.66,0],[2.64,0]],"atl":[[2.72,20.71],[2.9,49.83],[2.92,0]],"trd":[[2.62,0.58],[2.66,31.42],[2.64,90.41]],"bdatb":[[5,2.56,34.4],[6,2.54,2.15]],"ltp":2.62,"tv":550.26,"id":42930960},{"atb":[[3.95,54.51]],"bdatb":[[3,3.95,55.55],[4,3.9,4.58]],"bdatl":[[6,5,15.51],[7,5.2,28.27],[8,5.3,24],[9,5.4,34.61]],"id":40095374},{"atb":[[1.18,5.05]],"bdatb":[[0,1.24,41.23],[1,1.23,118.22],[6,1.18,9.83]],"bdatl":[[5,1.31,20.83],[6,1.32,19.33]],"id":39823721},{"atb":[[17,13.9],[17.5,0],[16.5,5.71]],"atl":[[19,0.57]],"bdatb":[[1,17,13.9],[2,16.5,5.71]],"bdatl":[[0,19.5,9.55]],"id":44331354},{"bdatb":[[4,2.68,19.53],[5,2.66,2.06]],"id":36276560},{"bdatb":[[3,5,25.89],[4,4.9,10.89]],"id":37947503}],"con":true,"tv":3214.65}]}
{"op":"mcm","clk":"AM6GAQCBdAD8dA==","pt":1650392778046,"mc":[{"id":"1.197931751","rc":[{"atb":[[2.02,0],[2.56,85.25],[2.6,22.16],[2.54,1968.5],[2.58,0],[2.46,6.29],[2.38,6.29]],"atl":[[2.74,43.37],[2.68,8.2],[2.72,22.71],[3.05,18.25],[2.98,4.19],[3.1,7.39]],"bdatb":[[3,2.56,86.84],[8,2.46,10.61],[9,2.44,102],[1,2.6,22.16],[4,2.54,1970.65],[2,2.58,2.62],[0,2.62,6.58],[5,2.52,13.55],[6,2.5,12.03],[7,2.48,4.6]],"bdatl":[[3,2.74,43.37],[0,2.68,8.2],[2,2.72,22.71]],"id":42930960},{"atb":[[3.45,1490.1]],"atl":[[5.4,0],[5.2,0],[5.6,0],[5,4],[4.9,15.84]],"bdatb":[[7,3.75,2.86],[8,3.7,7.19],[9,3.65,9.62],[2,4,43.08],[3,3.95,57.18],[4,3.9,2.16],[5,3.85,12.17],[6,3.8,3.95]],"bdatl":[[6,5,4.59],[7,5.1,1.84],[8,5.2,4.45],[5,4.9,18.48],[9,5.3,24]],"id":40095374},{"atb":[[2.34,2136.75]],"bdatb":[[8,2.56,101.25],[9,2.54,4.58],[2,2.72,18.79],[3,2.7,46.06],[4,2.68,20.05],[5,2.64,25.23],[6,2.6,16.2],[7,2.58,2.88]],"bdatl":[[8,3,42],[9,3.05,1.38]],"id":36276560},{"atb":[[5.3,3],[4.4,1136.36]],"bdatb":[[0,5.3,3],[6,4.6,9.88],[7,4.5,15.54],[8,4.4,1141.21],[9,4.3,71.03],[2,5.1,22.92],[3,5,25.36],[4,4.9,10.93],[5,4.8,9.57]],"bdatl":[[6,6.2,4.57],[7,6.4,2.93],[8,6.8,2.56],[9,7,19.15]],"id":37947503},{"atb":[[1.2,4402.19]],"atl":[[1.26,34.44],[1.28,88.36]],"bdatb":[[4,1.2,4440.33],[9,1.15,14.39],[0,1.24,44.51],[1,1.23,122.36],[2,1.22,77.14],[3,1.21,201.83],[5,1.19,318.05]],"bdatl":[[0,1.26,34.44],[2,1.28,88.36],[5,1.31,20.34],[6,1.32,18.52],[7,1.33,25.48],[8,1.34,119.49],[9,1.36,15.24],[3,1.29,14.12],[4,1.3,21.53]],"id":39823721},{"atb":[[9,555.56],[14.5,10.85]],"bdatb":[[4,15.5,13.78],[6,14.5,10.88],[7,14,7.94],[8,13.5,1.45],[9,13,23.02]],"id":44331354}],"con":true}]}
{"op":"mcm","clk":"APuHAQD9dACQdg==","pt":1650392779048,"mc":[{"id":"1.197931751","rc":[{"atb":[[2.6,13.7],[2.02,0],[2.56,91.94],[2.54,1977.16]],"bdatb":[[8,2.46,10.61],[9,2.44,102],[3,2.56,93.54],[4,2.54,1979.31]],"bdatl":[[6,2.8,13.45],[8,2.84,15.01],[9,2.88,17.13]],"id":42930960},{"atl":[[5.1,24.39]],"bdatb":[[7,3.75,2.86],[8,3.7,7.19],[9,3.65,9.62]],"bdatl":[[4,4.7,16.61],[5,4.9,18.48],[6,5,4.59],[7,5.1,26.23],[8,5.2,4.45],[9,5.3,24]],"id":40095374},{"atb":[[5.3,5.33],[5.4,0],[4.9,9.78],[5,24.26]],"atl":[[12.5,0],[1000,79.58]],"bdatb":[[0,5.3,3],[1,5.2,12.55],[2,5.1,22.92],[3,5,25.36],[4,4.9,10.93],[5,4.8,9.57],[6,4.6,9.88],[7,4.5,15.54],[8,4.4,1141.21],[9,4.3,71.03]],"bdatl":[[6,6.2,4.57],[7,6.4,2.93],[8,6.8,2.56],[9,7,19.15]],"id":37947503},{"atb":[[1.23,125.38],[1.25,0]],"atl":[[1.26,129.63],[1.27,168.08],[1.28,53.1]],"bdatb":[[0,1.24,44.51],[1,1.23,127.79],[2,1.22,77.14],[3,1.21,201.83],[4,1.2,4440.33],[5,1.19,318.05],[6,1.18,9.83],[7,1.17,63.36],[8,1.16,244.69],[9,1.15,14.39]],"bdatl":[[0,1.26,34.44],[3,1.29,14.12],[4,1.3,21.53],[5,1.31,20.34],[6,1.32,18.52],[7,1.33,25.48],[1,1.27,168.08],[2,1.28,53.1]],"id":39823721},{"bdatb":[[8,2.56,101.25],[9,2.54,4.58]],"bdatl":[[6,2.96,30.8],[8,3,42],[9,3.05,1.38]],"id":36276560},{"bdatl":[[9,34,7.58]],"id":44331354}],"con":true}]}
{"op":"mcm","clk":"AJ+JAQCZdgCndw==","pt":1650392780050,"mc":[{"id":"1.197931751","rc":[{"atb":[[2.56,34.68],[2.62,4.08],[2.6,2.14],[2.54,2024.46]],"bdatb":[[3,2.56,36.27],[0,2.62,4.08],[1,2.6,2.14],[2,2.58,2.62],[4,2.54,2026.61],[5,2.52,13.55],[6,2.5,12.03],[7,2.48,4.6],[8,2.46,24.89],[9,2.44,104.94]],"id":42930960},{"atl":[[5.3,58.88]],"bdatb":[[7,3.75,12.22],[8,3.7,9.13],[9,3.65,9.25]],"bdatl":[[9,5.3,59.44],[5,4.9,18.02],[6,5,4.45],[7,5.1,25.04],[8,5.2,1.74]],"id":40095374},{"atb":[[2.7,27.46]],"bdatb":[[3,2.7,28.97],[8,2.56,114.98],[9,2.54,18.48]],"id":36276560},{"atb":[[1.23,120.03]],"bdatb":[[1,1.23,127.79]],"bdatl":[[5,1.31,18.09],[6,1.32,13.92],[7,1.33,9.02],[8,1.34,130.86],[0,1.26,129.63],[9,1.36,26.77]],"id":39823721},{"atb":[[15,19.91]],"bdatb":[[5,15,19.91]],"id":44331354},{"bdatb":[[0,5.3,5.33],[6,4.7,9.68],[7,4.6,6.11],[8,4.5,14.04],[9,4.4,1142.76]],"bdatl":[[8,6.8,1.93],[9,7,18.47]],"id":37947503}],"con":true}]}
{"op":"mcm","clk":"AMGKAQCSdwC8eA==","pt":1650392781051,"mc":[{"id":"1.197931751","rc":[{"atb":[[2.62,6.35],[2.54,2043.33],[2.56,47.69]],"atl":[[2.74,38.34]],"bdatb":[[2,2.58,1.67],[3,2.56,48.65],[4,2.54,2043.48],[5,2.52,15.02],[6,2.5,14.21],[0,2.62,6.35]],"bdatl":[[3,2.74,38.34],[9,2.86,2.34]],"id":42930960},{"atb":[[3.95,52.23],[4.2,3.86]],"atl":[[4.4,19.29],[5.5,55.56],[4.3,1]],"bdatb":[[3,3.95,54.9],[0,4.2,3.86]],"bdatl":[[1,4.4,19.29],[0,4.3,1],[5,4.9,19.23],[6,5,4.6],[7,5.1,24.89],[8,5.3,60.03],[9,5.4,3.74]],"id":40095374},{"atb":[[2.72,14.04],[2.78,2.41]],"bdatb":[[3,2.72,15.62],[4,2.7,27.46],[5,2.68,18.92],[6,2.66,1.53],[7,2.64,27.3],[8,2.6,16.2],[9,2.58,2.88],[0,2.78,2.41],[1,2.76,4.69],[2,2.74,13.97]],"bdatl":[[9,3.05,5.32]],"id":36276560},{"atl":[[12.5,1.05]],"bdatb":[[7,4.5,20.27],[8,4.4,1145.62],[9,4.3,61.55],[2,5.1,21.64],[3,5,24.83],[4,4.9,12.8]],"bdatl":[[7,6.4,3.98],[8,6.6,1.44],[9,7,18.87]],"id":37947503},{"atl":[[1.26,139.63]],"bdatb":[[5,1.19,297.32],[6,1.18,30.74],[8,1.16,237.69],[9,1.15,8.53],[0,1.24,42.53],[1,1.23,122.02],[2,1.22,84.96]],"bdatl":[[9,1.36,18.34],[3,1.29,19.31],[4,1.3,25.62],[5,1.31,14.03],[6,1.32,13.35],[7,1.33,4.54],[8,1.34,139.82],[0,1.26,139.63]],"id":39823721},{"bdatb":[[4,15.5,13.62],[6,14.5,10.85],[7,14,7.46],[8,13.5,1.48],[9,13,23.72]],"id":44331354}],"con":true}]}
{"op":"mcm","clk":"APOLAQCaeADEeQ==","pt":1650392782053,"mc":[{"id":"1.197931751","rc":[{"atb":[[2.62,4.08],[2.54,2004.69],[2.56,66.38]],"bdatb":[[0,2.62,4.08],[3,2.56,67.34],[4,2.54,2004.84]],"bdatl":[[9,2.88,20.17]],"id":42930960},{"atb":[[2.78,0],[2.66,17.5]],"bdatb":[[0,2.76,4.69],[1,2.74,13.97],[2,2.72,15.62],[3,2.7,27.46],[4,2.68,18.92],[5,2.66,19.03],[6,2.64,27.3],[7,2.6,16.2],[8,2.58,2.88],[9,2.56,114.98]],"bdatl":[[9,3.05,3.51]],"id":36276560},{"atl":[[12.5,0]],"bdatl":[[7,6.4,2.93],[8,6.6,1.96],[9,7,18.49]],"id":37947503},{"bdatl":[[6,5,4.45],[7,5.1,25.04],[8,5.2,1.74],[5,4.9,18.02],[9,5.3,59.44]],"id":40095374},{"bdatl":[[3,1.29,14.12],[4,1.3,28.26],[5,1.31,13.9],[6,1.32,11.44],[7,1.33,9.02],[9,1.36,16.41]],"id":39823721}],"con":true}]}
{"op":"mcm","clk":"AJCNAQCieQDMeg==","pt":1650392783054,"mc":[{"id":"1.197931751","rc":[{"atb":[[2.6,2.75],[2.54,2007.77],[2.56,33.51],[2.58,2.72],[1.01,33774.7]],"atl":[[2.76,1.72],[2.7,31.62],[2.74,25.98],[2.72,19.84],[2.64,10.89]],"bdatb":[[3,2.54,2007.92],[1,2.58,4.39],[2,2.56,34.46],[4,2.52,19.2],[5,2.5,12.33],[6,2.48,2.25],[7,2.46,24.89],[8,2.44,104.94],[9,2.42,1.43]],"bdatl":[[2,2.7,31.62],[4,2.74,25.98],[9,2.86,2.34],[5,2.78,22.15],[6,2.8,13.45],[7,2.82,4.59],[8,2.84,15.01],[3,2.72,19.84],[0,2.64,10.89],[1,2.68,8.2]],"id":42930960},{"atb":[[3.95,37.08],[4,43.16]],"atl":[[4.9,5.58],[5,14]],"bdatb":[[3,3.95,37.08],[8,3.7,16.31],[9,3.65,4.56],[2,4,48.57],[6,3.8,9.81],[7,3.75,3.91],[4,3.9,3.03],[5,3.85,13.54],[1,4.1,15.15]],"bdatl":[[5,4.9,7.76],[7,5.1,26.15],[8,5.2,1.09],[6,5,14],[9,5.3,59.44]],"id":40095374},{"atb":[[2.76,2.61],[2.78,2.41],[2.66,0]],"bdatb":[[0,2.78,2.41],[1,2.76,6.25],[2,2.74,13.97],[3,2.72,14.94],[4,2.7,32.87],[5,2.68,20.77],[6,2.64,24.83],[7,2.62,6.13],[8,2.6,12.55],[9,2.58,10.77]],"id":36276560},{"atl":[[12.5,1.05]],"bdatb":[[6,4.6,10.74],[7,4.5,18.35],[8,4.4,1139.57],[9,4.3,59.66],[5,4.8,13.46],[2,5.1,25.28],[3,5,24.58],[4,4.9,13.87],[0,5.3,6.14]],"bdatl":[[7,6.4,3.98],[8,6.8,1.42],[9,7,18.21]],"id":37947503},{"atb":[[1.01,40909.31]],"atl":[[25,0],[24,5.87],[19,2.57]],"bdatb":[[8,13.5,1.88],[9,13,22.75],[1,17,14.16],[4,15.5,13.5],[6,14.5,10.88],[7,14,8.3]],"bdatl":[[5,24,5.87],[6,26,2.84],[7,28,3.7],[8,30,5.17],[9,34,7.58],[0,19,2.57],[1,19.5,8.98],[2,20,4],[3,21,2.5],[4,22,4.29]],"id":44331354},{"bdatb":[[6,1.19,316.76],[7,1.18,53.81],[8,1.17,25.35],[9,1.16,226.43],[5,1.2,4431.33],[3,1.22,79.05],[0,1.25,3.44],[1,1.24,41.04],[2,1.23,131.91],[4,1.21,210.57]],"bdatl":[[3,1.29,19.31],[4,1.3,21.37],[6,1.32,14.01],[7,1.33,6.47],[9,1.36,18.34],[5,1.31,15.62]],"id":39823721}],"con":true}]}
