{"op":"mcm","clk":"ALiOAQCfegDmew==","pt":1650392784055,"mc":[{"id":"1.197931751","rc":[{"atb":[[2.6,0],[2.56,37.15],[2.54,1991.42],[2.52,13.55],[1.01,33429.52],[2,10.84],[2.62,0]],"atl":[[2.78,22.1],[2.7,31.89],[2.62,0],[2.64,1.79],[2.68,15.95],[2.88,13.67],[2.9,54.02],[3.1,3.2]],"trd":[[2.6,14.66],[2.62,30.55],[2.64,108.62]],"bdatb":[[2,2.56,38.1],[0,2.6,2],[1,2.58,4.39],[3,2.54,1991.57],[4,2.52,19.2],[5,2.5,12.33],[6,2.48,2.25],[7,2.46,24.89],[8,2.44,104.94],[9,2.42,1.43]],"bdatl":[[0,2.64,1.79],[1,2.68,15.95],[2,2.7,31.89],[3,2.72,19.84],[4,2.74,25.98],[5,2.76,1.72],[6,2.78,22.15],[7,2.8,13.45],[8,2.82,4.59],[9,2.84,15.01]],"ltp":2.6,"tv":611.1,"id":42930960},{"atb":[[4.2,3.76]],"atl":[[5.2,23.81],[4.5,22]],"trd":[[4.2,0.2]],"bdatb":[[0,4.2,3.76],[1,4.1,14.56],[2,4,47.32],[3,3.95,38.55],[4,3.9,3.43],[5,3.85,13.19],[6,3.8,10.17],[7,3.75,3.91],[8,3.7,16.31],[9,3.65,4.3]],"bdatl":[[6,5,15.04],[7,5.1,25.77],[8,5.2,26.32],[5,4.9,5.58],[9,5.3,59.44],[2,4.5,22]],"ltp":4.2,"tv":92.84,"id":40095374},{"atb":[[2.66,0],[2.78,0]],"bdatb":[[0,2.76,4.17],[1,2.74,13.97],[2,2.72,14.2],[3,2.7,27.46],[4,2.68,18.76],[5,2.66,5.49],[6,2.64,27.63],[7,2.62,5.62],[8,2.6,12.34],[9,2.58,11.51]],"bdatl":[[9,3.1,17.05]],"id":36276560},{"atl":[[12.5,0]],"bdatb":[[0,5.3,6.14],[1,5.2,12.55],[2,5.1,20.88],[3,5,24.74],[4,4.9,18.01],[5,4.8,13.74],[6,4.6,10.4],[7,4.5,18.7],[8,4.4,1139],[9,4.3,58.14]],"bdatl":[[8,6.8,1.82],[9,7,18.51],[7,6.4,2.93]],"id":37947503},{"atl":[[26,6.84]],"bdatb":[[1,17,14.16],[3,16,9.77],[4,15.5,13.37],[6,14.5,10.85],[7,14,7.43],[8,13.5,1.48],[9,13,23.72]],"bdatl":[[6,26,6.84]],"id":44331354},{"bdatb":[[1,1.24,39.41],[2,1.23,121.67],[3,1.22,89.74],[4,1.21,209.19],[5,1.2,4434.04],[6,1.19,316.76],[8,1.17,23.19],[9,1.16,223.42]],"bdatl":[[4,1.3,22.3],[5,1.31,16.77],[6,1.32,14.12],[9,1.36,16.72],[7,1.33,9.37],[3,1.29,14.12],[8,1.34,139.51]],"id":39823721}],"con":true,"tv":3275.69}]}
{"op":"mcm","clk":"AOGPAQCmewD4fA==","pt":1650392785056,"mc":[{"id":"1.197931751","rc":[{"atb":[[2.5,10],[2.6,0],[2.58,2.72],[2.54,2005.36],[2.56,39.15],[2,0]],"atl":[[2.7,30.09],[2.72,15.17],[2.84,13.01],[2.66,5.5],[2.74,18.29]],"bdatb":[[4,2.5,12.33],[0,2.58,4.39],[1,2.56,40.1],[2,2.54,2005.52],[3,2.52,19.2],[5,2.48,2.25],[6,2.46,24.89],[7,2.44,104.94],[8,2.42,1.43],[9,2.4,12.63]],"bdatl":[[3,2.7,30.09],[4,2.72,15.17],[1,2.66,5.5],[5,2.74,18.29],[2,2.68,15.95],[6,2.76,1.72],[7,2.78,22.1],[8,2.8,13.45],[9,2.82,4.59]],"id":42930960},{"atl":[[5.4,34.09],[5.5,0],[5.3,24],[5.1,0]],"bdatb":[[9,3.65,6.55],[1,4.1,15.05],[2,4,46.82],[5,3.85,13.54],[6,3.8,9.81]],"bdatl":[[6,5,14],[7,5.1,1.41],[8,5.2,26.95],[9,5.3,24.89]],"id":40095374},{"atl":[[1.26,138.58]],"trd":[[1.26,335.92]],"bdatb":[[7,1.18,53.81],[8,1.17,20.69],[9,1.16,225.94],[4,1.21,221.28],[5,1.2,4421.85],[2,1.23,121.99],[3,1.22,89.42]],"bdatl":[[4,1.3,18.3],[5,1.31,16.91],[6,1.32,17.92],[7,1.33,9.37]],"ltp":1.26,"tv":2129.75,"id":39823721},{"atb":[[18,1.31]],"atl":[[28,5.56],[34,0]],"trd":[[18,6.47]],"bdatb":[[0,18,1.31],[8,13.5,2.36],[9,13,22.78],[6,14.5,10.99],[7,14,7.31]],"bdatl":[[7,28,5.56],[9,36,8.91]],"tv":44.43,"id":44331354},{"bdatb":[[4,2.68,22.71],[5,2.64,28.39],[6,2.62,6.13],[7,2.6,16.93],[8,2.58,6.36],[9,2.56,104.15],[3,2.7,28.21]],"bdatl":[[9,3.1,15.37]],"id":36276560},{"bdatb":[[6,4.6,10.74],[7,4.5,18.35],[8,4.4,1138.33],[9,4.3,58.82],[3,5,26.71],[4,4.9,15.79],[2,5.1,21.35],[5,4.8,13.46]],"bdatl":[[8,6.8,1.03],[9,7,19.25]],"id":37947503}],"con":true,"tv":3277.98}]}
{"op":"mcm","clk":"AIKRAQCbfACWfg==","pt":1650392786057,"mc":[{"id":"1.197931751","rc":[{"atb":[[2.48,19.63]],"atl":[[2.84,3.17],[2.72,24.83]],"bdatb":[[1,2.56,39.15],[2,2.54,2006.33],[3,2.52,18.83],[4,2.5,10.52],[5,2.48,24.23],[7,2.44,102.02],[8,2.42,4.38]],"bdatl":[[4,2.72,24.83]],"id":42930960},{"atl":[[5.6,54.35]],"bdatb":[[2,4,46.49],[3,3.95,37.41],[4,3.9,4.92],[7,3.75,2.01],[8,3.7,18.24]],"bdatl":[[6,5,15.4],[7,5.1,3.24],[8,5.2,24.27],[9,5.3,24.44]],"id":40095374},{"atb":[[2.72,19.76],[2.8,2.6],[2.78,4.67],[2.76,4.69]],"atl":[[2.86,23.01],[2.82,0]],"bdatb":[[0,2.78,4.67],[1,2.76,6.25],[2,2.74,13.97],[3,2.72,14.2],[4,2.7,28.21],[5,2.68,22.71],[6,2.64,28.39],[7,2.62,6.13],[8,2.6,16.93],[9,2.58,6.36]],"bdatl":[[0,2.84,7.06],[1,2.86,20.46],[2,2.88,17.18],[3,2.9,19.31],[4,2.92,36.84],[5,2.96,30.8],[6,2.98,16.19],[7,3,42],[8,3.1,15.37],[9,3.15,2.79]],"id":36276560},{"atl":[[12.5,1.05]],"bdatb":[[0,5.3,5.33],[1,5.2,13.38],[2,5.1,20.88],[3,5,27.19],[5,4.8,11.97],[6,4.7,2.25],[7,4.6,8.45],[8,4.5,19.64],[9,4.4,1138.5]],"bdatl":[[8,6.6,1.06],[9,7,19.28]],"id":37947503},{"atl":[[1000,369.84]],"bdatb":[[0,1.24,42.53],[1,1.23,122.02],[2,1.22,84.96],[3,1.21,226.09],[4,1.2,4415.9],[5,1.19,322.76],[6,1.18,53.81],[7,1.17,20.2],[8,1.16,238.62],[9,1.15,16.31]],"bdatl":[[4,1.3,23.7],[5,1.31,18.11],[6,1.32,17.28],[7,1.33,3.54],[9,1.36,23.26],[0,1.26,138.58]],"id":39823721},{"atl":[[30,8.62]],"bdatb":[[1,17,13.9],[3,16,10.04],[4,15.5,13.34],[5,15,19.94],[6,14.5,10.85],[7,14,7.43],[8,13.5,2.39],[9,13,22.68]],"bdatl":[[8,30,8.62]],"id":44331354}],"con":true}]}
{"op":"mcm","clk":"ALmSAQCOfQCffw==","pt":1650392787060,"mc":[{"id":"1.197931751","rc":[{"atb":[[1.99,11.44]],"atl":[[2.7,23.48],[2.68,20.04]],"bdatb":[[7,2.44,105.01],[8,2.42,1.36]],"bdatl":[[3,2.7,23.48],[2,2.68,20.04]],"id":42930960},{"atb":[[2.8,0],[2.7,44.55]],"atl":[[1000,142.9]],"bdatb":[[8,2.6,21.14],[9,2.58,2.12],[0,2.78,4.67],[1,2.76,6.25],[2,2.74,13.97],[3,2.72,19.92],[4,2.7,45.3],[5,2.68,22.71],[6,2.64,28.39],[7,2.62,6.13]],"bdatl":[[1,2.86,23.01]],"id":36276560},{"atb":[[1.24,34.07]],"atl":[[1000,363.72]],"trd":[[1.24,349.43]],"bdatb":[[8,1.16,233.93],[9,1.15,17.47],[3,1.21,235.13],[4,1.2,4412.86],[0,1.24,37.53],[5,1.19,316.63],[7,1.17,23.71]],"bdatl":[[4,1.3,23.7],[5,1.31,18.11],[7,1.33,3.54],[8,1.34,139.51],[9,1.36,26.81]],"ltp":1.24,"tv":2139.75,"id":39823721},{"atb":[[17,11.9],[16.5,7.71]],"bdatb":[[1,17,11.9],[2,16.5,7.71]],"id":44331354},{"bdatb":[[9,3.65,4.65],[7,3.75,3.96],[8,3.7,16.27]],"bdatl":[[5,4.9,5.58],[6,5,15.4],[7,5.1,3.24],[8,5.2,24.27],[9,5.3,24.44]],"id":40095374},{"bdatb":[[5,4.8,13.49],[6,4.6,10.74],[7,4.5,18.02],[8,4.4,1139.44],[9,4.3,58.74]],"bdatl":[[8,6.6,1.06],[9,7,19.28]],"id":37947503}],"con":true,"tv":3287.98}]}
{"op":"mcm","clk":"APOTAQCqfgDOgAE=","pt":1650392788218,"mc":[{"id":"1.197931751","rc":[{"atb":[[2.52,13.55],[2.5,10],[2.6,23.15],[2.54,1991.42],[2.56,77.97],[2.58,19.12],[2.62,4.58]],"atl":[[2.76,1.39],[1000,174.45],[2.68,24.52],[2.7,8.75],[2.64,0],[2.72,14.91],[2.82,0],[2.8,8.91]],"trd":[[2.64,110.25]],"bdatb":[[0,2.62,4.58],[1,2.6,31.05],[2,2.58,18.46],[3,2.56,70.99],[4,2.54,2009.25],[5,2.52,23.58],[6,2.5,11.36],[7,2.48,19.63],[8,2.46,7.21],[9,2.44,103.32]],"bdatl":[[0,2.66,5.5],[2,2.7,8.75],[3,2.72,14.91],[5,2.78,22.1],[6,2.8,8.91],[7,2.84,3.17],[8,2.88,16.28],[9,2.9,55.48],[1,2.68,20.04],[4,2.74,18.29]],"ltp":2.64,"tv":612.73,"id":42930960},{"atb":[[3.9,12.82],[3.95,52.23],[4.3,0],[2.84,15.08],[4,33.48],[4.2,8.87]],"atl":[[1000,111.37],[4.4,11.4],[5,4],[5.1,9.76],[4.3,0]],"trd":[[4.3,13.5]],"bdatb":[[8,3.75,5.32],[9,3.7,14.88],[0,4.3,2.73],[1,4.2,10.4],[2,4.1,14.72],[3,4,42.26],[4,3.95,37.94],[5,3.9,2],[6,3.85,9.95],[7,3.8,2.85]],"bdatl":[[5,5,4],[6,5.1,12.11],[7,5.2,26.03],[8,5.3,26.18],[9,5.4,35.42],[0,4.4,14.13],[1,4.5,22],[2,4.6,19.79],[3,4.7,16.61],[4,4.9,5.58]],"ltp":4.3,"tv":93.84,"id":40095374},{"atb":[[2.68,17.92],[2.66,2.68],[2.52,14.12],[1.01,28663],[2.72,0],[2.64,23.31],[1.89,32.19],[2,74.04],[2.7,13.75],[2.74,0],[2.76,0],[2.58,12.12],[2.78,0]],"atl":[[2.74,2.62],[2.8,0.85],[2.78,10.39],[2.92,25.23],[2.76,14.26],[2.96,28.54],[2.98,13.32],[2.86,39.2],[3.2,53.53],[2.88,83.74],[3.45,0],[1000,142.02],[2.84,12.54],[3.3,8.08],[3.1,21.19],[2.82,32.99]],"trd":[[2.74,5.57],[2.72,9.92],[2.76,25.04],[2.78,25.09]],"bdatb":[[0,2.72,2.76],[1,2.7,13.75],[2,2.68,20.42],[4,2.64,24.95],[5,2.62,2.7],[3,2.66,1.45],[6,2.6,22.85],[7,2.58,12.12],[8,2.56,102.14],[9,2.54,7.07]],"bdatl":[[5,2.86,39.2],[6,2.88,83.74],[8,2.92,34.52],[9,2.96,28.54],[1,2.78,12.64],[2,2.8,2.02],[3,2.82,32.99],[4,2.84,12.54],[7,2.9,19.31],[0,2.76,4.29]],"ltp":2.72,"tv":348.71,"id":36276560},{"atb":[[5.3,6.62]],"atl":[[6,7.01],[5.7,2],[5.6,0],[1000,79.93],[5.8,5.89],[12.5,0],[5.5,0]],"trd":[[5.6,3.51],[5.5,9.6]],"bdatb":[[1,5.2,14.12],[2,5.1,27.14],[6,4.7,1.31],[7,4.6,13.95],[8,4.5,12.22],[9,4.4,1139.89],[0,5.3,7.84],[3,5,24.94],[4,4.9,10.24],[5,4.8,7.76]],"bdatl":[[8,7,19.69],[9,7.2,2.6],[0,5.6,1.84],[2,5.8,5.89],[7,6.6,1.78],[1,5.7,2],[3,5.9,6.94],[4,6,5.01],[5,6.2,4.57],[6,6.4,2.93]],"ltp":5.6,"tv":71.32,"id":37947503},{"atl":[[1.28,83.7],[1.26,39.98]],"trd":[[1.26,339.33]],"bdatb":[[1,1.23,123.55],[2,1.22,104.14],[4,1.2,4426.99],[5,1.19,317.74],[6,1.18,20.97],[7,1.17,27.45],[9,1.14,721.91],[0,1.24,42.38],[3,1.21,200.31],[8,1.16,231.28]],"bdatl":[[5,1.31,11.61],[6,1.32,28.89],[7,1.33,10.45],[8,1.34,140.43],[9,1.36,5.6],[0,1.26,39.98],[4,1.3,27.33]],"ltp":1.26,"tv":2143.16,"id":39823721},{"atb":[[17,14.53]],"atl":[[1000,24.96],[19,2.34],[25,1.67],[24,4.13],[19.5,6.98]],"trd":[[19,0.8]],"bdatb":[[2,16.5,7.71],[3,16,10.42],[6,14.5,11.04],[7,14,7.79],[0,18,1.31],[5,15,20.02],[8,13.5,3.32],[9,13,22.89]],"bdatl":[[4,24,4.13],[5,25,1.67],[6,26,6.84],[7,28,5.56],[8,30,8.62],[9,36,8.91],[0,19.5,7.32],[1,20,4],[2,21,2.5],[3,22,4.29]],"ltp":19,"tv":44.66,"id":44331354}],"con":true,"tv":3314.42}]}
{"op":"mcm","clk":"AJiVAQC9fwDdgQE=","pt":1650392789219,"mc":[{"id":"1.197931751","rc":[{"atb":[[2.44,0],[2.42,103],[2.58,24.54],[2.62,6.96],[2.52,32.67],[2.56,75.89]],"atl":[[2.68,20.43],[2.86,44],[2.9,6.83],[2.7,13.23],[3.2,4.19]],"bdatb":[[9,2.44,109.14],[3,2.56,86.22],[4,2.54,1996.5],[0,2.62,6.96],[2,2.58,27.32],[5,2.52,34.11],[6,2.5,10],[7,2.48,19.71],[8,2.46,6.29],[1,2.6,23.15]],"bdatl":[[1,2.68,23.58],[9,2.86,5.66],[2,2.7,13.23],[5,2.76,1.39],[6,2.78,22.1],[7,2.8,8.91],[8,2.84,3.17]],"id":42930960},{"atb":[[3.65,68],[3.6,0],[4.1,26.32],[4,30.69],[1.01,40085.53],[3.9,2],[3.95,37.08]],"atl":[[5.4,57.09],[5.3,23.26],[4.6,17.78]],"bdatb":[[4,3.9,6.47],[5,3.85,11.97],[6,3.8,8.1],[7,3.75,5.34],[8,3.7,8.08],[9,3.65,3.9],[0,4.2,10.58],[1,4.1,32.77],[2,4,34.88],[3,3.95,37.08]],"bdatl":[[2,4.6,17.78],[4,4.9,8.88],[5,5,5.47],[6,5.1,11.54],[7,5.2,23.81],[8,5.3,48.11],[9,5.4,36.71],[0,4.4,11.4]],"id":40095374},{"atb":[[2.58,0],[2.7,0],[2.5,104.69],[2.56,2],[2.68,20.62],[2.64,5.6]],"atl":[[2.78,45.59],[3.3,0],[2.9,10.03],[2.94,43],[2.96,18.51],[2.84,20.04],[3,0],[3.1,8.08],[2.86,34.4],[2.88,17.18],[1000,138.08]],"bdatb":[[8,2.54,11.44],[9,2.52,18.11],[2,2.66,8.18],[3,2.64,12.8],[4,2.62,4.13],[5,2.6,14.02],[1,2.68,20.62],[0,2.7,13.75],[6,2.58,12.2],[7,2.56,100]],"bdatl":[[9,2.96,34.01],[2,2.78,24.44],[5,2.86,34.4],[6,2.88,17.18],[4,2.84,10.51],[0,2.74,2.62],[1,2.76,14.26],[3,2.82,33.84],[8,2.92,25.23]],"id":36276560},{"atb":[[4.8,5.77],[4.4,1193.36],[4.9,13.11],[5,24.26],[4.3,0],[5.4,3],[5.1,27.88]],"atl":[[7,0],[5.7,3.9],[7.2,17],[5.8,5.89],[1000,78.29],[12.5,1.4],[5.5,0],[6.6,2.22],[6.8,3.51],[6.4,5.15],[6,5.01],[5.9,5.63]],"trd":[[5.5,11.6]],"bdatb":[[6,4.8,14.82],[7,4.7,7.79],[8,4.6,7.55],[9,4.5,10.39],[1,5.3,9.38],[2,5.2,18.29],[3,5.1,29],[0,5.4,3],[5,4.9,23.54],[4,5,32.58]],"bdatl":[[1,5.8,5.89],[6,6.6,4.98],[7,6.8,5.63],[8,7,18],[9,7.4,6.96],[0,5.7,5.9],[2,5.9,5.63],[3,6,5.01],[4,6.2,4.57],[5,6.4,5.15]],"ltp":5.5,"tv":73.32,"id":37947503},{"atb":[[1.25,35.7],[1.2,4385.08],[1.17,228.18],[1.16,4.28],[1.22,72.98],[1.21,54.07]],"atl":[[1.28,53.1],[1000,369.84]],"bdatb":[[0,1.25,26.1],[1,1.24,45.87],[2,1.23,144.28],[3,1.22,77.67],[4,1.21,76.93],[5,1.2,4432.72],[6,1.19,302.37],[7,1.18,20.37],[8,1.17,22.93],[9,1.16,258.92]],"bdatl":[[8,1.35,15.61],[9,1.36,10.87],[2,1.28,53.1],[5,1.31,25.33],[6,1.32,25.71],[7,1.34,138.61],[4,1.3,18.3]],"id":39823721},{"atb":[[13,3.63],[12.5,26.26],[1.01,39950.65]],"atl":[[28,9.56],[19,0.34],[36,5.91],[27,3.85],[1000,24.69],[19.5,8.98]],"bdatb":[[6,14.5,12.16],[7,14,8.21],[1,17,14.53],[4,15.5,13.8],[5,15,20.41],[8,13.5,1.72],[9,13,22.63],[3,16,9.77]],"bdatl":[[8,27,3.85],[9,28,5.56],[0,19,2.34],[1,19.5,8.98],[2,20,4],[3,21,2.5],[4,22,4.29],[5,24,4.13],[6,25,1.67],[7,26,6.84]],"id":44331354}],"con":true,"tv":3316.42}]}
{"op":"mcm","clk":"AK6WAQDQgAEA7IIB","pt":1650392790220,"mc":[{"id":"1.197931751","rc":[{"atb":[[2.56,55.39],[2.58,27.62],[2.6,44.51]],"atl":[[2.68,17.31]],"bdatb":[[3,2.56,65.88],[2,2.58,30.4],[1,2.6,44.51],[4,2.54,1997.28],[5,2.52,33.17],[9,2.44,7.3]],"bdatl":[[1,2.68,17.31],[9,2.86,44]],"id":42930960},{"atl":[[5.5,33.33],[5.4,23],[5.2,0],[5.6,0]],"bdatb":[[4,3.9,4.73],[5,3.85,11.22],[6,3.8,9.51],[7,3.75,3.25],[8,3.7,15.31],[9,3.65,69.59],[0,4.2,10.4],[1,4.1,28.31],[2,4,39.63]],"bdatl":[[7,5.2,4.05],[9,5.4,24.95],[5,5,4.41],[6,5.1,10.8],[8,5.3,23.26]],"id":40095374},{"atb":[[2.6,22.5],[2.64,3.27],[2.68,17.92],[2.58,18.38],[2.46,16.97]],"atl":[[2.8,0],[2.76,15.12],[3.05,8.08]],"bdatb":[[4,2.6,28.71],[7,2.54,8.77],[8,2.52,16.96],[9,2.5,116.11],[2,2.64,6.36],[1,2.66,5.11],[0,2.68,17.92],[3,2.62,7.4],[5,2.58,18.46],[6,2.56,2]],"bdatl":[[3,2.82,32.99],[4,2.84,20.04],[9,2.94,43],[2,2.78,45.59],[7,2.9,10.03],[1,2.76,15.12]],"id":36276560},{"atb":[[5.1,19.55],[5.3,16.49],[5,27.59]],"atl":[[5.7,5.97]],"bdatb":[[6,4.8,7.99],[8,4.6,2.58],[9,4.5,15.18],[3,5.1,26.52],[1,5.3,17.85],[2,5.2,13.98],[5,4.9,13.11],[7,4.7,16.23],[4,5,27.63]],"bdatl":[[7,6.8,4.29],[8,7,1.96],[9,7.2,18.03],[0,5.7,5.97]],"id":37947503},{"atb":[[1.22,90.09]],"bdatb":[[3,1.22,103.33],[4,1.21,68.96],[5,1.2,4437.84],[6,1.19,293.26],[7,1.18,24.13],[9,1.16,19.03],[8,1.17,241.73],[1,1.24,39.86],[0,1.25,35.7],[2,1.23,141.86]],"bdatl":[[8,1.34,121.15],[9,1.35,6.4],[5,1.31,23.78],[6,1.32,16.97],[7,1.33,10.3]],"id":39823721},{"atl":[[29,5.36],[30,0],[28,4],[26,2.84],[1000,24.29]],"bdatb":[[9,13,3.63],[6,14.5,12.19],[7,14,8.35],[8,13.5,1.55]],"bdatl":[[9,29,5.36],[6,26,2.84],[8,28,4],[0,19.5,9.32],[1,20,4],[2,21,2.5],[3,22,4.29],[4,24,4.13],[5,25,1.67],[7,27,3.85]],"id":44331354}],"con":true}]}
{"op":"mcm","clk":"ANCXAQDggQEAgYQB","pt":1650392791221,"mc":[{"id":"1.197931751","rc":[{"atb":[[2.56,24.15],[2.58,62.71]],"bdatb":[[3,2.56,34.64],[2,2.58,65.49],[4,2.54,1995.35],[5,2.52,32.67],[6,2.5,11.97],[7,2.48,20.14],[9,2.44,7.38]],"id":42930960},{"atl":[[5.7,53.19]],"bdatb":[[2,4,38.03],[4,3.9,6.37]],"bdatl":[[6,5.1,11.54],[7,5.2,1.41],[8,5.3,23.46],[9,5.4,23],[4,4.9,5.58],[5,5,5.43]],"id":40095374},{"atb":[[2.6,47.93],[2.64,6.62],[1.01,28264.98],[2.68,0]],"atl":[[2.78,70.05]],"bdatb":[[3,2.6,51.76],[1,2.64,9.71],[0,2.66,5.11],[2,2.62,7.4],[4,2.58,18.38],[5,2.56,4.41],[6,2.54,8.85],[7,2.52,16.96],[8,2.5,116.11],[9,2.48,3.89]],"bdatl":[[2,2.78,70.05]],"id":36276560},{"atb":[[1.21,192.41]],"atl":[[1.26,34.92]],"bdatb":[[8,1.17,255.06],[9,1.16,18.22],[4,1.21,207.3]],"bdatl":[[6,1.32,18.28],[7,1.33,5.52],[8,1.34,108.58],[9,1.35,9.36],[5,1.31,16.85],[0,1.26,34.92]],"id":39823721},{"atb":[[1.01,39709.74]],"atl":[[32,8.06]],"bdatb":[[7,14,8],[8,13.5,1.45]],"id":44331354},{"bdatb":[[9,4.5,17.79],[3,5.1,25.31],[4,5,28.58],[5,4.9,13.36],[6,4.8,8.03]],"bdatl":[[8,7,2.34],[9,7.2,17.15],[6,6.6,2.22],[7,6.8,4.56]],"id":37947503}],"con":true}]}
{"op":"mcm","clk":"APaYAQCFgwEAg4UB","pt":1650392792222,"mc":[{"id":"1.197931751","rc":[{"atb":[[3.95,32.27],[4.1,31.82],[4.2,12.69]],"atl":[[1000,109.82],[4.5,19.33],[4.4,0]],"bdatb":[[1,4.1,33.81],[0,4.2,14.22]],"bdatl":[[0,4.5,19.33],[1,4.6,17.78],[2,4.7,16.61],[3,4.9,5.58],[4,5,4],[5,5.1,11.49],[6,5.2,1.81],[7,5.3,23.31],[8,5.4,23.93],[9,5.5,37.16]],"id":40095374},{"atb":[[2.62,3.69],[2.66,0],[2.64,3.35]],"atl":[[3.2,45.45],[2.86,23.28],[2.96,8.69],[2.88,6.77],[2.92,16.57]],"bdatb":[[7,2.5,112.21],[8,2.48,2],[9,2.46,20.94],[0,2.64,3.35],[1,2.62,9.27],[2,2.6,55.39],[3,2.58,22.25],[4,2.56,2],[5,2.54,11.28],[6,2.52,16.96]],"bdatl":[[5,2.86,23.28],[6,2.88,6.77],[8,2.92,16.57]],"id":36276560},{"atb":[[1.02,5001.8]],"bdatb":[[7,4.7,5.52],[8,4.6,10.94],[9,4.5,16.29],[1,5.3,16.49],[2,5.2,13.93],[3,5.1,21.01],[4,5,33.47],[5,4.9,14.11],[6,4.8,8.3]],"bdatl":[[7,6.8,3.51],[8,7,2.61],[9,7.2,17.04]],"id":37947503},{"atl":[[1.27,140.57]],"bdatb":[[5,1.2,4408.88],[6,1.19,317.59],[8,1.17,235.85],[9,1.16,24.97],[1,1.24,34.07],[2,1.23,131.92],[3,1.22,118.2],[4,1.21,208.34],[7,1.18,29.05]],"bdatl":[[1,1.27,140.57],[9,1.35,22.03],[5,1.31,11.41],[6,1.32,23.68],[7,1.33,1.53],[8,1.34,111.74]],"id":39823721},{"bdatb":[[2,2.58,62.71],[3,2.56,24.15],[4,2.54,1994.25],[5,2.52,43.32],[6,2.5,13.99],[7,2.48,19.63],[8,2.46,8.29],[9,2.44,7.9]],"id":42930960},{"bdatb":[[4,15.5,13.34],[5,15,19.91],[6,14.5,11.34],[7,14,7.82],[8,13.5,2.89],[9,13,4.39]],"id":44331354}],"con":true}]}
{"op":"mcm","clk":"AJGaAQCUhAEAgoYB","pt":1650392793223,"mc":[{"id":"1.197931751","rc":[{"atl":[[2.7,16.65]],"bdatb":[[5,2.52,42.76],[6,2.5,14.56],[9,2.44,7.32],[2,2.58,64.41],[4,2.54,1992.51]],"bdatl":[[2,2.7,16.65]],"id":42930960},{"atb":[[3.9,9.74],[3.95,49.27],[4.3,1]],"atl":[[4.6,27.2],[4.4,1]],"bdatb":[[5,3.9,14.11],[6,3.85,10.85],[8,3.75,3.59],[9,3.7,13.7],[4,3.95,49.27],[7,3.8,10.75],[0,4.3,1],[1,4.2,14.22],[2,4.1,33.81],[3,4,38.03]],"bdatl":[[2,4.6,27.2],[0,4.4,1],[1,4.5,19.33],[3,4.7,16.61],[4,4.9,5.58],[5,5,4],[6,5.1,11.49],[7,5.2,1.81],[8,5.3,24.26],[9,5.4,23.57]],"id":40095374},{"atb":[[2.62,6.78]],"atl":[[2.78,72.77],[2.98,21.4]],"bdatb":[[3,2.6,54.84],[4,2.58,22.8],[7,2.52,16.4],[8,2.5,114.54],[0,2.66,1.65],[1,2.64,3.35],[2,2.62,10.68],[5,2.56,2],[6,2.54,11.28],[9,2.48,2]],"bdatl":[[2,2.78,72.77],[7,2.9,11.52]],"id":36276560},{"atb":[[5.4,2.9],[1.02,5001.55]],"atl":[[5.7,5.72]],"trd":[[5.4,34.56],[5.7,0.5]],"bdatb":[[0,5.4,2.9],[9,4.5,20.43],[8,4.6,11.99],[1,5.3,17.33],[2,5.2,13.08],[7,4.7,6.46]],"bdatl":[[0,5.7,5.72],[7,6.8,4.15],[8,7,1.99],[9,7.2,17.74]],"ltp":5.4,"tv":74.01,"id":37947503},{"atb":[[1.24,58.28],[1.22,62.92]],"atl":[[1.47,0],[1.53,188.68]],"bdatb":[[4,1.21,207.16],[8,1.17,256.35],[9,1.16,16.91],[5,1.2,4412.78],[6,1.19,313.66],[1,1.24,61.83],[2,1.23,128.35],[3,1.22,91.02]],"bdatl":[[6,1.32,20.02],[7,1.33,1.94],[5,1.31,14.69],[9,1.35,22.95],[8,1.34,114.02]],"id":39823721},{"atl":[[24,5.87],[25,0]],"bdatb":[[8,13.5,2.78],[9,13,4.5],[4,15.5,13.62],[6,14.5,11.04]],"bdatl":[[4,24,5.87],[5,26,2.84],[6,27,3.85],[7,28,4],[8,29,5.36],[9,32,8.06]],"id":44331354}],"con":true,"tv":3317.11}]}
{"op":"mcm","clk":"ANGbAQCHhQEAkocB","pt":1650392794224,"mc":[{"id":"1.197931751","rc":[{"atb":[[2.02,16.55],[2.58,66.72],[1.99,0]],"bdatb":[[2,2.58,66.72],[4,2.54,1993.15],[5,2.52,32.67],[6,2.5,11.11],[7,2.48,25.12],[8,2.46,17.72],[9,2.44,13.05]],"bdatl":[[8,2.84,3.27]],"id":42930960},{"atb":[[3.9,2],[3.95,46.93]],"bdatb":[[1,4.2,12.69],[2,4.1,33.39],[3,4,32.73],[4,3.95,48.5],[5,3.9,12.31],[6,3.85,14.49],[7,3.8,8.63],[8,3.75,7.37],[9,3.7,15.31]],"bdatl":[[4,4.9,5.63],[6,5.1,11.44]],"id":40095374},{"atb":[[2.6,62.11]],"atl":[[2.78,75.03]],"bdatb":[[2,2.6,62.11],[0,2.64,3.35],[1,2.62,8.46],[3,2.58,19.18],[4,2.56,7.6],[5,2.54,20.42],[6,2.52,21.95],[7,2.5,108.94],[8,2.48,2],[9,2.46,22.9]],"bdatl":[[5,2.86,23.37],[7,2.9,11.42],[2,2.78,75.03]],"id":36276560},{"atb":[[5.3,14.16]],"atl":[[5.8,10.34],[1000,77.94],[5.9,7.68],[5.7,3.65]],"bdatb":[[1,5.3,14.16],[2,5.2,13.4],[3,5.1,19.55],[4,5,28.15],[5,4.9,21.62],[9,4.5,16.4]],"bdatl":[[5,6.4,5.19],[7,6.8,4.1],[1,5.8,10.34],[2,5.9,7.68],[0,5.7,3.65]],"id":37947503},{"atb":[[1.23,122.05],[1.22,33.85],[1.26,0.22]],"atl":[[1.29,28.3],[1.26,0],[1.28,38.92]],"trd":[[1.26,389.17]],"bdatb":[[2,1.23,130.37],[0,1.25,35.92],[3,1.22,61.95],[4,1.21,218.74],[5,1.2,4406.09],[6,1.19,330.57],[8,1.17,241.86],[9,1.16,18.9]],"bdatl":[[2,1.29,28.3],[0,1.27,140.57],[1,1.28,38.92],[3,1.3,18.3],[4,1.31,14.69],[5,1.32,20.02],[6,1.33,1.94],[7,1.34,114.02],[8,1.35,22.95],[9,1.36,56.16]],"tv":2193,"id":39823721},{"bdatb":[[4,15.5,13.34],[6,14.5,10.85],[7,14,7.6],[8,13.5,1.66],[9,13,4.2]],"id":44331354}],"con":true,"tv":3366.95}]}
{"op":"mcm","clk":"APucAQCGhgEAs4gB","pt":1650392795225,"mc":[{"id":"1.197931751","rc":[{"atb":[[2.58,65.02]],"atl":[[2.68,19.31],[2.66,0]],"trd":[[2.66,41.42]],"bdatb":[[2,2.58,65.02]],"bdatl":[[0,2.68,19.31],[1,2.7,16.65],[2,2.72,14.91],[3,2.74,18.29],[4,2.76,1.39],[5,2.78,22.1],[6,2.8,8.91],[7,2.84,3.17],[8,2.86,44],[9,2.88,15.17]],"ltp":2.66,"tv":622.73,"id":42930960},{"bdatb":[[2,4.1,31.82],[3,4,32.48],[5,3.9,9.94],[6,3.85,16.9],[7,3.8,6.19],[8,3.75,9.84],[4,3.95,50.38]],"bdatl":[[4,4.9,5.58],[6,5.1,12.83],[7,5.2,1.51],[8,5.3,24.01],[9,5.4,26.16]],"id":40095374},{"atb":[[2.6,67.67],[2.64,10.43]],"bdatb":[[1,2.62,6.78],[2,2.6,69.36],[5,2.54,16.77],[6,2.52,25.63],[9,2.46,19.13],[3,2.58,18.38],[4,2.56,8.41],[0,2.64,10.43]],"bdatl":[[5,2.86,23.28],[7,2.9,11.52]],"id":36276560},{"bdatb":[[2,5.2,12.55],[3,5.1,20.41],[5,4.9,21.77],[6,4.8,6.37],[7,4.7,8.43],[8,4.6,9.97],[9,4.5,13.99],[4,5,28]],"bdatl":[[5,6.4,5.15],[7,6.8,4.15],[8,7,2.75],[9,7.2,17.56]],"id":37947503},{"atb":[[1.23,120.03],[1.22,165.9],[1.26,0]],"atl":[[1.31,11.41],[1.27,124.73],[1.28,86.8]],"bdatb":[[1,1.24,58.28],[2,1.23,125.86],[3,1.22,200.11],[4,1.21,218.74],[5,1.2,4398.36],[6,1.19,338.36],[7,1.18,29.05],[8,1.17,233.94],[9,1.16,26.89],[0,1.25,35.7]],"bdatl":[[4,1.31,14.69],[0,1.27,124.73],[1,1.28,86.8],[6,1.33,5.92],[7,1.34,124.02],[8,1.35,9.1]],"id":39823721},{"atb":[[15.5,11.96],[16.5,6.42]],"bdatb":[[2,16.5,6.42],[4,15.5,11.96],[7,14,7.29],[8,13.5,1.78],[9,13,3.84]],"id":44331354}],"con":true,"tv":3376.95}]}
{"op":"mcm","clk":"AJ+eAQCAhwEAzokB","pt":1650392796227,"mc":[{"id":"1.197931751","rc":[{"atb":[[2.56,42.78]],"bdatb":[[3,2.56,42.78]],"id":42930960},{"atb":[[2.6,85.83]],"bdatb":[[2,2.6,87.52]],"id":36276560},{"atb":[[1.24,71.42],[1.23,106.09]],"atl":[[1.29,61.64]],"bdatb":[[1,1.24,71.42],[2,1.23,111.93]],"bdatl":[[2,1.29,61.64]],"id":39823721}],"con":true}]}
{"op":"mcm","clk":"ALmfAQD+hwEA2IoB","pt":1650392797229,"mc":[{"id":"1.197931751","rc":[{"atb":[[2.6,55.03]],"atl":[[2.7,16.65],[2.72,14.91],[2.68,12.11]],"bdatb":[[1,2.6,55.03],[2,2.58,66.72],[3,2.56,42.78],[4,2.54,1994.41],[5,2.52,36.17],[6,2.5,30.59],[7,2.48,23.06],[9,2.44,14.23],[8,2.46,10.61]],"bdatl":[[1,2.7,16.65],[2,2.72,14.91],[9,2.88,13.67],[0,2.68,12.11]],"id":42930960},{"atb":[[3.95,32.27]],"bdatb":[[4,3.95,42.35],[6,3.85,19.03],[7,3.8,4.14],[8,3.75,10.02],[2,4.1,34.74],[3,4,35.81],[5,3.9,4.18],[9,3.7,7.79]],"bdatl":[[6,5.1,9.76],[7,5.2,3.41],[8,5.3,23.35],[9,5.4,23.98]],"id":40095374},{"atb":[[2.6,83.49],[2.4,12.12],[2.52,2],[1.01,27865.75],[2.64,0]],"atl":[[2.76,99.48],[2.84,28.88],[2.7,4.44],[2.78,54.19],[2.86,9.75],[2.72,22.16],[2.82,12.62],[2.74,36.87]],"bdatb":[[5,2.52,19.84],[6,2.5,106.03],[7,2.48,6.28],[9,2.44,16.32],[0,2.62,6.78],[1,2.6,80.56],[2,2.58,18.38],[3,2.56,8.41],[4,2.54,9.17],[8,2.46,16.97]],"bdatl":[[3,2.76,99.48],[6,2.84,28.88],[0,2.7,4.44],[1,2.72,22.16],[2,2.74,36.87],[4,2.78,54.19],[5,2.82,12.62],[7,2.86,9.75],[8,2.88,6.77],[9,2.9,11.52]],"id":36276560},{"atb":[[1.19,135.49]],"bdatb":[[3,1.22,212.3],[4,1.21,203.96],[5,1.2,4414.02],[6,1.19,170.77],[7,1.18,9.45],[8,1.17,265.13],[1,1.24,76.63],[2,1.23,117.75],[9,1.16,5.08]],"bdatl":[[9,1.36,72.37],[4,1.31,11.41],[5,1.32,23.27],[6,1.33,1.58],[7,1.34,112.09],[8,1.35,25.22]],"id":39823721},{"bdatb":[[5,4.9,22.28],[6,4.8,8.68],[7,4.7,5.66],[8,4.6,8.79],[9,4.5,11.45],[3,5.1,21.04],[4,5,31.69],[2,5.2,13.4]],"bdatl":[[8,7,1.92],[9,7.2,17.07]],"id":37947503},{"bdatb":[[5,15,20.21],[7,14,7.29],[8,13.5,2.01],[9,13,4.31]],"id":44331354}],"con":true}]}
{"op":"mcm","clk":"AO2gAQCLiQEA7osB","pt":1650392798232,"mc":[{"id":"1.197931751","rc":[{"atb":[[2.68,10],[2.6,57.03],[1.01,33249.04],[2.58,42.51],[2.56,39.14],[2.54,1991.42],[2.66,6.29],[2.62,14.09],[2.64,4.04]],"atl":[[2.7,5.87],[1000,168.35],[2.68,0],[2.72,10.91]],"trd":[[2.68,188.64]],"bdatb":[[0,2.68,10],[4,2.6,57.03],[5,2.58,42.51],[6,2.56,39.14],[7,2.54,1999.61],[8,2.52,46.66],[9,2.5,19.89],[1,2.66,6.29],[2,2.64,4.04],[3,2.62,14.09]],"bdatl":[[0,2.7,5.87],[7,2.86,44],[9,2.9,10.16],[1,2.72,10.91],[2,2.74,18.29],[3,2.76,1.39],[4,2.78,22.1],[5,2.8,8.91],[6,2.84,3.17],[8,2.88,13.67]],"ltp":2.68,"tv":645.8,"id":42930960},{"atb":[[4.4,0],[3.95,46.93],[4.1,22.45],[4,26.34],[4.3,8.75]],"atl":[[1000,106.84],[4.9,19.19],[4.5,19.04],[4.4,0]],"trd":[[4.4,16.84]],"bdatb":[[2,4.1,24.02],[3,4,29.93],[4,3.95,53.19],[5,3.9,11.04],[6,3.85,13.23],[8,3.75,9.1],[0,4.3,8.75],[1,4.2,12.69],[7,3.8,3.01],[9,3.7,15.31]],"bdatl":[[4,5,5.2],[5,5.1,11.3],[6,5.3,27.25],[7,5.4,23],[8,5.5,35.07],[9,5.6,6.09],[0,4.5,19.04],[3,4.9,21.16],[1,4.6,27.2],[2,4.7,16.61]],"ltp":4.4,"tv":95.84,"id":40095374},{"atb":[[2.58,4.64],[2.6,30.24],[1.89,0],[1.8,92],[2.56,13.16],[2.62,3.69]],"atl":[[3.1,0],[2.7,20.76],[2.8,5.78],[2.78,37.35],[2.72,50.79],[2.9,0],[2.92,13.51],[2.98,8.08],[2.76,32.48],[2.74,17.71],[2.84,17.54]],"bdatb":[[4,2.54,10.82],[5,2.52,3.97],[6,2.5,114.58],[7,2.48,16.21],[8,2.46,18.97],[9,2.44,6.17],[2,2.58,4.64],[3,2.56,13.16],[1,2.6,30.24],[0,2.62,3.69]],"bdatl":[[7,2.84,23.06],[8,2.86,12.51],[9,2.88,6.77],[0,2.7,20.76],[5,2.8,5.78],[1,2.72,50.79],[4,2.78,37.35],[6,2.82,12.62],[2,2.74,17.71],[3,2.76,32.48]],"id":36276560},{"atl":[[1.28,100.99]],"bdatb":[[2,1.23,118.98],[3,1.22,198.85],[4,1.21,216.9],[5,1.2,4396.58],[6,1.19,183.13],[7,1.18,29.05],[8,1.17,229.36],[9,1.16,25.79],[1,1.24,71.42]],"bdatl":[[4,1.31,22],[5,1.32,22.08],[6,1.33,4.44],[7,1.34,141.19],[8,1.35,1.93],[9,1.37,6.83],[2,1.29,61.64],[3,1.3,25.74],[1,1.28,100.99]],"id":39823721},{"atl":[[25,1.67],[24,4.13]],"bdatb":[[9,13,5.23],[8,13.5,1.45],[5,15,19.91]],"bdatl":[[4,24,4.13],[5,25,1.67],[6,26,2.84],[7,27,3.85],[8,28,4],[9,29,5.36]],"id":44331354},{"bdatb":[[4,5,30.76],[5,4.9,21.31],[6,4.8,11.95],[7,4.7,2.12],[8,4.6,13.64],[9,4.5,9.29],[3,5.1,19.55],[2,5.2,12.55]],"bdatl":[[6,6.6,4.32],[7,6.8,5.59],[8,7.2,17.97],[9,7.4,6.32],[4,6.2,4.57],[5,6.4,6.66]],"id":37947503}],"con":true,"tv":3402.02}]}
{"op":"mcm","clk":"AO+hAQCnigEA/YwB","pt":1650392799291,"mc":[{"id":"1.197931751","rc":[{"atb":[[2.7,0],[2.64,13.68],[2.48,0],[2.5,16.29],[2.6,33.88],[2.38,0],[2.68,13.76],[2.58,35.81]],"atl":[[2.76,2],[2.74,21.47],[2.72,3.64],[1000,166.45],[2.7,0]],"trd":[[2.7,95.43],[2.72,82.66]],"bdatb":[[0,2.68,13.76],[2,2.64,13.68],[1,2.66,6.29],[3,2.62,14.09],[4,2.6,33.88],[5,2.58,38.31],[6,2.56,44.74],[7,2.54,1993.64],[8,2.52,42.94],[9,2.5,16.29]],"bdatl":[[0,2.72,3.64],[1,2.74,21.47],[2,2.76,2],[3,2.78,22.1],[4,2.8,8.91],[5,2.84,3.17],[6,2.86,44],[7,2.88,13.67],[8,2.9,6.83],[9,2.94,5.33]],"ltp":2.7,"tv":665.24,"id":42930960},{"atb":[[3.95,32.27],[1.01,39091.34],[4.1,31.82]],"atl":[[1000,105.39],[4.7,18.66],[4.9,5.58],[4.6,25.19],[4.5,11.63]],"bdatb":[[2,4.1,34.23],[3,4,29.06],[5,3.9,14.26],[6,3.85,10.15],[9,3.7,15.31],[4,3.95,33.7],[7,3.8,2.92],[8,3.75,14.09]],"bdatl":[[3,4.9,5.58],[4,5,7.13],[6,5.2,2.57],[7,5.3,24.72],[8,5.4,24.66],[9,5.5,35.25],[2,4.7,18.66],[0,4.5,11.63],[1,4.6,25.19]],"id":40095374},{"atb":[[2.52,24.91],[1.01,26934.22],[2.58,0],[2.6,24.68],[2.54,13.24],[2.62,0],[2.56,20.63]],"atl":[[1000,135.64],[2.76,28.19],[2.72,49.89],[2.8,0],[2.7,18.82],[2.66,4.51],[2.92,21.59],[2.82,10.16],[2.68,5.39]],"bdatb":[[3,2.52,28.84],[4,2.5,109.05],[7,2.44,11.08],[8,2.42,2.69],[5,2.48,14.71],[9,2.4,31.01],[1,2.56,20.63],[2,2.54,13.24],[6,2.46,16.97],[0,2.6,24.68]],"bdatl":[[7,2.82,10.16],[8,2.84,23.06],[3,2.72,49.89],[5,2.76,28.19],[9,2.86,12.51],[0,2.66,4.51],[1,2.68,5.39],[2,2.7,18.82],[4,2.74,17.71],[6,2.78,37.35]],"id":36276560},{"atb":[[15,8.47]],"bdatb":[[7,14,7.99],[8,13.5,1.61],[5,15,8.47],[6,14.5,10.85],[9,13,4.31]],"id":44331354},{"bdatb":[[3,5.1,21.49],[4,5,28.01],[7,4.7,4.67],[9,4.5,14.34],[5,4.9,21.34],[8,4.6,13.36],[2,5.2,12.55],[6,4.8,5.77]],"bdatl":[[5,6.4,5.15],[6,6.6,5.79],[9,7.4,7.53],[8,7.2,17.97]],"id":37947503},{"bdatb":[[1,1.24,76.63],[2,1.23,117.75],[4,1.21,210.53],[5,1.2,4390.51],[6,1.19,198.86],[7,1.18,8.83],[8,1.17,234.66],[9,1.16,18.31],[3,1.22,191.74]],"bdatl":[[3,1.3,18.3],[4,1.31,29.38],[6,1.33,12.02],[7,1.34,115.66],[8,1.35,19.67],[9,1.37,19.16]],"id":39823721}],"con":true,"tv":3421.46}]}
{"op":"mcm","clk":"ANijAQC4iwEA+o0B","pt":1650392800293,"mc":[{"id":"1.197931751","rc":[{"atb":[[2.7,3.71],[2.66,26.45],[2.6,12.52],[2.62,50.79]],"atl":[[2.76,6.52],[2.78,26.52],[2.74,16.29],[2.72,0]],"bdatb":[[0,2.7,3.71],[1,2.68,13.76],[2,2.66,26.45],[3,2.64,13.68],[4,2.62,50.79],[5,2.6,12.52],[6,2.58,38.31],[7,2.56,44.74],[8,2.54,1993.64],[9,2.52,42.94]],"bdatl":[[0,2.74,16.29],[1,2.76,6.52],[2,2.78,26.52],[3,2.8,8.91],[4,2.84,3.17],[5,2.86,44],[6,2.88,13.67],[7,2.9,6.83],[8,2.94,5.33],[9,2.96,2.66]],"id":42930960},{"atb":[[2.54,35.35],[2.56,19.85],[2.34,2148.87],[2.46,4.85],[2.52,44.03],[2.58,4.65],[2.6,14]],"atl":[[2.76,9.97],[2.7,26.59]],"bdatb":[[3,2.54,35.35],[2,2.56,19.85],[7,2.46,7.97],[4,2.52,44.03],[5,2.5,113.01],[6,2.48,11.61],[8,2.44,6.31],[9,2.42,7.5],[0,2.6,14],[1,2.58,4.65]],"bdatl":[[7,2.82,13.71],[8,2.84,19.53],[2,2.7,26.59],[5,2.76,9.97]],"id":36276560},{"bdatb":[[2,4.1,33.39],[3,4,29.93],[5,3.9,11.28],[6,3.85,14.08],[7,3.8,6.6],[8,3.75,9.43]],"bdatl":[[3,4.9,7.62],[4,5,5.13],[8,5.4,23.42],[9,5.5,33.6],[6,5.2,2.47],[7,5.3,24.81]],"id":40095374},{"bdatb":[[3,5.1,19.55],[4,5,29.99],[5,4.9,19.77],[6,4.8,7.38],[7,4.7,2.19],[8,4.6,16.02],[9,4.5,14.2]],"bdatl":[[5,6.4,6.72],[6,6.6,4.27],[7,6.8,5.59],[8,7.2,17.97],[9,7.4,6.63]],"id":37947503},{"bdatb":[[1,1.24,71.42],[2,1.23,123.01],[3,1.22,185.44],[4,1.21,207.27],[5,1.2,4414.76],[7,1.18,9.38],[8,1.17,234.11],[6,1.19,184.18]],"bdatl":[[9,1.37,26.35],[7,1.34,140.5],[8,1.36,19.49],[3,1.3,26.01],[4,1.31,21.73],[5,1.32,22.08],[6,1.33,6.97]],"id":39823721},{"bdatb":[[7,14,7.29],[8,13.5,2.34]],"id":44331354}],"con":true}]}
{"op":"mcm","clk":"AIilAQCkjAEAgo8B","pt":1650392801294,"mc":[{"id":"1.197931751","rc":[{"atb":[[2.72,6],[2.66,64.01]],"atl":[[2.74,0],[1000,164.59],[2.76,10.31],[2.78,38.76]],"bdatb":[[5,2.62,55.37],[7,2.58,35.81],[8,2.56,42.58],[0,2.72,2.16],[1,2.7,3.71],[2,2.68,13.76],[3,2.66,64.01],[4,2.64,13.68],[6,2.6,12.52],[9,2.54,1993.64]],"bdatl":[[1,2.76,10.31],[8,2.98,9.45],[9,3.05,25.05],[0,2.74,2.11],[2,2.78,38.76]],"id":42930960},{"atb":[[4.1,36.82]],"bdatb":[[1,4.2,14.06],[2,4.1,38.34],[3,4,26.34],[5,3.9,5.44],[6,3.85,21.45],[4,3.95,34.5],[7,3.8,8.89],[8,3.75,7.11]],"bdatl":[[3,4.9,5.58],[4,5,5.18],[5,5.1,11.68],[9,5.6,6.39],[6,5.3,24.74],[7,5.4,27.6],[8,5.5,34.12]],"id":40095374},{"atl":[[2.7,29.81]],"bdatb":[[3,2.54,37.63],[4,2.52,46.49],[5,2.5,104.69],[6,2.48,5.55],[7,2.46,10.3],[8,2.44,9.51],[9,2.42,11.75]],"bdatl":[[7,2.82,10.16],[8,2.84,19.61],[9,2.86,13.18],[2,2.7,29.81]],"id":36276560},{"atb":[[1.22,31.62],[1.23,115.32],[1.21,190.18],[1.25,0]],"atl":[[1.29,28.3],[1.31,9.92],[1.32,9.92],[1.3,16.81],[1.26,9.52],[1.27,176.36]],"bdatb":[[0,1.24,71.42],[1,1.23,115.85],[2,1.22,175.51],[3,1.21,211.57],[4,1.2,4430.59],[5,1.19,176.87],[6,1.18,14.15],[7,1.17,229.29],[8,1.16,18.31],[9,1.15,41.4]],"bdatl":[[0,1.26,9.52],[1,1.27,176.36],[2,1.28,100.99],[3,1.29,61.64],[4,1.3,28.86],[5,1.31,15.93],[6,1.32,20.59],[7,1.33,8.1],[8,1.34,139.37],[9,1.36,47.99]],"id":39823721},{"bdatb":[[2,5.2,13.66],[3,5.1,20.77],[4,5,27.59],[5,4.9,16.06],[6,4.8,7.39],[7,4.7,3.85],[8,4.6,19.49],[9,4.5,14.84]],"bdatl":[[5,6.4,5.15],[6,6.6,3.11],[7,6.8,6.11],[8,7,1.84],[9,7.2,17.17]],"id":37947503},{"bdatb":[[6,14.5,11.25],[7,14,7.73],[8,13.5,1.45],[9,13,3.63]],"id":44331354}],"con":true}]}
{"op":"mcm","clk":"AJamAQChjQEA/48B","pt":1650392802295,"mc":[{"id":"1.197931751","rc":[{"atb":[[2.62,28.29],[1.01,32134.94],[2.56,39.14],[2.42,109.29],[2.58,30.08],[2.66,11.29],[2.64,39.59],[2.54,1991.42],[2.7,0],[2.6,2],[2.52,13.55],[2.72,0],[2.12,10.56],[2.02,0],[2.46,0]],"atl":[[2.7,0],[2.8,8.91],[2.98,4.19],[2.76,10.77],[3.3,0],[2.78,43.68],[2.72,2.04],[2.74,7.05]],"trd":[[2.7,100.13]],"bdatb":[[6,2.56,47.27],[1,2.66,11.29],[2,2.64,39.59],[5,2.58,30.08],[7,2.54,1993.64],[0,2.68,13.76],[3,2.62,46.21],[4,2.6,2],[8,2.52,23.82],[9,2.5,16.29]],"bdatl":[[5,2.8,8.91],[0,2.7,3.57],[3,2.76,10.77],[1,2.72,2.04],[2,2.74,7.05],[4,2.78,43.68],[6,2.84,3.17],[7,2.86,44],[8,2.88,13.67],[9,2.9,6.83]],"tv":669.94,"id":42930960},{"atb":[[4.2,17.47],[4,21.1],[4.3,12.26]],"atl":[[4.7,16.61]],"trd":[[4.3,13.7]],"bdatb":[[1,4.2,17.47],[2,4.1,39.75],[3,4,23.3],[4,3.95,33.7],[5,3.9,11.68],[6,3.85,13.66],[0,4.3,12.26],[9,3.7,15.31]],"bdatl":[[9,5.6,3.31],[2,4.7,16.61],[5,5.1,13.41],[6,5.3,25.16],[7,5.4,23],[8,5.5,34.07],[3,4.9,5.58],[4,5,7.13]],"ltp":4.3,"tv":96.04,"id":40095374},{"atb":[[2.44,14.21],[2.34,2136.75]],"bdatb":[[3,2.54,39.15],[4,2.52,46.23],[5,2.5,106.94],[6,2.48,7.52],[7,2.46,12.1],[8,2.44,19.08],[9,2.42,6.84]],"bdatl":[[7,2.82,13.96],[8,2.84,19.28],[9,2.86,16.26]],"id":36276560},{"atb":[[1.23,106.09],[1.24,58.28],[1.25,35.45]],"atl":[[1.26,0]],"bdatb":[[9,1.16,26.78],[1,1.24,66.05],[2,1.23,115.17],[3,1.22,42.84],[5,1.2,4420.68],[4,1.21,214.75],[7,1.18,15.26],[8,1.17,242.09],[0,1.25,35.45],[6,1.19,176.87]],"bdatl":[[9,1.36,19.77],[6,1.33,11.91],[7,1.34,118.37],[8,1.35,23.94],[3,1.3,25.06],[5,1.32,11.9],[0,1.27,176.36],[1,1.28,100.99],[2,1.29,28.3],[4,1.31,27.89]],"id":39823721},{"atb":[[18.5,0.58]],"atl":[[22,4.77],[21,2],[19.5,4.22],[19,0]],"trd":[[19,1.48],[19.5,9.88]],"bdatb":[[6,14.5,11.51],[7,14,7.45],[8,13.5,1.45],[9,13,4.31],[0,18,1.89]],"bdatl":[[2,21,2],[3,22,4.77],[0,19.5,4.22]],"ltp":19.5,"tv":54.86,"id":44331354},{"bdatb":[[3,5.1,21.9],[4,5,28.23],[6,4.8,9.49],[7,4.7,2.53],[8,4.6,9.29],[9,4.5,22.91],[5,4.9,17.05],[2,5.2,12.55]],"bdatl":[[8,7,1.06],[9,7.2,17],[6,6.6,7.41],[7,6.8,3.9],[5,6.4,5.15]],"id":37947503}],"con":true,"tv":3436.56}]}
{"op":"mcm","clk":"AL2nAQCZjgEA/ZAB","pt":1650392803297,"mc":[{"id":"1.197931751","rc":[{"atb":[[2.68,6.01],[2.64,13.68],[2.62,23.57],[2.12,0],[2.66,15.92]],"atl":[[2.78,39.26],[1000,160.85],[2.76,17.05]],"bdatb":[[0,2.68,6.01],[2,2.64,13.68],[3,2.62,23.57],[1,2.66,15.92]],"bdatl":[[3,2.78,39.26],[2,2.76,17.05],[0,2.72,2.04],[1,2.74,7.05],[4,2.8,8.91],[5,2.84,3.17],[6,2.86,44],[7,2.88,13.67],[8,2.9,6.83],[9,2.92,3.67]],"id":42930960},{"atb":[[1.23,119.98]],"bdatb":[[2,1.23,136.89],[9,1.16,22.84],[4,1.21,227.76],[5,1.2,4414.26],[1,1.24,58.28],[3,1.22,36.25]],"bdatl":[[4,1.31,14.02],[5,1.32,25.29],[6,1.33,12.27],[7,1.34,112.06],[8,1.35,26.74],[9,1.36,23.2]],"id":39823721},{"bdatb":[[5,3.9,14.07],[6,3.85,11.66],[2,4.1,38.18],[3,4,24.92],[4,3.95,33.3]],"bdatl":[[5,5.1,9.85],[6,5.2,3.49],[7,5.3,25.16],[8,5.4,23],[9,5.5,34.07]],"id":40095374},{"bdatb":[[8,2.44,22.24],[9,2.42,3.66],[3,2.54,35.35],[5,2.5,110.79],[6,2.48,3.63],[7,2.46,16.02]],"bdatl":[[9,2.86,9.91]],"id":36276560},{"bdatb":[[7,4.7,4.17],[8,4.6,7.61],[9,4.5,22.91],[3,5.1,20.64],[4,5,28.88],[5,4.9,16.06],[6,4.8,11.17]],"bdatl":[[6,6.6,4.66],[7,6.8,6.5],[8,7,1.13]],"id":37947503},{"bdatb":[[6,14.5,10.85],[7,14,7.68],[8,13.5,1.93]],"id":44331354}],"con":true}]}
{"op":"mcm","clk":"AO6oAQCUjwEAo5IB","pt":1650392804299,"mc":[{"id":"1.197931751","rc":[{"atb":[[2.62,52.28],[2.68,0],[2.64,6.04]],"atl":[[2.74,9.38],[2.8,8.91]],"bdatb":[[0,2.68,3.76],[2,2.64,6.04]],"bdatl":[[4,2.8,8.91]],"id":42930960},{"atb":[[2.56,34.04]],"bdatb":[[2,2.56,34.04]],"bdatl":[[7,2.82,13.73],[8,2.84,17.77],[9,2.86,11.48]],"id":36276560},{"bdatl":[[4,5,6.15],[5,5.1,10.73],[6,5.2,3.58]],"id":40095374},{"bdatl":[[6,6.6,3.85],[7,6.8,7.29]],"id":37947503},{"bdatb":[[9,1.16,22.84]],"bdatl":[[3,1.3,24.56],[4,1.31,14.18],[5,1.32,25.63],[6,1.33,12.05],[7,1.34,108],[8,1.35,28.16],[9,1.36,26.02]],"id":39823721}],"con":true}]}
{"op":"mcm","clk":"AKCqAQD6jwEAvpMB","pt":1650392805300,"mc":[{"id":"1.197931751","rc":[{"atb":[[2.06,9.84],[2.58,11.69]],"atl":[[2.7,3.32],[2.72,9.11]],"bdatb":[[2,2.62,52.28],[5,2.56,47.27],[4,2.58,11.69],[0,2.66,15.92],[1,2.64,6.04],[3,2.6,2],[6,2.54,1993.64],[7,2.52,23.82],[8,2.5,16.29],[9,2.48,11.47]],"bdatl":[[0,2.7,3.32],[1,2.72,9.11],[2,2.74,9.38],[3,2.76,17.05],[4,2.78,39.26],[5,2.8,8.91],[6,2.84,3.17],[7,2.86,44],[8,2.88,13.67],[9,2.9,6.83]],"id":42930960},{"atb":[[1.25,9.6]],"atl":[[1.26,0],[1.31,9.92]],"bdatb":[[0,1.25,9.6],[1,1.24,65.51],[2,1.23,129.6],[3,1.22,57.46],[4,1.21,213.69],[5,1.2,4406.89],[6,1.19,176.87],[7,1.18,15.26],[8,1.17,242.09],[9,1.16,32.7]],"bdatl":[[0,1.27,176.36],[1,1.28,100.99],[2,1.29,28.3],[3,1.3,16.81],[4,1.31,21.87],[5,1.32,25.63],[6,1.33,9.02],[7,1.34,111.01],[8,1.35,28.16],[9,1.36,26.02]],"id":39823721},{"bdatb":[[1,4.2,17.47],[2,4.1,39.75],[3,4,24.72],[4,3.95,34.12],[5,3.9,14.06],[6,3.85,9.77],[7,3.8,8.48]],"bdatl":[[5,5.1,10.01],[6,5.3,27.46],[7,5.4,23.39],[8,5.5,34.41],[9,5.6,1.08],[4,5,6.15]],"id":40095374},{"bdatb":[[1,2.58,4.65],[2,2.56,34.04],[3,2.54,38.88],[4,2.52,48.73],[5,2.5,109.86],[6,2.48,9.5],[7,2.46,4.85],[8,2.44,25.87],[9,2.4,31.01]],"bdatl":[[9,2.86,10.2],[8,2.84,21.32],[7,2.82,10.16]],"id":36276560},{"bdatb":[[1,5.3,14.16],[2,5.2,12.55],[3,5.1,21.9],[4,5,30.48],[5,4.9,18.39],[6,4.8,5.77],[7,4.7,11.53],[8,4.5,23],[9,4.4,1204.14]],"bdatl":[[7,6.8,3.7],[8,7,3.18],[9,7.2,17.3],[6,6.6,3.85]],"id":37947503},{"bdatb":[[3,16,9.77],[5,15,8.47],[6,14.5,11.47],[7,14,7.5],[8,13.5,1.45]],"id":44331354}],"con":true}]}
{"op":"mcm","clk":"ANmrAQD9kAEAy5QB","pt":1650392806301,"mc":[{"id":"1.197931751","rc":[{"atb":[[2.68,3.35],[2.62,64.2]],"atl":[[2.74,26.27],[2.7,0]],"bdatb":[[0,2.68,3.35],[1,2.66,15.92],[2,2.64,6.04],[3,2.62,64.2],[4,2.6,7.56],[5,2.58,12.41],[6,2.56,39.14],[7,2.54,1993.18],[8,2.52,34.65],[9,2.5,19.01]],"bdatl":[[1,2.74,26.27],[0,2.72,9.11],[2,2.76,17.05],[3,2.78,39.26],[4,2.8,8.91],[5,2.84,3.17],[6,2.86,44],[7,2.88,13.67],[8,2.9,6.83],[9,2.96,5.29]],"id":42930960},{"atb":[[4.1,31.82],[4,23.1]],"atl":[[1000,105.84],[4.7,16.61],[4.5,3.63]],"trd":[[4.5,42]],"bdatb":[[4,3.95,34.39],[5,3.9,5.7],[6,3.85,21.05],[7,3.8,2],[8,3.75,2.56],[9,3.7,10.53],[1,4.2,17.47],[2,4.1,36.89],[3,4,36.39]],"bdatl":[[6,5.3,27.72],[7,5.4,26.16],[9,5.7,54.08],[8,5.5,36.23],[2,4.7,16.61],[4,5,4],[5,5.1,11.86],[0,4.5,3.63]],"ltp":4.5,"tv":112.04,"id":40095374},{"atb":[[2.48,14.12],[2.56,52.66],[2.62,10.39],[2.58,18.65],[2.4,0],[2.6,26.48],[2.52,56.58]],"atl":[[2.72,35.44],[2.7,22.04],[2.66,0]],"bdatb":[[3,2.56,59.04],[7,2.48,37.32],[8,2.46,10.72],[9,2.44,26.24],[0,2.62,10.39],[2,2.58,18.65],[5,2.52,58.36],[6,2.5,106.28],[1,2.6,26.48],[4,2.54,35.35]],"bdatl":[[2,2.72,35.44],[9,2.88,9.89],[0,2.68,5.39],[1,2.7,22.04],[3,2.74,17.71],[4,2.76,9.97],[5,2.78,37.35],[6,2.82,10.16],[7,2.84,17.54],[8,2.86,9.75]],"id":36276560},{"atb":[[1.25,0]],"atl":[[1.26,112.48]],"bdatb":[[3,1.21,239.74],[4,1.2,4422.86],[5,1.19,140.62],[8,1.16,26.51],[9,1.15,6.24],[0,1.24,58.28],[1,1.23,131.73],[2,1.22,36.83],[6,1.18,25.36],[7,1.17,252.38]],"bdatl":[[0,1.26,112.48],[5,1.31,22.51],[6,1.32,28.18],[7,1.33,1.05],[8,1.34,136.15],[9,1.35,26.21],[1,1.27,176.36],[2,1.28,100.99],[3,1.29,28.3],[4,1.3,25.06]],"id":39823721},{"bdatb":[[5,4.9,23.14],[6,4.8,10.52],[7,4.7,7.55],[8,4.6,2.07],[9,4.5,9.76],[2,5.2,15.33],[3,5.1,19.91],[4,5,29.28],[1,5.3,14.16]],"bdatl":[[6,6.6,3.58],[7,6.8,6.2],[8,7,1.01],[9,7.2,19.37]],"id":37947503},{"bdatb":[[5,15,8.47],[6,14.5,11.85],[7,14,7.42],[9,13,3.97],[3,16,9.77]],"id":44331354}],"con":true,"tv":3452.56}]}
{"op":"mcm","clk":"AImtAQD1kQEA45UB","pt":1650392807302,"mc":[{"id":"1.197931751","rc":[{"atb":[[2.6,2],[2.46,102],[2.42,6.29],[2.06,10.7],[2.62,54.86],[2.68,0]],"atl":[[2.9,49.83],[2.86,0],[2.7,3.3],[2.78,27.02]],"bdatb":[[3,2.6,2.94],[8,2.5,39.35],[9,2.48,1.48],[2,2.62,54.86],[7,2.52,14.48],[0,2.66,15.92],[1,2.64,6.04],[4,2.58,17.07],[5,2.56,39.14],[6,2.54,1993.18]],"bdatl":[[7,2.88,13.67],[8,2.9,49.83],[9,2.92,3.67],[0,2.7,3.3],[1,2.72,9.11],[2,2.74,26.27],[3,2.76,17.05],[4,2.78,27.02],[5,2.8,8.91],[6,2.84,3.17]],"id":42930960},{"atl":[[5.4,0],[5.5,56.33]],"bdatb":[[4,3.95,44.59],[5,3.9,2.55],[6,3.85,11.23],[7,3.8,5.69],[3,4,26.32],[8,3.75,7.45],[9,3.7,15.31],[1,4.2,18.06],[2,4.1,36.3]],"bdatl":[[7,5.4,1.5],[8,5.5,59.23],[4,5,4],[5,5.1,11.9],[9,5.6,2.5],[6,5.3,27.68]],"id":40095374},{"atb":[[2.44,116.21],[2.5,4.69],[2.6,27.19],[2.52,44.03],[2.62,4.19],[2.58,16.59],[2.64,4.13]],"atl":[[2.94,0],[2.9,43],[1000,129.38],[3.2,53.53],[2.72,22.54],[2.92,13.51],[2.7,7.66],[2.76,0],[2.74,2.62],[2.68,0.91]],"bdatb":[[7,2.5,9.84],[2,2.6,27.19],[6,2.52,45.81],[1,2.62,4.19],[3,2.58,20.05],[4,2.56,55.56],[8,2.48,33.73],[9,2.46,14.34],[0,2.64,4.13],[5,2.54,35.35]],"bdatl":[[8,2.9,46.7],[1,2.72,22.54],[9,2.92,15.2],[0,2.7,8.57],[2,2.74,2.62],[3,2.78,37.35],[4,2.82,10.16],[5,2.84,17.54],[6,2.86,9.75],[7,2.88,6.77]],"id":36276560},{"atl":[[7.4,23.32],[7.2,0]],"bdatb":[[6,4.8,16.35],[7,4.7,1.53],[8,4.6,8.82],[9,4.5,13.85],[4,5,28.95],[5,4.9,15.26],[2,5.2,14.26],[3,5.1,21]],"bdatl":[[9,7.2,1.12],[7,6.8,5.15],[8,7,1.77],[6,6.6,3.85]],"id":37947503},{"atb":[[1.17,14.18],[1.16,220.28]],"atl":[[1.26,230.75]],"bdatb":[[7,1.17,34.66],[8,1.16,244.69],[3,1.21,239.74],[4,1.2,4394.13],[5,1.19,147.28],[6,1.18,27.55],[9,1.15,17.24],[1,1.23,127.22],[2,1.22,41.37]],"bdatl":[[8,1.34,136.15],[9,1.35,26.21],[3,1.29,28.3],[4,1.3,25.2],[5,1.31,18.3],[6,1.32,25.42],[7,1.33,7.8],[0,1.26,230.75]],"id":39823721},{"atl":[[28,0],[36,8.91]],"bdatb":[[5,15,8.64],[6,14.5,11.29],[7,14,7.82]],"bdatl":[[8,29,5.36],[9,32,8.06]],"id":44331354}],"con":true}]}
{"op":"mcm","clk":"ALuuAQCCkwEA7JYB","pt":1650392808303,"mc":[{"id":"1.197931751","rc":[{"atb":[[2.6,25.47],[2.64,27.24],[2.54,22.92],[2.42,14.08],[2.5,23.33],[2.62,23.57],[2.68,3.32],[2.66,10.92]],"atl":[[2.72,0],[3.05,23.82],[2.98,9.97],[3.2,9.09],[2.74,29.7],[2.76,12.07],[2.78,22.1],[2.7,0]],"bdatb":[[4,2.6,12.17],[5,2.58,14.85],[6,2.56,45.49],[7,2.54,54.21],[8,2.52,30.02],[9,2.5,24.21],[3,2.62,23.57],[0,2.68,3.32],[1,2.66,10.92],[2,2.64,6.04]],"bdatl":[[9,2.98,12.9],[1,2.74,29.7],[8,2.94,5.33],[2,2.76,12.07],[3,2.78,22.1],[0,2.72,2.04],[4,2.8,8.91],[5,2.84,3.17],[6,2.88,13.67],[7,2.9,49.83]],"id":42930960},{"atb":[[4.2,26.56],[3.95,32.27],[4.1,26.32],[4.3,18.82],[3.45,40.82],[4.4,7.73],[3.85,4.31]],"atl":[[4.7,16.72],[1000,100.21],[5.1,0],[4.8,4.25],[5.2,9.52],[4.6,8.06],[4.5,0]],"bdatb":[[1,4.3,18.82],[2,4.2,20.49],[3,4.1,39.12],[4,4,27.01],[5,3.95,51.15],[6,3.9,5.16],[7,3.85,9.76],[8,3.8,8.27],[9,3.75,2],[0,4.4,7.73]],"bdatl":[[0,4.6,8.06],[1,4.7,14.25],[2,4.8,2.23],[3,4.9,5.58],[4,5,4],[5,5.1,11.5],[6,5.3,26.19],[7,5.4,1.83],[8,5.5,57],[9,5.6,2.85]],"id":40095374},{"atb":[[2.58,4.65],[2.6,4.46],[1.01,24772.56],[2.56,23.86],[2.36,15.61],[2.52,29.85],[2.48,2],[2.34,0],[2.62,0],[2.64,0],[2.54,32.77]],"atl":[[2.62,3.92],[2.72,44.58],[2.64,4.79],[2.74,0],[2.66,19.73],[2.68,5.01]],"trd":[[2.6,26.31]],"bdatb":[[0,2.6,9.38],[6,2.48,8.56],[7,2.46,22.61],[9,2.42,7.07],[4,2.52,32.05],[8,2.44,118.73],[2,2.56,38.48],[3,2.54,32.77],[5,2.5,10.79],[1,2.58,16.59]],"bdatl":[[0,2.64,4.79],[1,2.66,19.73],[2,2.68,5.01],[3,2.7,7.66],[4,2.72,22.54],[9,2.88,8.48],[5,2.78,37.35],[6,2.82,10.16],[7,2.84,20.68],[8,2.86,10.39]],"ltp":2.6,"tv":358.55,"id":36276560},{"atb":[[5.4,2.9],[4.4,57]],"atl":[[5.9,11.97],[5.7,5.65]],"bdatb":[[2,5.2,13.62],[3,5.1,20.94],[4,5,32.48],[5,4.9,18.83],[6,4.8,10.31],[7,4.7,2.62],[8,4.6,1.04],[9,4.5,11.67],[0,5.4,2.9]],"bdatl":[[8,7.4,26.01],[9,7.6,1.75],[2,5.9,5.63],[7,6.8,6.94]],"id":37947503},{"atb":[[1.21,190.18],[1.2,218.41]],"bdatb":[[1,1.23,130.26],[2,1.22,51.64],[3,1.21,224.47],[4,1.2,225.38],[5,1.19,149.87],[6,1.18,14.12],[7,1.17,37.54],[8,1.16,236.23],[9,1.15,1.31]],"bdatl":[[6,1.32,10.12],[7,1.33,14.75],[8,1.34,135.28],[9,1.35,17.91],[4,1.3,22.01],[5,1.31,23.92],[3,1.29,35.2]],"id":39823721},{"atb":[[15,6.47],[9,0]],"atl":[[27,1.54],[25,0],[22,1.61]],"bdatb":[[6,14.5,11.23],[7,14,7.79],[8,13.5,2.06],[9,13,4.88],[5,15,8.47]],"bdatl":[[3,22,1.61]],"id":44331354}],"con":true,"tv":3462.4}]}
{"op":"mcm","clk":"AOKvAQCAlAEAlpgB","pt":1650392809304,"mc":[{"id":"1.197931751","rc":[{"atb":[[2.62,41.49],[2.64,11.42],[2.7,3.52],[2.66,16.21],[2.68,5.57],[2.6,20.16]],"atl":[[1000,157.22],[2.78,22.1],[2.76,8.63],[2.74,5.76]],"bdatb":[[8,2.54,38.43],[9,2.52,21.72],[3,2.64,11.42],[4,2.62,23.57],[5,2.6,20.16],[6,2.58,15.67],[7,2.56,46.14],[0,2.7,3.52],[1,2.68,5.57],[2,2.66,16.21]],"bdatl":[[2,2.78,22.1],[9,3,5.13],[1,2.76,8.63],[0,2.74,5.76],[8,2.98,9.97],[3,2.8,8.91],[4,2.84,3.17],[5,2.88,13.67],[6,2.9,49.83],[7,2.94,3.94]],"id":42930960},{"atb":[[4.5,1],[4.4,9.15],[2.84,4.37],[4.3,29.52],[4.2,32.86],[4.1,22.78],[1.01,38108.86]],"atl":[[4.6,1],[5.4,22.73],[1000,98.91],[4.7,14.38],[4.8,6.89]],"bdatb":[[0,4.4,9.15],[5,3.95,34.28],[7,3.85,6.65],[8,3.8,2],[9,3.75,8.34],[1,4.3,29.52],[4,4,36.48],[6,3.9,8.4],[2,4.2,36.62],[3,4.1,28.59]],"bdatl":[[0,4.7,14.38],[1,4.8,6.89],[7,5.4,23.2],[8,5.5,56.5],[9,5.6,1.13],[6,5.3,25.68],[2,4.9,5.58],[3,5,4],[4,5.1,2.1],[5,5.2,9.69]],"id":40095374},{"atb":[[2.52,10.73],[2.5,24.05],[2.56,6.01],[2.54,17.86],[2.58,0]],"atl":[[2.64,31.38],[2.68,7.42],[2.72,37.26],[1000,123.83],[2.9,51.08],[2.94,2],[2.7,3.22],[3.2,45.45]],"bdatb":[[1,2.56,6.01],[8,2.42,11.56],[9,2.4,8.57],[2,2.54,17.86],[4,2.5,4.69],[5,2.48,8.37],[6,2.46,9.89],[7,2.44,120.89],[3,2.52,29.85],[0,2.6,4.46]],"bdatl":[[8,2.84,22.8],[1,2.64,31.38],[3,2.68,7.42],[5,2.72,37.26],[7,2.82,13.53],[9,2.86,9.75],[0,2.62,3.92],[2,2.66,19.73],[6,2.78,37.35],[4,2.7,3.22]],"id":36276560},{"atb":[[5.4,5.17]],"atl":[[5.7,4.94],[6.8,2.22]],"bdatb":[[5,4.9,23.67],[6,4.8,8.84],[7,4.7,3.91],[8,4.5,14.92],[9,4.4,57.46],[0,5.4,5.17],[2,5.2,12.55],[3,5.1,21.56],[4,5,28.7]],"bdatl":[[8,7,2.2],[9,7.2,1.01],[5,6.4,6.64],[6,6.6,2.54],[0,5.7,4.94],[7,6.8,2.22],[2,5.9,11.97]],"id":37947503},{"atl":[[29,3.57],[21,0]],"bdatb":[[6,14.5,10.85],[7,14,7.29],[8,13.5,2.21],[9,13,4.05],[5,15,6.47]],"bdatl":[[2,22,1.61],[3,24,4.13],[4,26,2.84],[5,27,1.54],[6,29,3.57],[7,32,8.06],[8,36,8.91],[9,60,2.5]],"id":44331354},{"bdatb":[[3,1.21,222.74],[4,1.2,235.55],[5,1.19,146.02],[6,1.18,26.51],[8,1.16,231.49],[9,1.15,9.35],[1,1.23,119.98],[2,1.22,54.72],[7,1.17,21.88]],"bdatl":[[5,1.31,21.66],[6,1.32,15.44],[7,1.33,4.49],[8,1.34,131.73],[9,1.35,22.71],[3,1.29,36.62],[4,1.3,17.48]],"id":39823721}],"con":true}]}
{"op":"mcm","clk":"AKmxAQCrlQEAyJkB","pt":1650392810518,"mc":[{"id":"1.197931751","rc":[{"atb":[[2.64,25.09],[2.68,7.57],[2.66,24.79],[2.74,5.28],[2.62,59.81],[2.76,2.22],[2.54,5.6],[2.72,3.26],[2.7,5.73],[1.01,31823.22]],"atl":[[3.25,8.89],[1000,153.83],[2.78,15.92],[2.98,0],[2.8,12.02],[2.76,0],[2.74,0]],"trd":[[2.76,24.16],[2.74,67.15]],"bdatb":[[1,2.74,5.28],[4,2.68,7.57],[5,2.66,24.79],[7,2.62,61.39],[0,2.76,2.22],[2,2.72,3.26],[3,2.7,5.73],[6,2.64,7.38],[8,2.6,20.16],[9,2.58,11.87]],"bdatl":[[0,2.78,15.92],[1,2.8,12.02],[6,3.05,29.93],[7,3.1,10.36],[8,3.15,5.01],[9,3.2,9.11],[2,2.84,3.17],[3,2.88,17.4],[4,2.9,50.13],[5,2.96,1.37]],"ltp":2.76,"tv":685.08,"id":42930960},{"atb":[[4.1,32.07],[4.2,26.56],[4.3,32.78],[2.9,6.48],[4.5,3.61]],"atl":[[5.6,32.61],[4.7,11.6],[5.7,0],[5.5,23],[5.3,0],[4.8,8.91]],"bdatb":[[4,4.1,33.08],[6,3.95,44.87],[7,3.9,2],[8,3.85,6.65],[9,3.8,2],[3,4.2,26.56],[5,4,29.11],[2,4.3,32.78],[0,4.5,3.61],[1,4.4,9.15]],"bdatl":[[1,4.7,11.6],[5,5.2,11.27],[6,5.3,1.21],[7,5.4,24.08],[8,5.5,24.94],[9,5.6,3.62],[3,4.9,7.77],[4,5,4.17],[2,4.8,8.91],[0,4.6,1]],"id":40095374},{"atb":[[2.6,0],[2.52,20.86],[2.4,12.12],[2.44,104.09],[2.46,19.03]],"atl":[[2.6,18.3],[2.84,25.62],[3.05,0],[2.72,14.18],[2.66,33.96],[2.68,4.1]],"trd":[[2.6,35.23]],"bdatb":[[3,2.52,20.86],[8,2.4,28.65],[9,2.38,20.43],[4,2.5,24.05],[5,2.48,3.67],[6,2.46,19.03],[7,2.44,104.28]],"bdatl":[[5,2.72,16.44],[6,2.74,3.48],[7,2.78,37.56],[8,2.82,11.7],[9,2.84,20.67],[2,2.66,33.96],[3,2.68,4.1]],"tv":367.47,"id":36276560},{"atb":[[5.4,2.9]],"bdatb":[[7,4.7,10.4],[8,4.6,4.08],[9,4.5,10.27],[3,5.1,19.55],[4,5,28.42],[5,4.9,13.2],[6,4.8,6.96],[2,5.2,12.55],[0,5.4,2.9]],"bdatl":[[6,6.6,3.85],[7,6.8,2.58],[8,7,2.21],[9,7.2,1.61],[2,5.9,13.01],[3,6,5.78],[4,6.2,4.71],[5,6.4,5.88]],"id":37947503},{"atb":[[1.25,49.6]],"atl":[[1.28,100.99],[1.26,3.28]],"trd":[[1.26,405.66]],"bdatb":[[3,1.21,218.27],[4,1.2,246.46],[5,1.19,143.06],[6,1.18,10.31],[7,1.17,42.54],[8,1.16,240.07],[9,1.15,8.26],[1,1.23,119.98],[2,1.22,40.04]],"bdatl":[[2,1.28,104.16],[3,1.29,28.76],[4,1.3,25.07],[5,1.31,15.48],[6,1.32,26.75],[7,1.33,6.57],[8,1.34,126.82],[9,1.35,25.3],[1,1.27,185.49],[0,1.26,3.28]],"tv":2209.49,"id":39823721},{"atl":[[32,4.84]],"bdatb":[[7,14,7.29],[8,13.5,1.76],[9,13,3.63],[6,14.5,10.85]],"bdatl":[[8,36,9.03],[9,60,2.23],[4,26,3.07],[6,29,3.77],[7,32,8.06]],"id":44331354}],"con":true,"tv":3502.95}]}
{"op":"mcm","clk":"AMyyAQC3lgEAyJoB","pt":1650392811519,"mc":[{"id":"1.197931751","rc":[{"atb":[[2.54,18.59],[2.76,0],[2.66,38.67],[2.42,0],[1.01,31525.06]],"atl":[[2.78,11.97],[2.88,23.75],[2.8,17.61],[1000,152.14]],"bdatb":[[0,2.74,5.28],[1,2.72,3.26],[2,2.7,5.73],[3,2.68,7.57],[4,2.66,40.23],[5,2.64,25.09],[6,2.62,59.99],[7,2.6,20.16],[8,2.58,20.83],[9,2.56,50.9]],"bdatl":[[0,2.78,11.97],[3,2.88,23.75],[6,3,3.81],[7,3.05,33.47],[9,3.2,11.48],[4,2.9,53.53],[1,2.8,17.61],[5,2.92,1.69],[8,3.1,4.97]],"id":42930960},{"atb":[[4.3,29.52]],"atl":[[5.8,52.08],[4.8,11.49]],"bdatb":[[4,4.1,39.18],[5,4,35.43],[6,3.95,32.27],[7,3.9,4.31],[8,3.85,4.31],[9,3.8,19.68],[2,4.3,30.48],[3,4.2,26.56]],"bdatl":[[3,4.9,5.58],[4,5,6.89],[5,5.2,11.23],[6,5.4,25.61],[7,5.5,26.69],[8,5.6,33.13],[9,5.8,52.54],[2,4.8,11.49]],"id":40095374},{"atb":[[2.48,2],[2.46,38.93],[1.01,24061.17],[2.28,12.12],[2.52,14.91],[2.54,10.66],[2.4,0],[2.56,0],[2.5,2]],"atl":[[2.92,15.51],[2.62,17.23],[2.66,19.73],[2.68,0],[2.58,22.59],[2.6,40.41]],"trd":[[2.56,12.72]],"bdatb":[[3,2.48,3.67],[4,2.46,38.93],[6,2.4,11.95],[7,2.38,25.05],[8,2.36,25.43],[9,2.32,2.51],[0,2.54,10.66],[1,2.52,14.91],[2,2.5,2],[5,2.44,104.28]],"bdatl":[[4,2.66,19.73],[5,2.68,4],[6,2.7,4.6],[7,2.72,14.62],[8,2.78,40.11],[9,2.8,3.9],[2,2.62,17.23],[0,2.58,22.59],[1,2.6,40.41],[3,2.64,31.38]],"ltp":2.56,"tv":371.47,"id":36276560},{"atb":[[1.25,47.09],[1.22,163.67]],"trd":[[1.25,508.66]],"bdatb":[[3,1.22,207.67],[4,1.21,210.04],[5,1.2,223.27],[6,1.19,138.37],[7,1.18,47.45],[9,1.16,220.89],[8,1.17,31.28],[1,1.24,58.28],[0,1.25,49.6],[2,1.23,123.72]],"bdatl":[[2,1.28,100.99],[3,1.29,40.44],[4,1.3,17.26],[5,1.31,18.19],[6,1.32,18.81],[7,1.33,13.3],[8,1.34,113.87],[9,1.35,7.38],[1,1.27,176.36]],"ltp":1.25,"tv":2214.51,"id":39823721},{"atl":[[36,16.05]],"bdatb":[[5,15,6.75],[7,14,7.29],[8,13.5,1.49],[9,13,3.63]],"bdatl":[[6,29,3.57],[7,32,5.32],[8,36,16.09],[9,60,2.44],[4,26,2.84]],"id":44331354},{"bdatb":[[7,4.7,4.99],[8,4.5,11.29],[9,4.4,68.37],[2,5.2,13.35],[3,5.1,19.55],[5,4.9,24.06],[6,4.8,5.95],[4,5,27.69]],"bdatl":[[3,6,5.01],[4,6.2,6.9],[5,6.4,5.43],[6,6.6,3.86],[7,6.8,3.28],[8,7,3.17],[2,5.9,11.97],[9,7.4,24.06]],"id":37947503}],"con":true,"tv":3511.97}]}
{"op":"mcm","clk":"ANuzAQC1lwEA0psB","pt":1650392812521,"mc":[{"id":"1.197931751","rc":[{"atb":[[2.76,2.94],[2.7,24.25],[2.06,0],[2.72,8.69],[2.62,59.81]],"atl":[[2.78,11.9]],"bdatb":[[0,2.76,2.94],[1,2.74,5.28],[2,2.72,8.69],[3,2.7,24.25],[4,2.68,9.11],[5,2.66,38.67],[6,2.64,25.27],[7,2.62,59.81],[8,2.6,29.23],[9,2.58,23.36]],"bdatl":[[0,2.78,11.9],[4,2.9,49.83],[5,2.94,5.29],[6,3.05,28.97],[7,3.1,4.18],[8,3.15,7.05],[9,3.2,9.83]],"id":42930960},{"atb":[[2.44,124.27],[2.46,39.03],[2.52,6.17],[2.54,0],[2.5,6.27]],"atl":[[2.56,22.77],[2.64,22.95],[2.6,43.27],[2.58,13.61],[2.88,8.77],[2.62,20.15],[2.66,15.81]],"trd":[[2.54,26.78]],"bdatb":[[5,2.4,11.87],[6,2.38,25.13],[7,2.36,25.43],[8,2.32,2.51],[9,2.3,78.33],[0,2.52,6.17],[1,2.5,6.27],[2,2.48,3.67],[3,2.46,39.03],[4,2.44,124.46]],"bdatl":[[0,2.56,22.77],[5,2.66,18.86],[6,2.7,6.03],[7,2.72,14.4],[8,2.76,2.3],[9,2.78,41.56],[2,2.6,43.27],[4,2.64,22.95],[1,2.58,13.61],[3,2.62,20.15]],"ltp":2.54,"tv":387.55,"id":36276560},{"atb":[[1.22,31.62]],"atl":[[1000,363.72]],"bdatb":[[2,1.23,139.15],[3,1.22,56.99],[4,1.21,209.39],[5,1.2,225.92],[6,1.19,137.19],[7,1.18,45.9],[8,1.17,31.28],[9,1.16,220.89],[1,1.24,61.99],[0,1.25,47.09]],"bdatl":[[3,1.29,40.36],[4,1.3,16.9],[5,1.31,15.2],[6,1.32,18.77],[7,1.33,1.44],[8,1.34,122.93],[9,1.35,25.37]],"id":39823721},{"bdatb":[[3,4.2,32.28],[4,4.1,39.41],[5,4,29.12],[6,3.95,33.73],[7,3.9,2.83],[8,3.85,4.84],[9,3.8,19.2]],"bdatl":[[4,5,5.62],[5,5.1,1.46],[6,5.2,9.54],[7,5.3,1.31],[8,5.4,24.33],[9,5.5,23.55]],"id":40095374},{"bdatb":[[4,5,33.29],[5,4.9,18.42],[6,4.8,10.6],[7,4.6,1.97],[8,4.5,9.74],[9,4.4,67.96],[1,5.3,14.94],[2,5.2,12.55],[3,5.1,19.64]],"bdatl":[[5,6.4,6.01],[6,6.6,3.18],[7,6.8,3.49],[8,7.2,2.1],[9,7.4,24.71],[4,6.2,6.3]],"id":37947503},{"bdatb":[[8,13.5,3.2],[4,15.5,12.23],[5,15,6.47],[7,14,7.32]],"bdatl":[[7,32,5.11],[8,36,16.27],[9,60,2.13]],"id":44331354}],"con":true,"tv":3528.05}]}
{"op":"mcm","clk":"APe0AQDDmAEA3pwB","pt":1650392813522,"mc":[{"id":"1.197931751","rc":[{"atb":[[2.68,38.1],[2.72,32.73],[2.56,7.5],[2.7,26.25],[2.76,5.02],[2.66,34.05],[2.14,16.07],[2.74,10.46]],"atl":[[2.82,4.76],[2.8,12.7],[2.78,0]],"trd":[[2.78,25.6]],"bdatb":[[2,2.72,32.73],[4,2.68,39.64],[3,2.7,26.25],[0,2.76,5.02],[5,2.66,34.05],[8,2.6,22.5],[9,2.58,18.47],[1,2.74,10.46]],"bdatl":[[1,2.82,4.76],[0,2.8,12.7],[2,2.84,3.17],[3,2.88,23.75],[4,2.9,49.83],[5,2.94,1.71],[6,2.96,1.92],[7,2.98,1.65],[8,3.05,25.49],[9,3.1,4.8]],"ltp":2.78,"tv":689.16,"id":42930960},{"atb":[[1.72,103.16],[1.8,0],[2.42,20.46],[2.44,104.09],[2.52,2]],"atl":[[2.6,65.74],[2.78,45.43],[2.7,0],[2.62,17.23],[2.98,0],[2.56,4.17],[2.58,31.17]],"bdatb":[[5,2.42,20.65],[6,2.4,9.82],[7,2.38,17.29],[8,2.36,21.3],[9,2.34,3.85],[4,2.44,104.09],[2,2.48,2],[3,2.46,40.71],[0,2.52,2]],"bdatl":[[2,2.6,55.18],[5,2.66,19.84],[6,2.68,1.17],[7,2.72,15.07],[9,2.78,48.4],[3,2.62,17.23],[0,2.56,4.17],[1,2.58,31.17],[8,2.76,6.53]],"id":36276560},{"atb":[[1.22,163.67]],"bdatb":[[3,1.22,184.07],[4,1.21,208.72],[5,1.2,238.68],[1,1.24,58.28],[2,1.23,128.66],[6,1.19,142.86],[7,1.18,47.86]],"bdatl":[[9,1.35,48.3],[3,1.29,36.62],[4,1.3,20.6],[7,1.33,12.66],[8,1.34,118.21],[5,1.31,13.78],[6,1.32,13.68]],"id":39823721},{"bdatb":[[5,4,30.55],[7,3.9,9.73],[9,3.8,11.29],[3,4.2,26.56],[4,4.1,37.93],[6,3.95,32.27],[8,3.85,5.08]],"bdatl":[[5,5.1,1.73],[6,5.2,9.87],[7,5.4,24.6],[8,5.5,24.56],[9,5.6,34.08],[4,5,5.01]],"id":40095374},{"bdatb":[[6,4.8,8.57],[8,4.5,16.64],[9,4.4,65.02],[5,4.9,19.42],[1,5.3,14.16],[2,5.2,13.35],[3,5.1,19.55],[4,5,27.69],[7,4.7,1.92]],"bdatl":[[4,6.2,6.3],[5,6.4,6.01],[6,6.6,2.9],[7,6.8,2.95],[8,7,1.23],[9,7.2,3.09]],"id":37947503},{"bdatb":[[4,15.5,11.96],[5,15,6.75],[7,14,7.29],[8,13.5,1.49],[9,13,4.1]],"bdatl":[[8,36,16.31],[9,60,2.14],[7,32,5.01]],"id":44331354}],"con":true,"tv":3532.13}]}
{"op":"mcm","clk":"AK22AQDsmQEA3J0B","pt":1650392814523,"mc":[{"id":"1.197931751","rc":[{"atb":[[2.76,2.08],[2.66,21.46],[2.72,42.59]],"atl":[[2.78,2.63],[2.8,9.52],[2.84,6.76]],"bdatb":[[4,2.68,38.1],[6,2.64,26.83],[7,2.62,59.81],[8,2.6,22.5],[9,2.58,18.47],[2,2.72,42.59],[5,2.66,21.46]],"bdatl":[[3,2.88,25.31],[5,2.96,3.77],[6,3,1.68],[7,3.05,24.49],[8,3.1,4.42],[9,3.15,2.45],[0,2.8,9.52],[4,2.9,49.83],[2,2.84,6.76]],"id":42930960},{"atb":[[4.1,35.86],[4.2,17.47],[4.4,4.15],[4.5,1]],"atl":[[4.7,19.53]],"bdatb":[[3,4.2,17.47],[0,4.5,1],[1,4.4,4.15],[2,4.3,29.52],[4,4.1,38.94],[5,4,30.88],[7,3.9,9.4],[9,3.8,11.63]],"bdatl":[[1,4.7,21.84],[3,4.9,7.77],[4,5,4.99],[5,5.2,11.63],[6,5.4,24.16],[7,5.5,23.4],[8,5.6,33.69],[9,5.7,7.52]],"id":40095374},{"atb":[[2.44,124.27],[2.48,6.35],[2.46,24.85]],"atl":[[2.6,58.7],[2.62,3.92]],"bdatb":[[4,2.44,124.27],[9,2.34,8.21],[2,2.48,6.35],[3,2.46,24.85],[5,2.42,22.36],[6,2.4,9.19],[7,2.38,14.82],[8,2.36,20.65]],"bdatl":[[3,2.62,5.64],[5,2.66,19.33],[6,2.72,17.46],[7,2.76,1.37],[8,2.78,45.43],[9,2.8,2.76],[4,2.64,22.95],[2,2.6,58.7]],"id":36276560},{"atb":[[1.21,212.24],[1.26,21.06]],"atl":[[1000,356.08],[1.27,115.27],[1.29,28.3],[1.26,0],[1.28,96.18]],"trd":[[1.26,472.72],[1.27,304.92]],"bdatb":[[5,1.21,237.95],[6,1.2,244.91],[7,1.19,149.06],[8,1.18,51.73],[9,1.17,36.84],[0,1.26,21.06],[1,1.25,47.09],[2,1.24,58.28],[3,1.23,128.66],[4,1.22,178.01]],"bdatl":[[0,1.27,115.27],[2,1.29,31.79],[6,1.33,8.66],[7,1.34,113.94],[8,1.35,40.8],[9,1.36,38.29],[1,1.28,96.18],[3,1.3,24.01],[4,1.31,15.16],[5,1.32,11.46]],"ltp":1.27,"tv":2281.59,"id":39823721},{"bdatb":[[7,4.7,4.09],[8,4.6,6.91],[9,4.5,12.88],[2,5.2,12.55],[3,5.1,19.55],[4,5,28.51],[5,4.9,17.61]],"bdatl":[[2,5.9,12.73],[4,6.2,5.57],[5,6.4,6.71],[6,6.6,2.53],[7,6.8,2.78],[8,7,1.1],[9,7.4,24.44],[3,6,5.01]],"id":37947503},{"bdatb":[[5,15,6.47],[7,14,7.29],[8,13.5,1.79],[9,13,4.1]],"bdatl":[[4,26,3.01],[6,29,3.59],[7,32,5.12],[8,36,16.1],[9,60,2.23]],"id":44331354}],"con":true,"tv":3599.21}]}
{"op":"mcm","clk":"AN+3AQD8mgEA154B","pt":1650392815525,"mc":[{"id":"1.197931751","rc":[{"atb":[[2.66,16.17],[2.74,5.88],[2.36,20.66],[2.56,7.5],[2.7,45.81],[2.68,20.81],[1.01,31232.6],[2.72,17.81],[2.76,0]],"atl":[[2.76,7.72],[2.78,9.58],[2.9,49.83]],"trd":[[2.74,106.27],[2.76,28.32]],"bdatb":[[0,2.74,5.88],[4,2.66,17.9],[5,2.64,25.09],[6,2.62,62.41],[7,2.6,25.14],[8,2.58,13.17],[9,2.56,20.84],[1,2.72,17.81],[2,2.7,45.81],[3,2.68,20.81]],"bdatl":[[0,2.76,7.72],[1,2.78,9.58],[7,2.96,1.52],[8,3.05,29.81],[9,3.1,4.42],[2,2.8,9.52],[3,2.82,4.76],[4,2.84,6.76],[5,2.88,23.75],[6,2.9,49.83]],"ltp":2.74,"tv":732.44,"id":42930960},{"atb":[[4,23.1],[4.2,24.73],[4.1,21.39]],"atl":[[4.7,21.76]],"bdatb":[[4,4.1,27.14],[5,4,31.7],[6,3.95,33.72],[7,3.9,6.93],[8,3.85,4.31],[9,3.8,11.87],[2,4.3,32.17],[3,4.2,27.81]],"bdatl":[[5,5.2,12.62],[6,5.3,1.97],[7,5.4,22.73],[8,5.5,25.22],[9,5.6,32.61],[4,5,4],[3,4.9,5.58],[1,4.7,21.76]],"id":40095374},{"atb":[[2.44,124.81],[2.46,36.3],[2.48,0],[2.32,12.12],[1.01,23704.66],[2.36,3.49],[2.5,0],[2.52,0]],"atl":[[2.64,18.16],[2.6,58.7],[2.54,4.49],[2.82,12.16],[2.86,11.75],[2.56,5.06]],"trd":[[2.52,30.5],[2.5,6]],"bdatb":[[1,2.44,124.81],[0,2.46,38.17],[2,2.42,27.36],[3,2.4,11.1],[4,2.38,20.23],[5,2.36,8.68],[6,2.34,5.74],[7,2.32,20.24],[8,2.3,77.08],[9,2.28,28.58]],"bdatl":[[3,2.6,58.7],[5,2.64,19.86],[7,2.68,4.33],[8,2.7,2.46],[9,2.72,14.18],[0,2.54,4.49],[1,2.56,5.06],[2,2.58,31.17],[4,2.62,3.92],[6,2.66,15.81]],"ltp":2.5,"tv":397.55,"id":36276560},{"atb":[[5.2,19.46],[5.4,7.18]],"atl":[[5.9,13.97],[5.8,5.89],[12.5,0]],"bdatb":[[3,5.1,22.82],[4,5,28.2],[5,4.9,23.36],[7,4.7,3.57],[8,4.5,9.82],[9,4.4,65.9],[2,5.2,19.46],[1,5.3,15.03],[0,5.4,7.18]],"bdatl":[[6,6.6,3.98],[7,6.8,3.2],[9,7.6,7.24],[4,6.2,4.57],[5,6.4,5.85],[8,7.4,24.9],[1,5.8,5.89],[2,5.9,13.97],[3,6,5.01]],"id":37947503},{"atb":[[1.23,82.37],[1.25,105.33],[1.17,0],[1.24,62.84],[1.21,180.26]],"atl":[[1.29,66.84],[1.34,117.7],[1.3,6.89]],"bdatb":[[2,1.24,68.33],[3,1.23,92.9],[5,1.21,201.48],[6,1.2,234.11],[7,1.19,135.8],[8,1.18,51.73],[1,1.25,109.01],[4,1.22,194.8],[9,1.17,10.69]],"bdatl":[[8,1.35,37.43],[9,1.36,44.39],[3,1.3,6.89],[4,1.31,13.36],[5,1.32,23.75],[2,1.29,66.84],[6,1.33,8.66],[7,1.34,121.06]],"id":39823721},{"bdatb":[[6,14.5,11.32],[7,14,7.29],[4,15.5,12.26],[8,13.5,2.41],[9,13,3.63]],"bdatl":[[9,60,2.49],[8,36,16.05],[7,32,4.84],[5,27,1.54],[4,26,2.84],[6,29,3.57]],"id":44331354}],"con":true,"tv":3652.49}]}
{"op":"mcm","clk":"AI25AQD3mwEA5J8B","pt":1650392816527,"mc":[{"id":"1.197931751","rc":[{"atb":[[2.76,2.63],[2.66,30.72],[2.78,0],[2.32,52.43],[2.74,3.15]],"atl":[[1000,148.88],[2.82,14.92],[2.8,6.91],[2.76,0],[2.78,0]],"trd":[[2.78,68.16],[2.76,43.76],[2.74,111.73]],"bdatb":[[0,2.74,3.15],[1,2.72,17.81],[2,2.7,45.81],[3,2.68,20.81],[4,2.66,17.9],[5,2.64,25.09],[6,2.62,62.41],[7,2.6,26.61],[8,2.58,14.25],[9,2.56,7.5]],"bdatl":[[0,2.8,9.52],[1,2.82,4.76],[2,2.84,6.76],[3,2.88,23.75],[4,2.9,49.83],[5,2.96,1.52],[6,3.05,29.81],[7,3.1,4.42],[8,3.15,2.45],[9,3.2,14.21]],"ltp":2.78,"tv":795.9,"id":42930960},{"atb":[[2.44,104.09],[2.42,27.11],[2.46,20.59]],"atl":[[2.6,40.41],[2.56,31.44]],"bdatb":[[0,2.46,20.59],[2,2.42,32.75],[3,2.4,9.19],[4,2.38,14.82],[5,2.36,6.29],[6,2.32,22.68],[7,2.3,76.92],[8,2.28,22.22],[9,2.26,10.86],[1,2.44,118.27]],"bdatl":[[3,2.6,40.41],[5,2.64,19.86],[6,2.66,15.81],[7,2.68,1.54],[8,2.7,5.23],[9,2.72,14.18],[1,2.56,31.44]],"id":36276560},{"atb":[[1.24,73.42],[1.21,180.26]],"atl":[[1.27,17.94],[1.28,143.01],[1.3,6.89],[1.31,9.92]],"bdatb":[[1,1.25,105.33],[2,1.24,75.11],[3,1.23,100.3],[4,1.22,174.67],[5,1.21,198.66],[6,1.2,255.51],[7,1.19,167.33],[8,1.18,19.94]],"bdatl":[[3,1.3,6.89],[4,1.31,13.36],[5,1.32,23.75],[6,1.33,8.66],[7,1.34,121.06],[8,1.35,13.55],[9,1.36,68.09],[0,1.27,27.39],[1,1.28,143.01]],"id":39823721},{"bdatb":[[2,4.3,29.52],[3,4.2,27.44],[4,4.1,27.09],[5,4,24.42],[6,3.95,37.14],[7,3.9,2],[8,3.85,5.1],[9,3.8,9.77]],"bdatl":[[4,5,4],[5,5.2,11.58],[6,5.3,2.98],[7,5.4,22.73],[8,5.5,25.22],[9,5.6,32.61]],"id":40095374},{"bdatb":[[1,5.3,14.16],[3,5.1,20.45],[4,5,28.95],[5,4.9,17.88],[6,4.8,5.77],[7,4.7,5.21],[8,4.6,5.01],[9,4.5,14.75]],"bdatl":[[4,6.2,4.57],[5,6.4,5.85],[6,6.6,2.85],[7,6.8,4.3],[8,7.4,24.9],[9,7.6,2.16]],"id":37947503},{"bdatb":[[4,15.5,11.96],[6,14.5,11.17],[8,13.5,1.96],[9,13,4.8]],"bdatl":[[7,32,4.84],[9,60,2.47]],"id":44331354}],"con":true,"tv":3715.95}]}
{"op":"mcm","clk":"AJW6AQDvnAEA4qAB","pt":1650392817528,"mc":[{"id":"1.197931751","rc":[{"atb":[[2.32,53.89],[2.7,20.83],[2.68,38.1],[2.74,7.91],[2.76,2.62],[1.01,30512.85],[2.66,16.17],[2.72,34.9]],"atl":[[2.86,9.41],[2.82,2],[2.8,0],[1000,146.42],[2.84,3.59]],"bdatb":[[3,2.7,20.83],[4,2.68,38.1],[1,2.74,7.91],[0,2.76,2.62],[2,2.72,34.9],[5,2.66,17.9],[6,2.64,25.09],[7,2.62,62.41],[8,2.6,26.61],[9,2.58,14.25]],"bdatl":[[8,3.15,2.45],[9,3.2,10.5],[0,2.82,2],[2,2.86,9.41],[3,2.88,23.75],[4,2.9,49.83],[5,2.96,1.52],[6,3.05,29.81],[7,3.1,4.42],[1,2.84,3.59]],"id":42930960},{"atb":[[2.42,18.96],[2.4,20.75],[2.46,14.89]],"atl":[[2.58,35.38]],"bdatb":[[2,2.42,18.96],[3,2.4,22.67],[0,2.46,14.89],[4,2.38,14.62],[5,2.36,13.04],[6,2.34,2.82],[7,2.32,12.12],[8,2.3,80.39],[9,2.28,29.47],[1,2.44,104.09]],"bdatl":[[8,2.72,15.57],[9,2.78,46.28],[4,2.62,5.64],[5,2.64,18.16],[6,2.66,16.84],[7,2.68,5.79],[2,2.58,35.38]],"id":36276560},{"atb":[[1.23,208.67]],"atl":[[1.27,27.39]],"bdatb":[[3,1.23,213.26],[4,1.22,172.03],[5,1.21,218.69],[2,1.24,73.42],[6,1.2,255.51],[7,1.19,167.33],[8,1.18,19.94]],"bdatl":[[3,1.3,10.35],[4,1.31,12],[5,1.32,21.68],[6,1.33,8.66],[7,1.34,119.46],[8,1.35,57.2],[9,1.36,26.34],[0,1.27,27.39]],"id":39823721},{"bdatb":[[3,4.2,26.07],[4,4.1,23.88],[5,4,27.84],[6,3.95,32.27],[7,3.9,4.04],[8,3.85,9.4],[9,3.8,9.77]],"bdatl":[[6,5.2,13.23],[7,5.4,23.17],[8,5.5,24.4],[5,5.1,1.42],[9,5.6,32.61]],"id":40095374},{"bdatb":[[5,4.9,14.49],[6,4.8,10.64],[7,4.6,10.33],[8,4.5,14.75],[9,4.4,57.98],[4,5,27.59]],"bdatl":[[8,7.4,24.91],[6,6.6,4.99],[7,6.8,2.22],[9,7.8,14.8]],"id":37947503},{"bdatb":[[9,13,3.71],[6,14.5,10.85],[8,13.5,1.79]],"bdatl":[[9,60,2.47],[8,36,16.18]],"id":44331354}],"con":true}]}
{"op":"mcm","clk":"AK67AQD+nQEA3KEB","pt":1650392818529,"mc":[{"id":"1.197931751","rc":[{"atb":[[2.28,161.5],[2.74,4.76],[2.16,10.47],[2.66,33.67],[2.14,0],[2.68,20.81]],"atl":[[2.86,32.51],[2.9,52.72],[2.84,13.13],[2.82,8.88]],"bdatb":[[1,2.74,4.76],[6,2.64,26.83],[7,2.62,59.81],[8,2.6,23.89],[9,2.58,17.07],[5,2.66,33.67],[4,2.68,20.81]],"bdatl":[[2,2.86,32.51],[4,2.9,54.27],[1,2.84,13.13],[5,2.96,2.53],[6,3,3.58],[7,3.05,25.06],[8,3.1,5.69],[9,3.15,1.43],[0,2.82,8.88]],"id":42930960},{"atl":[[5.2,0],[5.1,9.76]],"bdatb":[[7,3.9,8.53],[8,3.85,4.85],[9,3.8,2],[4,4.1,27.49],[5,4,25.54],[6,3.95,32.27],[3,4.2,24.73]],"bdatl":[[5,5.1,11.38],[6,5.2,1.2],[7,5.4,24.16],[9,5.6,35.9],[3,4.9,7.05],[4,5,4.95],[8,5.5,23.82]],"id":40095374},{"atb":[[2.42,53.59],[2.48,18.21],[2.46,43.57],[2.44,110.28],[2.28,6.29],[2.32,6.29],[2.5,4.8]],"atl":[[2.56,5.58],[2.6,8.63],[2.58,17.82],[2.78,41.54],[2.84,21.73],[2.9,47.19],[2.54,0]],"bdatb":[[4,2.42,53.59],[1,2.48,18.21],[2,2.46,43.57],[0,2.5,4.8],[3,2.44,110.28],[5,2.4,22.67],[6,2.38,22.77],[7,2.36,4.82],[8,2.34,2.82],[9,2.32,18.16]],"bdatl":[[0,2.56,5.58],[1,2.58,17.82],[2,2.6,8.63],[3,2.62,5.64],[4,2.64,18.16],[5,2.66,16.84],[6,2.68,4.87],[7,2.72,15.1],[8,2.74,1.38],[9,2.78,41.54]],"id":36276560},{"atl":[[13.5,0]],"bdatb":[[4,5,28.51],[5,4.9,15.08],[6,4.8,8.01],[8,4.6,5.54],[9,4.5,14.28],[7,4.7,2.08],[3,5.1,19.55]],"bdatl":[[8,7.2,1.07],[9,7.4,26.42],[3,6,5.76],[4,6.2,5.01],[5,6.4,5.9],[6,6.6,3.85],[7,6.8,2.78]],"id":37947503},{"atb":[[1.25,91.15],[1.23,82.37]],"bdatb":[[3,1.23,86.11],[4,1.22,180.41],[5,1.21,209.37],[6,1.2,236.8],[7,1.19,156.12],[8,1.18,37.16],[9,1.17,14.75],[1,1.25,91.15]],"bdatl":[[4,1.31,19.88],[5,1.32,11.8],[6,1.33,12.04],[8,1.35,42.98],[9,1.36,25.35],[7,1.34,131.43],[2,1.29,70.33],[3,1.3,8.99]],"id":39823721},{"atl":[[27,0],[25,1.67]],"bdatb":[[9,13,3.98],[8,13.5,1.45]],"bdatl":[[4,25,1.67],[5,26,2.84],[9,60,2.33],[6,29,3.73],[7,32,4.93],[8,36,16.18]],"id":44331354}],"con":true}]}
{"op":"mcm","clk":"ANO8AQD4ngEA96IB","pt":1650392819530,"mc":[{"id":"1.197931751","rc":[{"atb":[[2.24,143.42],[2.76,2.66],[2.7,63.28],[2.72,17.81]],"atl":[[2.82,19.04]],"bdatb":[[0,2.76,2.66],[1,2.74,4.76],[2,2.72,17.81],[3,2.7,63.28],[4,2.68,20.81],[5,2.66,33.67],[6,2.64,26.83],[7,2.62,59.81],[8,2.6,23.89],[9,2.58,17.07]],"bdatl":[[0,2.82,19.04]],"id":42930960},{"atb":[[2.44,130.46],[2.46,49.65]],"atl":[[2.6,8.95],[2.62,21.05]],"bdatb":[[3,2.44,130.46],[6,2.38,24.09],[7,2.36,6.29],[8,2.32,18.17],[9,2.3,89.37],[2,2.46,49.65]],"bdatl":[[2,2.6,8.95],[3,2.62,22.77],[4,2.64,18.16],[5,2.66,16.88],[6,2.68,4.87],[7,2.72,15.06],[8,2.74,1.38],[9,2.78,41.54]],"id":36276560},{"atl":[[13.5,1.11]],"bdatb":[[9,4.5,16.12],[6,4.8,10.04],[7,4.7,4.02],[8,4.6,1.43]],"bdatl":[[3,6,5.76],[4,6.2,5.03],[5,6.4,5.88]],"id":37947503},{"atb":[[1.24,64.86]],"bdatb":[[6,1.2,237.8],[7,1.19,155.11],[2,1.24,64.86],[4,1.22,182.99],[5,1.21,206.77],[8,1.18,51.78],[9,1.16,239.21]],"bdatl":[[2,1.29,70.33],[3,1.3,9.08],[4,1.31,19.88],[5,1.32,11.71],[8,1.35,41.98],[9,1.36,26.34]],"id":39823721},{"atl":[[27,3.85]],"bdatl":[[6,29,3.73],[7,32,4.93],[8,36,16.18],[9,60,2.32]],"id":44331354},{"bdatb":[[9,3.8,7.57],[4,4.1,28.26],[5,4,24.75],[6,3.95,37.06],[7,3.9,3.69]],"bdatl":[[3,4.9,7.08],[4,5,4.93],[5,5.1,11.4],[6,5.2,1.18]],"id":40095374}],"con":true}]}
{"op":"mcm","clk":"AIG+AQDwnwEA/6MB","pt":1650392820532,"mc":[{"id":"1.197931751","rc":[{"atb":[[2.7,20.83],[2.72,56.48]],"atl":[[2.84,28.39]],"bdatb":[[9,2.58,13.21],[2,2.72,56.48],[3,2.7,20.83],[5,2.66,33.67],[6,2.64,26.83],[7,2.62,59.81],[8,2.6,23.89]],"bdatl":[[1,2.84,28.39]],"id":42930960},{"atb":[[2.48,29.15],[2.42,34.64]],"atl":[[2.54,0]],"bdatb":[[6,2.38,19.9],[7,2.36,10.52],[9,2.3,100.04],[1,2.48,29.15],[4,2.42,34.64],[8,2.32,14.43]],"bdatl":[[0,2.56,5.58],[1,2.58,17.82],[2,2.6,8.95],[3,2.62,22.77],[4,2.64,18.16],[5,2.66,16.88],[6,2.68,4.87],[7,2.72,15.06],[8,2.74,1.38],[9,2.78,41.54]],"id":36276560},{"atb":[[4.9,9.78],[5,24.26]],"atl":[[1000,78.28],[5.9,15.97],[5.7,3.19],[5.8,3.89],[6.6,0],[6.8,0],[6.4,2.93]],"trd":[[5.7,3.79]],"bdatb":[[9,4.5,19.65],[3,5.1,19.55],[4,5,25.18],[5,4.9,11.75],[6,4.8,10.04],[8,4.6,1.43]],"bdatl":[[0,5.7,3.19],[1,5.8,3.89],[2,5.9,15.97],[5,6.4,3.66],[6,6.6,1.63],[7,7.2,1.63],[8,7.4,30.08],[9,7.6,7.39]],"ltp":5.7,"tv":77.3,"id":37947503},{"atl":[[29,5.36],[36,8.91]],"bdatb":[[8,13.5,1.45],[9,13,3.98]],"bdatl":[[6,27,3.85],[7,29,3.73],[8,32,4.93],[9,36,9.04]],"id":44331354},{"bdatb":[[4,4.1,25.83],[5,4,27.25],[6,3.95,33.79],[7,3.9,5.31],[3,4.2,24.73],[8,3.85,6.02],[9,3.8,8.12]],"bdatl":[[9,5.6,40.74]],"id":40095374},{"bdatb":[[4,1.22,174.82],[5,1.21,209.58],[7,1.19,178.17],[8,1.18,28.52],[9,1.16,241.5],[3,1.23,86.11],[6,1.2,243.27]],"bdatl":[[7,1.34,151.68],[8,1.35,48.42],[9,1.36,17.89]],"id":39823721}],"con":true,"tv":3719.24}]}
{"op":"mcm","clk":"AKy/AQCSoQEAhaUB","pt":1650392821692,"mc":[{"id":"1.197931751","rc":[{"atl":[[2.9,60.28]],"bdatb":[[9,2.58,14.12],[8,2.6,21.48]],"bdatl":[[4,2.9,52.72],[5,2.94,1.53],[6,2.98,2.09],[7,3.05,27.77],[8,3.1,8.36],[9,3.15,1.19]],"id":42930960},{"atb":[[2.9,0]],"atl":[[5.1,24.2]],"bdatb":[[8,3.85,8.27],[9,3.8,2.96],[4,4.1,23.35],[5,4,25.65],[6,3.95,36.47],[7,3.9,2]],"bdatl":[[3,4.9,5.58],[4,5,5.47],[5,5.1,10.67],[6,5.2,1.61],[7,5.3,2.62],[8,5.4,23.56],[9,5.5,23.68]],"id":40095374},{"atb":[[2.52,4.76],[2.5,12.21]],"bdatb":[[8,2.36,7.8],[9,2.34,7.09],[0,2.52,4.76],[1,2.5,12.21],[2,2.48,29.15],[3,2.46,49.65],[4,2.44,130.46],[5,2.42,34.64],[6,2.4,22.67],[7,2.38,15.62]],"bdatl":[[3,2.62,21.05],[5,2.66,17.5],[6,2.7,1.05],[7,2.72,15.43],[8,2.74,3.52],[9,2.78,42.4]],"id":36276560},{"atb":[[1.23,82.37],[1.24,62.84],[1.26,0]],"atl":[[1.28,156.99]],"bdatb":[[1,1.24,62.84],[3,1.22,171.61],[4,1.21,202.14],[5,1.2,234.65],[6,1.19,156.65],[7,1.18,46.46],[0,1.25,91.15],[2,1.23,86.11],[8,1.17,3.73],[9,1.16,243.02]],"bdatl":[[1,1.28,156.99],[3,1.3,12.66],[4,1.31,18.13],[5,1.32,18.64],[6,1.33,6.21],[7,1.34,170.92],[8,1.35,26.54]],"id":39823721},{"atb":[[1.04,0],[1.01,38824.73]],"atl":[[19.5,0.23],[1000,22.57],[21,2],[20,2],[32,8.06],[23,2]],"trd":[[19.5,13.87]],"bdatl":[[0,21,2.41],[1,22,1.61],[2,23,2],[3,24,4.13],[4,25,1.67],[5,26,2.84],[6,27,3.85],[7,29,5.36],[8,32,4.99],[9,36,8.98]],"tv":58.85,"id":44331354},{"bdatb":[[6,4.8,7.08],[7,4.7,4.36],[8,4.6,3.31],[9,4.5,11.57],[5,4.9,10.47]],"bdatl":[[3,6,5.01],[4,6.2,5.29],[5,6.4,3.9],[6,6.6,1.46],[7,7,1.99],[8,7.2,1.15],[9,7.4,32.97]],"id":37947503}],"con":true,"tv":3723.23}]}
{"op":"mcm","clk":"AM7AAQCvogEAkqYB","pt":1650392822694,"mc":[{"id":"1.197931751","rc":[{"atb":[[2.68,24.39],[2.72,17.81],[2.78,3.52],[2.76,4.74]],"atl":[[1000,141.76],[2.86,39.43],[2.84,15.26],[2.82,8.88]],"bdatb":[[3,2.72,17.81],[5,2.68,24.39],[8,2.62,59.81],[9,2.6,20.2],[0,2.78,3.52],[1,2.76,4.74],[2,2.74,4.76],[4,2.7,20.83],[6,2.66,33.67],[7,2.64,26.8]],"bdatl":[[2,2.86,39.43],[9,3.15,11.11],[4,2.9,60.28],[5,2.96,1.52],[6,3,2.08],[7,3.05,27.77],[8,3.1,6.91],[0,2.82,8.88],[1,2.84,15.26],[3,2.88,23.75]],"id":42930960},{"atb":[[4.1,33.21],[2.9,0]],"bdatb":[[4,4.1,34.31],[5,4,26.52],[6,3.95,34],[7,3.9,5.82],[8,3.85,4.53],[9,3.8,9.26]],"bdatl":[[7,5.3,2.46],[8,5.4,23.26],[9,5.5,28.54],[3,4.9,5.58],[4,5,5.96],[5,5.1,24.63],[6,5.2,2.09]],"id":40095374},{"atb":[[2.52,0],[2.5,4.8]],"atl":[[2.58,13.61],[2.6,11.45]],"bdatb":[[5,2.4,22.63],[6,2.38,14.22],[7,2.36,3.49],[8,2.34,5.81],[9,2.32,15.65],[0,2.5,4.8],[1,2.48,29.15],[2,2.46,49.65],[3,2.44,130.46],[4,2.42,34.64]],"bdatl":[[8,2.78,46.27],[9,2.8,1.02],[2,2.6,11.45],[4,2.64,19.86],[5,2.66,15.81],[6,2.68,1.97],[7,2.72,18.95],[3,2.62,21.05],[1,2.58,13.61]],"id":36276560},{"atb":[[5.2,12.55],[5.4,7.18]],"atl":[[13.5,1.01]],"bdatb":[[2,5.2,12.55],[4,5,25.16],[6,4.8,5.79],[7,4.7,4.35],[8,4.6,5.3],[0,5.4,7.18],[5,4.9,9.78],[9,4.5,15.91]],"bdatl":[[8,7.2,4.86],[9,7.4,25.35],[2,5.9,15.97],[4,6.2,5.29],[5,6.4,3.9],[6,6.6,1.82],[7,7,1.64]],"id":37947503},{"atb":[[1.25,94.15],[1.26,0],[1.23,208.67],[1.24,58.28]],"atl":[[1.27,67.39]],"bdatb":[[2,1.23,212.34],[3,1.22,163.74],[4,1.21,191.5],[5,1.2,237.21],[6,1.19,167.75],[7,1.18,28.53],[8,1.17,24.03],[0,1.25,91.15],[1,1.24,58.28],[9,1.16,246.21]],"bdatl":[[8,1.35,21.88],[9,1.36,26.34],[5,1.32,18.64],[6,1.33,3.39],[7,1.34,151.68],[0,1.27,67.39],[3,1.3,12.66],[4,1.31,18.13]],"id":39823721},{"atb":[[17.5,0],[14.5,6.19],[1.01,36063.49],[16,5.16]],"atl":[[1000,21.22],[20,0],[21,0],[19.5,0.23]],"bdatb":[[1,17.5,2],[2,17,14.53],[3,16.5,6.42],[4,16,5.16],[5,15.5,11.96],[6,15,6.47],[7,14.5,6.19],[8,14,7.29],[9,13.5,1.45]],"bdatl":[[0,22,1.84],[1,23,2],[2,24,4.13],[3,25,1.67],[4,26,2.84],[5,27,3.85],[6,29,5.36],[7,32,8.2],[8,36,9.05],[9,60,2.29]],"id":44331354}],"con":true}]}
{"op":"mcm","clk":"APXBAQCtowEAkKcB","pt":1650392823696,"mc":[{"id":"1.197931751","rc":[{"atb":[[2.68,17.49],[1.01,30094.73]],"atl":[[2.86,32.51]],"bdatb":[[6,2.66,35.36],[7,2.64,25.09],[8,2.62,59.85],[9,2.6,20.16],[5,2.68,17.49]],"bdatl":[[2,2.86,32.51],[9,3.15,1.43]],"id":42930960},{"atb":[[2.42,43.73]],"atl":[[2.54,4.72]],"bdatb":[[4,2.42,43.73]],"bdatl":[[0,2.54,4.72],[1,2.56,5.58],[2,2.58,13.61],[3,2.6,11.45],[4,2.62,21.05],[5,2.64,19.86],[6,2.66,15.81],[7,2.68,1.97],[8,2.72,18.95],[9,2.78,45.68]],"id":36276560},{"atb":[[5.2,19.46]],"bdatb":[[2,5.2,19.46],[3,5.1,20.43],[4,5,24.26],[5,4.9,9.79],[6,4.8,7.31],[7,4.7,3.04],[8,4.6,7.63],[9,4.5,14.67]],"bdatl":[[8,7.4,30.09],[9,7.6,4.39]],"id":37947503},{"atb":[[1.23,82.37]],"bdatb":[[3,1.22,169.8],[4,1.21,191.04],[5,1.2,231.52],[6,1.19,173.44],[7,1.18,22.79],[8,1.17,33.71],[9,1.16,236.44],[2,1.23,86.04],[0,1.25,94.15]],"id":39823721},{"atb":[[1.01,35698.28]],"atl":[[1000,20.91]],"bdatb":[[8,13.5,1.79],[9,13,4.2],[1,17,14.53],[2,16.5,6.42],[3,16,5.16],[4,15.5,11.96],[5,15,6.47],[6,14.5,6.19],[7,14,7.29]],"id":44331354},{"bdatb":[[3,4.2,25.8],[4,4.1,35.03],[5,4,26.36],[6,3.95,32.59],[7,3.9,5.5]],"bdatl":[[7,5.3,2.15],[8,5.4,23.03],[9,5.5,23.52]],"id":40095374}],"con":true}]}
{"op":"mcm","clk":"AJzDAQC8pAEAqagB","pt":1650392824697,"mc":[{"id":"1.197931751","rc":[{"atb":[[2.6,2],[2.74,21.81]],"atl":[[2.9,52.72]],"bdatb":[[9,2.6,2],[2,2.74,21.81]],"bdatl":[[4,2.9,52.72]],"id":42930960},{"atl":[[2.58,4.08],[2.6,8.95]],"bdatl":[[3,2.6,8.95]],"id":36276560},{"atl":[[25,0],[24,5.87]],"bdatl":[[2,24,5.87],[3,26,2.84],[4,27,3.85],[5,29,5.36],[6,32,8.2],[7,36,9.05],[8,60,2.29],[9,1000,21.72]],"id":44331354},{"bdatl":[[8,5.4,23.56],[9,5.5,30.97]],"id":40095374},{"bdatb":[[9,4.5,14.46]],"bdatl":[[8,7.2,6.72],[9,7.4,23.55]],"id":37947503},{"bdatb":[[6,1.19,172.37],[7,1.18,23.87],[8,1.17,28.15],[9,1.16,242.04]],"bdatl":[[8,1.35,34.64],[9,1.36,13.69]],"id":39823721}],"con":true}]}
{"op":"mcm","clk":"AMHEAQDFpQEAtqkB","pt":1650392825699,"mc":[{"id":"1.197931751","rc":[{"atb":[[2.78,0]],"bdatb":[[0,2.76,4.74],[1,2.74,21.81],[2,2.72,17.81],[3,2.7,20.83],[4,2.68,17.49],[5,2.66,35.36],[6,2.64,25.09],[7,2.62,62.67],[8,2.6,4.39],[9,2.58,13.57]],"bdatl":[[5,3,3.58],[6,3.05,26.29],[7,3.1,8.36],[8,3.15,1.43],[9,3.2,32.55]],"id":42930960},{"atb":[[4.1,27.4],[3.95,34.8],[1.01,37195.47],[4.3,22.96],[4,25.63],[4.5,0]],"atl":[[4.5,2],[5.1,9.76],[5,4],[4.6,5.01]],"trd":[[4.5,44]],"bdatb":[[3,4.1,29.22],[1,4.3,22.96],[4,4,28.89],[5,3.95,35.12],[0,4.4,4.15],[2,4.2,25.8],[6,3.9,4.7],[7,3.85,5.12],[8,3.8,7.3],[9,3.75,4.21]],"bdatl":[[0,4.6,5.01],[1,4.7,21.76],[2,4.8,11.49],[3,4.9,5.58],[4,5,4],[5,5.1,26.55],[6,5.3,4.21],[7,5.4,23.56],[8,5.5,29.19],[9,5.6,34.66]],"tv":114.04,"id":40095374},{"atb":[[2.5,1.8]],"trd":[[2.5,12]],"bdatb":[[3,2.44,130.46],[5,2.4,22.63],[6,2.38,19.94],[7,2.36,5.54],[8,2.32,13.57],[9,2.3,89.28]],"bdatl":[[7,2.7,3.97],[8,2.72,15.05],[9,2.74,1.89],[5,2.64,18.16],[2,2.58,4.08]],"tv":403.55,"id":36276560},{"atl":[[13.5,0]],"bdatb":[[2,5.2,19.46],[3,5.1,20.43],[4,5,24.26],[5,4.9,11.3],[6,4.8,8.08],[7,4.6,2.98],[8,4.5,14.46],[9,4.4,62.8]],"bdatl":[[6,6.8,1.12],[8,7.2,5.36],[9,7.4,24.87],[4,6.2,4.57],[5,6.4,4.61],[7,7,2.29]],"id":37947503},{"atb":[[17,18.6]],"bdatb":[[5,15,6.47],[8,13.5,2.34],[7,14,7.29],[9,13,4.11]],"bdatl":[[7,36,8.91],[8,60,2.41],[9,1000,21.76],[6,32,8.06]],"id":44331354},{"bdatb":[[1,1.24,58.28],[2,1.23,86.04],[3,1.22,178.86],[4,1.21,181.9],[5,1.2,230.83],[8,1.17,16.89],[9,1.16,246.21],[7,1.18,51.79],[6,1.19,152.41]],"bdatl":[[9,1.36,3.16],[8,1.35,24.2],[2,1.29,66.84],[3,1.3,16.12],[4,1.31,14.69],[5,1.32,22.05]],"id":39823721}],"con":true,"tv":3731.23}]}
{"op":"mcm","clk":"AOHFAQDNpgEAw6oB","pt":1650392826700,"mc":[{"id":"1.197931751","rc":[{"atb":[[2.58,24.35],[2.74,4.76],[2.5,10],[2.72,59.15]],"atl":[[2.9,60.28]],"bdatb":[[3,2.7,20.83],[4,2.68,19.17],[5,2.66,33.67],[7,2.62,61.53],[8,2.6,4.03],[9,2.58,25.87],[1,2.74,4.76],[2,2.72,59.15]],"bdatl":[[5,3,3.58],[6,3.05,26.29]],"id":42930960},{"atb":[[1.01,36745.89],[2.88,7.53],[4.1,21.39],[4.2,19.67]],"atl":[[1000,97.61]],"bdatb":[[8,3.8,9.48],[9,3.75,2.98],[2,4.2,19.67],[3,4.1,22.49],[4,4,29.05],[5,3.95,36.48],[6,3.9,2.06],[7,3.85,8.18]],"bdatl":[[6,5.1,12.33],[7,5.2,1.91],[8,5.4,24.83],[9,5.5,23.82],[0,4.5,2],[1,4.6,5.01],[2,4.7,21.76],[3,4.8,11.49],[4,4.9,5.58],[5,5,4]],"id":40095374},{"atb":[[2.46,43.57],[2.44,110.28],[2.42,23.27],[2.5,9.21],[2.48,23.23]],"atl":[[2.6,18.16],[2.54,0],[2.62,35.23],[2.92,2]],"bdatb":[[2,2.46,43.57],[3,2.44,112.13],[4,2.42,23.27],[0,2.5,9.21],[1,2.48,23.23],[5,2.4,22.62],[6,2.38,18.05],[7,2.36,6.38],[8,2.34,3],[9,2.32,9.69]],"bdatl":[[2,2.6,18.16],[0,2.56,5.58],[1,2.58,4.08],[3,2.62,35.23],[4,2.64,18.16],[5,2.66,15.81],[6,2.7,3.97],[7,2.72,15.05],[8,2.74,1.89],[9,2.78,44.37]],"id":36276560},{"atl":[[13.5,1.01]],"bdatb":[[8,4.5,18.18],[9,4.4,60.08],[2,5.2,19.46],[3,5.1,20.43],[5,4.9,9.78],[6,4.8,9.07],[7,4.6,1.58],[4,5,25.16]],"bdatl":[[5,6.4,4.61],[6,6.6,1.14],[7,7,1.12],[9,7.4,29.59],[8,7.2,1.13]],"id":37947503},{"atb":[[15.5,13.34],[16,6.49]],"bdatb":[[5,15,6.47],[7,14,7.93],[8,13.5,1.45],[9,13,4.03],[3,16,6.49],[4,15.5,13.34],[1,17,18.6]],"bdatl":[[8,60,2.52],[9,1000,21.56]],"id":44331354},{"bdatb":[[6,1.19,162.46],[7,1.18,57.83],[8,1.17,25.66],[9,1.16,220.9],[3,1.22,171.21],[4,1.21,185.9],[5,1.2,230.83],[1,1.24,61.92],[2,1.23,86.02]],"bdatl":[[3,1.3,16.95],[4,1.31,13.87],[7,1.34,148.95],[8,1.35,26.91],[9,1.36,51.49],[5,1.32,15.88],[6,1.33,9.51]],"id":39823721}],"con":true}]}
{"op":"mcm","clk":"APvGAQDXpwEAyasB","pt":1650392827701,"mc":[{"id":"1.197931751","rc":[{"atb":[[2.68,40.88],[2.74,18.66],[2.72,17.81],[2.76,7.29],[2.7,37.74],[2.78,2.7]],"atl":[[2.88,27.69],[3.15,9.3],[2.84,2],[2.82,0],[3.05,14.06],[2.86,12.71]],"bdatb":[[0,2.78,2.7],[3,2.72,60.8],[4,2.7,37.74],[1,2.76,7.29],[2,2.74,6.78],[5,2.68,37.53],[6,2.66,33.67],[7,2.64,27.49],[8,2.62,61.66],[9,2.6,2]],"bdatl":[[8,3.25,31.99],[0,2.84,2],[4,3.05,16.79],[9,3.3,1.16],[5,3.1,8.61],[6,3.15,9.76],[7,3.2,12.9],[1,2.86,12.71],[2,2.88,23.75],[3,2.9,60.28]],"id":42930960},{"atb":[[4.3,30.47],[4.5,1.85]],"atl":[[4.6,1],[4.8,7.24],[4.7,19.53],[1000,95.08],[4.5,0]],"trd":[[4.5,48]],"bdatb":[[0,4.5,1.85],[1,4.4,4.15],[2,4.3,24.01],[3,4.2,19.95],[9,3.8,5.76],[4,4.1,22.9],[5,4,31.24],[6,3.95,36.23],[7,3.9,2.54],[8,3.85,5.12]],"bdatl":[[0,4.6,5.01],[1,4.7,21.76],[2,4.8,11.49],[3,4.9,5.58],[4,5,4],[5,5.1,9.76],[6,5.2,1.44],[7,5.3,3.32],[8,5.4,23.19],[9,5.5,24.21]],"tv":118.04,"id":40095374},{"atb":[[2.44,132.67],[2.32,0],[1.01,23110.5],[2.46,10.21],[2.42,27.71],[2.48,0],[2.5,0]],"atl":[[2.6,24.33],[2.5,4.25],[2.48,13.38],[2.9,43],[2.52,8.9],[2.8,2],[2.62,31.31],[2.54,4.27]],"trd":[[2.5,21.86]],"bdatb":[[3,2.4,22.63],[4,2.38,14.18],[5,2.36,3.99],[6,2.34,5.35],[7,2.32,8.38],[8,2.3,84.62],[9,2.28,6.84],[0,2.46,10.21],[1,2.44,137.08],[2,2.42,27.71]],"bdatl":[[0,2.48,4.79],[1,2.52,8.9],[2,2.54,4.27],[3,2.56,5.58],[4,2.58,4.08],[5,2.6,21.24],[6,2.62,31.31],[7,2.64,21],[8,2.66,16.12],[9,2.72,20.9]],"tv":413.41,"id":36276560},{"atl":[[13.5,1.06]],"bdatb":[[1,5.3,15.02],[2,5.2,19.46],[3,5.1,19.78],[4,5,25.5],[5,4.9,12.05],[6,4.8,8.12],[7,4.7,1.2],[8,4.6,1.14],[9,4.5,14.81]],"bdatl":[[5,6.4,4.1],[6,6.8,2.59],[7,7.4,24.58],[8,7.6,1.57],[9,7.8,9.16]],"id":37947503},{"bdatb":[[1,1.24,62.86],[2,1.23,87.41],[3,1.22,172.82],[4,1.21,194.21],[5,1.2,220.15],[6,1.19,158.98],[7,1.18,51.86],[8,1.17,8.35],[9,1.16,246.21]],"bdatl":[[3,1.3,13.29],[4,1.31,11.76],[5,1.32,21.93],[6,1.33,5.78],[9,1.36,8.42],[7,1.34,121.06],[8,1.35,55.61]],"id":39823721},{"bdatb":[[4,15.5,13.71],[5,15,6.47],[6,14.5,6.62],[8,13.5,1.92],[9,13,4],[7,14,7.29]],"bdatl":[[8,60,2.53],[9,1000,21.14]],"id":44331354}],"con":true,"tv":3745.09}]}
{"op":"mcm","clk":"AKnIAQDfqAEA2KwB","pt":1650392828702,"mc":[{"id":"1.197931751","rc":[{"atb":[[2.86,0],[2.74,7.01],[2.84,2.39],[2.7,51.31],[2.82,4.47],[2.56,5.5],[2.8,4.6],[2.2,15.15],[2.72,17.36],[2.62,41.89],[2.78,5.04],[2.58,121.35],[2.46,0],[2.16,0],[2.68,34.78]],"atl":[[2.9,17.18],[2.88,12.43],[2.86,0],[1000,135.15],[2.84,0],[3.1,43.2]],"trd":[[2.86,8.74],[2.84,8.96]],"bdatb":[[0,2.84,2.39],[1,2.82,4.47],[2,2.8,4.6],[3,2.78,5.04],[4,2.76,7.29],[5,2.74,7.01],[6,2.72,19.01],[7,2.7,51.31],[8,2.68,34.81],[9,2.66,36.41]],"bdatl":[[0,2.88,12.43],[1,2.9,17.18],[2,3.05,16.79],[3,3.1,48.61],[4,3.15,9.76],[5,3.2,11.49],[6,3.25,10.28],[7,3.3,17.73],[8,3.35,7.87],[9,3.4,1.13]],"ltp":2.86,"tv":813.6,"id":42930960},{"atb":[[2.9,7.28],[2.88,0],[3.65,0],[3.75,69],[4.2,24.33],[4.1,33.21]],"atl":[[4.8,11.26],[4.9,9.63],[5.5,0],[5.6,54.61],[5.1,24]],"bdatb":[[8,3.85,15.31],[4,4.1,35.01],[5,4,32.64],[6,3.95,35.02],[7,3.9,2.64],[9,3.8,2],[2,4.3,30.47],[3,4.2,25.4]],"bdatl":[[3,4.9,9.63],[5,5.1,26.47],[6,5.2,1.1],[7,5.3,1.35],[8,5.4,23.1],[9,5.6,56.77],[4,5,5.36],[2,4.8,11.26],[1,4.7,19.53],[0,4.6,1]],"id":40095374},{"atb":[[2.38,35.23],[2.44,2.09],[2.26,111],[2.4,0],[2.22,6.29]],"atl":[[2.68,47],[2.52,16.92],[2.9,0],[2.6,9.21],[2.5,12.55],[2.54,14.81],[2.56,14.73],[2.48,4.79],[2.72,18.37]],"bdatb":[[5,2.3,90.52],[6,2.28,8.11],[7,2.26,131.2],[9,2.22,6.3],[3,2.38,35.23],[4,2.36,5.4],[1,2.44,2.09],[8,2.24,51.58]],"bdatl":[[5,2.58,4.08],[6,2.6,11.82],[7,2.62,31.9],[8,2.64,19.07],[9,2.66,19.07],[2,2.52,16.92],[1,2.5,12.55],[3,2.54,14.81],[4,2.56,14.73],[0,2.48,4.79]],"id":36276560},{"atb":[[5.2,19.46]],"bdatb":[[6,4.8,10.75],[7,4.7,1.59],[8,4.6,9.2],[9,4.5,9.3],[2,5.2,19.46],[3,5.1,20.43],[1,5.3,14.16],[4,5,24.28],[5,4.9,11.26]],"bdatl":[[3,6,5.01],[4,6.2,5.91],[5,6.4,3.31],[6,6.6,2.18],[7,7.2,1.29],[8,7.4,24.94],[9,7.6,2.65]],"id":37947503},{"atb":[[1.17,214],[1.16,4.28]],"atl":[[1.35,93],[1.34,24.7]],"bdatb":[[5,1.2,256.47],[8,1.17,223.21],[9,1.16,31.97],[4,1.21,198.22],[6,1.19,135.49],[7,1.18,5.05],[1,1.24,61.92],[2,1.23,82.44],[3,1.22,174.82]],"bdatl":[[1,1.28,156.99],[2,1.29,73.29],[3,1.3,15.4],[4,1.31,15.4],[6,1.33,3.05],[7,1.34,33.67],[8,1.35,122.13],[9,1.36,8.57],[5,1.32,12.68]],"id":39823721},{"atl":[[42,3],[36,5.91]],"bdatb":[[6,14.5,6.19],[7,14,7.61],[9,13,3.63],[4,15.5,13.34],[8,13.5,1.99]],"bdatl":[[5,29,5.36],[6,32,8.34],[7,36,5.91],[8,42,3.43],[9,60,2.03]],"id":44331354}],"con":true,"tv":3762.79}]}
{"op":"mcm","clk":"ANPJAQDxqQEA160B","pt":1650392829704,"mc":[{"id":"1.197931751","rc":[{"atb":[[2.72,12.67],[2.86,2.38],[2.74,37.27],[2.82,9.14],[2.84,13.4],[2.22,5.59],[2.32,107.78],[2.8,22.95],[2.64,7.38],[2.52,0],[2.76,9.29],[2.7,48.13],[2.58,119.35],[1.01,29810.18]],"atl":[[2.92,2.33],[3.9,17.46],[4.4,38.79],[2.9,14.88],[2.88,0]],"bdatb":[[7,2.72,14.33],[0,2.86,2.38],[1,2.84,13.4],[2,2.82,9.14],[3,2.8,22.95],[4,2.78,5.04],[5,2.76,9.29],[6,2.74,37.27],[8,2.7,48.13],[9,2.68,34.81]],"bdatl":[[2,3,2.78],[3,3.05,15.34],[4,3.1,47.36],[5,3.15,9.76],[6,3.2,12.89],[7,3.25,9.58],[8,3.3,20.32],[9,3.35,4.64],[1,2.92,2.33],[0,2.9,14.88]],"id":42930960},{"atb":[[4.1,21.39]],"atl":[[5.2,9.52],[5.1,14.24]],"bdatb":[[8,3.85,4.34],[9,3.8,3.76],[4,4.1,23.19],[7,3.9,2.61]],"bdatl":[[3,4.9,11.82],[4,5,6.88],[5,5.1,16.03],[6,5.2,10.38],[7,5.4,23.88],[8,5.5,11.48],[9,5.6,54.61]],"id":40095374},{"atb":[[2.38,14.18],[2.36,24.85],[1.72,0],[1.66,151.52],[2.44,6.5]],"atl":[[2.78,31.15],[2.66,0],[2.64,0],[2.82,2],[2.52,35.41],[2.56,5.58]],"bdatb":[[8,2.24,54.62],[3,2.38,14.18],[4,2.36,26.77],[5,2.3,82.87],[6,2.28,15.82],[7,2.26,112.42],[1,2.44,6.5],[9,2.22,6.29]],"bdatl":[[4,2.56,8.24],[5,2.58,4.67],[6,2.6,10.14],[7,2.62,31.88],[8,2.64,5.44],[9,2.68,49.87],[2,2.52,35.41]],"id":36276560},{"atb":[[5.6,2],[5.5,2.22],[5.4,4.91]],"atl":[[13.5,1.01],[5.9,9.63]],"bdatb":[[0,5.5,2.22],[1,5.4,4.91],[2,5.3,14.16],[3,5.2,19.46],[4,5.1,20.43],[5,5,24.26],[6,4.9,9.79],[7,4.8,7.29],[8,4.7,6.65],[9,4.6,1.48]],"bdatl":[[2,5.9,9.63],[3,6,6.15],[4,6.2,4.81],[7,7,1.51],[8,7.2,3.58],[9,7.4,28.37],[5,6.4,5.55],[6,6.8,1.35]],"id":37947503},{"bdatb":[[9,1.16,8.39],[5,1.2,221.18],[6,1.19,141.12],[7,1.18,5.05],[8,1.17,250.66],[1,1.24,58.28],[2,1.23,86.04],[3,1.22,169.71],[4,1.21,203.44]],"bdatl":[[1,1.28,163.49],[2,1.29,69.85],[3,1.3,17.94],[4,1.31,15.79],[5,1.32,15],[7,1.34,52.6],[8,1.35,97.28],[9,1.36,20.58],[6,1.33,22.3]],"id":39823721},{"bdatb":[[7,14,7.29],[8,13.5,1.79],[9,13,4.19]],"bdatl":[[3,26,3.1],[4,27,3.91],[5,29,5.36],[6,32,8.18],[7,36,6.26],[8,42,3.04],[9,60,2.28]],"id":44331354}],"con":true}]}
{"op":"mcm","clk":"AO3KAQCAqwEA964B","pt":1650392830705,"mc":[{"id":"1.197931751","rc":[{"atb":[[2.82,55.79],[2.8,20.35],[2.7,35.03]],"atl":[[3.05,36.73]],"bdatb":[[3,2.8,20.35],[8,2.7,35.03],[2,2.82,20.44]],"bdatl":[[3,3.05,41.69],[2,2.96,2.81],[4,3.1,43.75],[6,3.2,13.59],[7,3.25,11.64],[8,3.3,17.61],[9,3.35,5.8]],"id":42930960},{"atl":[[2.66,4.19],[2.84,17.54],[2.52,39.45]],"bdatl":[[9,2.66,4.19],[2,2.52,39.45],[3,2.54,17.49],[4,2.56,6.17],[5,2.58,5.01],[6,2.6,9.39],[7,2.62,35.97],[8,2.64,1.2]],"id":36276560},{"atl":[[1000,76.72]],"bdatb":[[0,5.6,2],[1,5.5,2.22],[2,5.4,4.91],[3,5.3,14.16],[4,5.2,19.46],[5,5.1,20.43],[6,5,24.26],[7,4.9,9.79],[8,4.8,7.29],[9,4.7,6.65]],"bdatl":[[8,7.2,8.01],[9,7.4,24.06]],"id":37947503},{"atl":[[1.3,16.81],[1.34,14.78]],"bdatb":[[8,1.17,253.68],[9,1.16,31.27]],"bdatl":[[6,1.33,43.35],[7,1.34,18.89],[9,1.36,23.97],[3,1.3,19.25],[0,1.27,72.75],[1,1.28,160.05],[2,1.29,76.67],[5,1.32,17.95],[8,1.35,105.57]],"id":39823721},{"bdatl":[[2,4.8,13.49],[3,4.9,9.72],[4,5,6.78],[6,5.2,10.81],[7,5.4,24.4],[8,5.5,10.56]],"id":40095374},{"bdatl":[[2,24,6.16],[3,26,2.9],[4,27,3.85],[5,29,5.46],[6,32,8.44],[7,36,5.95],[9,60,2.35]],"id":44331354}],"con":true}]}
{"op":"mcm","clk":"AJ7MAQCJrAEAirAB","pt":1650392831706,"mc":[{"id":"1.197931751","rc":[{"atb":[[2.66,16.17],[2.82,63.79],[2.8,2]],"atl":[[2.9,11.16]],"bdatb":[[2,2.82,63.79],[3,2.8,2]],"bdatl":[[3,3.05,42.25],[4,3.1,43.67],[5,3.15,11.74],[6,3.2,20.76],[7,3.25,17.05],[8,3.3,3],[0,2.9,11.16]],"id":42930960},{"atb":[[5.5,17.95]],"bdatb":[[1,5.5,10.98],[9,4.7,5.81]],"bdatl":[[8,7.2,8.77],[9,7.4,23.32]],"id":37947503},{"bdatb":[[5,4,30.75],[6,3.95,36.53],[7,3.9,2],[8,3.85,4.31],[9,3.8,2]],"bdatl":[[4,5,8.61],[5,5.1,15.56],[6,5.2,10.27],[7,5.3,5.05],[8,5.4,27.64],[9,5.5,1.8]],"id":40095374},{"bdatb":[[6,2.28,12.5],[7,2.26,114.01],[8,2.24,51.58]],"bdatl":[[7,2.62,37.18],[8,2.66,7.08],[9,2.68,50.95]],"id":36276560},{"bdatb":[[4,1.21,197.19],[5,1.2,224.08],[6,1.19,135.49],[7,1.18,8.51],[8,1.17,259.4]],"bdatl":[[2,1.29,77.99],[3,1.3,17.93],[4,1.31,20.91],[5,1.32,33.13],[6,1.33,27.38],[8,1.35,129.72],[9,1.36,11.47],[7,1.34,14.78]],"id":39823721},{"bdatl":[[6,32,8.49],[8,42,3],[9,60,2.86]],"id":44331354}],"con":true}]}
{"op":"mcm","clk":"ANDNAQCXrQEAnrEB","pt":1650392832723,"mc":[{"id":"1.197931751","rc":[{"atb":[[2.78,13.67],[2.7,38.21],[2.62,32.73]],"atl":[[3,13.42],[2.9,17.87],[3.1,46.43]],"bdatb":[[4,2.78,13.67],[8,2.7,38.21]],"bdatl":[[4,3.1,46.9],[6,3.2,32.14],[7,3.25,8.89],[8,3.3,2.93],[9,3.35,2.92]],"id":42930960},{"atb":[[2.46,0]],"atl":[[2.78,17.11],[2.58,18.26]],"trd":[[2.46,20.42]],"ltp":2.46,"tv":433.83,"id":36276560},{"atb":[[5.4,12.49],[4.8,2.18],[4.9,2.33],[5.2,13.24]],"bdatb":[[2,5.4,12.49],[8,4.8,3.7],[7,4.9,2.35],[4,5.2,13.24],[1,5.5,17.95]],"id":37947503},{"atb":[[1.23,90.51]],"atl":[[1.27,9.45]],"trd":[[1.27,348.92]],"bdatl":[[0,1.27,50.75],[7,1.34,38.56],[8,1.35,104.72],[5,1.32,60.72],[6,1.33,1.42],[9,1.36,31.5]],"tv":2325.59,"id":39823721},{"bdatl":[[7,5.3,11.92],[8,5.4,22.73],[9,5.6,56.34]],"id":40095374},{"bdatl":[[9,60,3.46]],"id":44331354}],"con":true,"tv":3827.21}]}
{"op":"mcm","clk":"AI/PAQDCrgEAzLIB","pt":1650392833728,"mc":[{"id":"1.197931751","rc":[{"atl":[[3.1,43.2]],"bdatb":[[9,2.68,35.48],[5,2.76,10.92],[7,2.72,12.67],[8,2.7,38.24]],"bdatl":[[2,2.96,1.28],[3,3,13.42],[4,3.05,38.22],[5,3.1,44.12],[6,3.15,14.18],[7,3.2,12.63],[8,3.25,15.16],[9,3.3,15.64],[0,2.9,17.87]],"id":42930960},{"atb":[[2.16,6.29],[2.4,8.49],[2.44,0],[2.28,0],[2.42,15.67],[1.01,22872.83]],"atl":[[2.52,39.45],[2.5,38.58],[2.56,17.76],[2.48,13.89],[2.58,14.18],[2.46,2.64],[2.96,6.69],[2.78,19.11]],"bdatb":[[1,2.4,8.49],[2,2.38,14.18],[3,2.36,26.77],[4,2.3,80.18],[5,2.26,113.74],[6,2.24,61.65],[7,2.22,11.27],[8,2.2,3.09],[9,2.16,23.77],[0,2.42,15.67]],"bdatl":[[2,2.5,40.09],[3,2.52,39.45],[4,2.54,16],[5,2.56,18.35],[0,2.46,2.64],[1,2.48,13.89],[6,2.58,15.11],[7,2.6,9.39],[8,2.62,37.18],[9,2.66,7.08]],"id":36276560},{"atb":[[5.3,11.04],[5.4,16.6]],"bdatb":[[9,4.7,5.94],[7,4.9,2.72],[8,4.8,3.33],[2,5.4,16.6],[3,5.3,11.04],[6,5,24.28]],"bdatl":[[3,6,5.64],[5,6.4,3.64],[8,7.4,26.1],[9,7.6,4.44],[4,6.2,4.57],[6,6.6,2.77],[7,7,1.62]],"id":37947503},{"atb":[[1.26,3],[1.25,91.15]],"bdatb":[[0,1.26,3],[1,1.25,91.15],[2,1.24,61.92],[3,1.23,90.58],[4,1.22,174.82],[5,1.21,199.05],[6,1.2,233.15],[7,1.19,135.49],[8,1.18,38.08],[9,1.17,215.1]],"bdatl":[[5,1.32,17.95],[6,1.33,35.48],[7,1.34,28.11],[8,1.35,123.22],[9,1.37,5.03],[1,1.28,162.3],[2,1.29,68.02],[3,1.3,30.85],[0,1.27,9.45],[4,1.31,15.79]],"id":39823721},{"bdatb":[[7,3.9,2.21],[5,4,27.18],[6,3.95,40.3],[8,3.85,4.36],[9,3.8,4.86],[4,4.1,23.22]],"bdatl":[[2,4.8,12.05],[3,4.9,10.25],[7,5.3,1.31],[8,5.4,25.22],[9,5.5,6.14],[4,5,4.88],[6,5.2,10.22],[5,5.1,18.76]],"id":40095374},{"bdatb":[[8,13.5,1.59],[9,13,4.05],[6,14.5,6.51]],"bdatl":[[2,24,6.03],[5,29,5.47],[9,60,2.35],[3,26,2.84],[4,27,3.85],[6,32,8.11],[7,36,5.99],[8,42,3.38]],"id":44331354}],"con":true}]}
{"op":"mcm","clk":"AK7QAQC6rwEA37MB","pt":1650392834729,"mc":[{"id":"1.197931751","rc":[{"atb":[[2.78,19.96],[2.8,21.76],[2.82,28.44],[2.86,0],[2.7,35.03],[2.84,2.39],[2.62,23.57]],"atl":[[2.94,4.9]],"bdatb":[[0,2.84,2.39],[1,2.82,63.79],[2,2.8,2],[3,2.78,22.3],[4,2.76,9.29],[5,2.74,37.27],[6,2.72,12.67],[7,2.7,36.7],[8,2.68,34.78],[9,2.66,16.21]],"bdatl":[[6,3.2,11.5],[7,3.25,11.44],[8,3.3,19.22],[9,3.35,12.47],[2,3,13.42],[3,3.05,41.9],[4,3.1,43.2],[5,3.15,10.09]],"id":42930960},{"atb":[[4,25.63],[1.01,36313.54],[4.5,0]],"atl":[[5.1,0],[4.9,7.58],[4.8,9.24]],"bdatb":[[4,4,35.93],[5,3.95,40.4],[6,3.9,4.9],[7,3.85,4.57],[0,4.4,4.15],[1,4.3,30.47],[2,4.2,24.33],[3,4.1,22.49],[8,3.8,4.86],[9,3.75,70.81]],"bdatl":[[2,4.8,10.65],[3,4.9,8.48],[6,5.2,9.55],[7,5.3,1.9],[8,5.4,24.26],[9,5.5,4.63],[5,5.1,14.24],[4,5,4.92]],"id":40095374},{"atb":[[2.34,9.4],[2.42,6.58],[2.36,39.54],[2.4,4.19]],"atl":[[2.54,12.8],[2.56,5.58]],"bdatb":[[6,2.26,111.68],[7,2.24,66.71],[8,2.22,11.65],[0,2.42,6.58],[3,2.36,39.54],[1,2.4,4.19],[4,2.32,1.94],[5,2.3,76.92],[9,2.2,3.09]],"bdatl":[[4,2.54,15.47],[5,2.56,7.12],[6,2.58,14.36],[7,2.6,10.97],[8,2.62,31.31],[9,2.66,5.13],[2,2.5,38.58],[3,2.52,39.45]],"id":36276560},{"atb":[[5.5,15.73]],"atl":[[5.9,7.63],[6,7.01],[5.8,2.06],[5.7,1.06],[13.5,0]],"trd":[[5.7,8.06]],"bdatb":[[1,5.5,15.73],[5,5.1,19.55],[6,5,25.16],[7,4.9,2.33],[8,4.8,2.2],[9,4.7,7.52]],"bdatl":[[0,5.7,1.06],[4,6.2,4.57],[5,6.4,4.61],[6,7,1.11],[7,7.2,1.07],[8,7.4,24.44],[9,7.6,3.35],[3,6,5.01]],"tv":81.57,"id":37947503},{"atb":[[1.22,163.67],[1.26,12.52]],"atl":[[1.34,25.83],[1.3,6.89],[1.27,0]],"bdatb":[[4,1.22,165.22],[5,1.21,208.73],[8,1.18,37.04],[9,1.17,216.15],[0,1.26,12.52]],"bdatl":[[1,1.29,66.84],[2,1.3,15.51],[3,1.31,15.3],[4,1.32,15.77],[5,1.33,25.38],[6,1.34,54.17],[7,1.35,131.2],[8,1.36,2.77],[9,1.38,24.88],[0,1.28,156.99]],"id":39823721},{"bdatb":[[6,14.5,6.19],[8,13.5,1.45],[9,13,3.98]],"bdatl":[[4,27,3.85],[5,29,5.59],[6,32,8.2],[7,36,6.04],[9,60,2.04],[8,42,3],[2,24,5.87],[3,26,2.84]],"id":44331354}],"con":true,"tv":3831.48}]}
{"op":"mcm","clk":"AOHRAQDDsAEA7LQB","pt":1650392835730,"mc":[{"id":"1.197931751","rc":[{"atl":[[3.1,43.2]],"bdatb":[[6,2.72,14.33],[9,2.66,16.21],[7,2.7,35.03],[1,2.82,28.44],[2,2.8,21.76],[3,2.78,19.96]],"bdatl":[[4,3.05,36.73],[5,3.1,45.24],[6,3.15,13.09],[9,3.3,21.49],[7,3.2,9.22],[8,3.25,13.69],[2,2.94,4.9],[3,3,13.42]],"id":42930960},{"atb":[[2.4,0],[2.38,22.75],[1.01,22397.5],[2.36,32.29],[2.42,0],[2.34,31.08]],"atl":[[2.44,3.99],[2.94,0],[2.42,14.36],[2.74,2],[2.92,0],[2.56,0.89],[2.52,14.55]],"trd":[[2.4,8.38],[2.42,13.16]],"bdatb":[[0,2.38,22.75],[1,2.36,32.29],[2,2.34,31.08],[3,2.3,76.92],[4,2.28,1.98],[5,2.26,111.04],[6,2.24,58.38],[7,2.22,15.35],[8,2.2,6.46],[9,2.16,15.04]],"bdatl":[[1,2.44,3.99],[2,2.46,2.64],[3,2.48,13.89],[4,2.5,38.58],[5,2.52,14.55],[6,2.54,15.29],[7,2.58,15.25],[8,2.6,10.73],[9,2.62,34.18],[0,2.42,14.36]],"ltp":2.4,"tv":455.37,"id":36276560},{"atb":[[5.4,19.03],[5.3,9.76],[5.6,3.33]],"atl":[[5.9,3.36],[6,5.72],[1000,75.21],[7.2,0.71],[5.7,0],[6.2,6.57],[5.8,0]],"bdatb":[[8,4.8,4.21],[2,5.4,19.03],[3,5.3,9.76],[7,4.9,8.48],[9,4.7,1.38],[0,5.6,3.33],[4,5.2,14.11],[6,5,24.28]],"bdatl":[[7,7.6,2.62],[8,7.8,4.21],[0,5.9,3.36],[1,6,5.72],[4,7,1.59],[5,7.2,1.75],[9,8,12.67],[3,6.4,2.93],[6,7.4,25.48],[2,6.2,6.57]],"id":37947503},{"atb":[[1.26,5.02]],"trd":[[1.26,487.72]],"bdatb":[[5,1.21,193.67],[6,1.2,221.06],[8,1.18,15.54],[9,1.17,222.07],[7,1.19,151.37],[0,1.26,5.02],[4,1.22,188.37],[2,1.24,61.92],[3,1.23,90.58]],"bdatl":[[2,1.3,6.89],[3,1.31,23.85],[5,1.33,26.68],[6,1.34,50.34],[7,1.35,125.12],[8,1.36,13.91],[9,1.37,39.28],[4,1.32,10.23]],"ltp":1.26,"tv":2340.59,"id":39823721},{"bdatb":[[5,3.95,36.12],[6,3.9,3.17],[7,3.85,6],[8,3.8,2.84],[9,3.75,69],[4,4,33.19],[3,4.1,22.49]],"bdatl":[[3,4.9,7.58],[4,5,5.27],[8,5.5,3.62],[9,5.6,60.48],[5,5.2,10.37],[6,5.3,1.5],[7,5.4,25.62],[2,4.8,9.24]],"id":40095374},{"bdatb":[[8,13.5,1.79],[9,13,3.63]],"bdatl":[[6,32,8.06],[7,36,6.08],[8,42,3],[9,60,2.22],[5,29,5.36]],"id":44331354}],"con":true,"tv":3868.02}]}
{"op":"mcm","clk":"AIvTAQDHsQEA+7UB","pt":1650392836732,"mc":[{"id":"1.197931751","rc":[{"atb":[[1.01,29551.69],[2.72,2.81],[2.8,29.26]],"atl":[[2.98,10.28],[2.88,4.17],[2.86,7.69],[2.94,8.41]],"bdatb":[[2,2.8,29.26],[6,2.72,4.47]],"bdatl":[[5,2.98,10.28],[6,3,13.42],[7,3.05,36.73],[8,3.1,45.24],[9,3.15,13.09],[1,2.88,4.17],[2,2.9,17.87],[3,2.92,2.33],[4,2.94,8.41],[0,2.86,7.69]],"id":42930960},{"atb":[[2.36,31.8],[2.34,16.07],[2.3,99.26],[2.38,20.51]],"atl":[[2.6,13.4],[2.78,14.92],[2.54,8.53]],"bdatb":[[1,2.36,31.8],[9,2.18,5.69],[3,2.32,1.94],[4,2.3,99.26],[5,2.26,117.78],[6,2.24,52.55],[7,2.22,14.37],[2,2.34,16.07],[0,2.38,20.51]],"bdatl":[[8,2.6,14.92],[6,2.54,11.02]],"id":36276560},{"atl":[[7.4,30.31],[6.4,5.34],[6.2,2]],"bdatb":[[3,5.3,10.61],[4,5.2,13.24],[5,5.1,19.57],[6,5,27.74],[7,4.9,4.93]],"bdatl":[[3,6.4,5.34],[6,7.4,32.47],[2,6.2,2],[7,7.6,1.91],[8,7.8,4.89]],"id":37947503},{"atb":[[1.23,107.08],[1.21,165.38]],"bdatb":[[7,1.19,161.77],[8,1.18,11.17],[9,1.17,220.89],[3,1.23,121.23],[5,1.21,178.79],[1,1.25,94.75],[2,1.24,58.35],[4,1.22,174.11]],"bdatl":[[7,1.35,120.31],[8,1.36,18.68],[9,1.37,8.9],[5,1.33,22.67],[6,1.34,54.32]],"id":39823721},{"bdatb":[[9,3.75,72.31],[2,4.2,25.4],[3,4.1,25.66],[4,4,28.82]],"bdatl":[[8,5.5,2.65],[9,5.6,61.43]],"id":40095374},{"bdatb":[[7,14,7.61],[8,13.5,2.58],[9,13,3.79]],"id":44331354}],"con":true}]}
{"op":"mcm","clk":"ALnUAQDusgEAkLcB","pt":1650392837733,"mc":[{"id":"1.197931751","rc":[{"atb":[[2.7,38.21],[2.74,20.58],[2.72,19.7]],"atl":[[2.94,4.9]],"bdatb":[[7,2.7,38.21],[5,2.74,20.58],[6,2.72,21.36]],"bdatl":[[4,2.94,4.9]],"id":42930960},{"atb":[[2.34,25.4],[2.32,22.01]],"bdatb":[[2,2.34,25.4],[3,2.32,23.96]],"id":36276560},{"bdatl":[[9,1.37,24.84]],"id":39823721}],"con":true}]}
{"op":"mcm","clk":"AM/VAQCPtAEAsLgB","pt":1650392838735,"mc":[{"id":"1.197931751","marketDefinition":{"bspMarket":true,"turnInPlayEnabled":false,"persistenceEnabled":false,"marketBaseRate":5,"eventId":"31389771","eventTypeId":"4339","numberOfWinners":2,"bettingType":"ODDS","marketType":"PLACE","marketTime":"2022-04-19T18:26:00.000Z","suspendTime":"2022-04-19T18:26:00.000Z","bspReconciled":true,"complete":true,"inPlay":false,"crossMatching":true,"runnersVoidable":false,"numberOfActiveRunners":6,"betDelay":0,"status":"SUSPENDED","runners":[{"status":"ACTIVE","sortPriority":1,"bsp":21,"id":44331354},{"status":"ACTIVE","sortPriority":2,"bsp":5.6,"id":37947503},{"status":"ACTIVE","sortPriority":3,"bsp":2.42,"id":36276560},{"status":"ACTIVE","sortPriority":4,"bsp":2.860593788,"id":42930960},{"status":"ACTIVE","sortPriority":5,"bsp":4.644813692,"id":40095374},{"status":"ACTIVE","sortPriority":6,"bsp":1.282193845135735,"id":39823721}],"regulators":["MR_INT"],"venue":"Sheffield","countryCode":"GB","discountAllowed":true,"timezone":"Europe/London","openDate":"2022-04-19T17:19:00.000Z","version":4497298501,"priceLadderDefinition":{"type":"CLASSIC"}},"rc":[{"atb":[[2.36,0],[2.56,0],[2.76,0],[1.08,0],[2.62,0],[2.84,0],[1.14,0],[1.23,0],[1.85,0],[2.22,0],[2.3,0],[2.32,0],[1.01,0],[2.54,0],[2.72,0],[2.8,0],[2.82,0],[2.7,0],[2.68,0],[2.78,0],[2.66,0],[2.28,0],[1.02,0],[2.74,0],[2.24,0],[1.95,0],[2.58,0],[2.6,0],[2.64,0],[2.5,0],[2.2,0]],"atl":[[4.7,0],[3.9,0],[3.15,0],[2.9,0],[3.2,0],[2.88,0],[5.1,0],[2.92,0],[1000,0],[3.05,0],[2.94,0],[4.4,0],[3.25,0],[2.98,0],[4.9,0],[3,0],[3.35,0],[5.3,0],[3.1,0],[2.86,0]],"trd":[[2.86,24.13],[2.88,0.48]],"bdatb":[[0,0,0],[1,0,0],[2,0,0],[3,0,0],[4,0,0],[5,0,0],[6,0,0],[7,0,0],[8,0,0],[9,0,0]],"bdatl":[[0,0,0],[1,0,0],[2,0,0],[3,0,0],[4,0,0],[5,0,0],[6,0,0],[7,0,0],[8,0,0],[9,0,0]],"ltp":2.88,"tv":829.47,"id":42930960},{"atb":[[3.9,0],[4.1,0],[1.79,0],[3.05,0],[1.08,0],[3.3,0],[2.26,0],[2.84,0],[1.23,0],[2.12,0],[3.8,0],[1.01,0],[4.3,0],[2.16,0],[4.2,0],[2.96,0],[2.2,0],[1.02,0],[3.7,0],[3.95,0],[3.45,0],[2.24,0],[4,0],[2.08,0],[3.75,0],[3.5,0],[4.4,0],[2.64,0],[3.1,0],[3.85,0],[2.9,0]],"atl":[[1000,0],[5.4,0],[4.7,0],[5.2,0],[4.9,0],[7.6,0],[5.8,0],[5,0],[6.4,0],[5.6,0],[4.8,0],[4.6,0]],"trd":[[4.7,13.38],[4.6,8.18]],"bdatb":[[0,0,0],[1,0,0],[2,0,0],[3,0,0],[4,0,0],[5,0,0],[6,0,0],[7,0,0],[8,0,0],[9,0,0]],"bdatl":[[0,0,0],[1,0,0],[2,0,0],[3,0,0],[4,0,0],[5,0,0],[6,0,0],[7,0,0],[8,0,0],[9,0,0]],"ltp":4.7,"tv":121.66,"id":40095374},{"atb":[[1.17,0],[2.16,0],[1.66,0],[1.02,0],[2.38,0],[1.92,0],[2.24,0],[2.36,0],[2.34,0],[1.08,0],[1.71,0],[1.48,0],[1.94,0],[2.26,0],[1.96,0],[1.23,0],[1.84,0],[2.22,0],[1.98,0],[2.3,0],[2.32,0],[1.01,0],[2,0]],"atl":[[3.9,0],[4.1,0],[2.42,0],[2.86,0],[2.56,0],[2.48,0],[2.62,0],[3.55,0],[2.84,0],[3.8,0],[2.54,0],[2.72,0],[2.82,0],[2.8,0],[2.68,0],[2.96,0],[2.78,0],[2.66,0],[2.46,0],[3.7,0],[2.52,0],[2.74,0],[3.2,0],[2.88,0],[2.58,0],[2.6,0],[2.44,0],[2.5,0],[1000,0]],"trd":[[2.42,39.59]],"bdatb":[[0,0,0],[1,0,0],[2,0,0],[3,0,0],[4,0,0],[5,0,0],[6,0,0],[7,0,0],[8,0,0],[9,0,0]],"bdatl":[[0,0,0],[1,0,0],[2,0,0],[3,0,0],[4,0,0],[5,0,0],[6,0,0],[7,0,0],[8,0,0],[9,0,0]],"ltp":2.42,"tv":481.8,"id":36276560},{"atb":[[3.9,0],[4.1,0],[5.1,0],[5.6,0],[1.08,0],[3.3,0],[2.84,0],[1.23,0],[5.3,0],[1.01,0],[4.8,0],[4.2,0],[5.2,0],[1.02,0],[5.5,0],[3.95,0],[5,0],[4.5,0],[2.24,0],[5.4,0],[3.75,0],[4.4,0],[4.9,0],[3,0],[3.1,0],[3.85,0]],"atl":[[9.8,0],[6,0],[6.2,0],[7.2,0],[1000,0],[9.4,0],[8.4,0],[5.9,0],[11.5,0],[7.4,0],[8.2,0],[10.5,0],[6.4,0],[8,0]],"trd":[[5.6,3.61]],"bdatb":[[0,0,0],[1,0,0],[2,0,0],[3,0,0],[4,0,0],[5,0,0],[6,0,0],[7,0,0],[8,0,0],[9,0,0]],"bdatl":[[0,0,0],[1,0,0],[2,0,0],[3,0,0],[4,0,0],[5,0,0],[6,0,0],[7,0,0],[8,0,0],[9,0,0]],"ltp":5.6,"tv":81.67,"id":37947503},{"atb":[[1.17,0],[1.24,0],[1.05,0],[1.07,0],[1.22,0],[1.16,0],[1.25,0],[1.08,0],[1.1,0],[1.09,0],[1.14,0],[1.23,0],[1.19,0],[1.26,0],[1.21,0],[1.03,0],[1.01,0],[1.18,0],[1.2,0]],"atl":[[1.52,0],[1.31,0],[1.29,0],[1.32,0],[1.3,0],[1.5,0],[1.74,0],[1.54,0],[2.36,0],[1.56,0],[1000,0],[1.35,0],[1.34,0],[1.53,0],[2.98,0],[46,0],[1.58,0],[1.28,0]],"trd":[[1.29,98.85],[1.28,436.28]],"bdatb":[[0,0,0],[1,0,0],[2,0,0],[3,0,0],[4,0,0],[5,0,0],[6,0,0],[7,0,0],[8,0,0],[9,0,0]],"bdatl":[[0,0,0],[1,0,0],[2,0,0],[3,0,0],[4,0,0],[5,0,0],[6,0,0],[7,0,0],[8,0,0],[9,0,0]],"ltp":1.29,"tv":2742.58,"id":39823721},{"atb":[[8.8,0],[5.1,0],[18,0],[18.5,0],[17,0],[16,0],[16.5,0],[15.5,0],[15,0],[1.08,0],[14.5,0],[14,0],[13.5,0],[13,0],[12.5,0],[1.23,0],[11.5,0],[5.3,0],[10.5,0],[10,0],[1.01,0],[7,0],[1.02,0],[5.5,0],[6.2,0],[4.9,0],[7.4,0],[1.05,0]],"atl":[[1000,0],[60,0],[29,0],[27,0],[26,0],[24,0],[23,0],[22,0],[42,0],[36,0],[32,0],[19.5,0]],"trd":[[22,0.66],[19.5,14.31]],"bdatb":[[0,0,0],[1,0,0],[2,0,0],[3,0,0],[4,0,0],[5,0,0],[6,0,0],[7,0,0],[8,0,0],[9,0,0]],"bdatl":[[0,0,0],[1,0,0],[2,0,0],[3,0,0],[4,0,0],[5,0,0],[6,0,0],[7,0,0],[8,0,0],[9,0,0]],"ltp":22,"tv":59.95,"id":44331354}],"con":true,"tv":4317.13}]}
{"op":"mcm","clk":"5649827878","pt":1650392996470,"mc":[{"id":"1.197931751","marketDefinition":{"bspMarket":true,"turnInPlayEnabled":false,"persistenceEnabled":false,"marketBaseRate":5.0,"eventId":"31389771","eventTypeId":"4339","numberOfWinners":2,"bettingType":"ODDS","marketType":"PLACE","marketTime":"2022-04-19T18:26:00.000Z","suspendTime":"2022-04-19T18:26:00.000Z","bspReconciled":true,"complete":true,"inPlay":false,"crossMatching":false,"runnersVoidable":false,"numberOfActiveRunners":0,"betDelay":0,"status":"CLOSED","settledTime":"2022-04-19T18:29:41.000Z","runners":[{"status":"LOSER","sortPriority":1,"bsp":21.0,"id":44331354,"name":"1. Paradise Mission"},{"status":"WINNER","sortPriority":2,"bsp":5.6,"id":37947503,"name":"2. Sandwood Jet"},{"status":"LOSER","sortPriority":3,"bsp":2.42,"id":36276560,"name":"3. Kirabilly Kathy"},{"status":"LOSER","sortPriority":4,"bsp":2.86,"id":42930960,"name":"4. Gurtnacrehyblake"},{"status":"LOSER","sortPriority":5,"bsp":4.64,"id":40095374,"name":"5. Castlehill Jil"},{"status":"WINNER","sortPriority":6,"bsp":1.28,"id":39823721,"name":"6. Coolavanny Galiv"}],"regulators":["MR_INT"],"venue":"Sheffield","countryCode":"GB","discountAllowed":true,"timezone":"Europe/London","openDate":"2022-04-19T17:19:00.000Z","version":4497303871,"name":"To Be Placed","eventName":"Sheffield 19th Apr"}}]}
