{"op":"mcm","clk":"AAAAAAAA","pt":1650392673420,"mc":[{"id":"1.197931750","marketDefinition":{"bspMarket":true,"turnInPlayEnabled":false,"persistenceEnabled":false,"marketBaseRate":5,"eventId":"31389771","eventTypeId":"4339","numberOfWinners":1,"bettingType":"ODDS","marketType":"WIN","marketTime":"2022-04-19T18:26:00.000Z","suspendTime":"2022-04-19T18:26:00.000Z","bspReconciled":false,"complete":true,"inPlay":false,"crossMatching":true,"runnersVoidable":false,"numberOfActiveRunners":6,"betDelay":0,"status":"OPEN","runners":[{"status":"ACTIVE","sortPriority":1,"id":44331354},{"status":"ACTIVE","sortPriority":2,"id":37947503},{"status":"ACTIVE","sortPriority":3,"id":36276560},{"status":"ACTIVE","sortPriority":4,"id":42930960},{"status":"ACTIVE","sortPriority":5,"id":40095374},{"status":"ACTIVE","sortPriority":6,"id":39823721}],"regulators":["MR_INT"],"venue":"Sheffield","countryCode":"GB","discountAllowed":true,"timezone":"Europe/London","openDate":"2022-04-19T17:19:00.000Z","version":4495990919,"priceLadderDefinition":{"type":"CLASSIC"}},"rc":[{"atb":[[8.8,18.62],[8.6,4.83],[7,7.19],[7.6,19.55],[7.4,9.11],[8.4,12.66],[7.8,8.34],[7.2,2.1],[8,4.86],[6.6,9.09],[8.2,7.6],[5.7,54.24],[4.3,30.3],[6.8,1.46],[6.4,2.15],[5.3,1.45],[1.02,1.99],[5.5,1.25],[4.9,30],[6,2.3],[5.9,30.61],[6.2,19.23],[3.65,10.56],[5.8,1.46],[1.43,500],[5.2,36.19],[4.2,78.75],[2.66,93.37],[1.05,1.49],[1.01,13002],[1.25,20],[1.3,16.31],[1.12,30]],"atl":[[9.4,10.39],[9.2,5.49],[1000,13],[9,5.45],[10,9.88],[10.5,11.56],[9.8,11.7],[9.6,13.74],[11,11.27],[12,10.85],[11.5,12.72],[18.5,14.29],[17.5,39.09],[16.5,6.45],[15.5,2.76],[16,23.87],[12.5,12.64],[15,2.92],[14.5,2.92],[13.5,2.62],[13,1.8],[14,12.2],[17,0.46],[34,18.5],[990,1.15],[290,2]],"trd":[[8.8,11.71],[9.2,97],[9.4,84.55],[9.6,6.02],[9,9.26],[8.6,22.24],[8.4,47.53],[8.2,10.35],[8,5.24],[10.5,0.42],[10,0.16],[11,0.84]],"bdatb":[[0,8.8,18.62],[1,8.6,8.82],[2,8.4,12.66],[3,8.2,17.25],[4,8,5],[5,7.8,13.58],[6,7.6,22.38],[8,7.2,2.93],[9,7,8.08],[7,7.4,11.88]],"bdatl":[[2,9.4,10.39],[7,11,16.66],[8,11.5,13.31],[9,12,11.24],[1,9.2,5.49],[3,9.6,13.74],[4,9.8,11.7],[5,10,9.88],[6,10.5,12.93],[0,9,5.45]],"ltp":8.8,"tv":295.32,"id":42930960},{"atb":[[21,25.4],[13,2.11],[15.5,13.46],[12.5,2.63],[20,4.84],[18.5,5.65],[19,7.27],[19.5,7.99],[3.9,34.48],[18,2.32],[16.5,4.04],[12,7.48],[11.5,1.46],[8,3.37],[17,2.88],[13.5,4.14],[15,3.34],[11,2],[1.02,1.99],[17.5,2.48],[10.5,31.46],[14,4.27],[16,3.1],[10,20.64],[8.4,34.05],[14.5,1.46],[1.05,1.52],[9.2,1.46],[5.5,55.56],[9.4,1.46],[5.9,26.12],[9.6,1.46],[1.43,500],[9.8,1.46],[5.7,31.91],[6.2,7.69],[2.66,93.37],[4.3,77.27],[8.2,0.74],[1.01,13003.77],[1.25,20],[1.3,16.31],[1.12,30]],"atl":[[1000,13.47],[24,9.03],[25,13.09],[23,29.17],[22,2.29],[28,1.91],[26,2.59],[29,6.78],[60,2],[36,1.46],[32,9.71],[30,2.2],[27,4.25],[44,17],[40,1.46],[38,1.46],[34,1.92],[42,12.2],[48,17.2],[990,1.19],[540,2]],"trd":[[21,18.49],[22,57.42],[23,0.25],[20,14.08],[19.5,0.42],[19,2.89],[18.5,3.05],[18,39.69],[17.5,1.31],[16,1.64],[17,0.77],[14,1.64],[15.5,6.84],[10.5,0.74],[10,5.18]],"bdatb":[[0,21,25.4],[1,20,6.56],[3,19,7.27],[4,18.5,6.44],[6,17.5,5.36],[9,16,3.17],[7,17,3.69],[8,16.5,4.04],[2,19.5,7.99],[5,18,2.32]],"bdatl":[[2,24,9.03],[0,22,2.29],[1,23,29.17],[3,25,13.09],[8,30,2.68],[9,32,9.71],[4,26,2.59],[5,27,4.25],[6,28,1.91],[7,29,6.78]],"ltp":21,"tv":154.41,"id":40095374},{"atb":[[8,6.38],[8.2,10.38],[7.8,15.75],[7.6,14.39],[6.8,1.46],[7.2,5.48],[7.4,11.68],[6,10.16],[6.2,7.48],[6.4,5.48],[3.9,34.48],[7,68.17],[5.2,31.47],[1.02,1.17],[5.6,1.23],[4.3,78.73],[5.5,56.44],[4,83.33],[1.43,500],[5.7,1.46],[5.8,1.46],[5.9,1.46],[6.6,1.46],[4.2,46.88],[4.4,29.41],[4.6,11.11],[1.01,16618.35],[2.66,93.37],[1.25,31.5],[5.1,6.83],[1.12,30]],"atl":[[8.8,12.92],[1000,15.5],[9,28.99],[8.6,13.19],[12.5,2.59],[15,19],[14,20.64],[9.4,3.31],[13,10.52],[12,7.4],[11.5,6.45],[11,3.29],[10.5,6.19],[13.5,5.52],[9.8,2.94],[9.2,10.63],[9.6,5.8],[14.5,2.1],[10,49.09],[15.5,2.26],[18.5,30],[17,2.92],[16,15.12],[21,17.2],[18,2.92],[17.5,1.46],[16.5,2.41],[34,18.5],[20,1.68],[19,0.2],[480,2]],"trd":[[8.2,68.26],[8.4,18.7],[8,3.08],[8.6,14.28],[8.8,13.94],[9,5.62],[9.4,68.75],[9.2,36.53],[9.8,30.48],[9.6,4.39],[11,45.9],[10.5,73.57],[10,64.07],[11.5,0.02],[7,3.58],[7.4,11.32],[6.6,96.51],[6,2.92],[6.2,0.18],[5.9,0.36]],"bdatb":[[0,8.2,14.56],[1,8,21.27],[2,7.8,15.92],[3,7.6,22.84],[6,7,71.05],[7,6.8,1.5],[5,7.2,14.15],[4,7.4,11.68],[8,6.6,2.36],[9,6.4,6.45]],"bdatl":[[1,8.8,12.92],[7,10,50.64],[8,10.5,6.83],[9,11,12.96],[4,9.4,4.84],[6,9.8,7.42],[0,8.6,13.19],[2,9,28.99],[3,9.2,10.63],[5,9.6,5.8]],"ltp":8.2,"tv":562.46,"id":36276560},{"atb":[[21,10.29],[22,2.65],[20,8.9],[19.5,8.98],[15.5,7.46],[19,2.68],[18,4.62],[18.5,2.76],[17,6.37],[16.5,2.31],[13.5,5.57],[13,2.05],[12,16.22],[8,3.37],[7.4,15.62],[10,44.33],[9,31.5],[1.02,1.99],[12.5,4.27],[11.5,1.52],[11,46.28],[17.5,3.35],[14.5,1.59],[16,1.46],[5.8,5.83],[15,1.46],[14,1.46],[1.43,500],[4.3,77.27],[2.66,93.37],[1.12,30],[1.01,13003.66],[1.25,20],[1.27,10.62]],"atl":[[24,36.39],[23,6.76],[25,4.51],[28,4.48],[29,1.88],[26,6.33],[27,3.25],[180,1],[1000,13.49],[46,16],[70,2.22],[44,1.46],[34,2.06],[32,1.87],[30,1.89],[60,0.16],[42,1.46],[40,1.46],[36,1.46],[55,0.17],[65,0.19],[38,1.46],[250,1],[50,17.2],[48,12.2],[230,1],[210,1],[360,2]],"trd":[[22,23.51],[24,0.83],[23,9.46],[21,17.37],[19.5,43.43],[20,2.13],[17,0.09],[16.5,0.27],[14,0.84],[27,0.18],[16,0.58]],"bdatb":[[1,21,11.92],[2,20,8.9],[4,19,3.46],[5,18.5,2.83],[7,17.5,6.16],[8,17,7.18],[9,16.5,2.31],[0,22,2.65],[3,19.5,8.98],[6,18,4.62]],"bdatl":[[8,32,2.32],[9,34,2.06],[1,24,36.39],[6,29,1.88],[5,28,4.48],[7,30,1.89],[0,23,6.76],[2,25,4.51],[3,26,6.33],[4,27,3.25]],"ltp":22,"tv":98.69,"id":37947503},{"atb":[[1.47,76.9],[1.48,40.13],[1.49,9.67],[1.45,29.98],[1.43,68.18],[1.46,40.89],[1.44,86.62],[1.42,20.04],[1.38,21.55],[1.26,77.31],[1.41,9.6],[1.39,55.19],[1.29,70.82],[1.34,260.71],[1.4,22.54],[1.35,20.34],[1.01,13009.58],[1.06,6.48],[1.23,33.61],[1.37,11.01],[1.32,261.03],[1.1,5.44],[1.16,4.35],[1.3,252.51],[1.02,1.99],[1.14,30],[1.36,111.11],[1.25,20]],"atl":[[1.5,22.88],[1.67,38.46],[1000,13],[1.51,53.17],[1.52,41.07],[1.92,250],[1.55,4.02],[1.9,166.67],[1.88,113.64],[1.86,46.51],[1.8,19.56],[1.53,13.39],[1.74,7.18],[1.99,59.64],[1.56,5.2],[1.54,3.88],[1.96,30],[1.58,1.97],[1.79,8.72],[1.69,5.54],[1.64,37.34],[1.6,10],[2.5,3.6],[2.4,12.2],[2.54,17.2],[17,11.5],[34,18.5],[1.91,3],[6.4,0.82],[450,2]],"trd":[[1.49,303.78],[1.48,275.22],[1.5,97.71],[1.47,131.44],[1.45,701.58],[1.44,120.83],[1.46,25.29],[1.51,38.97],[1.52,35.39],[1.53,103.07],[1.54,8.54],[1.56,135.02],[1.57,11.2],[1.55,26.99],[1.59,1.49],[1.62,2.24],[1.58,18.7],[1.67,15.28],[1.75,44.01],[1.79,4],[1.8,14.9]],"bdatb":[[1,1.48,74.26],[2,1.47,114.95],[3,1.46,89.98],[4,1.45,179.38],[6,1.43,98.4],[7,1.42,75.07],[8,1.41,15.73],[9,1.4,104.88],[0,1.49,42.59],[5,1.44,155.25]],"bdatl":[[0,1.5,22.88],[3,1.53,66.02],[4,1.54,58.02],[5,1.55,30.82],[6,1.56,27.68],[7,1.57,24.31],[8,1.58,22.93],[9,1.59,32.44],[2,1.52,41.07],[1,1.51,53.17]],"ltp":1.49,"tv":2115.65,"id":39823721},{"atb":[[60,3.07],[1.05,1.24],[70,0.71],[55,0.26],[50,17.1],[48,0.26],[46,3.91],[65,0.47],[44,3.55],[12,5.6],[8,3.37],[14,14.78],[24,1.46],[29,1.68],[16.5,0.31],[32,2.01],[36,22.5],[15,17.86],[1.01,13002.81],[34,1.59],[40,1.47],[16,10],[17,6.25],[42,1.5],[18,2.35],[20,13.26],[25,1.46],[38,1.06],[30,1.45],[26,1.46],[27,1.46],[28,1.46],[1.43,500],[2.66,93.37],[4.3,77.27],[1.25,20],[1.26,10.54],[1.12,30],[4.5,3]],"atl":[[75,6.59],[80,1.37],[90,2.23],[240,0.32],[85,2.01],[95,2.07],[200,2.39],[400,1.2],[110,0.04],[1000,13],[460,1.16],[440,1.16],[450,0.16],[390,0.19],[100,2.59],[120,0.39],[380,0.19],[420,1],[310,0.56],[370,0.23],[230,0.54],[470,0.15],[300,0.3],[270,2.28],[250,0.59],[490,0.15],[260,0.28],[190,4],[290,0.26],[280,0.27],[140,0.01],[360,0.23],[350,2.22],[320,0.23],[330,0.22],[340,0.43],[480,0.15],[170,0.01]],"trd":[[75,11.33],[70,3.65],[80,20.37],[90,0.49],[85,1.35],[110,0.21],[120,0.79],[60,1.17],[55,3.56],[260,0.1]],"bdatb":[[0,65,1.18],[1,60,3.07],[2,50,17.98],[3,46,4.49],[4,44,3.55],[5,42,1.5],[6,40,1.5],[7,38,2.36],[8,36,22.5],[9,34,2]],"bdatl":[[1,80,1.37],[3,90,2.23],[8,250,1.45],[0,75,6.93],[2,85,2.01],[4,95,2.07],[5,100,2.59],[6,190,4.45],[7,200,2.39],[9,270,2.56]],"ltp":75,"tv":43.02,"id":44331354}],"img":true,"tv":3269.55}]}
{"op":"mcm","clk":"AKABAI4BAJIB","pt":1650392674421,"mc":[{"id":"1.197931750","rc":[{"atb":[[8.8,20.62]],"atl":[[9.6,10.52]],"bdatb":[[6,7.6,21.5],[7,7.4,10.06],[8,7.2,3.97],[3,8.2,15.66],[4,8,7.76],[5,7.8,12.42],[9,7,8.05],[0,8.8,20.62]],"bdatl":[[7,11,13.86],[8,11.5,16.18],[6,10.5,13.83],[9,12,11.86],[4,9.8,12.73],[3,9.6,10.52]],"id":42930960},{"atb":[[18,5.55],[15.5,7.46],[21,24.17]],"atl":[[25,7.58],[24,10.61]],"bdatb":[[7,17,2.93],[9,16,4.55],[5,18,5.55],[0,21,24.17]],"bdatl":[[8,30,2.93],[9,32,9.77],[2,24,10.61],[3,25,7.58],[6,28,2.27]],"id":40095374},{"atb":[[8.4,1.2],[8.2,12.71]],"atl":[[8.6,11.68],[8.8,8.74]],"bdatb":[[6,7.2,11.96],[7,7,71.1],[8,6.8,2.34],[9,6.6,1.52],[4,7.6,24.03],[0,8.4,1.2],[1,8.2,16.9],[2,8,8.22],[3,7.8,15.92],[5,7.4,11.68]],"bdatl":[[7,10,49.51],[8,10.5,9.98],[0,8.6,11.68],[4,9.4,6.92],[6,9.8,5.42],[1,8.8,8.74],[9,11,13.57]],"id":36276560},{"atb":[[21,12.29]],"bdatb":[[8,17,6.42],[1,21,13.92]],"bdatl":[[8,32,2.55],[9,34,2.12],[7,30,2.22]],"id":37947503},{"atb":[[1.49,22.81],[1.48,46.13]],"atl":[[1.5,33.24],[1.52,30.71],[1000,13.03],[1.51,59.17]],"bdatb":[[6,1.43,85.25],[7,1.42,81.15],[8,1.41,30.03],[9,1.4,97.73],[0,1.49,55.73],[3,1.46,69.47],[4,1.45,178.65],[1,1.48,80.26]],"bdatl":[[2,1.52,37.34],[3,1.53,47.66],[4,1.54,70.66],[1,1.51,59.17],[5,1.55,14.44],[7,1.57,41.5],[8,1.58,19.82],[9,1.59,8.17],[6,1.56,31.83]],"id":39823721},{"atb":[[1.05,1.24],[1.04,0.52],[70,0.46],[50,19.1],[48,2.32]],"atl":[[220,0.35],[75,12.26]],"trd":[[70,4.17]],"bdatb":[[0,60,4],[1,50,19.98],[2,48,2.32],[3,46,4.23],[4,44,3.55],[5,42,1.5],[6,40,1.5],[7,38,2.36],[8,36,22.5],[9,34,1.61]],"bdatl":[[8,240,1.21],[9,270,3.15],[0,75,12.26]],"ltp":70,"tv":43.54,"id":44331354}],"con":true,"tv":3270.07}]}
{"op":"mcm","clk":"AMICALUCAI8C","pt":1650392675423,"mc":[{"id":"1.197931750","rc":[{"atb":[[1.01,13003.7],[8.6,6.58]],"atl":[[9.4,10.39],[9,5.45]],"bdatb":[[1,8.6,10.57],[2,8.4,16.39],[6,7.6,24.49],[7,7.4,10.27],[3,8.2,13.76],[4,8,9.71],[5,7.8,8.4],[9,7,7.19],[8,7.2,4.94]],"bdatl":[[2,9.4,10.39],[8,11.5,13.08],[9,12,12.73],[0,9,5.45],[1,9.2,5.49],[3,9.6,10.52],[4,9.8,14.08],[5,10,9.88],[6,10.5,14.89],[7,11,13.92]],"id":42930960},{"atl":[[1000,14.04],[24,8.61],[22,1.56],[23,7.61]],"trd":[[22,61.34]],"bdatb":[[1,20,7.29],[3,19,8.14],[4,18.5,5.65],[6,17.5,4.41],[7,17,3.86],[9,16,5.52]],"bdatl":[[0,22,1.56],[1,23,7.61],[2,24,8.61],[3,25,7.58],[4,26,2.59],[5,27,4.25],[6,28,2.74],[7,29,6.78],[8,30,2.2],[9,32,10.76]],"ltp":22,"tv":158.33,"id":40095374},{"atb":[[1.01,16618.92],[8,8.71],[8.4,7.96],[8.2,5.77]],"atl":[[8.6,13.51],[10.5,3.52],[9,31.77]],"bdatb":[[2,8,10.79],[6,7.2,11.34],[7,7,68.81],[0,8.4,7.96],[1,8.2,11.75],[3,7.8,15.75],[4,7.6,26.15],[5,7.4,11.68],[8,6.8,4.47],[9,6.6,2.36]],"bdatl":[[8,10.5,3.91],[0,8.6,13.51],[2,9,31.77],[4,9.4,5.79],[6,9.8,6.51],[7,10,52.01]],"id":36276560},{"atb":[[1.48,46.13],[1.49,15.67]],"atl":[[1000,15.27],[1.5,43.78],[1.57,0.03]],"trd":[[1.5,109.71]],"bdatb":[[3,1.46,69.47],[4,1.45,99.6],[5,1.44,168.51],[6,1.43,134.99],[7,1.42,65.94],[0,1.49,38.7],[1,1.48,90.21],[8,1.41,31.65],[9,1.4,62.32],[2,1.47,114.95]],"bdatl":[[4,1.54,64.92],[5,1.55,5.55],[6,1.56,39.96],[7,1.57,43.74],[8,1.58,8.1],[2,1.52,69.07],[3,1.53,32.47],[9,1.59,17.63],[0,1.5,43.78]],"ltp":1.5,"tv":2127.65,"id":39823721},{"atb":[[1.5,2],[60,3.07],[1.04,0],[70,0.81]],"atl":[[75,3.53],[100,2.61],[1000,13],[210,0.36]],"trd":[[75,32.78]],"bdatb":[[2,50,20.27],[4,46,4.27],[6,42,1.5],[8,38,1.95],[1,60,3.07],[3,48,2.32],[5,44,3.55],[7,40,1.47],[9,36,22.5],[0,65,1.28]],"bdatl":[[0,75,3.53],[5,100,2.61],[8,230,1.25],[9,260,1.19]],"ltp":75,"tv":64.99,"id":44331354},{"bdatb":[[1,21,13.92],[2,20,9.64],[4,19,3.55],[5,18.5,2.76],[7,17.5,5.29],[8,17,7.35]],"bdatl":[[7,30,2.67],[8,32,1.87],[9,34,3.05]],"id":37947503}],"con":true,"tv":3307.44}]}
{"op":"mcm","clk":"AIEEANkDAI4D","pt":1650392676427,"mc":[{"id":"1.197931750","rc":[{"atb":[[7.8,7.36],[8.8,29.43],[9.2,4.32],[9,4.49],[1.01,13002],[8.6,8.62],[6.8,7.46]],"atl":[[9.4,4.53],[9.6,8.51],[9.2,0],[9,0]],"trd":[[9.2,102.59],[9.4,87.19],[9,14.71]],"bdatb":[[0,9.2,7.23],[2,8.8,30.87],[3,8.6,11.43],[4,8.4,15.9],[5,8.2,7.6],[6,8,5.99],[7,7.8,8.58],[8,7.6,20.61],[9,7.4,10.55],[1,9,4.49]],"bdatl":[[6,11.5,18.12],[7,12,11.68],[9,13,4.72],[5,11,12.16],[8,12.5,12.64],[0,9.4,4.53],[1,9.6,8.51],[2,9.8,11.7],[3,10,9.88],[4,10.5,11.56]],"ltp":9.2,"tv":309,"id":42930960},{"atb":[[18.5,5.65],[21,25.47]],"atl":[[24,8.61],[22,2.89],[23,5.44],[28,2.91],[1000,13.47]],"trd":[[22,64.08],[23,3.08]],"bdatb":[[0,21,26.74],[2,19.5,8.64],[7,17,5.71],[8,16.5,4.04],[9,16,3.66],[5,18,5.72],[3,19,7.27],[6,17.5,2.48],[4,18.5,5.65],[1,20,4.84]],"bdatl":[[0,22,2.89],[2,24,8.61],[1,23,5.44],[3,25,7.58],[4,26,2.59],[5,27,4.25],[6,28,2.91],[7,29,6.78],[8,30,2.2],[9,32,10.02]],"ltp":22,"tv":163.9,"id":40095374},{"atb":[[5.7,7.46],[7.2,15.57],[6.8,3.76],[7.4,9.71],[7,44.87],[7.6,0],[4.9,38.97],[1.01,16618.35],[8.4,0],[7.8,0],[8.2,0],[8,0]],"atl":[[8.2,8.3],[7.8,39.2],[8.8,4.84],[7.6,3.52],[8.6,8.25],[8,8.37],[8.4,7.24],[9.2,3.92],[9,26.19],[9.8,2.84],[10,48.99]],"trd":[[7.6,28.87],[7.8,62.46],[8.4,34.62],[8.2,85.79],[8,22.57]],"bdatb":[[0,7.4,15.04],[1,7.2,8.23],[2,7,51.75],[3,6.8,5.09],[4,6.6,2.9],[5,6.4,6.75],[6,6.2,9.2],[7,6,10.68],[8,5.9,1.46],[9,5.8,1.46]],"bdatl":[[0,7.6,3.52],[1,7.8,39.2],[3,8.2,16.51],[6,8.8,10.34],[7,9,28.61],[8,9.2,4.1],[9,9.4,3.31],[2,8,8.37],[4,8.4,8.42],[5,8.6,8.25]],"ltp":7.6,"tv":706.73,"id":36276560},{"atb":[[22,2.65]],"atl":[[25,2.5],[24,36.35],[23,10.65]],"trd":[[23,14.91]],"bdatb":[[0,22,3.87],[2,20,9.53],[3,19.5,8.98],[5,18.5,2.93],[6,18,5.79],[8,17,7.97],[1,21,12.29],[9,16.5,2.31],[4,19,2.68],[7,17.5,3.35]],"bdatl":[[0,23,10.65],[1,24,36.35],[2,25,2.5],[9,34,2.35],[7,30,1.89]],"ltp":23,"tv":104.14,"id":37947503},{"atb":[[1.51,5.41],[1.45,64.42],[1.49,25.5],[1.5,47.94],[1.02,2.99],[1.48,38.56],[1.44,34.73]],"atl":[[1.53,4.48],[1000,13],[1.54,5.89],[1.57,6.81],[1.55,6.12],[1.63,5.71],[1.52,25.94],[1.51,0],[1.5,0]],"trd":[[1.51,80.84],[1.5,158.03]],"bdatb":[[0,1.51,24.26],[1,1.5,72.52],[2,1.49,109.45],[3,1.48,135.73],[4,1.47,80.41],[5,1.46,83.21],[6,1.45,132.31],[7,1.44,87.38],[8,1.43,103.1],[9,1.42,67.46]],"bdatl":[[1,1.53,33.57],[2,1.54,5.89],[3,1.55,43.73],[4,1.56,13.89],[5,1.57,12.08],[6,1.58,32.22],[7,1.59,89.6],[8,1.6,52.94],[9,1.61,46.04],[0,1.52,25.94]],"ltp":1.51,"tv":2217.84,"id":39823721},{"atb":[[50,19.17],[1.05,1.24],[55,0.28],[1.12,30],[60,1.06],[46,3.95],[1.5,0],[70,0],[65,2.95]],"atl":[[75,7.97],[95,0],[90,2.23],[85,2.01],[70,0],[80,1.36]],"trd":[[75,34.35],[70,5.74]],"bdatb":[[0,65,3.36],[2,50,19.63],[3,48,2.32],[4,46,3.95],[5,44,3.55],[6,42,1.58],[7,40,1.47],[8,38,1.61],[9,36,23.25],[1,60,1.06]],"bdatl":[[2,85,2.01],[3,90,2.23],[4,100,2.61],[5,190,4.45],[6,200,2.39],[7,230,1.25],[8,260,1.19],[9,270,2.28],[0,75,8.31],[1,80,1.36]],"ltp":75,"tv":68.13,"id":44331354}],"con":true,"tv":3569.74}]}
{"op":"mcm","clk":"ALQFAN8EAKAE","pt":1650392677428,"mc":[{"id":"1.197931750","rc":[{"atb":[[8.8,27.4],[9.2,0]],"atl":[[9.4,6.15],[9.6,9.56],[9.8,19.96]],"bdatb":[[1,8.8,29.94],[3,8.4,15.5],[4,8.2,8.3],[5,8,5.33],[6,7.8,7.36],[0,9,4.49],[2,8.6,8.62],[7,7.6,21.06],[8,7.4,10.55],[9,7.2,2.53]],"bdatl":[[0,9.4,6.15],[1,9.6,9.56],[7,12,15.88],[8,12.5,12.67],[5,11,13.38],[6,11.5,12.85],[2,9.8,19.96],[4,10.5,14.9],[9,13,1.8]],"id":42930960},{"atb":[[21,24.17]],"atl":[[24,12.72],[23,4.82]],"bdatb":[[3,19,8.45],[6,17.5,3.84],[8,16.5,4.39],[9,16,3.1],[0,21,24.17],[5,18,5.55],[7,17,2.88],[2,19.5,7.99]],"bdatl":[[6,28,3.41],[8,30,2.2],[9,32,10.36],[2,24,12.72],[1,23,4.82]],"id":40095374},{"atb":[[6.6,2.35],[5.9,0],[5.7,6],[6.8,4.39],[6.2,6.02],[5.8,0],[6.4,4.02],[7.2,11.8],[7.4,4.74],[7,42.84]],"atl":[[7.8,41.19],[13,9.65],[7.6,6.84],[9,6.78],[8,12.76]],"bdatb":[[1,7.2,14.91],[2,7,46.25],[3,6.8,5.78],[4,6.6,2.67],[5,6.4,5.49],[6,6.2,7.74],[8,5.8,2.76],[9,5.7,6],[0,7.4,4.74]],"bdatl":[[0,7.6,6.84],[1,7.8,41.19],[8,9.2,10.52],[3,8.2,10.03],[4,8.4,10.36],[5,8.6,10.33],[6,8.8,5],[7,9,6.78],[2,8,12.76],[9,9.4,3.31]],"id":36276560},{"atl":[[23,6.88],[25,4.51]],"bdatb":[[2,20,10.02],[5,18.5,4.05],[8,17,6.7],[9,16.5,2.31],[0,22,2.65],[6,18,4.62]],"bdatl":[[7,30,2.36],[8,32,1.87],[9,34,2.67],[0,23,6.88],[2,25,4.51]],"id":37947503},{"atb":[[1.17,0.03],[1.5,40.48],[1.52,9.33],[1.46,82.65],[1.51,30.15],[1.45,12.53],[1.47,52.15],[1.02,1.99]],"atl":[[1.53,14.61],[1.54,15.5],[1.56,7.37],[1.52,0]],"trd":[[1.53,115.5]],"bdatb":[[1,1.51,64.56],[2,1.5,48.26],[4,1.48,183.82],[5,1.47,100.29],[6,1.46,104.1],[8,1.44,50],[9,1.43,140.77],[0,1.52,9.33],[3,1.49,89.01],[7,1.45,59.47]],"bdatl":[[0,1.53,14.61],[7,1.6,49.48],[8,1.61,25.08],[9,1.62,18.42],[3,1.56,10.78],[4,1.57,57.54],[5,1.58,44.03],[6,1.59,81.69],[1,1.54,15.5],[2,1.55,28.76]],"ltp":1.53,"tv":2230.27,"id":39823721},{"atb":[[70,3.02],[1.05,1.24],[65,2.97],[60,3.28],[55,2.34]],"atl":[[400,0.2],[380,1.19]],"bdatb":[[4,50,19.62],[8,42,2.07],[1,65,2.97],[2,60,3.28],[3,55,2.34],[5,48,2.32],[6,46,3.95],[7,44,3.55],[9,40,1.47],[0,70,2.66]],"bdatl":[[0,75,7.97]],"id":44331354}],"con":true,"tv":3582.17}]}
{"op":"mcm","clk":"AOwGAPoFAKYF","pt":1650392678429,"mc":[{"id":"1.197931750","rc":[{"atb":[[8.8,21.17],[1.3,0]],"atl":[[11,9.26]],"bdatb":[[1,8.8,21.17],[6,7.8,8.83],[7,7.6,19.94],[8,7.4,11.49],[4,8.2,9.71],[5,8,4.86],[3,8.4,15.06]],"bdatl":[[6,11.5,14.48],[7,12,14.32],[8,12.5,16.24],[5,11,11.37]],"id":42930960},{"atb":[[1.3,0]],"bdatb":[[3,19,7.27],[8,16.5,5.09],[6,17.5,3.63]],"bdatl":[[6,28,3.76],[9,32,10.06]],"id":40095374},{"atb":[[1.25,20]],"atl":[[8.4,9.08],[12.5,1.71],[8,20.85],[7.8,43.19],[8.8,2.84]],"bdatb":[[1,7.2,11.8],[4,6.6,4.09],[5,6.4,5.41],[6,6.2,7.91],[3,6.8,6.93],[2,7,45.72]],"bdatl":[[2,8,20.85],[3,8.2,11.21],[4,8.4,9.21],[6,8.8,5.13],[8,9.2,13.33],[1,7.8,43.19]],"id":36276560},{"atb":[[1.27,0]],"bdatb":[[2,20,8.9],[8,17,7.39],[5,18.5,3.85]],"bdatl":[[7,30,2.68],[9,34,2.39]],"id":37947503},{"atb":[[1.47,104.04],[1.49,25.53],[1.46,30.76],[1.52,15.7],[1.17,0],[1.34,250],[1.5,57.72],[1.51,36.15]],"atl":[[1.58,8.93],[1.53,0],[1.54,13.08],[1.57,13.12],[1.55,11.17]],"trd":[[1.53,144.71],[1.54,8.56]],"bdatb":[[6,1.46,107.23],[7,1.45,19.23],[3,1.49,89.04],[5,1.47,141.57],[8,1.44,75.25],[9,1.43,98.57],[0,1.52,15.7],[2,1.5,65.5],[1,1.51,70.56],[4,1.48,194.36]],"bdatl":[[0,1.54,13.08],[1,1.55,33.8],[2,1.56,10.78],[3,1.57,63.85],[4,1.58,59.84],[5,1.59,56.19],[6,1.6,74.82],[7,1.61,1.64],[8,1.62,7.88],[9,1.63,24.01]],"ltp":1.54,"tv":2259.5,"id":39823721},{"atb":[[17.5,0.29],[2.06,0],[16.5,0],[1.26,0]],"atl":[[75,7.97]],"bdatb":[[4,50,19.17],[8,42,1.98],[0,70,3.02]],"bdatl":[[0,75,7.97]],"id":44331354}],"con":true,"tv":3611.4}]}
{"op":"mcm","clk":"AJQIAI0HALUG","pt":1650392679431,"mc":[{"id":"1.197931750","rc":[{"atb":[[9,5.61]],"bdatb":[[1,8.8,21.96],[3,8.4,18.01],[5,8,5.03],[9,7.2,3.77],[4,8.2,9.02],[6,7.8,11.89],[0,9,5.61],[7,7.6,22.45],[8,7.4,12.32]],"bdatl":[[4,10.5,16.08],[5,11,10.24],[6,11.5,16.53],[7,12,13.56],[8,12.5,16.97]],"id":42930960},{"atl":[[22,30.12]],"bdatb":[[3,19,7.64],[6,17.5,5.05],[9,16,3.55],[8,16.5,4.39]],"bdatl":[[9,32,10.1],[6,28,4.16]],"id":40095374},{"atb":[[7.4,27.43],[1.01,16618.35],[4.4,27.61],[7.2,13.8]],"atl":[[8,23.62],[8.6,9.25]],"bdatb":[[1,7.2,14.77],[2,7,50.1],[3,6.8,5.45],[8,5.7,8.49],[9,5.6,1.55],[4,6.6,7.71],[5,6.4,7.47],[6,6.2,9.85],[7,6,12.51]],"bdatl":[[3,8.2,14.09],[4,8.4,9.44],[6,8.8,7.81],[5,8.6,10.16],[2,8,23.62]],"id":36276560},{"atb":[[1.52,31.21],[1.05,0],[1.47,89.35]],"atl":[[1.53,11.95],[1.54,37.68],[1.55,22.82],[1.56,14.14],[1.57,15.13]],"trd":[[1.53,165.03],[1.52,41.06]],"bdatb":[[0,1.52,31.21],[5,1.47,126.88],[6,1.46,113.88],[7,1.45,21.08],[8,1.44,81.99],[9,1.43,83.11]],"bdatl":[[0,1.53,4.57],[1,1.54,37.68],[2,1.55,45.46],[3,1.56,24.01],[4,1.57,68.61],[5,1.58,57.69],[6,1.59,62.53],[7,1.6,68.52],[8,1.61,7.9],[9,1.62,10.54]],"ltp":1.53,"tv":2285.49,"id":39823721},{"atl":[[400,1.2]],"bdatb":[[8,42,2.57],[4,50,19.31]],"id":44331354},{"bdatb":[[2,20,9.25],[5,18.5,5.19],[8,17,6.71],[9,16.5,2.66]],"bdatl":[[9,34,2.42],[7,30,3.06]],"id":37947503}],"con":true,"tv":3637.39}]}
{"op":"mcm","clk":"ALcJALYIAMwH","pt":1650392680432,"mc":[{"id":"1.197931750","rc":[{"atb":[[8.8,14.15],[9,16.69]],"bdatb":[[2,8.8,16.19],[0,9.2,2.63],[1,9,7.61],[3,8.6,8.82],[4,8.4,19.6],[5,8.2,7.6],[6,8,9.28],[7,7.8,10.19],[8,7.6,21.34],[9,7.4,10.48]],"bdatl":[[7,12,17.09],[8,12.5,13.58],[4,10.5,16],[5,11,10.32],[6,11.5,16.46],[9,13,3.62]],"id":42930960},{"atb":[[14.5,7.46],[19,4.5],[19.5,0.75],[18,8.38],[20,0],[18.5,7.71],[21,0]],"atl":[[25,7.01],[23,7.49],[20,2.69],[21,11.99],[26,2.67],[1000,13.47],[22,36.22],[24,16.7]],"trd":[[20,21.6],[21,57.6]],"bdatb":[[0,19.5,4.06],[1,19,6.37],[3,18,7.85],[2,18.5,7.71],[4,17.5,2.48],[5,17,2.88],[6,16.5,5.79],[7,16,4.94],[8,15.5,7.46],[9,15,5.7]],"bdatl":[[1,21,11.99],[6,26,2.67],[8,28,4.57],[0,20,1.36],[2,22,36.22],[3,23,6.87],[4,24,16.7],[5,25,7.58],[7,27,4.25],[9,29,6.78]],"ltp":20,"tv":210.53,"id":40095374},{"atb":[[7.4,34.48]],"atl":[[7.6,3.19],[12,6.49]],"bdatb":[[0,7.4,38.15],[1,7.2,14.04],[2,7,51.16],[5,6.4,4.78],[6,6.2,9.06],[3,6.8,9.59],[4,6.6,5.69],[8,5.8,2.76],[9,5.7,6]],"bdatl":[[4,8.4,14.63],[6,8.8,4.17],[8,9.2,7.48],[9,9.4,3.31],[5,8.6,9.25],[7,9,7.91],[0,7.6,3.19],[3,8.2,8.3]],"id":36276560},{"atb":[[1.52,30.67]],"atl":[[1.53,11.95],[1.54,37.84],[1000,13]],"bdatb":[[5,1.47,150.53],[6,1.46,52.28],[8,1.44,68.82],[9,1.43,142.82],[0,1.52,46.6],[1,1.51,58.4],[2,1.5,124.68],[3,1.49,150.99],[7,1.45,48.89],[4,1.48,105.33]],"bdatl":[[4,1.57,28.37],[5,1.58,90.51],[6,1.59,29.66],[7,1.6,48.28],[8,1.61,23.68],[9,1.63,36.4],[1,1.54,37.84],[3,1.56,51.51],[0,1.53,18.92],[2,1.55,22.82]],"id":39823721},{"atl":[[75,5.67]],"bdatb":[[1,65,3.34],[3,55,2.34],[4,50,19.23],[5,48,2.36],[6,46,3.95],[9,40,2.19],[8,42,1.5]],"bdatl":[[0,75,5.67]],"id":44331354},{"bdatb":[[0,22,3.75],[1,21,12.29],[2,20,9.05],[3,19.5,9.07],[8,17,8.1],[4,19,2.68],[6,18,6.22],[5,18.5,2.76],[9,16.5,2.31]],"bdatl":[[9,34,3.43],[8,32,1.87],[7,30,1.89]],"id":37947503}],"con":true,"tv":3684.02}]}
{"op":"mcm","clk":"ANcKANkJAM8I","pt":1650392681433,"mc":[{"id":"1.197931750","rc":[{"atb":[[8.8,20.47],[7.6,16.68],[9,15.73],[7.4,3.11],[9.2,1.7]],"atl":[[9.8,17.94],[9.6,8.51],[9.4,1.3]],"bdatb":[[0,9.2,2.93],[2,8.8,21.27],[3,8.6,15.4],[8,7.6,16.68],[1,9,15.73],[4,8.4,12.66],[5,8.2,11.91],[6,8,7.62],[7,7.8,10.4],[9,7.4,5.02]],"bdatl":[[6,11.5,14.83],[7,12,13.38],[8,12.5,13.44],[9,13,7.69],[4,10.5,11.56],[5,11,13.49],[1,9.6,8.51],[2,9.8,17.94],[0,9.4,1.3]],"id":42930960},{"atb":[[18.5,8.84],[19,3.73],[19.5,0],[18,9.37],[17.5,3.2]],"atl":[[26,4.13],[24,10.61],[22,43.37],[20,9.11]],"trd":[[19,4.43],[19.5,1.92]],"bdatb":[[0,19,4.32],[1,18.5,2.18],[2,18,9.42],[6,16,6.74],[8,15,4.5],[9,14.5,8.7],[3,17.5,3.2],[4,17,3.23],[5,16.5,4.04],[7,15.5,7.46]],"bdatl":[[6,26,4.73],[2,22,43.37],[4,24,10.61],[0,20,9.11],[8,28,4.01],[3,23,7.49],[5,25,7.01]],"ltp":19,"tv":213.57,"id":40095374},{"atb":[[4.2,44]],"atl":[[8,21.61],[7.6,1.48]],"trd":[[7.6,32.27]],"bdatb":[[0,7.4,36.13],[1,7.2,14.64],[2,7,51.16],[5,6.4,7.73],[6,6.2,8.3],[7,6,10.16],[8,5.9,1.76],[9,5.7,6.97]],"bdatl":[[7,9,8.18],[8,9.2,7.22],[0,7.6,1.48],[3,8.2,8.3],[4,8.4,10.94],[5,8.6,12.85]],"tv":710.13,"id":36276560},{"atb":[[1.49,27.55]],"bdatb":[[0,1.52,38.09],[1,1.51,90.84],[3,1.49,138.93],[4,1.48,52.33],[6,1.46,63.08],[7,1.45,50.2],[8,1.44,97.03],[9,1.43,107.77],[2,1.5,116.61],[5,1.47,171.9]],"bdatl":[[4,1.57,36.46],[5,1.58,50.33],[6,1.59,61.6],[8,1.61,13.02],[9,1.62,10.59],[7,1.6,48.28],[0,1.53,11.95]],"id":39823721},{"atb":[[60,1.06],[70,1.31]],"atl":[[460,0.16],[75,7.97]],"trd":[[70,9.16]],"bdatb":[[0,70,1.31],[1,65,3.14],[3,55,2.34],[4,50,19.19],[5,48,2.45],[6,46,3.95],[9,40,2.93],[7,44,3.55]],"bdatl":[[0,75,7.97]],"ltp":70,"tv":71.55,"id":44331354},{"bdatb":[[0,22,3.16],[1,21,12.29],[2,20,8.95],[3,19.5,9.29],[4,19,2.68],[6,18,7.86],[9,16.5,3.36],[5,18.5,2.76],[8,17,6.37]],"bdatl":[[8,32,2.36],[9,34,2.06]],"id":37947503}],"con":true,"tv":3693.88}]}
{"op":"mcm","clk":"AOMLAPIKAOYJ","pt":1650392682434,"mc":[{"id":"1.197931750","rc":[{"atb":[[9,17.45],[9.2,3.36],[8.8,18.86]],"atl":[[9.8,12],[10,28.49]],"bdatb":[[9,7.4,5.93],[1,9,18.56],[5,8.2,12.33],[0,9.2,3.36],[2,8.8,18.86],[3,8.6,14.23],[6,8,6.3]],"bdatl":[[5,11,15.29],[6,11.5,17.21],[7,12,12.53],[2,9.8,12],[3,10,28.49],[8,12.5,18.74],[9,13,1.8]],"id":42930960},{"atb":[[3.9,0],[18,6.92],[18.5,9.63],[4.5,28.57]],"atl":[[23,6.87],[21,14],[22,45.81],[20,9.16],[19.5,2.07],[24,9.03]],"bdatb":[[9,14.5,7.68],[0,19,3.73],[2,18,6.92],[3,17.5,3.77],[4,17,2.88],[5,16.5,4.17],[6,16,5.98],[8,15,5.71],[1,18.5,9.63]],"bdatl":[[2,21,14],[4,23,6.87],[3,22,45.81],[0,19.5,2.07],[1,20,9.16],[9,28,4.18],[5,24,9.03],[6,25,7.01],[7,26,5.32],[8,27,4.25]],"id":40095374},{"atb":[[7.2,15.95]],"atl":[[8.2,19.38],[7.6,1.32]],"bdatb":[[6,6.2,9.38],[7,6,11.01],[8,5.9,1.85],[9,5.7,6],[3,6.8,10.1],[1,7.2,21.56],[2,7,45.4],[0,7.4,34.48],[4,6.6,4.09]],"bdatl":[[5,8.6,13.38],[6,8.8,3.35],[7,9,12.01],[8,9.2,6.11],[4,8.4,12.75],[3,8.2,19.38],[0,7.6,1.32],[2,8,21.61]],"id":36276560},{"atb":[[22,5.36],[21,10.29],[15.5,1.46]],"bdatb":[[0,22,5.36],[1,21,10.29],[5,18.5,4.28],[6,18,5.61],[2,20,9.4],[3,19.5,8.98],[4,19,2.8],[9,16.5,4.47]],"bdatl":[[8,32,2.83]],"id":37947503},{"atb":[[1.05,1],[1.52,43.68],[1.51,47.47],[1.5,50.82],[1.47,87.34],[1.45,10.52],[1.44,32.72],[1.46,28.75]],"atl":[[1.58,8.93],[1.55,25.04],[1.53,0],[1.56,7.37]],"trd":[[1.53,188.93]],"bdatb":[[0,1.52,51.72],[2,1.5,129.23],[3,1.49,118.44],[1,1.51,101.54],[4,1.48,139.56],[5,1.47,103.24],[6,1.46,95.86],[7,1.45,52.57],[8,1.44,61.08],[9,1.43,148.59]],"bdatl":[[4,1.58,96.17],[6,1.6,71.71],[7,1.61,6.27],[8,1.62,3.72],[9,1.63,41.3],[1,1.55,25.04],[3,1.57,45.09],[0,1.54,37.84],[2,1.56,52.8],[5,1.59,3.85]],"tv":2309.39,"id":39823721},{"atb":[[65,3.21],[55,0.28]],"atl":[[380,0.19],[370,1.23]],"bdatb":[[7,42,2.17],[8,40,1.92],[1,65,3.21],[3,50,19.63],[4,48,2.32],[5,46,4],[6,44,3.55],[9,38,1.06],[2,60,1.06]],"id":44331354}],"con":true,"tv":3717.78}]}
{"op":"mcm","clk":"AIYNAIcMAPoK","pt":1650392683435,"mc":[{"id":"1.197931750","rc":[{"atb":[[8.8,16.83],[9.2,1.65]],"bdatb":[[3,8.6,9.06],[4,8.4,16.83],[1,9,23.92],[2,8.8,16.83],[5,8.2,7.6],[8,7.6,18.54],[9,7.4,3.11],[0,9.2,1.65]],"bdatl":[[5,11,11.53],[6,11.5,16.33],[7,12,16.83],[8,12.5,12.64],[9,13,5.86],[4,10.5,11.56]],"id":42930960},{"atb":[[19,2.35]],"atl":[[19.5,7.99],[24,6.06],[22,40.7],[21,17.15]],"bdatb":[[6,16,3.34],[8,15,5.46],[0,19,2.35],[3,17.5,3.9],[4,17,5.59],[5,16.5,4.04]],"bdatl":[[0,19.5,7.99],[9,28,3.26],[5,24,6.06],[7,26,4.71],[2,21,17.15],[3,22,40.7]],"id":40095374},{"atb":[[7,42.84],[7.4,3.37],[7.2,23.04]],"atl":[[7.6,8.17],[8,23.62]],"trd":[[7.4,16.32]],"bdatb":[[2,7,47.93],[0,7.4,3.37],[1,7.2,31.13],[3,6.8,4.86],[6,6.2,8.3],[7,6,12.13],[8,5.7,6.71],[9,5.6,1.23]],"bdatl":[[0,7.6,8.17],[7,9,14.75],[8,9.2,3.92],[9,9.4,4.07],[2,8,23.62],[4,8.4,10.89],[5,8.6,15.2],[6,8.8,2.84]],"ltp":7.4,"tv":715.13,"id":36276560},{"atb":[[22,6.6]],"bdatb":[[0,22,6.6],[6,18,4.83],[8,17,8.24],[3,19.5,11.34],[4,19,2.68],[7,17.5,3.35],[9,16.5,2.5],[2,20,9.51],[5,18.5,2.76]],"bdatl":[[6,29,1.88],[8,32,2.34]],"id":37947503},{"atb":[[1.52,43.68],[1.53,0],[1.05,0],[1.5,64.4]],"atl":[[1000,14]],"trd":[[1.53,189.57],[1.52,44.26]],"bdatb":[[0,1.52,84.53],[1,1.51,109.53],[2,1.5,101.52],[3,1.49,153.38],[4,1.48,104.38],[8,1.44,51.68],[9,1.43,151.42],[5,1.47,156.45],[6,1.46,42.29],[7,1.45,80.73]],"bdatl":[[2,1.56,23.38],[3,1.57,27.66],[4,1.58,89.68],[5,1.59,11.71],[6,1.6,29.97],[7,1.61,77.35],[8,1.62,29.1],[9,1.63,20.82]],"ltp":1.53,"tv":2313.23,"id":39823721},{"atb":[[65,5.42],[60,1.57],[55,4.41],[70,0.95]],"atl":[[75,7.97]],"bdatb":[[0,65,6.37],[8,40,1.56],[1,60,1.57],[4,48,3.28],[5,46,3.95],[9,38,1.06],[2,55,4.63],[7,42,1.5],[3,50,19.17],[6,44,3.55]],"bdatl":[[0,75,7.97]],"id":44331354}],"con":true,"tv":3726.62}]}
{"op":"mcm","clk":"AL4OAJwNAI0M","pt":1650392684436,"mc":[{"id":"1.197931750","rc":[{"atb":[[9,19.16],[7.2,8.1],[8.8,18.86]],"bdatb":[[2,8.8,22.95],[5,8.2,9.79],[0,9.2,2.38],[1,9,18.98],[4,8.4,13.33],[6,8,8.94],[3,8.6,8.62],[7,7.8,7.36],[8,7.6,19.81],[9,7.4,5.02]],"bdatl":[[6,11.5,17.57],[7,12,17.11],[9,13,1.81],[5,11,9.26]],"id":42930960},{"atb":[[17,1.42]],"atl":[[22,38.9],[21,19.04]],"bdatb":[[9,14.5,8.7],[0,19,2.7],[3,17.5,3.52],[5,16.5,6.22],[7,15.5,7.82],[2,18,6.92],[4,17,1.91],[8,15,3.34],[6,16,3.1]],"bdatl":[[7,26,4.13],[2,21,19.04],[3,22,38.9],[9,28,2.91]],"id":40095374},{"atb":[[7.2,18.17],[7,44.84],[6,8.12],[4,78.23],[7.4,0]],"atl":[[7.8,43.19],[9.4,3.2],[7.4,0],[8.2,10.03],[8.6,2.83]],"trd":[[7.4,23.07]],"bdatb":[[2,6.8,7.87],[0,7.2,21],[1,7,49.97],[9,5.6,1.23],[3,6.6,7.3],[6,6,8.12],[4,6.4,7.73],[5,6.2,8.3],[7,5.9,2.71],[8,5.7,6]],"bdatl":[[5,8.6,7.54],[9,9.4,7.61],[2,8,23.62],[4,8.4,10.89],[1,7.8,43.19],[7,9,15.11],[0,7.6,8.17],[3,8.2,10.03],[6,8.8,2.84],[8,9.2,3.92]],"tv":721.88,"id":36276560},{"atb":[[22,9.11],[21,9.99],[20,8.22],[19.5,8.26]],"atl":[[25,2.5],[23,0.89]],"bdatb":[[0,22,8.95],[8,17,7.43],[2,20,8.5],[3,19.5,10.52],[6,18,4.93],[1,21,9.99],[7,17.5,3.35],[9,16.5,2.31]],"bdatl":[[7,32,1.87],[1,25,2.5],[0,24,37.24],[2,26,6.33],[3,27,3.25],[4,28,4.48],[5,29,1.88],[6,30,1.89],[8,34,2.06],[9,36,1.46]],"id":37947503},{"atb":[[1.52,36.67],[1.53,0],[1.05,0],[1.51,49.67],[1.49,42.53],[1.5,50.82],[1.46,15.55]],"atl":[[1000,14],[1.55,15.27],[1.53,4.38],[1.54,32.29],[1.56,20.94]],"trd":[[1.53,189.89]],"bdatb":[[0,1.52,50.15],[7,1.45,80.73],[8,1.44,46.17],[9,1.43,90.44],[1,1.51,98.27],[3,1.49,168.36],[4,1.48,104.38],[5,1.47,156.45],[6,1.46,29.09],[2,1.5,129.23]],"bdatl":[[2,1.55,15.27],[9,1.62,34.57],[0,1.53,4.38],[1,1.54,32.29],[3,1.56,20.94],[4,1.57,43.57],[5,1.58,63.48],[6,1.59,26.03],[7,1.6,41.61],[8,1.61,77.35]],"tv":2313.55,"id":39823721},{"bdatb":[[0,70,1.05],[1,65,5.42],[2,60,1.57],[3,55,4.51],[4,50,19.17],[5,48,2.49],[6,46,3.95],[7,44,4.37],[8,42,1.5],[9,40,1.47]],"id":44331354}],"con":true,"tv":3733.69}]}
{"op":"mcm","clk":"AOAPAKUOALAN","pt":1650392685438,"mc":[{"id":"1.197931750","rc":[{"atb":[[9,10.05],[8.8,18.86],[9.2,10.73]],"atl":[[9.8,9.68],[9.6,4.32],[9.4,0]],"trd":[[9.4,89.79]],"bdatb":[[3,8.6,9.84],[4,8.4,12.66],[7,7.8,10.4],[8,7.6,17.62],[9,7.4,4.05],[1,9,10.05],[5,8.2,13.15],[2,8.8,21.16],[6,8,5.02],[0,9.2,10.73]],"bdatl":[[4,11,12.43],[5,11.5,15.49],[6,12,13.77],[7,12.5,16.1],[8,13,4.5],[9,13.5,4.12],[1,9.8,9.68],[0,9.6,4.32],[2,10,28.49],[3,10.5,11.56]],"ltp":9.4,"tv":311.6,"id":42930960},{"atb":[[18.5,1.53],[18,10.2],[17,3.42],[19,0]],"atl":[[23,12.78],[19,5.71],[20,36.91],[22,11.15]],"trd":[[18.5,4.65],[19,9.13]],"bdatb":[[0,18.5,2.33],[1,18,10.2],[9,14,6.76],[3,17,3.42],[8,14.5,8.2],[4,16.5,5.26],[2,17.5,3.2],[5,16,3.1],[6,15.5,8.14],[7,15,3.34]],"bdatl":[[0,19,5.71],[1,19.5,7.99],[2,20,36.91],[3,21,19.04],[4,22,11.15],[5,23,6.87],[6,24,6.06],[7,25,7.01],[8,26,5.47],[9,27,4.25]],"ltp":18.5,"tv":219.87,"id":40095374},{"atb":[[5.6,7.23],[6.8,2.3],[7.2,20.14]],"atl":[[7.4,2.33],[7.6,10.04],[8.2,8.3],[7.8,48.63]],"bdatb":[[0,7.2,22.95],[1,7,44.84],[3,6.6,9.45],[9,5.6,2.08],[2,6.8,3.85]],"bdatl":[[3,8.2,12.57],[4,8.4,10.05],[5,8.6,9.3],[6,8.8,3.19],[7,9,6.78],[8,9.2,12.44],[9,9.4,3.2],[0,7.6,10.04],[2,8,23.62],[1,7.8,48.63]],"id":36276560},{"atb":[[20,8.93],[19.5,7.53],[19,4.14]],"atl":[[28,1.56],[25,2.46],[24,37.41],[26,11.25],[23,0]],"bdatb":[[2,20,9.94],[3,19.5,7.53],[5,18.5,3.33],[6,18,4.62],[9,16.5,4.42],[4,19,4.14],[8,17,7],[0,22,9.11]],"bdatl":[[8,34,3.09],[4,28,1.56],[0,24,37.41],[1,25,2.46],[7,32,1.87],[2,26,11.25]],"id":37947503},{"atb":[[1.53,22.86],[1.51,51.91],[1.49,42.53],[1.52,43.93],[1.48,22.68]],"atl":[[1.54,0],[1.56,30.03],[1.55,6.79],[1000,13],[1.53,0]],"trd":[[1.54,59.04],[1.53,217.19]],"bdatb":[[1,1.52,71.18],[2,1.51,96.33],[3,1.5,154.69],[4,1.49,147.81],[0,1.53,22.86],[6,1.47,156.59],[7,1.46,15.66],[8,1.45,57.46],[9,1.44,86.97],[5,1.48,104.68]],"bdatl":[[3,1.57,57.68],[4,1.58,58.43],[5,1.59,27.77],[6,1.6,17.03],[7,1.61,87.2],[8,1.62,8.84],[9,1.63,39.49],[2,1.56,30.03],[0,1.54,13.12],[1,1.55,6.79]],"ltp":1.54,"tv":2391.33,"id":39823721},{"atb":[[46,1.87],[44,1.39]],"bdatb":[[4,48,2.74],[6,44,1.39],[8,40,1.73],[9,38,1.06],[3,50,19.17],[0,65,6.37],[1,60,1.57],[2,55,4.41],[5,46,1.87],[7,42,1.5]],"id":44331354}],"con":true,"tv":3820.37}]}
{"op":"mcm","clk":"AIMRALkPAL4O","pt":1650392686440,"mc":[{"id":"1.197931750","rc":[{"atb":[[9.4,0.84],[9.2,15]],"atl":[[9.6,1.48],[9.8,8.38]],"trd":[[9.4,90.25]],"bdatb":[[0,9.2,15.84],[2,8.8,23.73],[3,8.6,12.28],[5,8.2,7.84],[6,8,12.21],[7,7.8,7.36],[8,7.6,20.3],[1,9,10.05],[4,8.4,12.66],[9,7.4,5.45]],"bdatl":[[7,12.5,17.28],[8,13,2.54],[9,13.5,6.95],[4,11,9.93],[5,11.5,17.89],[6,12,11.47],[0,9.6,3.08],[1,9.8,8.38]],"tv":312.06,"id":42930960},{"atb":[[18,7.88],[17.5,2.96],[11,6.48],[10.5,37.58],[10,28.88],[18.5,0],[17,4.25],[16.5,6.18],[15.5,1.46]],"atl":[[23,8.32],[1000,13.47],[21,15.89],[20,42.61],[19.5,7.99],[18.5,0],[19,6.29],[22,4.45]],"trd":[[18.5,8.05],[18,41.39]],"bdatb":[[0,18,7.88],[1,17.5,2.96],[3,16.5,7.97],[4,16,3.93],[5,15.5,1.46],[6,15,5.44],[7,14.5,7.46],[8,14,4.41],[9,13.5,6.76],[2,17,4.25]],"bdatl":[[5,23,8.32],[7,25,7.31],[8,26,4.13],[9,27,4.27],[2,20,42.61],[3,21,15.89],[0,19,6.29],[1,19.5,7.99],[4,22,4.45],[6,24,6.06]],"ltp":18.5,"tv":224.97,"id":40095374},{"atb":[[7.4,5.77],[7.2,50.03],[1.01,16618.35],[6.4,6.71],[6.8,18.63]],"atl":[[7.8,48.63],[7.4,0],[11.5,5.17],[8,10.61]],"bdatb":[[0,7.2,53],[1,7,46.74],[3,6.6,9.2],[4,6.4,9.14],[5,6.2,13.25],[6,6,10.02],[2,6.8,23.25],[7,5.9,2.71],[8,5.7,6],[9,5.6,7.23]],"bdatl":[[7,9,13.22],[8,9.2,3.92],[9,9.4,4.66],[0,7.6,10.04],[1,7.8,50.65],[2,8,10.61],[3,8.2,9.2],[4,8.4,9.14],[5,8.6,10.54],[6,8.8,2.84]],"id":36276560},{"atl":[[24,43.12]],"bdatb":[[0,22,9.11],[2,20,10.41],[3,19.5,8.21],[4,19,4.14],[6,18,6.37],[7,17.5,3.35],[9,16.5,2.43],[5,18.5,2.76],[8,17,6.37]],"bdatl":[[7,32,2.1],[9,36,1.46],[0,24,43.12],[8,34,2.06]],"id":37947503},{"atb":[[1.52,36.67],[1.53,0],[1.51,38.39],[1.08,0],[1.05,0],[1.46,11.2],[1.48,16.68]],"atl":[[1.53,20.82],[1.54,27.35],[1.55,20.95],[1.59,7.16],[1.56,38.97],[1.57,17.53],[1.58,10.94]],"trd":[[1.53,276.53],[1.54,59.24]],"bdatb":[[2,1.51,92.75],[0,1.53,4.84],[1,1.52,63.37],[3,1.5,159.93],[6,1.47,113.38],[7,1.46,54.71],[8,1.45,66.25],[9,1.44,66.98],[4,1.49,123.9],[5,1.48,98.68]],"bdatl":[[0,1.54,27.81],[4,1.58,60.99],[5,1.59,41.46],[6,1.6,50.96],[7,1.61,53.45],[8,1.62,31.05],[9,1.63,10.55],[2,1.56,38.97],[1,1.55,20.3],[3,1.57,60.08]],"ltp":1.53,"tv":2450.87,"id":39823721},{"atb":[[65,5.44]],"atl":[[75,7.97]],"bdatb":[[2,55,4.41],[4,48,2.94],[5,46,1.87],[7,42,1.82],[9,38,1.06],[1,60,1.57],[3,50,19.17],[8,40,1.47],[0,65,6.39]],"bdatl":[[0,75,14.02]],"id":44331354}],"con":true,"tv":3885.47}]}
{"op":"mcm","clk":"AK4SAMMQANQP","pt":1650392687441,"mc":[{"id":"1.197931750","rc":[{"atb":[[1.03,1],[9,23.77],[7.8,18.35],[9.2,5.92]],"atl":[[10.5,26.76],[10,7.87],[11,11.27]],"bdatb":[[0,9.4,2.01],[1,9.2,5.92],[2,9,24.52],[3,8.8,18.86],[4,8.6,13.63],[5,8.4,17.36],[6,8.2,7.6],[7,8,10.71],[8,7.8,18.35],[9,7.6,19.81]],"bdatl":[[3,10.5,26.76],[4,11,14.26],[5,11.5,15.15],[7,12.5,14.3],[8,13,2.51],[9,13.5,8.32],[6,12,11.35],[2,10,7.87],[0,9.6,1.48]],"id":42930960},{"atb":[[18,4.53],[17.5,7.83],[16.5,4.72],[15.5,9.11]],"atl":[[27,2.22],[20,16.84],[18.5,1.34],[19.5,35.22],[29,1.92],[23,4.03],[21,14],[32,2.4]],"trd":[[18,43.09]],"bdatb":[[0,18,5.38],[1,17.5,3.59],[2,17,4.25],[3,16.5,4.91],[4,16,4.45],[6,15,6.22],[8,14,5.51],[9,13.5,5.77],[5,15.5,9.11]],"bdatl":[[0,18.5,1.34],[1,19,6.29],[2,19.5,35.22],[3,20,17.36],[4,21,14],[5,22,4.45],[6,23,4.03],[7,24,6.06],[8,25,7.33],[9,26,5.09]],"ltp":18,"tv":226.67,"id":40095374},{"atb":[[7,60.14],[7.2,47.81],[7.4,8.22],[6,10.16]],"atl":[[8,12.21],[7.6,1.45],[7.8,50.57],[9.2,1.89],[9,4.78]],"bdatb":[[2,7,66.3],[1,7.2,50.8],[3,6.8,21.18],[4,6.6,9.63],[5,6.4,9.98],[6,6.2,7.6],[7,6,15.37],[0,7.4,10.14],[8,5.8,1.96],[9,5.7,8.81]],"bdatl":[[0,7.6,1.45],[5,8.6,5.75],[6,8.8,6.18],[8,9.2,4.15],[2,8,14.22],[7,9,5.27],[9,9.4,3.2],[1,7.8,50.57],[3,8.2,8.3],[4,8.4,10.02]],"id":36276560},{"atb":[[11.5,1.07],[2.06,1],[17.5,7.88],[18.5,5.25],[18,2.13]],"atl":[[29,2.88],[28,0.56]],"bdatb":[[0,22,9.59],[1,21,10.14],[2,20,9.46],[3,19.5,8.09],[6,18,4.52],[8,17,7.39],[7,17.5,7.88],[5,18.5,5.25],[9,16.5,2.31]],"bdatl":[[8,36,2.15],[4,29,3.44],[5,30,1.89],[6,32,1.87],[7,34,2.29],[9,38,1.46]],"id":37947503},{"atb":[[1.52,37.7],[1.46,173.59],[1.36,107.28],[1.51,36.15],[1.5,57.54]],"atl":[[1.54,28.16],[1.53,23.39],[1000,13],[1.55,25.45],[1.57,15.13],[1.56,30.03]],"trd":[[1.53,286.53]],"bdatb":[[4,1.48,50.8],[5,1.47,130.37],[8,1.44,62.53],[9,1.43,81.98],[0,1.52,28.95],[1,1.51,92.62],[3,1.49,197.18],[6,1.46,220.21],[7,1.45,63.12],[2,1.5,110.02]],"bdatl":[[0,1.53,23.39],[5,1.58,32.75],[6,1.59,72.3],[8,1.61,55.98],[9,1.62,34.95],[2,1.55,25.45],[7,1.6,46.16],[4,1.57,49.83],[1,1.54,28],[3,1.56,35.1]],"tv":2460.87,"id":39823721},{"atb":[[55,2.34]],"bdatb":[[0,65,6.56],[1,60,1.57],[3,50,19.23],[4,48,2.54],[6,44,1.64],[7,42,1.5],[9,38,2.2],[2,55,2.34]],"bdatl":[[0,75,7.97]],"id":44331354}],"con":true,"tv":3897.17}]}
{"op":"mcm","clk":"ANATAMgRANAQ","pt":1650392688443,"mc":[{"id":"1.197931750","rc":[{"atb":[[8.6,8.97],[1.03,0],[7.8,7.36]],"atl":[[15.5,4.22],[10,11.28]],"bdatb":[[4,8.6,16.04],[5,8.4,20.05],[6,8.2,8.39],[7,8,8.07],[8,7.8,7.36],[2,9,26.52]],"bdatl":[[2,10,11.28],[4,11,16.48],[5,11.5,13.03],[7,12.5,16.24],[8,13,1.8],[9,13.5,9.01]],"id":42930960},{"atb":[[15.5,3.96]],"atl":[[19,7.05],[19.5,38.42]],"bdatb":[[6,15,7.37],[7,14.5,7.48],[8,14,4.27],[9,13.5,9.22],[5,15.5,3.96],[0,18,4.53],[1,17.5,8.46]],"bdatl":[[1,19,7.05],[2,19.5,38.42],[3,20,16.84],[9,26,6.03]],"id":40095374},{"atb":[[7,47.69]],"atl":[[7.8,45.13]],"bdatb":[[2,7,56.33],[3,6.8,18.68],[4,6.6,12.75],[5,6.4,10.72],[6,6.2,8.94],[7,6,13.99]],"bdatl":[[1,7.8,45.13],[2,8,12.21],[5,8.6,8.58],[6,8.8,3.42],[8,9.2,3.49],[9,9.4,6.43]],"id":36276560},{"atb":[[12,16.65],[2.06,0],[17.5,3.35]],"bdatb":[[6,18,5.49],[7,17.5,3.37],[8,17,6.37]],"bdatl":[[8,36,2.83]],"id":37947503},{"atb":[[1.46,11.2]],"atl":[[1.54,39.51],[1.55,44.28],[1.56,16.46]],"bdatb":[[6,1.46,41.33],[7,1.45,65.64],[8,1.44,43.48],[9,1.43,115.74],[2,1.5,132.71],[3,1.49,145.88],[4,1.48,82.68],[5,1.47,107.23],[0,1.52,44.95]],"bdatl":[[1,1.54,39.51],[2,1.55,44.28],[3,1.56,21.53],[5,1.58,23.07],[6,1.59,93.34],[7,1.6,55.2],[8,1.61,70.9],[9,1.62,3.2]],"id":39823721},{"atl":[[75,5.67]],"bdatb":[[9,38,2.65]],"bdatl":[[0,75,5.67]],"id":44331354}],"con":true}]}
{"op":"mcm","clk":"AOUUANQSAMwR","pt":1650392689446,"mc":[{"id":"1.197931750","rc":[{"atb":[[9,23.77],[9.4,3.11],[9.2,3.65]],"atl":[[15.5,5.68]],"bdatb":[[2,9,26.94],[0,9.4,3.88],[5,8.4,20.83],[6,8.2,7.6],[1,9.2,3.65]],"bdatl":[[5,11.5,14.74],[6,12,11.81],[7,12.5,16.08],[4,11,15.75]],"id":42930960},{"atb":[[13,8.11]],"atl":[[22,8.94],[18.5,1.86],[19.5,37.9]],"bdatb":[[1,17.5,8.24],[3,16.5,5.14]],"bdatl":[[0,18.5,1.86],[5,22,8.94],[8,25,8.18],[9,26,4.9],[2,19.5,37.9]],"id":40095374},{"atb":[[7.4,11.35],[7.2,45.54]],"atl":[[7.8,43.19],[8,10.37],[7.6,0.95]],"trd":[[7.6,33.01]],"bdatb":[[0,7.4,13.27],[4,6.6,13.22],[5,6.4,10.23],[1,7.2,48.54]],"bdatl":[[0,7.8,44.14],[1,8,10.37],[5,8.8,3.94],[7,9.2,2.87],[8,9.4,8.04],[9,9.6,13.44],[2,8.2,8.3],[3,8.4,12.56],[4,8.6,6.74],[6,9,4.78]],"ltp":7.6,"tv":722.62,"id":36276560},{"atb":[[1.52,47.7]],"trd":[[1.52,53.88]],"bdatb":[[3,1.49,133.18],[4,1.48,72.73],[5,1.47,130.13],[6,1.46,66.97],[7,1.45,28.86],[8,1.44,48.51],[9,1.43,110.43],[0,1.52,52.45],[1,1.51,95.13]],"bdatl":[[4,1.57,48.45],[5,1.58,12.52],[6,1.59,91.78],[8,1.61,69.63],[9,1.62,5.49],[3,1.56,35.2]],"ltp":1.52,"tv":2470.49,"id":39823721},{"atb":[[70,0.71]],"atl":[[75,7.97]],"trd":[[70,9.66]],"bdatb":[[0,65,6.26],[3,50,19.31],[4,48,2.74],[6,44,1.43]],"bdatl":[[0,75,7.97]],"tv":72.05,"id":44331354},{"bdatb":[[0,22,9.42],[1,21,10.32],[2,20,9.94],[3,19.5,7.6]],"bdatl":[[7,34,2.92],[8,36,2.02],[9,38,1.81]],"id":37947503}],"con":true,"tv":3908.03}]}
{"op":"mcm","clk":"APwVANsTAOMS","pt":1650392690447,"mc":[{"id":"1.197931750","rc":[{"atb":[[9.4,5.22],[9.2,14.38],[9,21.94],[8.8,15.18],[6.8,1.46]],"atl":[[9.8,1.45],[9.6,0]],"trd":[[9.6,7.24]],"bdatb":[[0,9.4,6.91],[1,9.2,14.38],[2,9,27.96],[4,8.6,14.37],[5,8.4,20.83],[6,8.2,7.6],[8,7.8,10.4],[9,7.6,18.96],[3,8.8,15.18]],"bdatl":[[4,11.5,14.37],[5,12,18.19],[6,12.5,15.25],[8,13.5,7.12],[9,14,12.38],[0,9.8,1.45],[1,10,11.28],[2,10.5,26.76],[3,11,11.27],[7,13,1.8]],"ltp":9.6,"tv":313.28,"id":42930960},{"atb":[[18,4.95]],"atl":[[18.5,0.52],[19,34.28],[19.5,10.67]],"trd":[[18,45.03],[18.5,8.44]],"bdatb":[[0,18,4.95],[1,17.5,8.64],[3,16.5,4.82],[4,16,3.1],[5,15.5,7.45],[6,15,3.34],[7,14.5,10.66],[9,13.5,4.91]],"bdatl":[[7,25,7.77],[0,19,34.8],[1,19.5,10.67],[2,20,16.84],[3,21,14],[4,22,8.94],[5,23,4.03],[6,24,6.06],[8,26,4.13],[9,27,2.22]],"ltp":18,"tv":229,"id":40095374},{"atb":[[7.6,14.08],[7.4,41.42],[7.2,33.01],[6.8,2.3]],"atl":[[7.8,39.2],[8,12.37],[9.8,2.53],[7.6,0]],"trd":[[7.6,33.96]],"bdatb":[[0,7.6,15.35],[3,7,47.69],[4,6.8,9.13],[5,6.6,3.93],[6,6.4,19.82],[1,7.4,42.27],[2,7.2,40.53],[7,6.2,9.85],[8,6,13.04],[9,5.9,1.93]],"bdatl":[[5,8.8,4.99],[6,9,8.13],[7,9.2,1.93],[8,9.4,12.8],[0,7.8,39.2],[9,9.6,5.8],[1,8,12.37],[3,8.4,9.08],[4,8.6,2.83]],"tv":723.57,"id":36276560},{"atl":[[24,42.82]],"trd":[[24,1.13]],"bdatb":[[0,22,9.55],[1,21,10.21],[2,20,9.02],[3,19.5,7.53],[4,19,6.99],[6,18,2.13],[7,17.5,6.01]],"bdatl":[[7,34,2.62],[9,38,1.46],[0,24,42.82],[8,36,1.46]],"ltp":24,"tv":104.44,"id":37947503},{"atb":[[1.51,12.55],[1.5,80.44],[1.52,0]],"atl":[[1.53,35.4],[1.54,30.16],[1.52,10.46]],"trd":[[1.52,122.05]],"bdatb":[[0,1.51,21.94],[2,1.49,162.55],[3,1.48,85.67],[4,1.47,131.5],[5,1.46,51.61],[6,1.45,39.22],[7,1.44,50.08],[9,1.42,33.65],[1,1.5,155.61],[8,1.43,110.43]],"bdatl":[[3,1.55,75.93],[4,1.56,53.61],[5,1.57,62.48],[6,1.58,39.28],[7,1.59,101.62],[8,1.6,26.67],[9,1.61,6.55],[1,1.53,35.4],[2,1.54,30.16],[0,1.52,10.46]],"tv":2538.66,"id":39823721},{"atb":[[1.05,2.9],[1.5,2]],"atl":[[75,7.88]],"trd":[[75,34.45]],"bdatb":[[0,65,6.15],[1,60,1.73],[2,55,2.42],[3,50,19.2],[6,44,1.39],[8,40,2.82],[9,38,1.06],[4,48,2.32]],"bdatl":[[0,75,7.88]],"ltp":75,"tv":72.15,"id":44331354}],"con":true,"tv":3981.1}]}
{"op":"mcm","clk":"AKYXAOAUAPkT","pt":1650392691448,"mc":[{"id":"1.197931750","rc":[{"atb":[[9.2,3.76],[6,3.23],[9.6,1.48],[9.4,8.62],[9,14.69]],"atl":[[9.8,0.32],[10.5,15.61],[10,4.68],[11,34.91],[11.5,14.73]],"trd":[[9.8,3.71],[10,0.18]],"bdatb":[[0,9.6,1.48],[1,9.4,11.87],[2,9.2,12.84],[3,9,24.36],[4,8.8,15.7],[5,8.6,17.48],[6,8.4,17.36],[7,8.2,7.6],[8,8,6.3],[9,7.8,10.4]],"bdatl":[[0,10,4.68],[1,10.5,15.61],[7,13.5,8.44],[8,14,12.54],[9,14.5,2.92],[2,11,34.91],[4,12,17.98],[5,12.5,12.98],[3,11.5,16.38],[6,13,1.8]],"ltp":10,"tv":317.01,"id":42930960},{"atb":[[15.5,5.57],[18,2.8]],"atl":[[18.5,7.17],[1000,13.47],[24,10.21],[19.5,10],[20,21.27],[26,2],[25,5],[23,1.98]],"trd":[[18,46.55]],"bdatb":[[5,15.5,6.62],[7,14.5,12.33],[0,18,2.8],[1,17.5,7.83],[3,16.5,6.57],[9,13.5,9.9]],"bdatl":[[7,24,10.8],[8,25,5.19],[2,19.5,10],[3,20,21.27],[0,18.5,6.6],[6,23,1.98],[9,26,2],[1,19,34.28],[4,21,14],[5,22,8.94]],"tv":230.52,"id":40095374},{"atb":[[7.4,11.92],[1.01,16618.35],[7.6,13.75],[5.7,0]],"atl":[[8,10.42],[7.8,37.23],[8.6,4.29]],"trd":[[7.8,66.4],[7.6,37.26]],"bdatb":[[2,7.2,35.27],[3,7,57.79],[6,6.4,9.12],[7,6.2,11.75],[0,7.6,13.75],[8,6,14.12],[1,7.4,45.54],[9,5.9,2.93],[4,6.8,2.98],[5,6.6,13.44]],"bdatl":[[1,8,10.42],[4,8.6,5.93],[5,8.8,3.38],[6,9,8.27],[7,9.2,6.76],[8,9.4,4.64],[0,7.8,37.23]],"ltp":7.8,"tv":730.81,"id":36276560},{"atb":[[22,7.46]],"atl":[[29,2.95],[1000,13.49]],"trd":[[22,26.81]],"bdatb":[[0,22,7.46],[3,19.5,8.37],[7,17.5,7.39],[1,21,11.44],[9,16.5,2.59],[6,18,2.13],[4,19,4.14],[2,20,8.93]],"bdatl":[[4,29,3.51],[6,32,2.31],[7,34,2.2]],"ltp":22,"tv":107.74,"id":37947503},{"atb":[[1.49,55.97],[1.5,59.89],[1.48,26.26]],"atl":[[1.53,45.52],[1.52,20.06],[1.54,50.52],[1.55,25.45],[1.56,7.37]],"bdatb":[[1,1.5,91.11],[2,1.49,166],[3,1.48,80.07],[4,1.47,190.34],[7,1.44,43.02],[8,1.43,100.05],[0,1.51,12.55],[5,1.46,63.44],[6,1.45,53.19],[9,1.42,80.43]],"bdatl":[[5,1.57,67.94],[6,1.58,56.71],[8,1.6,31.38],[9,1.61,23.05],[3,1.55,57.97],[4,1.56,42.05],[7,1.59,57.45],[0,1.52,20.06],[1,1.53,56.87],[2,1.54,50.52]],"id":39823721},{"atb":[[70,2.1],[65,3.44],[60,3.79],[46,1.91],[1.5,0],[1.05,1.24]],"atl":[[75,7.66]],"trd":[[70,15.16],[75,34.89]],"bdatb":[[1,65,3.44],[7,44,1.77],[2,60,3.79],[3,55,2.89],[0,70,4.85],[6,46,1.91],[9,40,1.47],[4,50,19.17],[5,48,2.32],[8,42,1.5]],"bdatl":[[0,75,7.66]],"ltp":70,"tv":78.09,"id":44331354}],"con":true,"tv":4002.83}]}
{"op":"mcm","clk":"AL0YAOoVAPoU","pt":1650392692449,"mc":[{"id":"1.197931750","rc":[{"atb":[[9.4,21.27],[9.2,10.32],[9.6,4.07],[9,12.05]],"atl":[[10,0],[12,14.33],[11,34.9],[10.5,12.8],[11.5,16.9],[9.8,0]],"trd":[[10,4.09],[9.8,4.03]],"bdatb":[[4,9,14.97],[5,8.8,16.02],[6,8.6,17.15],[0,9.8,3.37],[1,9.6,4.07],[2,9.4,22.27],[3,9.2,8.3],[7,8.4,17.36],[8,8.2,7.6],[9,8,6.3]],"bdatl":[[0,10.5,16.15],[7,14,12.65],[9,15,8.21],[1,11,32.9],[2,11.5,16.9],[3,12,15.22],[4,12.5,15.77],[5,13,1.8],[6,13.5,5.32],[8,14.5,2.92]],"tv":321.24,"id":42930960},{"atl":[[18.5,4.89],[23,3.44],[60,0],[44,19.33],[19.5,14.72],[20,13.88]],"trd":[[18.5,10.72]],"bdatb":[[7,14.5,9.27],[3,16.5,6.72],[5,15.5,5.57],[6,15,5.23],[9,13.5,9.9],[1,17.5,7.83]],"bdatl":[[6,23,3.44],[0,18.5,5.14],[3,20,13.88],[7,24,10.21],[8,25,5],[2,19.5,14.72]],"ltp":18.5,"tv":232.8,"id":40095374},{"atb":[[7.4,0],[6.8,4.39],[6,10.16],[7.2,12.06],[7.6,0]],"atl":[[7.8,31.85],[7.6,10.97],[11.5,17.37],[7.4,8.62],[16,2.92],[8,13.06]],"trd":[[7.4,83.89],[7.8,84.07],[7.6,127.72],[7.2,20.78]],"bdatb":[[2,7,55.49],[3,6.8,3.39],[4,6.6,13.01],[5,6.4,7.37],[6,6.2,13.56],[0,7.4,8.64],[1,7.2,9.67],[7,6,12.08],[8,5.9,2.93],[9,5.7,2]],"bdatl":[[8,9.2,9.25],[0,7.6,8.07],[1,7.8,29.85],[2,8,12.82],[3,8.2,8.3],[4,8.4,9.08],[5,8.6,7.17],[6,8.8,2.84],[7,9,6.37],[9,9.4,3.2]],"ltp":7.4,"tv":920.54,"id":36276560},{"atb":[[20,8.93],[22,9.24],[21,12.81]],"atl":[[24,47.31]],"trd":[[24,2.89],[22,38.81]],"bdatb":[[7,17.5,4.85],[9,16.5,2.76],[0,22,9.24],[2,20,8.58],[3,19.5,7.53],[4,19,5.63],[1,21,12.81]],"bdatl":[[0,24,47.51],[9,38,2.11],[6,32,1.87],[7,34,2.06]],"ltp":24,"tv":121.5,"id":37947503},{"atb":[[1.52,0],[1.51,31.62],[1.5,56.67],[1.49,55.3],[1.47,37.46],[1.46,63.09]],"atl":[[1000,13.48],[1.54,48.52],[1.52,3.27],[1.53,35.68]],"trd":[[1.52,173.14],[1.51,122.28]],"bdatb":[[1,1.5,95.57],[2,1.49,125.96],[3,1.48,110.42],[5,1.46,108.81],[6,1.45,17.09],[7,1.44,75.68],[9,1.42,64.12],[0,1.51,16.39],[4,1.47,153.52],[8,1.43,110.43]],"bdatl":[[1,1.53,35.68],[0,1.52,21.72],[4,1.56,39.68],[5,1.57,23.75],[6,1.58,34.09],[7,1.59,82.35],[8,1.6,34.8],[9,1.61,48.37],[3,1.55,25.45]],"tv":2631.19,"id":39823721},{"atb":[[55,0.28],[60,1.55],[65,3.42],[1.05,1.24],[70,0]],"atl":[[75,6.75]],"trd":[[75,36.13]],"bdatb":[[0,65,3.44],[1,60,3.79],[2,55,2.34],[3,50,19.83],[4,48,2.32],[5,46,1.91],[6,44,1.39],[7,42,1.5],[8,40,2.18],[9,38,1.06]],"bdatl":[[0,75,7.16]],"ltp":75,"tv":79.33,"id":44331354}],"con":true,"tv":4306.6}]}
{"op":"mcm","clk":"AM0ZAOEWAJAW","pt":1650392693450,"mc":[{"id":"1.197931750","rc":[{"atb":[[9.4,21.27],[7.8,6.7],[8.8,13.18],[9.8,4.73],[2.06,1],[9.6,4.07]],"atl":[[11,12.19],[10.5,15.67]],"bdatb":[[0,9.8,4.73],[1,9.6,6.08],[2,9.4,25.65],[5,8.8,13.18],[6,8.6,11.29],[7,8.4,14.56],[3,9.2,10.32],[4,9,16.21],[8,8.2,7.6],[9,8,6.3]],"bdatl":[[3,12,16.3],[4,12.5,17.59],[6,13.5,3.63],[7,14,18.5],[8,14.5,3.19],[1,11,12.19],[0,10.5,15.67],[9,15,2.92]],"id":42930960},{"atl":[[21,20.48],[19,7.05],[25,0.58],[19.5,12.04],[18.5,6.2]],"bdatb":[[9,13.5,5.61],[7,14.5,10.04],[4,16,4.31],[6,15,6.09],[3,16.5,4.72]],"bdatl":[[1,19,7.05],[8,25,1.53],[9,26,2],[0,18.5,6.2],[2,19.5,12.04]],"id":40095374},{"atb":[[7.2,13.79],[6.6,4.5],[6.8,2.3]],"atl":[[7.8,36.35],[7.4,8.85],[7.6,12.97],[9.8,3.99],[8,23.94]],"trd":[[7.4,85.02]],"bdatb":[[0,7.2,13.79],[2,6.8,7.8],[3,6.6,7.04],[5,6.2,9.12],[6,6,10.92],[4,6.4,11.5],[1,7,56.33],[7,5.9,2.93],[8,5.7,2],[9,5.6,10.08]],"bdatl":[[4,8.2,11.18],[5,8.4,11.79],[8,9,4.8],[9,9.2,12.96],[1,7.6,12.97],[6,8.6,4.76],[7,8.8,6.81],[3,8,23.94],[0,7.4,2.61],[2,7.8,33.87]],"tv":921.67,"id":36276560},{"atb":[[21,15.57]],"atl":[[24,53.82],[26,6.33]],"bdatb":[[7,17.5,5.49],[8,17,6.37],[2,20,9.89],[4,19,6.31],[5,18.5,5.25],[9,16.5,2.31]],"bdatl":[[7,34,2.75],[8,36,1.46],[2,26,6.33],[0,24,47.31],[9,38,1.46]],"id":37947503},{"atb":[[1.52,15.54],[1.48,16.68],[1.51,41.01],[1.5,70.56],[1.49,52.86]],"atl":[[1.54,24.29],[1.55,23.15],[1000,13],[1.53,39.55],[1.52,0]],"trd":[[1.52,180.64]],"bdatb":[[0,1.52,15.54],[7,1.45,66.11],[8,1.44,79.98],[9,1.43,121.52],[6,1.46,139.07],[1,1.51,53.81],[2,1.5,136.26],[3,1.49,84.17],[4,1.48,107.26],[5,1.47,94.24]],"bdatl":[[4,1.57,39.98],[5,1.58,19.75],[6,1.59,108.07],[3,1.56,37.08],[7,1.6,25.98],[9,1.62,4.27],[8,1.61,58.97],[1,1.54,24.29],[2,1.55,23.15],[0,1.53,39.55]],"tv":2638.69,"id":39823721},{"atb":[[60,3.55],[65,5.42]],"atl":[[70,2.3],[75,4.45]],"bdatb":[[3,48,2.72],[7,40,2.5],[2,50,19.45],[4,46,1.91],[5,44,1.39],[6,42,1.5],[8,38,1.06],[9,36,22.5],[0,65,5.42],[1,60,1.55]],"bdatl":[[0,75,4.45]],"id":44331354}],"con":true,"tv":4315.23}]}
{"op":"mcm","clk":"AOgaAOcXAMkX","pt":1650392694451,"mc":[{"id":"1.197931750","rc":[{"atb":[[9.4,15.6],[8,5.5],[9.8,5.76],[2.06,0],[7.8,12.7]],"atl":[[11,18.84],[10.5,13.1]],"bdatb":[[1,9.6,4.07],[2,9.4,15.6],[3,9.2,10.32],[4,9,18.77],[6,8.6,13.32],[7,8.4,16.93],[9,8,6.94],[8,8.2,7.6],[0,9.8,5.76],[5,8.8,13.18]],"bdatl":[[0,10.5,14.14],[1,11,19.99],[2,11.5,20.15],[3,12,14.33],[4,12.5,14.61],[6,13.5,8.05],[7,14,15.77],[5,13,1.9],[9,15,3.13],[8,14.5,2.92]],"id":42930960},{"atb":[[18,4.22],[18.5,0.59]],"atl":[[19,9.06],[26,11.43],[19.5,7.99],[25,2.04],[20,13.2],[18.5,0]],"trd":[[18.5,11.96]],"bdatb":[[3,16.5,4.72],[5,15.5,5.57],[7,14.5,11.63],[8,14,6.94],[9,13.5,4.14],[0,18,4.81],[4,16,3.1],[6,15,3.34]],"bdatl":[[3,21,21.61],[6,24,11.58],[7,25,2.22],[0,19,9.06],[1,19.5,7.99],[8,26,11.43],[2,20,13.2],[4,22,8.94],[5,23,3.44],[9,27,2.22]],"tv":234.04,"id":40095374},{"atb":[[5.6,13.23],[7.6,8.02]],"atl":[[7.6,0],[7.4,0],[7.8,46.73],[8,13.06]],"trd":[[7.6,153.66],[7.4,105.44]],"bdatb":[[0,7.6,8.02],[1,7.2,13.79],[2,7,56.33],[3,6.8,7.8],[4,6.6,9.94],[5,6.4,7.3],[6,6.2,7.27],[7,6,14.12],[8,5.8,2.97],[9,5.7,2]],"bdatl":[[0,7.8,46.73],[1,8,14.42],[2,8.2,9.85],[3,8.4,12.99],[4,8.6,7.67],[5,8.8,2.84],[6,9,5.88],[7,9.2,14.37],[8,9.4,3.2],[9,9.6,6.13]],"ltp":7.6,"tv":968.03,"id":36276560},{"atb":[[22,9.7]],"bdatb":[[2,20,8.93],[5,18.5,5.25],[7,17.5,6.81],[9,16.5,4.58],[4,19,4.14],[6,18,2.13],[0,22,9.7],[1,21,15.57]],"bdatl":[[2,26,6.75],[3,27,3.72],[6,32,2.89],[7,34,2.19],[0,24,53.82]],"id":37947503},{"atb":[[1.52,0],[1.47,89.35],[1.46,11.2],[1.5,83.14],[1.49,41.86]],"trd":[[1.52,211.72]],"bdatb":[[1,1.51,41.01],[2,1.5,83.14],[3,1.49,134.19],[4,1.48,105.8],[5,1.47,140.57],[6,1.46,86.23],[7,1.45,67.55],[8,1.44,34.23],[9,1.43,119.99]],"bdatl":[[1,1.54,60.94],[2,1.55,26.06],[3,1.56,7.37],[4,1.57,37.11],[5,1.58,51.95],[6,1.59,58.62],[7,1.6,43.83],[8,1.61,48.37],[9,1.62,30.6]],"tv":2669.77,"id":39823721},{"atb":[[55,2.08],[50,19.45]],"atl":[[95,2.01],[85,0.16],[80,1.36],[75,0],[90,2.07]],"bdatb":[[5,46,1.91],[9,38,1.06],[2,55,2.08],[3,50,19.45],[4,48,2.32],[8,40,1.47],[6,44,1.39],[7,42,1.5],[1,60,3.55]],"bdatl":[[5,190,4.63],[1,80,1.36],[2,85,2.17],[3,90,2.07],[4,100,2.61],[6,200,2.39],[7,230,1.25],[8,260,1.19],[9,270,2.28],[0,70,2.3]],"id":44331354}],"con":true,"tv":4393.91}]}
{"op":"mcm","clk":"AIMcAOsYANQY","pt":1650392695452,"mc":[{"id":"1.197931750","rc":[{"atb":[[9.4,4.26],[9,11.92],[9.2,6.31],[9.8,0],[9.6,0]],"atl":[[9.8,1.85],[10.5,12.56],[10,4.93],[11,22.31]],"trd":[[9.4,131.51],[9.8,15.55],[9.6,15.38]],"bdatb":[[0,9.4,4.86],[1,9.2,6.31],[2,9,17.76],[4,8.6,13.16],[5,8.4,14.23],[3,8.8,13.18],[6,8.2,7.6],[7,8,6.94],[8,7.8,15.74],[9,7.6,16.68]],"bdatl":[[0,9.8,1.85],[1,10,4.93],[2,10.5,12.56],[3,11,24.85],[4,11.5,17.54],[5,12,19.6],[6,12.5,13.89],[7,13,1.8],[8,13.5,10.16],[9,14,12.2]],"ltp":9.4,"tv":382.16,"id":42930960},{"atb":[[18.5,1.91],[14.5,1.46]],"atl":[[19,8.28]],"trd":[[19,9.91]],"bdatb":[[0,18.5,1.91],[1,18,4.22],[2,17.5,8.87],[3,17,4.25],[4,16.5,6.39],[5,16,3.1],[6,15.5,6.97],[7,15,3.34],[8,14.5,2.54],[9,14,4.27]],"bdatl":[[9,27,3.26],[0,19,8.28],[8,26,11.43],[6,24,10.21],[7,25,2.04],[3,21,20.48]],"ltp":19,"tv":234.82,"id":40095374},{"atb":[[1.01,16618.92],[7,51.33],[7.2,14.15],[7.4,15.43],[6.6,2.35],[7.6,0]],"atl":[[7.6,15.67],[8.6,7.86],[7.8,45.96],[8,26.33],[8.2,10.03]],"trd":[[7.6,171.65]],"bdatb":[[1,7.2,20.49],[2,7,54.44],[3,6.8,4.6],[4,6.6,9.81],[5,6.4,8.51],[6,6.2,9.85],[7,6,13.04],[8,5.9,1.93],[9,5.6,16.08],[0,7.4,15.43]],"bdatl":[[5,8.6,11.11],[6,8.8,3.67],[7,9,7.3],[8,9.2,6.29],[0,7.6,15.67],[4,8.4,9.08],[1,7.8,45.96],[2,8,26.33],[3,8.2,10.03],[9,9.4,3.2]],"tv":986.02,"id":36276560},{"atb":[[22,9.24]],"atl":[[24,53.2]],"trd":[[24,3.51]],"bdatb":[[1,21,16.43],[2,20,10.31],[4,19,5.28],[5,18.5,5.25],[7,17.5,4.25],[0,22,9.24],[9,16.5,2.31]],"bdatl":[[8,36,2.24],[0,24,53.2],[7,34,2.06],[9,38,1.46],[4,29,3.51],[6,32,1.87],[2,26,6.33],[3,27,3.25]],"tv":122.12,"id":37947503},{"atb":[[1.52,0],[1.04,1],[1.46,63.09],[1.47,37.46],[1.48,26.51],[1.51,46.71],[1.5,81.14]],"atl":[[1.53,29.84],[1.55,31.76]],"trd":[[1.52,248.58],[1.53,296.24]],"bdatb":[[0,1.52,30.36],[1,1.51,79.35],[2,1.5,115.59],[3,1.49,95.7],[4,1.48,192.29],[5,1.47,59.81],[6,1.46,131.29],[7,1.45,53.26],[8,1.44,123.94],[9,1.43,97.16]],"bdatl":[[0,1.53,29.84],[3,1.56,30.02],[5,1.58,12.77],[8,1.61,49.91],[9,1.62,14.96],[2,1.55,31.76],[4,1.57,63.51],[6,1.59,63.2],[7,1.6,17.98],[1,1.54,24.29]],"ltp":1.52,"tv":2716.34,"id":39823721},{"atb":[[60,3.57]],"atl":[[1000,13.02],[70,7.76],[85,2.17],[80,3.36],[90,0]],"trd":[[70,15.37]],"bdatb":[[3,50,19.82],[4,48,2.89],[8,40,2.01],[9,38,1.06],[1,60,3.57]],"bdatl":[[0,70,7.76],[1,80,3.36],[2,85,2.17],[3,95,2.01],[4,100,2.61],[5,190,4.45],[6,200,2.39],[7,230,1.25],[8,260,1.19],[9,270,2.28]],"ltp":70,"tv":79.54,"id":44331354}],"con":true,"tv":4521}]}
{"op":"mcm","clk":"AJsdAPEZAOAZ","pt":1650392696454,"mc":[{"id":"1.197931750","rc":[{"atb":[[9,11.92],[9.4,0],[9.2,5.85],[8.4,12.66],[8.2,5.58]],"atl":[[9.6,7.34],[12,13.15],[10,7.04],[10.5,11.71],[9.8,7.36],[11,24.32]],"bdatb":[[2,9,16.08],[5,8.4,16.01],[6,8.2,5.93],[0,9.4,6.75],[1,9.2,5.85],[4,8.6,11.09]],"bdatl":[[0,9.6,7.34],[4,11,27.78],[5,11.5,20.8],[6,12,16.11],[7,12.5,12.65],[8,13,4.9],[2,10,7.04],[9,13.5,7.16],[3,10.5,11.71],[1,9.8,7.36]],"id":42930960},{"atb":[[10,26.88],[17.5,9.85],[18.5,4.48]],"atl":[[19,7.75],[19.5,6.64]],"trd":[[18.5,15.16]],"bdatb":[[4,16.5,5.14],[5,16,5],[8,14.5,3.08],[9,14,4.81],[1,18,7.75],[7,15,4.55],[2,17.5,9.85],[0,18.5,4.48],[6,15.5,5.57]],"bdatl":[[0,19,7.75],[9,27,3.63],[8,26,11.43],[1,19.5,6.64]],"ltp":18.5,"tv":238.02,"id":40095374},{"atb":[[7,51.33],[7.4,16],[1.01,16618.35]],"atl":[[7.8,35.58]],"bdatb":[[1,7.2,15.12],[2,7,55.68],[3,6.8,9.12],[4,6.6,2.79],[5,6.4,12.22],[7,6,11.87],[8,5.7,3],[0,7.4,24.58],[6,6.2,8.81],[9,5.6,13.23]],"bdatl":[[5,8.6,12.28],[6,8.8,4.63],[8,9.2,5.76],[4,8.4,9.08],[7,9,8.01],[9,9.4,3.2],[1,7.8,35.58]],"id":36276560},{"atb":[[22,9.7]],"bdatb":[[2,20,9.28],[3,19.5,9.09],[8,17,7.75],[9,16.5,2.59],[0,22,12.59],[6,18,3.14],[1,21,15.57],[7,17.5,3.35],[4,19,4.14]],"bdatl":[[8,36,2.52],[7,34,2.06],[9,38,1.46]],"id":37947503},{"atb":[[1.5,83.14],[1.52,25.04],[1.51,53.25],[1.04,0]],"atl":[[1000,14],[1.53,41.5]],"trd":[[1.52,286.14]],"bdatb":[[2,1.5,130.06],[0,1.52,103.39],[1,1.51,68.79],[4,1.48,67.53],[5,1.47,135.48],[6,1.46,106],[7,1.45,69.93],[9,1.43,90.55],[8,1.44,85.69],[3,1.49,124.38]],"bdatl":[[8,1.61,35.3],[0,1.53,41.5],[3,1.56,41.89],[4,1.57,56.23],[6,1.59,41.47],[7,1.6,14.28],[9,1.62,47.62],[5,1.58,36.55]],"tv":2753.9,"id":39823721},{"atb":[[1.05,1.24]],"atl":[[70,7.41],[95,2.03],[170,0.46],[1000,13]],"trd":[[70,16.09]],"bdatb":[[4,48,2.47],[7,42,2.23],[1,60,4.63],[3,50,19.45],[8,40,1.47]],"bdatl":[[0,70,7.41],[3,95,2.03],[5,190,4.9]],"tv":80.26,"id":44331354}],"con":true,"tv":4562.48}]}
{"op":"mcm","clk":"AMgeAOcaAPEa","pt":1650392697455,"mc":[{"id":"1.197931750","rc":[{"atb":[[9.2,9.85],[9.6,2.76],[9.4,16.85],[9,15.93],[7.6,10]],"atl":[[9.8,7.1],[10,8.03],[9.6,0],[10.5,15.7]],"trd":[[9.6,22.26],[9.4,134.11]],"bdatb":[[0,9.6,2.99],[1,9.4,16.85],[2,9.2,7.85],[3,9,15.93],[4,8.8,17.37],[5,8.6,11.96],[6,8.4,12.66],[7,8.2,8.47],[8,8,7.66],[9,7.8,12.7]],"bdatl":[[4,11.5,21.65],[5,12,17.77],[6,12.5,15.29],[7,13,4.61],[9,14,16.89],[0,9.8,6.01],[1,10,7.93],[2,10.5,15.7],[3,11,24.32],[8,13.5,2.62]],"ltp":9.6,"tv":391.64,"id":42930960},{"atb":[[17,2.25],[16,5.16],[18,1.95],[17.5,7.89],[10,28.96],[18.5,0]],"atl":[[18.5,4.06],[19,38.84],[19.5,7.89]],"trd":[[18,48.25],[19,11.9],[18.5,16.46]],"bdatb":[[0,18,1.95],[1,17.5,7.89],[2,17,4.25],[4,16,3.1],[5,15.5,7.95],[6,15,3.34],[7,14.5,3.23],[8,14,4.27],[9,13.5,5.9],[3,16.5,4.72]],"bdatl":[[8,26,12.42],[5,23,3.44],[6,24,11.41],[0,19,38.84],[1,19.5,7.89],[9,27,2.22]],"ltp":18,"tv":243.01,"id":40095374},{"atb":[[7.6,0],[7.4,72.4],[6.8,4.39],[7.2,12.18]],"atl":[[7.8,38.54],[8.2,11.77],[8,24.32],[7.6,0],[9.2,3.35]],"trd":[[7.6,197.76]],"bdatb":[[0,7.4,72.4],[1,7.2,17.31],[2,7,54.47],[3,6.8,4.93],[4,6.6,5.95],[5,6.4,9.41],[6,6.2,10.44],[7,6,10.16],[8,5.8,1.02],[9,5.6,13.45]],"bdatl":[[4,8.6,10.13],[7,9.2,6.96],[8,9.4,6.39],[9,9.6,6.49],[0,7.8,38.54],[1,8,24.32],[2,8.2,11.77],[3,8.4,13.26],[6,9,10.93],[5,8.8,2.84]],"tv":1012.13,"id":36276560},{"atb":[[20,3.36],[21,0],[19.5,9.56],[19,4.14],[18.5,8.07],[18,4.17],[22,0]],"atl":[[23,21.29],[24,47.84],[21,6.52],[25,4.46],[22,6.82],[20,0],[26,10.16]],"trd":[[21,51.03],[20,41.7],[22,58.21]],"bdatb":[[0,20,7.16],[1,19.5,9.56],[2,19,4.14],[3,18.5,8.07],[6,17,8.54],[8,16,2.83],[9,15.5,1.7],[4,18,4.17],[5,17.5,3.35],[7,16.5,2.31]],"bdatl":[[0,21,6.52],[1,22,6.82],[2,23,6.48],[3,24,47.84],[4,25,4.46],[5,26,10.16],[6,27,3.25],[7,28,1.59],[8,29,2.95],[9,30,2.1]],"ltp":21,"tv":214.75,"id":37947503},{"atb":[[1.53,35.69],[1.52,36.44],[1.05,0],[1.51,46.22]],"atl":[[1.56,14.29],[1000,13],[1.54,0],[1.55,23.81],[1.53,0]],"trd":[[1.53,371.97],[1.54,83.77],[1.52,293.87]],"bdatb":[[0,1.53,35.69],[1,1.52,126.52],[2,1.51,47.05],[3,1.5,191.44],[4,1.49,43.47],[5,1.48,129.63],[6,1.47,64.37],[7,1.46,129.2],[9,1.44,81.31],[8,1.45,63.12]],"bdatl":[[6,1.61,30.79],[7,1.62,21.79],[8,1.63,67.74],[0,1.55,23.81],[1,1.56,16.46],[2,1.57,37.48],[3,1.58,107.16],[4,1.59,43.87],[5,1.6,58.67],[9,1.64,43.03]],"ltp":1.53,"tv":2861.89,"id":39823721},{"atb":[[1.05,1.24]],"atl":[[70,6.51],[360,1.23],[370,0.23],[180,0.43]],"trd":[[70,17.34]],"bdatb":[[4,48,2.32],[6,44,1.39],[8,40,2.39],[2,55,2.08],[5,46,1.91],[7,42,1.5],[1,60,3.57],[3,50,19.45]],"bdatl":[[6,190,4],[0,70,6.51],[5,180,1.33],[7,200,2.39],[8,230,1.25],[9,260,1.19]],"tv":81.51,"id":44331354}],"con":true,"tv":4804.93}]}
{"op":"mcm","clk":"ANofANYbAIYc","pt":1650392698457,"mc":[{"id":"1.197931750","rc":[{"atb":[[9.2,17.75],[9.4,20.26]],"atl":[[10.5,17.78],[9.8,1.19],[10,7.93]],"bdatb":[[6,8.4,15.49],[7,8.2,5.58],[9,7.8,13.27],[2,9.2,18.41],[5,8.6,16.44],[1,9.4,20.26],[0,9.6,2.76],[3,9,20.03],[4,8.8,13.18]],"bdatl":[[3,11,24.32],[4,11.5,21.65],[5,12,15.65],[6,12.5,14.99],[9,14,12.31],[7,13,9.75],[2,10.5,17.78],[1,10,7.93],[0,9.8,1.19]],"id":42930960},{"atb":[[16.5,3.01],[17,6.83],[18,0]],"atl":[[23,3.44],[18.5,8.26],[19,37.14],[19.5,9.9]],"trd":[[18,51.25]],"bdatb":[[2,16.5,3.01],[1,17,7.19],[8,13.5,5.35],[3,16,5.16],[7,14,4.27],[9,13,8.11],[0,17.5,7.89],[4,15.5,5.93],[5,15,5.43],[6,14.5,4.76]],"bdatl":[[0,18.5,8.26],[6,23,3.44],[7,24,11.31],[9,26,12.51],[2,19.5,9.9],[1,19,37.14],[3,20,13.2],[4,21,20.48],[5,22,8.94],[8,25,2.04]],"tv":246.01,"id":40095374},{"atb":[[7.6,0],[6.8,2.3],[7,53.36]],"atl":[[7.8,32.33],[8.2,21.66]],"trd":[[7.6,204.9]],"bdatb":[[0,7.4,73.22],[1,7.2,17.31],[2,7,53.36],[3,6.8,9.35],[4,6.6,4.83],[5,6.4,13.12],[6,6.2,6.74],[7,6,13.98],[8,5.6,14.89],[9,5.5,61.93]],"bdatl":[[7,9.2,3.35],[8,9.4,5.76],[3,8.4,12.23],[4,8.6,11.13],[0,7.8,33.58],[2,8.2,23.4],[6,9,11.38],[9,9.6,14.01]],"tv":1019.27,"id":36276560},{"atb":[[19.5,7.61],[20,4.23],[19,5.39],[18,2.71],[18.5,6.62],[17,3.53],[17.5,1.9]],"atl":[[21,10.25],[26,6.33],[22,13.5],[25,5.92],[23,9.15]],"trd":[[20,45.19]],"bdatb":[[0,20,4.23],[1,19.5,6.89],[3,18.5,6.62],[4,18,2.71],[7,16.5,2.31],[2,19,5.71],[5,17.5,2.21],[6,17,5.37],[8,16,4.45],[9,15.5,1.46]],"bdatl":[[6,27,3.25],[7,29,4.42],[9,32,2.75],[2,23,9.15],[4,25,5.92],[8,30,1.89],[1,22,13.5],[5,26,6.33],[0,21,10.25]],"ltp":20,"tv":218.24,"id":37947503},{"atb":[[1.08,0],[1.49,39.18],[1.54,4.69],[1.44,32.03],[1.5,72.45],[1.52,39.07],[1.51,68.49]],"atl":[[1.54,0],[1.57,24.18],[1.56,41.2]],"trd":[[1.54,118.71]],"bdatb":[[4,1.49,52.42],[5,1.48,147.34],[6,1.47,97.75],[7,1.46,133.8],[8,1.45,63.12],[1,1.52,98.91],[9,1.44,79.64],[2,1.51,150.8],[3,1.5,94.51]],"bdatl":[[2,1.56,41.2],[3,1.57,32],[4,1.58,131.46],[6,1.6,51.9],[7,1.61,36.6],[8,1.62,39.18],[9,1.63,35.63],[5,1.59,30.64],[0,1.54,3.97],[1,1.55,23.81]],"ltp":1.54,"tv":2896.83,"id":39823721},{"atb":[[60,1.57],[1.05,2.9]],"atl":[[70,6.51]],"bdatb":[[3,50,19.58],[7,42,1.64],[8,40,2.25]],"id":44331354}],"con":true,"tv":4853.5}]}
{"op":"mcm","clk":"APYgAM4cAKod","pt":1650392699472,"mc":[{"id":"1.197931750","rc":[{"atb":[[2.06,1],[8,4.86],[7.2,2.1]],"atl":[[10,8.93],[11,34.8]],"bdatb":[[8,8,7.02],[4,8.8,17.18],[5,8.6,8.97],[9,7.8,14.16],[2,9.2,17.75],[6,8.4,17.18]],"bdatl":[[7,13,2.94],[8,13.5,7.61],[3,11,34.8],[5,12,13.15],[6,12.5,19.1],[9,14,12.2],[1,10,8.93]],"id":42930960},{"atb":[[15.5,7.57],[17.5,0],[16.5,8.53],[1.01,13004.34],[17,8.83],[12.5,8.63]],"atl":[[21,14.08],[19,6.38],[18,5.5],[18.5,42.85]],"trd":[[17.5,3.11]],"bdatb":[[0,17,8.83],[1,16.5,8.53],[3,15.5,8.32],[2,16,5.16],[4,15,5.02],[5,14.5,3.89],[6,14,4.27],[7,13.5,6.27],[8,13,8.11],[9,12.5,9.36]],"bdatl":[[2,19,6.38],[5,21,14.08],[0,18,5.5],[1,18.5,42.85],[3,19.5,9.9],[4,20,13.2],[6,22,8.94],[7,23,3.44],[8,24,11.31],[9,25,2.04]],"ltp":17.5,"tv":247.81,"id":40095374},{"atl":[[8.2,25.1],[7.8,38.51]],"bdatb":[[3,6.8,6.25],[4,6.6,2.65],[2,7,58.39],[8,5.7,1.63],[9,5.6,13.23],[5,6.4,10.84],[6,6.2,7.86],[7,6,12.83],[0,7.4,72.4]],"bdatl":[[2,8.2,25.1],[3,8.4,9.08],[4,8.6,10.94],[9,9.6,7.35],[5,8.8,6.03],[6,9,8.11],[7,9.2,8.86],[8,9.4,3.2],[0,7.8,38.51]],"id":36276560},{"atb":[[19,2.68]],"atl":[[1000,13.57],[23,17.54],[28,2.02]],"bdatb":[[4,18,3.36],[5,17.5,3.34],[6,17,3.53],[2,19,2.68],[8,16,3.66],[1,19.5,7.61]],"bdatl":[[8,29,2.95],[5,26,6.33],[2,23,17.54],[7,28,2.02],[9,30,1.89]],"id":37947503},{"atb":[[1.08,0.1],[1.54,0],[1.5,90.78],[1.44,24.12],[1.52,53.11],[1.51,54.44],[1.49,43.26]],"atl":[[1.56,22.58]],"trd":[[1.54,119.11]],"bdatb":[[7,1.46,136.12],[9,1.44,41.48],[0,1.53,43.31],[1,1.52,111.86],[4,1.49,139.21],[5,1.48,81.72],[6,1.47,145],[8,1.45,57.12],[3,1.5,139.06],[2,1.51,130.14]],"bdatl":[[2,1.57,24.18],[4,1.59,49.13],[5,1.6,56.26],[6,1.61,51.26],[7,1.62,20.27],[8,1.63,55.98],[3,1.58,105.99],[9,1.64,58.88],[1,1.56,22.58],[0,1.55,23.81]],"tv":2897.23,"id":39823721},{"atb":[[1.05,1.24],[60,1.55]],"atl":[[380,1.19],[70,6.15]],"trd":[[70,18.05]],"bdatb":[[5,46,2.16],[7,42,2.1],[8,40,1.47],[1,60,1.55],[3,50,19.45]],"bdatl":[[0,70,6.15],[9,260,1.19]],"tv":82.22,"id":44331354}],"con":true,"tv":4856.41}]}
{"op":"mcm","clk":"AJciAM4dAMYe","pt":1650392700473,"mc":[{"id":"1.197931750","rc":[{"atb":[[7.8,23.69],[9.2,20.19],[9,20.29],[9.6,2.66],[9.4,24.61],[7.2,1.46],[8.2,9.63],[2.06,0]],"atl":[[10.5,26.29],[1000,13],[10,13.29],[13,1.46],[12,12.97],[11.5,19.57]],"trd":[[9.6,22.46]],"bdatb":[[0,9.6,2.66],[3,9,18.77],[4,8.8,20.36],[5,8.6,11.66],[1,9.4,24.61],[2,9.2,22.11],[7,8.2,9.63],[6,8.4,21.41],[8,8,7.02]],"bdatl":[[8,13.5,3.71],[9,14,17.02],[1,10,13.29],[2,10.5,21.93],[7,13,5.95],[3,11,40.02],[4,11.5,21.92],[5,12,15.12],[6,12.5,14.69]],"tv":391.84,"id":42930960},{"atb":[[15.5,11.13],[14.5,9.17],[17,6.64],[16,8.15],[16.5,4.43],[8.2,0.46],[17.5,0],[1.01,13003.77]],"atl":[[18.5,5.98],[17.5,1.37],[21,17.65],[19.5,14.19],[19,9.94],[27,2.14],[26,11.35],[23,3.35],[25,3.32],[18,4.93],[20,12.49]],"trd":[[18,52.39],[17.5,5.1]],"bdatb":[[1,16.5,4.43],[2,16,8.15],[4,15,4.27],[5,14.5,9.59],[7,13.5,6.55],[9,12.5,11.89],[0,17,8],[3,15.5,8.32],[6,14,4.27],[8,13,8.11]],"bdatl":[[5,21,17.65],[6,22,10.1],[7,23,4.74],[2,19,9.94],[3,19.5,14.19],[9,25,3.32],[0,18,4.93],[1,18.5,40.02],[8,24,10.21],[4,20,12.49]],"ltp":18,"tv":250.94,"id":40095374},{"atb":[[7,65.81],[7.2,26.51],[6,9.76],[5.5,56],[6.4,14.07],[5.6,7.23]],"atl":[[8.4,23.41],[14,20.49],[10.5,3.31],[9,6.91]],"bdatb":[[1,7.2,15.73],[2,7,62.38],[3,6.8,5.71],[4,6.6,7.29],[5,6.4,23.15],[8,5.8,2.99],[9,5.6,8.89],[7,6,14.49],[0,7.4,72.4]],"bdatl":[[2,8.2,28.22],[3,8.4,27.21],[8,9.4,9.41],[5,8.8,8.84],[6,9,6.91],[4,8.6,7.86],[7,9.2,6.14],[9,9.6,5.8]],"id":36276560},{"atb":[[20,12.31],[17.5,5.31],[16.5,9.06],[18.5,9.17],[19,6.86],[18,6.13],[12,16.47],[11.5,0.88]],"atl":[[25,9.33],[23,20.95],[22,16.92],[29,2.88],[28,4.57],[26,6.17],[34,2],[1000,13.49]],"bdatb":[[3,18.5,9.17],[5,17.5,2.69],[8,16,6.85],[2,19,6.86],[4,18,6.77],[7,16.5,4.24]],"bdatl":[[6,27,4.19],[8,29,3.98],[1,22,16.92],[2,23,20.95],[5,26,6.17],[7,28,4.57]],"id":37947503},{"atb":[[1.48,182.13],[1.54,35.33],[1.52,55.29],[1.53,34.53],[1.45,45.58],[1.08,0]],"atl":[[1000,13],[1.58,28.47],[1.55,16.48],[1.56,55.35],[1.61,10.77],[1.6,17.75],[1.57,46.79]],"trd":[[1.54,123.11]],"bdatb":[[8,1.46,150.96],[9,1.45,92.73],[2,1.52,142.7],[3,1.51,101.28],[4,1.5,197.13],[5,1.49,80.75],[6,1.48,132.49],[7,1.47,114.54],[0,1.54,37.33],[1,1.53,42.15]],"bdatl":[[0,1.55,16.48],[1,1.56,55.35],[4,1.59,68.16],[5,1.6,84.32],[6,1.61,25.52],[7,1.62,57.76],[8,1.63,36.45],[9,1.64,54.9],[2,1.57,46.79],[3,1.58,97.02]],"tv":2901.23,"id":39823721},{"atb":[[50,19.37],[48,2.28],[46,1.71],[44,1.34],[42,1.45]],"atl":[[120,0.35],[110,0],[100,2.59],[95,2.01],[170,0.45],[280,0.26],[140,0]],"bdatb":[[3,50,19.37],[4,48,2.28],[5,46,1.96],[6,44,1.34],[7,42,1.78]],"bdatl":[[3,95,2.01],[4,100,2.59],[5,180,1.23]],"id":44331354}],"con":true,"tv":4863.74}]}
{"op":"mcm","clk":"ANkjAMMeAN4f","pt":1650392701474,"mc":[{"id":"1.197931750","rc":[{"atb":[[8.8,20.43],[9,22.29],[1.12,30],[8.4,17],[8.2,13.97],[9.6,10.4],[8,15.53],[9.8,1.59],[9.2,22.04],[8.6,13.33],[9.4,24.27]],"atl":[[10,3.03],[12,34.15],[11.5,21.58],[10.5,17.84],[9.8,0]],"trd":[[10,6.62],[9.8,17.93]],"bdatb":[[1,9.6,12.38],[2,9.4,24.27],[3,9.2,26.42],[4,9,22.29],[5,8.8,26.35],[8,8.2,22.19],[9,8,17.13],[6,8.6,22.73],[7,8.4,17],[0,9.8,1.59]],"bdatl":[[0,10,4.03],[1,10.5,17.84],[3,11.5,21.58],[4,12,40.88],[5,12.5,19.2],[6,13,1.61],[8,14,22.14],[9,14.5,2.92],[7,13.5,2.62],[2,11,34.8]],"ltp":10,"tv":396.75,"id":42930960},{"atb":[[15.5,13.23],[15,14.12],[17,10.68],[16.5,8.99],[14,10.01],[14.5,3.64]],"atl":[[20,8.09],[19.5,15.47],[17.5,0],[19,10.69],[18.5,5.98],[32,1.85],[18,38.97]],"trd":[[17.5,6.47],[17,2.67]],"bdatb":[[0,17,11.79],[1,16.5,8.99],[3,15.5,14.61],[4,15,14.12],[5,14.5,4.95],[6,14,10.01],[7,13.5,8],[8,13,14.33],[9,12.5,11.45]],"bdatl":[[0,18,38.97],[1,18.5,5.98],[2,19,10.69],[3,19.5,15.47],[4,20,8.09],[5,21,17.65],[6,22,8.94],[7,23,3.35],[8,24,10.86],[9,25,3.32]],"ltp":17.5,"tv":254.21,"id":40095374},{"atb":[[6.6,9.17],[6.8,13.88],[6.2,10.78],[6.4,23.59]],"atl":[[8.4,25.45],[7.8,33.3],[8.6,9.87]],"trd":[[7.8,91.42]],"bdatb":[[0,7.6,2.49],[1,7.4,72.4],[2,7.2,29.48],[3,7,68.52],[4,6.8,21.54],[5,6.6,21.42],[6,6.4,29.11],[7,6.2,18.02],[8,6,17.82],[9,5.9,11.42]],"bdatl":[[0,7.8,33.3],[3,8.4,25.45],[4,8.6,11.68],[5,8.8,10.24],[6,9,10.77],[7,9.2,8.49],[8,9.4,3.41],[9,9.6,5.8],[2,8.2,25.1]],"ltp":7.8,"tv":1026.62,"id":36276560},{"atb":[[21,7.75],[18,8.17],[18.5,14.65],[19.5,11.02],[16,4.87],[16.5,7.65],[15.5,6.61],[17,10.36],[20,14.06]],"atl":[[26,8.3],[23,21.8],[25,11.34],[24,49.84],[22,11.87],[21,0]],"trd":[[21,56.39]],"bdatb":[[0,21,7.75],[1,20,15.01],[2,19.5,11.02],[3,19,7.98],[4,18.5,14.65],[5,18,8.17],[6,17.5,5.31],[7,17,11.48],[8,16.5,7.65],[9,16,8.12]],"bdatl":[[0,22,11.87],[1,23,23.85],[2,24,49.84],[3,25,11.34],[4,26,6.17],[5,27,3.25],[6,28,4.57],[7,29,2.88],[8,30,1.89],[9,32,1.87]],"ltp":21,"tv":223.6,"id":37947503},{"atb":[[1.52,45.5],[1.47,248.28],[1.48,28.52],[1.51,53.25],[1.49,45.26],[1.5,92.78],[1.53,0],[1.46,11.2],[1.54,0]],"atl":[[1.55,34.26],[1.56,48.26],[1000,14],[1.53,12.37],[1.54,26.21],[1.57,51.09],[1.58,30.6],[1.61,46.34],[1.63,23.49],[1.6,35.35],[1.59,42.37]],"trd":[[1.53,404.19],[1.54,157.73]],"bdatb":[[0,1.52,79.63],[1,1.51,179.64],[2,1.5,114.21],[3,1.49,143.96],[4,1.48,164.05],[5,1.47,230.27],[6,1.46,113.51],[7,1.45,79.34],[8,1.44,34.85],[9,1.43,145]],"bdatl":[[0,1.53,12.37],[1,1.54,26.21],[2,1.55,33.61],[3,1.56,51.85],[4,1.57,124.63],[5,1.58,72.42],[6,1.59,144.27],[7,1.6,98.9],[8,1.61,102.56],[9,1.62,6.52]],"ltp":1.53,"tv":2968.07,"id":39823721},{"atb":[[1.05,1.24],[50,21.41],[48,4.28],[1.02,0]],"atl":[[70,5.73],[440,0.16]],"trd":[[70,18.56]],"bdatb":[[2,55,2.42],[3,50,21.41],[4,48,4.28],[5,46,2.17],[7,42,1.45],[9,38,1.56],[1,60,1.55],[6,44,1.34],[8,40,1.47]],"bdatl":[[0,70,5.81]],"tv":82.73,"id":44331354}],"con":true,"tv":4951.98}]}
{"op":"mcm","clk":"AI0lAMQfAOUg","pt":1650392702475,"mc":[{"id":"1.197931750","rc":[{"atb":[[7.8,12.7],[8.8,18.25],[9,8.61],[6,2.3],[9.4,0],[9.2,14.48],[8.6,16.93],[7.6,14.48],[7.4,7.59],[8.4,19.01],[8,13.4],[9.8,0],[10,0],[9.6,0]],"atl":[[9.4,1.82],[9.6,11.91],[10,17.23],[13.5,7.13],[9.8,14.49],[10.5,20.51],[11.5,26.05],[11,36.81],[13,10.4],[12.5,19.12],[12,19.49]],"trd":[[9.4,234.71],[9.8,24.01],[10,13.26],[9.6,45.23]],"bdatb":[[1,9,8.77],[2,8.8,19.21],[3,8.6,17.56],[4,8.4,26.16],[5,8.2,16.19],[6,8,20.13],[7,7.8,24.59],[0,9.2,14.48],[8,7.6,14.48],[9,7.4,14.13]],"bdatl":[[0,9.4,1.82],[1,9.6,11.91],[2,9.8,14.49],[3,10,17.23],[4,10.5,20.51],[5,11,41.71],[6,11.5,31.19],[7,12,19.49],[8,12.5,24.78],[9,13,11.42]],"ltp":9.4,"tv":532.84,"id":42930960},{"atb":[[16,8.15],[16.5,12.56],[13,11.71],[13.5,11.34],[1.27,0],[14.5,16.37],[14,13.61],[5.1,24.39],[4.5,0]],"atl":[[22,12.57],[20,9.73],[17.5,0.57],[1000,13.47],[23,6.98],[18,35.62],[19,12.79]],"trd":[[18,53.5]],"bdatb":[[1,16.5,12.65],[3,15.5,14.13],[4,15,14.24],[5,14.5,20.39],[6,14,13.61],[7,13.5,12.69],[8,13,14.62],[9,12.5,9.91],[2,16,8.15],[0,17,10.68]],"bdatl":[[0,18,36.19],[4,20,9.73],[5,21,17.65],[6,22,12.57],[7,23,7.98],[8,24,11.5],[9,25,3.32],[2,19,12.79]],"ltp":18,"tv":255.32,"id":40095374},{"atb":[[7.8,2.95],[1.02,1.17],[7.2,28.53],[7.6,21.16],[7.4,73.61],[7,67.81],[6,19.27]],"atl":[[8.8,9.68],[9,11.74],[8.6,16.69],[8.2,31.29],[8,11.71],[8.4,23.41],[7.8,0]],"trd":[[7.8,137.77]],"bdatb":[[0,7.8,3.14],[1,7.6,22.28],[2,7.4,74.35],[3,7.2,36.87],[4,7,75.81],[5,6.8,16.25],[6,6.6,23.21],[8,6.2,22.17],[9,6,28.7],[7,6.4,31.14]],"bdatl":[[3,8.6,16.69],[4,8.8,15.81],[5,9,11.74],[6,9.2,9.78],[8,9.6,7.9],[0,8,11.71],[1,8.2,31.29],[2,8.4,23.41],[9,9.8,8.92],[7,9.4,3.2]],"tv":1072.97,"id":36276560},{"atb":[[19,9.72],[20,18.62],[13.5,4.24],[21,9.39],[18.5,13.88],[19.5,13.02],[16.5,12.47]],"atl":[[27,8.69],[23,13.56],[26,11.74],[25,9.9],[24,48.05],[22,0.7]],"trd":[[22,61.33]],"bdatb":[[1,20,18.69],[3,19,10.17],[4,18.5,14.27],[6,17.5,8.64],[7,17,10.36],[8,16.5,13.58],[9,16,4.87],[2,19.5,13.02],[5,18,8.17],[0,21,9.39]],"bdatl":[[0,23,14.26],[4,27,8.69],[7,30,2.65],[9,34,2.91],[3,26,11.74],[1,24,48.05],[2,25,9.9],[5,28,4.57],[8,32,1.87],[6,29,2.88]],"ltp":22,"tv":226.72,"id":37947503},{"atb":[[1.52,38.92],[1.48,80.41],[1.51,76.03],[1.49,77.85],[1.54,0],[1.47,196.39],[1.53,35.23],[1.37,119.66],[1.46,260.55],[1.41,107.4],[1.5,92.78]],"atl":[[1.54,0.95],[1.57,59.05],[1.55,47.7],[1.59,44.43],[1.56,46.26],[1000,13.16],[1.53,0]],"trd":[[1.54,204.67],[1.53,416.56]],"bdatb":[[0,1.53,45.26],[1,1.52,90.44],[2,1.51,101.05],[3,1.5,238.63],[4,1.49,141.94],[5,1.48,148.75],[6,1.47,274.06],[7,1.46,280.66],[8,1.45,107.74],[9,1.44,115.43]],"bdatl":[[0,1.55,48.65],[1,1.56,46.26],[2,1.57,73.71],[3,1.58,130.93],[4,1.59,45.89],[5,1.6,52.11],[6,1.61,47.74],[7,1.62,108.57],[8,1.63,102.08],[9,1.64,134.7]],"ltp":1.54,"tv":3027.38,"id":39823721},{"atb":[[60,3.55],[50,19.39],[55,0],[48,4.34],[44,5.34],[42,3.47],[65,0],[46,5.83]],"atl":[[70,11.15],[80,2]],"trd":[[65,9.73],[70,19.55]],"bdatb":[[0,60,3.55],[1,50,19.42],[3,46,6.01],[4,44,5.47],[6,40,1.51],[8,36,24.12],[9,34,1.59],[2,48,4.34],[5,42,3.47],[7,38,1.06]],"bdatl":[[5,180,1.23],[0,70,11.15],[6,190,4],[9,260,1.19],[1,80,2]],"ltp":65,"tv":93.45,"id":44331354}],"con":true,"tv":5208.68}]}
{"op":"mcm","clk":"AK8mAMUgAIki","pt":1650392703476,"mc":[{"id":"1.197931750","rc":[{"atb":[[7.8,21.84],[8.8,20.23],[8.6,16.93],[9,12.8],[7.6,22.23],[9.2,8.5]],"atl":[[9.8,16.51],[10,22.89],[9.4,3.12],[11,29.68],[10.5,21.86],[9.6,6.57]],"trd":[[9.4,238.35],[9.6,58.6]],"bdatb":[[0,9.2,9.58],[1,9,14.49],[2,8.8,21.01],[3,8.6,16.93],[4,8.4,27],[7,7.8,24.12],[8,7.6,25.3],[5,8.2,22.13],[6,8,14.56]],"bdatl":[[0,9.4,3.12],[5,11,34.58],[4,10.5,21.86],[1,9.6,6.57],[2,9.8,14.49],[3,10,20.88],[6,11.5,30.91],[7,12,25.12],[8,12.5,21.96],[9,13,10.55]],"ltp":9.6,"tv":549.85,"id":42930960},{"atb":[[13,5.71],[8,4.49]],"bdatb":[[0,17,12.16],[1,16.5,12.56],[5,14.5,20.53],[6,14,14.09],[2,16,8.15],[3,15.5,13.5],[4,15,14.3],[7,13.5,11.34],[8,13,16.86],[9,12.5,9.37]],"bdatl":[[9,25,4.29],[7,23,9.32],[8,24,10.21]],"id":40095374},{"atb":[[7.8,21.74],[1.21,2],[5.7,1.46],[6.8,13.88],[7.4,89.04],[7,65.78],[7.2,30.5],[7.6,22.19]],"atl":[[8,4],[8.4,42.89],[8.2,19.66]],"trd":[[7.8,139.77],[8,26.21]],"bdatb":[[0,7.8,25.97],[1,7.6,22.19],[2,7.4,98.13],[3,7.2,31.44],[9,6,37.2],[4,7,75.35],[5,6.8,15.25],[6,6.6,15.4],[7,6.4,31.14],[8,6.2,22.17]],"bdatl":[[0,8,4],[2,8.4,42.89],[1,8.2,19.66],[6,9.2,5.99],[7,9.4,6.56],[8,9.6,5.8],[9,9.8,11.31]],"ltp":7.8,"tv":1078.61,"id":36276560},{"atb":[[20,17.68],[8,4.49],[21,10.23]],"atl":[[25,7.04],[24,50.05],[23,27.71],[22,7.55]],"bdatb":[[0,21,10.7],[1,20,18.44],[3,19,9.94],[4,18.5,13.88],[5,18,8.31],[6,17.5,5.31],[7,17,13.91],[8,16.5,12.88],[9,16,4.87],[2,19.5,13.02]],"bdatl":[[2,24,50.05],[3,25,7.04],[0,22,7.55],[1,23,27.71],[4,26,11.74],[5,27,8.69],[6,28,4.57],[7,29,2.88],[8,30,3.68],[9,32,1.87]],"id":37947503},{"atb":[[1.43,86.47],[1.48,80.41],[1.52,36.78],[1.51,73.99],[1.49,45.26]],"atl":[[1.54,0],[1.57,26.19],[1.56,48.92],[1000,13]],"trd":[[1.54,237.35]],"bdatb":[[1,1.52,78.25],[2,1.51,122.82],[5,1.48,220.9],[6,1.47,211.07],[7,1.46,321.55],[8,1.45,74.33],[0,1.53,54.4],[3,1.5,138.26],[9,1.44,104.15],[4,1.49,185.41]],"bdatl":[[9,1.63,102.18],[0,1.54,16.34],[3,1.57,139.17],[4,1.58,33.23],[7,1.61,127.85],[8,1.62,26.39],[2,1.56,48.92],[6,1.6,36.55],[5,1.59,64.17],[1,1.55,47.7]],"tv":3060.06,"id":39823721},{"atb":[[8,4.49]],"atl":[[160,0.48],[65,2.09],[70,9.26],[85,2.01]],"bdatb":[[1,50,19.88],[2,48,4.34],[4,44,5.44],[6,40,1.54],[8,36,24.17],[5,42,3.47],[9,34,1.59],[3,46,5.83],[7,38,1.06]],"bdatl":[[0,65,2.09],[1,70,9.26],[2,80,2],[3,85,2.01],[4,95,2.01],[5,100,2.59],[6,170,1.28],[7,190,4.43],[8,200,2.39],[9,230,1.25]],"id":44331354}],"con":true,"tv":5264.01}]}
{"op":"mcm","clk":"ANUnAMshAKAj","pt":1650392704478,"mc":[{"id":"1.197931750","rc":[{"atb":[[9.2,6.31]],"atl":[[9.6,9.86],[10.5,20.51],[11,26.33]],"bdatb":[[2,8.8,23.78],[4,8.4,24.1],[6,8,19.92],[7,7.8,27.92],[8,7.6,27.64],[0,9.2,8.5],[1,9,12.8],[5,8.2,13.97]],"bdatl":[[1,9.6,9.86],[4,10.5,20.51],[7,12,26.48],[8,12.5,20.56],[9,13,11.15],[6,11.5,31.54],[5,11,30.67],[2,9.8,16.51],[3,10,22.89]],"id":42930960},{"atb":[[12.5,15.9]],"atl":[[17.5,0],[20,14.69]],"bdatb":[[4,15,14.24],[5,14.5,17.62],[9,12.5,16.07],[0,17,10.68],[3,15.5,15.12],[6,14,15.36],[7,13.5,14.05],[8,13,6.75]],"bdatl":[[9,25,4.54],[7,23,9.06],[4,20,14.69]],"id":40095374},{"atb":[[5.9,1.46],[1.21,0],[7.8,28.55],[7.4,70.57],[7.2,42.55],[4.6,0],[5.1,15.99]],"atl":[[8.4,43.53],[8.6,16.69],[8,3.9],[8.2,11.57]],"trd":[[8,26.41]],"bdatb":[[5,6.8,21.17],[6,6.6,15.4],[7,6.4,34.69],[8,6.2,18.51],[9,6,31.75],[0,7.8,28.55],[1,7.6,23.5],[2,7.4,75.91],[3,7.2,45.95],[4,7,72.93]],"bdatl":[[0,8,3.9],[2,8.4,43.53],[3,8.6,16.69],[6,9.2,6.65],[7,9.4,6.68],[9,9.8,11.19],[4,8.8,15.11],[1,8.2,11.57]],"ltp":8,"tv":1078.81,"id":36276560},{"atb":[[16,9.85],[21,11.49],[16.5,7.65]],"atl":[[29,6.32],[28,8.01],[25,10.48],[22,2.25],[23,26.82]],"bdatb":[[5,18,8.27],[7,17,12.87],[0,21,11.49],[1,20,17.68],[2,19.5,13.53],[3,19,10.75],[9,16,12.13],[8,16.5,7.65]],"bdatl":[[3,25,10.48],[6,28,8.01],[7,29,6.32],[0,22,2.25],[8,30,3.48],[1,23,26.82]],"id":37947503},{"atb":[[1.54,0],[1.52,41.55],[1.48,236.03],[1.08,0],[1.53,31.23],[1.51,55.61]],"atl":[[1.57,26.19],[1.56,63.86],[1000,14],[1.54,0]],"trd":[[1.54,258.67],[1.53,438.56]],"bdatb":[[4,1.49,183.55],[5,1.48,251.49],[6,1.47,278.47],[7,1.46,318.91],[8,1.45,52.11],[9,1.44,90.89],[0,1.53,50.4],[1,1.52,54.79],[2,1.51,104.97],[3,1.5,200.62]],"bdatl":[[1,1.56,63.86],[2,1.57,141.82],[5,1.6,108.4],[6,1.61,76.93],[0,1.55,47.7],[3,1.58,50.47],[4,1.59,50.57],[7,1.62,1.58],[8,1.63,100.61],[9,1.64,134.7]],"ltp":1.54,"tv":3103.38,"id":39823721},{"atb":[[55,2.3],[46,4.53],[1.05,1.24],[44,5.93]],"atl":[[75,0],[140,0.54],[65,1.7],[70,4.26]],"trd":[[65,10.51]],"bdatb":[[1,55,2.3],[4,46,4.75],[7,40,1.52],[9,36,23],[2,50,19.39],[5,44,6.38],[3,48,4.34],[6,42,3.47],[8,38,1.06]],"bdatl":[[2,80,2],[3,85,2.01],[4,95,2.01],[5,100,2.59],[6,160,1.37],[7,190,4.88],[8,200,2.39],[9,230,1.25],[0,65,1.7],[1,70,4.26]],"tv":94.23,"id":44331354}],"con":true,"tv":5308.31}]}
{"op":"mcm","clk":"AJgpAOciAK4k","pt":1650392705480,"mc":[{"id":"1.197931750","rc":[{"atb":[[9.2,10.85]],"atl":[[10,24.67],[9.8,18.76]],"bdatb":[[4,8.4,24.35],[6,8,18.56],[7,7.8,28.88],[2,8.8,21.96],[3,8.6,17.95],[0,9.2,10.85],[8,7.6,29.32]],"bdatl":[[3,10,24.67],[2,9.8,18.76],[7,12,26.42],[8,12.5,20.74],[9,13,10.49],[5,11,30.53]],"id":42930960},{"atb":[[14,13.98],[2.06,0],[17,9.26],[13,5.31],[12.5,12.26]],"atl":[[24,17.52],[17.5,1.37]],"bdatb":[[6,14,15.36],[7,13.5,14.4],[9,12.5,15.55],[3,15.5,14.21],[4,15,15.06],[5,14.5,17.75],[8,13,6.38],[0,17,9.26]],"bdatl":[[9,24,17.52],[0,17.5,1.37],[1,18,35.62],[2,18.5,5.98],[3,19,12.79],[4,19.5,15.47],[5,20,14.69],[6,21,17.65],[7,22,12.57],[8,23,8.99]],"id":40095374},{"atb":[[7.4,70],[7.8,24.7]],"atl":[[8.4,41.49],[8.8,11.7],[9,13.74],[8.6,14.68],[8,1.9]],"bdatb":[[2,7.4,73.44],[3,7.2,45.24],[7,6.4,29.93],[8,6.2,24.75],[1,7.6,25.35],[0,7.8,24.7],[5,6.8,21.8],[4,7,79.53],[6,6.6,16.49],[9,6,31.7]],"bdatl":[[2,8.4,41.49],[3,8.6,14.68],[4,8.8,16.96],[5,9,13.74],[0,8,1.9],[9,9.8,8.88],[6,9.2,9.17],[7,9.4,4.22]],"id":36276560},{"atb":[[16.5,12.78],[2.06,0],[12,16.04]],"bdatb":[[7,17,12.68],[8,16.5,12.78],[9,16,12.43],[2,19.5,13.8],[3,19,9.72],[4,18.5,14.36],[5,18,8.17],[6,17.5,5.62]],"bdatl":[[8,30,3.43]],"id":37947503},{"atb":[[1.49,53.84],[1.51,69.37],[1.53,30.23]],"atl":[[1.55,44.4],[1000,13],[1.57,34.3],[1.56,61.69]],"trd":[[1.53,440.56]],"bdatb":[[3,1.5,325.15],[4,1.49,118.22],[5,1.48,256.51],[6,1.47,251.74],[9,1.44,70.34],[0,1.53,40.16],[1,1.52,64.08],[2,1.51,109.55],[7,1.46,331.55],[8,1.45,49.6]],"bdatl":[[0,1.55,44.4],[2,1.57,134.55],[3,1.58,52.91],[4,1.59,58.49],[5,1.6,113.2],[7,1.62,19.58],[8,1.63,112.83],[6,1.61,59.86],[1,1.56,61.69]],"ltp":1.53,"tv":3105.38,"id":39823721},{"atl":[[80,2.18],[70,4.05],[75,2.01],[65,7.37]],"bdatb":[[4,46,4.86],[5,44,5.93],[7,40,1.69],[8,38,1.2],[9,36,23.06]],"bdatl":[[1,70,4.05],[3,80,2.18],[2,75,2.01],[4,85,2.01],[5,95,2.01],[6,100,2.59],[7,160,1.37],[8,190,4.88],[9,200,2.39],[0,65,7.37]],"id":44331354}],"con":true,"tv":5310.31}]}
{"op":"mcm","clk":"AKYqAOUjAK8l","pt":1650392706481,"mc":[{"id":"1.197931750","rc":[{"atb":[[9,17.34]],"atl":[[12.5,17.11],[12,17.45],[11.5,24.04],[11,24.32]],"bdatb":[[6,8,25.85],[7,7.8,25.69],[8,7.6,23.74],[9,7.4,9.68],[0,9.2,10.85],[1,9,21.4],[2,8.8,20.23],[3,8.6,18.43],[4,8.4,21.15],[5,8.2,18]],"bdatl":[[4,10.5,22.79],[5,11,25.54],[6,11.5,28.06],[8,12.5,25.49],[9,13,12.29],[7,12,17.45]],"id":42930960},{"atb":[[16.5,2.49],[15.5,4.11],[15,10.55],[14.5,14.89],[14,10.39],[2.06,0.38],[16,14.57],[17,0]],"atl":[[17.5,12.39],[18.5,11.74],[18,39.64],[17,1.46],[16.5,0],[26,1.92],[22,14.82]],"trd":[[16.5,47.48],[17,21.19]],"bdatb":[[0,16.5,2.49],[1,16,16.4],[2,15.5,4.58],[3,15,10.55],[4,14.5,15.78],[5,14,11.67],[6,13.5,13.79],[7,13,7.12],[8,12.5,18.35],[9,12,9.98]],"bdatl":[[1,17.5,12.39],[0,17,1.46],[2,18,39.64],[3,18.5,11.74],[7,21,18.78],[9,23,7.56],[4,19,12.79],[5,19.5,15.47],[6,20,14.69],[8,22,14.82]],"ltp":16.5,"tv":321.32,"id":40095374},{"atb":[[8,2.99],[6.6,7.13],[7.6,35.38],[6.8,11.85],[7.2,40.58],[7.4,72.01],[4.9,63.04],[5.8,1.46],[7.8,25.27]],"atl":[[8.4,19.38],[8.2,8.22],[8.6,24.01],[8,0]],"trd":[[8,30.21]],"bdatb":[[0,8,6.09],[1,7.8,25.84],[2,7.6,36.33],[3,7.4,80.65],[4,7.2,43.85],[5,7,76.65],[6,6.8,20.24],[7,6.6,14.45],[8,6.4,23.96],[9,6.2,21.79]],"bdatl":[[4,9,17.89],[5,9.2,3.35],[0,8.2,8.22],[1,8.4,19.38],[6,9.4,8.12],[7,9.6,5.8],[8,9.8,5.64],[3,8.8,11.7],[9,10,48.99],[2,8.6,24.01]],"tv":1082.61,"id":36276560},{"atb":[[2.06,0.3],[18,6.13]],"atl":[[30,5.33],[32,5.31]],"bdatb":[[0,21,11.49],[1,20,19.14],[3,19,10.1],[4,18.5,13.88],[6,17.5,7.07],[8,16.5,14.79],[9,16,9.85],[5,18,6.13],[7,17,10.36],[2,19.5,13.02]],"bdatl":[[7,29,7.14],[8,30,5.33],[9,32,5.73],[5,27,8.69]],"id":37947503},{"atb":[[1.52,30.41],[1.48,78.4],[1.53,24.42]],"atl":[[1.55,41.25],[1.54,23.73],[1.57,36.31],[1.56,63.86]],"trd":[[1.53,450.89]],"bdatb":[[3,1.5,171.22],[4,1.49,184.71],[0,1.53,40.64],[1,1.52,58.43],[2,1.51,106.85],[5,1.48,158.09],[8,1.45,85.47],[9,1.44,62.79],[7,1.46,337.04],[6,1.47,196.39]],"bdatl":[[2,1.56,79.2],[3,1.57,47.24],[4,1.58,139.36],[5,1.59,62.27],[6,1.6,44.46],[7,1.61,97.26],[8,1.62,59.3],[9,1.63,57.85],[1,1.55,41.25],[0,1.54,23.73]],"tv":3115.71,"id":39823721},{"atb":[[44,3.93],[42,1.45]],"atl":[[150,0.54],[100,0.58],[95,0],[65,5.67]],"bdatb":[[0,60,3.55],[1,55,2.75],[2,50,19.48],[5,44,4.1],[7,40,1.47],[8,38,1.4],[9,36,22.5],[6,42,1.45],[4,46,4.53]],"bdatl":[[9,230,1.35],[6,160,1.02],[7,190,4.88],[5,140,1.47],[8,200,2.39],[0,65,5.67]],"id":44331354}],"con":true,"tv":5390.44}]}
{"op":"mcm","clk":"AMQrAPskALYm","pt":1650392707484,"mc":[{"id":"1.197931750","rc":[{"atb":[[9.2,15.4]],"atl":[[9.4,1.3],[9.8,16.74],[11,26.33],[10,22.66]],"trd":[[9.4,240.16]],"bdatb":[[2,8.8,22.32],[4,8.4,20.02],[5,8.2,21.19],[7,7.8,23.64],[9,7.4,9.99],[0,9.2,10.85],[1,9,20.93],[3,8.6,16.93],[6,8,26.35],[8,7.6,23.46]],"bdatl":[[0,9.4,1.3],[2,9.8,16.74],[3,10,22.66],[5,11,32.55],[6,11.5,25.97],[8,12.5,19.98],[9,13,14.93],[7,12,21.03],[4,10.5,20.51]],"ltp":9.4,"tv":551.66,"id":42930960},{"atb":[[14,10.02],[13.5,19.82],[15.5,8.05],[14.5,16.6],[15,12.59],[16,14.07],[2.06,0],[16.5,5.5],[12,11.23]],"atl":[[17.5,16.53],[18.5,21.91],[18,38.63],[17,0.46],[30,1.77],[19.5,9.6],[19,11.18],[20,12.67]],"trd":[[17,22.19],[16.5,49.5]],"bdatb":[[2,15.5,9.35],[3,15,13.81],[5,14,11],[7,13,6.19],[9,12,12.4],[0,16.5,5.5],[1,16,14.84],[4,14.5,16.6],[6,13.5,23.74],[8,12.5,20.55]],"bdatl":[[8,23,9.96],[0,17.5,14.03],[1,18,38.63],[2,18.5,21.91],[3,19,11.18],[4,19.5,9.6],[5,20,12.67],[6,21,17.65],[7,22,14.82],[9,24,17.52]],"ltp":17,"tv":324.34,"id":40095374},{"atb":[[6.4,18.83],[8,16.72],[4.2,0],[4.4,0],[4,0],[7,61.78],[7.6,33.52]],"atl":[[8.8,11.7],[9.8,8.82],[8.6,26.02],[9.2,10.19],[9,15.74],[8.2,7.21],[8.4,21.07],[9.4,8.01],[9.6,10.61]],"trd":[[8.2,87.86],[8,41.78]],"bdatb":[[1,7.8,25.83],[2,7.6,38.57],[3,7.4,79.61],[4,7.2,42.18],[7,6.6,8.31],[8,6.4,29.92],[0,8,17.7],[5,7,76.58],[9,6.2,21.64],[6,6.8,17.9]],"bdatl":[[2,8.6,24.01],[3,8.8,9.68],[4,9,15.74],[5,9.2,10.19],[6,9.4,15.29],[8,9.8,7.19],[0,8.2,7.21],[1,8.4,21.07],[7,9.6,10.61],[9,10,48.99]],"ltp":8.2,"tv":1096.25,"id":36276560},{"atb":[[17,10.36],[16.5,12.47],[21,13.49],[2.06,0]],"atl":[[27,8.69],[25,8.47],[24,48.05],[22,1.47],[23,13.56]],"trd":[[22,62.11]],"bdatb":[[3,19,11.75],[6,17.5,5.79],[9,16,10.57],[0,21,13.49],[1,20,18.29],[2,19.5,13.02],[4,18.5,13.88],[5,18,6.13],[8,16.5,15.68],[7,17,10.66]],"bdatl":[[2,24,48.05],[3,25,8.47],[5,27,8.69],[0,22,1.47],[7,29,6.32],[1,23,13.56],[8,30,5.33],[9,32,5.31]],"tv":227.5,"id":37947503},{"atb":[[1.52,41.57],[1.53,18.35],[1.51,69.11],[1.5,92.78],[1.47,37.46],[1.48,80.41],[1.46,173.59]],"atl":[[1.56,70.23],[1.54,32.9],[1.53,0],[1.59,42.37],[1.57,26.19],[1.55,43.69]],"trd":[[1.53,477.55]],"bdatb":[[1,1.52,78.8],[2,1.51,98.64],[3,1.5,183.11],[5,1.48,178.67],[6,1.47,57.98],[7,1.46,270.59],[8,1.45,75.6],[9,1.44,111.27],[0,1.53,5.11],[4,1.49,125.51]],"bdatl":[[0,1.54,32.9],[2,1.56,124.59],[3,1.57,53.6],[4,1.58,90.57],[5,1.59,76.82],[6,1.6,65.08],[7,1.61,61.44],[9,1.63,108.63],[8,1.62,52.83],[1,1.55,43.69]],"tv":3142.37,"id":39823721},{"atb":[[60,3.81]],"atl":[[65,5.42],[360,0.23],[330,1.22]],"trd":[[65,10.76]],"bdatb":[[7,40,1.93],[1,55,2.44],[2,50,19.48],[4,46,4.53],[5,44,4.39],[9,36,22.5],[3,48,4.34],[6,42,1.45],[0,60,3.81],[8,38,1.06]],"bdatl":[[0,65,5.42],[9,230,1.25]],"tv":94.48,"id":44331354}],"con":true,"tv":5436.6}]}
{"op":"mcm","clk":"APosAPklAMcn","pt":1650392708486,"mc":[{"id":"1.197931750","rc":[{"atb":[[9.2,12.57],[7.8,15.84]],"bdatb":[[3,8.6,20.05],[4,8.4,23.88],[5,8.2,13.97],[2,8.8,20.23],[7,7.8,20],[8,7.6,23.37],[0,9.2,12.57],[6,8,26.35],[9,7.4,14.13]],"bdatl":[[6,11.5,27.16],[7,12,23.15],[5,11,30.53],[8,12.5,20.35],[9,13,11.12],[4,10.5,23.18]],"id":42930960},{"atb":[[16.5,6.68],[15.5,13.74]],"atl":[[17,7.97],[19.5,7.59],[24,13.86],[18.5,23.92],[18,12.63],[17.5,45.34]],"trd":[[16.5,51.61]],"bdatb":[[0,16.5,6.68],[3,15,12.59],[5,14,11.94],[6,13.5,22.85],[7,13,5.84],[8,12.5,20],[9,12,13.93],[2,15.5,15.04]],"bdatl":[[0,17,7.97],[5,19.5,7.59],[2,18,12.63],[3,18.5,23.92],[1,17.5,45.34],[4,19,11.18],[6,20,12.67],[7,21,18.98],[8,22,14.82],[9,23,8.99]],"ltp":16.5,"tv":326.45,"id":40095374},{"atb":[[7.6,33.52],[4.7,38.06],[8,27.39],[7.8,18.46]],"atl":[[8.6,24.56]],"bdatb":[[2,7.6,33.52],[0,8,28.92],[1,7.8,21.03],[3,7.4,81.16],[4,7.2,41.53],[5,7,75.6],[8,6.4,26.8],[9,6.2,13.42],[7,6.6,14.45]],"bdatl":[[9,10,48.99],[6,9.4,12.93],[8,9.8,13.03],[2,8.6,24.56],[3,8.8,11.7],[4,9,18.85]],"id":36276560},{"atl":[[25,17.58],[24,45.84]],"bdatb":[[5,18,7.62],[6,17.5,5.31],[7,17,12.77],[8,16.5,12.47],[9,16,10.28],[2,19.5,14.05],[3,19,9.72]],"bdatl":[[2,24,45.84],[3,25,17.58],[7,29,7.28]],"id":37947503},{"atb":[[1.05,0],[1.48,234.02],[1.46,260.55],[1.49,49.76],[1.52,30.41],[1.47,35.45]],"atl":[[1.54,20.98],[1.56,66.42]],"bdatb":[[2,1.51,119.69],[3,1.5,183.1],[5,1.48,268],[9,1.44,123.68],[7,1.46,371.94],[0,1.53,26.33],[1,1.52,61.27],[4,1.49,168.11],[6,1.47,71.29],[8,1.45,95.74]],"bdatl":[[8,1.62,114.41],[9,1.63,52.25],[2,1.56,137.07],[3,1.57,95.58],[0,1.54,20.98],[4,1.58,36.53],[5,1.59,76.82],[6,1.6,80.27],[7,1.61,51.29]],"id":39823721},{"bdatb":[[9,36,23.24],[1,55,2.52],[2,50,19.39],[3,48,4.76],[5,44,3.93],[7,40,1.47]],"bdatl":[[9,230,1.37]],"id":44331354}],"con":true,"tv":5438.71}]}
{"op":"mcm","clk":"AK8uAIonANoo","pt":1650392709488,"mc":[{"id":"1.197931750","rc":[{"atb":[[8.8,18.25],[7,23.69]],"atl":[[9.8,18.76],[10,24.67],[9.4,3.12],[9.6,18.44]],"bdatb":[[0,9.2,12.69],[1,9,20.69],[2,8.8,18.36],[4,8.4,23.31],[7,7.8,20.61],[8,7.6,22.74]],"bdatl":[[4,10.5,20.51],[5,11,31.46],[9,13,10.4],[6,11.5,29.53],[2,9.8,18.76],[3,10,24.67],[7,12,25.74],[8,12.5,17.5],[0,9.4,3.12],[1,9.6,18.44]],"id":42930960},{"atb":[[15.5,11.64],[15,11.5],[16.5,0],[16,13.19],[12,20.86]],"atl":[[1000,14.47],[29,1.46],[16.5,0.07],[19,16.42],[18.5,13.75],[22,12.79],[21,15.64],[20,10.65],[19.5,5.58],[17,8.03]],"trd":[[16.5,64.97]],"bdatb":[[2,15,11.5],[0,16,15.02],[1,15.5,13.87],[3,14.5,16.67],[4,14,11.94],[5,13.5,22.49],[6,13,13.28],[7,12.5,12.26],[8,12,23.96],[9,11.5,1.8]],"bdatl":[[0,17,8.1],[7,21,18.32],[9,23,9.55],[3,18.5,13.75],[4,19,16.42],[5,19.5,5.58],[6,20,10.65],[8,22,12.79]],"tv":339.81,"id":40095374},{"atb":[[6.2,29.41],[6.6,2.35],[7.8,23.29],[7.4,83.68],[7.6,22.19],[5.6,1.23]],"bdatb":[[1,7.8,23.54],[2,7.6,22.32],[3,7.4,92.19],[9,6.2,34.98],[7,6.6,9.68],[0,8,31.06],[4,7.2,54.97],[5,7,61.78],[8,6.4,29.35]],"bdatl":[[4,9,15.74],[5,9.2,16.33],[6,9.4,14.3],[7,9.6,11.03],[8,9.8,8.82]],"id":36276560},{"atb":[[21,11.49],[16,17.07]],"bdatb":[[0,21,11.55],[1,20,19.08],[9,16,19.72],[2,19.5,13.12],[5,18,7.67],[7,17,12.48]],"bdatl":[[7,29,6.32],[8,30,7.21]],"id":37947503},{"atb":[[1.39,138.31],[1.47,194.38],[1.53,36.92],[1.52,41.57],[1.48,78.4]],"atl":[[1.54,20.33],[1.55,41.25]],"bdatb":[[9,1.44,78.91],[0,1.53,56.09],[6,1.47,253.35],[7,1.46,362.39],[8,1.45,91.54],[1,1.52,61.17],[2,1.51,166.62],[3,1.5,184.62],[5,1.48,147.98],[4,1.49,119.01]],"bdatl":[[2,1.56,66.42],[3,1.57,160.61],[4,1.58,35.74],[5,1.59,56.29],[6,1.6,106.52],[8,1.62,19.42],[9,1.63,107.67],[0,1.54,20.33],[1,1.55,41.25],[7,1.61,74.71]],"id":39823721},{"atb":[[44,6.56]],"atl":[[350,3.22]],"bdatb":[[0,60,3.83],[1,55,2.81],[3,48,4.38],[7,40,1.49],[5,44,6.56]],"bdatl":[[9,230,1.25]],"id":44331354}],"con":true,"tv":5452.07}]}
{"op":"mcm","clk":"AOsvAJQoAPgp","pt":1650392710489,"mc":[{"id":"1.197931750","rc":[{"atb":[[8.2,13.35],[2.06,1],[8.8,22.22],[9,22.84],[9.4,2.77],[9.2,12.68]],"atl":[[9.8,11.43],[10,19.71],[9.6,1.65],[11.5,26.05],[10.5,18.5],[9.4,0]],"trd":[[9.4,243.28],[9.8,26.5],[9.6,77.04]],"bdatb":[[2,9,23.42],[3,8.8,26.29],[7,8,21.78],[8,7.8,29.55],[4,8.6,16.93],[5,8.4,23.75],[0,9.4,2.77],[1,9.2,12.68],[6,8.2,13.97],[9,7.6,22.23]],"bdatl":[[1,9.8,10.24],[2,10,16.18],[5,11.5,31.86],[6,12,19.11],[7,12.5,25.37],[8,13,10.62],[9,13.5,9.76],[0,9.6,1.78],[3,10.5,18.5],[4,11,26.33]],"ltp":9.8,"tv":575.71,"id":42930960},{"atb":[[16.5,1.54],[15.5,9.75],[11.5,5.26],[16,10.29]],"atl":[[18,13.45],[17,36.2],[19.5,4.86],[1000,13.47],[16.5,0],[17.5,13.57]],"trd":[[16,4],[17,35.7],[16.5,65.04]],"bdatb":[[0,16.5,1.54],[1,16,10.29],[2,15.5,10.09],[3,15,11.5],[4,14.5,17.42],[5,14,11.73],[6,13.5,22.16],[7,13,5.93],[8,12.5,15.19],[9,12,23.39]],"bdatl":[[0,17,36.2],[9,23,8.11],[5,19.5,4.86],[7,21,15.64],[1,17.5,13.57]],"ltp":16,"tv":355.75,"id":40095374},{"atb":[[8.2,14.75],[6.6,7.22],[7.6,26.23],[7,49.33],[7.4,70.79],[7.2,21.55],[8,27.54],[4.5,67.05],[7.8,22.72]],"atl":[[8.4,4.68],[8.6,29.78],[8.8,7.66],[9.4,10.05],[9.2,12.22],[9,13.74],[8.2,0]],"trd":[[8.4,53.38],[8.2,96.8]],"bdatb":[[0,8.2,10.59],[2,7.8,25.79],[3,7.6,30.4],[4,7.4,71.89],[5,7.2,26.64],[6,7,53.67],[7,6.8,27.59],[8,6.6,10.92],[9,6.4,21.44],[1,8,29.68]],"bdatl":[[0,8.6,30.4],[4,9.4,12.75],[5,9.6,10.68],[8,10.5,15.04],[9,11,3.55],[1,8.8,7.66],[6,9.8,12.99],[7,10,48.99],[2,9,13.74],[3,9.2,12.22]],"ltp":8.4,"tv":1123.95,"id":36276560},{"atb":[[21,15.7],[20,17.73]],"atl":[[28,10.31],[26,9.61],[25,15.58],[23,3.16],[22,0]],"trd":[[23,23.54],[22,63.58]],"bdatb":[[0,21,15.7],[1,20,17.99],[3,19,10.35],[4,18.5,15.17],[9,16,19.36],[2,19.5,13.02],[7,17,12.7],[5,18,6.13]],"bdatl":[[2,25,15.58],[3,26,9.61],[5,28,10.31],[8,32,6.1],[9,34,2.02],[0,23,3.16],[1,24,45.84],[4,27,8.69],[6,29,6.32],[7,30,5.33]],"ltp":23,"tv":237.6,"id":37947503},{"atb":[[1.47,39.47],[1.51,52.92],[1.49,57.78],[1.46,100.17],[1.5,84.06],[1.48,71.31],[1.42,38.96],[1.52,0],[1.53,0]],"atl":[[1.54,34.28],[1.53,26.8],[1.55,43.26],[1.56,68.59],[1.59,46.6]],"trd":[[1.52,405.91],[1.53,570.57],[1.51,364.83]],"bdatb":[[1,1.5,150.96],[2,1.49,152.33],[3,1.48,83.43],[4,1.47,232.07],[5,1.46,361.7],[6,1.45,108.54],[7,1.44,89.72],[8,1.43,157.71],[9,1.42,40.33],[0,1.51,55.63]],"bdatl":[[0,1.53,26.8],[2,1.55,59.65],[3,1.56,107.97],[4,1.57,91.97],[5,1.58,104.69],[6,1.59,60.77],[7,1.6,46.94],[8,1.61,130.93],[9,1.62,18.09],[1,1.54,25.84]],"ltp":1.51,"tv":3589.98,"id":39823721},{"atb":[[1.5,2]],"atl":[[90,2.07],[80,0.18],[65,2.7],[75,0],[70,2]],"trd":[[65,14.31]],"bdatb":[[4,46,4.64],[6,42,1.74],[8,38,1.69],[9,36,22.5],[0,60,3.81],[1,55,2.3],[3,48,4.34],[7,40,1.47]],"bdatl":[[2,80,2.18],[3,85,2.01],[4,140,1.47],[5,160,1.02],[6,190,4.88],[7,200,2.39],[8,230,1.25],[9,260,1.19],[1,70,2],[0,65,1.87]],"tv":98.03,"id":44331354}],"con":true,"tv":5981.02}]}
{"op":"mcm","clk":"AIoxAJcpAJUr","pt":1650392711492,"mc":[{"id":"1.197931750","rc":[{"atb":[[9.4,12.04],[9.2,14.84],[9,24.84],[1.08,0.02],[8.4,17.61],[9.6,3.41],[2.06,0],[8.8,20.61],[7.8,26.83],[8.6,15.37]],"atl":[[9.8,1.19],[12,17.45],[9.6,0],[10.5,19.85]],"trd":[[9.8,27.23],[9.6,78.69]],"bdatb":[[1,9.4,15.51],[2,9.2,15.18],[3,9,29.61],[5,8.6,19.17],[6,8.4,20.23],[7,8.2,15.65],[8,8,17.62],[9,7.8,28.05],[0,9.6,3.41],[4,8.8,20.61]],"bdatl":[[7,13,12.15],[8,13.5,8],[0,9.8,1.19],[5,12,27.83],[6,12.5,21.3],[9,14,12.2],[1,10,19.71],[2,10.5,19.85],[3,11,26.33],[4,11.5,26.05]],"ltp":9.8,"tv":578.09,"id":42930960},{"atb":[[2.06,0.42],[16,12.48],[16.5,0]],"atl":[[16.5,2.17],[17,35.28],[24,7.71],[20,13.14]],"trd":[[16,10.72],[16.5,68.55],[17,36.64]],"bdatb":[[0,16,12.48],[3,14.5,21.22],[5,13.5,22.24],[6,13,7],[7,12.5,13.78],[8,12,23.67],[9,11.5,6.09],[2,15,12.27],[1,15.5,9.75],[4,14,10.02]],"bdatl":[[0,16.5,2.17],[1,17,35.28],[2,17.5,13.57],[3,18,13.45],[4,18.5,13.75],[5,19,16.42],[6,19.5,4.86],[7,20,13.14],[8,21,15.64],[9,22,12.79]],"ltp":16,"tv":366.92,"id":40095374},{"atb":[[7,58.14],[7.4,64.72],[7.8,26.42],[8.4,0],[7.6,32.87],[7.2,12.75],[8.2,21.58],[6.8,24.74]],"atl":[[8.8,9.58],[9,10.49],[8.6,12.96],[8.4,0]],"trd":[[8.6,16.95],[8.4,61.5]],"bdatb":[[0,8.2,23],[1,8,30.56],[2,7.8,31.92],[3,7.6,40.08],[4,7.4,67.28],[5,7.2,17.45],[6,7,61.36],[7,6.8,33.78],[9,6.4,24.76],[8,6.6,19.34]],"bdatl":[[8,10.5,5.34],[9,11,9.25],[7,10,58.18],[1,8.8,9.58],[5,9.6,10.61],[0,8.6,12.96],[2,9,10.49],[6,9.8,12.16],[4,9.4,10.05],[3,9.2,12.22]],"ltp":8.6,"tv":1134.74,"id":36276560},{"atb":[[21,15.75],[2.06,0.3],[19,8.98],[19.5,13.75],[18,8.62],[18.5,11.39]],"atl":[[24,45.8],[26,9.61],[25,6.47],[23,1.42],[34,5.49],[28,11.31],[29,5.32]],"trd":[[23,24.54]],"bdatb":[[0,21,15.75],[1,20,19.52],[3,19,11.23],[6,17.5,7.18],[7,17,11.65],[4,18.5,11.39],[8,16.5,12.47],[9,16,17.07],[2,19.5,13.75],[5,18,8.62]],"bdatl":[[1,24,45.8],[8,32,5.31],[0,23,1.42],[2,25,6.47],[3,26,9.61],[9,34,5.49],[6,29,5.32],[5,28,11.31]],"tv":238.6,"id":37947503},{"atb":[[1.47,64.69],[1.49,58.36],[1.5,83.06],[1.48,29],[1.51,0],[1.46,152.06],[1.45,211.58]],"atl":[[1.52,51.78],[1.53,35.8],[1.54,34.24],[1000,13],[1.51,0],[1.57,24.18],[1.55,54.25],[1.56,51.25],[1.58,28.47],[1.63,17.79]],"trd":[[1.51,395.03],[1.52,412.85]],"bdatb":[[0,1.51,7.72],[1,1.5,99.16],[2,1.49,136.62],[3,1.48,67.09],[4,1.47,120.05],[5,1.46,229.06],[6,1.45,221.65],[7,1.44,150.32],[8,1.43,146.89],[9,1.42,54.07]],"bdatl":[[0,1.52,51.78],[1,1.53,35.8],[2,1.54,34.24],[6,1.58,93.18],[7,1.59,63.33],[9,1.61,124.61],[4,1.56,143.69],[5,1.57,57.03],[3,1.55,75.37],[8,1.6,60.3]],"ltp":1.51,"tv":3627.12,"id":39823721},{"atb":[[55,2.34],[1.5,0]],"atl":[[65,2.34],[420,0],[400,0.2],[380,0.19],[370,1.23]],"trd":[[65,14.66]],"bdatb":[[2,50,19.63],[4,46,4.53],[5,44,7.04],[6,42,1.53],[8,38,2.19],[9,36,22.5],[1,55,2.34],[0,60,3.81]],"bdatl":[[0,65,2.34],[9,260,1.19],[2,85,2.19],[3,90,2.07]],"tv":98.38,"id":44331354}],"con":true,"tv":6043.85}]}
{"op":"mcm","clk":"ALwyALUqAKMs","pt":1650392712494,"mc":[{"id":"1.197931750","rc":[{"atb":[[9.4,0],[9.2,10.61],[9.6,0],[8,24.07],[1.08,0],[8.6,13.33]],"atl":[[12,30.24],[11,35.6],[10.5,19.75],[9.8,3.4]],"trd":[[9.4,268.81],[9.2,111.05],[9.6,92.89],[9.8,28.42]],"bdatb":[[0,9.2,11.92],[1,9,24.84],[2,8.8,27.94],[3,8.6,13.33],[4,8.4,18.66],[5,8.2,34.66],[6,8,24.78],[7,7.8,26.83],[8,7.6,34.62],[9,7.4,9.3]],"bdatl":[[4,11.5,30.21],[5,12,35.05],[6,12.5,19.44],[8,13.5,9.25],[9,14,12.2],[2,10.5,19.75],[3,11,35.81],[0,9.8,3.4],[1,10,19.71],[7,13,10.4]],"ltp":9.2,"tv":627.47,"id":42930960},{"atb":[[13.5,19.82],[13,11.54],[12.5,12.68],[16.5,0.14],[2.06,0],[16,12.76]],"atl":[[22,17.28],[19,16.42],[17,32.78],[18,13.45],[16.5,0]],"trd":[[17,37.65],[16.5,72.18]],"bdatb":[[0,16,12.9],[5,13.5,19.82],[7,12.5,24.29],[9,11.5,8.11],[1,15.5,9.75],[2,15,12.3],[3,14.5,16.6],[4,14,14.63],[6,13,12.21],[8,12,20.86]],"bdatl":[[0,17,32.78],[4,19,16.42],[7,21,15.64],[8,22,12.79],[9,23,6.98],[2,18,13.45],[1,17.5,13.57],[3,18.5,13.75],[5,19.5,4.86],[6,20,13.14]],"ltp":17,"tv":371.56,"id":40095374},{"atb":[[7.6,28.12],[8.4,12.86],[7.8,36.27],[8.2,28.39],[8,28.92],[4.9,64.61]],"atl":[[8.6,0],[1000,17.2],[8.8,9.7],[9,19.42]],"trd":[[8.6,20.3]],"bdatb":[[0,8.4,12.86],[1,8.2,29.86],[2,8,31.58],[3,7.8,41.81],[4,7.6,34.27],[5,7.4,79.2],[6,7.2,17.67],[7,7,59.78],[8,6.8,36.88],[9,6.6,19.02]],"bdatl":[[0,8.8,9.7],[1,9,19.42],[2,9.2,12.22],[3,9.4,10.05],[4,9.6,10.61],[5,9.8,8.82],[6,10,54.01],[7,10.5,7.82],[8,11,6.89],[9,11.5,17.37]],"tv":1138.09,"id":36276560},{"atb":[[17,11.92],[21,16.82],[22,5.97],[18.5,9.33],[20,19.73],[19.5,15.87],[2.06,0]],"atl":[[26,18.39],[24,45.24],[23,0],[25,8.47]],"trd":[[24,4.07],[23,25.21],[22,66.18]],"bdatb":[[0,22,5.97],[1,21,16.82],[4,19,10.09],[6,18,11.02],[8,17,15.85],[2,20,20.33],[5,18.5,9.33],[3,19.5,15.87],[9,16.5,12.47],[7,17.5,5.31]],"bdatl":[[0,24,45.24],[7,32,5.31],[8,34,5.49],[9,36,1.52],[1,25,8.47],[2,26,20.52],[3,27,8.69],[4,28,11.31],[5,29,5.32],[6,30,5.33]],"ltp":24,"tv":242.43,"id":37947503},{"atb":[[1.37,11.01],[1.5,33.49],[1.41,9.6],[1.47,74.34],[1.48,19.42],[1.45,263.47],[1.46,100.17]],"atl":[[1.51,7.98],[1.52,42.45],[1.53,123.69],[1.54,61.11]],"trd":[[1.51,414.13]],"bdatb":[[0,1.5,33.49],[2,1.48,117.45],[3,1.47,94.55],[5,1.45,308.45],[6,1.44,107.12],[7,1.43,154.99],[8,1.42,137.25],[9,1.41,78.63],[1,1.49,115.65],[4,1.46,177.17]],"bdatl":[[0,1.51,7.98],[2,1.53,123.69],[3,1.54,62.61],[4,1.55,122.46],[5,1.56,66.18],[6,1.57,86.08],[7,1.58,99.54],[8,1.59,57.21],[9,1.6,114.64],[1,1.52,42.45]],"tv":3646.22,"id":39823721},{"atl":[[390,1.19],[65,1.9]],"trd":[[65,15.11]],"bdatb":[[1,55,2.34],[2,50,19.39],[8,38,1.62],[4,46,4.79],[7,40,1.47],[6,42,1.45],[5,44,6.56]],"bdatl":[[0,65,1.9],[9,260,1.19]],"tv":98.83,"id":44331354}],"con":true,"tv":6124.6}]}
{"op":"mcm","clk":"AOozAMYrAMst","pt":1650392713496,"mc":[{"id":"1.197931750","rc":[{"atb":[[9,5.2],[8.8,13.85],[8.6,14.98],[9.2,0],[7.8,15.84],[8.2,15.37],[8.4,19.62],[8,13.4]],"atl":[[9.2,1.87],[9.8,13.81],[10,23.6],[9.6,11.91],[9.4,3.86],[10.5,20.41],[14,12.2],[11,26.33],[12,19.49]],"trd":[[9.4,271.82],[9.2,124.55],[9,51.2]],"bdatb":[[0,9,7.62],[1,8.8,16.92],[2,8.6,15.37],[3,8.4,23.84],[8,7.4,7.78],[9,7.2,12.94],[4,8.2,35.38],[5,8,15.11],[6,7.8,17.1],[7,7.6,28.56]],"bdatl":[[1,9.6,13.31],[2,9.8,23.24],[3,10,30.08],[0,9.4,2.24],[4,10.5,22.27],[6,11.5,26.4],[7,12,23.11],[8,12.5,21.89],[9,13,11.17],[5,11,32.26]],"ltp":9.4,"tv":680.47,"id":42930960},{"atb":[[14,7.86],[16.5,7.05],[16,12.76],[15.5,11.85],[15,13.54],[12.5,6.68]],"atl":[[17,30.84],[17.5,12.44]],"trd":[[17,43.81],[16.5,74.2]],"bdatb":[[1,16,12.76],[3,15,14.79],[4,14.5,17.25],[5,14,10.02],[6,13.5,22.44],[7,13,16.47],[8,12.5,15.78],[0,16.5,5.39],[2,15.5,13.21],[9,12,20.89]],"bdatl":[[0,17,31.36],[7,21,16.56],[8,22,17.28],[9,23,7.38]],"ltp":17,"tv":379.74,"id":40095374},{"atb":[[7.6,28.12],[8,29.17],[4.7,40.54],[6,19.27],[8.6,8.04],[7.4,53.36],[7.2,24.81],[8.4,19.95],[7.8,28.45]],"atl":[[8.8,11.63],[9.2,5.38],[10.5,10.16],[9,20.86],[9.4,12.05],[1000,15.5],[12.5,9.75],[12,14.91],[11.5,25.4],[11,7.31],[9.6,12.62]],"trd":[[8.4,64.9]],"bdatb":[[2,8.2,30.67],[3,8,30.36],[4,7.8,41.21],[5,7.6,43.08],[6,7.4,53.36],[7,7.2,32.86],[8,7,66.14],[9,6.8,28.86],[0,8.6,4.02],[1,8.4,22.46]],"bdatl":[[2,9.2,5.38],[7,10.5,16.38],[0,8.8,9.63],[4,9.6,12.62],[5,9.8,10.81],[6,10,48.99],[8,11,7.68],[1,9,20.86],[9,11.5,32.3],[3,9.4,12.05]],"ltp":8.4,"tv":1141.49,"id":36276560},{"atb":[[17.5,9.83],[17,7.24],[20,20.44],[18.5,9.76],[18,4.09],[22,6.02],[19.5,15.14]],"atl":[[26,18.39],[25,6.47],[23,1.73],[27,8.77],[29,6.32],[28,10.31],[24,57.95]],"bdatb":[[8,17,9.59],[9,16.5,18.54],[3,19.5,16.59],[4,19,8.98],[6,18,6.06],[7,17.5,11.21],[2,20,21.49],[5,18.5,9.76],[0,22,6.02]],"bdatl":[[0,23,1.73],[2,25,8.48],[3,26,20.52],[4,27,8.77],[8,32,5.92],[9,34,5.49],[1,24,57.95],[5,28,10.31],[6,29,6.32],[7,30,5.33]],"id":37947503},{"atb":[[1.46,175.6],[1.38,127.08],[1.34,368.24],[1.48,50.56],[1.51,12.93],[1.49,72.03],[1.5,43.53],[1.47,64.69],[1.41,29.15]],"atl":[[1.53,56.97],[1.52,23.85],[1.54,37.64],[1.51,0]],"trd":[[1.51,427.22],[1.5,162.71]],"bdatb":[[2,1.49,115.06],[3,1.48,134.08],[4,1.47,135.52],[5,1.46,369.82],[6,1.45,339.04],[7,1.44,48.21],[8,1.43,236.31],[9,1.42,102.82],[0,1.51,12.93],[1,1.5,100.03]],"bdatl":[[6,1.58,86.05],[7,1.59,51.17],[4,1.56,113.99],[5,1.57,68.6],[0,1.52,32.42],[2,1.54,56.36],[3,1.55,57.95],[8,1.6,119.42],[9,1.61,65.16],[1,1.53,139.41]],"ltp":1.51,"tv":3663.99,"id":39823721},{"atb":[[60,4.31],[55,2.6]],"atl":[[65,1.51],[100,2.38],[90,2.7],[95,2.07],[85,0]],"trd":[[65,15.89]],"bdatb":[[5,44,6.99],[7,40,1.71],[8,38,1.06],[2,50,19.81],[9,36,22.5],[4,46,4.53]],"bdatl":[[4,100,2.38],[0,65,1.68],[2,90,2.88],[5,150,1.43],[6,180,1.36],[7,190,4],[8,200,2.39],[9,230,1.25],[3,95,2.07]],"tv":99.61,"id":44331354}],"con":true,"tv":6207.73}]}
{"op":"mcm","clk":"AKY1ANwsAOQu","pt":1650392714498,"mc":[{"id":"1.197931750","rc":[{"atb":[[7.6,22.23],[8.6,13.33],[8.4,21.31],[7.4,19.26],[8.8,11.24]],"atl":[[9.4,5.16],[9.8,21.2]],"bdatb":[[3,8.4,23.81],[4,8.2,17.6],[5,8,21.37],[7,7.6,20.74],[8,7.4,19.67],[9,7.2,2.34],[2,8.6,17.39],[1,8.8,11.24],[0,9,9.23],[6,7.8,15.84]],"bdatl":[[5,10.5,23.58],[7,11.5,27.59],[9,12.5,22.99],[1,9.4,5.16],[3,9.8,21.2],[0,9.2,1.87],[2,9.6,11.91],[4,10,23.6],[6,11,32.26],[8,12,20.83]],"id":42930960},{"atb":[[15.5,15.26],[16,13.11]],"bdatb":[[6,13.5,20.73],[7,13,12.95],[8,12.5,11.78],[2,15.5,16.49],[4,14.5,18.03],[5,14,8.48],[9,12,20.86],[1,16,14.19],[0,16.5,7.05],[3,15,13.54]],"bdatl":[[7,21,17.22],[9,23,7.57],[1,17.5,12.44],[0,17,30.84]],"id":40095374},{"atb":[[1.03,0.38],[8.6,10.84],[8.4,26.76],[8.2,32.64],[8,20.99]],"atl":[[9.2,3.92],[8.8,8.74],[9,11.93]],"bdatb":[[0,8.6,12.84],[1,8.4,29.03],[2,8.2,32.64],[3,8,24.67],[4,7.8,32.37],[5,7.6,28.32],[6,7.4,61.77],[7,7.2,35.61],[8,7,59.04],[9,6.8,36.49]],"bdatl":[[5,9.8,12.21],[8,11,8.92],[0,8.8,8.86],[1,9,11.93],[9,11.5,27.96]],"id":36276560},{"atb":[[17.5,9.83]],"atl":[[26,18.83],[25,8.48],[23,2.48]],"bdatb":[[6,18,4.77],[7,17.5,6.36],[8,17,7.24],[9,16.5,12.47],[4,19,10.52],[3,19.5,15.14],[1,21,17.64],[2,20,21.39]],"bdatl":[[3,26,18.83],[8,32,6.35],[2,25,8.48],[0,23,2.48]],"id":37947503},{"atb":[[1.46,65.1],[1.51,41.54],[1.45,211.58],[1.44,115.03]],"atl":[[1.53,39.24],[1.54,41.41]],"bdatb":[[6,1.45,271.17],[7,1.44,162.43],[0,1.51,33.43],[1,1.5,84.04],[2,1.49,140.54],[3,1.48,87.55],[4,1.47,141.73],[5,1.46,258.59],[8,1.43,236.31],[9,1.42,141.76]],"bdatl":[[8,1.6,115.02],[9,1.61,114.11],[3,1.55,84.18],[4,1.56,76.39],[6,1.58,66.13],[7,1.59,51.67],[1,1.53,39.24],[2,1.54,71.82],[5,1.57,104.49],[0,1.52,23.85]],"id":39823721},{"atb":[[44,4.56]],"atl":[[90,2.93]],"bdatb":[[7,40,1.99],[8,38,1.29],[5,44,4.56],[0,60,4.31],[1,55,2.92],[2,50,19.77]],"bdatl":[[2,90,3.11],[0,65,1.51]],"id":44331354}],"con":true}]}
{"op":"mcm","clk":"AOk2AOEtAPgv","pt":1650392715500,"mc":[{"id":"1.197931750","rc":[{"atb":[[9,7.9]],"atl":[[11.5,24.04],[9.8,23.22],[9.6,13.92],[11,28.03],[9.4,6.98],[9.2,3.23]],"bdatb":[[0,9,12.51],[2,8.6,15.14],[3,8.4,25.98],[7,7.6,30.26],[9,7.2,4.33],[5,8,21.37],[8,7.4,19.59],[4,8.2,15.37]],"bdatl":[[5,10.5,26.37],[6,11,32.92],[7,11.5,25.04],[8,12,19.77],[9,12.5,25.42],[2,9.6,13.92],[3,9.8,23.22],[0,9.2,3.23],[1,9.4,6.98]],"id":42930960},{"atl":[[23,8.28]],"bdatb":[[2,15.5,16.02],[4,14.5,17.67],[5,14,10.6],[6,13.5,19.88],[7,13,13.12],[8,12.5,10.14],[1,16,14.97]],"bdatl":[[7,21,18.62],[9,23,8.65],[8,22,17.28]],"id":40095374},{"atb":[[7.6,26.08],[4.5,71.42],[8,21.37],[1.03,0]],"atl":[[9,7.57],[11,12.15],[8.8,13.28],[9.4,13.56],[10.5,12.94]],"bdatb":[[1,8.4,28.15],[3,8,26.62],[4,7.8,30.08],[5,7.6,26.08],[6,7.4,61.99],[7,7.2,34.38],[8,7,60.3],[0,8.6,14.3]],"bdatl":[[5,9.8,15.21],[7,10.5,18.05],[8,11,13.2],[9,11.5,29.06],[1,9,7.57],[0,8.8,13.28],[6,10,48.99],[3,9.4,13.56],[2,9.2,3.92]],"id":36276560},{"atb":[[22,5.97]],"atl":[[28,8.01],[26,11.62],[32,7.37]],"bdatb":[[2,20,21.02],[4,19,11.19],[5,18.5,10.4],[6,18,4.13],[8,17,7.24],[9,16.5,13.73],[0,22,5.97],[7,17.5,9.83],[1,21,18.23]],"bdatl":[[5,28,8.01],[8,32,9.32],[3,26,11.62],[9,34,5.49]],"id":37947503},{"atb":[[1.51,41.47],[1.46,63.09]],"atl":[[1.52,27.26],[1.54,41.45],[1.53,35.8],[1.6,44.26]],"bdatb":[[0,1.51,61.15],[5,1.46,146.08],[2,1.49,132.2],[3,1.48,76.56],[4,1.47,149.73],[7,1.44,209.84],[1,1.5,87.27],[9,1.42,88.98]],"bdatl":[[0,1.52,27.26],[2,1.54,87.64],[3,1.55,68.5],[4,1.56,75.68],[5,1.57,105.19],[8,1.6,130.24],[9,1.61,107.84],[1,1.53,35.8]],"id":39823721},{"atl":[[65,1.28]],"trd":[[65,16.33]],"bdatb":[[2,50,19.63],[7,40,1.86],[8,38,2.07],[1,55,3.14]],"bdatl":[[0,65,1.28]],"tv":100.05,"id":44331354}],"con":true,"tv":6208.17}]}
{"op":"mcm","clk":"AKY4AIsvAJEx","pt":1650392716502,"mc":[{"id":"1.197931750","rc":[{"atb":[[7.2,6.22]],"atl":[[9.4,2.45],[9.2,0],[9.8,22.99],[12,17.45],[11,26.02],[9.6,11.91]],"trd":[[9.4,276.35],[9.2,127.78]],"bdatb":[[0,9,10.17],[1,8.8,11.24],[2,8.6,16.52],[3,8.4,24.56],[6,7.8,22.28],[7,7.6,24.46],[8,7.4,21.55],[9,7.2,10.98],[4,8.2,15.37],[5,8,21.37]],"bdatl":[[2,9.6,11.91],[3,9.8,22.99],[5,10.5,22.43],[6,11,26.49],[7,11.5,27.19],[8,12,22.89],[0,9.2,1.02],[9,12.5,25.69]],"ltp":9.4,"tv":688.23,"id":42930960},{"atb":[[15.5,16.18],[15,12.59],[14,13.61],[17,0.63],[16.5,9.11],[2.06,0.38],[16,14.13],[12.5,6.26]],"atl":[[19,17.17],[18.5,12.54],[18,10.66],[17.5,7.92],[19.5,6.86],[17,0]],"trd":[[17.5,9.44],[17,46.9]],"bdatb":[[0,16.5,8.27],[1,16,14.13],[2,15.5,15.26],[3,15,15.37],[4,14.5,18.47],[5,14,7.87],[7,13,16.45],[8,12.5,10.28],[9,12,20.87],[6,13.5,19.82]],"bdatl":[[7,22,18.25],[9,24,7.93],[1,18,11.44],[2,18.5,11.74],[4,19.5,6.86],[0,17.5,12.44],[3,19,16.42],[5,20,13.14],[6,21,15.64],[8,23,8.28]],"ltp":17,"tv":385.8,"id":40095374},{"atb":[[8.4,2],[7.8,30.27],[7.4,51.35],[7.6,28.12],[8.2,32.52],[7.2,12.75],[8,19.33],[8.6,0]],"atl":[[9.4,12.05],[8.6,1.16],[9.2,10.79],[9,14.47],[8.8,19.34]],"trd":[[8.6,50.39],[8.4,117.36]],"bdatb":[[0,8.4,3.64],[1,8.2,33.86],[2,8,23.29],[3,7.8,31.4],[4,7.6,36.52],[6,7.2,20.13],[7,7,62.56],[9,6.6,13.74],[5,7.4,53.36],[8,6.8,36.49]],"bdatl":[[0,8.6,5.56],[1,8.8,16.07],[2,9,7.57],[3,9.2,8.76],[4,9.4,13.56],[5,9.6,12.62],[6,9.8,11.51],[7,10,52.61],[8,10.5,13.75],[9,11,17.31]],"ltp":8.6,"tv":1224.04,"id":36276560},{"atb":[[20,18.44],[19.5,13.02],[18.5,11.82],[22,1.2],[17.5,5.31],[21,17.54]],"atl":[[23,16.88],[24,45.24]],"trd":[[23,28.35]],"bdatb":[[0,22,1.63],[1,21,18.06],[2,20,20.44],[3,19.5,16.55],[5,18.5,9.99],[7,17.5,5.31],[8,17,7.25],[4,19,8.98],[6,18,5.36],[9,16.5,12.47]],"bdatl":[[0,23,19.14],[9,34,6.11],[1,24,45.24],[8,32,7.37]],"ltp":23,"tv":245.57,"id":37947503},{"atb":[[1.51,0],[1.47,84.07]],"atl":[[1.51,23.03],[1.52,13.4],[1.57,27.38]],"trd":[[1.51,544.6],[1.52,426.21]],"bdatb":[[0,1.51,73.14],[1,1.5,61.64],[2,1.49,148.77],[3,1.48,69.72],[4,1.47,165.85],[5,1.46,121.84],[6,1.45,323.89],[7,1.44,159.58],[8,1.43,102.02],[9,1.42,174.19]],"bdatl":[[0,1.52,13.4],[3,1.55,67.95],[4,1.56,83.24],[5,1.57,90.38],[7,1.59,48.65],[8,1.6,111.01],[9,1.61,76.04],[2,1.54,41.45],[6,1.58,101.01]],"ltp":1.51,"tv":3794.73,"id":39823721},{"atb":[[55,2.86]],"atl":[[90,5],[70,6.82],[65,0]],"trd":[[65,17.79]],"bdatb":[[0,60,4.47],[2,50,19.61],[4,46,4.53],[6,42,2.11],[8,38,1.78],[1,55,2.86],[9,36,22.5],[7,40,1.47]],"bdatl":[[0,70,2.8],[1,90,3.11],[2,95,2.07],[3,100,2.38],[4,150,1.43],[5,180,1.36],[6,190,4],[7,200,2.39],[8,230,1.25],[9,260,1.19]],"tv":101.51,"id":44331354}],"con":true,"tv":6439.88}]}
{"op":"mcm","clk":"AMM5ALcwALoy","pt":1650392717503,"mc":[{"id":"1.197931750","rc":[{"atb":[[9,8.91],[8.4,19.62],[8.8,13.2],[4.5,74.86],[4,87.34]],"atl":[[9.4,4.51],[9.6,11.91],[120,2.2],[9.8,24.18],[65,4.1]],"bdatb":[[1,8.8,14.55],[3,8.4,26.37],[4,8.2,16.93],[5,8,19.4],[6,7.8,17.86],[9,7.2,15.47],[0,9,8.91],[7,7.6,33.3],[8,7.4,19.26],[2,8.6,13.33]],"bdatl":[[0,9.4,4.51],[9,13,11],[4,10.5,25.97],[5,11,26.3],[6,11.5,29.71],[1,9.6,11.91],[7,12,25.02],[8,12.5,18.43],[2,9.8,24.18],[3,10,23.6]],"id":42930960},{"atb":[[14.5,20.14],[15,10.55],[17,5.07],[17.5,3.34],[16,19.17],[16.5,15.11],[15.5,21.76],[13.5,20.2],[7,43.67],[6,52.41],[2.06,0]],"atl":[[18,3.81],[18.5,11.45],[20,15.16],[19.5,8.87],[19,15.93],[17.5,0],[430,0.61],[200,1.32]],"trd":[[18,56.48],[17.5,28.88]],"bdatb":[[3,16,19.92],[5,15,12.46],[6,14.5,14.73],[7,14,16.39],[9,13,16.45],[2,16.5,15.11],[8,13.5,20.2],[0,17.5,3.34],[1,17,5.07],[4,15.5,21.76]],"bdatl":[[0,18,3.81],[1,18.5,11.45],[6,22,17.28],[8,24,10.28],[2,19,15.93],[3,19.5,8.87],[4,20,15.16],[9,25,3.32],[5,21,15.64],[7,23,8.28]],"ltp":18,"tv":408.22,"id":40095374},{"atb":[[7.8,28.24],[8,19.2],[7.4,8.35],[8.2,29.5],[8.4,0],[4.9,62.54],[4.4,77.07],[3.95,88.82]],"atl":[[8.8,18.92],[8.4,0],[12.5,3.72],[12,8.79],[9.6,10.61],[8.6,15.05],[9.4,12.05],[9.2,10.79],[9,14.47],[55,4.85],[100,2.65]],"trd":[[8.4,131.16],[8.6,51.45]],"bdatb":[[1,8,20.68],[2,7.8,31.91],[3,7.6,31.82],[4,7.4,10.08],[7,6.8,32.25],[8,6.6,11.56],[0,8.2,29.5],[5,7.2,21.62],[9,6.4,25.54],[6,7,70.15]],"bdatl":[[1,8.8,18.92],[0,8.6,15.05],[4,9.4,18.27],[5,9.6,10.93],[6,9.8,8.82],[7,10,50.86],[9,11,18.47],[8,10.5,17.38],[2,9,14.47],[3,9.2,10.79]],"ltp":8.4,"tv":1238.9,"id":36276560},{"atb":[[17.5,9.83],[22,9.89],[20,20.44],[19.5,15.14],[19,5.56],[8.4,35.41],[7.2,42.26]],"atl":[[28,10.31],[26,9.61],[25,6.47],[23,1.76],[780,0.33],[330,0.79]],"trd":[[23,30.43]],"bdatb":[[2,20,21.03],[5,18.5,13.47],[7,17.5,6.81],[8,17,8],[1,21,17.54],[9,16.5,12.47],[0,22,9.89],[4,19,5.56],[3,19.5,15.14],[6,18,4.09]],"bdatl":[[0,23,1.76],[9,34,7.21],[7,30,5.33],[8,32,7.37]],"tv":247.65,"id":37947503},{"atb":[[1.46,227.49],[1.47,84.07],[1.48,57.65],[1.5,43.53],[1.51,40.74],[1.49,72.03],[1.3,1125.93],[1.33,794.02]],"atl":[[1.52,7.8],[1.53,45.46],[1.54,41.45],[1.56,51.08],[2.48,177.05],[1.51,0],[2.2,218.36]],"trd":[[1.52,436.43],[1.51,609.43]],"bdatb":[[1,1.5,71.79],[2,1.49,130.45],[3,1.48,159.66],[4,1.47,161.15],[5,1.46,155.33],[6,1.45,283.5],[7,1.44,121.26],[8,1.43,216.36],[9,1.42,52.73],[0,1.51,40.74]],"bdatl":[[0,1.52,7.8],[8,1.6,45.18],[9,1.61,96.22],[6,1.58,54.32],[7,1.59,131.81],[1,1.53,45.46],[2,1.54,41.45],[3,1.55,106.01],[4,1.56,125.53],[5,1.57,40.95]],"ltp":1.52,"tv":3869.78,"id":39823721},{"atb":[[15.5,18.07],[12.5,22.78]],"atl":[[340,1.43],[330,0.22],[85,2.01],[80,2.21],[1000,13.52]],"bdatb":[[3,48,4.59],[7,40,2.18],[9,36,22.55],[1,55,2.86],[5,44,4.56],[2,50,19.39],[4,46,4.53],[8,38,1.06],[6,42,1.45],[0,60,4.31]],"bdatl":[[1,80,2.21],[2,85,2.01],[3,90,5],[4,95,2.07],[5,100,2.38],[6,150,1.43],[7,180,1.36],[8,190,4],[9,200,2.39],[0,70,6.82]],"id":44331354}],"con":true,"tv":6554.29}]}
{"op":"mcm","clk":"APQ6AN8xAN8z","pt":1650392718503,"mc":[{"id":"1.197931750","rc":[{"atb":[[8.8,18.21]],"atl":[[10.5,20.41],[9.2,0.55],[9.4,8.05],[9.6,13.91]],"trd":[[9.2,129.07]],"bdatb":[[3,8.4,23.33],[1,8.8,18.21],[2,8.6,14.61],[5,8,13.4],[4,8.2,19.73],[6,7.8,26.2],[9,7.2,12.63],[7,7.6,22.23],[8,7.4,30.03]],"bdatl":[[4,10.5,22.99],[6,11.5,28.43],[7,12,18.68],[8,12.5,23.67],[9,13,11.28],[5,11,32.71],[0,9.4,8.6],[1,9.6,13.91]],"ltp":9.2,"tv":689.52,"id":42930960},{"atb":[[17,0],[16.5,12.97],[14.5,14.6],[15,12.59],[16,17.01],[17.5,0],[15.5,13.95]],"atl":[[18,1.78],[1000,14.1],[17.5,34.11],[18.5,14.11],[19,17.17]],"trd":[[17.5,36.24],[18,57.82]],"bdatb":[[0,17,2],[5,14.5,16.75],[7,13.5,22.85],[8,13,11.75],[9,12.5,10.17],[1,16.5,12.97],[2,16,17.01],[3,15.5,14.28],[4,15,12.99],[6,14,13.61]],"bdatl":[[0,17.5,34.11],[7,22,18.51],[9,24,9.93],[2,18.5,14.11],[1,18,3.78],[3,19,17.17],[4,19.5,8.87],[5,20,15.16],[6,21,15.64],[8,23,8.28]],"ltp":17.5,"tv":416.92,"id":40095374},{"atb":[[7.4,18.27],[7.8,38.43],[8,25.8],[8.2,18.44]],"atl":[[8.6,11.78],[8.4,1.31],[12.5,1.71],[12,6.49],[11.5,23.4],[9,21.27]],"trd":[[8.4,132.57]],"bdatb":[[2,7.8,43.19],[3,7.6,32.83],[4,7.4,18.27],[6,7,66.06],[7,6.8,28.3],[9,6.4,37.43],[5,7.2,23.98],[8,6.6,14.21],[1,8,26.44],[0,8.2,18.44]],"bdatl":[[4,9.2,13.74],[6,9.6,11.33],[7,9.8,13.53],[8,10,51.04],[9,10.5,19.16],[0,8.4,1.31],[1,8.6,13.78],[2,8.8,18.92],[3,9,21.27],[5,9.4,12.05]],"tv":1240.31,"id":36276560},{"atb":[[22,14.02],[19,9.12]],"atl":[[23,0],[26,16.82]],"trd":[[23,30.95]],"bdatb":[[4,19,10.76],[7,17.5,11.88],[8,17,7.24],[0,22,11.79],[5,18.5,11.82],[6,18,4.09],[1,21,17.78],[2,20,20.73]],"bdatl":[[6,30,6.23],[9,36,1.65],[0,24,45.24],[1,25,6.47],[2,26,16.82],[3,27,8.77],[4,28,10.31],[5,29,6.32],[7,32,7.37],[8,34,5.49]],"tv":248.17,"id":37947503},{"atb":[[1.49,74.04],[1.5,45.53],[1.52,17.84],[1.48,50.56],[1.51,48.74],[1.46,65.1]],"atl":[[1.53,27.58],[1.54,23.23],[1.57,29.39],[1.55,52.15],[1.52,0]],"trd":[[1.52,444.23]],"bdatb":[[0,1.52,17.84],[1,1.51,56.03],[2,1.5,122.54],[3,1.49,128.91],[4,1.48,210.69],[5,1.47,176.22],[6,1.46,118.72],[7,1.45,226.94],[8,1.44,194.59],[9,1.43,156.19]],"bdatl":[[0,1.53,27.58],[2,1.55,74.08],[3,1.56,126.2],[5,1.58,39.89],[6,1.59,107.34],[8,1.61,147.39],[9,1.62,66.35],[7,1.6,45.84],[1,1.54,23.23],[4,1.57,86.26]],"tv":3877.58,"id":39823721},{"atb":[[55,4.86]],"atl":[[70,6.65]],"trd":[[70,19.72]],"bdatb":[[7,40,2.25],[1,55,4.86],[2,50,19.49],[3,48,4.34],[5,44,4.7],[6,42,1.45],[9,36,22.5]],"bdatl":[[0,70,6.65]],"ltp":70,"tv":101.68,"id":44331354}],"con":true,"tv":6574.18}]}
{"op":"mcm","clk":"AJU8AIozAIo1","pt":1650392719505,"mc":[{"id":"1.197931750","rc":[{"atb":[[9,7.34],[8.8,11.24],[7.6,22.23],[8.6,14.98]],"atl":[[11,22.55],[9.6,17.32],[9.4,14.18],[13,5.93]],"bdatb":[[3,8.4,24.02],[5,8,21.86],[6,7.8,18.05],[0,9,7.34],[7,7.6,32.31],[9,7.2,12.63],[1,8.8,11.24],[2,8.6,14.98],[8,7.4,19.26],[4,8.2,15.37]],"bdatl":[[8,12.5,17.95],[9,13,12.27],[5,11,31.09],[6,11.5,26.05],[0,9.4,14.73],[7,12,24.32],[4,10.5,24.32]],"id":42930960},{"atb":[[16.5,12.91],[16,21.43],[15.5,11.85],[14.5,16.66]],"atl":[[18,35.44],[1000,13.47],[17.5,6.93],[20,14.48],[19.5,13.97]],"trd":[[16.5,74.31]],"bdatb":[[5,14,15.88],[6,13.5,25.21],[7,13,12.87],[0,16.5,12.91],[9,12,27.24],[8,12.5,6.26],[2,15.5,11.85],[3,15,12.59],[4,14.5,17.01],[1,16,21.43]],"bdatl":[[1,18,35.44],[9,24,8.75],[0,17.5,6.93],[4,19.5,13.97],[5,20,14.48],[7,22,19.15]],"ltp":16.5,"tv":417.03,"id":40095374},{"atb":[[5.5,64.17],[5.1,6.83],[8.2,11.81],[7,45.69],[7.6,28.12],[4.7,37.27]],"atl":[[8.4,12.46],[9.4,10.01],[8.8,24.12],[9,23.27],[8.6,13.34]],"bdatb":[[3,7.6,32.98],[6,7,48.03],[7,6.8,33.58],[8,6.6,18.34],[9,6.4,22.1],[0,8.2,11.81],[5,7.2,24.56],[1,8,25.8],[2,7.8,38.43]],"bdatl":[[7,9.8,11.36],[8,10,54.39],[9,10.5,17.21],[0,8.4,12.46],[5,9.4,14.38],[1,8.6,13.34],[2,8.8,24.12],[3,9,23.27],[4,9.2,10.79],[6,9.6,10.61]],"id":36276560},{"atb":[[17.5,9.83]],"atl":[[1000,15.14],[36,5.03]],"bdatb":[[5,18.5,13.55],[8,17,11.23],[7,17.5,9.83],[1,21,17.54],[2,20,20.44],[4,19,9.39],[0,22,14.02]],"bdatl":[[7,32,8.65],[9,36,5.03],[6,30,5.33]],"id":37947503},{"atb":[[1.5,64.85],[1.44,24.12],[1.47,240.99],[1.51,52.28],[1.49,62.38],[1.48,40.98],[1.52,27.04]],"atl":[[1000,14.61],[1.54,24],[1.55,54.85],[1.58,30.48],[1.56,49.08],[1.53,0]],"bdatb":[[3,1.49,152.01],[4,1.48,171.6],[5,1.47,360.58],[6,1.46,136.26],[7,1.45,221.4],[8,1.44,147.09],[9,1.43,102.53],[1,1.51,121.6],[2,1.5,77.46],[0,1.52,27.04]],"bdatl":[[0,1.54,24],[1,1.55,54.85],[2,1.56,111.17],[3,1.57,72.75],[4,1.58,89.72],[5,1.59,74.76],[6,1.6,47.54],[8,1.62,36.16],[9,1.63,29.14],[7,1.61,181.39]],"id":39823721},{"atl":[[360,1.23]],"bdatb":[[9,36,23.38],[2,50,19.39],[5,44,4.56],[7,40,1.6]],"id":44331354}],"con":true,"tv":6574.29}]}
{"op":"mcm","clk":"ALs9AKM0AJk2","pt":1650392720507,"mc":[{"id":"1.197931750","rc":[{"atb":[[7.6,10.91],[9,2.84]],"bdatb":[[7,7.6,21.5],[0,9,2.84],[3,8.4,25.02],[5,8,24.02],[6,7.8,15.84],[8,7.4,23.63],[9,7.2,8.13]],"bdatl":[[7,12,28.08],[8,12.5,18.33],[9,13,8.2],[4,10.5,25.35],[5,11,26.64],[6,11.5,26.99],[1,9.6,17.32]],"id":42930960},{"atl":[[17,1.6],[22,6.05],[21,22.71],[20,7.03],[19,11.93]],"bdatb":[[5,14,16.48],[6,13.5,26.49],[7,13,11.54],[8,12.5,12.7],[9,12,20.86]],"bdatl":[[3,19,11.93],[5,20,7.03],[6,21,22.71],[7,22,7.21],[8,23,9.42],[9,24,7.71]],"id":40095374},{"atb":[[7.6,39.44]],"atl":[[8.4,28.95],[8.8,28.16]],"bdatb":[[3,7.6,45.41],[6,7,46.83],[7,6.8,35.39],[8,6.6,21.44],[9,6.4,18.9]],"bdatl":[[6,9.6,13.36],[8,10,56.24],[9,10.5,13.55],[0,8.4,28.95],[2,8.8,28.16],[5,9.4,12.72],[7,9.8,8.82]],"id":36276560},{"atl":[[1000,13.56]],"bdatb":[[5,18.5,14],[8,17,11.71],[9,16.5,13.03]],"bdatl":[[9,36,5.76],[7,32,8.16]],"id":37947503},{"atb":[[1.5,95.27],[1.48,40.98],[1.45,300.47],[1.52,34.15]],"atl":[[1.54,29.45],[1.56,51.59],[1000,13]],"trd":[[1.52,482.87]],"bdatb":[[7,1.45,394.75],[4,1.48,165.13],[2,1.5,176.57],[0,1.52,34.15],[1,1.51,132.57],[3,1.49,139.39],[5,1.47,388.96],[6,1.46,77.78],[8,1.44,77.99],[9,1.43,106.23]],"bdatl":[[7,1.61,180.02],[8,1.62,12.52],[0,1.54,29.45],[2,1.56,113.68],[3,1.57,46.95],[4,1.58,112.01],[5,1.59,78.07],[9,1.63,53.99]],"tv":3916.22,"id":39823721},{"atb":[[55,4.82]],"atl":[[390,0.19],[370,0.23],[350,2.22],[380,1.19]],"bdatb":[[1,55,4.82],[9,36,23.62]],"id":44331354}],"con":true,"tv":6612.93}]}
{"op":"mcm","clk":"AIM/AMM1AJo3","pt":1650392721605,"mc":[{"id":"1.197931750","rc":[{"atb":[[8.6,16.55],[8.8,11.64],[8.2,13.96],[8.4,17.61],[8,15.44],[7,90.36],[9,0]],"atl":[[10.5,18.4],[9.6,17.7],[9.8,26.2],[9.2,2.22],[9,0.01],[1000,13]],"bdatb":[[1,8.6,17.49],[2,8.4,22.95],[3,8.2,13.96],[6,7.6,14.04],[4,8,26.47],[5,7.8,23.51],[8,7.2,12.45],[9,7,90.83],[0,8.8,9.54],[7,7.4,25.5]],"bdatl":[[0,9.2,2.23],[1,9.4,14.18],[2,9.6,17.32],[3,9.8,24.18],[4,10,23.6],[5,10.5,23.33],[6,11,28.57],[7,11.5,24.68],[8,12,29.35],[9,12.5,17.11]],"id":42930960},{"atb":[[13.5,19.82],[2.06,1],[14.5,14.48],[14,13.61],[12.5,41.04],[16.5,11.85]],"atl":[[20,5.01],[21,19.5],[17.5,34.68],[17,0],[18,7.69]],"trd":[[16.5,76.42],[17,48.26]],"bdatb":[[3,15,13.9],[4,14.5,14.48],[5,14,16.81],[2,15.5,13.17],[6,13.5,25.3],[7,13,13.03],[8,12.5,45.83],[9,12,22.84],[0,16.5,11.86]],"bdatl":[[7,22,6.05],[8,23,9.61],[0,17.5,34.68],[1,18,7.69],[2,18.5,14.11],[3,19,11.93],[4,19.5,13.97],[5,20,7.03],[6,21,19.5],[9,24,7.71]],"ltp":16.5,"tv":420.5,"id":40095374},{"atb":[[5.3,21.38],[6.4,11.47],[6.2,106.33],[8,19.2]],"atl":[[8.4,23.99]],"trd":[[8.4,142.5]],"bdatb":[[2,7.8,40.94],[3,7.6,45.34],[9,6.4,27.89],[1,8,21.76],[8,6.6,9.82],[5,7.2,25.01],[6,7,57.63],[7,6.8,31.52]],"bdatl":[[0,8.4,27.75],[9,10.5,14.87],[5,9.4,10.01],[6,9.6,13.8],[8,10,54.32],[7,9.8,8.82]],"tv":1250.24,"id":36276560},{"atb":[[2.06,1],[17,31.94],[22,13.95],[18.5,9.76],[16.5,10.54]],"atl":[[1000,13.49]],"trd":[[22,66.31]],"bdatb":[[2,20,21.42],[5,18.5,14.25],[9,16.5,11.72],[1,21,18.51],[8,17,36.29],[0,22,14.03],[4,19,9.12]],"bdatl":[[7,32,7.37],[9,36,5.88]],"ltp":22,"tv":248.3,"id":37947503},{"atb":[[1.47,126.66],[1.46,173.59],[1.05,0],[1.49,71.9],[1.45,265.41],[1.48,40.98],[1.51,48.74],[1.18,2222.22],[1.52,20.16]],"atl":[[1.54,23.68],[1.53,26.06],[1.55,56.95],[1.56,53.59]],"trd":[[1.53,570.89],[1.52,542.88]],"bdatb":[[3,1.49,90.5],[7,1.45,342.07],[1,1.51,150.56],[5,1.47,176.58],[6,1.46,260.26],[8,1.44,94.98],[9,1.43,87.22],[0,1.52,20.22],[4,1.48,208.4],[2,1.5,206.14]],"bdatl":[[0,1.53,26.22],[1,1.54,29.13],[8,1.61,138.33],[9,1.62,41.44],[5,1.58,92.97],[6,1.59,81.1],[2,1.55,56.95],[3,1.56,107.38],[4,1.57,37.63],[7,1.6,80.57]],"ltp":1.53,"tv":3976.55,"id":39823721},{"atb":[[2.06,1],[17.5,0],[46,13.42]],"bdatb":[[5,44,5.01],[9,36,23.74],[2,50,19.8],[4,46,13.42],[7,40,1.47]],"id":44331354}],"con":true,"tv":6686.79}]}
{"op":"mcm","clk":"AJRAAOw2AJk4","pt":1650392722607,"mc":[{"id":"1.197931750","rc":[{"atl":[[11.5,21.38]],"bdatb":[[1,8.6,19.31],[6,7.6,11.73],[7,7.4,24.66],[9,7,94.17],[5,7.8,26.05],[0,8.8,11.64],[2,8.4,21.98],[8,7.2,12.91],[4,8,26.95]],"bdatl":[[7,11.5,22.02],[3,9.8,26.2],[2,9.6,17.7],[5,10.5,21.32]],"id":42930960},{"atb":[[15.5,26.49],[14,13.98],[16.5,10.2],[2.06,0]],"atl":[[25,2.04],[17,0],[23,19],[17.5,34.11]],"trd":[[17,51.58]],"bdatb":[[2,15.5,27.81],[3,15,12.8],[4,14.5,14.48],[5,14,16.6],[6,13.5,26.64],[7,13,11.54],[8,12.5,47.42],[9,12,20.86],[0,16.5,10.21]],"bdatl":[[0,17.5,34.11],[1,18,7.69],[2,18.5,14.11],[3,19,11.93],[4,19.5,13.97],[5,20,5.01],[6,21,19.5],[7,22,6.05],[8,23,20.33],[9,24,7.71]],"ltp":17,"tv":423.82,"id":40095374},{"atb":[[1.01,16621.19],[4.5,0],[8,21.65]],"atl":[[9,21.14],[8.4,28.39]],"bdatb":[[1,8,24.21],[2,7.8,38.84],[8,6.6,14.1],[9,6.4,23.48],[0,8.2,11.81],[3,7.6,44.27],[5,7.2,25.55],[6,7,57.07]],"bdatl":[[3,9,21.14],[0,8.4,28.39],[8,10,56.17],[9,10.5,13.11]],"id":36276560},{"atb":[[18,4.38],[2.06,0]],"atl":[[28,9.07],[24,57.32]],"bdatb":[[1,21,18.51],[2,20,20.6],[4,19,9.12],[5,18.5,11.75],[8,17,37.36],[9,16.5,10.54],[0,22,13.96],[6,18,4.38]],"bdatl":[[4,28,9.07],[0,24,57.32]],"id":37947503},{"atl":[[1.61,35.57],[1.53,15.51],[1.54,23.84],[1000,13],[1.55,59.45],[1.56,51.08]],"bdatb":[[7,1.45,316.36],[8,1.44,97.68],[9,1.43,95.81],[0,1.52,20.22],[1,1.51,150.56],[4,1.48,205.68],[5,1.47,220.8],[6,1.46,229.23],[3,1.49,91.65],[2,1.5,208.58]],"bdatl":[[0,1.53,15.51],[8,1.61,159.89],[1,1.54,23.84],[9,1.62,2.53],[2,1.55,59.45],[3,1.56,113.17],[6,1.59,62.48],[7,1.6,67.37],[5,1.58,120.55],[4,1.57,32.97]],"id":39823721},{"atb":[[21,0.25],[14,11.69],[2.06,0],[16.5,6.45]],"atl":[[370,1.23],[350,3.22],[340,0.43]],"bdatb":[[2,50,19.8],[5,44,4.64],[7,40,1.47],[9,36,23.52],[1,55,4.82],[3,48,4.34]],"id":44331354}],"con":true,"tv":6690.11}]}
{"op":"mcm","clk":"AMFBAPc3AKI5","pt":1650392723607,"mc":[{"id":"1.197931750","rc":[{"atb":[[8.8,13.35],[1.01,13002]],"atl":[[12,15.15],[11.5,19.37],[11,20.54],[10.5,16.39]],"bdatb":[[2,8.4,23.95],[5,7.8,23.83],[6,7.6,13.19],[7,7.4,25.5],[1,8.6,19.31],[4,8,27.83],[9,7,100.95]],"bdatl":[[6,11,26.98],[7,11.5,20.74],[8,12,26.13],[9,12.5,17.38],[5,10.5,20.2]],"id":42930960},{"atb":[[15.5,11.85],[16.5,11.96]],"atl":[[17.5,34.94]],"bdatb":[[5,14,17.78],[6,13.5,25.51],[7,13,13.25],[8,12.5,46.03],[9,12,22.3],[2,15.5,13.17],[3,15,12.8],[4,14.5,14.48],[0,16.5,11.97]],"bdatl":[[8,23,20.74],[0,17.5,34.94]],"id":40095374},{"atb":[[8.2,13.51],[1.01,16618.35],[8,19.2],[5.3,22.38]],"atl":[[8.8,20.94],[8.6,25.06]],"bdatb":[[0,8.2,13.51],[3,7.6,46.45],[8,6.6,10.53],[9,6.4,27.16],[1,8,21.76],[2,7.8,38.84],[5,7.2,26.52]],"bdatl":[[6,9.6,14.78],[8,10,55.23],[9,10.5,15.24],[1,8.6,25.06],[2,8.8,20.94]],"id":36276560},{"atb":[[1.34,250],[1.49,71.9],[1.5,90.2],[1.52,26.34],[1.48,55.15],[1.51,57.36]],"atl":[[1.54,34.58],[1.53,15.51],[1.55,63.96]],"trd":[[1.52,562.8]],"bdatb":[[2,1.5,203.51],[3,1.49,159.29],[0,1.52,26.4],[1,1.51,159.17],[4,1.48,161.49],[5,1.47,220.8],[7,1.45,342.1],[8,1.44,66.39],[9,1.43,109.7],[6,1.46,219.35]],"bdatl":[[3,1.56,116.77],[4,1.57,34.71],[5,1.58,115.27],[6,1.59,58.93],[7,1.6,70.89],[1,1.54,34.58],[0,1.53,15.51],[2,1.55,63.96],[9,1.62,10.25]],"ltp":1.52,"tv":3996.47,"id":39823721},{"atl":[[410,1]],"bdatb":[[9,36,23.98],[2,50,19.8],[5,44,4.64],[7,40,1.47]],"id":44331354},{"bdatb":[[5,18.5,12.64],[8,17,36.46],[9,16.5,11.89],[1,21,18.51],[2,20,20.6],[4,19,9.12]],"bdatl":[[9,36,6.14]],"id":37947503}],"con":true,"tv":6710.03}]}
{"op":"mcm","clk":"ANxCAJQ5ALA6","pt":1650392724607,"mc":[{"id":"1.197931750","rc":[{"atb":[[8.8,13.35],[8.4,21.62],[9,4.08],[8.6,17.85],[8,22.01]],"atl":[[10,23.6],[10.5,26.16],[9.2,3.12],[11,30.29],[9.8,24.18],[9.6,16.93],[9,0]],"trd":[[9.2,131.29],[9,51.21]],"bdatb":[[1,8.8,13.35],[6,7.8,25.65],[7,7.6,10.91],[8,7.4,25.5],[9,7.2,12.96],[0,9,4.08],[2,8.6,17.85],[3,8.4,21.62],[4,8.2,22.18],[5,8,33.99]],"bdatl":[[4,10,23.6],[9,12.5,18.81],[0,9.2,3.12],[2,9.6,19.52],[3,9.8,24.48],[5,10.5,30.82],[6,11,37.95],[7,11.5,19.88],[8,12,17.68],[1,9.4,14.18]],"ltp":9.2,"tv":691.75,"id":42930960},{"atl":[[17.5,33.76]],"trd":[[17.5,37.42]],"bdatb":[[1,16,21.43],[3,15,12.59],[4,14.5,16.46],[5,14,16.74],[6,13.5,19.82],[7,13,18.91],[8,12.5,41.04],[9,12,27.24],[2,15.5,11.85],[0,16.5,11.96]],"bdatl":[[2,18.5,15.45],[4,19.5,14.12],[6,21,19.92],[7,22,6.05],[8,23,20.74],[0,17.5,33.76],[9,24,7.71]],"ltp":17.5,"tv":425,"id":40095374},{"atb":[[8,7.2],[8.4,19.17],[5.1,42.03],[7.4,32],[7.6,26.08],[7.2,14.77],[8.2,0]],"atl":[[9.2,8.76],[8.4,0],[8.2,0],[8.8,26.04],[8.6,30.83]],"trd":[[8.4,176.73],[8.2,143.77],[8,42.74]],"bdatb":[[1,8,7.2],[8,6.6,14.58],[9,6.4,23.05],[0,8.4,19.17],[2,7.8,42.11],[3,7.6,31.18],[4,7.4,44.78],[5,7.2,14.95],[6,7,56.62],[7,6.8,31.52]],"bdatl":[[3,9.2,9.08],[0,8.6,30.83],[1,8.8,26.04],[2,9,23.9],[4,9.4,10.01],[5,9.6,11.54],[6,9.8,12.9],[7,10,48.99],[8,10.5,21.53],[9,11,14.92]],"ltp":8.4,"tv":1332.4,"id":36276560},{"atb":[[17,31.94],[20,18.44],[19.5,13.02],[22,1.13],[17.5,5.31],[21,19.81],[18.5,11.82]],"atl":[[23,21.07],[28,6.77],[25,8.48],[24,45.24],[26,18.95],[22,0]],"trd":[[22,105.39]],"bdatb":[[8,17,31.94],[2,20,18.44],[3,19.5,13.02],[6,18,5.97],[7,17.5,7.52],[5,18.5,11.82],[0,22,1.13],[9,16.5,10.54],[1,21,19.81],[4,19,9.12]],"bdatl":[[0,23,21.07],[3,26,20.02],[6,29,6.62],[8,32,8.62],[9,34,5.49],[1,24,45.24],[2,25,8.48],[5,28,6.77],[4,27,8.77],[7,30,5.33]],"tv":287.38,"id":37947503},{"atb":[[1.48,53.14],[1.52,32.21],[1.49,62.38],[1.47,285.59],[1.53,18.17],[1.51,59.74],[1.5,92.2],[1.36,218.95],[1.4,122.79],[1.38,21.55]],"atl":[[1.54,43.79],[1.55,61.86],[1.58,30.72],[1.56,49.08],[1.53,0]],"trd":[[1.53,600.92],[1.52,581.34]],"bdatb":[[4,1.49,183.05],[5,1.48,131.94],[7,1.46,228.79],[8,1.45,287.8],[9,1.44,137.66],[1,1.52,32.21],[2,1.51,78.74],[3,1.5,249.84],[6,1.47,369.25],[0,1.53,18.17]],"bdatl":[[2,1.56,131.97],[3,1.57,33.76],[5,1.59,59.93],[6,1.6,99.91],[8,1.62,17.97],[9,1.63,31.24],[0,1.54,43.79],[1,1.55,77.9],[4,1.58,53.74],[7,1.61,148.37]],"ltp":1.53,"tv":4045.04,"id":39823721},{"atl":[[70,6.36],[390,1.19]],"trd":[[70,20.01]],"bdatb":[[2,50,19.39],[4,46,13.42],[8,38,1.82],[9,36,23.57],[7,40,1.47],[3,48,4.34],[5,44,4.56],[0,60,4.31]],"bdatl":[[5,100,2.63],[6,150,1.45],[0,70,6.36]],"tv":101.97,"id":44331354}],"con":true,"tv":6883.54}]}
{"op":"mcm","clk":"AOpDAKQ6AK07","pt":1650392725608,"mc":[{"id":"1.197931750","rc":[{"atb":[[1.05,4.42],[8.8,16.45],[8,13.4]],"atl":[[9.8,40.35],[9.4,16.18],[11,28.29],[10.5,18.4],[9.6,18.94]],"bdatb":[[0,9,12.11],[1,8.8,25.16],[2,8.6,18.32],[3,8.4,21.62],[4,8.2,20.21],[5,8,15.25],[6,7.8,26.73],[7,7.6,22.02],[8,7.4,20.32],[9,7.2,12.63]],"bdatl":[[5,10.5,23.06],[6,11,28.29],[7,11.5,29],[8,12,15.86],[9,12.5,19.38],[3,9.8,40.35],[1,9.4,16.18],[4,10,23.6],[2,9.6,18.94]],"id":42930960},{"atb":[[16.5,10.2]],"atl":[[17,1.72],[17.5,38.59]],"bdatb":[[0,16.5,11.94],[1,16,24.16],[2,15.5,16.79],[3,15,12.86],[5,14,15.96],[6,13.5,21.55],[7,13,12.68],[8,12.5,47.84],[9,12,20.86],[4,14.5,14.48]],"bdatl":[[0,17,1.72],[1,17.5,38.59],[2,18,7.69],[3,18.5,14.11],[4,19,11.93],[5,19.5,13.97],[6,20,5.01],[7,21,19.5],[8,22,6.05],[9,23,20.59]],"id":40095374},{"atb":[[7.6,28.12],[8.2,15.29],[1.05,2.93],[8,18.47],[8.4,0],[7.4,20.33]],"atl":[[8.4,8.61],[9,21.14],[8.6,15.34],[9.4,12.05],[9.2,10.76],[8.8,20.94]],"trd":[[8.4,215.07]],"bdatb":[[0,8.2,9.54],[1,8,33.43],[2,7.8,38.95],[3,7.6,46.1],[4,7.4,20.33],[5,7.2,26.58],[6,7,58.87],[7,6.8,31.52],[8,6.6,7.58],[9,6.4,30.26]],"bdatl":[[9,10.5,23.49],[0,8.4,8.61],[4,9.2,10.76],[6,9.6,14.43],[7,9.8,10.07],[3,9,21.14],[1,8.6,15.34],[5,9.4,12.05],[2,8.8,20.94],[8,10,48.99]],"tv":1370.74,"id":36276560},{"atb":[[1.05,2.93],[20,17.73],[19,9.87],[21,15.54],[22,0]],"atl":[[27,6.77],[25,17.82],[24,47.24],[26,11.74],[22,6.77]],"trd":[[22,107.65]],"bdatb":[[0,21,16.91],[1,20,19.91],[3,19,14.12],[4,18.5,11.82],[6,17.5,6.9],[7,17,33.32],[9,16,18],[2,19.5,13.02],[5,18,4.38],[8,16.5,10.54]],"bdatl":[[9,32,8.51],[5,27,6.77],[2,24,47.24],[3,25,17.82],[0,22,6.77],[1,23,21.07],[4,26,11.74],[6,28,6.77],[7,29,6.32],[8,30,5.33]],"tv":289.64,"id":37947503},{"atb":[[1.52,16.07],[1.47,74.77],[1.49,71.9],[1.51,73.38],[1.5,73.92],[1.53,0],[1.45,176.52],[1.48,107.04]],"atl":[[1000,13.66],[1.53,115.55],[1.54,57.83],[1.55,56.95],[1.56,61.34]],"trd":[[1.53,620.72]],"bdatb":[[1,1.51,124.12],[2,1.5,110.8],[5,1.47,301.04],[6,1.46,251.17],[9,1.43,163.37],[0,1.52,79.79],[3,1.49,186.08],[4,1.48,235.56],[7,1.45,246.78],[8,1.44,94.39]],"bdatl":[[3,1.56,82.69],[4,1.57,37.2],[5,1.58,114.61],[6,1.59,56.15],[7,1.6,125.28],[8,1.61,141.24],[9,1.62,9.14],[0,1.53,100],[1,1.54,42.93],[2,1.55,54.85]],"tv":4064.84,"id":39823721},{"atb":[[1.05,4.17]],"atl":[[380,0.19],[360,0.23]],"bdatb":[[0,60,4.75],[1,55,4.83],[2,50,20.25],[3,48,4.34],[4,46,15.09],[5,44,4.56],[6,42,1.55],[9,36,23.27],[8,38,1.06]],"bdatl":[[6,150,1.43],[7,180,1.36],[8,190,4],[9,200,2.39],[5,100,2.38]],"id":44331354}],"con":true,"tv":6943.94}]}
{"op":"mcm","clk":"AJRFAJ47AKs8","pt":1650392726609,"mc":[{"id":"1.197931750","rc":[{"atb":[[7.6,10.91],[1.02,3.7],[1.05,1.49],[9,5.78],[8.8,14.75]],"atl":[[9.2,3.02],[9.4,11.35],[9.8,26.2],[9.6,23.59]],"trd":[[9.2,131.49]],"bdatb":[[7,7.6,21.43],[0,9,10.96],[1,8.8,25.54],[3,8.4,26.03],[4,8.2,15.66],[5,8,16.76],[8,7.4,24.44],[9,7.2,7.3],[6,7.8,29.16],[2,8.6,17.85]],"bdatl":[[8,12,24.38],[9,12.5,17.11],[7,11.5,21.28],[0,9.2,3.02],[6,11,36.39],[1,9.4,11.35],[5,10.5,22.03],[2,9.6,23.59],[3,9.8,26.2]],"tv":691.95,"id":42930960},{"atb":[[15.5,14.86],[15,12.59],[1.05,1.62],[14,13.98],[1.02,2.91],[14.5,12.42],[16,22.55],[16.5,12.02],[17,7.48]],"atl":[[17.5,36.58],[19,11.18],[17,0]],"trd":[[17,55.02]],"bdatb":[[3,15.5,20.53],[4,15,13.06],[6,14,16.62],[1,16.5,13.71],[2,16,23.72],[5,14.5,12.42],[8,13,13.61],[0,17,7.48],[7,13.5,20.85],[9,12.5,49.35]],"bdatl":[[0,17.5,36.58],[7,22,6.34],[8,23,20.38],[1,18,7.69],[2,18.5,14.11],[4,19.5,13.97],[5,20,5.01],[6,21,19.5],[9,24,7.71],[3,19,11.18]],"ltp":17,"tv":428.44,"id":40095374},{"atb":[[1.02,3.06],[8.2,18.17],[7.8,37.61],[1.05,0],[4.7,0],[5.1,43.31],[8,16.47]],"atl":[[8.4,5.55],[8.8,29.89]],"trd":[[8.4,215.26]],"bdatb":[[0,8.2,21.56],[2,7.8,38.51],[1,8,29.8],[3,7.6,38.37],[7,6.8,30.86],[8,6.6,7.9],[9,6.4,30.63],[5,7.2,29.21],[6,7,57.11]],"bdatl":[[4,9.2,11.44],[5,9.4,15.43],[9,10.5,15.03],[0,8.4,5.55],[7,9.8,10.24],[6,9.6,10.61],[8,10,56.5],[2,8.8,29.89]],"tv":1370.93,"id":36276560},{"atb":[[1.02,2.74],[1.05,0],[21,13.7]],"atl":[[22,8.75],[25,10.49]],"trd":[[22,107.85]],"bdatb":[[0,21,15.02],[1,20,18.67],[3,19,14.49],[5,18,4.77],[6,17.5,5.31],[7,17,34.12],[8,16.5,10.54],[9,16,19.62]],"bdatl":[[7,29,6.53],[8,30,6.39],[0,22,8.75],[9,32,7.37],[3,25,10.49]],"tv":289.84,"id":37947503},{"atb":[[1.51,73.55],[1.46,173.59],[1.04,0],[1.52,25.06],[1.49,78.95],[1.5,73.92],[1.45,265.41],[1.47,128.67],[1.48,55.15]],"atl":[[1.54,50.6],[1.53,92.49],[1000,13],[1.55,67.04],[1.56,51.25]],"trd":[[1.52,595.4],[1.53,686.68]],"bdatb":[[5,1.47,143.92],[6,1.46,268.39],[7,1.45,317.28],[9,1.43,151.96],[1,1.51,131.72],[2,1.5,112.61],[4,1.48,174.15],[8,1.44,88.14],[0,1.52,55.73],[3,1.49,246.14]],"bdatl":[[5,1.58,104.01],[6,1.59,61],[3,1.56,132.76],[4,1.57,43.29],[9,1.62,35.28],[1,1.54,50.6],[7,1.6,67.93],[8,1.61,154.43],[0,1.53,92.49],[2,1.55,67.04]],"ltp":1.52,"tv":4144.86,"id":39823721},{"atb":[[65,0.1],[1.05,1.24],[1.02,0.29]],"bdatb":[[0,60,4.87],[2,50,19.77],[4,46,15.33],[6,42,1.62],[8,38,1.06],[9,36,23.53],[1,55,4.82]],"id":44331354}],"con":true,"tv":7027.99}]}
{"op":"mcm","clk":"ALZGAL48ALU9","pt":1650392727611,"mc":[{"id":"1.197931750","rc":[{"atb":[[8.8,11.26],[9,8.96],[8.4,23.33],[1.02,1.99]],"atl":[[9.4,16.31],[9.6,18.94]],"trd":[[9,55.05]],"bdatb":[[2,8.6,17.85],[3,8.4,23.33],[5,8,22.84],[6,7.8,18.21],[7,7.6,14.55],[8,7.4,25.82],[9,7.2,9.31],[0,9,8.96],[1,8.8,9.65],[4,8.2,13.96]],"bdatl":[[0,9.2,3.7],[1,9.4,17.95],[3,9.8,26.2],[4,10,23.6],[5,10.5,26.31],[6,11,30.82],[7,11.5,22.47],[8,12,19.66],[9,12.5,18.23],[2,9.6,18.94]],"ltp":9,"tv":695.79,"id":42930960},{"atb":[[15.5,13.69],[14.5,14.62],[17,0],[16,20.55],[16.5,10.2],[1.05,1.52],[1.02,1.99]],"atl":[[17.5,36.83]],"trd":[[17,55.22]],"bdatb":[[0,16.5,10.2],[1,16,20.55],[2,15.5,13.69],[4,14.5,14.62],[5,14,13.98],[6,13.5,25.41],[7,13,11.54],[8,12.5,42.52],[9,12,23.16],[3,15,12.59]],"bdatl":[[0,17.5,38.07],[5,20,5.01],[6,21,21.44],[8,23,19.78],[9,24,8.72],[7,22,6.05]],"tv":428.64,"id":40095374},{"atb":[[4.9,126.45],[7.6,31.88],[8.2,7.7],[1.02,1.17]],"atl":[[8.4,11.2],[8.8,22.32]],"bdatb":[[2,7.8,37.61],[3,7.6,30.01],[4,7.4,24.08],[5,7.2,21.41],[6,7,52.28],[7,6.8,31.87],[8,6.6,10.6],[9,6.4,31.13],[0,8.2,12.79],[1,8,16.47]],"bdatl":[[0,8.4,11.94],[1,8.6,17.14],[3,9,21.14],[4,9.2,15.21],[6,9.6,12.49],[7,9.8,14.12],[9,10.5,16.34],[8,10,48.99],[5,9.4,12.05],[2,8.8,22.32]],"id":36276560},{"atb":[[16.5,5.72],[19,10.63],[1.02,1.99]],"atl":[[23,8.47]],"bdatb":[[3,19,10.63],[6,17.5,5.31],[7,17,31.94],[8,16.5,7.4],[9,16,20.05],[0,21,13.7],[1,20,17.73],[5,18,4.38]],"bdatl":[[0,22,9.03],[1,23,9.14],[4,26,11.74],[5,27,6.77],[6,28,8.24],[9,32,7.93],[7,29,6.32],[8,30,5.33]],"id":37947503},{"atb":[[1.47,287.6],[1.02,11.03],[1.55,4.88],[1.51,59.52],[1.5,75.92],[1.52,46.07],[1.53,26.74],[1.05,0.1],[1.46,166.09],[1.36,216.23]],"atl":[[1.54,0],[1.57,29.39],[1.55,0],[1.56,48.43],[1.59,48.6],[1.53,0]],"trd":[[1.55,213.27],[1.53,871.66],[1.54,359.86]],"bdatb":[[0,1.55,14.03],[1,1.53,26.74],[2,1.52,107.95],[3,1.51,117.15],[4,1.5,105.86],[5,1.49,187.21],[6,1.48,207.42],[7,1.47,134.62],[8,1.46,276.72],[9,1.45,315.63]],"bdatl":[[0,1.56,100.15],[1,1.57,44.8],[2,1.58,70.9],[3,1.59,91.52],[4,1.6,76.18],[5,1.61,165.64],[6,1.62,11.05],[7,1.63,27.74],[8,1.64,97.24],[9,1.65,48.38]],"ltp":1.55,"tv":4617.31,"id":39823721},{"atb":[[50,19.68],[48,4.34],[1.02,0],[60,4.33]],"atl":[[100,0.37],[95,0],[350,2.22],[360,1.23]],"bdatb":[[3,48,4.34],[7,40,1.47],[9,36,22.5],[0,60,4.43],[2,50,19.68],[4,46,13.42],[6,42,1.45]],"bdatl":[[1,80,2.5],[4,140,1.26],[5,160,1.02],[6,190,4.88],[7,200,2.59],[8,230,1.25],[9,260,1.19]],"id":44331354}],"con":true,"tv":7504.48}]}
{"op":"mcm","clk":"ANtHAM49AMI+","pt":1650392728612,"mc":[{"id":"1.197931750","rc":[{"atb":[[8.8,1.32],[8.2,17.73],[8.6,19.87],[1.02,2.88],[8.4,21.32],[8,15.44],[9,0]],"atl":[[10.5,14.25],[10,13.59],[9.2,13.78],[9,6.73],[9.4,18.35],[9.6,25.6]],"trd":[[8.8,15.65],[9,66.4]],"bdatb":[[0,8.8,2.93],[2,8.4,21.32],[3,8.2,23.81],[6,7.6,13.81],[7,7.4,24.77],[8,7.2,15.49],[9,7,92.33],[1,8.6,17.87],[4,8,15.44],[5,7.8,21.35]],"bdatl":[[0,9,6.73],[3,9.6,26.26],[4,9.8,26.57],[5,10,18.06],[6,10.5,25.78],[8,11.5,24.66],[9,12,17.55],[2,9.4,18.35],[7,11,32.11],[1,9.2,6.77]],"ltp":8.8,"tv":711.08,"id":42930960},{"atb":[[15.5,9.23],[14.5,15.6],[15,19.92],[14,10.39],[16,13.31],[16.5,0]],"atl":[[18,9.7],[17.5,38.83],[19.5,11.97],[19,15.33],[17,9.8],[16.5,0],[18.5,16.12]],"trd":[[16.5,76.54]],"bdatb":[[2,15,19.92],[4,14,14.72],[5,13.5,20.08],[6,13,14.84],[7,12.5,42.31],[8,12,21.37],[9,11.5,8.8],[0,16,13.31],[1,15.5,13.95],[3,14.5,14.62]],"bdatl":[[1,17.5,38.83],[2,18,9.7],[7,21,20.25],[9,23,22.66],[4,19,15.66],[5,19.5,12.16],[0,17,9.8],[3,18.5,16.12],[6,20,5.01],[8,22,6.05]],"ltp":16.5,"tv":428.76,"id":40095374},{"atb":[[7.6,41.16],[7.8,28.85],[4.9,102.88],[8.2,0]],"atl":[[8.6,19.06],[8.4,15.36],[8.8,18.11]],"bdatb":[[1,7.8,28.85],[2,7.6,49.13],[3,7.4,20.8],[5,7,54.2],[6,6.8,25.2],[0,8,16.47],[7,6.6,19.43],[9,6.2,119.36],[4,7.2,20.74],[8,6.4,23.04]],"bdatl":[[4,9.2,12.48],[5,9.4,21.01],[2,8.8,19.23],[3,9,21.14],[9,10.5,18.74],[1,8.6,19.06],[6,9.6,10.61],[7,9.8,13.11],[0,8.4,15.36]],"id":36276560},{"atb":[[16.5,5.72],[20,18.34],[21,13.22]],"atl":[[22,10.75]],"bdatb":[[8,16.5,5.72],[3,19,10.63],[6,17.5,8.77],[7,17,32.15],[9,16,19.75],[1,20,18.34],[4,18.5,11.82],[0,21,13.22]],"bdatl":[[9,32,7.86],[5,27,7],[6,28,6.9],[8,30,5.33],[7,29,6.32],[4,26,11.74],[0,22,10.75],[1,23,8.47]],"id":37947503},{"atb":[[1.52,61.18],[1.53,29.65],[1.5,250.61],[1.54,55.77],[1.55,15.54],[1.49,107.27],[1.47,210.49],[1.48,200.95],[1.02,1.99],[1.51,98.26],[1.05,0]],"atl":[[1.57,31.37],[1.58,37.45],[1.56,17.53],[1.55,0],[1.61,50.18],[1.6,46.27],[1.59,50.66]],"trd":[[1.55,234.85]],"bdatb":[[0,1.55,6.39],[1,1.54,64.97],[2,1.53,67.07],[3,1.52,104.16],[4,1.51,169.43],[5,1.5,140.42],[6,1.49,212.63],[7,1.48,329.47],[8,1.47,291.37],[9,1.46,230.03]],"bdatl":[[2,1.58,56.01],[3,1.59,117.3],[8,1.64,74.25],[9,1.65,74.84],[0,1.56,41.06],[1,1.57,27.38],[4,1.6,97.04],[5,1.61,90.33],[6,1.62,48.85],[7,1.63,62.2]],"tv":4638.89,"id":39823721},{"atb":[[55,5.04]],"atl":[[380,1.19],[90,2.3],[70,8.36]],"bdatb":[[3,48,4.34],[7,40,2.98],[9,36,22.59],[2,50,19.68],[6,42,1.45],[8,38,1.06],[1,55,5.04]],"bdatl":[[6,190,4.94],[5,160,1.02],[3,90,2.3],[0,70,8.36],[1,80,2.21],[7,200,2.39]],"id":44331354}],"con":true,"tv":7541.47}]}
{"op":"mcm","clk":"APlIAOw+AOo/","pt":1650392729613,"mc":[{"id":"1.197931750","rc":[{"atb":[[8.4,21.32],[8.2,17.72],[8.6,18.7],[7.8,17.87],[8.8,2.21],[8,17.44],[1.02,1.99]],"atl":[[10.5,12.24],[9,7.96],[10,18.61],[9.6,20.95]],"bdatb":[[5,7.8,22.08],[7,7.4,21.36],[8,7.2,15.25],[9,7,94.38],[4,8,17.96],[2,8.4,21.32],[3,8.2,21.05],[6,7.6,19.27],[1,8.6,18.7],[0,8.8,2.21]],"bdatl":[[8,11.5,20.85],[9,12,20.38],[6,10.5,20.42],[0,9,7.96],[5,10,18.61],[3,9.6,21.61],[7,11,33.05],[1,9.2,13.78],[4,9.8,28.02]],"id":42930960},{"atb":[[15.5,9.29],[16,11.21],[14,12.59],[15,10.55]],"atl":[[17,9.8],[16.5,1.91]],"bdatb":[[0,16,11.21],[1,15.5,9.29],[5,13.5,22.56],[6,13,11.54],[9,11.5,11.39],[4,14,14.55],[7,12.5,46.12],[8,12,20.86],[2,15,10.55],[3,14.5,15.6]],"bdatl":[[0,16.5,1.91],[1,17,11.8],[2,17.5,38.83],[3,18,9.7],[4,18.5,16.12],[5,19,15.66],[6,19.5,12.65],[7,20,5.01],[8,21,19.72],[9,22,6.05]],"id":40095374},{"atb":[[6.6,25.08]],"atl":[[8.4,17.07],[9.4,10.01]],"bdatb":[[9,6.2,128.07],[3,7.4,25.33],[4,7.2,15.78],[5,7,53.72],[7,6.6,28.68],[8,6.4,19.33],[1,7.8,32.35],[2,7.6,41.16],[6,6.8,36.58]],"bdatl":[[9,10.5,14.64],[0,8.4,17.07],[5,9.4,19.14],[2,8.8,20.32],[3,9,21.65],[7,9.8,14.16],[4,9.2,10.76]],"id":36276560},{"atb":[[16.5,10.54]],"atl":[[23,12.21]],"bdatb":[[8,16.5,12.53],[9,16,17.07],[4,18.5,13.3],[6,17.5,5.31],[7,17,32.19]],"bdatl":[[1,23,12.21],[6,28,7.24],[8,30,5.48],[9,32,7.37]],"id":37947503},{"atb":[[1.01,13009.58],[1.5,302.5],[1.49,55.38],[1.39,135.84],[1.48,198.94],[1.52,52.56],[1.53,34.22],[1.51,81.98]],"atl":[[1.57,17.27],[1.61,83.71],[1.64,3.81],[1.58,40.19]],"bdatb":[[5,1.5,392.08],[6,1.49,153.65],[7,1.48,293.25],[8,1.47,281.61],[9,1.46,226.72],[2,1.53,81.05],[4,1.51,107.2],[3,1.52,135.96],[0,1.55,15.54],[1,1.54,55.77]],"bdatl":[[4,1.6,76.57],[5,1.61,144.2],[7,1.63,19.34],[8,1.64,78.45],[9,1.65,37.35],[1,1.57,23.58],[2,1.58,52.49],[6,1.62,48.85],[3,1.59,121.29],[0,1.56,17.53]],"id":39823721},{"bdatb":[[6,42,2.1],[7,40,1.47],[9,36,22.61]],"bdatl":[[6,190,4.99]],"id":44331354}],"con":true}]}
{"op":"mcm","clk":"APlJAIZAAPBA","pt":1650392730614,"mc":[{"id":"1.197931750","rc":[{"atb":[[8.2,17.72],[7.6,18.39],[6.8,295.46],[1.02,5001.99],[1.01,13002.57],[8.6,21.85],[8.8,7.75]],"atl":[[9,0],[9.4,14.9],[12.5,97.11],[11.5,24.62],[10.5,17.16],[9.2,10.08],[10,20.87],[9.6,18.94]],"trd":[[9.2,136.93],[9,74.36]],"bdatb":[[1,8.6,25.59],[2,8.4,21.37],[3,8.2,17.59],[4,8,22.94],[5,7.8,18.94],[7,7.4,25.17],[8,7.2,9.35],[9,7,101.87],[6,7.6,27.17],[0,8.8,7.75]],"bdatl":[[2,9.4,14.9],[4,9.8,26.78],[6,10.5,23.31],[7,11,35.7],[8,11.5,30.23],[9,12,15.9],[1,9.2,10.08],[5,10,20.87],[0,9,1.9],[3,9.6,18.94]],"ltp":9.2,"tv":724.48,"id":42930960},{"atb":[[15,11.5],[14,15.36],[1.02,5001.99],[11,188.48],[15.5,16.91],[8.2,0],[16,11.21]],"atl":[[16.5,1.95],[24,49.71],[20,3.76],[19,15.33],[18,9.7],[17.5,38.83],[17,13.89]],"trd":[[16.5,83.91]],"bdatb":[[3,14.5,16.67],[5,13.5,20.79],[6,13,15.57],[7,12.5,41.04],[8,12,26.42],[9,11.5,9.06],[4,14,15.36],[0,16,11.21],[1,15.5,16.91],[2,15,11.69]],"bdatl":[[0,16.5,1.95],[1,17,13.89],[2,17.5,38.83],[3,18,9.7],[4,18.5,16.12],[5,19,15.33],[6,19.5,12.26],[7,20,3.76],[8,21,19.53],[9,22,8.87]],"tv":436.13,"id":40095374},{"atb":[[7,53.65],[1.02,5001.17],[6.2,429.33],[7.2,12.75],[7.6,30.01],[8.2,8.57],[1.01,16687.47],[8,18.25]],"atl":[[8.4,2.58],[9.4,15],[11,103.15],[10.5,18.25],[19,0],[8.6,18.94]],"trd":[[8.4,229.75]],"bdatb":[[1,8,20.39],[2,7.8,30.83],[4,7.4,29.18],[5,7.2,14.38],[6,7,61.51],[7,6.8,34.48],[8,6.6,30.72],[9,6.4,27.45],[3,7.6,30.01],[0,8.2,8.57]],"bdatl":[[3,9,21.76],[5,9.4,15.07],[7,9.8,17.35],[9,10.5,25.26],[4,9.2,10.76],[6,9.6,17.06],[1,8.6,18.94],[0,8.4,5.44],[8,10,48.99],[2,8.8,18.11]],"tv":1385.42,"id":36276560},{"atb":[[15.5,135.61],[1.02,5001.99],[18,6.56],[12.5,4]],"atl":[[26,14.01],[42,25.46],[22,4.08]],"trd":[[22,113.39]],"bdatb":[[1,20,19.19],[3,19,11.42],[4,18.5,11.84],[7,17,32.71],[9,16,20.35],[5,18,6.56],[6,17.5,5.31],[8,16.5,10.54]],"bdatl":[[5,27,6.97],[9,32,9.32],[4,26,14.01],[6,28,6.77],[0,22,4.08],[8,30,5.33]],"tv":295.38,"id":37947503},{"atb":[[1.48,252.84],[1.52,48.36],[1.51,82.7],[1.54,3.64],[1.47,250.27],[1.5,101.21],[1.02,5001.99],[1.43,1485.47],[1.53,95.56],[1.49,207.83],[1.55,0]],"atl":[[1.62,53.52],[1.55,19.03],[1.6,79.8],[1.64,3.81],[1.56,51.96],[1.58,41.94],[1.61,50.18],[1.65,606],[1.72,14],[1.57,42.48],[1.66,19.69]],"trd":[[1.55,293.15],[1.54,504.81],[1.53,1046.27]],"bdatb":[[0,1.54,3.64],[1,1.53,116.59],[2,1.52,86.25],[3,1.51,161.39],[4,1.5,141.02],[5,1.49,276.45],[9,1.45,333.71],[7,1.47,317.6],[8,1.46,262.67],[6,1.48,327.7]],"bdatl":[[0,1.55,21.03],[1,1.56,42.02],[3,1.58,43.26],[6,1.61,161.4],[7,1.62,17.88],[8,1.63,17.9],[2,1.57,85.91],[4,1.59,142.5],[5,1.6,71.12],[9,1.64,99.56]],"ltp":1.55,"tv":5016.75,"id":39823721},{"atb":[[60,8.33],[28,72.46],[1.02,5000],[42,1.36]],"atl":[[190,9],[410,0],[400,1.2],[390,0.19],[370,0.23],[70,6.62]],"trd":[[70,21.74]],"bdatb":[[2,50,20.02],[3,48,4.34],[4,46,13.75],[6,42,1.37],[9,36,22.86],[0,60,8.43],[8,38,1.06]],"bdatl":[[6,190,9.88],[8,230,1.28],[0,70,6.62]],"tv":103.7,"id":44331354}],"con":true,"tv":7961.86}]}
{"op":"mcm","clk":"AKBLAIxBAIxC","pt":1650392731615,"mc":[{"id":"1.197931750","rc":[{"atb":[[7.2,18.27],[8.8,8.32],[8.2,15.99],[7.4,7.59],[1.01,13002]],"atl":[[9,1.88],[9.6,30.97]],"bdatb":[[1,8.6,23.77],[3,8.2,16.61],[5,7.8,19.39],[6,7.6,29.37],[7,7.4,8.19],[2,8.4,21.32],[4,8,25.89],[9,7,101.87],[8,7.2,31.16],[0,8.8,8.32]],"bdatl":[[7,11,39.64],[8,11.5,27.33],[0,9,1.88],[1,9.2,10.08],[2,9.4,14.9],[3,9.6,30.97],[4,9.8,26.84],[5,10,21.6],[6,10.5,22.55],[9,12,19.42]],"id":42930960},{"atb":[[16,9.21],[14.5,14.62]],"atl":[[17,14.71]],"bdatb":[[2,15,12.6],[4,14,15.38],[6,13,17.65],[8,12,27.81],[9,11.5,5.64],[3,14.5,14.62],[5,13.5,20.17],[7,12.5,41.04],[0,16,9.21]],"bdatl":[[6,19.5,12.29],[7,20,4.13],[8,21,19.5],[9,22,8.63],[1,17,14.71]],"id":40095374},{"atb":[[7.6,41.33],[8,19.5]],"atl":[[1000,18.52],[8.8,26.99]],"bdatb":[[1,8,21.57],[2,7.8,28.89],[4,7.4,29.65],[5,7.2,13.93],[6,7,64.99],[8,6.6,25.16],[3,7.6,43.34],[7,6.8,38.39],[9,6.4,25.19]],"bdatl":[[8,10,53.76],[9,10.5,24.53],[3,9,21.83],[4,9.2,11.56],[5,9.4,15],[6,9.6,16.81],[7,9.8,16.39],[2,8.8,26.99],[0,8.4,2.58]],"id":36276560},{"atb":[[1.41,0]],"atl":[[22,4.06]],"trd":[[22,113.43]],"bdatb":[[1,20,19.16],[4,18.5,11.84],[9,16,21.38],[3,19,10.63],[5,18,6.56],[6,17.5,5.58],[8,16.5,11.18],[7,17,31.94]],"bdatl":[[5,27,7],[6,28,7.04],[9,32,9.14],[0,22,4.06]],"tv":295.42,"id":37947503},{"atb":[[1.52,66.44],[1.53,118.65],[1.51,80.32],[1.49,207.83],[1.54,8.85],[1.45,176.52],[1.08,0]],"atl":[[1.55,10.69],[1.64,43.44],[1000,13],[1.58,58.76],[1.57,55.93],[1.56,54.23]],"trd":[[1.54,513.33],[1.53,1058.79]],"bdatb":[[1,1.53,132.81],[2,1.52,110.95],[3,1.51,143.39],[5,1.49,301.61],[0,1.54,8.85],[4,1.5,166.38],[6,1.48,381.36],[7,1.47,317.6],[8,1.46,262.67],[9,1.45,287]],"bdatl":[[0,1.55,10.69],[9,1.64,116.56],[2,1.57,100.69],[3,1.58,60.6],[4,1.59,146.96],[5,1.6,101.52],[6,1.61,142.38],[7,1.62,72.43],[8,1.63,24.65],[1,1.56,54.23]],"ltp":1.54,"tv":5037.79,"id":39823721},{"atb":[[21,0],[2.06,1]],"atl":[[420,1]],"bdatb":[[2,50,20.01],[6,42,1.37],[4,46,13.42],[8,38,1.19],[9,36,22.5]],"bdatl":[[8,230,1.32]],"id":44331354}],"con":true,"tv":7982.94}]}
{"op":"mcm","clk":"ALNMAKFCAJ1D","pt":1650392732617,"mc":[{"id":"1.197931750","rc":[{"atb":[[8.8,8.97],[8.2,17.72],[6,82.3]],"bdatb":[[3,8.2,17.72],[2,8.4,23.31],[4,8,26.51],[5,7.8,19.4],[6,7.6,24.35],[7,7.4,13.35],[1,8.6,21.85],[0,8.8,10.59]],"bdatl":[[6,10.5,23.08],[7,11,42.61],[8,11.5,28.35],[9,12,15.77],[5,10,20.99]],"id":42930960},{"atb":[[13.5,22.25],[16,8.43],[9,50],[5.1,0],[5.6,21.74]],"atl":[[17.5,17.48],[17,42.47],[18.5,13.96],[18,20.2],[20,11.97]],"trd":[[16,12.28]],"bdatb":[[0,16,8.43],[3,14.5,15.77],[5,13.5,19.83],[6,13,18.03],[8,12,24.63],[9,11.5,8.96],[2,15,11.5],[4,14,15.36]],"bdatl":[[1,17,42.47],[9,22,8.88],[2,17.5,13.37],[4,18.5,13.96],[3,18,20.2],[7,20,12.03]],"ltp":16,"tv":437.69,"id":40095374},{"atb":[[7,12.67],[5.8,84.79],[8.2,8.5],[7.8,34.67],[8,25.06]],"atl":[[1000,15.5],[8.8,24.86],[9.4,17.04],[8.4,0],[9,19.14],[8.6,17.04]],"trd":[[8.2,144.14],[8.4,233.17]],"bdatb":[[0,8.2,8.5],[8,6.6,37.29],[9,6.4,27.27],[6,7,24.03],[1,8,27.15],[2,7.8,34.69],[4,7.4,29.67],[5,7.2,13.91]],"bdatl":[[1,8.8,24.86],[6,9.8,13.08],[7,10,58.22],[0,8.6,17.04],[2,9,19.83],[4,9.4,17.04],[8,10.5,23.05],[9,11,109.8],[3,9.2,10.89],[5,9.6,19.54]],"ltp":8.2,"tv":1389.21,"id":36276560},{"atb":[[14.5,0.14],[10,88.77]],"atl":[[24,52.41]],"bdatb":[[3,19,11.51],[6,17.5,5.32],[9,16,21.39],[1,20,18.34],[4,18.5,11.82],[8,16.5,11.46]],"bdatl":[[9,32,9.31],[2,24,52.41],[6,28,6.82]],"id":37947503},{"atb":[[1.48,196.78],[1.47,335.38],[1.43,2415.7],[1.53,143.65],[1.52,81.28],[1.51,82.6],[1.54,4.86]],"atl":[[1.6,77.79],[1.55,10.79],[1000,13],[1.64,23.62]],"trd":[[1.54,521.31]],"bdatb":[[4,1.5,247.05],[5,1.49,273.83],[6,1.48,304.99],[8,1.46,200.12],[9,1.45,301.47],[7,1.47,476.27],[1,1.53,154.71],[3,1.51,120.5],[2,1.52,128.91],[0,1.54,4.86]],"bdatl":[[2,1.57,100.33],[3,1.58,73.6],[4,1.59,161.98],[5,1.6,82.45],[8,1.63,67.14],[6,1.61,124.35],[7,1.62,92.46],[9,1.64,41.26],[0,1.55,10.79]],"tv":5045.77,"id":39823721},{"atb":[[30,0],[29,0.45],[28,71],[27,0],[26,0],[25,0],[24,0],[44,3.22],[42,0],[40,0.05],[38,0],[36,21.09],[34,0.13],[32,0.56],[15,46.43],[2.06,0]],"atl":[[490,0],[480,0],[470,0],[460,0],[450,0],[440,0],[400,1],[390,0],[380,1],[370,0],[360,1],[350,2],[340,0],[330,0],[320,0],[310,0],[300,0],[290,0],[280,0],[270,2],[260,0],[250,0],[240,0],[230,0.22],[220,0],[210,0],[200,2],[180,0],[170,0],[160,0],[150,0],[140,0]],"bdatb":[[2,50,19.68],[4,46,13.78],[6,42,1.36],[8,38,1.07]],"bdatl":[[8,230,1.29]],"id":44331354}],"con":true,"tv":7996.27}]}
{"op":"mcm","clk":"AMhNAM9DAJtE","pt":1650392733620,"mc":[{"id":"1.197931750","rc":[{"atb":[[8.4,19.31],[7.8,22.5],[8.8,1.61],[6,80.84],[1.02,5000],[8.2,18.73],[1.01,13000],[7.2,16.81],[8.6,21.84],[1.41,0.02]],"atl":[[15.5,4.22],[15,0],[13.5,5.67],[9.2,10.19],[9,6.6],[1000,13.02],[9.6,34.08]],"trd":[[8.8,33.59],[8.6,22.26]],"bdatb":[[0,8.6,23.5],[1,8.4,21.61],[2,8.2,20.74],[3,8,27.55],[4,7.8,22.34],[5,7.6,22.01],[6,7.4,15.74],[7,7.2,31.16],[8,7,93.72],[9,6.8,303.85]],"bdatl":[[0,9,5.48],[4,9.8,26.2],[5,10,21.49],[6,10.5,24.76],[8,11.5,24.99],[9,12,19.25],[7,11,41.64],[3,9.6,34.08]],"ltp":8.6,"tv":742.44,"id":42930960},{"atb":[[15,9.46],[14.5,14.45],[14,17.52],[13.5,18.27],[1.02,5000],[1.01,13001.77],[16,0],[8,8.98],[15.5,15.3]],"atl":[[19,20.03],[18.5,19.35],[17.5,19.96],[18,18.9],[16.5,8.47],[17,44.47]],"trd":[[16,25.03]],"bdatb":[[4,13.5,18.69],[5,13,15.25],[6,12.5,42.21],[7,12,23.34],[8,11.5,10.3],[9,11,195.94],[0,15.5,15.3],[1,15,12.45],[2,14.5,16.82],[3,14,15.36]],"bdatl":[[2,17.5,22.79],[3,18,18.9],[5,19,24.16],[6,19.5,11.97],[7,20,11.97],[8,21,19.85],[9,22,6.05],[0,16.5,8.47],[1,17,44.47]],"tv":450.44,"id":40095374},{"atb":[[5.9,0],[5.7,0],[1.02,5000],[5.8,83.33],[1.01,16685.47],[1.41,0.02],[6,22.57],[8.2,10.5],[7,17.89],[7.8,39.3],[8,25.04],[5.6,3.23]],"atl":[[9.8,7.36],[18,0],[17.5,0],[17,0],[16.5,0.95],[16,0],[9.6,9.15],[15.5,0.81],[9.4,15.58],[15,17.54],[14.5,0.65],[14,19.03],[13.5,4.06],[13,8.19],[12.5,0.25],[12,3.57],[1000,15.52],[8.6,9.69],[9,25.98],[8.4,1.7]],"bdatb":[[2,7.8,43.47],[3,7.6,46.59],[5,7.2,16.89],[6,7,26.18],[4,7.4,23.42],[0,8.2,10.5],[8,6.6,36.78],[9,6.4,26.08],[1,8,27.13]],"bdatl":[[3,9,25.98],[4,9.2,10.76],[5,9.4,17.71],[6,9.6,10.73],[7,9.8,8.82],[8,10,67.03],[9,10.5,22.55],[1,8.6,9.69],[0,8.4,1.7],[2,8.8,24.86]],"id":36276560},{"atb":[[15.5,134.15],[15,0],[14,0],[13.5,2.78],[13,0.59],[12.5,2.54],[12,14.58],[1.02,5000],[11,44.82],[1.01,13001.66],[16,15.61],[16.5,9.08],[8,8.98],[19,12.93]],"atl":[[30,3.87],[29,4.86],[28,3.86],[44,0],[42,24],[40,0],[38,0],[36,3.57],[34,4.03],[32,5.91]],"bdatb":[[6,17.5,7.17],[8,16.5,13.47],[9,16,17.98],[3,19,13.05],[1,20,19.05]],"bdatl":[[5,27,6.77],[6,28,6.77],[9,32,7.56]],"id":37947503},{"atb":[[1.02,5000],[1.01,13007.58],[1.54,4.79],[1.53,147.4],[1.43,2488.86],[1.51,89.08],[1.49,259.72]],"atl":[[1000,14.61],[1.56,64.36]],"trd":[[1.54,521.44]],"bdatb":[[1,1.53,179.64],[2,1.52,113.07],[3,1.51,118.48],[4,1.5,217.45],[6,1.48,295.13],[7,1.47,471.58],[0,1.54,4.79],[8,1.46,225.18],[9,1.45,246.86],[5,1.49,358.54]],"bdatl":[[2,1.57,55.93],[3,1.58,113.25],[4,1.59,114.61],[5,1.6,133.92],[6,1.61,55.66],[7,1.62,103.17],[8,1.63,122.12],[9,1.64,57.77],[1,1.56,61.23]],"tv":5045.9,"id":39823721},{"atb":[[8,8.98],[60,14.33],[27,2]],"bdatb":[[6,36,22],[7,34,1.31],[8,30,1.31],[9,28,71.45],[0,60,14.43],[5,44,3.22],[2,50,19.97],[4,46,13.47]],"bdatl":[[6,270,2.22],[4,190,9.72],[5,200,2],[7,350,2],[8,360,1],[9,380,1]],"id":44331354}],"con":true,"tv":8027.11}]}
{"op":"mcm","clk":"AN1OANZEAKdF","pt":1650392734622,"mc":[{"id":"1.197931750","rc":[{"atb":[[7,102.81],[7.2,4.76],[8.4,19.31],[8.2,17],[8,19.21],[8.6,21.68],[8.8,0],[1.41,0]],"atl":[[9.4,24.16],[1000,13],[9.8,20.55],[10,18.61],[9.6,20.95],[9,8.29],[9.2,12.22],[8.8,5.71]],"trd":[[8.8,38.48],[8.6,22.29]],"bdatb":[[7,7.2,17.65],[8,7,108.12],[2,8.2,18.04],[3,8,26.38],[4,7.8,28.01],[5,7.6,28.6],[6,7.4,8.97],[9,6.8,301.84],[1,8.4,19.31],[0,8.6,21.68]],"bdatl":[[8,11,33.81],[9,11.5,34.64],[3,9.4,24.16],[5,9.8,21.19],[6,10,19.63],[7,10.5,29.21],[4,9.6,20.95],[1,9,8.29],[2,9.2,12.22],[0,8.8,5.71]],"ltp":8.8,"tv":747.36,"id":42930960},{"atb":[[14.5,29.75],[14,17.52],[15,10.55],[15.5,28.68],[16,6.66]],"atl":[[16,0],[16.5,11.31],[17.5,23.1],[17,44.47],[22,6],[18,11.71]],"trd":[[16,28.19]],"bdatb":[[3,14.5,30.34],[4,14,20.49],[2,15,10.55],[6,13,14.84],[1,15.5,28.68],[0,16,6.66],[5,13.5,19.44],[7,12.5,41.04],[8,12,28.18],[9,11.5,5.26]],"bdatl":[[0,16.5,11.31],[1,17,44.47],[2,17.5,23.1],[3,18,11.71],[4,18.5,19.35],[5,19,20.03],[6,19.5,11.97],[7,20,11.97],[8,21,20.28],[9,22,6]],"tv":453.6,"id":40095374},{"atb":[[7,25.12],[7.6,30.01],[8,23.27],[8.2,17.44],[1.41,0]],"atl":[[8.8,33.11],[1000,17.5],[8.6,7.67],[8.4,0]],"trd":[[8.4,234.89],[8.6,51.48]],"bdatb":[[3,7.6,37.73],[6,7,30.9],[1,8,24.34],[2,7.8,44.64],[4,7.4,22.47],[5,7.2,22.75],[7,6.8,32.44],[8,6.6,30.72],[9,6.4,32.96],[0,8.2,17.44]],"bdatl":[[8,10.5,19.9],[9,11,114.38],[1,8.8,33.11],[3,9.2,11.44],[4,9.4,16.67],[5,9.6,9.15],[6,9.8,16.55],[7,10,56.98],[0,8.6,7.67],[2,9,25.98]],"ltp":8.6,"tv":1390.96,"id":36276560},{"atb":[[19,12.18],[19.5,13.75],[21,15.19]],"atl":[[27,8.77],[25,8.48],[24,50.41],[23,14.21],[22,0]],"trd":[[22,114.09]],"bdatb":[[2,19.5,14.18],[3,19,12.18],[5,18,8.88],[8,16.5,11.69],[1,20,18.34],[9,16,15.61],[6,17.5,6.21],[0,21,15.19]],"bdatl":[[1,24,50.41],[2,25,8.48],[4,27,8.77],[6,29,5.07],[8,32,6.23],[9,34,4.03],[0,23,14.21],[3,26,14.01],[5,28,3.86],[7,30,3.87]],"tv":296.08,"id":37947503},{"atb":[[1.53,122.4],[1.49,110.45],[1.4,22.54],[1.36,104.56],[1.48,194.77],[1.54,10.69]],"atl":[[1.55,5.53],[1.63,51.53],[1000,13]],"trd":[[1.55,305.72],[1.54,524.66]],"bdatb":[[1,1.53,155.24],[5,1.49,202.76],[4,1.5,160.9],[6,1.48,330.69],[7,1.47,451.81],[8,1.46,186.82],[9,1.45,228.65],[3,1.51,163.53],[0,1.54,10.69],[2,1.52,130.34]],"bdatl":[[0,1.55,5.53],[8,1.63,90.19],[9,1.64,78.88],[7,1.62,139.56],[6,1.61,68.62],[3,1.58,149.29],[4,1.59,77.97],[5,1.6,160.6],[1,1.56,64.36]],"ltp":1.55,"tv":5061.69,"id":39823721},{"atl":[[70,4.42]],"trd":[[70,21.95]],"bdatb":[[4,46,13.61],[6,40,1.09],[8,32,2.03],[9,28,71.99],[2,50,19.68],[1,55,5.04],[7,36,21.53]],"bdatl":[[0,70,4.42],[7,350,2]],"tv":103.91,"id":44331354}],"con":true,"tv":8053.6}]}
{"op":"mcm","clk":"AP9PAOZFAL5G","pt":1650392735623,"mc":[{"id":"1.197931750","rc":[{"atb":[[6.6,7.63],[6.8,294],[5.8,0],[6.4,0.69],[8,17.75],[8.4,24.23],[8.6,17.91],[7.2,16.81]],"atl":[[15.5,2.76],[14.5,0],[13,4.47],[12,13.69],[11.5,23.16],[9.2,24.37],[9.8,15.9],[11,21.64],[9,15.83]],"bdatb":[[1,8.4,24.23],[0,8.6,17.91],[4,7.8,27.5],[6,7.4,11.38],[7,7.2,25.34],[8,7,105.83],[9,6.8,304.19],[5,7.6,26.75],[2,8.2,17],[3,8,27.45]],"bdatl":[[6,10,26.09],[7,10.5,20.96],[8,11,35.33],[9,11.5,27.71],[2,9.2,24.37],[1,9,15.83],[5,9.8,15.9],[3,9.4,24.83],[4,9.6,22.72]],"id":42930960},{"atb":[[9.8,0],[9.6,0],[9.4,0],[14.5,16.17],[14,14.6],[13,10.08],[12.5,39.58],[12,19.4],[11.5,3.8],[11,187.02],[10.5,36.12],[10,27.5],[9.2,0],[16,6.89],[15.5,26.26],[15,17.3]],"atl":[[30,0.31],[29,0],[28,1.45],[27,0.68],[26,0.46],[25,0.58],[23,6.82],[17,15.89],[40,0],[38,0],[36,0],[34,0.46],[32,0.39],[19,18.03],[16.5,11.92],[19.5,14.52],[17.5,19.79]],"bdatb":[[0,16,6.89],[6,13,14.54],[9,11.5,7.36],[8,12,26.15],[1,15.5,26.26],[2,15,17.3],[3,14.5,17.63],[4,14,21.1]],"bdatl":[[0,16.5,11.92],[5,19,18.36],[8,21,23.06],[1,17,16.71],[6,19.5,15.39],[2,17.5,19.79]],"id":40095374},{"atb":[[8.2,16.83]],"atl":[[8.4,2.85],[1000,19.2],[8.8,24.23],[9,19.14]],"trd":[[8.2,145.36]],"bdatb":[[3,7.6,37.22],[5,7.2,16.11],[6,7,34.45],[8,6.6,31.63],[9,6.4,24.67],[0,8.2,16.83],[4,7.4,28.91],[7,6.8,36.58],[1,8,23.27],[2,7.8,45.74]],"bdatl":[[6,9.8,8.6],[7,10,53.37],[8,10.5,31.08],[9,11,110.47],[4,9.4,23.54],[1,8.8,24.23],[2,9,21.72],[3,9.2,10.76]],"ltp":8.2,"tv":1392.18,"id":36276560},{"atb":[[18,9.05],[18.5,9.33],[21,17.58]],"atl":[[28,4.86],[29,3.86],[24,45.24],[23,16.6]],"bdatb":[[8,16.5,11.45],[5,18,11.84],[4,18.5,9.33],[0,21,17.58],[2,19.5,13.75]],"bdatl":[[8,32,8.24],[5,28,4.86],[6,29,3.86],[1,24,45.24],[0,23,16.6],[3,26,14.25],[4,27,9.39]],"id":37947503},{"atb":[[1.52,83.52],[1.39,238.92],[1.5,248.61],[1.54,48.57],[1.43,2582.12],[1.53,124.56],[1.55,15]],"atl":[[1.56,67.32],[1.57,40.47],[1.58,56.63],[1.6,79.8],[1.55,0]],"trd":[[1.55,325.72]],"bdatb":[[1,1.54,48.57],[3,1.52,177.25],[4,1.51,146.34],[5,1.5,323.72],[9,1.46,255.34],[7,1.48,261.65],[8,1.47,435.02],[2,1.53,157.4],[6,1.49,150.42],[0,1.55,15]],"bdatl":[[5,1.61,70.88],[7,1.63,63.96],[8,1.64,104.94],[9,1.65,657.72],[0,1.56,67.32],[3,1.59,60.7],[4,1.6,186.16],[2,1.58,143.99],[6,1.62,139.56],[1,1.57,40.47]],"tv":5081.69,"id":39823721},{"atb":[[1.5,2]],"atl":[[75,1.1]],"bdatb":[[8,32,1.91],[9,29,2.64],[4,46,13.42],[6,40,1.31]],"bdatl":[[1,75,1.1],[2,80,2.21],[3,85,2.01],[4,90,2.3],[5,190,9.87],[6,200,2],[7,270,2.22],[8,350,2],[9,360,1]],"id":44331354}],"con":true,"tv":8074.82}]}
{"op":"mcm","clk":"AI5RAIBHAOZH","pt":1650392736626,"mc":[{"id":"1.197931750","rc":[{"atb":[[8.6,24.72],[8.4,27.88]],"atl":[[9,15.59],[8.8,0],[9.2,28.94]],"trd":[[9,76.03],[8.8,44.19]],"bdatb":[[0,8.8,1.99],[1,8.6,24.72],[2,8.4,27.88],[3,8.2,17],[4,8,18.62],[5,7.8,35.06],[6,7.6,26.75],[7,7.4,16.98],[8,7.2,19.59],[9,7,110.82]],"bdatl":[[0,9,17.26],[1,9.2,28.94],[2,9.4,24.16],[3,9.6,20.95],[4,9.8,15.9],[5,10,18.61],[6,10.5,17.16],[7,11,29.93],[8,11.5,27.24],[9,12,20.99]],"ltp":9,"tv":754.74,"id":42930960},{"atb":[[16,0]],"atl":[[16.5,41.79],[21,24.22]],"trd":[[16.5,87.56],[16,33.1]],"bdatb":[[0,16,10.05],[3,14.5,16.17],[4,14,14.6],[5,13.5,18.79],[6,13,17.62],[9,11.5,3.8],[7,12.5,39.58],[8,12,24.69]],"bdatl":[[0,16.5,40.4],[5,19,18.03],[6,19.5,14.52],[8,21,24.22],[1,17,15.89]],"ltp":16,"tv":462.16,"id":40095374},{"atb":[[7.6,41.33]],"atl":[[9,19.14],[8.6,2.27],[8.4,0],[9.4,13.54],[1000,17.5],[8.8,26.25]],"trd":[[8.4,244.15],[8.6,56.88]],"bdatb":[[0,8.4,2.09],[1,8.2,16.83],[2,8,23.27],[3,7.8,39.3],[4,7.6,55.15],[5,7.4,24.76],[6,7.2,17.02],[7,7,37.9],[8,6.8,34.48],[9,6.6,27.25]],"bdatl":[[0,8.6,2.85],[1,8.8,26.25],[2,9,21.14],[3,9.2,10.76],[4,9.4,13.54],[5,9.6,9.15],[6,9.8,7.36],[7,10,49.62],[8,10.5,26.34],[9,11,114.19]],"ltp":8.6,"tv":1406.84,"id":36276560},{"atl":[[23,13.76]],"trd":[[23,33.79]],"bdatb":[[0,21,18.38],[3,19,12.18],[5,18,9.05],[6,17.5,5.71],[8,16.5,15.02]],"bdatl":[[0,23,14.42],[3,26,14.01],[4,27,8.77],[8,32,5.91]],"ltp":23,"tv":298.92,"id":37947503},{"atb":[[1.49,108.35],[1.53,0],[1.54,0],[1.55,0],[1.52,59.95]],"atl":[[1.53,1.62]],"trd":[[1.53,1380.11],[1.54,627.49],[1.55,355.72]],"bdatb":[[0,1.52,162.15],[1,1.51,157.93],[2,1.5,356.81],[3,1.49,191.06],[4,1.48,277.09],[5,1.47,398.88],[6,1.46,227.71],[7,1.45,236.4],[8,1.44,72],[9,1.43,2712.24]],"bdatl":[[0,1.53,11.45],[1,1.56,67.32],[2,1.57,40.47],[3,1.58,143.99],[4,1.59,97.52],[5,1.6,149.57],[6,1.61,126.3],[7,1.62,117.45],[8,1.63,73.51],[9,1.64,110.19]],"ltp":1.53,"tv":5535.84,"id":39823721},{"atb":[[50,19.61],[55,5.08],[1.5,0]],"atl":[[70,3.49]],"trd":[[70,22.87]],"bdatb":[[0,60,14.7],[5,44,3.22],[6,36,21.34],[7,32,3.75],[8,29,1.58],[9,28,71],[1,55,5.08]],"bdatl":[[0,70,3.7],[5,190,9.72]],"tv":104.83,"id":44331354}],"con":true,"tv":8563.33}]}
{"op":"mcm","clk":"AKJSAIJIAP1I","pt":1650392737627,"mc":[{"id":"1.197931750","rc":[{"atb":[[8.8,4.42],[7.6,30.97],[8,38.74],[8.4,29.89],[8.2,20.75],[8.6,26.46]],"atl":[[10.5,29.74],[9.2,27.66],[9,4.45],[9.8,28.23],[9.4,23.42]],"bdatb":[[5,7.8,26.65],[6,7.6,30.48],[9,7,104.17],[1,8.6,29.3],[7,7.4,12.05],[8,7.2,21.93],[2,8.4,37.13],[3,8.2,20.75],[4,8,34.45],[0,8.8,4.33]],"bdatl":[[0,9,4.45],[6,10.5,17.75],[7,11,29.04],[8,11.5,30.73],[1,9.2,35.94],[4,9.8,28.23],[2,9.4,23.42],[9,12,13.69]],"id":42930960},{"atb":[[15.5,26.63],[14,27.31],[13,17.17],[15,20.59],[14.5,13.97]],"atl":[[23,18.43],[18.5,15.29],[16.5,40.65]],"bdatb":[[2,14.5,15.05],[3,14,23.56],[6,12.5,42.18],[7,12,27.06],[0,15.5,27.83],[4,13.5,18.27],[5,13,15.61],[8,11.5,6.67],[9,11,190.37],[1,15,20.59]],"bdatl":[[7,20,11.97],[8,21,24.22],[9,22,6.29],[0,16.5,40.65],[4,18.5,15.29]],"id":40095374},{"atb":[[8,35.04],[8.4,16.68],[7.4,13.37],[7,35.59],[8.2,15.1],[7.8,41.33],[7.6,30.01]],"atl":[[9.8,19.39],[8.8,21.54],[9,19.03],[9.4,24.69],[12.5,8.28],[12,11.61],[11.5,25.41],[9.2,8.76],[9.6,11.16],[8.6,0]],"bdatb":[[0,8.4,19.59],[1,8.2,17.01],[2,8,28.92],[6,7.2,19.29],[7,7,38.85],[8,6.8,38.36],[9,6.6,29.68],[3,7.8,50.54],[4,7.6,30.01],[5,7.4,30.16]],"bdatl":[[0,8.8,21.54],[4,9.6,11.16],[5,9.8,7.36],[6,10,49.62],[7,10.5,26.01],[9,11.5,33.32],[1,9,19.03],[8,11,111.06],[3,9.4,24.69],[2,9.2,8.76]],"id":36276560},{"atb":[[19.5,18.21],[21,19.58]],"atl":[[23,20.62]],"bdatb":[[2,19.5,14.55],[4,18.5,11.78],[9,16,17.63],[0,21,20.74],[5,18,9.05],[7,17,36.17],[8,16.5,9.08],[1,20,18.34],[3,19,12.18],[6,17.5,5.31]],"bdatl":[[7,30,3.87],[8,32,5.91],[9,34,4.21],[0,23,20.62]],"id":37947503},{"atb":[[1.47,89.32],[1.48,39.14],[1.51,55.39],[1.49,154.25],[1.5,99.21],[1.53,0],[1.52,57.69]],"atl":[[1.53,9.27],[1.54,30.3],[1.55,48.48],[1.6,232.92],[1.56,113.23],[1.59,48.66],[1.57,44.48],[1.58,58.64],[1.62,33.79]],"trd":[[1.53,1433.79]],"bdatb":[[0,1.52,84.02],[1,1.51,184.73],[2,1.5,187.1],[4,1.48,139.84],[5,1.47,119.9],[6,1.46,196.24],[7,1.45,258.31],[3,1.49,198.81],[8,1.44,216.23],[9,1.43,2712.24]],"bdatl":[[5,1.58,201.59],[6,1.59,49.72],[8,1.61,74.38],[9,1.62,74.91],[0,1.53,15.95],[1,1.54,39.51],[2,1.55,46.38],[3,1.56,79.67],[4,1.57,68.75],[7,1.6,170.74]],"tv":5589.52,"id":39823721},{"atb":[[60,14.33]],"atl":[[90,0.22],[95,0],[100,2.38],[85,0],[70,3.31],[80,0.18]],"trd":[[70,23.23]],"bdatb":[[5,44,3.58],[6,40,1.18],[7,36,21.09],[8,34,2.24],[9,30,1.64],[1,55,5.53],[0,60,14.43],[2,50,19.61]],"bdatl":[[2,100,2.79],[3,190,9.35],[4,200,2],[5,270,2.22],[6,350,2],[7,360,1],[8,380,1],[9,400,1],[0,70,3.31]],"tv":105.19,"id":44331354}],"con":true,"tv":8617.37}]}
{"op":"mcm","clk":"ALZTAJdJAKVK","pt":1650392738627,"mc":[{"id":"1.197931750","rc":[{"atb":[[8.4,33.59],[8.8,11.92],[6.6,25.49],[8,36.7],[7.8,20.47],[8.6,25.7],[9,4.07],[7.4,19.26]],"atl":[[9.8,29.68],[9.4,26.6],[10,20.87],[9.2,18.47],[9.6,18.94],[9,0]],"trd":[[9,84.92]],"bdatb":[[2,8.6,30.84],[5,8,41.82],[6,7.8,27.24],[7,7.6,40.74],[9,7.2,28.8],[1,8.8,12.01],[3,8.4,39.14],[8,7.4,21.43],[0,9,4.07],[4,8.2,20.75]],"bdatl":[[4,10,21.49],[5,10.5,32.31],[0,9.2,18.47],[1,9.4,26.6],[2,9.6,18.94],[6,11,26.19],[9,12.5,110.15],[3,9.8,28.23],[7,11.5,33.7],[8,12,13.69]],"tv":763.63,"id":42930960},{"atb":[[15,22.77],[14.5,16.17],[11.5,13.32],[16,2.08]],"atl":[[19.5,12.51],[19,16.03],[16.5,40.89],[17,15.83]],"bdatb":[[2,15,25.71],[3,14.5,16.17],[6,13,20.32],[7,12.5,43.31],[8,12,19.92],[9,11.5,19.78],[0,16,2.08],[1,15.5,26.63],[4,14,31.65],[5,13.5,18.27]],"bdatl":[[5,19,16.03],[6,19.5,12.83],[7,20,12.93],[8,21,24.75],[0,16.5,40.89],[9,22,6],[1,17,15.83]],"id":40095374},{"atb":[[6.4,29.99],[8.6,2.96],[8.2,28.31],[7.8,35.51],[8,38.86]],"atl":[[8.8,16.59],[9,14.12],[9.2,13.88]],"bdatb":[[0,8.6,2.96],[1,8.4,16.68],[2,8.2,33.7],[3,8,46.46],[4,7.8,43.82],[5,7.6,33.81],[6,7.4,13.37],[7,7.2,37.29],[8,7,41.95],[9,6.8,28.47]],"bdatl":[[0,8.8,16.59],[1,9,14.12],[4,9.6,14.63],[5,9.8,19.73],[7,10.5,28.32],[8,11,108.81],[9,11.5,39.21],[6,10,48.99],[2,9.2,13.88]],"id":36276560},{"atb":[[16,22.28]],"atl":[[25,13.6]],"bdatb":[[1,20,20.55],[7,17,34.35],[9,16,23.7],[8,16.5,10.53],[0,21,19.58],[2,19.5,18.21],[4,18.5,12.62]],"bdatl":[[5,28,5.08],[6,29,4.52],[7,30,3.87],[8,32,6.15],[9,34,4.13],[2,25,13.6]],"id":37947503},{"atb":[[1.49,154.25],[1.16,629.35],[1.48,43.31],[1.45,265.41],[1.52,54.84],[1.5,108.66],[1.51,80.29]],"atl":[[1.53,38.16],[1.54,39.51],[1.55,60.52],[1.6,108.93]],"bdatb":[[8,1.44,165.65],[9,1.43,2682.32],[1,1.51,192.82],[2,1.5,177.45],[3,1.49,230.43],[4,1.48,92.94],[5,1.47,167.83],[6,1.46,195.69],[7,1.45,339.32],[0,1.52,54.84]],"bdatl":[[0,1.53,28.89],[2,1.55,76.94],[3,1.56,120.4],[4,1.57,111.79],[5,1.58,198.51],[6,1.59,70.29],[7,1.6,117.34],[9,1.62,81.51],[8,1.61,186.89],[1,1.54,39.51]],"id":39823721},{"atb":[[44,5.55],[60,16.33]],"atl":[[95,0.22],[90,0],[70,2.75]],"trd":[[70,24.35]],"bdatb":[[2,50,20.5],[5,44,5.55],[8,34,1.33],[0,60,16.43],[9,32,1.31],[1,55,5.08],[6,40,1.57],[7,36,21.09]],"bdatl":[[5,270,2.34],[2,100,2.78],[0,70,2.75]],"tv":106.31,"id":44331354}],"con":true,"tv":8627.38}]}
{"op":"mcm","clk":"ANVUAIpKAKhL","pt":1650392739628,"mc":[{"id":"1.197931750","rc":[{"atb":[[8.4,31.9],[7.4,24.63],[9,13.23],[8.6,31.55],[6,150.84],[8.8,23.29],[8.2,19.02]],"atl":[[1000,13.42],[9.4,16.07],[9.8,27.66],[10.5,31.75],[9.6,34.5],[11,33.4],[9.2,0]],"trd":[[9.4,287.55],[9.2,141.36]],"bdatb":[[0,9,10.53],[1,8.8,31.93],[3,8.4,35.5],[4,8.2,19.76],[5,8,44.07],[6,7.8,26.12],[7,7.6,32.12],[8,7.4,32.85],[9,7.2,19.28],[2,8.6,31.55]],"bdatl":[[0,9.4,16.07],[1,9.6,34.5],[2,9.8,27.66],[3,10,21.92],[4,10.5,33.2],[5,11,44.6],[6,11.5,23.81],[7,12,14.3],[8,12.5,108.32],[9,13,6.4]],"ltp":9.4,"tv":779.26,"id":42930960},{"atb":[[13,20.04],[15,20.59],[14.5,13.97],[13.5,18.27],[1.03,0.25],[16,9.25],[8.6,13.16],[15.5,26.26],[8.4,67.83]],"atl":[[16.5,34.31],[17,11.74]],"trd":[[16.5,99.5],[16,34.74]],"bdatb":[[0,16,9.25],[1,15.5,26.26],[2,15,20.59],[3,14.5,19.22],[5,13.5,19.46],[6,13,17.64],[7,12.5,43.82],[8,12,19.9],[9,11.5,17.92],[4,14,27.31]],"bdatl":[[0,16.5,35.85],[1,17,11.74],[6,19.5,13.05],[8,21,24.94],[7,20,11.97]],"ltp":16.5,"tv":475.74,"id":40095374},{"atb":[[7,38.8],[1.8,0],[7.8,30.67],[8.8,2.93],[7.6,21],[8.6,16.04],[7.4,26],[5.9,20.41],[8,37.08],[6,20.53],[8.2,32.13],[5.8,135.41],[7.2,24.81]],"atl":[[9.2,11.74],[9.6,14.64],[9.4,22.65],[9.8,21.41],[9,10.23],[8.8,0]],"trd":[[8.8,30.53]],"bdatb":[[0,8.8,2.93],[1,8.6,16.04],[2,8.4,25.74],[3,8.2,32.13],[4,8,39.84],[5,7.8,38.22],[6,7.6,21],[7,7.4,33.14],[8,7.2,38.77],[9,7,42.2]],"bdatl":[[0,9,10.23],[1,9.2,11.85],[2,9.4,22.65],[3,9.6,13.16],[4,9.8,22.49],[6,10.5,31.34],[7,11,103.91],[8,11.5,26.54],[9,12,24.91],[5,10,48.99]],"ltp":8.8,"tv":1423.43,"id":36276560},{"atb":[[17,34.09],[1.02,5000.35],[22,6.77],[21,19.63],[9.8,11.36],[10,116.55]],"atl":[[23,14.27]],"trd":[[23,40.14]],"bdatb":[[0,22,6.77],[1,21,19.63],[2,20,18.42],[3,19.5,22.03],[4,19,12.18],[5,18.5,9.33],[6,18,9.49],[7,17.5,5.77],[8,17,32.3],[9,16.5,10.32]],"bdatl":[[6,29,4.22],[9,34,4.48],[0,23,14.27],[5,28,4.86],[7,30,3.87],[8,32,5.91]],"tv":305.27,"id":37947503},{"atb":[[1.47,102.99],[1.51,0],[1.49,106.34],[1.09,0],[1.46,5.71],[1.41,80.78],[1.5,97.21],[1.52,0],[1.4,897.54]],"atl":[[1.53,43.66],[1.51,2.39],[1.52,50.05],[1.61,32.4],[1.54,34.32],[1.55,64.86],[1.6,106.92],[1.56,213.23]],"trd":[[1.51,888.74],[1.52,633.4],[1.53,1434.27]],"bdatb":[[0,1.51,7],[1,1.5,158.61],[2,1.49,155.45],[3,1.48,162.98],[4,1.47,141.26],[5,1.46,225.41],[6,1.45,340.77],[7,1.44,162.72],[8,1.43,2701.59],[9,1.42,234.81]],"bdatl":[[0,1.52,50.05],[1,1.53,52.93],[2,1.54,51.06],[3,1.55,143.71],[4,1.56,223.34],[5,1.57,131.07],[6,1.58,220.21],[7,1.59,52.53],[8,1.6,113.1],[9,1.61,207.65]],"ltp":1.51,"tv":5907.31,"id":39823721},{"atb":[[65,2.61],[14,19.38],[14.5,18.52]],"atl":[[1000,15.52],[70,0.02]],"trd":[[70,27.72]],"bdatb":[[0,65,2.61],[1,60,16.33],[2,55,5.08],[3,50,19.61],[4,48,5.92],[5,46,13.42],[6,44,5.55],[7,36,23.18],[8,29,2.85],[9,28,71]],"bdatl":[[3,200,2.05],[0,75,1.12],[1,100,2.78],[2,190,9.35],[4,270,2.22],[5,350,2],[6,360,1],[7,380,1],[8,400,1],[9,420,1]],"tv":109.68,"id":44331354}],"con":true,"tv":9000.69}]}
{"op":"mcm","clk":"APdVAJ1LAMhM","pt":1650392740631,"mc":[{"id":"1.197931750","rc":[{"atb":[[2.06,0.6],[9,24.6],[8.4,31.29],[8.8,19.08],[9.2,4.86],[7.6,42.29],[8.6,33.59]],"atl":[[1000,13],[9.4,8.66],[9.8,45.05],[9.6,19.17]],"trd":[[9.2,142.4]],"bdatb":[[1,9,24.6],[2,8.8,25.79],[3,8.6,34.15],[4,8.4,33.51],[8,7.6,50.28],[9,7.4,30.36],[0,9.2,4.86],[5,8.2,25.56],[6,8,36.7],[7,7.8,29.03]],"bdatl":[[9,13,8.84],[4,10.5,38.12],[5,11,40.78],[6,11.5,23.92],[7,12,22.8],[8,12.5,98.83],[0,9.4,8.66],[1,9.6,19.17],[2,9.8,45.05],[3,10,20.87]],"ltp":9.2,"tv":780.3,"id":42930960},{"atb":[[2.06,0.36],[14,26.94],[13.5,18.27],[15,22.63],[14.5,15.97],[1.03,0]],"atl":[[17,11.96],[16.5,32.53]],"trd":[[16.5,103.06]],"bdatb":[[2,15,26.57],[3,14.5,15.97],[4,14,27.28],[5,13.5,19.57],[9,11.5,18.6],[7,12.5,42.75],[8,12,24.97],[1,15.5,26.26],[6,13,21.21],[0,16,9.25]],"bdatl":[[5,19,18.07],[7,20,12.27],[8,21,25.27],[1,17,11.96],[0,16.5,32.53],[6,19.5,12.51]],"tv":479.3,"id":40095374},{"atb":[[8,25.37],[8.4,17.17],[9,4.31],[7.8,29.8],[8.8,12.48],[1.01,16729.84],[8.6,16.15],[8.2,41.23],[7.4,23.94]],"atl":[[9.4,25.77],[9.2,6.94],[9.6,10.63],[9.8,30.48],[11,114.91],[1000,19.2],[10.5,20.26],[10,53.26],[9,0]],"trd":[[9,30.09],[8.8,34.33],[9.2,36.55]],"bdatb":[[5,8,30.32],[0,9,4.31],[1,8.8,12.48],[2,8.6,23.03],[3,8.4,19.83],[4,8.2,43.08],[6,7.8,38.37],[7,7.6,21],[8,7.4,32.15],[9,7.2,37.67]],"bdatl":[[9,12.5,14.54],[0,9.2,6.94],[1,9.4,25.77],[2,9.6,10.63],[3,9.8,30.48],[4,10,57.73],[5,10.5,22.37],[6,11,123.08],[7,11.5,34.92],[8,12,11.62]],"ltp":9,"tv":1451.72,"id":36276560},{"atb":[[21,17.24],[18.5,7.27],[22,7.12],[1.02,5000],[20,20.34],[19.5,20.27],[17,38.77]],"atl":[[23,18.67]],"trd":[[23,44.3]],"bdatb":[[2,20,23.29],[3,19.5,20.27],[5,18.5,7.53],[6,18,10.02],[9,16.5,11.48],[1,21,17.24],[8,17,39.66],[0,22,7.12],[4,19,12.18],[7,17.5,5.31]],"bdatl":[[0,23,18.67],[6,29,5.2],[8,32,6.09],[9,34,4.68]],"tv":309.43,"id":37947503},{"atb":[[1.47,130.65],[1.48,52.89],[1.5,44.57],[1.49,133.7],[1.46,55.85]],"atl":[[1000,13.28],[1.51,39.13],[1.58,63.16],[1.53,43.66],[1.54,39.44],[1.55,59.74],[1.52,50.71],[1.56,204.43]],"trd":[[1.51,888.93]],"bdatb":[[2,1.48,177.26],[3,1.47,227.71],[0,1.5,44.57],[4,1.46,225.9],[8,1.42,252.35],[9,1.41,87.57],[1,1.49,188.33],[5,1.45,323.11],[6,1.44,146.04],[7,1.43,2596.65]],"bdatl":[[8,1.59,75.06],[9,1.6,237.63],[3,1.54,106.91],[4,1.55,64.97],[5,1.56,288.29],[6,1.57,136.36],[7,1.58,118.19],[2,1.53,72.88],[0,1.51,39.13],[1,1.52,50.71]],"tv":5907.5,"id":39823721},{"atb":[[60,4.33],[65,8.63],[55,5.14]],"atl":[[95,5.89],[1000,13.52],[70,0]],"bdatb":[[0,65,8.63],[1,60,4.33],[3,50,20.79],[5,46,13.42],[7,36,23.23],[8,30,2.92],[9,28,71.45],[4,48,4.34],[2,55,5.14]],"bdatl":[[3,190,9.57],[6,350,2.02],[1,95,6.07],[0,75,1.1],[2,100,2.38],[4,200,2],[5,270,2.22],[7,360,1],[8,380,1],[9,400,1]],"id":44331354}],"con":true,"tv":9037.93}]}
{"op":"mcm","clk":"AIpXAJBMANpN","pt":1650392741633,"mc":[{"id":"1.197931750","rc":[{"atb":[[3.4,2],[9.2,4.52],[8.6,34.19],[2.06,0]],"atl":[[9.4,9.96],[1000,13.34]],"trd":[[9.2,143.07]],"bdatb":[[0,9.2,4.52],[3,8.6,39.04],[4,8.4,33.96],[5,8.2,25.69],[8,7.6,43.41],[9,7.4,30.62],[2,8.8,21.17]],"bdatl":[[5,11,41.11],[6,11.5,25.38],[7,12,21.46],[8,12.5,102.57],[0,9.4,9.96],[9,13,9.1],[4,10.5,35.34]],"tv":780.97,"id":42930960},{"atb":[[13.5,24.25],[1.41,0],[14.5,16.33],[2.06,0]],"atl":[[16.5,32.51]],"trd":[[16.5,103.1]],"bdatb":[[5,13.5,26.73],[6,13,20.27],[3,14.5,19.2],[7,12.5,42.83],[9,11.5,14.06],[2,15,23.85],[4,14,26.94]],"bdatl":[[8,21,24.4],[9,22,9.68],[0,16.5,32.51],[7,20,13.47],[5,19,16.44]],"tv":479.34,"id":40095374},{"atb":[[1.14,2.06],[7.4,35.61],[7.8,27.77],[8.8,10.87],[9,4.19],[8.4,31.09],[8.2,28.26],[8.6,20.5]],"atl":[[9.4,11.54],[1000,17.5],[9.8,32.5],[9.2,2],[9.6,13.88]],"trd":[[9,33.49]],"bdatb":[[8,7.4,42.75],[3,8.4,33.75],[4,8.2,29.98],[2,8.6,27.48],[5,8,30.44],[6,7.8,36.34],[0,9,4.19],[1,8.8,10.87],[9,7.2,34.3]],"bdatl":[[5,10.5,31.18],[6,11,117.24],[7,11.5,33.52],[8,12,13.42],[9,12.5,17.62],[4,10,54.04],[1,9.4,20.65],[0,9.2,2],[2,9.6,13.88],[3,9.8,32.5]],"tv":1455.12,"id":36276560},{"atb":[[21,19.78],[17,34.09],[20,21.85],[19.5,18.21],[18.5,9.33],[22,0.35]],"atl":[[23,20.72],[25,8.48]],"bdatb":[[5,18,10.29],[6,17.5,5.95],[7,17,34.27],[2,19.5,20.35],[8,16.5,11.54],[1,20,22.77],[4,18.5,9.33],[0,21,17.59],[3,19,12.18],[9,16,22.28]],"bdatl":[[8,32,6.03],[9,34,6.41],[6,29,5.16],[0,23,20.72],[2,25,8.48]],"id":37947503},{"atb":[[1.5,102.47],[1.48,93.54],[1.01,13009.19],[1.46,89.79],[1.49,79.79]],"atl":[[1.51,30.33],[1.61,65.93],[1.57,42.47],[1.58,61.15],[1.55,44.13],[1.6,73.39],[1.54,34.32],[1000,13]],"trd":[[1.5,230.43]],"bdatb":[[0,1.5,81.62],[1,1.49,142.62],[2,1.48,173.86],[4,1.46,220.36],[5,1.45,386.86],[6,1.44,43.02],[7,1.43,2713.7],[8,1.42,228.36],[9,1.41,126.47],[3,1.47,221.28]],"bdatl":[[6,1.57,119.73],[7,1.58,139.7],[8,1.59,155.53],[9,1.6,121.84],[0,1.51,39.79],[2,1.53,68.29],[3,1.54,96.42],[4,1.55,53.6],[5,1.56,308.02]],"ltp":1.5,"tv":5975.22,"id":39823721},{"atb":[[65,14.63]],"atl":[[95,3.54]],"bdatb":[[7,36,23.23],[5,46,14.33],[0,65,14.63],[3,50,19.98]],"bdatl":[[6,350,2.1],[3,190,9.39],[1,95,3.72]],"id":44331354}],"con":true,"tv":9109.76}]}
{"op":"mcm","clk":"AJlYAJBNAOlO","pt":1650392742634,"mc":[{"id":"1.197931750","rc":[{"atb":[[3.4,0],[8.2,17],[9.2,10.42],[9,18.36]],"atl":[[9.4,9.96],[1000,13]],"trd":[[9.2,143.75]],"bdatb":[[2,8.8,24.23],[3,8.6,35.28],[5,8.2,23.59],[6,8,43.51],[7,7.8,22.05],[8,7.6,43.2],[9,7.4,30.83],[4,8.4,32.92],[0,9.2,10.42],[1,9,18.36]],"bdatl":[[6,11.5,33.22],[7,12,13.95],[0,9.4,9.96],[5,11,34.03],[8,12.5,108.18],[9,13,4.47]],"tv":781.65,"id":42930960},{"atb":[[13.5,24.25]],"atl":[[16.5,35.91]],"bdatb":[[2,15,25.65],[4,14,28.58],[5,13.5,26.11],[6,13,22.26],[7,12.5,43.94],[8,12,20.43],[9,11.5,13.92],[3,14.5,16.33]],"bdatl":[[8,21,24.54],[0,16.5,35.91],[9,22,6]],"id":40095374},{"atb":[[8,20.55],[8.8,13.93],[3.9,0],[4.3,109.03],[1.14,0],[8.4,19.18],[7.4,23.94],[8.6,28.25]],"atl":[[9.4,20.37],[9.2,7.44],[9.6,17.85]],"trd":[[9.2,36.67]],"bdatb":[[1,8.8,13.93],[2,8.6,33.53],[3,8.4,20.3],[4,8.2,36.52],[5,8,25.37],[6,7.8,36.34],[7,7.6,21.92],[8,7.4,30.15],[9,7.2,29.75]],"bdatl":[[5,10.5,23.77],[6,11,124.31],[7,11.5,26.76],[8,12,19.75],[9,12.5,11.54],[0,9.2,7.44],[2,9.6,17.85],[1,9.4,11.54]],"ltp":9.2,"tv":1455.24,"id":36276560},{"atl":[[23,8.53],[25,12.45]],"bdatb":[[1,20,24.12],[4,18.5,10.58],[6,17.5,6.75],[7,17,35.79],[8,16.5,9.08],[5,18,9.05],[2,19.5,18.21],[0,21,20.13]],"bdatl":[[8,32,6.12],[0,23,8.53],[9,34,4.03],[2,25,12.45]],"id":37947503},{"atb":[[1.5,29.73],[1.45,317.3],[1.01,13007.58]],"atl":[[1.51,30.05],[1.56,202.26],[1.52,50.71]],"trd":[[1.51,892.15]],"bdatb":[[0,1.5,29.73],[1,1.49,142.62],[2,1.48,162.84],[3,1.47,186.09],[4,1.46,356.29],[6,1.44,115.78],[7,1.43,2661.51],[9,1.41,124.63],[5,1.45,406.31],[8,1.42,150.24]],"bdatl":[[3,1.54,105.95],[4,1.55,52.07],[5,1.56,357.99],[6,1.57,58.88],[7,1.58,140.89],[8,1.59,154.35],[9,1.6,119.07],[0,1.51,30.05],[1,1.52,50.71]],"ltp":1.51,"tv":5978.44,"id":39823721},{"atb":[[75,0.1],[46,11.38],[50,21.65]],"atl":[[75,0],[95,5.61],[360,0],[80,2.18]],"trd":[[75,38.33]],"bdatb":[[5,46,11.38],[3,50,22.56],[7,38,1.26],[8,36,21.89],[9,30,2.51]],"bdatl":[[1,95,5.61],[7,380,1],[8,400,1],[9,420,1],[0,80,2.91],[2,100,2.38],[3,190,9.39],[4,200,2],[5,270,2.22],[6,350,2.1]],"ltp":75,"tv":111.88,"id":44331354}],"con":true,"tv":9115.98}]}
{"op":"mcm","clk":"AKpZAJFOAJJQ","pt":1650392743635,"mc":[{"id":"1.197931750","rc":[{"atb":[[9.2,10.42],[8.8,15.67],[6.8,0],[7.2,294.81]],"atl":[[13.5,79.67],[12.5,17.11]],"bdatb":[[5,8.2,17.68],[7,7.8,25.7],[0,9.2,10.42],[3,8.6,36.87],[4,8.4,37.6],[9,7.4,26.41],[2,8.8,20.83],[6,8,39.95],[8,7.6,49.24]],"bdatl":[[3,10,20.87],[4,10.5,32.49],[5,11,36.75],[8,12.5,28.18]],"id":42930960},{"atb":[[15.5,26.63],[16,0],[15,20.59],[14.5,14.33],[13.5,18.27]],"atl":[[16.5,37.99],[21,22.96],[24,7.71],[23,61.43]],"trd":[[16,36.74]],"bdatb":[[0,15.5,26.63],[7,12,22.8],[9,11,188.23],[1,15,23.61],[2,14.5,14.33],[8,11.5,17.92],[3,14,28.58],[4,13.5,20.14],[5,13,22.61],[6,12.5,41.66]],"bdatl":[[0,16.5,37.99],[4,18.5,15.29],[5,19,16.44],[8,21,23.28]],"ltp":16,"tv":481.34,"id":40095374},{"atb":[[8,23.73],[1.02,5003.51],[7,324.8],[7.4,35.61],[6.2,106.33]],"atl":[[13,85.19],[11,23.91]],"bdatb":[[5,8,23.73],[9,7.2,31.57],[2,8.6,33.52],[4,8.2,32.33],[3,8.4,24.93],[6,7.8,36.34],[7,7.6,21],[8,7.4,42.75]],"bdatl":[[4,10,53.26],[5,10.5,24.51],[6,11,28.57],[7,11.5,31.29],[8,12,19.75],[9,12.5,11.54],[3,9.8,32.5],[1,9.4,20.37]],"id":36276560},{"atb":[[1.02,5003.17],[20,18.34]],"atl":[[23,6.65],[44,23],[42,0]],"trd":[[23,48.06]],"bdatb":[[1,20,20.6],[5,18,10.45],[6,17.5,5.31],[7,17,36.06]],"bdatl":[[6,29,3.86],[7,30,5.12],[4,27,8.77],[8,32,5.91],[9,34,4.23],[0,23,6.65]],"tv":313.19,"id":37947503},{"atb":[[1.45,228.41],[1.42,1446.96],[1.43,1183.12]],"atl":[[1.51,30.04],[1.61,686.93],[1.65,0],[1.52,53.71]],"trd":[[1.51,892.18]],"bdatb":[[3,1.47,154.81],[4,1.46,346.54],[5,1.45,338.72],[7,1.43,1198.77],[8,1.42,1665.96],[6,1.44,91.95],[2,1.48,205.86],[9,1.41,95.76]],"bdatl":[[0,1.51,30.04],[6,1.57,51.22],[7,1.58,67.7],[9,1.6,91.2],[3,1.54,91.52],[4,1.55,85.7],[5,1.56,355.31],[8,1.59,218.44],[1,1.52,53.71],[2,1.53,48.75]],"tv":5978.47,"id":39823721},{"atb":[[1.07,0.07],[50,21.37],[75,0],[65,14.84],[29,69.45],[28,0]],"atl":[[95,3.95],[85,0.16],[440,1],[80,2],[75,1.62],[220,5],[190,4]],"trd":[[75,38.53]],"bdatb":[[9,30,1.56],[0,65,14.84],[3,50,22.28],[8,36,22.02]],"bdatl":[[2,95,4.11],[4,190,4.35],[8,350,2.03],[0,75,1.62],[1,80,2],[3,100,2.38],[5,200,2],[6,220,5],[7,270,2.22],[9,380,1]],"tv":112.08,"id":44331354}],"con":true,"tv":9121.97}]}
{"op":"mcm","clk":"AM9aAKxPAK1R","pt":1650392744643,"mc":[{"id":"1.197931750","rc":[{"atb":[[1.02,5000.76],[9.2,12.59]],"atl":[[9.4,7.99]],"bdatb":[[3,8.6,35.66],[4,8.4,38.84],[8,7.6,49.61],[9,7.4,36],[1,9,21.92],[2,8.8,17.19],[0,9.2,12.59],[6,8,37.75],[7,7.8,27.95]],"bdatl":[[0,9.4,7.99]],"id":42930960},{"atb":[[14.5,14.33],[14,27.95],[13,13.81]],"atl":[[16,0],[17.5,21.8],[17,18.24],[16.5,40.95]],"trd":[[16,40.74]],"bdatb":[[3,14,27.84],[4,13.5,19.54],[9,11,192.97],[2,14.5,26.63],[5,13,24.03],[6,12.5,39.58],[7,12,21.56],[8,11.5,16.87]],"bdatl":[[0,16,2],[1,16.5,40.95],[2,17,16.24],[3,17.5,19.79],[4,18,11.71],[5,18.5,15.29],[6,19,16.44],[7,19.5,12.51],[8,20,13.47],[9,21,23.28]],"tv":485.34,"id":40095374},{"atb":[[6.2,107],[1.02,5000]],"atl":[[9.2,3.64],[9.4,15.56],[10.5,18.25]],"bdatb":[[1,8.8,17.57],[2,8.6,29.8],[3,8.4,22.73],[4,8.2,33.91],[8,7.4,44.45],[9,7.2,35.13],[5,8,24.43],[6,7.8,31.1],[7,7.6,26.38]],"bdatl":[[0,9.2,6.3],[5,10.5,22.5],[6,11,30.39],[7,11.5,29.55],[8,12,21.41],[9,12.5,9.94]],"id":36276560},{"atb":[[12.5,2.87],[1.02,5000]],"bdatb":[[4,18.5,10.02],[5,18,10],[0,21,21.65],[1,20,19],[7,17,36.82],[8,16.5,9.42]],"id":37947503},{"atb":[[1.43,1276.14]],"atl":[[1000,15.84],[1.51,30.02],[1.54,90.76]],"trd":[[1.51,892.21]],"bdatb":[[3,1.47,202.91],[4,1.46,287.09],[9,1.41,101.49],[0,1.5,51.06],[1,1.49,108.72],[5,1.45,334.23],[6,1.44,169.03],[7,1.43,1328.24],[8,1.42,1629.26],[2,1.48,146.14]],"bdatl":[[3,1.54,160.92],[4,1.55,72.82],[5,1.56,357.99],[6,1.57,52.52],[7,1.58,63.76],[8,1.59,230.99],[9,1.6,78.72],[0,1.51,30.02]],"tv":5978.5,"id":39823721},{"atb":[[1.4,0.04],[65,10.02],[1.17,2.86],[60,2.4],[1.07,0],[50,21.65]],"atl":[[100,0.37],[95,3.95],[80,0]],"trd":[[65,25.78]],"bdatb":[[7,36,23.33],[2,55,5.72],[3,50,21.92],[0,65,12.02],[1,60,2.4],[8,30,1.56],[9,29,70.85]],"bdatl":[[2,190,4.72],[3,200,2],[4,220,5],[5,270,2.22],[6,350,2.03],[7,380,1],[8,400,1],[9,420,1],[1,95,4.11]],"ltp":65,"tv":120.07,"id":44331354}],"con":true,"tv":9133.99}]}
{"op":"mcm","clk":"AIVcAMVQAMBS","pt":1650392745644,"mc":[{"id":"1.197931750","rc":[{"atb":[[8.8,24.66],[7,109.4],[5.5,2.01],[1.02,5000]],"atl":[[27,6.11]],"bdatb":[[3,8.6,39.11],[4,8.4,34.08],[5,8.2,26.69],[6,8,37.67],[7,7.8,26.97],[8,7.6,43.39],[9,7.4,43.52],[2,8.8,24.66],[1,9,18.36]],"bdatl":[[3,10,21.16],[4,10.5,34.37],[5,11,34.6],[6,11.5,33.5],[7,12,13.69]],"id":42930960},{"atb":[[14.5,13.35],[14,27.95],[1.02,5000],[13,20.04],[11.5,17.08]],"atl":[[65,2.64],[18.5,15.29],[17.5,19.79],[17,16.24]],"bdatb":[[2,14.5,16.27],[3,14,27.95],[4,13.5,20.01],[5,13,20.76],[6,12.5,45.19],[7,12,24.27],[8,11.5,17.81],[9,11,191.31],[1,15,20.59]],"bdatl":[[9,22,8.24],[3,18,11.87],[4,18.5,15.55],[5,19,17.22],[7,20,12.63],[0,16.5,40.95],[6,19.5,12.51],[1,17,16.24],[2,17.5,19.79],[8,21,22.96]],"id":40095374},{"atb":[[8.2,21.4],[9,6.94],[8.6,30.29],[9.2,3.31],[8.4,32.37],[7,325.64]],"atl":[[9.4,6.99],[10,54.68],[9.6,14.37],[9.8,31.67],[10.5,20.26],[9.2,0]],"trd":[[9.2,43.95],[9,33.51]],"bdatb":[[3,8.6,35.21],[4,8.4,36.28],[5,8.2,29.95],[6,8,24.7],[7,7.8,35.35],[8,7.6,27.21],[9,7.4,48.13],[1,9,6.94],[0,9.2,3.31],[2,8.8,13.93]],"bdatl":[[0,9.4,6.99],[1,9.6,14.37],[3,10,54.97],[2,9.8,31.67],[4,10.5,24.14],[5,11,30.47],[6,11.5,29.47],[7,12,21.49],[8,12.5,9.87],[9,13,93.79]],"tv":1462.54,"id":36276560},{"atb":[[8.2,8.01],[8.6,31.66],[16,24.91]],"atl":[[44,26.09],[34,6.87]],"bdatb":[[2,19.5,20.38],[5,18,10.35],[7,17,34.65],[8,16.5,13.33],[1,20,18.34],[9,16,24.91],[0,21,20.13],[4,18.5,9.33]],"bdatl":[[4,27,8.87],[5,28,5.84],[6,29,3.86],[7,30,4.31],[9,34,6.87]],"id":37947503},{"atb":[[1.43,1182.88],[1.5,29.1],[1.27,3.29],[1.37,117.82]],"atl":[[1.51,28.02],[1.52,67.71],[1000,13],[1.57,36.47]],"trd":[[1.51,896.21],[1.5,231.69]],"bdatb":[[1,1.49,123.9],[2,1.48,152.47],[7,1.43,1259.07],[8,1.42,1575.06],[9,1.41,102.68],[3,1.47,202.91],[4,1.46,375.08],[5,1.45,389.54],[0,1.5,29.1],[6,1.44,53.63]],"bdatl":[[0,1.51,28.02],[4,1.55,108.44],[5,1.56,328.73],[6,1.57,76.72],[7,1.58,75.16],[8,1.59,205.76],[9,1.6,99.6],[1,1.52,69.62],[2,1.53,61.66],[3,1.54,146.2]],"ltp":1.51,"tv":5983.76,"id":39823721},{"atb":[[1.17,0],[50,21.37],[65,10.26],[70,0.04],[1.4,0]],"atl":[[100,2.01],[75,3.59],[90,2],[85,5.01],[120,3.19],[190,6.84]],"trd":[[75,38.58]],"bdatb":[[5,46,12.3],[7,36,22.02],[8,32,2.88],[9,29,69.71],[3,50,21.37],[0,65,10.3],[2,55,5.14]],"bdatl":[[4,100,2.01],[0,75,3.59],[1,85,5.01],[2,90,2],[3,95,3.95],[5,120,3.19],[6,190,6.89],[7,200,2],[8,220,5],[9,270,2.3]],"ltp":75,"tv":120.12,"id":44331354}],"con":true,"tv":9146.6}]}
{"op":"mcm","clk":"AJddAPdRAMRT","pt":1650392746646,"mc":[{"id":"1.197931750","rc":[{"atb":[[9.4,9.8],[8.4,25.14],[8.8,26.69],[9.2,15.7],[9,20.36],[4.5,0],[4,0]],"atl":[[9.6,6.77],[11,33.71],[10,13.59],[120,0],[9.8,47.58],[10.5,33.76],[65,0],[9.4,0]],"trd":[[9.4,303.55],[9.6,115.55]],"bdatb":[[0,9.4,9.8],[4,8.6,34.96],[5,8.4,35.72],[6,8.2,19.26],[1,9.2,15.7],[2,9,20.36],[3,8.8,32.88],[7,8,36.7],[8,7.8,29.03],[9,7.6,42.29]],"bdatl":[[0,9.6,6.77],[7,12.5,29.16],[8,13,6.21],[3,10.5,36.53],[4,11,33.83],[5,11.5,33.38],[6,12,15.26],[2,10,13.59],[1,9.8,47.58],[9,13.5,85.05]],"ltp":9.4,"tv":820.31,"id":42930960},{"atb":[[15,21.76],[7,0],[6,0],[12,19.75]],"atl":[[17.5,27.77],[17,18.24],[23,60.13],[16,3.4],[430,0],[200,0],[16.5,37.55]],"bdatb":[[1,15,21.76],[5,13,26.88],[7,12,21.04],[3,14,32.32],[6,12.5,39.82],[8,11.5,22.89],[9,11,187.02],[2,14.5,13.35],[4,13.5,18.27]],"bdatl":[[2,17,18.24],[3,17.5,28.22],[9,21,25.89],[5,18.5,16.44],[8,20,12.04],[0,16,3.4],[1,16.5,37.55],[4,18,11.71],[6,19,16.03],[7,19.5,12.51]],"id":40095374},{"atb":[[8.2,26.66],[4.4,0],[3.95,0],[9,15.16],[8,21.73],[3.8,71.66],[6.4,40.63],[4.8,28.37],[8.8,19.69],[8.6,18.19]],"atl":[[9.4,21.94],[12,16.85],[10.5,17.49],[55,0],[100,0],[10,63.53],[9.6,7.72],[13.5,9.1],[9.8,37.64]],"bdatb":[[5,8.2,27.14],[6,8,32.73],[3,8.6,25.3],[7,7.8,29.77],[1,9,15.16],[2,8.8,19.69],[8,7.6,29.79],[4,8.4,32.37],[9,7.4,54.5]],"bdatl":[[7,12,23.6],[8,12.5,15.9],[9,13,85.73],[4,10.5,19.52],[6,11.5,33.12],[0,9.4,21.94],[1,9.6,7.72],[3,10,64.31],[5,11,34.72],[2,9.8,37.64]],"id":36276560},{"atb":[[20,19.2],[8.4,0],[7.2,0]],"atl":[[32,3.85],[780,0],[330,0]],"bdatb":[[7,17,34.32],[8,16.5,14.23],[1,20,19.2],[4,18.5,9.69],[9,16,26.07],[3,19,15.04],[2,19.5,18.21],[5,18,9.05]],"bdatl":[[4,27,9.84],[8,32,5.78],[5,28,4.86],[7,30,3.91]],"id":37947503},{"atb":[[1.38,127.08],[1.34,368.24],[1.48,114.57],[1.04,0.2],[1.46,114.57],[1.5,19.37],[1.3,252.51],[1.33,0],[1.39,135.84]],"atl":[[1.51,40.45],[1.57,40.47],[1.6,64.48],[2.48,0],[2.2,0],[1.52,70.68],[1000,15]],"trd":[[1.51,896.29],[1.5,232.03]],"bdatb":[[2,1.48,179.12],[5,1.45,240.78],[6,1.44,244.2],[7,1.43,1209.14],[8,1.42,1632.13],[9,1.41,157.24],[4,1.46,367.24],[0,1.5,19.37],[1,1.49,116.34],[3,1.47,219.34]],"bdatl":[[0,1.51,40.45],[2,1.53,98.78],[4,1.55,110.93],[5,1.56,253.37],[6,1.57,89.35],[7,1.58,161.24],[8,1.59,120.22],[9,1.6,88.58],[3,1.54,184.55],[1,1.52,75.8]],"ltp":1.51,"tv":5984.18,"id":39823721},{"atb":[[19,5.56],[16.5,0],[60,2.67],[2.06,0.17],[55,5.1],[65,11.72],[29,69.27],[15.5,0],[12.5,0],[70,0],[1.1,2.84]],"atl":[[1000,13],[75,2]],"trd":[[70,27.8],[65,26.86]],"bdatb":[[7,36,21.41],[8,32,3.44],[1,60,2.67],[0,65,11.72],[2,55,5.1],[9,29,69.79],[5,46,12.56]],"bdatl":[[9,270,2.22],[0,75,2],[6,190,7.03]],"ltp":65,"tv":121.28,"id":44331354}],"con":true,"tv":9186.84}]}
{"op":"mcm","clk":"ALpeAKdTANhU","pt":1650392747648,"mc":[{"id":"1.197931750","rc":[{"atb":[[8.6,30.38],[9.6,4.67],[7.6,22.23],[9.2,20.9],[9.4,11.98],[4.7,88.52],[1.1,2.08],[4.4,96.34],[7,151.07],[9,32.4],[7.8,31.46]],"atl":[[9.8,18.43],[11.5,25.17],[11,35.71],[10.5,33.1],[10,28.64],[9.6,0],[85,3.9],[65,5.12]],"trd":[[9.6,118.03]],"bdatb":[[0,9.6,4.67],[1,9.4,11.98],[2,9.2,20.9],[3,9,32.4],[4,8.8,32.88],[5,8.6,34.92],[6,8.4,35.77],[7,8.2,19.22],[8,8,40.55],[9,7.8,36.07]],"bdatl":[[0,9.8,18.43],[1,10,28.64],[2,10.5,35.86],[3,11,35.83],[4,11.5,35.39],[5,12,15.26],[6,12.5,28.67],[7,13,6.68],[8,13.5,85.06],[9,14,12.94]],"ltp":9.6,"tv":822.79,"id":42930960},{"atb":[[15.5,26.61],[14,25.19],[6.8,56.47],[6.2,70.68],[11.5,40.89]],"atl":[[1000,13.47],[17.5,19.5],[17,23.83],[240,1.37],[170,1.94],[16.5,34.59]],"trd":[[15.5,6.87]],"bdatb":[[3,14,25.19],[4,13.5,22.77],[7,12,20.78],[8,11.5,43.13],[9,11,189.64],[6,12.5,41.04],[5,13,26.9]],"bdatl":[[2,17,24.29],[3,17.5,20.72],[5,18.5,15.29],[6,19,16.1],[8,20,12.7],[9,21,27.86],[1,16.5,34.59]],"ltp":15.5,"tv":485.37,"id":40095374},{"atb":[[9.2,1.99],[7,317.68],[4.6,90.98],[4.3,208.28],[6.8,67.84],[7.6,32.33]],"atl":[[1000,21.47],[60,5.55],[85,3.9],[10,75.8]],"trd":[[9.2,46.59]],"bdatb":[[3,8.6,18.19],[4,8.4,39.6],[8,7.6,36.37],[9,7.4,40.48],[6,8,35.16],[7,7.8,27.77],[5,8.2,26.66],[0,9.2,3.3]],"bdatl":[[2,9.8,38.44],[3,10,77.93],[4,10.5,19],[5,11,33.28],[6,11.5,39.62],[7,12,20.05],[8,12.5,13.33],[9,13,85.99]],"tv":1465.18,"id":36276560},{"atb":[[18,6.87],[8.4,44.26],[7.6,49.63],[15.5,151.39]],"atl":[[1000,16.33],[440,0.75],[23,8.65],[290,1.13]],"bdatb":[[3,19,12.18],[4,18.5,12.28],[5,18,7.21],[7,17,34.09],[8,16.5,14.49],[9,16,26.05]],"bdatl":[[2,25,13.61],[4,27,8.77],[5,28,4.91],[7,30,4.35],[8,32,7.07],[0,23,8.65]],"id":37947503},{"atb":[[1.48,110.4],[1.47,88.87],[1.31,1056.56],[1.32,1284.57],[1.13,1923.08],[1.2,1],[1.5,19.35],[1.04,0]],"atl":[[1.57,38.47],[1.58,59.14],[1.59,46.6],[1.56,200.09],[2.14,287.31],[2.26,259.95],[1.51,40.23]],"trd":[[1.51,896.75],[1.5,232.07]],"bdatb":[[1,1.49,79.79],[2,1.48,211.75],[3,1.47,127.14],[4,1.46,293.14],[5,1.45,337.51],[6,1.44,155.61],[7,1.43,1333.78],[8,1.42,1571.58],[9,1.41,222.65],[0,1.5,19.35]],"bdatl":[[1,1.52,90.66],[2,1.53,126.72],[3,1.54,209.31],[4,1.55,50.37],[5,1.56,249.35],[6,1.57,179.41],[7,1.58,128.38],[9,1.6,131.83],[8,1.59,61.81],[0,1.51,40.23]],"ltp":1.5,"tv":5984.68,"id":39823721},{"atb":[[20,16.33],[18.5,18.72],[16.5,21.13],[1.1,2.96],[48,9.66],[65,11.5],[30,0.17],[2.06,0],[50,21.65]],"atl":[[380,0],[350,3],[1000,13.66]],"bdatb":[[5,46,11.38],[7,42,1.3],[8,36,21.31],[9,32,4.05],[4,48,9.66],[0,65,11.5],[3,50,21.65]],"bdatl":[[4,100,2.09],[5,120,3.36],[6,190,6.84],[9,270,2.23]],"id":44331354}],"con":true,"tv":9192.49}]}
{"op":"mcm","clk":"AM9fALJUAOFV","pt":1650392748650,"mc":[{"id":"1.197931750","rc":[{"atb":[[9.4,17.93],[9.6,4.64],[8,47.38],[8.6,27.99],[7,138.62],[9.2,20.08],[9,36.64],[8.2,14.96]],"atl":[[9.8,11.03],[1000,13],[11,44.56],[10.5,42.07]],"trd":[[9.6,118.1]],"bdatb":[[0,9.6,4.64],[1,9.4,17.93],[3,9,36.67],[4,8.8,33.56],[8,8,51.22],[5,8.6,27.99],[6,8.4,37.93],[7,8.2,14.96],[9,7.8,36.07],[2,9.2,20.08]],"bdatl":[[0,9.8,11.03],[7,13,4.66],[8,13.5,82.52],[9,14,17.25],[3,11,46.52],[2,10.5,42.78],[5,12,13.69],[6,12.5,30.18],[4,11.5,35.51]],"tv":822.86,"id":42930960},{"atb":[[15.5,20.24],[15,18.25]],"atl":[[18.5,11.41],[16.5,14.19],[16,24.77]],"trd":[[16,66.26],[15.5,7.2]],"bdatb":[[0,15.5,20.24],[1,15,18.25],[3,14,25.21],[4,13.5,22.75],[5,13,23.68],[6,12.5,42.94],[7,12,21.26],[8,11.5,43.08],[9,11,190.81]],"bdatl":[[0,16,24.77],[1,16.5,14.19],[5,18.5,12.58],[8,20,12.75],[9,21,27.33],[3,17.5,19.93],[2,17,23.83],[6,19,16.03]],"ltp":16,"tv":511.22,"id":40095374},{"atb":[[7.6,21],[8.6,16.15],[8.2,28.68],[9.2,0],[8.8,24.52]],"atl":[[9.2,0.03],[1000,17.5],[9.8,39.09],[10,74.38],[9.4,20.53],[12.5,13.52]],"trd":[[9.4,78.75],[9.2,46.61]],"bdatb":[[4,8.2,34.46],[5,8,29.25],[6,7.8,27.77],[7,7.6,29.79],[8,7.4,54.5],[9,7.2,24.81],[2,8.6,16.15],[0,9,15.16],[1,8.8,24.52],[3,8.4,39.6]],"bdatl":[[0,9.4,20.56],[4,10.5,18.97],[5,11,33.31],[7,12,17.05],[8,12.5,20.25],[9,13,87.11],[2,9.8,39.85],[3,10,76.54]],"ltp":9.4,"tv":1475.2,"id":36276560},{"atb":[[22,0.34]],"atl":[[1000,13.49]],"trd":[[22,114.12]],"bdatb":[[2,19.5,18.23],[4,18.5,12.6],[7,17,36.88],[8,16.5,11.62],[9,16,26.05],[0,21,20.12],[5,18,6.87]],"bdatl":[[8,32,6.72],[2,25,12.45],[4,27,9.84],[5,28,4.86],[7,30,4.39]],"ltp":22,"tv":313.22,"id":37947503},{"atb":[[1.1,0.12],[65,10.85]],"atl":[[370,1],[120,2.84]],"trd":[[65,28.16]],"bdatb":[[0,65,10.85],[5,46,11.39],[7,42,1.44],[8,36,22.46],[9,32,2.57]],"bdatl":[[6,190,7.03],[5,120,2.84],[4,100,2.01],[9,270,2.22]],"tv":122.58,"id":44331354},{"bdatb":[[1,1.49,80],[2,1.48,211.54],[3,1.47,168.77],[4,1.46,201.58],[5,1.45,391.14],[6,1.44,167.04],[7,1.43,1322.28],[8,1.42,1651.77],[9,1.41,128.98]],"bdatl":[[3,1.54,205.89],[4,1.55,98.38],[5,1.56,216.13],[6,1.57,143.32],[7,1.58,147.82],[8,1.59,68.91],[9,1.6,128.37],[1,1.52,75.58],[2,1.53,127.95]],"id":39823721}],"con":true,"tv":9229.76}]}
{"op":"mcm","clk":"AN9gALxVANlW","pt":1650392749652,"mc":[{"id":"1.197931750","rc":[{"atb":[[9.4,26.5],[8.4,23.13],[8.2,12.94],[8.6,25.95],[8,45.38],[9.6,5.69],[4.2,0],[2.66,0],[5.2,0],[9.2,25.1],[1.1,0.08]],"atl":[[14,0],[34,0],[16,6.67],[12.5,29.11],[10,23.62],[10.5,46.26]],"bdatb":[[1,9.4,21.33],[2,9.2,29.86],[6,8.4,30.7],[7,8.2,19.21],[8,8,50.61],[9,7.8,31.46],[3,9,36.64],[4,8.8,33.45]],"bdatl":[[9,14,4.34],[2,10.5,46.26],[3,11,45.24],[4,11.5,34.86],[5,12,15.15],[6,12.5,40.78],[7,13,6.76],[8,13.5,82.64],[1,10,23.62]],"id":42930960},{"atb":[[15,15.87],[8.4,33.78],[2.66,0],[10,10.61],[4.3,0],[15.5,20.13]],"atl":[[65,0],[48,0],[42,0],[28,1],[1000,13.47],[18.5,9.4],[16,27.05],[20,9.59]],"trd":[[15.5,7.41]],"bdatb":[[1,15,11.5],[2,14.5,16.37],[6,12.5,39.8],[7,12,25.92],[8,11.5,43.14],[9,11,187.02],[3,14,25.19],[4,13.5,22.68],[5,13,20.41],[0,15.5,20.13]],"bdatl":[[3,17.5,19.5],[5,18.5,9.4],[6,19,16.42],[8,20,11.45],[9,21,26.5],[0,16,27.05]],"ltp":15.5,"tv":511.43,"id":40095374},{"atb":[[2.66,0],[4.9,63.91],[5.5,8.17],[4.3,131.01]],"atl":[[9.8,33.07],[9.6,6.48],[9.4,11.78],[11.5,13.21],[21,0],[9.2,0],[34,0]],"trd":[[9.4,96.25],[9.2,46.68]],"bdatb":[[1,8.8,29.49],[4,8.2,29.26],[5,8,33.09],[6,7.8,29.29],[8,7.4,44.63],[3,8.4,39.46]],"bdatl":[[0,9.4,11.78],[6,11.5,27.42],[2,9.8,39.09],[3,10,74.38],[4,10.5,21.73],[5,11,30.67],[7,12,19.33],[8,12.5,21.59],[9,13,85.19]],"tv":1492.77,"id":36276560},{"atb":[[2.66,0],[10,99.66],[4.3,0],[9,0]],"atl":[[50,0],[48,0],[26,11.74]],"bdatb":[[0,21,20.12],[1,20,21.39],[8,16.5,9.24],[9,16,27.36],[2,19.5,18.21],[4,18.5,12.55],[7,17,34.38]],"bdatl":[[4,27,8.77],[7,30,5.35],[8,32,6.17],[3,26,11.74]],"id":37947503},{"atb":[[1.47,86.86],[1.48,108.39],[1.45,230.42],[1.46,126.29],[1.43,1089.86],[1.5,0]],"atl":[[1.52,72.69],[1.53,39.67],[1.51,53.41],[1.56,190.09],[2.54,0],[17,0],[34,0],[2.4,0],[1.5,29.2],[1.67,0],[1.62,19.73]],"trd":[[1.5,270.77],[1.51,898.38]],"bdatb":[[0,1.49,79.79],[1,1.48,185.25],[2,1.47,148.85],[3,1.46,214.12],[4,1.45,382.67],[5,1.44,206.09],[6,1.43,1259.13],[7,1.42,1615.79],[8,1.41,86.72],[9,1.4,1022.74]],"bdatl":[[5,1.55,104.93],[6,1.56,244.79],[8,1.58,106.71],[9,1.59,170.35],[0,1.5,29.2],[1,1.51,39.41],[2,1.52,75.58],[3,1.53,127.95],[4,1.54,204.78],[7,1.57,48.1]],"ltp":1.5,"tv":6025.01,"id":39823721},{"atb":[[55,7.97],[50,24.52],[46,14.24],[14,7.69],[2.66,0],[20,3.07],[4.3,0],[65,6.25]],"trd":[[65,37.36]],"bdatb":[[0,65,6.25],[3,50,22.53],[9,30,3.42],[5,46,11.38],[7,42,1.42],[8,36,21.27]],"bdatl":[[6,190,6.84]],"tv":131.78,"id":44331354}],"con":true,"tv":9297.07}]}
{"op":"mcm","clk":"APdhAMVWANpX","pt":1650392750653,"mc":[{"id":"1.197931750","rc":[{"atb":[[1.1,0],[9.2,26.64],[9.4,26.5],[9,35.06],[9.8,0],[8.6,30.01],[9.6,10.96],[8.8,22.36]],"atl":[[10.5,50.81],[15.5,5.22],[15,2.86],[10,16.12],[12,22.35],[11.5,27.18],[11,42.55],[9.8,0]],"trd":[[9.8,41.86]],"bdatb":[[4,8.8,26.96],[5,8.6,34.48],[7,8.2,17.15],[8,8,48.3],[9,7.8,49.17],[2,9.2,26.64],[1,9.4,26.5],[3,9,41.11],[6,8.4,24.04],[0,9.6,10.96]],"bdatl":[[1,10.5,50.81],[0,10,16.12],[2,11,47.59],[3,11.5,36.16],[4,12,24.9],[5,12.5,38.38],[6,13,5.38],[8,14,3.03],[7,13.5,79.67],[9,14.5,3.22]],"ltp":9.8,"tv":836.3,"id":42930960},{"atb":[[15.5,22.44]],"atl":[[18,23.52],[17.5,19.51],[17,23.83],[18.5,15.82],[22,4.87],[19,18.48],[16,3.4]],"bdatb":[[4,13.5,25.3],[5,13,22.99],[6,12.5,41.82],[8,11.5,42.14],[9,11,193.42],[3,14,25.19],[7,12,19.75],[0,15.5,22.44],[2,14.5,13.35],[1,15,15.87]],"bdatl":[[2,17,23.83],[3,17.5,19.51],[4,18,23.52],[5,18.5,18.15],[6,19,19.13],[9,21,25.33],[0,16,3.4],[1,16.5,14.19],[7,19.5,12.51],[8,20,9.59]],"id":40095374},{"atb":[[8.4,20.55],[6.8,54.95],[8.8,26.55],[9.2,12.59],[9.4,4.57],[7.6,32.33],[8.6,18.19],[9,16.28]],"atl":[[1000,17.58],[9.6,10.94],[9.8,33.61],[10,86.04],[12.5,17],[12,13.28],[9.4,0],[11.5,19.88],[11,25.92],[10.5,19.5]],"trd":[[9.4,109.9]],"bdatb":[[4,8.6,29.23],[5,8.4,20.55],[6,8.2,36.77],[8,7.8,29.61],[9,7.6,35.41],[1,9.2,12.59],[3,8.8,26.55],[0,9.4,4.57],[2,9,16.28],[7,8,21.73]],"bdatl":[[1,9.8,33.61],[2,10,86.04],[6,12,23.92],[7,12.5,19.46],[3,10.5,24.78],[4,11,30.45],[5,11.5,27.19],[8,13,85.69],[9,13.5,12.95],[0,9.6,13.89]],"tv":1506.42,"id":36276560},{"atb":[[22,0],[21,17.12]],"atl":[[180,0],[170,1],[28,7.09]],"trd":[[22,114.8],[21,61.71]],"bdatb":[[5,18,9.11],[8,16.5,11.41],[4,18.5,12.28],[9,16,25.39],[0,21,17.12],[2,19.5,18.21],[7,17,34.09],[1,20,19.2],[6,17.5,5.31]],"bdatl":[[5,28,7.54],[8,32,5.4],[4,27,10.36],[7,30,3.87]],"ltp":21,"tv":319.22,"id":37947503},{"atb":[[1.47,111.97],[1.42,1542.2],[1.49,37.21],[1.43,1095.65],[1.48,90.49],[1.44,193.9],[1.45,64.42]],"atl":[[1.5,63.26],[1.52,106.32],[1.6,35.35],[1.56,180.15],[1.62,29.83],[1.81,3.07],[1.54,70.32],[1.55,42.03]],"trd":[[1.49,334.21]],"bdatb":[[5,1.44,475.25],[6,1.43,1096.3],[7,1.42,1801.44],[8,1.41,151.67],[9,1.4,1012.05],[0,1.49,37.21],[3,1.46,145.4],[4,1.45,152.3],[2,1.47,177.55],[1,1.48,90.49]],"bdatl":[[0,1.5,63.26],[9,1.59,155.18],[2,1.52,175.54],[7,1.57,59.6],[8,1.58,119.84],[3,1.53,170.4],[4,1.54,102.18],[5,1.55,75.54],[6,1.56,282.72],[1,1.51,53.41]],"ltp":1.49,"tv":6055.44,"id":39823721},{"atb":[[46,12.16],[1.12,30.11],[1.1,0]],"atl":[[95,0.22],[80,1.31],[90,0],[85,3],[75,1.88],[440,0],[420,0],[400,0],[390,1]],"trd":[[75,38.83]],"bdatb":[[8,38,1.11],[9,36,21.09],[7,42,1.3],[5,46,14.24],[3,50,24.52],[2,55,7.97]],"bdatl":[[3,100,2.23],[4,120,2.84],[5,190,7.09],[6,200,2],[7,220,5],[8,270,2.27],[9,350,3],[1,80,1.31],[2,85,3],[0,75,1.88]],"ltp":75,"tv":132.03,"id":44331354}],"con":true,"tv":9360.84}]}
{"op":"mcm","clk":"AJNjANlXAPFY","pt":1650392751654,"mc":[{"id":"1.197931750","rc":[{"atb":[[9.8,5.41],[1.02,5000],[7.2,282.76],[8.8,27.82],[9.6,17.2],[9.4,20.26]],"atl":[[10,7.5],[19,0.21],[1000,13],[15,8.09],[10.5,32.73],[12,40.11],[11,63.68]],"trd":[[10,14.38]],"bdatb":[[1,9.4,21.9],[3,9,37.44],[7,8.2,18.94],[4,8.8,37.63],[5,8.6,44.17],[6,8.4,46.15],[8,8,45.38],[9,7.8,41.34],[0,9.6,17.28]],"bdatl":[[3,11.5,37.89],[4,12,56.87],[5,12.5,29.11],[6,13,6.27],[7,13.5,80.55],[8,14,3.32],[9,14.5,7.07],[2,11,63.68],[1,10.5,36.51]],"ltp":10,"tv":837.42,"id":42930960},{"atb":[[13.5,22.13]],"atl":[[32,0.52],[1000,13.47],[16,2.3]],"trd":[[16,68.47]],"bdatb":[[2,14.5,14.42],[4,13.5,30.11],[8,11.5,45.17],[9,11,192.21],[5,13,22.97],[7,12,42.84],[6,12.5,39.58]],"bdatl":[[8,20,15.72],[9,21,22.96],[3,17.5,19.51],[5,18.5,15.82],[6,19,18.52],[0,16,2.3]],"ltp":16,"tv":513.64,"id":40095374},{"atb":[[9.4,28.58],[8.4,18.55],[8.8,20.95],[8.2,24.24],[9,24.18],[8.6,18.45],[9.6,10.08],[9.2,15.59],[7.8,38.76]],"atl":[[13.5,17.1],[9.8,29.63],[11.5,21.89],[11,27.93],[10.5,19.23],[10,74.19],[1000,17.5],[9.6,0]],"trd":[[9.6,8.39],[9.4,110.06]],"bdatb":[[0,9.4,23.02],[1,9.2,15.59],[2,9,23.89],[4,8.6,37.13],[6,8.2,36.18],[8,7.8,66.52],[9,7.6,35.9],[5,8.4,23.76],[7,8,25.73],[3,8.8,15.96]],"bdatl":[[4,11,37.12],[5,11.5,23.59],[6,12,26.49],[7,12.5,18.88],[0,9.6,12.83],[3,10.5,20.85],[8,13,85.85],[9,13.5,12.8],[2,10,75.32],[1,9.8,32.16]],"ltp":9.6,"tv":1510.58,"id":36276560},{"atb":[[16.5,9.08],[1.07,0.07],[18.5,12.35],[19,12.93],[19.5,17.49],[20,23.17]],"atl":[[50,0.08],[190,1],[1000,13.49],[23,8.1]],"trd":[[23,53.16]],"bdatb":[[1,20,23.94],[4,18.5,13.51],[5,18,11.66],[7,17,36.33],[8,16.5,4.26],[9,16,24.91],[2,19.5,17.49],[3,19,12.93]],"bdatl":[[7,30,7.95],[8,32,3.85],[2,25,12.45],[4,27,8.77],[5,28,7.12],[0,23,10.65]],"ltp":23,"tv":324.32,"id":37947503},{"atb":[[1.48,17.09],[1.45,103.79],[1.47,105.55],[1.43,1269.38],[1.44,26.13],[1.46,124.28],[1.49,0]],"atl":[[1.53,20.34],[1.49,46.87],[1.54,68.31],[1.52,95.34],[1.5,329.74],[1.55,32.03],[1.51,53.09]],"trd":[[1.48,300.8],[1.49,408.96],[1.5,282.77]],"bdatb":[[0,1.48,83.24],[1,1.47,220.66],[2,1.46,152.35],[3,1.45,167.73],[4,1.44,214.06],[5,1.43,1187.7],[6,1.42,1809.73],[7,1.41,176.85],[8,1.4,935.71],[9,1.39,254.9]],"bdatl":[[0,1.49,10.35],[1,1.5,314.74],[2,1.51,51.6],[3,1.52,242.18],[4,1.53,131.15],[5,1.54,72.55],[6,1.55,170.8],[7,1.56,197.12],[8,1.57,111.1],[9,1.58,137.04]],"ltp":1.48,"tv":6167.77,"id":39823721},{"atb":[[60,5.56],[48,13.79],[44,8.44],[1.12,30]],"atl":[[75,1.69],[130,0.03],[1000,13.66],[410,1]],"trd":[[75,39.24]],"bdatb":[[3,50,24.83],[7,38,2.83],[8,36,22.15],[4,48,10.9],[9,30,3.65],[5,46,12.16]],"bdatl":[[0,75,1.79],[5,190,6.84],[8,270,2.22]],"tv":132.44,"id":44331354}],"con":true,"tv":9486.17}]}
{"op":"mcm","clk":"AMJkANJYAIVa","pt":1650392752655,"mc":[{"id":"1.197931750","rc":[{"atb":[[8.8,31.12],[2.06,0.56],[9.8,7.59],[8.2,23.31],[10,0],[9,30.99],[8.6,29.41],[9.4,22.27],[9.2,28.66],[9.6,22.41]],"atl":[[10,17.44],[11.5,27.18],[11,63.69],[12.5,31.12],[12,24.39]],"trd":[[9.8,41.88],[10,25.94]],"bdatb":[[1,9.6,23.1],[2,9.4,22.8],[3,9.2,33.57],[4,9,30.99],[5,8.8,37.56],[6,8.6,30.96],[7,8.4,63.4],[8,8.2,39.02],[9,8,45.38],[0,9.8,7.59]],"bdatl":[[4,12,28.84],[5,12.5,48.34],[6,13,5.89],[7,13.5,80.11],[8,14,3.34],[9,14.5,3.73],[3,11.5,32.97],[0,10,17.44],[2,11,63.69],[1,10.5,32.73]],"ltp":9.8,"tv":849,"id":42930960},{"atb":[[15.5,39.46],[6.4,42.55],[8,26]],"atl":[[16.5,39.5],[24,10.55],[23,59.09],[17.5,17.5],[17,22.44],[16,0.41]],"trd":[[16,72.24]],"bdatb":[[1,15,16.65],[2,14.5,16.46],[3,14,25.19],[4,13.5,26.33],[5,13,21.06],[6,12.5,43.4],[9,11,193.91],[0,15.5,39.46],[7,12,43.97],[8,11.5,45.5]],"bdatl":[[9,22,6.94],[0,16.5,39.91],[7,20,12.92],[8,21,23.33],[4,18.5,15.82],[1,17,22.44],[2,17.5,17.5],[5,19,18.48],[3,18,23.52],[6,19.5,12.51]],"tv":517.41,"id":40095374},{"atb":[[9.4,28.58],[9.6,6.93],[8.2,22.22],[9,24.18],[8,32.41],[8.4,23.81],[8.8,18.34],[9.2,22.72],[7,305.23]],"atl":[[9.8,1.19],[15,0],[14,12.95],[13,77],[1000,18.07],[13.5,22.36],[10.5,21.87],[10,80.56],[11.5,27.14]],"bdatb":[[1,9.4,29.28],[2,9.2,28.17],[3,9,24.18],[4,8.8,24.78],[5,8.6,20.01],[0,9.6,6.93],[6,8.4,29.48],[7,8.2,29.2],[8,8,64.29],[9,7.8,42.79]],"bdatl":[[0,9.8,1.19],[4,11.5,37.57],[5,12,27.41],[6,12.5,22.13],[7,13,77],[8,13.5,22.8],[9,14,20.15],[3,11,27.93],[2,10.5,21.87],[1,10,80.56]],"id":36276560},{"atb":[[19,12.18],[19.5,18.21],[1.07,0]],"atl":[[250,0],[23,20.22],[24,45.67]],"trd":[[23,53.31]],"bdatb":[[0,21,17.43],[1,20,23.42],[2,19.5,20.52],[3,19,12.18],[4,18.5,12.35],[5,18,10.01],[7,17,34.09],[8,16.5,12.78],[6,17.5,5.31],[9,16,24.91]],"bdatl":[[7,30,6.09],[8,32,4.09],[0,23,20.22],[4,27,8.77],[1,24,45.67],[5,28,7.09]],"tv":324.47,"id":37947503},{"atb":[[1.47,81.6],[1.45,73.65],[1.44,62.62],[1.43,1323.28],[1.46,160.02],[1.02,5000.32],[1.17,0.03],[1.08,0.23],[1.48,0],[1.09,0.15]],"atl":[[1.48,38.35],[1.49,38.02],[1.94,93.11],[1.99,0],[2.58,1.55],[1.55,35.94],[1.53,66.46],[1.6,17.75],[1.5,320.28]],"trd":[[1.48,321.68]],"bdatb":[[0,1.47,86.11],[2,1.45,274.11],[3,1.44,99.42],[5,1.42,1619.03],[6,1.41,243.65],[7,1.4,1020.16],[8,1.39,227.62],[9,1.38,261.13],[1,1.46,274.92],[4,1.43,1456.23]],"bdatl":[[0,1.48,38.35],[1,1.49,38.02],[2,1.5,320.28],[3,1.51,102.35],[4,1.52,266.91],[5,1.53,173.43],[6,1.54,97.78],[7,1.55,176.32],[8,1.56,180.63],[9,1.57,93.94]],"tv":6188.65,"id":39823721},{"atb":[[55,8.22],[50,24.23],[2.06,0.16],[30,0]],"atl":[[380,1],[350,2]],"bdatb":[[1,60,5.67],[2,55,8.22],[3,50,24.33],[4,48,14.73],[5,46,12.16],[7,40,1.47],[8,36,21.09],[9,34,1.92],[6,44,8.44]],"bdatl":[[9,350,2],[5,190,6.87],[8,270,2.22],[0,75,1.69]],"id":44331354}],"con":true,"tv":9522.55}]}
{"op":"mcm","clk":"AO1lAN5ZAKBb","pt":1650392753657,"mc":[{"id":"1.197931750","rc":[{"atb":[[7,148.34],[5.1,26.7],[4,68.08],[9.6,19.57],[9.8,5.4],[9.2,29.22],[2.06,0]],"atl":[[14,4.86],[10,19.7],[11.5,35.81]],"bdatb":[[0,9.8,5.4],[8,8.2,38.72],[9,8,54.92],[2,9.4,22.27],[3,9.2,35.28],[7,8.4,56.98],[1,9.6,22.41],[5,8.8,40.1],[6,8.6,29.41]],"bdatl":[[2,11,64.79],[3,11.5,40.14],[4,12,33.83],[5,12.5,39.51],[9,14.5,1.33],[7,13.5,85.54],[8,14,1.96],[6,13,4.47]],"id":42930960},{"atb":[[14.5,16.53],[14,24.17],[15.5,39.08],[16,9.93],[13.5,20.13],[15,18.05]],"atl":[[1000,14.48],[17.5,22.2],[17,16.85],[16.5,33.06],[16,0],[65,2.74]],"trd":[[16,73.07]],"bdatb":[[0,16,9.93],[1,15.5,39.08],[2,15,18.05],[3,14.5,19.39],[5,13.5,25.98],[4,14,25.19],[6,13,20.04],[7,12.5,42.76],[8,12,40.13],[9,11.5,49.5]],"bdatl":[[0,16.5,33.06],[1,17,16.85],[2,17.5,22.2],[7,20,11.63],[8,21,23.38],[9,22,4.87],[5,19,19.12]],"tv":518.24,"id":40095374},{"atb":[[7.2,12.75],[9.8,1.24],[9.6,16.99],[9.2,28.2],[7.8,29.51],[8.6,15.45],[8,41.39],[8.8,13.77],[6.4,37.94],[9,16.7]],"atl":[[12,15.32],[11,27.93],[10.5,21.84],[9.8,0],[11.5,30.38],[1000,17.5],[10,75.47],[14.5,11.76]],"trd":[[9.8,51.6]],"bdatb":[[0,9.8,1.24],[1,9.6,16.99],[2,9.4,28.58],[3,9.2,34.25],[4,9,16.7],[5,8.8,22.75],[6,8.6,15.45],[7,8.4,28.53],[8,8.2,29.2],[9,8,73.27]],"bdatl":[[1,10.5,21.84],[2,11,32.74],[3,11.5,31.17],[4,12,40.76],[5,12.5,17.97],[6,13,77],[7,13.5,28.24],[0,10,75.47],[8,14,14.91],[9,14.5,13.09]],"ltp":9.8,"tv":1531.7,"id":36276560},{"atl":[[1000,14.24],[23,18.22],[25,10.88]],"bdatb":[[1,20,23.17],[2,19.5,21.07],[5,18,10.81],[6,17.5,5.76],[8,16.5,11.49],[0,21,17.12]],"bdatl":[[6,29,5.26],[7,30,4.17],[9,34,6.87],[4,27,9.22],[5,28,7.09],[8,32,3.85],[0,23,18.22],[2,25,10.88]],"id":37947503},{"atb":[[1.47,51.79],[1.44,77.49],[1.42,1720.06],[1.46,149.47],[1.08,0],[1.09,0],[1.43,1149.55],[1.17,0],[1.02,5000]],"atl":[[20,1.12],[1.48,37.63],[1.51,42.12],[1.49,53.02],[1.5,324.7]],"trd":[[1.48,323.13]],"bdatb":[[6,1.41,243.39],[7,1.4,1065.1],[8,1.39,137.16],[9,1.38,340.66],[5,1.42,1752.85],[0,1.47,42.14],[1,1.46,268.91],[2,1.45,242.39],[3,1.44,156.09],[4,1.43,1282.51]],"bdatl":[[2,1.5,359.98],[3,1.51,123.14],[5,1.53,143.5],[6,1.54,215.04],[7,1.55,63.61],[8,1.56,249],[4,1.52,216.55],[0,1.48,37.63],[9,1.57,115.68],[1,1.49,53.02]],"tv":6190.1,"id":39823721},{"atb":[[55,7.97],[50,24.52],[34,0.29],[2.06,0],[40,5.84],[38,2.89]],"atl":[[1000,13.9],[400,1],[370,0]],"bdatb":[[3,50,24.52],[4,48,14.95],[2,55,7.97],[1,60,5.56],[7,40,7.81],[8,38,2.89],[9,36,21.09]],"bdatl":[[9,350,2.14],[5,190,6.93]],"id":44331354}],"con":true,"tv":9545.95}]}
