{"op":"mcm","clk":"ANvQogkA8f6RCgDp0JkK","pt":1657538654237,"mc":[{"id":"1.200806927","rc":[{"atl":[[2,1.51]],"id":228749}]}]}
{"op":"mcm","clk":"AKvRogkAvf+RCgCv0ZkK","pt":1657538655232,"mc":[{"id":"1.200806927","rc":[{"atb":[[4.6,22.55]],"id":2857977}]}]}
{"op":"mcm","clk":"AN7RogkAg4CSCgDS0ZkK","pt":1657538655917,"mc":[{"id":"1.200806927","rc":[{"atl":[[1.28,698.77]],"trd":[[1.28,11.21]],"tv":4946.77,"id":228749}],"tv":5753.76}]}
{"op":"mcm","clk":"AOXSogkAyoGSCgCy0pkK","pt":1657538658046,"mc":[{"id":"1.200806927","rc":[{"atb":[[1.27,95.52]],"trd":[[1.27,451.92]],"ltp":1.27,"tv":4947.76,"id":228749}],"tv":5754.75}]}
{"op":"mcm","clk":"AJrXogkA1YiSCgDd1pkK","pt":1657538668424,"mc":[{"id":"1.200806927","rc":[{"atl":[[1.28,90.84]],"trd":[[1.28,1227.08]],"ltp":1.28,"tv":6163.63,"id":228749}],"tv":6970.62}]}
{"op":"mcm","clk":"ALDXogkAiomSCgD41pkK","pt":1657538669041,"mc":[{"id":"1.200806927","rc":[{"atb":[[4.6,0]],"id":2857977}]}]}
{"op":"mcm","clk":"ALPYogkA5IqSCgCQ2JkK","pt":1657538671630,"mc":[{"id":"1.200806927","rc":[{"atl":[[4.6,0.11]],"id":2857977}]}]}
{"op":"mcm","clk":"AJPZogkA2YuSCgDR2JkK","pt":1657538673139,"mc":[{"id":"1.200806927","rc":[{"atl":[[4.6,0.24]],"id":2857977}]}]}
{"op":"mcm","clk":"AKrZogkA/YuSCgDs2JkK","pt":1657538673549,"mc":[{"id":"1.200806927","rc":[{"atl":[[4.6,0.34]],"id":2857977}]}]}
{"op":"mcm","clk":"AODZogkA34ySCgCZ2ZkK","pt":1657538674562,"mc":[{"id":"1.200806927","rc":[{"atb":[[1.04,253.05]],"id":228749}]}]}
{"op":"mcm","clk":"AI7aogkAo42SCgC62ZkK","pt":1657538675333,"mc":[{"id":"1.200806927","rc":[{"atb":[[1.04,252.58]],"id":228749}]}]}
{"op":"mcm","clk":"AKXaogkAuY2SCgDF2ZkK","pt":1657538675563,"mc":[{"id":"1.200806927","rc":[{"atb":[[1.04,252.05]],"id":228749}]}]}
{"op":"mcm","clk":"ANbaogkA9Y2SCgDc2ZkK","pt":1657538676125,"mc":[{"id":"1.200806927","rc":[{"atb":[[1.27,90.79]],"trd":[[1.27,461.39]],"ltp":1.27,"tv":6173.1,"id":228749}],"tv":6980.09}]}
{"op":"mcm","clk":"ANvbogkA8Y+SCgD02pkK","pt":1657538679270,"mc":[{"id":"1.200806927","rc":[{"atl":[[4.6,0.5]],"id":2857977}]}]}
{"op":"mcm","clk":"APPbogkApZCSCgCH25kK","pt":1657538679844,"mc":[{"id":"1.200806927","rc":[{"atl":[[1.3,2.15]],"id":228749}]}]}
{"op":"mcm","clk":"AIjcogkA0JCSCgCg25kK","pt":1657538680355,"mc":[{"id":"1.200806927","rc":[{"atl":[[4.6,0.39]],"id":2857977}]}]}
{"op":"mcm","clk":"AJfcogkA6ZCSCgCq25kK","pt":1657538680671,"mc":[{"id":"1.200806927","rc":[{"atl":[[1.28,90.31]],"trd":[[1.28,1228.14]],"ltp":1.28,"tv":6174.16,"id":228749}],"tv":6981.15}]}
{"op":"mcm","clk":"AJfcogkA8JCSCgCv25kK","pt":1657538680751,"mc":[{"id":"1.200806927","rc":[{"atl":[[4.6,0.26]],"id":2857977}]}]}
{"op":"mcm","clk":"AObcogkAh5KSCgD525kK","pt":1657538682363,"mc":[{"id":"1.200806927","rc":[{"atl":[[1.28,89.55]],"trd":[[1.28,1228.9]],"tv":6174.92,"id":228749},{"trd":[[4.5,1.18]],"tv":807.21,"id":2857977}],"tv":6982.13}]}
{"op":"mcm","clk":"AJPdogkAyJKSCgCY3JkK","pt":1657538683159,"mc":[{"id":"1.200806927","rc":[{"atl":[[1.28,86.52]],"trd":[[1.28,1231.93]],"tv":6177.95,"id":228749},{"trd":[[4.5,2.04]],"tv":808.07,"id":2857977}],"tv":6986.02}]}
{"op":"mcm","clk":"AJveogkAjJWSCgDP3ZkK","pt":1657538686783,"mc":[{"id":"1.200806927","rc":[{"atl":[[2.04,0]],"id":228749}]}]}
{"op":"mcm","clk":"AIPfogkAvZaSCgC93pkK","pt":1657538688859,"mc":[{"id":"1.200806927","rc":[{"atl":[[1.28,68.48]],"id":228749}]}]}
{"op":"mcm","clk":"AIPgogkAnJiSCgC635kK","pt":1657538691274,"mc":[{"id":"1.200806927","rc":[{"atl":[[4.6,0.15]],"id":2857977}]}]}
{"op":"mcm","clk":"AKzgogkA3piSCgDX35kK","pt":1657538692054,"mc":[{"id":"1.200806927","rc":[{"atl":[[1.28,68.11]],"trd":[[1.28,1232.3]],"tv":6178.32,"id":228749},{"trd":[[4.5,2.14]],"tv":808.17,"id":2857977}],"tv":6986.49}]}
{"op":"mcm","clk":"AInjogkA2J2SCgDp4ZkK","pt":1657538699074,"mc":[{"id":"1.200806927","rc":[{"atl":[[1.28,67.59]],"trd":[[1.28,1233.33]],"tv":6179.35,"id":228749}],"tv":6987.52}]}
{"op":"mcm","clk":"AJXjogkA752SCgD54ZkK","pt":1657538699284,"mc":[{"id":"1.200806927","rc":[{"atl":[[1.28,67.22]],"trd":[[1.28,1233.7]],"tv":6179.72,"id":228749},{"trd":[[4.5,2.25]],"tv":808.28,"id":2857977}],"tv":6988}]}
{"op":"mcm","clk":"AM/oogkA+KaSCgDD5ZkK","pt":1657538709153,"mc":[{"id":"1.200806927","rc":[{"atl":[[1.28,66.32]],"trd":[[1.28,1234.6]],"tv":6180.62,"id":228749},{"trd":[[4.5,2.51]],"tv":808.54,"id":2857977}],"tv":6989.16}]}
{"op":"mcm","clk":"AI/sogkAka2SCgCI6JkK","pt":1657538716990,"mc":[{"id":"1.200806927","rc":[{"atl":[[1.28,65.95]],"trd":[[1.28,1234.97]],"tv":6180.99,"id":228749},{"trd":[[4.5,2.61]],"tv":808.64,"id":2857977}],"tv":6989.63}]}
{"op":"mcm","clk":"ALHvogkAy7GSCgD06ZkK","pt":1657538722650,"mc":[{"id":"1.200806927","rc":[{"atl":[[1.28,65.34]],"trd":[[1.28,1235.58]],"tv":6181.6,"id":228749},{"trd":[[4.5,2.79]],"tv":808.82,"id":2857977}],"tv":6990.42}]}
{"op":"mcm","clk":"ANbvogkAjrKSCgCJ6pkK","pt":1657538723288,"mc":[{"id":"1.200806927","rc":[{"atb":[[1.01,2751.71]],"id":228749}]}]}
{"op":"mcm","clk":"APLwogkAoLSSCgDr6pkK","pt":1657538726092,"mc":[{"id":"1.200806927","rc":[{"atl":[[4.6,0]],"id":2857977}]}]}
{"op":"mcm","clk":"APjxogkA8LWSCgC965kK","pt":1657538728204,"mc":[{"id":"1.200806927","rc":[{"atl":[[1.28,65.23]],"trd":[[1.28,1235.8]],"tv":6181.82,"id":228749}],"tv":6990.64}]}
{"op":"mcm","clk":"AIL2ogkAoL2SCgD57ZkK","pt":1657538737213,"mc":[{"id":"1.200806927","rc":[{"atl":[[1.28,61.62]],"trd":[[1.28,1239.41]],"tv":6185.43,"id":228749},{"trd":[[4.5,3.81]],"tv":809.84,"id":2857977}],"tv":6995.27}]}
{"op":"mcm","clk":"ANf2ogkArb6SCgCr7pkK","pt":1657538738529,"mc":[{"id":"1.200806927","rc":[{"atl":[[1.28,58.91]],"id":228749}]}]}
{"op":"mcm","clk":"AIj4ogkAw8CSCgCz75kK","pt":1657538741305,"mc":[{"id":"1.200806927","rc":[{"atl":[[1.28,58.46]],"trd":[[1.28,1239.86]],"tv":6185.88,"id":228749},{"trd":[[4.5,3.94]],"tv":809.97,"id":2857977}],"tv":6995.85}]}
{"op":"mcm","clk":"AJP4ogkAzMCSCgC675kK","pt":1657538741418,"mc":[{"id":"1.200806927","rc":[{"atb":[[1.01,2751.71]],"id":2857977}]}]}
{"op":"mcm","clk":"ANr5ogkAssOSCgDR8JkK","pt":1657538744811,"mc":[{"id":"1.200806927","rc":[{"atl":[[1.28,43.33]],"trd":[[1.28,1254.99]],"tv":6201.01,"id":228749},{"trd":[[4.5,8.25]],"tv":814.28,"id":2857977}],"tv":7015.29}]}
{"op":"mcm","clk":"ANT8ogkAm8mSCgD98pkK","pt":1657538751637,"mc":[{"id":"1.200806927","rc":[{"atb":[[1.27,95.3]],"id":228749}]}]}
{"op":"mcm","clk":"AMb9ogkAi8uSCgDQ85kK","pt":1657538753954,"mc":[{"id":"1.200806927","rc":[{"atb":[[1.28,276.67]],"atl":[[1.28,0]],"trd":[[1.28,1341.65]],"tv":6287.67,"id":228749}],"tv":7101.95}]}
{"op":"mcm","clk":"AOf9ogkA3MuSCgDu85kK","pt":1657538754749,"mc":[{"id":"1.200806927","rc":[{"atb":[[1.27,169.6]],"id":228749}]}]}
{"op":"mcm","clk":"AMH+ogkApM2SCgC69JkK","pt":1657538756618,"mc":[{"id":"1.200806927","rc":[{"atb":[[1.28,276.78]],"id":228749}]}]}
{"op":"mcm","clk":"AIaDowkAg9aSCgDS95kK","pt":1657538768147,"mc":[{"id":"1.200806927","rc":[{"atl":[[9,0.11]],"id":2857977}]}]}
{"op":"mcm","clk":"ALuEowkAt9iSCgDA+JkK","pt":1657538771050,"mc":[{"id":"1.200806927","rc":[{"atb":[[1.27,165.09]],"id":228749}]}]}
{"op":"mcm","clk":"AOqEowkAmdmSCgDn+JkK","pt":1657538771942,"mc":[{"id":"1.200806927","rc":[{"atl":[[4.5,0.17]],"id":2857977}]}]}
{"op":"mcm","clk":"AKKJowkA2t+SCgDJ+5kK","pt":1657538780260,"mc":[{"id":"1.200806927","rc":[{"atl":[[9,0.11]],"id":228749}]}]}
{"op":"mcm","clk":"AO+KowkAyOKSCgDb/JkK","pt":1657538783643,"mc":[{"id":"1.200806927","rc":[{"atl":[[1.3,1.15]],"trd":[[1.3,330.81]],"ltp":1.3,"tv":6288.67,"id":228749},{"trd":[[4.3,250.42]],"ltp":4.3,"tv":814.58,"id":2857977}],"tv":7103.25}]}
{"op":"mcm","clk":"AL+LowkAyeOSCgCX/ZkK","pt":1657538784968,"mc":[{"id":"1.200806927","rc":[{"atb":[[1.28,275.04]],"trd":[[1.28,1345.13]],"ltp":1.28,"tv":6292.15,"id":228749}],"tv":7106.73}]}
{"op":"mcm","clk":"ANKMowkA8OWSCgD0/ZkK","pt":1657538787656,"mc":[{"id":"1.200806927","rc":[{"atl":[[1.3,4.6]],"id":228749}]}]}
{"op":"mcm","clk":"AOGMowkAleaSCgCA/pkK","pt":1657538788054,"mc":[{"id":"1.200806927","rc":[{"atb":[[1.17,0]],"id":228749}]}]}
{"op":"mcm","clk":"AO+OowkAyOmSCgCQ/5kK","pt":1657538792768,"mc":[{"id":"1.200806927","rc":[{"atl":[[1.3,4.49]],"id":228749}]}]}
{"op":"mcm","clk":"AKCQowkAvOuSCgD7/5kK","pt":1657538795389,"mc":[{"id":"1.200806927","rc":[{"atb":[[1.28,270.53]],"trd":[[1.28,1354.15]],"tv":6301.17,"id":228749}],"tv":7115.75}]}
{"op":"mcm","clk":"AJORowkAiO2SCgC8gJoK","pt":1657538797275,"mc":[{"id":"1.200806927","rc":[{"atb":[[1.28,268.53]],"trd":[[1.28,1358.15]],"tv":6305.17,"id":228749}],"tv":7119.75}]}
{"op":"mcm","clk":"AJaYowkA9/eSCgD3hJoK","pt":1657538811602,"mc":[{"id":"1.200806927","rc":[{"atl":[[4.5,0]],"id":2857977}]}]}
{"op":"mcm","clk":"ALOaowkAl/uSCgClhpoK","pt":1657538816232,"mc":[{"id":"1.200806927","rc":[{"atl":[[1.31,124.06]],"id":228749}]}]}
{"op":"mcm","clk":"AICbowkAnfySCgDVhpoK","pt":1657538817442,"mc":[{"id":"1.200806927","rc":[{"atb":[[1.28,0]],"atl":[[1.28,31.47]],"trd":[[1.28,1895.21]],"tv":6842.23,"id":228749}],"tv":7656.81}]}
{"op":"mcm","clk":"AMaeowkAhIKTCgD/iJoK","pt":1657538824431,"mc":[{"id":"1.200806927","rc":[{"atl":[[1.28,0]],"id":228749}]}]}
{"op":"mcm","clk":"AJ6fowkAk4OTCgC1iZoK","pt":1657538825615,"mc":[{"id":"1.200806927","rc":[{"atl":[[1.3,3.85]],"id":228749}]}]}
{"op":"mcm","clk":"AMmjowkA9YqTCgCEjJoK","pt":1657538834212,"mc":[{"id":"1.200806927","rc":[{"atl":[[4.5,0.17]],"id":2857977}]}]}
{"op":"mcm","clk":"APmkowkAvYyTCgCpjZoK","pt":1657538835947,"mc":[{"id":"1.200806927","rc":[{"trd":[[1.28,1895.55]],"tv":6842.57,"id":228749},{"atl":[[4.5,0.08]],"trd":[[4.5,8.34]],"ltp":4.5,"tv":814.67,"id":2857977}],"tv":7657.24}]}
{"op":"mcm","clk":"AKylowkAjY2TCgDejZoK","pt":1657538836821,"mc":[{"id":"1.200806927","rc":[{"atb":[[1.28,0.19]],"id":228749}]}]}
{"op":"mcm","clk":"AJamowkAuI6TCgC/jpoK","pt":1657538838415,"mc":[{"id":"1.200806927","rc":[{"atl":[[1.3,303.85]],"id":228749}]}]}
{"op":"mcm","clk":"AKGnowkA9Y+TCgDIj5oK","pt":1657538839824,"mc":[{"id":"1.200806927","rc":[{"atb":[[1.28,0]],"id":228749}]}]}
{"op":"mcm","clk":"AOOoowkAqpKTCgDbkJoK","pt":1657538842732,"mc":[{"id":"1.200806927","rc":[{"atl":[[1.3,302.42]],"trd":[[1.3,332.23]],"ltp":1.3,"tv":6843.99,"id":228749},{"trd":[[4.3,250.85]],"ltp":4.3,"tv":815.1,"id":2857977}],"tv":7659.09}]}
{"op":"mcm","clk":"AKqpowkAmpOTCgCEkZoK","pt":1657538843941,"mc":[{"id":"1.200806927","rc":[{"atl":[[1.5,11.35]],"id":228749}]}]}
{"op":"mcm","clk":"AKKqowkAiZWTCgDqkZoK","pt":1657538846233,"mc":[{"id":"1.200806927","rc":[{"atl":[[6,0]],"id":2857977}]}]}
{"op":"mcm","clk":"ALWsowkA+ZiTCgCSk5oK","pt":1657538850643,"mc":[{"id":"1.200806927","rc":[{"atb":[[1.27,485.09]],"id":228749}]}]}
{"op":"mcm","clk":"AI6towkAvZqTCgDPk5oK","pt":1657538852430,"mc":[{"id":"1.200806927","rc":[{"atb":[[1.27,483.36]],"trd":[[1.27,464.85],[1.28,1895.82]],"ltp":1.27,"tv":6847.72,"id":228749},{"atl":[[4.5,0]],"trd":[[4.5,8.42]],"ltp":4.5,"tv":815.18,"id":2857977}],"tv":7662.9}]}
{"op":"mcm","clk":"APGvowkAgZ+TCgCXlZoK","pt":1657538857730,"mc":[{"id":"1.200806927","rc":[{"atl":[[1.3,301.83]],"trd":[[1.3,332.82]],"ltp":1.3,"tv":6848.31,"id":228749},{"trd":[[4.3,251.03]],"ltp":4.3,"tv":815.36,"id":2857977}],"tv":7663.67}]}
{"op":"mcm","clk":"AMmwowkAkKCTCgDFlZoK","pt":1657538859142,"mc":[{"id":"1.200806927","rc":[{"atl":[[1.3,300.69]],"id":228749}]}]}
{"op":"mcm","clk":"AMOxowkA0aGTCgCqlpoK","pt":1657538861030,"mc":[{"id":"1.200806927","rc":[{"atl":[[1.3,274.23]],"trd":[[1.3,359.28]],"tv":6874.77,"id":228749},{"trd":[[4.3,259.03]],"tv":823.36,"id":2857977}],"tv":7698.13}]}
{"op":"mcm","clk":"AIazowkA2qOTCgC9l5oK","pt":1657538864053,"mc":[{"id":"1.200806927","rc":[{"atb":[[1.16,0]],"id":228749}]}]}
{"op":"mcm","clk":"ANC0owkAp6aTCgDXmJoK","pt":1657538867573,"mc":[{"id":"1.200806927","rc":[{"atl":[[1.3,271.43]],"trd":[[1.3,362.08]],"tv":6877.57,"id":228749},{"trd":[[4.3,259.87]],"tv":824.2,"id":2857977}],"tv":7701.77}]}
{"op":"mcm","clk":"ANe0owkAsKaTCgDZmJoK","pt":1657538867631,"mc":[{"id":"1.200806927","rc":[{"atl":[[1.3,270.29]],"trd":[[1.3,363.22]],"tv":6878.71,"id":228749},{"trd":[[4.3,260.22]],"tv":824.55,"id":2857977}],"tv":7703.26}]}
{"op":"mcm","clk":"AKi1owkAo6eTCgCJmZoK","pt":1657538868774,"mc":[{"id":"1.200806927","rc":[{"atl":[[1.3,270.12]],"trd":[[1.3,363.56]],"tv":6879.05,"id":228749}],"tv":7703.6}]}
{"op":"mcm","clk":"ALS1owkAwaeTCgCQmZoK","pt":1657538869023,"mc":[{"id":"1.200806927","rc":[{"atb":[[1.02,602.61]],"id":228749}]}]}
{"op":"mcm","clk":"AJu2owkA+aiTCgDQmZoK","pt":1657538870878,"mc":[{"id":"1.200806927","rc":[{"atb":[[1.22,0]],"atl":[[1000,1.22],[1.32,0],[1.37,0]],"id":228749}]}]}
{"op":"mcm","clk":"AKq2owkAnqmTCgDYmZoK","pt":1657538871274,"mc":[{"id":"1.200806927","rc":[{"atb":[[1.02,600.89]],"id":228749}]}]}
{"op":"mcm","clk":"AMa2owkAxqmTCgDvmZoK","pt":1657538871728,"mc":[{"id":"1.200806927","rc":[{"atl":[[1000,0.13]],"id":228749}]}]}
{"op":"mcm","clk":"AM22owkA0KmTCgDvmZoK","pt":1657538871784,"mc":[{"id":"1.200806927","rc":[{"atl":[[1.41,1.25]],"id":228749}]}]}
{"op":"mcm","clk":"AOC2owkA9qmTCgD9mZoK","pt":1657538872062,"mc":[{"id":"1.200806927","rc":[{"atb":[[1.02,599.78]],"id":228749}]}]}
{"op":"mcm","clk":"AJy4owkApKyTCgDbmpoK","pt":1657538874762,"mc":[{"id":"1.200806927","rc":[{"atl":[[1.3,255.2]],"trd":[[1.3,378.48]],"tv":6893.97,"id":228749},{"trd":[[4.3,264.73]],"tv":829.06,"id":2857977}],"tv":7723.03}]}
{"op":"mcm","clk":"AIa5owkAw62TCgCXm5oK","pt":1657538876267,"mc":[{"id":"1.200806927","rc":[{"atl":[[1.3,255.1]],"trd":[[1.3,378.68]],"tv":6894.17,"id":228749}],"tv":7723.23}]}
{"op":"mcm","clk":"AK65owkA/62TCgCqm5oK","pt":1657538876846,"mc":[{"id":"1.200806927","rc":[{"atl":[[1.33,1.09]],"id":228749}]}]}
{"op":"mcm","clk":"AMS5owkAna6TCgCzm5oK","pt":1657538877153,"mc":[{"id":"1.200806927","rc":[{"atl":[[1.3,253.99]],"trd":[[1.3,380.91]],"tv":6896.4,"id":228749}],"tv":7725.46}]}
{"op":"mcm","clk":"AMi6owkAu6+TCgDqm5oK","pt":1657538878774,"mc":[{"id":"1.200806927","rc":[{"atb":[[1.27,481.36]],"trd":[[1.27,468.85]],"ltp":1.27,"tv":6900.4,"id":228749}],"tv":7729.46}]}
{"op":"mcm","clk":"APq+owkA9rSTCgCfn5oK","pt":1657538883462,"mc":[{"id":"1.200806927","rc":[{"atl":[[1.3,252.38]],"trd":[[1.3,382.52]],"ltp":1.3,"tv":6902.01,"id":228749},{"trd":[[4.3,265.22]],"tv":829.55,"id":2857977}],"tv":7731.56}]}
{"op":"mcm","clk":"ANm/owkAh7aTCgD7n5oK","pt":1657538884244,"mc":[{"id":"1.200806927","rc":[{"atl":[[1.31,0]],"id":228749}]}]}
{"op":"mcm","clk":"APrCowkAlLqTCgD0opoK","pt":1657538886756,"mc":[{"id":"1.200806927","rc":[{"atl":[[1.33,0]],"id":228749}]}]}
{"op":"mcm","clk":"AKXEowkAkLyTCgDko5oK","pt":1657538889151,"mc":[{"id":"1.200806927","rc":[{"atl":[[1.3,252.28]],"trd":[[1.3,382.72]],"tv":6902.21,"id":228749}],"tv":7731.76}]}
{"op":"mcm","clk":"AIjIowkAgMKTCgCkppoK","pt":1657538896193,"mc":[{"id":"1.200806927","rc":[{"atb":[[1.27,161.36]],"id":228749}]}]}
{"op":"mcm","clk":"ANbJowkAqMSTCgC/p5oK","pt":1657538899262,"mc":[{"id":"1.200806927","rc":[{"atl":[[1.3,251.85]],"trd":[[1.3,383.58]],"tv":6903.07,"id":228749}],"tv":7732.62}]}
{"op":"mcm","clk":"AM3KowkAtcWTCgDvp5oK","pt":1657538900839,"mc":[{"id":"1.200806927","rc":[{"atl":[[1.3,251.28]],"trd":[[1.3,384.15]],"tv":6903.64,"id":228749},{"trd":[[4.3,265.39]],"tv":829.72,"id":2857977}],"tv":7733.36}]}
{"op":"mcm","clk":"AJLSowkA286TCgDMrZoK","pt":1657538911768,"mc":[{"id":"1.200806927","rc":[{"atl":[[1.3,251.18]],"trd":[[1.3,384.35]],"tv":6903.84,"id":228749}],"tv":7733.56}]}
{"op":"mcm","clk":"AIzVowkA9dGTCgCvr5oK","pt":1657538916885,"mc":[{"id":"1.200806927","rc":[{"atl":[[1.3,250.75]],"trd":[[1.3,385.21]],"tv":6904.7,"id":228749}],"tv":7734.42}]}
{"op":"mcm","clk":"AJrdowkAkduTCgCptZoK","pt":1657538928286,"mc":[{"id":"1.200806927","rc":[{"atl":[[1.3,250.04]],"trd":[[1.3,385.92]],"tv":6905.41,"id":228749},{"trd":[[4.3,265.6]],"tv":829.93,"id":2857977}],"tv":7735.34}]}
{"op":"mcm","clk":"AM7gowkAlN+TCgCAt5oK","pt":1657538934283,"mc":[{"id":"1.200806927","rc":[{"atl":[[1.29,248.12]],"id":228749}]}]}
{"op":"mcm","clk":"AMzmowkA/+STCgCEupoK","pt":1657538943622,"mc":[{"id":"1.200806927","rc":[{"atb":[[1.23,320]],"id":228749}]}]}
{"op":"mcm","clk":"AJvnowkAu+WTCgCfupoK","pt":1657538944393,"mc":[{"id":"1.200806927","rc":[{"atl":[[1.29,175.71]],"trd":[[1.29,209.8]],"ltp":1.29,"tv":7050.23,"id":228749}],"tv":7880.16}]}
{"op":"mcm","clk":"AITrowkA0OmTCgCsvJoK","pt":1657538950592,"mc":[{"id":"1.200806927","rc":[{"atl":[[4.5,0.11]],"id":2857977}]}]}
{"op":"mcm","clk":"ANvtowkA1uyTCgDbvZoK","pt":1657538954830,"mc":[{"id":"1.200806927","rc":[{"atl":[[1.29,103.3]],"trd":[[1.29,354.62]],"tv":7195.05,"id":228749}],"tv":8024.98}]}
{"op":"mcm","clk":"AJ31owkAsPaTCgDUwpoK","pt":1657538967735,"mc":[{"id":"1.200806927","rc":[{"atl":[[4.5,0]],"id":2857977}]}]}
{"op":"mcm","clk":"APz3owkA8vmTCgDQxJoK","pt":1657538972523,"mc":[{"id":"1.200806927","rc":[{"atl":[[1.29,30.88]],"trd":[[1.29,499.45]],"tv":7339.88,"id":228749}],"tv":8169.81}]}
{"op":"mcm","clk":"AIX6owkA0vyTCgDuxZoK","pt":1657538976117,"mc":[{"id":"1.200806927","rc":[{"atl":[[1.29,30.78]],"trd":[[1.29,499.65]],"tv":7340.08,"id":228749}],"tv":8170.01}]}
{"op":"mcm","clk":"AML6owkAkP2TCgCaxpoK","pt":1657538976850,"mc":[{"id":"1.200806927","rc":[{"atl":[[1.29,28.58]],"trd":[[1.29,501.85]],"tv":7342.28,"id":228749},{"trd":[[4.4,29.52]],"ltp":4.4,"tv":830.57,"id":2857977}],"tv":8172.85}]}
{"op":"mcm","clk":"AN36owkAtP2TCgCqxpoK","pt":1657538977258,"mc":[{"id":"1.200806927","rc":[{"atb":[[1.24,124.06]],"id":228749}]}]}
{"op":"mcm","clk":"AN37owkA1f6TCgD7xpoK","pt":1657538978911,"mc":[{"id":"1.200806927","rc":[{"atl":[[1.29,27.67]],"trd":[[1.29,502.76]],"tv":7343.19,"id":228749},{"trd":[[4.4,29.79]],"tv":830.84,"id":2857977}],"tv":8174.03}]}
{"op":"mcm","clk":"AJr8owkAof+TCgCnx5oK","pt":1657538979757,"mc":[{"id":"1.200806927","rc":[{"atl":[[1.29,19.59]],"trd":[[1.29,510.84]],"tv":7351.27,"id":228749},{"trd":[[4.4,32.16]],"tv":833.21,"id":2857977}],"tv":8184.48}]}
{"op":"mcm","clk":"AMj9owkA7oCUCgCPyJoK","pt":1657538981841,"mc":[{"id":"1.200806927","rc":[{"atl":[[1.29,19.16]],"trd":[[1.29,511.7]],"tv":7352.13,"id":228749}],"tv":8185.34}]}
{"op":"mcm","clk":"AKf+owkA1YGUCgC5yJoK","pt":1657538982938,"mc":[{"id":"1.200806927","rc":[{"atl":[[1.29,0],[1.3,198.56]],"trd":[[1.29,550.02],[1.3,488.88]],"ltp":1.3,"tv":7493.41,"id":228749}],"tv":8326.62}]}
{"op":"mcm","clk":"AOKDpAkA0YeUCgCay5oK","pt":1657538991474,"mc":[{"id":"1.200806927","rc":[{"atl":[[1.42,1.67]],"id":228749}]}]}
{"op":"mcm","clk":"AJmFpAkAv4mUCgCTzJoK","pt":1657538994165,"mc":[{"id":"1.200806927","rc":[{"atb":[[1.27,285.42]],"id":228749}]}]}
{"op":"mcm","clk":"AI6GpAkAzYqUCgDVzJoK","pt":1657538995771,"mc":[{"id":"1.200806927","rc":[{"atl":[[1.42,0]],"id":228749}]}]}
{"op":"mcm","clk":"AImIpAkA9IyUCgD9zZoK","pt":1657538999256,"mc":[{"id":"1.200806927","rc":[{"atb":[[1.27,161.36]],"id":228749}]}]}
{"op":"mcm","clk":"AJaJpAkA/Y2UCgDezpoK","pt":1657539000903,"mc":[{"id":"1.200806927","rc":[{"atl":[[1.4,1.67]],"id":228749}]}]}
{"op":"mcm","clk":"APOKpAkA+Y+UCgDpz5oK","pt":1657539003274,"mc":[{"id":"1.200806927","rc":[{"atb":[[1.27,161.19]],"atl":[[1.3,196.86]],"trd":[[1.3,490.58],[1.27,469.19]],"tv":7495.45,"id":228749},{"trd":[[4.3,266.12]],"ltp":4.3,"tv":833.73,"id":2857977}],"tv":8329.18}]}
{"op":"mcm","clk":"AOaLpAkA5JCUCgCv0JoK","pt":1657539004390,"mc":[{"id":"1.200806927","rc":[{"atb":[[1.28,124.06]],"id":228749}]}]}
{"op":"mcm","clk":"AMyPpAkA6JOUCgDV0ZoK","pt":1657539008307,"mc":[{"id":"1.200806927","rc":[{"atl":[[1.3,196.66]],"trd":[[1.3,490.98]],"tv":7495.85,"id":228749}],"tv":8329.58}]}
{"op":"mcm","clk":"AOaTpAkArpiUCgCu1JoK","pt":1657539014492,"mc":[{"id":"1.200806927","rc":[{"atl":[[1.3,196.25]],"trd":[[1.3,491.8]],"tv":7496.67,"id":228749}],"tv":8330.4}]}
{"op":"mcm","clk":"ANyXpAkAxJuUCgC21poK","pt":1657539019207,"mc":[{"id":"1.200806927","rc":[{"atl":[[4.4,0.72]],"id":2857977}]}]}
{"op":"mcm","clk":"ANCYpAkAvJyUCgCA15oK","pt":1657539020528,"mc":[{"id":"1.200806927","rc":[{"atl":[[1.3,194.55]],"trd":[[1.3,493.5]],"tv":7498.37,"id":228749},{"trd":[[4.3,266.63]],"tv":834.24,"id":2857977}],"tv":8332.61}]}
{"op":"mcm","clk":"AJyapAkApJ6UCgDs15oK","pt":1657539022743,"mc":[{"id":"1.200806927","rc":[{"atb":[[1.29,422.83]],"id":228749}]}]}
{"op":"mcm","clk":"ANOfpAkA9KOUCgCf2poK","pt":1657539030121,"mc":[{"id":"1.200806927","rc":[{"atb":[[1.29,404.79]],"trd":[[1.29,586.1]],"ltp":1.29,"tv":7534.45,"id":228749}],"tv":8368.69}]}
{"op":"mcm","clk":"ALWlpAkApqqUCgD83JoK","pt":1657539038521,"mc":[{"id":"1.200806927","rc":[{"atl":[[1.3,187.43]],"trd":[[1.3,500.62]],"ltp":1.3,"tv":7541.57,"id":228749},{"trd":[[4.3,268.78]],"tv":836.39,"id":2857977}],"tv":8377.96}]}
{"op":"mcm","clk":"AIaopAkAnq2UCgCp3poK","pt":1657539042402,"mc":[{"id":"1.200806927","rc":[{"atl":[[1.3,0]],"id":228749}]}]}
{"op":"mcm","clk":"AOCqpAkAo7CUCgDa35oK","pt":1657539046422,"mc":[{"id":"1.200806927","rc":[{"atb":[[1.29,404.36]],"trd":[[1.29,586.96]],"ltp":1.29,"tv":7542.43,"id":228749}],"tv":8378.82}]}
{"op":"mcm","clk":"AMirpAkAlbGUCgCX4JoK","pt":1657539047623,"mc":[{"id":"1.200806927","rc":[{"atl":[[4.4,0.74]],"id":2857977}]}]}
{"op":"mcm","clk":"APCwpAkAzLaUCgC94poK","pt":1657539055164,"mc":[{"id":"1.200806927","rc":[{"atb":[[1.23,0]],"id":228749}]}]}
{"op":"mcm","clk":"AIK2pAkA1buUCgDo5JoK","pt":1657539062155,"mc":[{"id":"1.200806927","rc":[{"atl":[[1.3,8.36]],"id":228749}]}]}
{"op":"mcm","clk":"AJm2pAkA9buUCgD75JoK","pt":1657539062462,"mc":[{"id":"1.200806927","rc":[{"atb":[[1.29,399.86]],"trd":[[1.29,595.98]],"tv":7551.45,"id":228749}],"tv":8387.84}]}
{"op":"mcm","clk":"ALu3pAkAwL2UCgDO5ZoK","pt":1657539064449,"mc":[{"id":"1.200806927","rc":[{"atb":[[1.29,0]],"atl":[[1.29,197.62]],"trd":[[1.29,1398.21]],"tv":8353.68,"id":228749},{"atl":[[4.4,0]],"trd":[[4.4,32.9]],"ltp":4.4,"tv":837.13,"id":2857977}],"tv":9190.81}]}
{"op":"mcm","clk":"ALy6pAkAp8CUCgDg5poK","pt":1657539068125,"mc":[{"id":"1.200806927","rc":[{"atl":[[1.39,9.02]],"id":228749}]}]}
{"op":"mcm","clk":"APG6pAkA78CUCgD/5poK","pt":1657539068793,"mc":[{"id":"1.200806927","rc":[{"atl":[[1.29,0]],"id":228749}]}]}
{"op":"mcm","clk":"AP2/pAkAmsaUCgCf6ZoK","pt":1657539076008,"mc":[{"id":"1.200806927","rc":[{"atl":[[4.4,0.11]],"id":2857977}]}]}
{"op":"mcm","clk":"AJbBpAkAwceUCgDc6ZoK","pt":1657539077822,"mc":[{"id":"1.200806927","rc":[{"atl":[[1.39,0]],"id":228749}]}]}
{"op":"mcm","clk":"AL7FpAkA3MuUCgDh65oK","pt":1657539083586,"mc":[{"id":"1.200806927","rc":[{"atb":[[1.29,15.51]],"id":228749}]}]}
{"op":"mcm","clk":"AP7GpAkAsc2UCgCy7JoK","pt":1657539085682,"mc":[{"id":"1.200806927","rc":[{"atl":[[1.3,6.21]],"trd":[[1.3,504.92]],"ltp":1.3,"tv":8357.98,"id":228749}],"tv":9195.11}]}
{"op":"mcm","clk":"AJjLpAkAutGUCgCv7poK","pt":1657539091548,"mc":[{"id":"1.200806927","rc":[{"atb":[[1.22,320]],"id":228749}]}]}
{"op":"mcm","clk":"AIzPpAkAg9WUCgCm8JoK","pt":1657539096209,"mc":[{"id":"1.200806927","rc":[{"atb":[[1.29,33.55]],"id":228749}]}]}
{"op":"mcm","clk":"AJzPpAkAltWUCgCt8JoK","pt":1657539096410,"mc":[{"id":"1.200806927","rc":[{"atb":[[1.04,253.74]],"id":228749}]}]}
{"op":"mcm","clk":"ALDPpAkAq9WUCgC38JoK","pt":1657539096625,"mc":[{"id":"1.200806927","rc":[{"atb":[[1.04,252.22]],"id":228749}]}]}
{"op":"mcm","clk":"AM7PpAkAyNWUCgDH8JoK","pt":1657539096930,"mc":[{"id":"1.200806927","rc":[{"atb":[[1.04,252.05]],"id":228749}]}]}
{"op":"mcm","clk":"AK3TpAkAx9mUCgC08poK","pt":1657539102017,"mc":[{"id":"1.200806927","rc":[{"atb":[[1.19,0.17]],"id":228749}]}]}
{"op":"mcm","clk":"ALXTpAkAzNmUCgC38poK","pt":1657539102110,"mc":[{"id":"1.200806927","rc":[{"atl":[[1.3,5.86]],"trd":[[1.3,505.27]],"tv":8358.33,"id":228749},{"trd":[[4.3,268.89]],"ltp":4.3,"tv":837.24,"id":2857977}],"tv":9195.57}]}
{"op":"mcm","clk":"AL7UpAkAztqUCgDw8poK","pt":1657539103438,"mc":[{"id":"1.200806927","rc":[{"atl":[[1.3,2.54]],"trd":[[1.3,509.11]],"tv":8362.17,"id":228749},{"trd":[[4.3,269.73]],"tv":838.08,"id":2857977}],"tv":9200.25}]}
{"op":"mcm","clk":"AKjVpAkAttuUCgCs85oK","pt":1657539104649,"mc":[{"id":"1.200806927","rc":[{"atb":[[1.04,253.74]],"id":2857977}]}]}
{"op":"mcm","clk":"ALzVpAkAy9uUCgC185oK","pt":1657539104854,"mc":[{"id":"1.200806927","rc":[{"atb":[[1.04,252.22]],"id":2857977}]}]}
{"op":"mcm","clk":"ANPVpAkA5NuUCgC+85oK","pt":1657539105066,"mc":[{"id":"1.200806927","rc":[{"atb":[[1.04,252.05]],"id":2857977}]}]}
{"op":"mcm","clk":"AKrXpAkA8t2UCgCm9JoK","pt":1657539107609,"mc":[{"id":"1.200806927","rc":[{"atl":[[1.3,0.39]],"trd":[[1.3,513.41]],"tv":8366.47,"id":228749}],"tv":9204.55}]}
{"op":"mcm","clk":"ANnXpAkAo96UCgDN9JoK","pt":1657539108153,"mc":[{"id":"1.200806927","rc":[{"atb":[[1.3,0.04]],"atl":[[1.3,0]],"trd":[[1.3,514.19]],"tv":8367.25,"id":228749}],"tv":9205.33}]}
{"op":"mcm","clk":"AIDYpAkA0t6UCgDl9JoK","pt":1657539108604,"mc":[{"id":"1.200806927","rc":[{"atb":[[1.29,0],[1.3,0]],"atl":[[1.29,51.05]],"trd":[[1.29,1465.67],[1.3,514.27]],"ltp":1.29,"tv":8434.79,"id":228749},{"atl":[[4.4,0]],"trd":[[4.4,33.01]],"ltp":4.4,"tv":838.19,"id":2857977}],"tv":9272.98}]}
{"op":"mcm","clk":"APnYpAkA89+UCgC69ZoK","pt":1657539110123,"mc":[{"id":"1.200806927","rc":[{"atb":[[1.66,0.17]],"id":2857977}]}]}
{"op":"mcm","clk":"ANvbpAkAiOOUCgDp9poK","pt":1657539114156,"mc":[{"id":"1.200806927","rc":[{"atb":[[1.27,86.89]],"id":228749}]}]}
{"op":"mcm","clk":"AITdpAkAq+SUCgDI95oK","pt":1657539115732,"mc":[{"id":"1.200806927","rc":[{"atl":[[1.29,49.25]],"trd":[[1.29,1469.27]],"tv":8438.39,"id":228749}],"tv":9276.58}]}
{"op":"mcm","clk":"ANjepAkAj+aUCgDF+JoK","pt":1657539117916,"mc":[{"id":"1.200806927","rc":[{"atb":[[4.5,1.8]],"id":2857977}]}]}
{"op":"mcm","clk":"ANzgpAkAs+iUCgDm+ZoK","pt":1657539120832,"mc":[{"id":"1.200806927","rc":[{"atb":[[4.5,1.37]],"trd":[[4.5,9.28]],"ltp":4.5,"tv":839.05,"id":2857977}],"tv":9277.44}]}
{"op":"mcm","clk":"APHgpAkAyeiUCgD1+ZoK","pt":1657539121047,"mc":[{"id":"1.200806927","rc":[{"atb":[[4.5,0.98]],"trd":[[4.5,10.06]],"tv":839.83,"id":2857977}],"tv":9278.22}]}
{"op":"mcm","clk":"AK7hpAkAjemUCgCU+poK","pt":1657539121628,"mc":[{"id":"1.200806927","rc":[{"atl":[[1.29,48.52]],"trd":[[1.29,1470]],"tv":8439.12,"id":228749},{"atb":[[4.5,0]],"trd":[[4.4,33.22],[4.5,12.02]],"ltp":4.4,"tv":842,"id":2857977}],"tv":9281.12}]}
{"op":"mcm","clk":"AMfipAkApOqUCgDZ+poK","pt":1657539126160,"mc":[{"id":"1.200806927","rc":[{"atl":[[1.29,48.08]],"trd":[[1.29,1470.44]],"tv":8439.56,"id":228749},{"trd":[[4.4,33.35]],"tv":842.13,"id":2857977}],"tv":9281.69}]}
{"op":"mcm","clk":"AK3kpAkAquyUCgDR+5oK","pt":1657539126653,"mc":[{"id":"1.200806927","rc":[{"atl":[[1.29,47.72]],"trd":[[1.29,1470.8]],"tv":8439.92,"id":228749},{"trd":[[4.4,33.46]],"tv":842.24,"id":2857977}],"tv":9282.16}]}
{"op":"mcm","clk":"AJzlpAkApO2UCgCV/JoK","pt":1657539127233,"mc":[{"id":"1.200806927","rc":[{"atl":[[1.29,47.36]],"trd":[[1.29,1471.16]],"tv":8440.28,"id":228749},{"trd":[[4.4,33.56]],"tv":842.34,"id":2857977}],"tv":9282.62}]}
{"op":"mcm","clk":"AK3lpAkAv+2UCgCl/JoK","pt":1657539127459,"mc":[{"id":"1.200806927","rc":[{"atb":[[1.29,26.94]],"atl":[[1.29,0]],"trd":[[1.29,1565.88]],"tv":8535,"id":228749},{"atl":[[4.5,20]],"id":2857977}],"tv":9377.34}]}
{"op":"mcm","clk":"AMvlpAkA1+2UCgCy/JoK","pt":1657539127678,"mc":[{"id":"1.200806927","rc":[{"atl":[[1.34,1000]],"id":228749}]}]}
{"op":"mcm","clk":"ANvlpAkA6u2UCgDH/JoK","pt":1657539127882,"mc":[{"id":"1.200806927","rc":[{"atl":[[1.34,0]],"id":228749},{"atl":[[4.4,0.11]],"id":2857977}]}]}
{"op":"mcm","clk":"AOvlpAkA+e2UCgDX/JoK","pt":1657539128087,"mc":[{"id":"1.200806927","rc":[{"atl":[[1.32,1000]],"id":228749}]}]}
{"op":"mcm","clk":"APrlpAkAje6UCgDg/JoK","pt":1657539128236,"mc":[{"id":"1.200806927","rc":[{"atl":[[1.32,0]],"id":228749}]}]}
{"op":"mcm","clk":"AMjmpAkA4e6UCgCR/ZoK","pt":1657539129138,"mc":[{"id":"1.200806927","rc":[{"atl":[[4.4,0],[4.5,15.6]],"trd":[[4.4,33.78],[4.5,20.82]],"ltp":4.5,"tv":851.36,"id":2857977}],"tv":9386.36}]}
{"op":"mcm","clk":"ALXnpAkA5u+UCgDZ/ZoK","pt":1657539130451,"mc":[{"id":"1.200806927","rc":[{"atl":[[4.4,1.72]],"id":2857977}]}]}
{"op":"mcm","clk":"AM/ppAkAsfKUCgDx/poK","pt":1657539133436,"mc":[{"id":"1.200806927","rc":[{"atl":[[4.4,1.83]],"id":2857977}]}]}
{"op":"mcm","clk":"ANDrpAkAl/WUCgCCgJsK","pt":1657539136744,"mc":[{"id":"1.200806927","rc":[{"atl":[[4.4,1.72]],"id":2857977}]}]}
{"op":"mcm","clk":"APTtpAkA4/eUCgC2gZsK","pt":1657539140072,"mc":[{"id":"1.200806927","rc":[{"atl":[[4.4,0]],"id":2857977}]}]}
{"op":"mcm","clk":"ANbupAkA7PiUCgCCgpsK","pt":1657539141279,"mc":[{"id":"1.200806927","rc":[{"atb":[[1.28,0]],"id":228749}]}]}
{"op":"mcm","clk":"ANHxpAkAqfyUCgDyg5sK","pt":1657539145963,"mc":[{"id":"1.200806927","rc":[{"atl":[[1.39,9.02]],"id":228749}]}]}
{"op":"mcm","clk":"AJHzpAkAnf6UCgDXhJsK","pt":1657539148560,"mc":[{"id":"1.200806927","rc":[{"atl":[[1.35,0.53]],"trd":[[1.35,4.33]],"ltp":1.35,"tv":8535.3,"id":228749},{"trd":[[3.85,1.22]],"ltp":3.85,"tv":851.47,"id":2857977}],"tv":9386.77}]}
{"op":"mcm","clk":"AK/4pAkAs4SVCgDbh5sK","pt":1657539155884,"mc":[{"id":"1.200806927","rc":[{"atb":[[1.29,0],[1.27,68.67]],"atl":[[1.28,200]],"trd":[[1.29,1619.76],[1.27,505.63],[1.28,1950.66]],"ltp":1.27,"tv":8680.46,"id":228749},{"atl":[[4.5,0]],"trd":[[4.5,36.42]],"ltp":4.5,"tv":867.07,"id":2857977}],"tv":9547.53}]}
{"op":"mcm","clk":"ALf4pAkAwYSVCgDih5sK","pt":1657539155979,"mc":[{"id":"1.200806927","rc":[{"atl":[[1.29,26]],"id":228749}]}]}
{"op":"mcm","clk":"AMD4pAkAx4SVCgDoh5sK","pt":1657539156088,"mc":[{"id":"1.200806927","rc":[{"atl":[[1.28,199.24]],"trd":[[1.28,1951.42]],"ltp":1.28,"tv":8681.22,"id":228749},{"trd":[[4.5,36.63]],"tv":867.28,"id":2857977}],"tv":9548.5}]}
{"op":"mcm","clk":"ALf5pAkAyoWVCgDOiJsK","pt":1657539157480,"mc":[{"id":"1.200806927","rc":[{"atl":[[1.28,1199.24]],"id":228749}]}]}
{"op":"mcm","clk":"AJ76pAkAt4aVCgCGiZsK","pt":1657539158594,"mc":[{"id":"1.200806927","rc":[{"atl":[[1.28,1198.87]],"trd":[[1.28,1951.79]],"tv":8681.59,"id":228749},{"trd":[[4.5,36.74]],"tv":867.39,"id":2857977}],"tv":9548.98}]}
{"op":"mcm","clk":"ALr6pAkA14aVCgCXiZsK","pt":1657539158908,"mc":[{"id":"1.200806927","rc":[{"atl":[[1.28,198.87]],"id":228749}]}]}
{"op":"mcm","clk":"AIv7pAkAtYeVCgDbiZsK","pt":1657539160003,"mc":[{"id":"1.200806927","rc":[{"atl":[[1.28,198.11]],"trd":[[1.28,1952.55]],"tv":8682.35,"id":228749},{"trd":[[4.5,36.95]],"tv":867.6,"id":2857977}],"tv":9549.95}]}
{"op":"mcm","clk":"AKX8pAkAkYmVCgC7ipsK","pt":1657539162174,"mc":[{"id":"1.200806927","rc":[{"atb":[[1.27,0]],"atl":[[1.27,931.33]],"trd":[[1.27,642.97]],"ltp":1.27,"tv":8819.69,"id":228749}],"tv":9687.29}]}
{"op":"mcm","clk":"AL/8pAkAsomVCgDPipsK","pt":1657539162505,"mc":[{"id":"1.200806927","rc":[{"atl":[[1.27,0]],"id":228749}]}]}
{"op":"mcm","clk":"AOf8pAkA6YmVCgDnipsK","pt":1657539163010,"mc":[{"id":"1.200806927","rc":[{"atl":[[1.28,197.76]],"trd":[[1.28,1952.9]],"ltp":1.28,"tv":8820.04,"id":228749},{"trd":[[4.5,37.05]],"tv":867.7,"id":2857977}],"tv":9687.74}]}
{"op":"mcm","clk":"AKf/pAkA5IyVCgDPjJsK","pt":1657539167021,"mc":[{"id":"1.200806927","rc":[{"atl":[[1.28,197]],"trd":[[1.28,1953.66]],"tv":8820.8,"id":228749},{"trd":[[4.5,37.27]],"tv":867.92,"id":2857977}],"tv":9688.72}]}
{"op":"mcm","clk":"AOz/pAkAoY2VCgD3jJsK","pt":1657539167698,"mc":[{"id":"1.200806927","rc":[{"atl":[[1.28,194.85]],"trd":[[1.28,1957.96]],"tv":8825.1,"id":228749}],"tv":9693.02}]}
{"op":"mcm","clk":"AJ2BpQkAi4+VCgCWjpsK","pt":1657539170308,"mc":[{"id":"1.200806927","rc":[{"atl":[[1.28,188.8]],"trd":[[1.28,1964.01]],"tv":8831.15,"id":228749},{"trd":[[4.5,38.99]],"tv":869.64,"id":2857977}],"tv":9700.79}]}
{"op":"mcm","clk":"AM+BpQkA44+VCgC/jpsK","pt":1657539171084,"mc":[{"id":"1.200806927","rc":[{"atl":[[1.39,0]],"id":228749}]}]}
{"op":"mcm","clk":"APqBpQkAl5CVCgDajpsK","pt":1657539171605,"mc":[{"id":"1.200806927","rc":[{"atl":[[1.28,187.45]],"trd":[[1.28,1966.71]],"tv":8833.85,"id":228749}],"tv":9703.49}]}
{"op":"mcm","clk":"AKOCpQkA4JCVCgCFj5sK","pt":1657539172183,"mc":[{"id":"1.200806927","rc":[{"atl":[[1.28,187.08]],"trd":[[1.28,1967.08]],"tv":8834.22,"id":228749},{"trd":[[4.5,39.1]],"tv":869.75,"id":2857977}],"tv":9703.97}]}
{"op":"mcm","clk":"AKiCpQkA7ZCVCgCMj5sK","pt":1657539172303,"mc":[{"id":"1.200806927","rc":[{"atl":[[1.29,0]],"id":228749}]}]}
{"op":"mcm","clk":"ALyCpQkAiJGVCgCWj5sK","pt":1657539172515,"mc":[{"id":"1.200806927","rc":[{"atb":[[1.24,0]],"id":228749}]}]}
{"op":"mcm","clk":"AJ6DpQkA9JGVCgDZj5sK","pt":1657539173595,"mc":[{"id":"1.200806927","rc":[{"atl":[[1.28,169.04]],"trd":[[1.28,2003.16]],"tv":8870.3,"id":228749}],"tv":9740.05}]}
{"op":"mcm","clk":"ANeFpQkA95SVCgCjkZsK","pt":1657539177388,"mc":[{"id":"1.200806927","rc":[{"atl":[[1.27,26]],"id":228749}]}]}
{"op":"mcm","clk":"AO2FpQkAlZWVCgC0kZsK","pt":1657539177709,"mc":[{"id":"1.200806927","rc":[{"atb":[[1.23,124.06]],"id":228749}]}]}
{"op":"mcm","clk":"AJaIpQkAj5iVCgD1kpsK","pt":1657539181339,"mc":[{"id":"1.200806927","rc":[{"atl":[[1.27,25]],"trd":[[1.27,644.97]],"ltp":1.27,"tv":8872.3,"id":228749}],"tv":9742.05}]}
{"op":"mcm","clk":"AIyLpQkAxpuVCgC3lJsK","pt":1657539185533,"mc":[{"id":"1.200806927","rc":[{"atl":[[1.27,5.99]],"trd":[[1.27,663.98]],"tv":8891.31,"id":228749},{"trd":[[4.7,56.64]],"ltp":4.7,"tv":874.89,"id":2857977}],"tv":9766.2}]}
{"op":"mcm","clk":"AMWMpQkAw52VCgCHlZsK","pt":1657539187628,"mc":[{"id":"1.200806927","rc":[{"atl":[[1.27,5.14]],"trd":[[1.27,665.67]],"tv":8893,"id":228749}],"tv":9767.89}]}
{"op":"mcm","clk":"AOyMpQkAgp6VCgCglZsK","pt":1657539188175,"mc":[{"id":"1.200806927","rc":[{"atl":[[1.28,0]],"id":228749}]}]}
{"op":"mcm","clk":"AIGNpQkAmp6VCgCklZsK","pt":1657539188347,"mc":[{"id":"1.200806927","rc":[{"atl":[[1.27,4.75]],"trd":[[1.27,666.06]],"tv":8893.39,"id":228749},{"trd":[[4.7,56.74]],"tv":874.99,"id":2857977}],"tv":9768.38}]}
{"op":"mcm","clk":"APeNpQkAqJ+VCgDulZsK","pt":1657539189623,"mc":[{"id":"1.200806927","rc":[{"atl":[[1.27,0.45]],"trd":[[1.27,674.66]],"tv":8901.99,"id":228749}],"tv":9776.98}]}
{"op":"mcm","clk":"AI2PpQkA8aCVCgC/lpsK","pt":1657539191415,"mc":[{"id":"1.200806927","rc":[{"atl":[[1.27,0]],"trd":[[1.27,675.11]],"tv":8902.44,"id":228749},{"atl":[[4.7,0.83]],"trd":[[4.7,56.86]],"tv":875.11,"id":2857977}],"tv":9777.55}]}
{"op":"mcm","clk":"AIeQpQkA9KGVCgD7lpsK","pt":1657539192716,"mc":[{"id":"1.200806927","rc":[{"atl":[[4.5,0.43]],"id":2857977}]}]}
{"op":"mcm","clk":"APyXpQkA/amVCgDMm5sK","pt":1657539203368,"mc":[{"id":"1.200806927","rc":[{"atb":[[1.28,167.24]],"id":228749}]}]}
{"op":"mcm","clk":"ANiZpQkAj6yVCgDOnJsK","pt":1657539205756,"mc":[{"id":"1.200806927","rc":[{"atb":[[1.8,213.55]],"atl":[[1.35,0],[1.65,0],[1.5,0],[1.68,0],[1.74,0],[1.45,0],[1.43,0],[1.41,0],[1.4,0]],"trd":[[1.35,5.39],[1.65,0.25],[1.5,22.7],[1.68,11.71],[1.74,2.6],[1.45,113.48],[1.43,1.37],[1.41,2.49],[1.4,55.51]],"ltp":1.74,"tv":9060.67,"id":228749}],"tv":9935.78}]}
{"op":"mcm","clk":"AO+bpQkAgK+VCgCKnpsK","pt":1657539209182,"mc":[{"id":"1.200806927","rc":[{"atl":[[4.5,0]],"id":2857977}]}]}
{"op":"mcm","clk":"AIacpQkAla+VCgCSnpsK","pt":1657539209355,"mc":[{"id":"1.200806927","rc":[{"atb":[[1.8,212.61]],"trd":[[1.8,1.89]],"ltp":1.8,"tv":9062.56,"id":228749}],"tv":9937.67}]}
{"op":"mcm","clk":"AJSdpQkAp7CVCgDknpsK","pt":1657539210878,"mc":[{"id":"1.200806927","rc":[{"atb":[[1.8,183.73]],"trd":[[1.8,59.65]],"tv":9120.32,"id":228749}],"tv":9995.43}]}
{"op":"mcm","clk":"ANedpQkA4bCVCgCGn5sK","pt":1657539211582,"mc":[{"id":"1.200806927","rc":[{"atb":[[1.8,165.69]],"trd":[[1.8,95.73]],"tv":9156.4,"id":228749}],"tv":10031.51}]}
{"op":"mcm","clk":"AOCdpQkA77CVCgCLn5sK","pt":1657539211684,"mc":[{"id":"1.200806927","rc":[{"atb":[[1.8,0]],"id":228749}]}]}
{"op":"mcm","clk":"AMuhpQkA/7SVCgC9oZsK","pt":1657539217251,"mc":[{"id":"1.200806927","rc":[{"atl":[[1.8,7.99]],"id":228749}]}]}
{"op":"mcm","clk":"AJWipQkA1bWVCgD3oZsK","pt":1657539218174,"mc":[{"id":"1.200806927","rc":[{"atl":[[1.8,32.74]],"id":228749}]}]}
{"op":"mcm","clk":"AJyipQkA4LWVCgD8oZsK","pt":1657539218275,"mc":[{"id":"1.200806927","rc":[{"atl":[[1.8,34.12]],"id":228749}]}]}
{"op":"mcm","clk":"ALqipQkAg7aVCgCcopsK","pt":1657539218646,"mc":[{"id":"1.200806927","rc":[{"atl":[[1.8,235.02]],"id":228749}]}]}
{"op":"mcm","clk":"AK2lpQkAy7iVCgCLpJsK","pt":1657539222915,"mc":[{"id":"1.200806927","rc":[{"atb":[[1.28,166.33]],"trd":[[1.28,2004.96]],"ltp":1.28,"tv":9158.2,"id":228749}],"tv":10033.31}]}
{"op":"mcm","clk":"AMOmpQkA7LmVCgD6pJsK","pt":1657539224780,"mc":[{"id":"1.200806927","rc":[{"atl":[[1.8,237.36]],"id":228749}]}]}
{"op":"mcm","clk":"AOyopQkAuryVCgCgppsK","pt":1657539228675,"mc":[{"id":"1.200806927","rc":[{"atl":[[1.8,237.23]],"trd":[[1.8,95.86]],"ltp":1.8,"tv":9158.33,"id":228749},{"trd":[[2.24,0.1]],"ltp":2.24,"tv":875.21,"id":2857977}],"tv":10033.54}]}
{"op":"mcm","clk":"AL2qpQkAsr6VCgDAp5sK","pt":1657539231476,"mc":[{"id":"1.200806927","rc":[{"atl":[[1.8,234.89]],"id":228749}]}]}
{"op":"mcm","clk":"ANSrpQkA27+VCgCnqJsK","pt":1657539233266,"mc":[{"id":"1.200806927","rc":[{"atb":[[1.29,18.04]],"id":228749}]}]}
{"op":"mcm","clk":"AL+spQkA/cCVCgDjqJsK","pt":1657539234879,"mc":[{"id":"1.200806927","rc":[{"atb":[[1.3,0.11]],"id":228749}]}]}
{"op":"mcm","clk":"APuspQkAwsGVCgD0qJsK","pt":1657539235478,"mc":[{"id":"1.200806927","rc":[{"atl":[[1.7,124.06]],"id":228749}]}]}
{"op":"mcm","clk":"AIatpQkAzsGVCgD4qJsK","pt":1657539235581,"mc":[{"id":"1.200806927","rc":[{"atl":[[1.7,106.02]],"trd":[[1.7,36.08]],"ltp":1.7,"tv":9194.41,"id":228749}],"tv":10069.62}]}
{"op":"mcm","clk":"ANitpQkApcKVCgCYqZsK","pt":1657539236472,"mc":[{"id":"1.200806927","rc":[{"atl":[[1.76,1000]],"id":228749}]}]}
{"op":"mcm","clk":"AIyvpQkAjsSVCgCgqpsK","pt":1657539238863,"mc":[{"id":"1.200806927","rc":[{"atl":[[1.8,235.79]],"id":228749}]}]}
{"op":"mcm","clk":"AIewpQkApMWVCgDfqpsK","pt":1657539240469,"mc":[{"id":"1.200806927","rc":[{"atl":[[4.7,0]],"id":2857977}]}]}
{"op":"mcm","clk":"AJ6wpQkAxcWVCgDrqpsK","pt":1657539240778,"mc":[{"id":"1.200806927","rc":[{"atl":[[1.75,9.02]],"id":228749}]}]}
{"op":"mcm","clk":"ALWwpQkA4MWVCgD7qpsK","pt":1657539241085,"mc":[{"id":"1.200806927","rc":[{"atb":[[1.3,0.75]],"id":228749}]}]}
{"op":"mcm","clk":"APaxpQkAsMeVCgCYrJsK","pt":1657539243378,"mc":[{"id":"1.200806927","rc":[{"atb":[[2.3,9.02]],"id":2857977}]}]}
{"op":"mcm","clk":"AP6xpQkAvceVCgCfrJsK","pt":1657539243481,"mc":[{"id":"1.200806927","rc":[{"atl":[[1.8,227.93]],"id":228749}]}]}
{"op":"mcm","clk":"AOCypQkAnsiVCgDTrJsK","pt":1657539244480,"mc":[{"id":"1.200806927","rc":[{"atl":[[1.8,27.93]],"id":228749}]}]}
{"op":"mcm","clk":"AIy0pQkA/cmVCgDErZsK","pt":1657539246592,"mc":[{"id":"1.200806927","rc":[{"atl":[[1.8,100.06]],"id":228749}]}]}
{"op":"mcm","clk":"AMe0pQkAyMqVCgD7rZsK","pt":1657539247308,"mc":[{"id":"1.200806927","rc":[{"atl":[[1.75,0]],"id":228749}]}]}
{"op":"mcm","clk":"AO60pQkA+8qVCgCUrpsK","pt":1657539247816,"mc":[{"id":"1.200806927","rc":[{"atl":[[1.69,18.13]],"id":228749}]}]}
{"op":"mcm","clk":"AIe1pQkAlcuVCgCprpsK","pt":1657539248084,"mc":[{"id":"1.200806927","rc":[{"atl":[[1.66,328.58]],"id":228749}]}]}
{"op":"mcm","clk":"AKS2pQkAw8yVCgCRr5sK","pt":1657539249899,"mc":[{"id":"1.200806927","rc":[{"atb":[[1.29,148.04]],"id":228749}]}]}
{"op":"mcm","clk":"AMS2pQkA4syVCgCpr5sK","pt":1657539250298,"mc":[{"id":"1.200806927","rc":[{"atb":[[2.46,5.07]],"id":2857977}]}]}
{"op":"mcm","clk":"AIi4pQkAo86VCgChsJsK","pt":1657539252392,"mc":[{"id":"1.200806927","rc":[{"atl":[[1.61,9.02]],"id":228749}]}]}
{"op":"mcm","clk":"AKS4pQkAt86VCgC0sJsK","pt":1657539252687,"mc":[{"id":"1.200806927","rc":[{"atb":[[2.46,10.15]],"id":2857977}]}]}
{"op":"mcm","clk":"ALu5pQkA9s+VCgC3sZsK","pt":1657539254488,"mc":[{"id":"1.200806927","rc":[{"atb":[[1.3,0.65]],"id":228749}]}]}
{"op":"mcm","clk":"AOq5pQkApdCVCgDdsZsK","pt":1657539255102,"mc":[{"id":"1.200806927","rc":[{"atb":[[1.29,18.04]],"id":228749}]}]}
{"op":"mcm","clk":"AJa6pQkA39CVCgD/sZsK","pt":1657539255688,"mc":[{"id":"1.200806927","rc":[{"atb":[[1.29,0],[1.3,0],[1.28,127.03]],"atl":[[1.61,0],[1.66,304.16]],"trd":[[1.61,18.04],[1.66,48.85],[1.29,1655.84],[1.3,515.57],[1.28,2083.58]],"ltp":1.28,"tv":9377.3,"id":228749}],"tv":10252.51}]}
{"op":"mcm","clk":"ANq6pQkAsNGVCgC5spsK","pt":1657539256513,"mc":[{"id":"1.200806927","rc":[{"atl":[[1.66,303.54]],"trd":[[1.66,49.47]],"ltp":1.66,"tv":9377.92,"id":228749},{"trd":[[2.5,0.41]],"ltp":2.5,"tv":875.62,"id":2857977}],"tv":10253.54}]}
{"op":"mcm","clk":"APK6pQkAydGVCgDFspsK","pt":1657539256787,"mc":[{"id":"1.200806927","rc":[{"atl":[[1.69,0]],"id":228749}]}]}
{"op":"mcm","clk":"AKu8pQkAktOVCgC+s5sK","pt":1657539259084,"mc":[{"id":"1.200806927","rc":[{"atl":[[1.5,180.32]],"id":228749}]}]}
{"op":"mcm","clk":"AIS9pQkA4tOVCgDts5sK","pt":1657539260000,"mc":[{"id":"1.200806927","rc":[{"atl":[[1.6,7.99]],"id":228749}]}]}
{"op":"mcm","clk":"AJW9pQkA8dOVCgD7s5sK","pt":1657539260205,"mc":[{"id":"1.200806927","rc":[{"atb":[[1.3,130]],"id":228749}]}]}
{"op":"mcm","clk":"ALK+pQkAmtWVCgDotJsK","pt":1657539261894,"mc":[{"id":"1.200806927","rc":[{"atl":[[1.6,26.12]],"id":228749}]}]}
{"op":"mcm","clk":"AIjCpQkAn9mVCgDMt5sK","pt":1657539267628,"mc":[{"id":"1.200806927","rc":[{"atl":[[1.33,3]],"id":228749}]}]}
{"op":"mcm","clk":"ALXDpQkAztqVCgDNuJsK","pt":1657539269499,"mc":[{"id":"1.200806927","rc":[{"atb":[[2.3,0]],"id":2857977}]}]}
{"op":"mcm","clk":"ANXFpQkAytyVCgD5uZsK","pt":1657539272222,"mc":[{"id":"1.200806927","rc":[{"atl":[[1.49,0.22]],"id":228749}]}]}
{"op":"mcm","clk":"AOfFpQkA4NyVCgCDupsK","pt":1657539272411,"mc":[{"id":"1.200806927","rc":[{"atb":[[1.24,422.83]],"id":228749}]}]}
{"op":"mcm","clk":"AKjGpQkArN2VCgCqupsK","pt":1657539273140,"mc":[{"id":"1.200806927","rc":[{"atb":[[1.28,0]],"id":228749}]}]}
{"op":"mcm","clk":"AP3GpQkAi96VCgDqupsK","pt":1657539274120,"mc":[{"id":"1.200806927","rc":[{"atl":[[1.8,99.16]],"id":228749}]}]}
{"op":"mcm","clk":"AJ7IpQkAnd+VCgC5u5sK","pt":1657539275496,"mc":[{"id":"1.200806927","rc":[{"atl":[[1.33,2.07]],"trd":[[1.33,10.8]],"ltp":1.33,"tv":9378.85,"id":228749},{"trd":[[4,1.96]],"ltp":4,"tv":875.93,"id":2857977}],"tv":10254.78}]}
{"op":"mcm","clk":"APjIpQkA/t+VCgDpu5sK","pt":1657539276578,"mc":[{"id":"1.200806927","rc":[{"atl":[[1.34,3]],"id":228749}]}]}
{"op":"mcm","clk":"AIzJpQkAlOCVCgDzu5sK","pt":1657539276799,"mc":[{"id":"1.200806927","rc":[{"atl":[[1.49,0]],"id":228749}]}]}
{"op":"mcm","clk":"AKbKpQkAt+GVCgDSvJsK","pt":1657539278659,"mc":[{"id":"1.200806927","rc":[{"atl":[[1.8,100.01]],"id":228749}]}]}
{"op":"mcm","clk":"AOHKpQkAmOKVCgCAvZsK","pt":1657539279446,"mc":[{"id":"1.200806927","rc":[{"atl":[[1.34,2.39],[1.33,0]],"trd":[[1.34,84.33],[1.33,12.87]],"ltp":1.34,"tv":9381.53,"id":228749},{"trd":[[3.9,6.93],[4,2.65]],"ltp":3.9,"tv":876.83,"id":2857977}],"tv":10258.36}]}
{"op":"mcm","clk":"AJ/LpQkA6+KVCgCjvZsK","pt":1657539280176,"mc":[{"id":"1.200806927","rc":[{"atb":[[1.3,129.55]],"trd":[[1.3,516.47]],"ltp":1.3,"tv":9382.43,"id":228749}],"tv":10259.26}]}
{"op":"mcm","clk":"APrLpQkAwuOVCgDjvZsK","pt":1657539281085,"mc":[{"id":"1.200806927","rc":[{"atb":[[1.3,89.96]],"trd":[[1.3,595.65]],"tv":9461.61,"id":228749}],"tv":10338.44}]}
{"op":"mcm","clk":"AJPMpQkA2uOVCgDvvZsK","pt":1657539281368,"mc":[{"id":"1.200806927","rc":[{"atl":[[1.7,119.55]],"id":228749}]}]}
{"op":"mcm","clk":"AKbMpQkA7+OVCgD5vZsK","pt":1657539281549,"mc":[{"id":"1.200806927","rc":[{"atb":[[1.3,89.76]],"trd":[[1.3,596.05]],"tv":9462.01,"id":228749}],"tv":10338.84}]}
{"op":"mcm","clk":"AMrMpQkAjeSVCgCPvpsK","pt":1657539281960,"mc":[{"id":"1.200806927","rc":[{"atl":[[1.34,1.11]],"trd":[[1.34,85.61]],"ltp":1.34,"tv":9463.29,"id":228749},{"trd":[[3.9,7.37]],"tv":877.27,"id":2857977}],"tv":10340.56}]}
{"op":"mcm","clk":"ANTMpQkAleSVCgCSvpsK","pt":1657539282060,"mc":[{"id":"1.200806927","rc":[{"atl":[[1.6,18.13]],"id":228749}]}]}
{"op":"mcm","clk":"APPMpQkAq+SVCgCnvpsK","pt":1657539282351,"mc":[{"id":"1.200806927","rc":[{"atb":[[1.3,80.29]],"trd":[[1.3,614.99]],"ltp":1.3,"tv":9482.23,"id":228749}],"tv":10359.5}]}
{"op":"mcm","clk":"AOnNpQkApeWVCgDmvpsK","pt":1657539283683,"mc":[{"id":"1.200806927","rc":[{"atb":[[1.3,80.19]],"trd":[[1.3,615.19]],"tv":9482.43,"id":228749}],"tv":10359.7}]}
{"op":"mcm","clk":"AIPOpQkAxeWVCgD6vpsK","pt":1657539283977,"mc":[{"id":"1.200806927","rc":[{"atl":[[1.6,0]],"id":228749}]}]}
{"op":"mcm","clk":"ALLOpQkA8uWVCgCZv5sK","pt":1657539284466,"mc":[{"id":"1.200806927","rc":[{"atb":[[2.2,13.38]],"id":2857977}]}]}
{"op":"mcm","clk":"AOXOpQkAteaVCgDQv5sK","pt":1657539285182,"mc":[{"id":"1.200806927","rc":[{"atl":[[1.32,5]],"id":228749}]}]}
{"op":"mcm","clk":"AODPpQkAw+eVCgCywJsK","pt":1657539286672,"mc":[{"id":"1.200806927","rc":[{"atl":[[1.59,45.08]],"id":228749}]}]}
{"op":"mcm","clk":"AMzRpQkA7eiVCgDPwZsK","pt":1657539289098,"mc":[{"id":"1.200806927","rc":[{"atl":[[1.49,18.13]],"id":228749}]}]}
{"op":"mcm","clk":"AIrTpQkAreqVCgDTwpsK","pt":1657539291493,"mc":[{"id":"1.200806927","rc":[{"atl":[[1.48,0.65]],"id":228749}]}]}
{"op":"mcm","clk":"AKPTpQkA0uqVCgDjwpsK","pt":1657539291855,"mc":[{"id":"1.200806927","rc":[{"atl":[[1.34,0.26],[1.32,0]],"trd":[[1.34,87.31],[1.32,516.47]],"ltp":1.34,"tv":9494.13,"id":228749}],"tv":10371.4}]}
{"op":"mcm","clk":"ALLTpQkA3OqVCgDpwpsK","pt":1657539291964,"mc":[{"id":"1.200806927","rc":[{"atb":[[1.34,0.64]],"atl":[[1.34,0]],"trd":[[1.34,87.83]],"tv":9494.65,"id":228749}],"tv":10371.92}]}
{"op":"mcm","clk":"APzTpQkArOuVCgCZw5sK","pt":1657539292901,"mc":[{"id":"1.200806927","rc":[{"atb":[[1.31,9.02]],"id":228749}]}]}
{"op":"mcm","clk":"AOLUpQkAn+yVCgDcw5sK","pt":1657539294190,"mc":[{"id":"1.200806927","rc":[{"atb":[[1.34,0]],"atl":[[1.33,2.36]],"trd":[[1.34,89.11]],"tv":9495.93,"id":228749}],"tv":10373.2}]}
{"op":"mcm","clk":"APPUpQkAwuyVCgDww5sK","pt":1657539294486,"mc":[{"id":"1.200806927","rc":[{"atb":[[1.31,8.33]],"trd":[[1.31,621.39]],"ltp":1.31,"tv":9497.31,"id":228749}],"tv":10374.58}]}
{"op":"mcm","clk":"AITVpQkA3+yVCgD/w5sK","pt":1657539294799,"mc":[{"id":"1.200806927","rc":[{"atb":[[1.31,7.43]],"id":228749}]}]}
{"op":"mcm","clk":"AN3VpQkAlO2VCgCaxJsK","pt":1657539295285,"mc":[{"id":"1.200806927","rc":[{"atb":[[1.25,18.04]],"id":228749}]}]}
{"op":"mcm","clk":"AMfWpQkAoO6VCgD5xJsK","pt":1657539296492,"mc":[{"id":"1.200806927","rc":[{"atb":[[1.31,0],[1.3,0]],"atl":[[1.3,152.75]],"trd":[[1.3,775.57]],"ltp":1.3,"tv":9657.69,"id":228749}],"tv":10534.96}]}
{"op":"mcm","clk":"APnXpQkAtO+VCgDgxZsK","pt":1657539298209,"mc":[{"id":"1.200806927","rc":[{"atl":[[5,0.31]],"id":2857977}]}]}
{"op":"mcm","clk":"AJfYpQkA2++VCgDyxZsK","pt":1657539298581,"mc":[{"id":"1.200806927","rc":[{"atl":[[1.3,151.46]],"trd":[[1.3,778.15]],"tv":9660.27,"id":228749}],"tv":10537.54}]}
{"op":"mcm","clk":"ALvYpQkAk/CVCgCNxpsK","pt":1657539299090,"mc":[{"id":"1.200806927","rc":[{"atl":[[1.78,10.03]],"id":228749},{"atl":[[8,0.56]],"id":2857977}]}]}
{"op":"mcm","clk":"ANLYpQkArfCVCgCYxpsK","pt":1657539299405,"mc":[{"id":"1.200806927","rc":[{"atl":[[1.3,149.1]],"trd":[[1.3,782.87]],"tv":9664.99,"id":228749}],"tv":10542.26}]}
{"op":"mcm","clk":"APTYpQkA4/CVCgCyxpsK","pt":1657539299978,"mc":[{"id":"1.200806927","rc":[{"atl":[[1.3,144.59]],"id":228749}]}]}
{"op":"mcm","clk":"AJDapQkA8/GVCgCJx5sK","pt":1657539301504,"mc":[{"id":"1.200806927","rc":[{"atl":[[1.31,240.37]],"id":228749}]}]}
{"op":"mcm","clk":"ANPapQkAwfKVCgCxx5sK","pt":1657539302298,"mc":[{"id":"1.200806927","rc":[{"atb":[[1.23,0]],"id":228749}]}]}
{"op":"mcm","clk":"ANDcpQkAtPSVCgDayJsK","pt":1657539305119,"mc":[{"id":"1.200806927","rc":[{"atl":[[1.3,143.88]],"trd":[[1.3,783.58]],"tv":9665.7,"id":228749},{"trd":[[4.3,269.95]],"ltp":4.3,"tv":877.49,"id":2857977}],"tv":10543.19}]}
{"op":"mcm","clk":"AJbepQkAiPaVCgDXyZsK","pt":1657539307408,"mc":[{"id":"1.200806927","rc":[{"atb":[[1.25,142.1]],"id":228749}]}]}
{"op":"mcm","clk":"AMPepQkAqfaVCgDsyZsK","pt":1657539307798,"mc":[{"id":"1.200806927","rc":[{"atl":[[1.27,4]],"id":228749}]}]}
{"op":"mcm","clk":"AIbfpQkA6faVCgCeypsK","pt":1657539308604,"mc":[{"id":"1.200806927","rc":[{"atl":[[1.27,3.66]],"trd":[[1.27,675.8]],"ltp":1.27,"tv":9666.39,"id":228749}],"tv":10543.88}]}
{"op":"mcm","clk":"AIHgpQkA4feVCgCAy5sK","pt":1657539310087,"mc":[{"id":"1.200806927","rc":[{"atl":[[1.27,2.8]],"trd":[[1.27,677.52]],"tv":9668.11,"id":228749}],"tv":10545.6}]}
{"op":"mcm","clk":"ANrhpQkA5fmVCgChzJsK","pt":1657539312682,"mc":[{"id":"1.200806927","rc":[{"atl":[[1.27,1.85]],"trd":[[1.27,678.47]],"tv":9669.06,"id":228749},{"trd":[[4.7,57.12]],"ltp":4.7,"tv":877.75,"id":2857977}],"tv":10546.81}]}
{"op":"mcm","clk":"AO/hpQkAiPqVCgC8zJsK","pt":1657539313002,"mc":[{"id":"1.200806927","rc":[{"atl":[[1.27,1.68]],"trd":[[1.27,678.81]],"tv":9669.4,"id":228749}],"tv":10547.15}]}
{"op":"mcm","clk":"AOHjpQkAifyVCgDmzZsK","pt":1657539315720,"mc":[{"id":"1.200806927","rc":[{"atl":[[1.3,144.05]],"id":228749}]}]}
{"op":"mcm","clk":"APfjpQkAmvyVCgDzzZsK","pt":1657539315930,"mc":[{"id":"1.200806927","rc":[{"atl":[[1.27,1.2]],"trd":[[1.27,679.29]],"tv":9669.88,"id":228749},{"trd":[[4.7,57.25]],"tv":877.88,"id":2857977}],"tv":10547.76}]}
{"op":"mcm","clk":"AKXkpQkAxfyVCgCPzpsK","pt":1657539316417,"mc":[{"id":"1.200806927","rc":[{"atl":[[1.28,3]],"id":228749}]}]}
{"op":"mcm","clk":"AI7lpQkArv2VCgDKzpsK","pt":1657539317499,"mc":[{"id":"1.200806927","rc":[{"atl":[[1.27,0.56]],"trd":[[1.27,679.93]],"tv":9670.52,"id":228749},{"trd":[[4.7,57.42]],"tv":878.05,"id":2857977}],"tv":10548.57}]}
{"op":"mcm","clk":"AOHlpQkA7f2VCgD1zpsK","pt":1657539318287,"mc":[{"id":"1.200806927","rc":[{"atl":[[1.49,0]],"id":228749}]}]}
{"op":"mcm","clk":"AIDmpQkAg/6VCgCFz5sK","pt":1657539318646,"mc":[{"id":"1.200806927","rc":[{"atl":[[1.3,142.05],[1.27,0],[1.28,0]],"trd":[[1.3,785.41],[1.27,680.49],[1.28,2086.58]],"ltp":1.3,"tv":9675.91,"id":228749},{"trd":[[4.7,57.57],[4.5,39.95],[4.3,270.5]],"ltp":4.3,"tv":879.6,"id":2857977}],"tv":10555.51}]}
{"op":"mcm","clk":"AJ7npQkAj/+VCgDaz5sK","pt":1657539320241,"mc":[{"id":"1.200806927","rc":[{"atl":[[6.6,0.26]],"id":2857977}]}]}
{"op":"mcm","clk":"AIPppQkA1ICWCgDe0JsK","pt":1657539322728,"mc":[{"id":"1.200806927","rc":[{"atl":[[1.3,141.7]],"trd":[[1.3,785.76]],"tv":9676.26,"id":228749},{"trd":[[4.3,270.61]],"tv":879.71,"id":2857977}],"tv":10555.97}]}
{"op":"mcm","clk":"ALzrpQkA7IKWCgCq0psK","pt":1657539326144,"mc":[{"id":"1.200806927","rc":[{"atl":[[1.5,184.83]],"id":228749}]}]}
{"op":"mcm","clk":"AJXspQkAvoOWCgDl0psK","pt":1657539327035,"mc":[{"id":"1.200806927","rc":[{"atl":[[1.3,134.58]],"trd":[[1.3,792.88]],"tv":9683.38,"id":228749},{"trd":[[4.3,272.76]],"tv":881.86,"id":2857977}],"tv":10565.24}]}
{"op":"mcm","clk":"AI7tpQkAsoSWCgCv05sK","pt":1657539328342,"mc":[{"id":"1.200806927","rc":[{"atl":[[1.29,3]],"id":228749}]}]}
{"op":"mcm","clk":"AP3tpQkAnYWWCgD805sK","pt":1657539329648,"mc":[{"id":"1.200806927","rc":[{"atb":[[1.28,0.26]],"id":228749}]}]}
{"op":"mcm","clk":"AJPxpQkAiYiWCgDy1ZsK","pt":1657539333730,"mc":[{"id":"1.200806927","rc":[{"atl":[[1.29,2.27]],"trd":[[1.29,1656.57]],"ltp":1.29,"tv":9684.11,"id":228749},{"trd":[[4.4,33.99]],"ltp":4.4,"tv":882.07,"id":2857977}],"tv":10566.18}]}
{"op":"mcm","clk":"AMrypQkAx4mWCgDk1psK","pt":1657539335624,"mc":[{"id":"1.200806927","rc":[{"atl":[[8,0]],"id":2857977}]}]}
{"op":"mcm","clk":"AO7zpQkAwIqWCgC215sK","pt":1657539337038,"mc":[{"id":"1.200806927","rc":[{"atb":[[1.28,0]],"atl":[[1.28,3.74]],"trd":[[1.28,2087.1]],"ltp":1.28,"tv":9684.63,"id":228749}],"tv":10566.7}]}
{"op":"mcm","clk":"AKD0pQkA5oqWCgDV15sK","pt":1657539337558,"mc":[{"id":"1.200806927","rc":[{"atl":[[1.28,3.13]],"trd":[[1.28,2087.71]],"tv":9685.24,"id":228749},{"trd":[[4.5,40.12]],"ltp":4.5,"tv":882.24,"id":2857977}],"tv":10567.48}]}
{"op":"mcm","clk":"AMP0pQkAjYuWCgDo15sK","pt":1657539337913,"mc":[{"id":"1.200806927","rc":[{"atl":[[1.28,2.76]],"trd":[[1.28,2088.08]],"tv":9685.61,"id":228749},{"trd":[[4.5,40.23]],"tv":882.35,"id":2857977}],"tv":10567.96}]}
{"op":"mcm","clk":"ANv1pQkAn4yWCgDH2JsK","pt":1657539339652,"mc":[{"id":"1.200806927","rc":[{"atl":[[1.28,2]],"trd":[[1.28,2088.84]],"tv":9686.37,"id":228749},{"trd":[[4.5,40.44]],"tv":882.56,"id":2857977}],"tv":10568.93}]}
{"op":"mcm","clk":"AI/2pQkA1IyWCgDt2JsK","pt":1657539340213,"mc":[{"id":"1.200806927","rc":[{"atl":[[8,0.26]],"id":2857977}]}]}
{"op":"mcm","clk":"AIj4pQkAq46WCgCa2psK","pt":1657539342406,"mc":[{"id":"1.200806927","rc":[{"atl":[[2,2.46]],"id":228749}]}]}
{"op":"mcm","clk":"APD4pQkAiY+WCgDS2psK","pt":1657539343353,"mc":[{"id":"1.200806927","rc":[{"atb":[[1.29,0.03]],"atl":[[1.29,0],[1.28,0]],"trd":[[1.29,1661.11],[1.28,2092.84]],"ltp":1.29,"tv":9694.91,"id":228749}],"tv":10577.47}]}
{"op":"mcm","clk":"ANT5pQkA84+WCgCh25sK","pt":1657539344464,"mc":[{"id":"1.200806927","rc":[{"atl":[[1.66,0]],"id":228749}]}]}
{"op":"mcm","clk":"AIP6pQkAoJCWCgDS25sK","pt":1657539345083,"mc":[{"id":"1.200806927","rc":[{"atb":[[1.29,0]],"atl":[[1.27,2.97]],"trd":[[1.29,1661.18]],"tv":9694.98,"id":228749}],"tv":10577.54}]}
{"op":"mcm","clk":"AL/6pQkAzJCWCgDw25sK","pt":1657539345579,"mc":[{"id":"1.200806927","rc":[{"atl":[[1.3,133.04],[1.27,0]],"trd":[[1.27,686.43]],"ltp":1.27,"tv":9700.92,"id":228749}],"tv":10583.48}]}
{"op":"mcm","clk":"AISApgkArZWWCgCc4JsK","pt":1657539353693,"mc":[{"id":"1.200806927","rc":[{"atl":[[1.55,422.83]],"id":228749}]}]}
{"op":"mcm","clk":"ANGCpgkA/JeWCgCk4psK","pt":1657539357483,"mc":[{"id":"1.200806927","rc":[{"atl":[[1.3,113.04]],"trd":[[1.3,832.88]],"ltp":1.3,"tv":9740.92,"id":228749}],"tv":10623.48}]}
{"op":"mcm","clk":"AO2DpgkAgpmWCgCc45sK","pt":1657539359212,"mc":[{"id":"1.200806927","rc":[{"atl":[[10,0.31]],"id":2857977}]}]}
{"op":"mcm","clk":"AJqGpgkAhpuWCgDh5JsK","pt":1657539362186,"mc":[{"id":"1.200806927","rc":[{"atl":[[1.8,27.88]],"id":228749}]}]}
{"op":"mcm","clk":"ALGJpgkA+52WCgDn5psK","pt":1657539366292,"mc":[{"id":"1.200806927","rc":[{"atb":[[1.27,1.8]],"id":228749}]}]}
{"op":"mcm","clk":"ALqJpgkAhp6WCgDp5psK","pt":1657539366388,"mc":[{"id":"1.200806927","rc":[{"atb":[[1.27,4.05]],"id":228749}]}]}
{"op":"mcm","clk":"ANONpgkAl6KWCgDw6ZsK","pt":1657539372276,"mc":[{"id":"1.200806927","rc":[{"atl":[[1.59,0]],"id":228749}]}]}
{"op":"mcm","clk":"ANaOpgkAh6OWCgCy6psK","pt":1657539373670,"mc":[{"id":"1.200806927","rc":[{"atl":[[1.3,108.74]],"trd":[[1.3,841.48]],"tv":9749.52,"id":228749}],"tv":10632.08}]}
{"op":"mcm","clk":"AOSPpgkA96OWCgCI65sK","pt":1657539375085,"mc":[{"id":"1.200806927","rc":[{"atb":[[1.27,3.2]],"trd":[[1.27,688.13]],"ltp":1.27,"tv":9751.22,"id":228749}],"tv":10633.78}]}
{"op":"mcm","clk":"AP2PpgkAkqSWCgCb65sK","pt":1657539375399,"mc":[{"id":"1.200806927","rc":[{"atl":[[1.3,108.03]],"trd":[[1.3,842.19]],"ltp":1.3,"tv":9751.93,"id":228749},{"trd":[[4.3,272.98]],"ltp":4.3,"tv":882.78,"id":2857977}],"tv":10634.71}]}
{"op":"mcm","clk":"AIOQpgkAnKSWCgCh65sK","pt":1657539375507,"mc":[{"id":"1.200806927","rc":[{"atl":[[1.3,107.93]],"trd":[[1.3,842.39]],"tv":9752.13,"id":228749}],"tv":10634.91}]}
{"op":"mcm","clk":"AJ2QpgkAsKSWCgC365sK","pt":1657539375808,"mc":[{"id":"1.200806927","rc":[{"atl":[[1.3,105.08]],"trd":[[1.3,845.24]],"tv":9754.98,"id":228749},{"trd":[[4.3,273.84]],"tv":883.64,"id":2857977}],"tv":10638.62}]}
{"op":"mcm","clk":"AOiSpgkAw6aWCgC27ZsK","pt":1657539379418,"mc":[{"id":"1.200806927","rc":[{"atl":[[13,0.21]],"id":2857977}]}]}
{"op":"mcm","clk":"AJmUpgkA96eWCgDK7psK","pt":1657539381519,"mc":[{"id":"1.200806927","rc":[{"atl":[[1.3,104.65]],"trd":[[1.3,846.1]],"tv":9755.84,"id":228749}],"tv":10639.48}]}
{"op":"mcm","clk":"AKKUpgkAgKiWCgDQ7psK","pt":1657539381637,"mc":[{"id":"1.200806927","rc":[{"atl":[[1.3,103.23]],"trd":[[1.3,847.52]],"tv":9757.26,"id":228749},{"trd":[[4.3,274.27]],"tv":884.07,"id":2857977}],"tv":10641.33}]}
{"op":"mcm","clk":"AMaUpgkAraiWCgDr7psK","pt":1657539382049,"mc":[{"id":"1.200806927","rc":[{"atl":[[1.29,0.43]],"id":228749}]}]}
{"op":"mcm","clk":"AJeXpgkA6qqWCgDq8JsK","pt":1657539385510,"mc":[{"id":"1.200806927","rc":[{"atl":[[1.29,0.33]],"trd":[[1.29,1661.38]],"ltp":1.29,"tv":9757.46,"id":228749}],"tv":10641.53}]}
{"op":"mcm","clk":"AKiXpgkAhKuWCgD48JsK","pt":1657539385814,"mc":[{"id":"1.200806927","rc":[{"atb":[[1.26,0],[1.25,0],[1.27,0]],"atl":[[1.25,2089.49]],"trd":[[1.26,679.03],[1.25,1055.14]],"ltp":1.25,"tv":10078.98,"id":228749},{"atl":[[5,0]],"trd":[[5,10.99]],"ltp":5,"tv":884.38,"id":2857977}],"tv":10963.36}]}
{"op":"mcm","clk":"ANmYpgkAsKyWCgDg8ZsK","pt":1657539387530,"mc":[{"id":"1.200806927","rc":[{"atl":[[1.25,2089.29]],"trd":[[1.25,1055.54]],"tv":10079.38,"id":228749}],"tv":10963.76}]}
{"op":"mcm","clk":"AIWZpgkA1qyWCgD98ZsK","pt":1657539388027,"mc":[{"id":"1.200806927","rc":[{"atl":[[1.25,2088.86]],"trd":[[1.25,1055.97]],"tv":10079.81,"id":228749},{"trd":[[5,11.09]],"tv":884.48,"id":2857977}],"tv":10964.29}]}
{"op":"mcm","clk":"AOSZpgkArq2WCgDU8psK","pt":1657539389037,"mc":[{"id":"1.200806927","rc":[{"atl":[[1.25,2085.42]],"trd":[[1.25,1059.41]],"tv":10083.25,"id":228749},{"trd":[[5,11.95]],"tv":885.34,"id":2857977}],"tv":10968.59}]}
{"op":"mcm","clk":"AOCepgkAmLKWCgDF9psK","pt":1657539395816,"mc":[{"id":"1.200806927","rc":[{"atb":[[1.15,10.03]],"id":228749}]}]}
{"op":"mcm","clk":"AJKfpgkAwbKWCgDp9psK","pt":1657539396352,"mc":[{"id":"1.200806927","rc":[{"atl":[[1.25,2065.45]],"trd":[[1.25,1099.35]],"tv":10123.19,"id":228749}],"tv":11008.53}]}
{"op":"mcm","clk":"ANOfpgkA9LKWCgCW95sK","pt":1657539396925,"mc":[{"id":"1.200806927","rc":[{"atl":[[1.25,2065.02]],"trd":[[1.25,1100.21]],"tv":10124.05,"id":228749}],"tv":11009.39}]}
{"op":"mcm","clk":"AOigpgkA5bOWCgD295sK","pt":1657539398338,"mc":[{"id":"1.200806927","rc":[{"atl":[[1.25,2060.51]],"id":228749}]}]}
{"op":"mcm","clk":"AP+gpgkA97OWCgCK+JsK","pt":1657539398565,"mc":[{"id":"1.200806927","rc":[{"atl":[[1.25,2057.43]],"trd":[[1.25,1103.29]],"tv":10127.13,"id":228749},{"trd":[[5,12.72]],"tv":886.11,"id":2857977}],"tv":11013.24}]}
{"op":"mcm","clk":"AL6hpgkAp7SWCgCv+JsK","pt":1657539399105,"mc":[{"id":"1.200806927","rc":[{"atl":[[1.25,0]],"id":228749}]}]}
{"op":"mcm","clk":"ANqhpgkAw7SWCgDD+JsK","pt":1657539399429,"mc":[{"id":"1.200806927","rc":[{"atl":[[5,0.11]],"id":2857977}]}]}
{"op":"mcm","clk":"ANWipgkAtrWWCgCa+ZsK","pt":1657539400853,"mc":[{"id":"1.200806927","rc":[{"atb":[[1.25,0.1]],"id":228749}]}]}
{"op":"mcm","clk":"APqipgkA3LWWCgCv+ZsK","pt":1657539401273,"mc":[{"id":"1.200806927","rc":[{"atb":[[1.24,419.05],[1.25,0]],"trd":[[1.24,781.72],[1.25,1103.92]],"ltp":1.24,"tv":10135.32,"id":228749},{"atl":[[5,0]],"trd":[[5,12.83]],"tv":886.22,"id":2857977}],"tv":11021.54}]}
{"op":"mcm","clk":"AOajpgkAp7aWCgDo+ZsK","pt":1657539402226,"mc":[{"id":"1.200806927","rc":[{"atl":[[5,0.1]],"id":2857977}]}]}
{"op":"mcm","clk":"ALukpgkA2LaWCgCc+psK","pt":1657539403036,"mc":[{"id":"1.200806927","rc":[{"atl":[[5,0.2]],"id":2857977}]}]}
{"op":"mcm","clk":"AMukpgkA5baWCgCj+psK","pt":1657539403231,"mc":[{"id":"1.200806927","rc":[{"atl":[[5,0.43]],"id":2857977}]}]}
{"op":"mcm","clk":"ANakpgkA7baWCgCs+psK","pt":1657539403339,"mc":[{"id":"1.200806927","rc":[{"atl":[[1.55,512.99]],"id":228749},{"atl":[[5,0.23]],"id":2857977}]}]}
{"op":"mcm","clk":"AOmkpgkA+7aWCgC++psK","pt":1657539403547,"mc":[{"id":"1.200806927","rc":[{"atb":[[1.25,124.06]],"id":228749},{"atl":[[5,0.7]],"id":2857977}]}]}
{"op":"mcm","clk":"APukpgkAhLeWCgDF+psK","pt":1657539403676,"mc":[{"id":"1.200806927","rc":[{"atl":[[5,1.13]],"id":2857977}]}]}
{"op":"mcm","clk":"ALKlpgkA1beWCgDr+psK","pt":1657539404279,"mc":[{"id":"1.200806927","rc":[{"atl":[[16.5,0.21]],"id":2857977}]}]}
{"op":"mcm","clk":"AOClpgkAgbiWCgCK+5sK","pt":1657539404771,"mc":[{"id":"1.200806927","rc":[{"atl":[[5,0.9]],"id":2857977}]}]}
{"op":"mcm","clk":"AJumpgkAtriWCgCr+5sK","pt":1657539405387,"mc":[{"id":"1.200806927","rc":[{"atb":[[1.1,368.75]],"id":228749}]}]}
{"op":"mcm","clk":"AKampgkAvbiWCgCw+5sK","pt":1657539405484,"mc":[{"id":"1.200806927","rc":[{"atl":[[1.48,0]],"id":228749}]}]}
{"op":"mcm","clk":"AK+mpgkAx7iWCgC2+5sK","pt":1657539405594,"mc":[{"id":"1.200806927","rc":[{"atl":[[5,1.33]],"id":2857977}]}]}
{"op":"mcm","clk":"APCmpgkAhLmWCgDf+5sK","pt":1657539406274,"mc":[{"id":"1.200806927","rc":[{"atb":[[1.25,123.66]],"trd":[[1.25,1104.72]],"ltp":1.25,"tv":10136.12,"id":228749}],"tv":11022.34}]}
{"op":"mcm","clk":"ALGnpgkAvLmWCgCU/JsK","pt":1657539406978,"mc":[{"id":"1.200806927","rc":[{"atb":[[1.25,132.68]],"id":228749}]}]}
{"op":"mcm","clk":"ANOnpgkA4bmWCgCr/JsK","pt":1657539407399,"mc":[{"id":"1.200806927","rc":[{"atb":[[1.25,141.7]],"id":228749}]}]}
{"op":"mcm","clk":"AMqopgkA3rqWCgCC/ZsK","pt":1657539408700,"mc":[{"id":"1.200806927","rc":[{"atl":[[5,1.76]],"id":2857977}]}]}
{"op":"mcm","clk":"APSopgkAgbuWCgCc/ZsK","pt":1657539409169,"mc":[{"id":"1.200806927","rc":[{"atl":[[5,3.11]],"id":2857977}]}]}
{"op":"mcm","clk":"AI6qpgkAsbyWCgCh/psK","pt":1657539410998,"mc":[{"id":"1.200806927","rc":[{"atb":[[1.24,0],[1.25,0]],"atl":[[1.23,328.44]],"trd":[[1.24,1619.82],[1.25,1364.47]],"ltp":1.24,"tv":11233.97,"id":228749},{"atl":[[5,0]],"trd":[[5,15.94]],"tv":889.33,"id":2857977}],"tv":12123.3}]}
{"op":"mcm","clk":"APetpgkA7L+WCgCBgZwK","pt":1657539416195,"mc":[{"id":"1.200806927","rc":[{"atl":[[1.23,288.67]],"trd":[[1.23,556.63]],"ltp":1.23,"tv":11313.51,"id":228749}],"tv":12202.84}]}
{"op":"mcm","clk":"AKCupgkAnsCWCgChgZwK","pt":1657539416680,"mc":[{"id":"1.200806927","rc":[{"atl":[[1.55,90.16]],"id":228749}]}]}
{"op":"mcm","clk":"AM2upgkAzMCWCgDBgZwK","pt":1657539417192,"mc":[{"id":"1.200806927","rc":[{"atl":[[1.76,0]],"id":228749}]}]}
{"op":"mcm","clk":"AKuvpgkAnMGWCgCXgpwK","pt":1657539418306,"mc":[{"id":"1.200806927","rc":[{"atl":[[1.66,6.69]],"id":228749}]}]}
{"op":"mcm","clk":"AOuvpgkA1cGWCgDXgpwK","pt":1657539419089,"mc":[{"id":"1.200806927","rc":[{"atl":[[1.23,286.81]],"trd":[[1.23,558.49]],"tv":11315.37,"id":228749},{"trd":[[5.3,7.85]],"ltp":5.3,"tv":889.76,"id":2857977}],"tv":12205.13}]}
{"op":"mcm","clk":"APSvpgkA3MGWCgDggpwK","pt":1657539419200,"mc":[{"id":"1.200806927","rc":[{"atl":[[1.23,285.88]],"trd":[[1.23,559.42]],"tv":11316.3,"id":228749},{"trd":[[5.3,8.07]],"tv":889.98,"id":2857977}],"tv":12206.28}]}
{"op":"mcm","clk":"AIiwpgkA7MGWCgDxgpwK","pt":1657539419397,"mc":[{"id":"1.200806927","rc":[{"atl":[[1.23,0]],"id":228749}]}]}
{"op":"mcm","clk":"AJmwpgkA+MGWCgCIg5wK","pt":1657539419629,"mc":[{"id":"1.200806927","rc":[{"atb":[[1.24,1000]],"id":228749}]}]}
{"op":"mcm","clk":"AK+wpgkAiMKWCgCbg5wK","pt":1657539419804,"mc":[{"id":"1.200806927","rc":[{"atb":[[1.24,0]],"id":228749}]}]}
{"op":"mcm","clk":"AOuwpgkAwMKWCgDOg5wK","pt":1657539420490,"mc":[{"id":"1.200806927","rc":[{"atb":[[1.22,291.81]],"trd":[[1.22,181.27]],"ltp":1.22,"tv":11372.68,"id":228749}],"tv":12262.66}]}
{"op":"mcm","clk":"AKixpgkA78KWCgDxg5wK","pt":1657539421096,"mc":[{"id":"1.200806927","rc":[{"atl":[[5.3,1.51]],"id":2857977}]}]}
{"op":"mcm","clk":"ALOxpgkA+8KWCgD5g5wK","pt":1657539421221,"mc":[{"id":"1.200806927","rc":[{"atl":[[1.8,26.98]],"id":228749}]}]}
{"op":"mcm","clk":"APmxpgkAu8OWCgCihJwK","pt":1657539421915,"mc":[{"id":"1.200806927","rc":[{"atl":[[1.27,809.61]],"id":228749}]}]}
{"op":"mcm","clk":"AMWypgkAjMSWCgDrhJwK","pt":1657539422819,"mc":[{"id":"1.200806927","rc":[{"atl":[[5.3,1.68]],"id":2857977}]}]}
{"op":"mcm","clk":"AOqypgkAtsSWCgCNhZwK","pt":1657539423192,"mc":[{"id":"1.200806927","rc":[{"atl":[[5.3,2.45]],"id":2857977}]}]}
{"op":"mcm","clk":"AMuzpgkAkcWWCgDghZwK","pt":1657539424296,"mc":[{"id":"1.200806927","rc":[{"atl":[[5.3,3.53]],"id":2857977}]}]}
{"op":"mcm","clk":"ANSzpgkAnMWWCgDnhZwK","pt":1657539424398,"mc":[{"id":"1.200806927","rc":[{"atb":[[1.22,157.02]],"trd":[[1.22,450.85],[1.23,574.63]],"tv":11657.47,"id":228749},{"atl":[[5.3,0.43]],"trd":[[5.3,11.6]],"tv":893.51,"id":2857977}],"tv":12550.98}]}
{"op":"mcm","clk":"AN+zpgkAqMWWCgDthZwK","pt":1657539424512,"mc":[{"id":"1.200806927","rc":[{"atl":[[20,0.26]],"id":2857977}]}]}
{"op":"mcm","clk":"AJ20pgkA+cWWCgCchpwK","pt":1657539425294,"mc":[{"id":"1.200806927","rc":[{"atl":[[5.3,1.81]],"id":2857977}]}]}
{"op":"mcm","clk":"AN20pgkAzMaWCgDUhpwK","pt":1657539426006,"mc":[{"id":"1.200806927","rc":[{"atb":[[1.23,9.02]],"id":228749}]}]}
{"op":"mcm","clk":"AIO1pgkA88aWCgDwhpwK","pt":1657539426430,"mc":[{"id":"1.200806927","rc":[{"atb":[[1.23,12.63]],"id":228749}]}]}
{"op":"mcm","clk":"AJG2pgkA28eWCgCth5wK","pt":1657539427395,"mc":[{"id":"1.200806927","rc":[{"atl":[[5.3,0.43]],"id":2857977}]}]}
{"op":"mcm","clk":"ANm2pgkAsciWCgDih5wK","pt":1657539428297,"mc":[{"id":"1.200806927","rc":[{"atl":[[1.24,200]],"id":228749}]}]}
{"op":"mcm","clk":"AK63pgkAl8mWCgCkiJwK","pt":1657539429400,"mc":[{"id":"1.200806927","rc":[{"atl":[[1.3,103.88]],"id":228749}]}]}
{"op":"mcm","clk":"AM+4pgkAysqWCgCRiZwK","pt":1657539431227,"mc":[{"id":"1.200806927","rc":[{"atl":[[5.3,0.56]],"id":2857977}]}]}
{"op":"mcm","clk":"AJW5pgkA4cqWCgChiZwK","pt":1657539431424,"mc":[{"id":"1.200806927","rc":[{"atl":[[1.25,1000]],"id":228749}]}]}
{"op":"mcm","clk":"AKe5pgkA9sqWCgCviZwK","pt":1657539431662,"mc":[{"id":"1.200806927","rc":[{"atl":[[1.25,0]],"id":228749}]}]}
{"op":"mcm","clk":"AK65pgkAg8uWCgC1iZwK","pt":1657539431710,"mc":[{"id":"1.200806927","rc":[{"atl":[[1.25,1000]],"id":228749}]}]}
{"op":"mcm","clk":"ALe5pgkAlsuWCgDCiZwK","pt":1657539431914,"mc":[{"id":"1.200806927","rc":[{"atl":[[1.25,0]],"id":228749},{"atl":[[5.3,0.92]],"id":2857977}]}]}
{"op":"mcm","clk":"AMW6pgkAz8yWCgC6ipwK","pt":1657539433828,"mc":[{"id":"1.200806927","rc":[{"atb":[[1.13,18.13]],"id":228749}]}]}
{"op":"mcm","clk":"ANG6pgkA5MyWCgDGipwK","pt":1657539434002,"mc":[{"id":"1.200806927","rc":[{"atl":[[1.24,198.23]],"trd":[[1.24,1621.59]],"ltp":1.24,"tv":11659.24,"id":228749},{"trd":[[5.1,2.25]],"ltp":5.1,"tv":893.94,"id":2857977}],"tv":12553.18}]}
{"op":"mcm","clk":"AMq7pgkA1s2WCgCai5wK","pt":1657539435108,"mc":[{"id":"1.200806927","rc":[{"atb":[[1.23,0]],"atl":[[1.23,67.04]],"trd":[[1.23,603.85]],"ltp":1.23,"tv":11688.46,"id":228749},{"atl":[[5.3,0]],"trd":[[5.3,12.51]],"ltp":5.3,"tv":894.85,"id":2857977}],"tv":12583.31}]}
{"op":"mcm","clk":"AOC7pgkA9M2WCgCti5wK","pt":1657539435428,"mc":[{"id":"1.200806927","rc":[{"atb":[[1.22,166.04]],"atl":[[1.23,63.04]],"trd":[[1.23,611.84]],"tv":11696.45,"id":228749}],"con":true,"tv":12591.3}]}
{"op":"mcm","clk":"ALW+pgkAwdCWCgCojZwK","pt":1657539438816,"mc":[{"id":"1.200806927","rc":[{"atl":[[1.23,62.94]],"trd":[[1.23,612.04]],"tv":11696.65,"id":228749}],"tv":12591.5}]}
{"op":"mcm","clk":"AJzApgkA1NKWCgDgjpwK","pt":1657539441610,"mc":[{"id":"1.200806927","rc":[{"atl":[[1.23,59.5]],"trd":[[1.23,615.48]],"tv":11700.09,"id":228749},{"trd":[[5.3,13.31]],"tv":895.65,"id":2857977}],"tv":12595.74}]}
{"op":"mcm","clk":"AOHCpgkAitaWCgDnkJwK","pt":1657539445528,"mc":[{"id":"1.200806927","rc":[{"atl":[[25,0.21]],"id":2857977}]}]}
{"op":"mcm","clk":"AMfDpgkA9daWCgC7kZwK","pt":1657539446821,"mc":[{"id":"1.200806927","rc":[{"atl":[[1.23,52.3]],"trd":[[1.23,629.9]],"tv":11714.51,"id":228749}],"tv":12610.16}]}
{"op":"mcm","clk":"AJbGpgkAtdmWCgDfk5wK","pt":1657539450734,"mc":[{"id":"1.200806927","rc":[{"atl":[[1.23,51.37]],"trd":[[1.23,630.83]],"tv":11715.44,"id":228749},{"trd":[[5.3,13.52]],"tv":895.86,"id":2857977}],"tv":12611.3}]}
{"op":"mcm","clk":"AKzGpgkAydmWCgDwk5wK","pt":1657539450934,"mc":[{"id":"1.200806927","rc":[{"atl":[[1.23,45.43]],"trd":[[1.23,636.76]],"tv":11721.37,"id":228749},{"trd":[[5.3,14.9]],"tv":897.24,"id":2857977}],"tv":12618.61}]}
{"op":"mcm","clk":"AOHGpgkAg9qWCgCVlJwK","pt":1657539451538,"mc":[{"id":"1.200806927","rc":[{"atl":[[1.23,44.33]],"trd":[[1.23,637.87]],"tv":11722.48,"id":228749},{"trd":[[5.3,15.16]],"tv":897.5,"id":2857977}],"tv":12619.98}]}
{"op":"mcm","clk":"AKLHpgkAwdqWCgC7lJwK","pt":1657539452250,"mc":[{"id":"1.200806927","rc":[{"atb":[[1.22,63.3]],"trd":[[1.22,656.33]],"ltp":1.22,"tv":11927.96,"id":228749}],"tv":12825.46}]}
{"op":"mcm","clk":"AJXIpgkApNuWCgDwlJwK","pt":1657539453328,"mc":[{"id":"1.200806927","rc":[{"atb":[[1.22,54.28]],"id":228749}]}]}
{"op":"mcm","clk":"AJXKpgkApN2WCgCElpwK","pt":1657539455940,"mc":[{"id":"1.200806927","rc":[{"atl":[[1.24,0]],"id":228749}]}]}
{"op":"mcm","clk":"AOTMpgkA+d+WCgDsl5wK","pt":1657539459449,"mc":[{"id":"1.200806927","rc":[{"atb":[[1.22,53.49]],"trd":[[1.22,657.91]],"tv":11929.54,"id":228749}],"tv":12827.04}]}
{"op":"mcm","clk":"AK3OpgkAw+GWCgDrmJwK","pt":1657539461556,"mc":[{"id":"1.200806927","rc":[{"atb":[[1.22,0]],"atl":[[1.22,25.51]],"trd":[[1.22,764.89]],"tv":12036.52,"id":228749}],"tv":12934.02}]}
{"op":"mcm","clk":"AN7PpgkAz+KWCgC/mZwK","pt":1657539463233,"mc":[{"id":"1.200806927","rc":[{"atl":[[1.22,20.88]],"trd":[[1.22,769.52]],"tv":12041.15,"id":228749},{"trd":[[5.5,2.83]],"ltp":5.5,"tv":898.53,"id":2857977}],"tv":12939.68}]}
{"op":"mcm","clk":"AKzSpgkAmuWWCgCim5wK","pt":1657539466656,"mc":[{"id":"1.200806927","rc":[{"atb":[[1.01,2762.47]],"id":228749}]}]}
{"op":"mcm","clk":"AOrSpgkAy+WWCgDkm5wK","pt":1657539467363,"mc":[{"id":"1.200806927","rc":[{"atl":[[1.22,19.33]],"trd":[[1.22,771.07]],"tv":12042.7,"id":228749},{"trd":[[5.5,3.17]],"tv":898.87,"id":2857977}],"tv":12941.57}]}
{"op":"mcm","clk":"ALPTpgkA/+WWCgCSnJwK","pt":1657539468044,"mc":[{"id":"1.200806927","rc":[{"atl":[[1.22,18.43]],"trd":[[1.22,772.87]],"tv":12044.5,"id":228749}],"tv":12943.37}]}
{"op":"mcm","clk":"APfUpgkApueWCgCXnZwK","pt":1657539470152,"mc":[{"id":"1.200806927","rc":[{"atl":[[1.22,16.18]],"trd":[[1.22,775.12]],"tv":12046.75,"id":228749},{"trd":[[5.5,3.67]],"tv":899.37,"id":2857977}],"tv":12946.12}]}
{"op":"mcm","clk":"AMXZpgkAouyWCgD2oJwK","pt":1657539477321,"mc":[{"id":"1.200806927","rc":[{"atb":[[1.22,33.82]],"atl":[[1.22,0]],"trd":[[1.22,807.48]],"tv":12079.11,"id":228749}],"tv":12978.48}]}
{"op":"mcm","clk":"ANDbpgkAse6WCgDYopwK","pt":1657539480221,"mc":[{"id":"1.200806927","rc":[{"atb":[[1.13,0]],"id":228749}]}]}
{"op":"mcm","clk":"AKPdpgkAhfCWCgDuo5wK","pt":1657539482528,"mc":[{"id":"1.200806927","rc":[{"atb":[[1.22,0]],"trd":[[1.22,875.12]],"tv":12146.75,"id":228749}],"tv":13046.12}]}
{"op":"mcm","clk":"AKndpgkAkPCWCgD0o5wK","pt":1657539482634,"mc":[{"id":"1.200806927","rc":[{"atb":[[1.15,28.07]],"id":228749},{"atl":[[5.5,0.13]],"id":2857977}]}]}
{"op":"mcm","clk":"AJnfpgkAm/KWCgCypZwK","pt":1657539485315,"mc":[{"id":"1.200806927","rc":[{"atb":[[1.16,18.13]],"id":228749}]}]}
{"op":"mcm","clk":"AMzfpgkA0vKWCgDjpZwK","pt":1657539485995,"mc":[{"id":"1.200806927","rc":[{"atb":[[1.17,333],[1.22,0.11]],"id":228749}]}]}
{"op":"mcm","clk":"AJfgpgkAm/OWCgCippwK","pt":1657539486992,"mc":[{"id":"1.200806927","rc":[{"atl":[[5.5,0]],"id":2857977}]}]}
{"op":"mcm","clk":"AI7hpgkA5PSWCgDvppwK","pt":1657539488314,"mc":[{"id":"1.200806927","rc":[{"atb":[[1.01,2762.47]],"id":2857977}]}]}
{"op":"mcm","clk":"AOLhpgkAvfWWCgCnp5wK","pt":1657539488821,"mc":[{"id":"1.200806927","rc":[{"atb":[[1.22,0.53]],"id":228749}]}]}
{"op":"mcm","clk":"AJ3jpgkA2PaWCgCvqJwK","pt":1657539490508,"mc":[{"id":"1.200806927","rc":[{"atb":[[1.22,0]],"atl":[[1.22,1.62]],"id":228749}]}]}
{"op":"mcm","clk":"ALHlpgkA3/iWCgD5qZwK","pt":1657539493327,"mc":[{"id":"1.200806927","rc":[{"atl":[[30,0.21]],"id":2857977}]}]}
{"op":"mcm","clk":"APnlpgkApvmWCgClqpwK","pt":1657539494030,"mc":[{"id":"1.200806927","rc":[{"atb":[[1.16,0]],"id":228749}]}]}
{"op":"mcm","clk":"AILmpgkAr/mWCgCsqpwK","pt":1657539494129,"mc":[{"id":"1.200806927","rc":[{"atl":[[1.22,0]],"id":228749}]}]}
{"op":"mcm","clk":"AM3npgkA//qWCgDWq5wK","pt":1657539496510,"mc":[{"id":"1.200806927","rc":[{"atb":[[1.17,332.72],[1.19,0]],"trd":[[1.17,0.56],[1.19,0.34]],"ltp":1.17,"tv":12147.65,"id":228749}],"tv":13047.02}]}
{"op":"mcm","clk":"AKjopgkA4/uWCgChrJwK","pt":1657539497731,"mc":[{"id":"1.200806927","rc":[{"atl":[[1.23,43.47]],"trd":[[1.23,639.59]],"ltp":1.23,"tv":12149.37,"id":228749}],"tv":13048.74}]}
{"op":"mcm","clk":"AKLppgkA0/yWCgCBrZwK","pt":1657539499107,"mc":[{"id":"1.200806927","rc":[{"atb":[[1.18,18.13]],"id":228749}]}]}
{"op":"mcm","clk":"AOTqpgkAgf6WCgCSrpwK","pt":1657539501203,"mc":[{"id":"1.200806927","rc":[{"atb":[[1.18,120.87]],"id":228749}]}]}
{"op":"mcm","clk":"AMvrpgkA/P6WCgDvrpwK","pt":1657539502532,"mc":[{"id":"1.200806927","rc":[{"atb":[[1.18,133.28]],"id":228749}]}]}
{"op":"mcm","clk":"AP7rpgkAs/+WCgCbr5wK","pt":1657539503203,"mc":[{"id":"1.200806927","rc":[{"atl":[[1.8,26.13]],"id":228749}]}]}
{"op":"mcm","clk":"AN3spgkAsICXCgDqr5wK","pt":1657539504411,"mc":[{"id":"1.200806927","rc":[{"atl":[[1.23,41.61]],"trd":[[1.23,641.45]],"tv":12151.23,"id":228749},{"trd":[[5.3,15.59]],"ltp":5.3,"tv":899.8,"id":2857977}],"tv":13051.03}]}
{"op":"mcm","clk":"AJHtpgkA+ICXCgCVsJwK","pt":1657539505043,"mc":[{"id":"1.200806927","rc":[{"atb":[[1.12,0]],"id":228749}]}]}
{"op":"mcm","clk":"AIDvpgkA8IKXCgC9sZwK","pt":1657539507820,"mc":[{"id":"1.200806927","rc":[{"atl":[[1.23,41.06]],"trd":[[1.23,642]],"tv":12151.78,"id":228749},{"trd":[[5.3,15.72]],"tv":899.93,"id":2857977}],"tv":13051.71}]}
{"op":"mcm","clk":"AI3vpgkAgIOXCgDJsZwK","pt":1657539508029,"mc":[{"id":"1.200806927","rc":[{"atb":[[1.22,0.15]],"id":228749}]}]}
{"op":"mcm","clk":"ALLvpgkAnIOXCgDwsZwK","pt":1657539508435,"mc":[{"id":"1.200806927","rc":[{"atl":[[1.23,39.64]],"trd":[[1.23,644.27]],"tv":12154.05,"id":228749},{"trd":[[5.3,15.85]],"tv":900.06,"id":2857977}],"tv":13054.11}]}
{"op":"mcm","clk":"AITwpgkAhoSXCgC+spwK","pt":1657539509553,"mc":[{"id":"1.200806927","rc":[{"atl":[[1.23,37.79]],"trd":[[1.23,646.13]],"tv":12155.91,"id":228749},{"trd":[[5.3,16.28]],"tv":900.49,"id":2857977}],"tv":13056.4}]}
{"op":"mcm","clk":"AKjxpgkAqoWXCgC6s5wK","pt":1657539511534,"mc":[{"id":"1.200806927","rc":[{"atl":[[50,0.21]],"id":2857977}]}]}
{"op":"mcm","clk":"ALfypgkAxIaXCgCWtJwK","pt":1657539513216,"mc":[{"id":"1.200806927","rc":[{"atb":[[1.17,255.87],[1.22,0],[1.18,0]],"trd":[[1.17,154.26],[1.22,875.42],[1.18,269.16]],"ltp":1.17,"tv":12576.47,"id":228749}],"tv":13476.96}]}
{"op":"mcm","clk":"AKb0pgkAuYiXCgC4tZwK","pt":1657539515661,"mc":[{"id":"1.200806927","rc":[{"atl":[[1.18,1.29]],"id":228749}]}]}
{"op":"mcm","clk":"AN30pgkA7YiXCgDYtZwK","pt":1657539516235,"mc":[{"id":"1.200806927","rc":[{"atb":[[1.23,12.29]],"atl":[[1.23,0],[1.18,0]],"trd":[[1.23,721.7],[1.18,271.74]],"ltp":1.23,"tv":12654.62,"id":228749}],"tv":13555.11}]}
{"op":"mcm","clk":"AKP4pgkAyoyXCgDIuJwK","pt":1657539521427,"mc":[{"id":"1.200806927","rc":[{"atb":[[1.23,3.57],[1.12,422.83]],"trd":[[1.23,739.14]],"tv":12672.06,"id":228749}],"tv":13572.55}]}
{"op":"mcm","clk":"AOL4pgkAl42XCgD8uJwK","pt":1657539522160,"mc":[{"id":"1.200806927","rc":[{"atb":[[1.12,845.67]],"id":228749}]}]}
{"op":"mcm","clk":"APT5pgkAwo6XCgDiuZwK","pt":1657539523822,"mc":[{"id":"1.200806927","rc":[{"atb":[[1.12,0]],"atl":[[1.27,0]],"id":228749}]}]}
{"op":"mcm","clk":"AI76pgkA4o6XCgD+uZwK","pt":1657539524143,"mc":[{"id":"1.200806927","rc":[{"atb":[[1.23,0]],"atl":[[1.21,14.56]],"trd":[[1.23,746.28]],"tv":12679.2,"id":228749}],"tv":13579.69}]}
{"op":"mcm","clk":"ALn7pgkAo5CXCgCSu5wK","pt":1657539526220,"mc":[{"id":"1.200806927","rc":[{"atl":[[1.21,11.32]],"trd":[[1.21,6.48]],"ltp":1.21,"tv":12685.68,"id":228749}],"tv":13586.17}]}
{"op":"mcm","clk":"AKv8pgkAlJGXCgDSu5wK","pt":1657539527348,"mc":[{"id":"1.200806927","rc":[{"atl":[[1.23,2.71],[1.21,10.38]],"trd":[[1.21,7.42]],"tv":12686.62,"id":228749},{"trd":[[5.7,0.2]],"ltp":5.7,"tv":900.69,"id":2857977}],"tv":13587.31}]}
{"op":"mcm","clk":"APn8pgkA3JGXCgD7u5wK","pt":1657539528154,"mc":[{"id":"1.200806927","rc":[{"atl":[[1.21,9.91]],"trd":[[1.21,7.89]],"tv":12687.09,"id":228749},{"trd":[[5.7,0.3]],"tv":900.79,"id":2857977}],"tv":13587.88}]}
{"op":"mcm","clk":"AJj9pgkAgJKXCgCTvJwK","pt":1657539528468,"mc":[{"id":"1.200806927","rc":[{"atb":[[1.01,2764.98]],"id":228749}]}]}
{"op":"mcm","clk":"ALb9pgkAoZKXCgCjvJwK","pt":1657539528734,"mc":[{"id":"1.200806927","rc":[{"atb":[[1.01,2763.31]],"id":228749}]}]}
{"op":"mcm","clk":"ANb9pgkAxJKXCgCzvJwK","pt":1657539529045,"mc":[{"id":"1.200806927","rc":[{"atb":[[1.01,2762.47]],"atl":[[1.23,838.65]],"id":228749}]}]}
{"op":"mcm","clk":"AOz9pgkA5JKXCgDOvJwK","pt":1657539529370,"mc":[{"id":"1.200806927","rc":[{"atl":[[1.21,0]],"trd":[[1.21,27.71]],"tv":12706.91,"id":228749}],"tv":13607.7}]}
{"op":"mcm","clk":"AMH/pgkA3JSXCgDpvZwK","pt":1657539531672,"mc":[{"id":"1.200806927","rc":[{"atl":[[1.23,835.94]],"id":228749}]}]}
{"op":"mcm","clk":"AKGBpwkA3paXCgCVv5wK","pt":1657539534168,"mc":[{"id":"1.200806927","rc":[{"atb":[[1.18,0.84]],"id":228749}]}]}
{"op":"mcm","clk":"ALSCpwkAppiXCgCMwJwK","pt":1657539535756,"mc":[{"id":"1.200806927","rc":[{"atb":[[1.05,329.27]],"id":228749}]}]}
{"op":"mcm","clk":"APSCpwkA65iXCgC5wJwK","pt":1657539536475,"mc":[{"id":"1.200806927","rc":[{"atl":[[100,0.21]],"id":2857977}]}]}
{"op":"mcm","clk":"ALSFpwkArZuXCgDLwpwK","pt":1657539539853,"mc":[{"id":"1.200806927","rc":[{"atl":[[5.7,2.71]],"id":2857977}]}]}
{"op":"mcm","clk":"AM2FpwkAx5uXCgDdwpwK","pt":1657539540079,"mc":[{"id":"1.200806927","rc":[{"atl":[[1.21,109.23]],"trd":[[1.21,40.48]],"tv":12719.68,"id":228749},{"atl":[[5.7,0]],"trd":[[5.7,3.01]],"tv":903.5,"id":2857977}],"tv":13623.18}]}
{"op":"mcm","clk":"AP6FpwkAiJyXCgD8wpwK","pt":1657539540662,"mc":[{"id":"1.200806927","rc":[{"atl":[[1.21,107.61]],"trd":[[1.21,42.1]],"tv":12721.3,"id":228749},{"trd":[[5.7,3.35]],"tv":903.84,"id":2857977}],"tv":13625.14}]}
{"op":"mcm","clk":"ALeGpwkA35yXCgCow5wK","pt":1657539541368,"mc":[{"id":"1.200806927","rc":[{"atb":[[1.18,0.74]],"trd":[[1.18,271.94]],"ltp":1.18,"tv":12721.5,"id":228749}],"tv":13625.34}]}
{"op":"mcm","clk":"AIOHpwkAup2XCgDlw5wK","pt":1657539542296,"mc":[{"id":"1.200806927","rc":[{"atl":[[1.21,83.41]],"trd":[[1.21,66.3]],"ltp":1.21,"tv":12745.7,"id":228749},{"trd":[[5.7,8.49]],"tv":908.98,"id":2857977}],"tv":13654.68}]}
{"op":"mcm","clk":"AJOHpwkA1Z2XCgDww5wK","pt":1657539542517,"mc":[{"id":"1.200806927","rc":[{"atb":[[5.4,1.35]],"id":2857977}]}]}
{"op":"mcm","clk":"ALeHpwkA/Z2XCgCLxJwK","pt":1657539542869,"mc":[{"id":"1.200806927","rc":[{"atl":[[1.21,82.33]],"trd":[[1.21,67.38]],"tv":12746.78,"id":228749},{"trd":[[5.7,8.72]],"tv":909.21,"id":2857977}],"tv":13655.99}]}
{"op":"mcm","clk":"ANmHpwkAn56XCgCmxJwK","pt":1657539543207,"mc":[{"id":"1.200806927","rc":[{"atl":[[1.21,81.86]],"trd":[[1.21,67.85]],"tv":12747.25,"id":228749},{"trd":[[5.7,8.82]],"tv":909.31,"id":2857977}],"tv":13656.56}]}
{"op":"mcm","clk":"ALCIpwkA+Z6XCgDexJwK","pt":1657539544085,"mc":[{"id":"1.200806927","rc":[{"atb":[[1.18,9.76]],"id":228749}]}]}
{"op":"mcm","clk":"AMCJpwkAhqCXCgC3xZwK","pt":1657539545480,"mc":[{"id":"1.200806927","rc":[{"atl":[[1.21,81.36]],"trd":[[1.21,68.35]],"tv":12747.75,"id":228749},{"trd":[[5.7,8.93]],"tv":909.42,"id":2857977}],"tv":13657.17}]}
{"op":"mcm","clk":"AM+JpwkAkaCXCgC8xZwK","pt":1657539545577,"mc":[{"id":"1.200806927","rc":[{"atl":[[1.21,77.06]],"trd":[[1.21,76.95]],"tv":12756.35,"id":228749}],"tv":13665.77}]}
{"op":"mcm","clk":"AL6KpwkAsaGXCgD5xZwK","pt":1657539546704,"mc":[{"id":"1.200806927","rc":[{"atl":[[1.21,55.81]],"trd":[[1.21,98.2]],"tv":12777.6,"id":228749},{"trd":[[5.7,13.44]],"tv":913.93,"id":2857977}],"tv":13691.53}]}
{"op":"mcm","clk":"AMmKpwkAvKGXCgCAxpwK","pt":1657539546799,"mc":[{"id":"1.200806927","rc":[{"atl":[[1.21,54.8]],"trd":[[1.21,99.21]],"tv":12778.61,"id":228749},{"trd":[[5.7,13.65]],"tv":914.14,"id":2857977}],"tv":13692.75}]}
{"op":"mcm","clk":"AP2LpwkA5aKXCgD1xpwK","pt":1657539548587,"mc":[{"id":"1.200806927","rc":[{"atl":[[1.21,53.18]],"trd":[[1.21,100.83]],"tv":12780.23,"id":228749},{"trd":[[5.7,14]],"tv":914.49,"id":2857977}],"tv":13694.72}]}
{"op":"mcm","clk":"AIyOpwkAgaWXCgC/yJwK","pt":1657539551472,"mc":[{"id":"1.200806927","rc":[{"atl":[[1.21,53.02]],"trd":[[1.21,101.15]],"tv":12780.55,"id":228749}],"tv":13695.04}]}
{"op":"mcm","clk":"ANSOpwkAxKWXCgDzyJwK","pt":1657539552197,"mc":[{"id":"1.200806927","rc":[{"atl":[[1.21,52.67]],"trd":[[1.21,101.5]],"tv":12780.9,"id":228749},{"trd":[[5.7,14.07]],"tv":914.56,"id":2857977}],"tv":13695.46}]}
{"op":"mcm","clk":"AIyPpwkA+qWXCgCeyZwK","pt":1657539552882,"mc":[{"id":"1.200806927","rc":[{"atl":[[1.21,43.69]],"trd":[[1.21,110.48]],"tv":12789.88,"id":228749},{"trd":[[5.7,15.98]],"tv":916.47,"id":2857977}],"tv":13706.35}]}
{"op":"mcm","clk":"ALGPpwkAoqaXCgC9yZwK","pt":1657539553380,"mc":[{"id":"1.200806927","rc":[{"atb":[[1.18,27.89]],"id":228749}]}]}
{"op":"mcm","clk":"AMWPpwkAuqaXCgDNyZwK","pt":1657539553615,"mc":[{"id":"1.200806927","rc":[{"atl":[[1.21,43.19]],"trd":[[1.21,110.98]],"tv":12790.38,"id":228749},{"trd":[[5.7,16.08]],"tv":916.57,"id":2857977}],"tv":13706.95}]}
{"op":"mcm","clk":"ANiSpwkAh6qXCgDby5wK","pt":1657539558089,"mc":[{"id":"1.200806927","rc":[{"atl":[[1.21,43]],"trd":[[1.21,111.36]],"tv":12790.76,"id":228749}],"tv":13707.33}]}
{"op":"mcm","clk":"ANWUpwkA/6uXCgCczZwK","pt":1657539560736,"mc":[{"id":"1.200806927","rc":[{"atl":[[1.21,42.72]],"trd":[[1.21,111.92]],"tv":12791.32,"id":228749}],"tv":13707.89}]}
{"op":"mcm","clk":"AJaVpwkAzayXCgC/zZwK","pt":1657539561406,"mc":[{"id":"1.200806927","rc":[{"atl":[[1.21,42.5]],"trd":[[1.21,112.36]],"tv":12791.76,"id":228749}],"tv":13708.33}]}
{"op":"mcm","clk":"ALKVpwkA6qyXCgDWzZwK","pt":1657539561707,"mc":[{"id":"1.200806927","rc":[{"atb":[[1.18,25.18]],"trd":[[1.18,273.42]],"ltp":1.18,"tv":12793.24,"id":228749}],"tv":13709.81}]}
{"op":"mcm","clk":"AMSVpwkAga2XCgDizZwK","pt":1657539561883,"mc":[{"id":"1.200806927","rc":[{"atb":[[1.18,18.13]],"id":228749}]}]}
{"op":"mcm","clk":"AJSXpwkA8K6XCgCez5wK","pt":1657539564383,"mc":[{"id":"1.200806927","rc":[{"atb":[[1.18,15.33]],"trd":[[1.18,279.02]],"tv":12798.84,"id":228749}],"tv":13715.41}]}
{"op":"mcm","clk":"AKKYpwkAg7CXCgCU0JwK","pt":1657539565892,"mc":[{"id":"1.200806927","rc":[{"atl":[[1.21,42.07]],"trd":[[1.21,113.22]],"ltp":1.21,"tv":12799.7,"id":228749}],"tv":13716.27}]}
{"op":"mcm","clk":"ALaYpwkAl7CXCgCl0JwK","pt":1657539566107,"mc":[{"id":"1.200806927","rc":[{"atl":[[1.21,41.6]],"trd":[[1.21,113.69]],"tv":12800.17,"id":228749},{"trd":[[5.7,16.18]],"tv":916.67,"id":2857977}],"tv":13716.84}]}
{"op":"mcm","clk":"AKuZpwkAp7GXCgCK0ZwK","pt":1657539567516,"mc":[{"id":"1.200806927","rc":[{"atl":[[1.21,37.36]],"trd":[[1.21,117.93]],"tv":12804.41,"id":228749},{"trd":[[5.7,17.08]],"tv":917.57,"id":2857977}],"tv":13721.98}]}
{"op":"mcm","clk":"AMeZpwkAx7GXCgCe0ZwK","pt":1657539567798,"mc":[{"id":"1.200806927","rc":[{"atb":[[1.18,13.53]],"id":228749}]}]}
{"op":"mcm","clk":"AOGZpwkA5rGXCgC00ZwK","pt":1657539568107,"mc":[{"id":"1.200806927","rc":[{"atl":[[1.21,36.86]],"trd":[[1.21,118.43]],"tv":12804.91,"id":228749},{"trd":[[5.7,17.19]],"tv":917.68,"id":2857977}],"tv":13722.59}]}
{"op":"mcm","clk":"ANGapwkA/LKXCgCd0pwK","pt":1657539569618,"mc":[{"id":"1.200806927","rc":[{"atl":[[1.21,36.35]],"trd":[[1.21,118.94]],"tv":12805.42,"id":228749},{"trd":[[5.7,17.3]],"tv":917.79,"id":2857977}],"tv":13723.21}]}
{"op":"mcm","clk":"AP+apwkAwLOXCgDM0pwK","pt":1657539570317,"mc":[{"id":"1.200806927","rc":[{"atl":[[1.8,24.75]],"id":228749}]}]}
{"op":"mcm","clk":"ALqbpwkAjbSXCgCE05wK","pt":1657539571115,"mc":[{"id":"1.200806927","rc":[{"atl":[[1.21,17.35]],"trd":[[1.21,156.94]],"tv":12843.42,"id":228749}],"tv":13761.21}]}
{"op":"mcm","clk":"AIycpwkA4bSXCgDD05wK","pt":1657539572021,"mc":[{"id":"1.200806927","rc":[{"atl":[[1.21,13.3]],"trd":[[1.21,160.99]],"tv":12847.47,"id":228749},{"trd":[[5.7,18.16]],"tv":918.65,"id":2857977}],"tv":13766.12}]}
{"op":"mcm","clk":"AKGhpwkAorqXCgCb15wK","pt":1657539579819,"mc":[{"id":"1.200806927","rc":[{"atl":[[1.2,1.8]],"id":228749}]}]}
{"op":"mcm","clk":"AL2ipwkA57uXCgCW2JwK","pt":1657539581895,"mc":[{"id":"1.200806927","rc":[{"atl":[[2.14,0]],"id":228749}]}]}
{"op":"mcm","clk":"AMWjpwkAmb2XCgDw2JwK","pt":1657539583639,"mc":[{"id":"1.200806927","rc":[{"atl":[[1.2,1.27]],"trd":[[1.2,3.06]],"ltp":1.2,"tv":12848,"id":228749},{"trd":[[6,0.21]],"ltp":6,"tv":918.75,"id":2857977}],"tv":13766.75}]}
{"op":"mcm","clk":"AJCkpwkA5b2XCgCd2ZwK","pt":1657539584440,"mc":[{"id":"1.200806927","rc":[{"atl":[[1.2,10.38]],"id":228749}]}]}
{"op":"mcm","clk":"AJikpwkA8b2XCgCh2ZwK","pt":1657539584535,"mc":[{"id":"1.200806927","rc":[{"atl":[[1.2,9.85]],"trd":[[1.2,3.59]],"tv":12848.53,"id":228749},{"trd":[[6,0.32]],"tv":918.86,"id":2857977}],"tv":13767.39}]}
{"op":"mcm","clk":"AIalpwkA9r6XCgCA2pwK","pt":1657539586006,"mc":[{"id":"1.200806927","rc":[{"atb":[[1.18,13.19]],"trd":[[1.18,279.7]],"ltp":1.18,"tv":12849.21,"id":228749}],"tv":13768.07}]}
{"op":"mcm","clk":"AIylpwkAg7+XCgCG2pwK","pt":1657539586106,"mc":[{"id":"1.200806927","rc":[{"atl":[[1.2,9.74]],"trd":[[1.2,3.81]],"ltp":1.2,"tv":12849.43,"id":228749}],"tv":13768.29}]}
{"op":"mcm","clk":"AOSlpwkA6L+XCgDN2pwK","pt":1657539587131,"mc":[{"id":"1.200806927","rc":[{"atl":[[1.2,8.66]],"trd":[[1.2,4.89]],"tv":12850.51,"id":228749},{"trd":[[6,0.53]],"tv":919.07,"id":2857977}],"tv":13769.58}]}
{"op":"mcm","clk":"AP6mpwkAtsGXCgDg25wK","pt":1657539589139,"mc":[{"id":"1.200806927","rc":[{"atl":[[1.2,7.8]],"trd":[[1.2,5.75]],"tv":12851.37,"id":228749},{"trd":[[6,0.71]],"tv":919.25,"id":2857977}],"tv":13770.62}]}
{"op":"mcm","clk":"ALinpwkA5MGXCgCK3JwK","pt":1657539589707,"mc":[{"id":"1.200806927","rc":[{"atl":[[1.22,75]],"id":228749}]}]}
{"op":"mcm","clk":"AIispwkAycaXCgC73pwK","pt":1657539596324,"mc":[{"id":"1.200806927","rc":[{"atb":[[1.2,13.72]],"atl":[[1.2,0]],"trd":[[1.2,21.35]],"tv":12866.97,"id":228749}],"tv":13786.22}]}
{"op":"mcm","clk":"AKqvpwkAt8qXCgDY4JwK","pt":1657539601323,"mc":[{"id":"1.200806927","rc":[{"atb":[[1.19,6.76]],"id":228749}]}]}
{"op":"mcm","clk":"AMKvpwkA2MqXCgDt4JwK","pt":1657539601607,"mc":[{"id":"1.200806927","rc":[{"atl":[[1.8,24.92]],"id":228749}]}]}
{"op":"mcm","clk":"ALezpwkAus+XCgCO45wK","pt":1657539607155,"mc":[{"id":"1.200806927","rc":[{"atb":[[1.19,0],[1.2,14.62]],"id":228749}]}]}
{"op":"mcm","clk":"ANKzpwkA0s+XCgCa45wK","pt":1657539607444,"mc":[{"id":"1.200806927","rc":[{"atb":[[1.2,13.97]],"id":228749}]}]}
{"op":"mcm","clk":"ALq0pwkAz9CXCgDG45wK","pt":1657539608702,"mc":[{"id":"1.200806927","rc":[{"atb":[[1.2,0.9]],"id":228749}]}]}
{"op":"mcm","clk":"ANy2pwkAktOXCgDy5JwK","pt":1657539612207,"mc":[{"id":"1.200806927","rc":[{"atl":[[1.21,11.5]],"trd":[[1.21,164.59]],"ltp":1.21,"tv":12870.57,"id":228749}],"tv":13789.82}]}
{"op":"mcm","clk":"AIC3pwkAvdOXCgCG5ZwK","pt":1657539612631,"mc":[{"id":"1.200806927","rc":[{"atl":[[1.21,7.45]],"trd":[[1.21,168.64]],"tv":12874.62,"id":228749},{"trd":[[5.7,19.02]],"ltp":5.7,"tv":920.11,"id":2857977}],"tv":13794.73}]}
{"op":"mcm","clk":"AOK3pwkAsdSXCgC45ZwK","pt":1657539613821,"mc":[{"id":"1.200806927","rc":[{"atb":[[1.2,0]],"atl":[[1.19,1999.1]],"trd":[[1.2,23.15]],"ltp":1.2,"tv":12876.42,"id":228749}],"tv":13796.53}]}
{"op":"mcm","clk":"AMy4pwkAktWXCgCG5pwK","pt":1657539615125,"mc":[{"id":"1.200806927","rc":[{"atl":[[1.19,1998.2]],"trd":[[1.19,2.14]],"ltp":1.19,"tv":12878.22,"id":228749}],"tv":13798.33}]}
{"op":"mcm","clk":"AIC6pwkAyNaXCgD25pwK","pt":1657539617331,"mc":[{"id":"1.200806927","rc":[{"atb":[[1.18,0]],"id":228749}]}]}
{"op":"mcm","clk":"AJC6pwkA3daXCgD95pwK","pt":1657539617549,"mc":[{"id":"1.200806927","rc":[{"atb":[[1.17,0]],"atl":[[1.22,0]],"id":228749}]}]}
{"op":"mcm","clk":"ANi6pwkAvNeXCgCf55wK","pt":1657539618431,"mc":[{"id":"1.200806927","rc":[{"atl":[[1.19,1993.79]],"trd":[[1.19,6.55]],"tv":12882.63,"id":228749},{"trd":[[6.2,0.85]],"ltp":6.2,"tv":920.96,"id":2857977}],"tv":13803.59}]}
{"op":"mcm","clk":"AJi9pwkA7dmXCgDP6JwK","pt":1657539621911,"mc":[{"id":"1.200806927","rc":[{"atl":[[1.19,1980.45]],"trd":[[1.19,33.23]],"tv":12909.31,"id":228749}],"tv":13830.27}]}
{"op":"mcm","clk":"AKO9pwkA9dmXCgDU6JwK","pt":1657539622025,"mc":[{"id":"1.200806927","rc":[{"atl":[[1.19,1973.69]],"trd":[[1.19,46.75]],"tv":12922.83,"id":228749}],"tv":13843.79}]}
{"op":"mcm","clk":"ANi9pwkAstqXCgCD6ZwK","pt":1657539622657,"mc":[{"id":"1.200806927","rc":[{"atl":[[1.19,1953.69]],"trd":[[1.19,86.75]],"tv":12962.83,"id":228749}],"tv":13883.79}]}
{"op":"mcm","clk":"AKu+pwkAiNuXCgC76ZwK","pt":1657539623536,"mc":[{"id":"1.200806927","rc":[{"atl":[[1.19,1952.69]],"trd":[[1.19,88.75]],"tv":12964.83,"id":228749}],"tv":13885.79}]}
{"op":"mcm","clk":"AMi+pwkAp9uXCgDK6ZwK","pt":1657539623853,"mc":[{"id":"1.200806927","rc":[{"atl":[[1.19,1952.49]],"trd":[[1.19,89.15]],"tv":12965.23,"id":228749}],"tv":13886.19}]}
{"op":"mcm","clk":"AM6+pwkAs9uXCgDP6ZwK","pt":1657539623930,"mc":[{"id":"1.200806927","rc":[{"atl":[[1.19,1951.37]],"trd":[[1.19,90.27]],"tv":12966.35,"id":228749},{"trd":[[6.2,1.06]],"tv":921.17,"id":2857977}],"tv":13887.52}]}
{"op":"mcm","clk":"AOq+pwkAz9uXCgDa6ZwK","pt":1657539624237,"mc":[{"id":"1.200806927","rc":[{"atl":[[1.19,1950.85]],"trd":[[1.19,90.79]],"tv":12966.87,"id":228749},{"trd":[[6.2,1.16]],"tv":921.27,"id":2857977}],"tv":13888.14}]}
{"op":"mcm","clk":"AIm/pwkA+NuXCgDu6ZwK","pt":1657539624643,"mc":[{"id":"1.200806927","rc":[{"atl":[[1.18,450.81]],"id":228749}]}]}
{"op":"mcm","clk":"AJO/pwkAhtyXCgD06ZwK","pt":1657539624752,"mc":[{"id":"1.200806927","rc":[{"atl":[[1.18,448.64]],"trd":[[1.18,281.87]],"ltp":1.18,"tv":12969.04,"id":228749},{"trd":[[6.4,0.4]],"ltp":6.4,"tv":921.67,"id":2857977}],"tv":13890.71}]}
{"op":"mcm","clk":"AIDApwkAgd2XCgCz6pwK","pt":1657539626044,"mc":[{"id":"1.200806927","rc":[{"atl":[[1.18,446.66]],"trd":[[1.18,282.95]],"tv":12970.12,"id":228749},{"trd":[[6.4,0.6]],"tv":921.87,"id":2857977}],"tv":13891.99}]}
{"op":"mcm","clk":"AMHApwkAvd2XCgDQ6pwK","pt":1657539626673,"mc":[{"id":"1.200806927","rc":[{"atl":[[7.8,0.11]],"id":2857977}]}]}
{"op":"mcm","clk":"ANTApwkAzd2XCgDZ6pwK","pt":1657539626849,"mc":[{"id":"1.200806927","rc":[{"atb":[[5.4,0]],"id":2857977}]}]}
{"op":"mcm","clk":"AKXCpwkAwN+XCgDj65wK","pt":1657539629463,"mc":[{"id":"1.200806927","rc":[{"atl":[[1.18,446.12]],"trd":[[1.18,283.49]],"tv":12970.66,"id":228749},{"trd":[[6.4,0.7]],"tv":921.97,"id":2857977}],"tv":13892.63}]}
{"op":"mcm","clk":"ANTCpwkA79+XCgD165wK","pt":1657539629967,"mc":[{"id":"1.200806927","rc":[{"atl":[[1.18,445.04]],"trd":[[1.18,284.57]],"tv":12971.74,"id":228749},{"trd":[[6.4,0.9]],"tv":922.17,"id":2857977}],"tv":13893.91}]}
{"op":"mcm","clk":"AOnCpwkAjuCXCgCD7JwK","pt":1657539630269,"mc":[{"id":"1.200806927","rc":[{"atl":[[1.18,443.65]],"trd":[[1.18,285.96]],"tv":12973.13,"id":228749},{"trd":[[6.4,1.16]],"tv":922.43,"id":2857977}],"tv":13895.56}]}
{"op":"mcm","clk":"APfCpwkApuCXCgCN7JwK","pt":1657539630464,"mc":[{"id":"1.200806927","rc":[{"atl":[[1.18,442.48]],"trd":[[1.18,287.13]],"tv":12974.3,"id":228749},{"trd":[[6.4,1.37]],"tv":922.64,"id":2857977}],"tv":13896.94}]}
{"op":"mcm","clk":"AO/FpwkAteOXCgDr7ZwK","pt":1657539634748,"mc":[{"id":"1.200806927","rc":[{"atl":[[1.18,438.18]],"trd":[[1.18,295.74]],"tv":12982.91,"id":228749}],"tv":13905.55}]}
{"op":"mcm","clk":"AOPGpwkAyeSXCgC67pwK","pt":1657539636258,"mc":[{"id":"1.200806927","rc":[{"atl":[[1.8,24.75]],"id":228749}]}]}
{"op":"mcm","clk":"APLGpwkA4uSXCgDC7pwK","pt":1657539636467,"mc":[{"id":"1.200806927","rc":[{"atb":[[1.16,4.24]],"id":228749}]}]}
{"op":"mcm","clk":"AMjIpwkAzOaXCgCu75wK","pt":1657539638995,"mc":[{"id":"1.200806927","rc":[{"atl":[[1.18,438.07]],"trd":[[1.18,295.96]],"tv":12983.13,"id":228749}],"tv":13905.77}]}
{"op":"mcm","clk":"ANbIpwkA3OaXCgC375wK","pt":1657539639167,"mc":[{"id":"1.200806927","rc":[{"atl":[[1.18,437.31]],"trd":[[1.18,296.72]],"tv":12983.89,"id":228749},{"trd":[[6.4,1.51]],"tv":922.78,"id":2857977}],"tv":13906.67}]}
{"op":"mcm","clk":"AJjJpwkAqOeXCgDf75wK","pt":1657539639957,"mc":[{"id":"1.200806927","rc":[{"atb":[[1.15,0],[1.16,0]],"atl":[[1.14,865.33]],"trd":[[1.17,155.71],[1.14,2.53],[1.15,20.06]],"ltp":1.14,"tv":13007.93,"id":228749},{"atl":[[6.6,0],[7.8,0],[8,0]],"trd":[[6.6,0.26],[7.8,0.11],[8,0.26]],"ltp":8,"tv":923.41,"id":2857977}],"tv":13931.34}]}
{"op":"mcm","clk":"AP3JpwkAm+iXCgCX8JwK","pt":1657539641084,"mc":[{"id":"1.200806927","rc":[{"atl":[[1.14,864.58]],"trd":[[1.14,3.28]],"tv":13008.68,"id":228749},{"trd":[[8,0.36]],"tv":923.51,"id":2857977}],"tv":13932.19}]}
{"op":"mcm","clk":"AKDKpwkAu+iXCgCv8JwK","pt":1657539641492,"mc":[{"id":"1.200806927","rc":[{"atl":[[1.14,861.56]],"trd":[[1.14,6.3]],"tv":13011.7,"id":228749},{"trd":[[8,0.79]],"tv":923.94,"id":2857977}],"tv":13935.64}]}
{"op":"mcm","clk":"AJ/MpwkAmeqXCgCd8ZwK","pt":1657539643763,"mc":[{"id":"1.200806927","rc":[{"atl":[[1.14,847.74]],"trd":[[1.14,20.12]],"tv":13025.52,"id":228749},{"trd":[[8,2.76]],"tv":925.91,"id":2857977}],"tv":13951.43}]}
{"op":"mcm","clk":"APHMpwkA/+qXCgDg8ZwK","pt":1657539644864,"mc":[{"id":"1.200806927","rc":[{"atl":[[1.14,844.72]],"trd":[[1.14,23.14]],"tv":13028.54,"id":228749},{"trd":[[8,3.19]],"tv":926.34,"id":2857977}],"tv":13954.88}]}
{"op":"mcm","clk":"AIvNpwkAouuXCgD08ZwK","pt":1657539645280,"mc":[{"id":"1.200806927","rc":[{"atl":[[1.14,843.02]],"trd":[[1.14,24.84]],"tv":13030.24,"id":228749},{"trd":[[8,3.43]],"tv":926.58,"id":2857977}],"tv":13956.82}]}
{"op":"mcm","clk":"AKTNpwkAzOuXCgCF8pwK","pt":1657539645635,"mc":[{"id":"1.200806927","rc":[{"atl":[[1.14,840.61]],"trd":[[1.14,27.25]],"tv":13032.65,"id":228749},{"trd":[[8,3.78]],"tv":926.93,"id":2857977}],"tv":13959.58}]}
{"op":"mcm","clk":"AOTOpwkA6O2XCgCl85wK","pt":1657539648670,"mc":[{"id":"1.200806927","rc":[{"atl":[[1.15,17.05]],"id":228749}]}]}
{"op":"mcm","clk":"AP3PpwkA8u6XCgDv85wK","pt":1657539650100,"mc":[{"id":"1.200806927","rc":[{"atb":[[1.11,555]],"id":228749}]}]}
{"op":"mcm","clk":"AKnQpwkAs++XCgCP9JwK","pt":1657539650769,"mc":[{"id":"1.200806927","rc":[{"atl":[[1.14,839.91]],"trd":[[1.14,27.95]],"tv":13033.35,"id":228749},{"trd":[[8,3.88]],"tv":927.03,"id":2857977}],"tv":13960.38}]}
{"op":"mcm","clk":"ALfQpwkAwu+XCgCY9JwK","pt":1657539650968,"mc":[{"id":"1.200806927","rc":[{"atl":[[1.14,839.21]],"trd":[[1.14,28.65]],"tv":13034.05,"id":228749},{"trd":[[8,3.98]],"tv":927.13,"id":2857977}],"tv":13961.18}]}
{"op":"mcm","clk":"AIXRpwkAtfCXCgDT9JwK","pt":1657539652171,"mc":[{"id":"1.200806927","rc":[{"atl":[[1.14,837.41]],"trd":[[1.14,30.45]],"tv":13035.85,"id":228749},{"trd":[[8,4.24]],"tv":927.39,"id":2857977}],"tv":13963.24}]}
{"op":"mcm","clk":"AI3RpwkAwvCXCgDZ9JwK","pt":1657539652284,"mc":[{"id":"1.200806927","rc":[{"atb":[[1.12,4.3]],"id":228749}]}]}
{"op":"mcm","clk":"AKzRpwkA6vCXCgDp9JwK","pt":1657539652693,"mc":[{"id":"1.200806927","rc":[{"atl":[[1.14,0]],"id":228749}]}]}
{"op":"mcm","clk":"ALTRpwkA8vCXCgDp9JwK","pt":1657539652752,"mc":[{"id":"1.200806927","rc":[{"atb":[[1.14,0.9]],"id":228749},{"atl":[[8,0.11]],"id":2857977}]}]}
{"op":"mcm","clk":"AOLRpwkAoPGXCgD89JwK","pt":1657539653266,"mc":[{"id":"1.200806927","rc":[{"atb":[[1.17,14.91]],"atl":[[1.15,0]],"trd":[[1.15,54.16]],"ltp":1.15,"tv":13069.95,"id":228749}],"tv":13997.34}]}
{"op":"mcm","clk":"ALPSpwkAifKXCgCr9ZwK","pt":1657539654285,"mc":[{"id":"1.200806927","rc":[{"atb":[[1.14,1.01]],"id":228749}]}]}
{"op":"mcm","clk":"AMjSpwkAqPKXCgDC9ZwK","pt":1657539654582,"mc":[{"id":"1.200806927","rc":[{"atl":[[8,0.21]],"id":2857977}]}]}
{"op":"mcm","clk":"AMbTpwkA8POXCgCS9pwK","pt":1657539656262,"mc":[{"id":"1.200806927","rc":[{"atb":[[1.14,9]],"id":228749}]}]}
{"op":"mcm","clk":"AM3TpwkA+vOXCgCY9pwK","pt":1657539656371,"mc":[{"id":"1.200806927","rc":[{"atl":[[8,0.43]],"id":2857977}]}]}
{"op":"mcm","clk":"AJ/UpwkA2/SXCgDB9pwK","pt":1657539657346,"mc":[{"id":"1.200806927","rc":[{"atl":[[8,0.73]],"id":2857977}]}]}
{"op":"mcm","clk":"AKDUpwkA4vSXCgDE9pwK","pt":1657539657392,"mc":[{"id":"1.200806927","rc":[{"atl":[[8,0.9]],"id":2857977}]}]}
{"op":"mcm","clk":"AKvUpwkA7vSXCgDG9pwK","pt":1657539657501,"mc":[{"id":"1.200806927","rc":[{"atb":[[1.14,8.89]],"id":228749}]}]}
{"op":"mcm","clk":"ALXUpwkA/fSXCgDK9pwK","pt":1657539657605,"mc":[{"id":"1.200806927","rc":[{"atl":[[1.6,0.34]],"id":228749}]}]}
{"op":"mcm","clk":"AMrUpwkAlfWXCgDX9pwK","pt":1657539657915,"mc":[{"id":"1.200806927","rc":[{"atl":[[8,0.79]],"id":2857977}]}]}
{"op":"mcm","clk":"AM7UpwkAm/WXCgDb9pwK","pt":1657539658004,"mc":[{"id":"1.200806927","rc":[{"atl":[[8,0.9]],"id":2857977}]}]}
{"op":"mcm","clk":"ANTUpwkAofWXCgDe9pwK","pt":1657539658100,"mc":[{"id":"1.200806927","rc":[{"atl":[[8,0.6]],"id":2857977}]}]}
{"op":"mcm","clk":"AObUpwkAwPWXCgDo9pwK","pt":1657539658379,"mc":[{"id":"1.200806927","rc":[{"atb":[[1.17,4.66]],"trd":[[1.17,176.21]],"ltp":1.17,"tv":13090.45,"id":228749}],"tv":14017.84}]}
{"op":"mcm","clk":"AIvVpwkA7PWXCgD69pwK","pt":1657539658892,"mc":[{"id":"1.200806927","rc":[{"atl":[[8,0.49]],"id":2857977}]}]}
{"op":"mcm","clk":"AN7VpwkA5PaXCgCv95wK","pt":1657539660008,"mc":[{"id":"1.200806927","rc":[{"atb":[[1.17,0]],"id":228749}]}]}
{"op":"mcm","clk":"AP/VpwkAkPeXCgDK95wK","pt":1657539660398,"mc":[{"id":"1.200806927","rc":[{"atl":[[8,0.62]],"id":2857977}]}]}
{"op":"mcm","clk":"AObWpwkAg/iXCgD/95wK","pt":1657539661607,"mc":[{"id":"1.200806927","rc":[{"atb":[[1.14,50.7]],"id":228749}]}]}
{"op":"mcm","clk":"AKvXpwkAzfiXCgCg+JwK","pt":1657539662499,"mc":[{"id":"1.200806927","rc":[{"atl":[[1.17,7.53]],"id":228749}]}]}
{"op":"mcm","clk":"ALTXpwkA1/iXCgCh+JwK","pt":1657539662602,"mc":[{"id":"1.200806927","rc":[{"atb":[[1.12,49.38]],"id":228749}]}]}
{"op":"mcm","clk":"APHXpwkAnfmXCgDZ+JwK","pt":1657539663299,"mc":[{"id":"1.200806927","rc":[{"atb":[[1.14,52.5]],"id":228749}]}]}
{"op":"mcm","clk":"AILapwkA/vuXCgCo+pwK","pt":1657539666950,"mc":[{"id":"1.200806927","rc":[{"atl":[[1.17,7.43]],"trd":[[1.17,176.41]],"tv":13090.65,"id":228749}],"tv":14018.04}]}
{"op":"mcm","clk":"AK7apwkAtfyXCgDP+pwK","pt":1657539667534,"mc":[{"id":"1.200806927","rc":[{"atl":[[1.17,6.81]],"trd":[[1.17,177.03]],"tv":13091.27,"id":228749},{"trd":[[6.8,0.11]],"ltp":6.8,"tv":927.5,"id":2857977}],"tv":14018.77}]}
{"op":"mcm","clk":"APXbpwkAmv6XCgDB+5wK","pt":1657539669899,"mc":[{"id":"1.200806927","rc":[{"atl":[[1.17,6.91]],"id":228749}]}]}
{"op":"mcm","clk":"AIXcpwkAsf6XCgDL+5wK","pt":1657539670107,"mc":[{"id":"1.200806927","rc":[{"atb":[[1.14,51.6]],"id":228749}]}]}
{"op":"mcm","clk":"AK3dpwkA8/+XCgCZ/JwK","pt":1657539672084,"mc":[{"id":"1.200806927","rc":[{"atl":[[8,1.16]],"id":2857977}]}]}
{"op":"mcm","clk":"ANndpwkApICYCgCq/JwK","pt":1657539672603,"mc":[{"id":"1.200806927","rc":[{"atb":[[1.12,58.58]],"id":228749}]}]}
{"op":"mcm","clk":"ALDjpwkAzoaYCgCG/5wK","pt":1657539680825,"mc":[{"id":"1.200806927","rc":[{"atl":[[1.17,6.29]],"trd":[[1.17,177.65]],"tv":13091.89,"id":228749},{"trd":[[6.8,0.21]],"tv":927.6,"id":2857977}],"tv":14019.49}]}
{"op":"mcm","clk":"ALjjpwkA3oaYCgCK/5wK","pt":1657539680922,"mc":[{"id":"1.200806927","rc":[{"atb":[[1.14,9.79]],"id":228749}]}]}
{"op":"mcm","clk":"AMTjpwkA7IaYCgCR/5wK","pt":1657539681120,"mc":[{"id":"1.200806927","rc":[{"atb":[[1.1,115.05]],"id":228749},{"atl":[[10,0.41]],"id":2857977}]}]}
{"op":"mcm","clk":"AK/kpwkA4YeYCgDD/5wK","pt":1657539682311,"mc":[{"id":"1.200806927","rc":[{"atb":[[7,0.9]],"id":2857977}]}]}
{"op":"mcm","clk":"ANblpwkAqImYCgCYgJ0K","pt":1657539684236,"mc":[{"id":"1.200806927","rc":[{"atl":[[1.17,2.37]],"trd":[[1.17,181.57]],"tv":13095.81,"id":228749},{"atb":[[7,0]],"trd":[[7,1.8],[6.8,0.89]],"tv":930.08,"id":2857977}],"tv":14025.89}]}
{"op":"mcm","clk":"APPmpwkA0IqYCgDXgJ0K","pt":1657539686034,"mc":[{"id":"1.200806927","rc":[{"atb":[[1.14,0]],"trd":[[1.14,52.24]],"ltp":1.14,"tv":13117.6,"id":228749},{"atl":[[8,0.84]],"trd":[[8,4.55]],"ltp":8,"tv":930.39,"id":2857977}],"tv":14047.99}]}
{"op":"mcm","clk":"AIznpwkA8YqYCgDngJ0K","pt":1657539686335,"mc":[{"id":"1.200806927","rc":[{"atb":[[1.06,420.37]],"id":228749}]}]}
{"op":"mcm","clk":"AIHopwkA9YuYCgCfgZ0K","pt":1657539687624,"mc":[{"id":"1.200806927","rc":[{"atl":[[1.17,0],[1.18,437.19]],"trd":[[1.17,183.94],[1.18,296.84]],"ltp":1.18,"tv":13120.09,"id":228749},{"trd":[[6.8,1.3],[6.4,1.53]],"ltp":6.4,"tv":930.82,"id":2857977}],"tv":14050.91}]}
{"op":"mcm","clk":"AObppwkAho6YCgCWgp0K","pt":1657539690345,"mc":[{"id":"1.200806927","rc":[{"atl":[[10,0.52]],"id":2857977}]}]}
{"op":"mcm","clk":"AP7ppwkAm46YCgChgp0K","pt":1657539690547,"mc":[{"id":"1.200806927","rc":[{"atl":[[1.18,430.19]],"trd":[[1.18,303.84]],"tv":13127.09,"id":228749},{"trd":[[6.4,2.83]],"tv":932.12,"id":2857977}],"tv":14059.21}]}
{"op":"mcm","clk":"AIbspwkAvJCYCgCXg50K","pt":1657539693422,"mc":[{"id":"1.200806927","rc":[{"atl":[[1.18,425.52]],"trd":[[1.18,308.51]],"tv":13131.76,"id":228749},{"trd":[[6.4,3.69]],"tv":932.98,"id":2857977}],"tv":14064.74}]}
{"op":"mcm","clk":"ANzspwkAnJGYCgDIg50K","pt":1657539694357,"mc":[{"id":"1.200806927","rc":[{"atl":[[1.21,0]],"id":228749}]}]}
{"op":"mcm","clk":"AMrtpwkAlpKYCgCAhJ0K","pt":1657539695520,"mc":[{"id":"1.200806927","rc":[{"atb":[[1.15,500]],"id":228749}]}]}
{"op":"mcm","clk":"AMXupwkAoJOYCgDGhJ0K","pt":1657539696937,"mc":[{"id":"1.200806927","rc":[{"atb":[[1.17,41.81]],"id":228749}]}]}
{"op":"mcm","clk":"ANnvpwkA05SYCgC1hZ0K","pt":1657539698632,"mc":[{"id":"1.200806927","rc":[{"atb":[[1.17,0]],"atl":[[1.17,958.19]],"trd":[[1.17,267.56]],"ltp":1.17,"tv":13215.38,"id":228749}],"tv":14148.36}]}
{"op":"mcm","clk":"AOrvpwkA5ZSYCgC9hZ0K","pt":1657539698831,"mc":[{"id":"1.200806927","rc":[{"atl":[[1.17,0]],"id":228749}]}]}
{"op":"mcm","clk":"AJHwpwkAlJWYCgDZhZ0K","pt":1657539699356,"mc":[{"id":"1.200806927","rc":[{"atl":[[1.18,424.94]],"trd":[[1.18,309.09]],"ltp":1.18,"tv":13215.96,"id":228749},{"trd":[[6.4,3.79]],"tv":933.08,"id":2857977}],"tv":14149.04}]}
{"op":"mcm","clk":"AMzwpwkA0JWYCgD9hZ0K","pt":1657539700030,"mc":[{"id":"1.200806927","rc":[{"atl":[[1000,2.64]],"id":228749}]}]}
{"op":"mcm","clk":"AOvwpwkA8JWYCgCNhp0K","pt":1657539700347,"mc":[{"id":"1.200806927","rc":[{"atl":[[1000,1.8]],"id":228749}]}]}
{"op":"mcm","clk":"APXwpwkA+5WYCgCThp0K","pt":1657539700451,"mc":[{"id":"1.200806927","rc":[{"atb":[[1.14,4.51]],"id":228749}]}]}
{"op":"mcm","clk":"AIfxpwkAk5aYCgCchp0K","pt":1657539700647,"mc":[{"id":"1.200806927","rc":[{"atl":[[1000,0.13]],"id":228749}]}]}
{"op":"mcm","clk":"AP3zpwkAqJmYCgCGiJ0K","pt":1657539704966,"mc":[{"id":"1.200806927","rc":[{"atl":[[1.18,422.61]],"trd":[[1.18,311.42]],"tv":13218.29,"id":228749},{"trd":[[6.4,4.22]],"tv":933.51,"id":2857977}],"tv":14151.8}]}
{"op":"mcm","clk":"AIj0pwkAvJmYCgCUiJ0K","pt":1657539705165,"mc":[{"id":"1.200806927","rc":[{"atl":[[8,0.77]],"id":2857977}]}]}
{"op":"mcm","clk":"AL30pwkA9JmYCgC7iJ0K","pt":1657539705750,"mc":[{"id":"1.200806927","rc":[{"atl":[[1.17,1.67]],"id":228749}]}]}
{"op":"mcm","clk":"AO70pwkAq5qYCgDliJ0K","pt":1657539706332,"mc":[{"id":"1.200806927","rc":[{"atl":[[1.17,0],[1.18,412.5]],"trd":[[1.17,269.24],[1.18,321.53]],"tv":13230.08,"id":228749},{"trd":[[6.8,1.58],[6.4,6.09]],"tv":935.66,"id":2857977}],"tv":14165.74}]}
{"op":"mcm","clk":"ANz1pwkAlJuYCgCgiZ0K","pt":1657539707566,"mc":[{"id":"1.200806927","rc":[{"atl":[[1.18,356.77]],"trd":[[1.18,377.26]],"tv":13285.81,"id":228749},{"trd":[[6.4,16.36]],"tv":945.93,"id":2857977}],"tv":14231.74}]}
{"op":"mcm","clk":"APz1pwkAv5uYCgC+iZ0K","pt":1657539707946,"mc":[{"id":"1.200806927","rc":[{"atl":[[1.17,444]],"id":228749}]}]}
{"op":"mcm","clk":"AOf7pwkA9qGYCgCAjZ0K","pt":1657539716647,"mc":[{"id":"1.200806927","rc":[{"atb":[[1.14,0],[1.15,0]],"atl":[[1.14,391.69]],"trd":[[1.14,57.66],[1.15,1054.16]],"ltp":1.14,"tv":14291.23,"id":228749},{"atl":[[8,0]],"trd":[[8,5.32]],"ltp":8,"tv":946.7,"id":2857977}],"tv":15237.93}]}
{"op":"mcm","clk":"ANL9pwkAj6SYCgCbjp0K","pt":1657539719555,"mc":[{"id":"1.200806927","rc":[{"atl":[[1.14,388.09]],"trd":[[1.14,61.26]],"tv":14294.83,"id":228749},{"trd":[[8,5.84]],"tv":947.22,"id":2857977}],"tv":15242.05}]}
{"op":"mcm","clk":"APb9pwkAs6SYCgCzjp0K","pt":1657539719972,"mc":[{"id":"1.200806927","rc":[{"atl":[[1.14,386.58]],"trd":[[1.14,62.77]],"tv":14296.34,"id":228749},{"trd":[[8,6.05]],"tv":947.43,"id":2857977}],"tv":15243.77}]}
{"op":"mcm","clk":"AIH+pwkAvKSYCgC4jp0K","pt":1657539720061,"mc":[{"id":"1.200806927","rc":[{"atl":[[1.14,384.02]],"trd":[[1.14,65.33]],"tv":14298.9,"id":228749},{"trd":[[8,6.42]],"tv":947.8,"id":2857977}],"tv":15246.7}]}
{"op":"mcm","clk":"AOT+pwkAq6WYCgDrjp0K","pt":1657539721174,"mc":[{"id":"1.200806927","rc":[{"atl":[[1.14,383.92]],"trd":[[1.14,65.53]],"tv":14299.1,"id":228749}],"tv":15246.9}]}
{"op":"mcm","clk":"AJj/pwkA6KWYCgCUj50K","pt":1657539721774,"mc":[{"id":"1.200806927","rc":[{"atl":[[1.14,382.71]],"trd":[[1.14,66.74]],"tv":14300.31,"id":228749},{"trd":[[8,6.59]],"tv":947.97,"id":2857977}],"tv":15248.28}]}
{"op":"mcm","clk":"AKL/pwkAoKaYCgCXj50K","pt":1657539721878,"mc":[{"id":"1.200806927","rc":[{"atl":[[1.14,381.85]],"trd":[[1.14,68.46]],"tv":14302.03,"id":228749}],"tv":15250}]}
{"op":"mcm","clk":"AMX/pwkAyaaYCgCuj50K","pt":1657539722286,"mc":[{"id":"1.200806927","rc":[{"atl":[[1.14,380.96]],"trd":[[1.14,70.24]],"tv":14303.81,"id":228749}],"tv":15251.78}]}
{"op":"mcm","clk":"APb/pwkAh6eYCgDMj50K","pt":1657539722846,"mc":[{"id":"1.200806927","rc":[{"atl":[[1.14,379.78]],"trd":[[1.14,71.42]],"tv":14304.99,"id":228749},{"trd":[[8,6.76]],"tv":948.14,"id":2857977}],"tv":15253.13}]}
{"op":"mcm","clk":"AJyAqAkAr6eYCgDlj50K","pt":1657539723260,"mc":[{"id":"1.200806927","rc":[{"atl":[[1.17,322.32],[1.14,0]],"trd":[[1.17,512.6],[1.14,830.98]],"ltp":1.17,"tv":15307.91,"id":228749}],"con":true,"tv":16256.05}]}
{"op":"mcm","clk":"AJKCqAkA3amYCgDwkJ0K","pt":1657539725881,"mc":[{"id":"1.200806927","rc":[{"atb":[[1.12,54.28]],"id":228749}]}]}
{"op":"mcm","clk":"ALSDqAkAiKuYCgC4kZ0K","pt":1657539727670,"mc":[{"id":"1.200806927","rc":[{"atl":[[8,0.22]],"id":2857977}]}]}
{"op":"mcm","clk":"AJGEqAkA/quYCgDykZ0K","pt":1657539728793,"mc":[{"id":"1.200806927","rc":[{"atb":[[1.14,8.61]],"id":228749}]}]}
{"op":"mcm","clk":"AMuEqAkAuKyYCgCRkp0K","pt":1657539729424,"mc":[{"id":"1.200806927","rc":[{"atl":[[8,9.24]],"id":2857977}]}]}
{"op":"mcm","clk":"AKiFqAkAqa2YCgDLkp0K","pt":1657539730563,"mc":[{"id":"1.200806927","rc":[{"atb":[[1.14,10.86]],"id":228749}]}]}
{"op":"mcm","clk":"ALmFqAkAwa2YCgDRkp0K","pt":1657539730790,"mc":[{"id":"1.200806927","rc":[{"atl":[[8,9.34]],"id":2857977}]}]}
{"op":"mcm","clk":"ANKFqAkA5K2YCgDckp0K","pt":1657539731060,"mc":[{"id":"1.200806927","rc":[{"atb":[[1.14,11.16]],"id":228749}]}]}
{"op":"mcm","clk":"AOOFqAkA9q2YCgDnkp0K","pt":1657539731269,"mc":[{"id":"1.200806927","rc":[{"atb":[[1.14,32.68]],"id":228749}]}]}
{"op":"mcm","clk":"APKIqAkAwLGYCgCulJ0K","pt":1657539735567,"mc":[{"id":"1.200806927","rc":[{"atl":[[8,9.54]],"id":2857977}]}]}
{"op":"mcm","clk":"AOyJqAkAuLKYCgDllJ0K","pt":1657539736667,"mc":[{"id":"1.200806927","rc":[{"atb":[[1.14,0],[1.12,53.22]],"trd":[[1.14,963.3],[1.12,2.12]],"ltp":1.12,"tv":15442.35,"id":228749},{"atl":[[8,0]],"trd":[[8,16.3]],"tv":957.68,"id":2857977}],"tv":16400.03}]}
{"op":"mcm","clk":"AKSKqAkA9LKYCgD3lJ0K","pt":1657539737285,"mc":[{"id":"1.200806927","rc":[{"atb":[[1.12,476.05]],"id":228749}]}]}
{"op":"mcm","clk":"AMyKqAkAm7OYCgCKlZ0K","pt":1657539737768,"mc":[{"id":"1.200806927","rc":[{"atl":[[1.14,100]],"id":228749}]}]}
{"op":"mcm","clk":"AP+KqAkAyLOYCgCplZ0K","pt":1657539738167,"mc":[{"id":"1.200806927","rc":[{"atl":[[1.16,1000]],"id":228749}]}]}
{"op":"mcm","clk":"AOKLqAkAwLSYCgDslZ0K","pt":1657539739267,"mc":[{"id":"1.200806927","rc":[{"atl":[[1.14,0]],"id":228749}]}]}
{"op":"mcm","clk":"APiLqAkA2LSYCgD6lZ0K","pt":1657539739491,"mc":[{"id":"1.200806927","rc":[{"atl":[[1.16,0]],"id":228749}]}]}
{"op":"mcm","clk":"ANOMqAkArbWYCgCrlp0K","pt":1657539740385,"mc":[{"id":"1.200806927","rc":[{"atb":[[1.11,0]],"id":228749}]}]}
{"op":"mcm","clk":"APKMqAkAzLWYCgC5lp0K","pt":1657539740695,"mc":[{"id":"1.200806927","rc":[{"atl":[[1.17,320.32]],"trd":[[1.17,516.6]],"ltp":1.17,"tv":15446.35,"id":228749}],"tv":16404.03}]}
{"op":"mcm","clk":"AIGNqAkA4LWYCgDBlp0K","pt":1657539740862,"mc":[{"id":"1.200806927","rc":[{"atb":[[1.12,454.53]],"trd":[[1.12,45.16]],"ltp":1.12,"tv":15489.39,"id":228749}],"tv":16447.07}]}
{"op":"mcm","clk":"AKSNqAkAhLaYCgDZlp0K","pt":1657539741279,"mc":[{"id":"1.200806927","rc":[{"atl":[[8,0.11]],"id":2857977}]}]}
{"op":"mcm","clk":"AOGPqAkArLmYCgCEmJ0K","pt":1657539744962,"mc":[{"id":"1.200806927","rc":[{"atl":[[1.17,317.82],[1.32,1.08],[1.14,44.25]],"trd":[[1.17,519.1],[1.14,964.05]],"ltp":1.14,"tv":15492.64,"id":228749},{"atl":[[8,0]],"trd":[[6.8,2.01],[8,16.41]],"tv":958.22,"id":2857977}],"tv":16450.86}]}
{"op":"mcm","clk":"AOeQqAkA1rqYCgDJmJ0K","pt":1657539746593,"mc":[{"id":"1.200806927","rc":[{"atl":[[1.14,42.8]],"trd":[[1.14,965.5]],"tv":15494.09,"id":228749},{"trd":[[8,16.61]],"tv":958.42,"id":2857977}],"tv":16452.51}]}
{"op":"mcm","clk":"AJORqAkAiLuYCgDsmJ0K","pt":1657539747090,"mc":[{"id":"1.200806927","rc":[{"atl":[[1.14,41.3]],"trd":[[1.14,967]],"tv":15495.59,"id":228749},{"trd":[[8,16.83]],"tv":958.64,"id":2857977}],"tv":16454.23}]}
{"op":"mcm","clk":"AJuRqAkAkruYCgDymJ0K","pt":1657539747189,"mc":[{"id":"1.200806927","rc":[{"atl":[[1.14,37.45]],"trd":[[1.14,974.7]],"tv":15503.29,"id":228749}],"tv":16461.93}]}
{"op":"mcm","clk":"AMKRqAkAtLuYCgCImZ0K","pt":1657539747581,"mc":[{"id":"1.200806927","rc":[{"atb":[[1.13,4.3]],"id":228749}]}]}
{"op":"mcm","clk":"AOaRqAkA1ruYCgCWmZ0K","pt":1657539747964,"mc":[{"id":"1.200806927","rc":[{"atl":[[1.14,37.05]],"trd":[[1.14,975.5]],"tv":15504.09,"id":228749}],"tv":16462.73}]}
{"op":"mcm","clk":"AMWUqAkAhb+YCgCam50K","pt":1657539752348,"mc":[{"id":"1.200806927","rc":[{"atb":[[1.13,0]],"id":228749}]}]}
{"op":"mcm","clk":"AICWqAkAx8CYCgDvm50K","pt":1657539754407,"mc":[{"id":"1.200806927","rc":[{"atl":[[1.14,36.3]],"trd":[[1.14,976.25]],"tv":15504.84,"id":228749},{"trd":[[8,16.93]],"tv":958.74,"id":2857977}],"tv":16463.58}]}
{"op":"mcm","clk":"AJaWqAkA2sCYCgD5m50K","pt":1657539754608,"mc":[{"id":"1.200806927","rc":[{"atl":[[1.14,33.87]],"trd":[[1.14,981.11]],"tv":15509.7,"id":228749}],"tv":16468.44}]}
{"op":"mcm","clk":"AKKWqAkA7MCYCgCDnJ0K","pt":1657539754760,"mc":[{"id":"1.200806927","rc":[{"atb":[[1.13,1000]],"id":228749}]}]}
{"op":"mcm","clk":"ANCXqAkAjcKYCgDlnJ0K","pt":1657539756474,"mc":[{"id":"1.200806927","rc":[{"atl":[[1.14,30.05]],"trd":[[1.14,984.93]],"tv":15513.52,"id":228749},{"trd":[[8,17.48]],"tv":959.29,"id":2857977}],"tv":16472.81}]}
{"op":"mcm","clk":"APCXqAkAsMKYCgDynJ0K","pt":1657539756879,"mc":[{"id":"1.200806927","rc":[{"atl":[[8.2,0.22]],"id":2857977}]}]}
{"op":"mcm","clk":"AMeYqAkAmsOYCgConZ0K","pt":1657539757901,"mc":[{"id":"1.200806927","rc":[{"atb":[[1.13,950]],"trd":[[1.13,100]],"ltp":1.13,"tv":15613.52,"id":228749}],"tv":16572.81}]}
{"op":"mcm","clk":"APiYqAkA1MOYCgDDnZ0K","pt":1657539758420,"mc":[{"id":"1.200806927","rc":[{"atl":[[1.14,28.84]],"trd":[[1.14,986.14]],"ltp":1.14,"tv":15614.73,"id":228749},{"trd":[[8,17.65]],"tv":959.46,"id":2857977}],"tv":16574.19}]}
{"op":"mcm","clk":"AP+YqAkA4MOYCgDKnZ0K","pt":1657539758481,"mc":[{"id":"1.200806927","rc":[{"atl":[[1.14,28.09]],"trd":[[1.14,986.89]],"tv":15615.48,"id":228749},{"trd":[[8,17.76]],"tv":959.57,"id":2857977}],"tv":16575.05}]}
{"op":"mcm","clk":"AJGZqAkA9cOYCgDUnZ0K","pt":1657539758681,"mc":[{"id":"1.200806927","rc":[{"atl":[[1.14,26.44]],"trd":[[1.14,988.54]],"tv":15617.13,"id":228749},{"trd":[[8,17.99]],"tv":959.8,"id":2857977}],"tv":16576.93}]}
{"op":"mcm","clk":"AKOZqAkAisSYCgDlnZ0K","pt":1657539758893,"mc":[{"id":"1.200806927","rc":[{"atl":[[1.14,17.83]],"trd":[[1.14,1005.76]],"tv":15634.35,"id":228749}],"tv":16594.15}]}
{"op":"mcm","clk":"AMOZqAkAtcSYCgD+nZ0K","pt":1657539759272,"mc":[{"id":"1.200806927","rc":[{"atl":[[1.14,14.81]],"trd":[[1.14,1008.78]],"tv":15637.37,"id":228749},{"trd":[[8,18.42]],"tv":960.23,"id":2857977}],"tv":16597.6}]}
{"op":"mcm","clk":"AI6aqAkAl8WYCgC2np0K","pt":1657539760284,"mc":[{"id":"1.200806927","rc":[{"atl":[[12,0]],"id":2857977}]}]}
{"op":"mcm","clk":"APKaqAkAk8aYCgD7np0K","pt":1657539761464,"mc":[{"id":"1.200806927","rc":[{"atl":[[1.14,11.79]],"trd":[[1.14,1011.8]],"tv":15640.39,"id":228749},{"trd":[[8,18.85]],"tv":960.66,"id":2857977}],"tv":16601.05}]}
{"op":"mcm","clk":"AP+aqAkAncaYCgCCn50K","pt":1657539761579,"mc":[{"id":"1.200806927","rc":[{"atl":[[1.14,9.06]],"trd":[[1.14,1014.53]],"tv":15643.12,"id":228749},{"trd":[[8,19.24]],"tv":961.05,"id":2857977}],"tv":16604.17}]}
{"op":"mcm","clk":"AMCdqAkAncmYCgC6oJ0K","pt":1657539765208,"mc":[{"id":"1.200806927","rc":[{"atb":[[1.14,10.91]],"atl":[[1.14,0]],"trd":[[1.14,1032.65]],"tv":15661.24,"id":228749}],"tv":16622.29}]}
{"op":"mcm","clk":"AOOdqAkAxsmYCgDIoJ0K","pt":1657539765621,"mc":[{"id":"1.200806927","rc":[{"atl":[[8,0.9]],"id":2857977}]}]}
{"op":"mcm","clk":"AJeeqAkAmcqYCgD0oJ0K","pt":1657539766427,"mc":[{"id":"1.200806927","rc":[{"atb":[[1.14,24.44]],"id":228749}]}]}
{"op":"mcm","clk":"APOeqAkA+sqYCgCpoZ0K","pt":1657539767502,"mc":[{"id":"1.200806927","rc":[{"atl":[[1.15,22.55]],"id":228749}]}]}
{"op":"mcm","clk":"AKifqAkAwcuYCgDMoZ0K","pt":1657539768204,"mc":[{"id":"1.200806927","rc":[{"atb":[[1.14,39.86]],"id":228749}]}]}
{"op":"mcm","clk":"ANyfqAkA/MuYCgD1oZ0K","pt":1657539768810,"mc":[{"id":"1.200806927","rc":[{"atl":[[8,1.03]],"id":2857977}]}]}
{"op":"mcm","clk":"APugqAkAzM2YCgDiop0K","pt":1657539770931,"mc":[{"id":"1.200806927","rc":[{"atb":[[1.14,44.16]],"id":228749}]}]}
{"op":"mcm","clk":"AMmhqAkAzM6YCgCao50K","pt":1657539771982,"mc":[{"id":"1.200806927","rc":[{"atl":[[1.15,19.71]],"trd":[[1.15,1057]],"ltp":1.15,"tv":15664.08,"id":228749},{"trd":[[7.6,0.43]],"ltp":7.6,"tv":961.48,"id":2857977}],"tv":16625.56}]}
{"op":"mcm","clk":"APOhqAkAgs+YCgCzo50K","pt":1657539772505,"mc":[{"id":"1.200806927","rc":[{"atb":[[1.14,33.25]],"id":228749}]}]}
{"op":"mcm","clk":"AIiiqAkAlM+YCgDFo50K","pt":1657539772720,"mc":[{"id":"1.200806927","rc":[{"atl":[[8,2.76]],"id":2857977}]}]}
{"op":"mcm","clk":"AJiiqAkApc+YCgDOo50K","pt":1657539772918,"mc":[{"id":"1.200806927","rc":[{"atb":[[1.12,432.03]],"id":228749}]}]}
{"op":"mcm","clk":"ALiiqAkAwM+YCgDfo50K","pt":1657539773220,"mc":[{"id":"1.200806927","rc":[{"atb":[[1.14,38.51]],"id":228749}]}]}
{"op":"mcm","clk":"AKKjqAkArtCYCgCgpJ0K","pt":1657539774297,"mc":[{"id":"1.200806927","rc":[{"atb":[[1.14,41.67]],"id":228749}]}]}
{"op":"mcm","clk":"AKujqAkAu9CYCgCppJ0K","pt":1657539774415,"mc":[{"id":"1.200806927","rc":[{"atb":[[1.14,42.72]],"id":228749}]}]}
{"op":"mcm","clk":"ANCjqAkA6NCYCgDLpJ0K","pt":1657539774824,"mc":[{"id":"1.200806927","rc":[{"atb":[[1.14,95.31]],"id":228749}]}]}
{"op":"mcm","clk":"APCjqAkAjNGYCgDcpJ0K","pt":1657539775130,"mc":[{"id":"1.200806927","rc":[{"atb":[[1.14,95.84]],"id":228749}]}]}
{"op":"mcm","clk":"AKGkqAkAx9GYCgD3pJ0K","pt":1657539775716,"mc":[{"id":"1.200806927","rc":[{"atb":[[1.1,115.58]],"atl":[[1.17,304.57],[1.15,0]],"trd":[[1.17,532.35],[1.15,1076.71]],"ltp":1.17,"tv":15697.04,"id":228749},{"trd":[[7.6,3.41],[6.8,4.29]],"ltp":6.8,"tv":966.74,"id":2857977}],"tv":16663.78}]}
{"op":"mcm","clk":"AMOkqAkA+tGYCgCWpZ0K","pt":1657539776137,"mc":[{"id":"1.200806927","rc":[{"atb":[[1.14,98.43]],"id":228749}]}]}
{"op":"mcm","clk":"AMekqAkAgtKYCgCbpZ0K","pt":1657539776230,"mc":[{"id":"1.200806927","rc":[{"atl":[[15,0.11]],"id":2857977}]}]}
{"op":"mcm","clk":"ANKkqAkAlNKYCgChpZ0K","pt":1657539776391,"mc":[{"id":"1.200806927","rc":[{"atb":[[1.1,120.84]],"id":228749}]}]}
{"op":"mcm","clk":"AOWkqAkAntKYCgCnpZ0K","pt":1657539776507,"mc":[{"id":"1.200806927","rc":[{"atb":[[1.14,98.53]],"id":228749},{"atl":[[8,3.27]],"id":2857977}]}]}
{"op":"mcm","clk":"APOkqAkAtNKYCgC0pZ0K","pt":1657539776712,"mc":[{"id":"1.200806927","rc":[{"atb":[[1.14,77.49]],"trd":[[1.14,1047.67]],"ltp":1.14,"tv":15712.06,"id":228749}],"tv":16678.8}]}
{"op":"mcm","clk":"AOelqAkAvtOYCgCJpp0K","pt":1657539778124,"mc":[{"id":"1.200806927","rc":[{"atb":[[1.14,80.12]],"trd":[[1.14,1052.93]],"tv":15717.32,"id":228749}],"tv":16684.06}]}
{"op":"mcm","clk":"AP6lqAkA1tOYCgCSpp0K","pt":1657539778324,"mc":[{"id":"1.200806927","rc":[{"atl":[[1.17,302.07]],"trd":[[1.17,534.85]],"ltp":1.17,"tv":15719.82,"id":228749},{"trd":[[6.8,4.72]],"tv":967.17,"id":2857977}],"tv":16686.99}]}
{"op":"mcm","clk":"AMemqAkAm9SYCgC/pp0K","pt":1657539779013,"mc":[{"id":"1.200806927","rc":[{"atl":[[7.6,0.53]],"id":2857977}]}]}
{"op":"mcm","clk":"AN6mqAkAutSYCgDapp0K","pt":1657539779332,"mc":[{"id":"1.200806927","rc":[{"atl":[[7.6,1.06]],"id":2857977}]}]}
{"op":"mcm","clk":"AOamqAkAxtSYCgDkpp0K","pt":1657539779434,"mc":[{"id":"1.200806927","rc":[{"atb":[[1.15,1.58]],"id":228749}]}]}
{"op":"mcm","clk":"AIynqAkA69SYCgCAp50K","pt":1657539779839,"mc":[{"id":"1.200806927","rc":[{"atb":[[1.15,6.84]],"id":228749},{"atl":[[8,3.57]],"id":2857977}]}]}
{"op":"mcm","clk":"AKCnqAkAjNWYCgCMp50K","pt":1657539780127,"mc":[{"id":"1.200806927","rc":[{"atb":[[1.14,82.75]],"id":228749}]}]}
{"op":"mcm","clk":"AMOnqAkAytWYCgCnp50K","pt":1657539780639,"mc":[{"id":"1.200806927","rc":[{"atl":[[8.2,0]],"id":2857977}]}]}
{"op":"mcm","clk":"ANanqAkA69WYCgC0p50K","pt":1657539780893,"mc":[{"id":"1.200806927","rc":[{"atb":[[1.14,85.38]],"id":228749}]}]}
{"op":"mcm","clk":"AN6nqAkA99WYCgC5p50K","pt":1657539780998,"mc":[{"id":"1.200806927","rc":[{"atb":[[1.14,86.17]],"id":228749}]}]}
{"op":"mcm","clk":"AJmoqAkAvtaYCgDzp50K","pt":1657539781730,"mc":[{"id":"1.200806927","rc":[{"atb":[[1.14,99.12]],"id":228749}]}]}
{"op":"mcm","clk":"AK+oqAkA3daYCgCCqJ0K","pt":1657539782043,"mc":[{"id":"1.200806927","rc":[{"atb":[[1.15,12.1]],"id":228749}]}]}
{"op":"mcm","clk":"AMWoqAkA/taYCgCPqJ0K","pt":1657539782307,"mc":[{"id":"1.200806927","rc":[{"atb":[[1.15,17.36]],"id":228749}]}]}
{"op":"mcm","clk":"AJGpqAkAyteYCgDIqJ0K","pt":1657539783141,"mc":[{"id":"1.200806927","rc":[{"atb":[[1.15,19.84]],"id":228749}]}]}
{"op":"mcm","clk":"ALCpqAkA+deYCgDbqJ0K","pt":1657539783524,"mc":[{"id":"1.200806927","rc":[{"atb":[[1.15,20.89]],"id":228749}]}]}
{"op":"mcm","clk":"AMipqAkAl9iYCgDrqJ0K","pt":1657539783817,"mc":[{"id":"1.200806927","rc":[{"atb":[[1.15,23.52]],"id":228749}]}]}
{"op":"mcm","clk":"ANupqAkAptiYCgD4qJ0K","pt":1657539784037,"mc":[{"id":"1.200806927","rc":[{"atl":[[7.6,1.81]],"id":2857977}]}]}
{"op":"mcm","clk":"APGpqAkAuNiYCgCDqZ0K","pt":1657539784255,"mc":[{"id":"1.200806927","rc":[{"atb":[[1.15,0]],"trd":[[1.15,1079.49]],"ltp":1.15,"tv":15722.6,"id":228749},{"atl":[[7.6,1.39]],"trd":[[7.6,3.83]],"ltp":7.6,"tv":967.59,"id":2857977}],"tv":16690.19}]}
{"op":"mcm","clk":"APipqAkAwdiYCgCHqZ0K","pt":1657539784346,"mc":[{"id":"1.200806927","rc":[{"atl":[[7.6,1.49]],"id":2857977}]}]}
{"op":"mcm","clk":"ANmqqAkAtdmYCgDGqZ0K","pt":1657539785443,"mc":[{"id":"1.200806927","rc":[{"atl":[[1.17,298.99]],"trd":[[1.17,537.93]],"ltp":1.17,"tv":15725.68,"id":228749},{"trd":[[6.8,5.25]],"ltp":6.8,"tv":968.12,"id":2857977}],"tv":16693.8}]}
{"op":"mcm","clk":"AIyrqAkA+tmYCgDqqZ0K","pt":1657539786038,"mc":[{"id":"1.200806927","rc":[{"atl":[[1.16,10.52]],"id":228749}]}]}
{"op":"mcm","clk":"ALCrqAkAoNqYCgCJqp0K","pt":1657539786448,"mc":[{"id":"1.200806927","rc":[{"atb":[[1.15,2.59]],"id":228749}]}]}
{"op":"mcm","clk":"AOqrqAkA+NqYCgC4qp0K","pt":1657539787237,"mc":[{"id":"1.200806927","rc":[{"atb":[[1.15,5.22]],"id":228749}]}]}
{"op":"mcm","clk":"APurqAkAiduYCgDCqp0K","pt":1657539787439,"mc":[{"id":"1.200806927","rc":[{"atb":[[1.01,2972.79]],"id":228749}]}]}
{"op":"mcm","clk":"AIOsqAkAltuYCgDHqp0K","pt":1657539787553,"mc":[{"id":"1.200806927","rc":[{"atl":[[8,4.22]],"id":2857977}]}]}
{"op":"mcm","clk":"AJCsqAkAqNuYCgDOqp0K","pt":1657539787714,"mc":[{"id":"1.200806927","rc":[{"atl":[[1.18,0]],"id":228749},{"atl":[[8,1.59]],"id":2857977}]}]}
{"op":"mcm","clk":"AJusqAkAu9uYCgDZqp0K","pt":1657539787916,"mc":[{"id":"1.200806927","rc":[{"atb":[[1.15,9.11]],"id":228749}]}]}
{"op":"mcm","clk":"AMGsqAkA6duYCgDxqp0K","pt":1657539788442,"mc":[{"id":"1.200806927","rc":[{"atb":[[1.14,86.17]],"id":228749}]}]}
{"op":"mcm","clk":"AOqsqAkAotyYCgCHq50K","pt":1657539788923,"mc":[{"id":"1.200806927","rc":[{"atl":[[1.16,5.26]],"id":228749}]}]}
{"op":"mcm","clk":"ANStqAkApN2YCgDAq50K","pt":1657539790322,"mc":[{"id":"1.200806927","rc":[{"atl":[[1.19,1998.18]],"id":228749}]}]}
{"op":"mcm","clk":"AOCtqAkArN2YCgDDq50K","pt":1657539790440,"mc":[{"id":"1.200806927","rc":[{"atl":[[1.16,0]],"id":228749}]}]}
{"op":"mcm","clk":"APStqAkAwt2YCgDOq50K","pt":1657539790642,"mc":[{"id":"1.200806927","rc":[{"atb":[[1.15,11.74]],"atl":[[1.17,298.46]],"trd":[[1.17,538.99]],"tv":15726.74,"id":228749}],"tv":16694.86}]}
{"op":"mcm","clk":"AImuqAkA292YCgDcq50K","pt":1657539790867,"mc":[{"id":"1.200806927","rc":[{"atl":[[7.6,1.6]],"id":2857977}]}]}
{"op":"mcm","clk":"AOquqAkAwN6YCgCZrJ0K","pt":1657539792040,"mc":[{"id":"1.200806927","rc":[{"atl":[[7.6,3.18]],"id":2857977}]}]}
{"op":"mcm","clk":"AMevqAkAv9+YCgDRrJ0K","pt":1657539793153,"mc":[{"id":"1.200806927","rc":[{"atl":[[1.17,272.16]],"trd":[[1.17,591.59]],"tv":15779.34,"id":228749}],"tv":16747.46}]}
{"op":"mcm","clk":"ANGvqAkAyd+YCgDUrJ0K","pt":1657539793250,"mc":[{"id":"1.200806927","rc":[{"atb":[[1.15,3.13]],"trd":[[1.15,1096.7]],"ltp":1.15,"tv":15796.55,"id":228749}],"tv":16764.67}]}
{"op":"mcm","clk":"AJawqAkAleCYCgCKrZ0K","pt":1657539794041,"mc":[{"id":"1.200806927","rc":[{"atb":[[1.15,4.18]],"id":228749}]}]}
{"op":"mcm","clk":"AKewqAkAqOCYCgCXrZ0K","pt":1657539794257,"mc":[{"id":"1.200806927","rc":[{"atl":[[1.19,1950.85]],"id":228749}]}]}
{"op":"mcm","clk":"AKywqAkAsuCYCgCbrZ0K","pt":1657539794345,"mc":[{"id":"1.200806927","rc":[{"atb":[[1.14,81.87]],"id":228749}]}]}
{"op":"mcm","clk":"AIWxqAkAmeGYCgDQrZ0K","pt":1657539795446,"mc":[{"id":"1.200806927","rc":[{"atl":[[1.17,266.9]],"trd":[[1.17,602.11]],"ltp":1.17,"tv":15807.07,"id":228749}],"tv":16775.19}]}
{"op":"mcm","clk":"ALCxqAkAyOGYCgDjrZ0K","pt":1657539795861,"mc":[{"id":"1.200806927","rc":[{"atb":[[1.14,83.71]],"id":228749}]}]}
{"op":"mcm","clk":"ANGxqAkA7uGYCgD2rZ0K","pt":1657539796229,"mc":[{"id":"1.200806927","rc":[{"atb":[[1.15,1.55]],"id":228749}]}]}
{"op":"mcm","clk":"APWxqAkAiuKYCgCNrp0K","pt":1657539796550,"mc":[{"id":"1.200806927","rc":[{"atb":[[1.14,81.08]],"id":228749}]}]}
{"op":"mcm","clk":"APqxqAkAkuKYCgCRrp0K","pt":1657539796645,"mc":[{"id":"1.200806927","rc":[{"atl":[[1.17,264.27]],"trd":[[1.17,607.37]],"tv":15812.33,"id":228749}],"tv":16780.45}]}
{"op":"mcm","clk":"AJOyqAkAo+KYCgCkrp0K","pt":1657539796847,"mc":[{"id":"1.200806927","rc":[{"atl":[[1.17,261.19]],"trd":[[1.17,610.45]],"tv":15815.41,"id":228749},{"trd":[[6.8,5.78]],"tv":968.65,"id":2857977}],"tv":16784.06}]}
{"op":"mcm","clk":"AKmyqAkAu+KYCgCurp0K","pt":1657539797021,"mc":[{"id":"1.200806927","rc":[{"atb":[[1.14,75.82]],"id":228749}]}]}
{"op":"mcm","clk":"AMCyqAkA1OKYCgDArp0K","pt":1657539797333,"mc":[{"id":"1.200806927","rc":[{"atl":[[1.17,255.09]],"trd":[[1.17,616.55]],"tv":15821.51,"id":228749},{"atl":[[7.6,1.6]],"trd":[[6.8,6.83]],"tv":969.7,"id":2857977}],"tv":16791.21}]}
{"op":"mcm","clk":"AOOyqAkA7uKYCgDYrp0K","pt":1657539797640,"mc":[{"id":"1.200806927","rc":[{"atl":[[8,1.29]],"id":2857977}]}]}
{"op":"mcm","clk":"AIqzqAkAo+OYCgDtrp0K","pt":1657539798114,"mc":[{"id":"1.200806927","rc":[{"atl":[[1.17,254.47]],"trd":[[1.17,617.17]],"tv":15822.13,"id":228749},{"trd":[[6.8,6.94]],"tv":969.81,"id":2857977}],"tv":16791.94}]}
{"op":"mcm","clk":"AJCzqAkAqeOYCgDxrp0K","pt":1657539798210,"mc":[{"id":"1.200806927","rc":[{"atb":[[1.15,0]],"atl":[[1.15,31.75]],"trd":[[1.15,1107.26]],"ltp":1.15,"tv":15832.69,"id":228749},{"atl":[[7.6,0]],"trd":[[7.6,5.43]],"ltp":7.6,"tv":971.41,"id":2857977}],"tv":16804.1}]}
{"op":"mcm","clk":"AMyzqAkA6+OYCgChr50K","pt":1657539798960,"mc":[{"id":"1.200806927","rc":[{"atl":[[1.17,233.63],[1.15,0]],"trd":[[1.17,658.85]],"ltp":1.17,"tv":15874.37,"id":228749}],"tv":16845.78}]}
{"op":"mcm","clk":"APqzqAkAjuSYCgC+r50K","pt":1657539799438,"mc":[{"id":"1.200806927","rc":[{"atl":[[8,1.72]],"id":2857977}]}]}
{"op":"mcm","clk":"AIm0qAkAmuSYCgDHr50K","pt":1657539799625,"mc":[{"id":"1.200806927","rc":[{"atl":[[1.17,233.01]],"trd":[[1.17,659.47]],"tv":15874.99,"id":228749},{"trd":[[6.8,7.05]],"ltp":6.8,"tv":971.52,"id":2857977}],"tv":16846.51}]}
{"op":"mcm","clk":"AKO0qAkAs+SYCgDbr50K","pt":1657539799945,"mc":[{"id":"1.200806927","rc":[{"atl":[[8,1.07]],"id":2857977}]}]}
{"op":"mcm","clk":"AMK0qAkA2OSYCgD6r50K","pt":1657539800327,"mc":[{"id":"1.200806927","rc":[{"atl":[[1.17,229.93]],"trd":[[1.17,662.55]],"tv":15878.07,"id":228749},{"trd":[[6.8,7.58]],"tv":972.05,"id":2857977}],"tv":16850.12}]}
{"op":"mcm","clk":"ANW0qAkA8eSYCgCMsJ0K","pt":1657539800643,"mc":[{"id":"1.200806927","rc":[{"atb":[[1.16,1.05]],"id":228749}]}]}
{"op":"mcm","clk":"ANm0qAkA+uSYCgCSsJ0K","pt":1657539800740,"mc":[{"id":"1.200806927","rc":[{"atb":[[1.15,5.26]],"atl":[[1.17,219.53]],"trd":[[1.17,683.35]],"tv":15898.87,"id":228749}],"tv":16870.92}]}
{"op":"mcm","clk":"AIG1qAkAnuWYCgCssJ0K","pt":1657539801251,"mc":[{"id":"1.200806927","rc":[{"atb":[[1.16,11.57]],"id":228749}]}]}
{"op":"mcm","clk":"AJq1qAkAveWYCgC+sJ0K","pt":1657539801559,"mc":[{"id":"1.200806927","rc":[{"atb":[[1.14,963.82],[1.16,12.36]],"id":228749}]}]}
{"op":"mcm","clk":"AKO1qAkAwuWYCgDDsJ0K","pt":1657539801659,"mc":[{"id":"1.200806927","rc":[{"atb":[[1.15,6.57]],"id":228749}]}]}
{"op":"mcm","clk":"ALq1qAkA1eWYCgDQsJ0K","pt":1657539801919,"mc":[{"id":"1.200806927","rc":[{"atl":[[1.17,216.45]],"trd":[[1.17,686.43]],"tv":15901.95,"id":228749},{"trd":[[6.8,8.11]],"tv":972.58,"id":2857977}],"tv":16874.53}]}
{"op":"mcm","clk":"AOC1qAkA/OWYCgDssJ0K","pt":1657539802381,"mc":[{"id":"1.200806927","rc":[{"atb":[[1.14,963.29]],"id":228749}]}]}
{"op":"mcm","clk":"AOm1qAkAgOaYCgDwsJ0K","pt":1657539802455,"mc":[{"id":"1.200806927","rc":[{"atb":[[1.14,965.92]],"atl":[[1.17,213.37]],"trd":[[1.17,689.51]],"tv":15905.03,"id":228749},{"trd":[[6.8,8.64]],"tv":973.11,"id":2857977}],"tv":16878.14}]}
{"op":"mcm","clk":"AP+1qAkAk+aYCgD8sJ0K","pt":1657539802676,"mc":[{"id":"1.200806927","rc":[{"atb":[[1.16,3.1]],"id":228749}]}]}
{"op":"mcm","clk":"ALm2qAkA0uaYCgCisZ0K","pt":1657539803347,"mc":[{"id":"1.200806927","rc":[{"atb":[[1.16,5.73]],"id":228749}]}]}
{"op":"mcm","clk":"ANW2qAkA5+aYCgCvsZ0K","pt":1657539803650,"mc":[{"id":"1.200806927","rc":[{"atb":[[1.15,0],[1.16,0]],"atl":[[1.15,145.47]],"id":228749}]}]}
{"op":"mcm","clk":"ALW3qAkAxueYCgDqsZ0K","pt":1657539804754,"mc":[{"id":"1.200806927","rc":[{"atl":[[1.17,0],[1.15,0]],"trd":[[1.17,902.88],[1.15,1247.47]],"tv":16258.61,"id":228749},{"atl":[[6.8,152.44]],"trd":[[7.6,26.65],[6.8,45.35]],"tv":1031.04,"id":2857977}],"tv":17289.65}]}
{"op":"mcm","clk":"AM+3qAkA3ueYCgD5sZ0K","pt":1657539805066,"mc":[{"id":"1.200806927","rc":[{"atb":[[1.17,1.58]],"id":228749}]}]}
{"op":"mcm","clk":"AJu4qAkAu+iYCgC1sp0K","pt":1657539806063,"mc":[{"id":"1.200806927","rc":[{"atb":[[1.17,3.16]],"id":228749}]}]}
{"op":"mcm","clk":"AJu5qAkAu+mYCgCIs50K","pt":1657539807550,"mc":[{"id":"1.200806927","rc":[{"atb":[[1.16,12.95]],"id":228749}]}]}
{"op":"mcm","clk":"ALC5qAkAy+mYCgCUs50K","pt":1657539807770,"mc":[{"id":"1.200806927","rc":[{"atb":[[1.17,5.64]],"id":228749}]}]}
{"op":"mcm","clk":"AMW5qAkA3umYCgCks50K","pt":1657539808018,"mc":[{"id":"1.200806927","rc":[{"atb":[[1.14,966.45]],"id":228749}]}]}
{"op":"mcm","clk":"ANq5qAkA8umYCgC4s50K","pt":1657539808243,"mc":[{"id":"1.200806927","rc":[{"atb":[[1.15,0.89]],"id":228749}]}]}
{"op":"mcm","clk":"APe5qAkAkeqYCgDTs50K","pt":1657539808647,"mc":[{"id":"1.200806927","rc":[{"atb":[[1.15,6.15]],"id":228749}]}]}
{"op":"mcm","clk":"AIC6qAkAmuqYCgDcs50K","pt":1657539808750,"mc":[{"id":"1.200806927","rc":[{"atb":[[1.17,31.94]],"id":228749}]}]}
{"op":"mcm","clk":"AMW6qAkA5OqYCgCWtJ0K","pt":1657539809647,"mc":[{"id":"1.200806927","rc":[{"atb":[[1.17,44.89]],"id":228749}]}]}
{"op":"mcm","clk":"AMm6qAkA7eqYCgCbtJ0K","pt":1657539809740,"mc":[{"id":"1.200806927","rc":[{"atl":[[8,6.33]],"id":2857977}]}]}
{"op":"mcm","clk":"AJC7qAkAq+uYCgDOtJ0K","pt":1657539810624,"mc":[{"id":"1.200806927","rc":[{"atb":[[1.17,43.31]],"id":228749}]}]}
{"op":"mcm","clk":"ALi7qAkA0OuYCgDutJ0K","pt":1657539811168,"mc":[{"id":"1.200806927","rc":[{"atb":[[1.17,46.75]],"id":228749}]}]}
{"op":"mcm","clk":"ANi8qAkA1eyYCgDVtZ0K","pt":1657539813056,"mc":[{"id":"1.200806927","rc":[{"atb":[[1.15,5.26]],"id":228749}]}]}
{"op":"mcm","clk":"AO+8qAkA6uyYCgDrtZ0K","pt":1657539813352,"mc":[{"id":"1.200806927","rc":[{"atb":[[1.17,52.01]],"id":228749}]}]}
{"op":"mcm","clk":"AIm9qAkAhO2YCgCBtp0K","pt":1657539813693,"mc":[{"id":"1.200806927","rc":[{"atb":[[1.17,32.01]],"trd":[[1.17,942.88]],"tv":16298.61,"id":228749},{"atl":[[6.8,154.02]],"id":2857977}],"tv":17329.65}]}
{"op":"mcm","clk":"AJi9qAkAk+2YCgCNtp0K","pt":1657539813864,"mc":[{"id":"1.200806927","rc":[{"atb":[[1.17,37.27]],"id":228749}]}]}
{"op":"mcm","clk":"ALW9qAkAvu2YCgCqtp0K","pt":1657539814239,"mc":[{"id":"1.200806927","rc":[{"atb":[[1.17,0]],"trd":[[1.17,1065.08]],"tv":16420.81,"id":228749},{"atl":[[6.8,133.29]],"trd":[[6.8,66.08]],"tv":1051.77,"id":2857977}],"tv":17472.58}]}
{"op":"mcm","clk":"APe9qAkA8u2YCgDbtp0K","pt":1657539814976,"mc":[{"id":"1.200806927","rc":[{"atl":[[1.32,0]],"id":228749}]}]}
{"op":"mcm","clk":"AIS+qAkAgO6YCgDitp0K","pt":1657539815062,"mc":[{"id":"1.200806927","rc":[{"atl":[[7.6,0.84]],"id":2857977}]}]}
{"op":"mcm","clk":"AOa+qAkA1e6YCgCbt50K","pt":1657539816165,"mc":[{"id":"1.200806927","rc":[{"atl":[[1.19,0]],"id":228749}]}]}
{"op":"mcm","clk":"APK+qAkA6O6YCgClt50K","pt":1657539816334,"mc":[{"id":"1.200806927","rc":[{"trd":[[1.17,1066.66]],"tv":16422.39,"id":228749},{"atl":[[6.8,133.02]],"trd":[[6.8,66.35]],"tv":1052.04,"id":2857977}],"tv":17474.43}]}
{"op":"mcm","clk":"AP6+qAkA9u6YCgCyt50K","pt":1657539816446,"mc":[{"id":"1.200806927","rc":[{"atb":[[1.17,2.63]],"id":228749}]}]}
{"op":"mcm","clk":"AKi/qAkAnO+YCgDQt50K","pt":1657539816956,"mc":[{"id":"1.200806927","rc":[{"atb":[[1.19,0.11]],"id":228749}]}]}
{"op":"mcm","clk":"ALa/qAkApu+YCgDXt50K","pt":1657539817069,"mc":[{"id":"1.200806927","rc":[{"atl":[[6.2,0.1]],"id":2857977}]}]}
{"op":"mcm","clk":"AN6/qAkA0++YCgD0t50K","pt":1657539817533,"mc":[{"id":"1.200806927","rc":[{"atb":[[1.17,0],[1.19,0]],"trd":[[1.17,1068.66],[1.19,91.53]],"tv":16425.13,"id":228749},{"atl":[[6.8,132.68],[6.2,0]],"trd":[[6.8,66.69],[6.2,1.26]],"tv":1052.48,"id":2857977}],"tv":17477.61}]}
{"op":"mcm","clk":"AJLAqAkAg/CYCgDTuJ0K","pt":1657539818146,"mc":[{"id":"1.200806927","rc":[{"atb":[[1.17,10.52]],"id":228749}]}]}
{"op":"mcm","clk":"ALfAqAkAr/CYCgD1uJ0K","pt":1657539818557,"mc":[{"id":"1.200806927","rc":[{"atl":[[6.8,123.66]],"id":2857977}]}]}
{"op":"mcm","clk":"AL/AqAkAt/CYCgD+uJ0K","pt":1657539818706,"mc":[{"id":"1.200806927","rc":[{"atb":[[1.17,0]],"trd":[[1.17,1215.91]],"tv":16572.38,"id":228749},{"atl":[[6.8,98.32]],"trd":[[6.8,92.03]],"tv":1077.82,"id":2857977}],"tv":17650.2}]}
{"op":"mcm","clk":"AKLBqAkAkvGYCgC5uZ0K","pt":1657539819880,"mc":[{"id":"1.200806927","rc":[{"atb":[[1.14,963.82]],"id":228749}]}]}
{"op":"mcm","clk":"AM/BqAkAsPGYCgDJuZ0K","pt":1657539820352,"mc":[{"id":"1.200806927","rc":[{"atb":[[1.16,0]],"atl":[[1.16,317.24]],"trd":[[1.17,1787.34]],"tv":17143.81,"id":228749},{"atl":[[6.8,0]],"trd":[[6.8,190.35]],"tv":1176.14,"id":2857977}],"tv":18319.95}]}
{"op":"mcm","clk":"APrBqAkA2/GYCgDjuZ0K","pt":1657539820958,"mc":[{"id":"1.200806927","rc":[{"atl":[[7.6,1]],"id":2857977}]}]}
{"op":"mcm","clk":"AILCqAkA5vGYCgDouZ0K","pt":1657539821064,"mc":[{"id":"1.200806927","rc":[{"atb":[[1.15,0]],"id":228749}]}]}
{"op":"mcm","clk":"AJfCqAkA9/GYCgDyuZ0K","pt":1657539821283,"mc":[{"id":"1.200806927","rc":[{"atl":[[1.17,1950.85]],"id":228749}]}]}
{"op":"mcm","clk":"AKjCqAkAivKYCgD6uZ0K","pt":1657539821481,"mc":[{"id":"1.200806927","rc":[{"atl":[[1.16,316.19]],"id":228749}]}]}
{"op":"mcm","clk":"AKjDqAkAmPOYCgDMup0K","pt":1657539823152,"mc":[{"id":"1.200806927","rc":[{"atl":[[2.3,0.3]],"id":228749}]}]}
{"op":"mcm","clk":"AMnDqAkAufOYCgDWup0K","pt":1657539823583,"mc":[{"id":"1.200806927","rc":[{"atl":[[1.17,1952.65]],"id":228749}]}]}
{"op":"mcm","clk":"AIvEqAkA+POYCgDxup0K","pt":1657539824261,"mc":[{"id":"1.200806927","rc":[{"atl":[[1.18,76]],"id":228749}]}]}
{"op":"mcm","clk":"AOfEqAkA0vSYCgChu50K","pt":1657539825464,"mc":[{"id":"1.200806927","rc":[{"atb":[[1.13,0]],"id":228749}]}]}
{"op":"mcm","clk":"AIrFqAkA9/SYCgC0u50K","pt":1657539825949,"mc":[{"id":"1.200806927","rc":[{"atl":[[7.6,0.84]],"id":2857977}]}]}
{"op":"mcm","clk":"AL3FqAkAmvWYCgDXu50K","pt":1657539826470,"mc":[{"id":"1.200806927","rc":[{"atl":[[1.17,1957.47]],"id":228749}]}]}
{"op":"mcm","clk":"ANHFqAkArvWYCgDlu50K","pt":1657539826744,"mc":[{"id":"1.200806927","rc":[{"atb":[[1.14,969.08]],"id":228749}]}]}
{"op":"mcm","clk":"AIDGqAkA3PWYCgCEvJ0K","pt":1657539827356,"mc":[{"id":"1.200806927","rc":[{"atl":[[1.16,310.85]],"trd":[[1.16,5.34]],"ltp":1.16,"tv":17149.15,"id":228749},{"trd":[[7.2,0.86]],"ltp":7.2,"tv":1177,"id":2857977}],"tv":18326.15}]}
{"op":"mcm","clk":"AMvGqAkAm/aYCgCwvJ0K","pt":1657539828155,"mc":[{"id":"1.200806927","rc":[{"atl":[[1.16,284.55]],"id":228749}]}]}
{"op":"mcm","clk":"ANbGqAkArPaYCgC6vJ0K","pt":1657539828349,"mc":[{"id":"1.200806927","rc":[{"atl":[[1.16,283.75]],"trd":[[1.16,6.94]],"tv":17150.75,"id":228749}],"tv":18327.75}]}
{"op":"mcm","clk":"AOTGqAkAufaYCgDAvJ0K","pt":1657539828472,"mc":[{"id":"1.200806927","rc":[{"atl":[[8,5.9]],"id":2857977}]}]}
{"op":"mcm","clk":"AI3HqAkA3faYCgDVvJ0K","pt":1657539828876,"mc":[{"id":"1.200806927","rc":[{"atl":[[1.16,283.08]],"trd":[[1.16,7.61]],"tv":17151.42,"id":228749},{"trd":[[7.2,0.97]],"tv":1177.11,"id":2857977}],"tv":18328.53}]}
{"op":"mcm","clk":"AIbIqAkA1/eYCgCYvZ0K","pt":1657539830377,"mc":[{"id":"1.200806927","rc":[{"atl":[[1.16,280.45]],"id":228749}]}]}
{"op":"mcm","clk":"AIzIqAkA4veYCgCcvZ0K","pt":1657539830485,"mc":[{"id":"1.200806927","rc":[{"atl":[[1.16,0]],"trd":[[1.16,288.06]],"tv":17431.87,"id":228749},{"atl":[[7.2,165.19]],"trd":[[7.2,46.15]],"tv":1222.29,"id":2857977}],"tv":18654.16}]}
{"op":"mcm","clk":"AJLIqAkA7feYCgCgvZ0K","pt":1657539830579,"mc":[{"id":"1.200806927","rc":[{"atb":[[1.16,950]],"atl":[[1.17,1956.85]],"trd":[[1.17,1787.96]],"ltp":1.17,"tv":17432.49,"id":228749},{"trd":[[6.8,190.45]],"ltp":6.8,"tv":1222.39,"id":2857977}],"tv":18654.88}]}
{"op":"mcm","clk":"AMvIqAkAq/iYCgDCvZ0K","pt":1657539831361,"mc":[{"id":"1.200806927","rc":[{"atl":[[7.6,0]],"id":2857977}]}]}
{"op":"mcm","clk":"AO7IqAkA1PiYCgDZvZ0K","pt":1657539831883,"mc":[{"id":"1.200806927","rc":[{"atb":[[1.16,976.3]],"id":228749}]}]}
{"op":"mcm","clk":"AO/IqAkA2PiYCgDZvZ0K","pt":1657539831968,"mc":[{"id":"1.200806927","rc":[{"atb":[[1.16,978.93]],"id":228749},{"atl":[[7.2,165.72]],"id":2857977}]}]}
{"op":"mcm","clk":"APzIqAkA3fiYCgDgvZ0K","pt":1657539832074,"mc":[{"id":"1.200806927","rc":[{"atb":[[1.16,981.56]],"id":228749}]}]}
{"op":"mcm","clk":"AIvJqAkA7/iYCgDwvZ0K","pt":1657539832267,"mc":[{"id":"1.200806927","rc":[{"atl":[[7.2,166.25]],"id":2857977}]}]}
{"op":"mcm","clk":"AJHJqAkA/fiYCgD5vZ0K","pt":1657539832452,"mc":[{"id":"1.200806927","rc":[{"atl":[[7.6,0.9]],"id":2857977}]}]}
{"op":"mcm","clk":"AJvJqAkAhvmYCgD9vZ0K","pt":1657539832554,"mc":[{"id":"1.200806927","rc":[{"atb":[[1.16,983.14]],"id":228749}]}]}
{"op":"mcm","clk":"AN7JqAkAxvmYCgCsvp0K","pt":1657539833388,"mc":[{"id":"1.200806927","rc":[{"atb":[[1.16,984.19]],"id":228749}]}]}
{"op":"mcm","clk":"AOTJqAkAzvmYCgC0vp0K","pt":1657539833485,"mc":[{"id":"1.200806927","rc":[{"atb":[[1.16,999.97]],"id":228749}]}]}
{"op":"mcm","clk":"APTJqAkA3fmYCgC7vp0K","pt":1657539833644,"mc":[{"id":"1.200806927","rc":[{"atb":[[1.16,1021.9]],"id":228749}]}]}
{"op":"mcm","clk":"APzJqAkA7PmYCgDGvp0K","pt":1657539833765,"mc":[{"id":"1.200806927","rc":[{"atl":[[7.2,166.36]],"id":2857977}]}]}
{"op":"mcm","clk":"ALfKqAkApfqYCgDnvp0K","pt":1657539834483,"mc":[{"id":"1.200806927","rc":[{"atb":[[1.16,1022.95]],"atl":[[1.33,2.88]],"id":228749}]}]}
{"op":"mcm","clk":"AN3KqAkAyvqYCgD7vp0K","pt":1657539834906,"mc":[{"id":"1.200806927","rc":[{"atb":[[1.16,1065.03]],"id":228749}]}]}
{"op":"mcm","clk":"AOHKqAkA0fqYCgD9vp0K","pt":1657539834949,"mc":[{"id":"1.200806927","rc":[{"atb":[[1.16,1067.66]],"id":228749}]}]}
{"op":"mcm","clk":"AO3KqAkA3fqYCgCAv50K","pt":1657539835074,"mc":[{"id":"1.200806927","rc":[{"atb":[[1.16,117.66]],"id":228749}]}]}
{"op":"mcm","clk":"AIbLqAkAgvuYCgCSv50K","pt":1657539835486,"mc":[{"id":"1.200806927","rc":[{"atb":[[1.16,93.08],[1.14,963.82]],"id":228749},{"atl":[[7.2,166.57]],"id":2857977}],"con":true}]}
{"op":"mcm","clk":"AI3LqAkAiPuYCgCUv50K","pt":1657539835568,"mc":[{"id":"1.200806927","rc":[{"atb":[[1.16,94.13]],"id":228749}]}]}
{"op":"mcm","clk":"AJnLqAkAlvuYCgCav50K","pt":1657539835779,"mc":[{"id":"1.200806927","rc":[{"atb":[[1.16,96.24]],"atl":[[1.22,1.58]],"id":228749}]}]}
{"op":"mcm","clk":"AKHLqAkAoPuYCgCev50K","pt":1657539835881,"mc":[{"id":"1.200806927","rc":[{"atb":[[1.16,78.67]],"id":228749}]}]}
{"op":"mcm","clk":"ALPLqAkAu/uYCgCtv50K","pt":1657539836196,"mc":[{"id":"1.200806927","rc":[{"atb":[[1.16,81.3]],"id":228749}]}]}
{"op":"mcm","clk":"AMXLqAkAxPuYCgC0v50K","pt":1657539836391,"mc":[{"id":"1.200806927","rc":[{"atb":[[1.16,83.93]],"id":228749}]}]}
{"op":"mcm","clk":"AMrLqAkAzPuYCgC6v50K","pt":1657539836505,"mc":[{"id":"1.200806927","rc":[{"atb":[[1.16,120.74]],"id":228749}]}]}
{"op":"mcm","clk":"ANPLqAkA0PuYCgC8v50K","pt":1657539836587,"mc":[{"id":"1.200806927","rc":[{"atb":[[1.16,123.37]],"id":228749}]}]}
{"op":"mcm","clk":"ANrLqAkA3vuYCgDFv50K","pt":1657539836701,"mc":[{"id":"1.200806927","rc":[{"atb":[[1.16,125.48]],"id":228749}]}]}
{"op":"mcm","clk":"AODLqAkA6fuYCgDLv50K","pt":1657539836775,"mc":[{"id":"1.200806927","rc":[{"atb":[[1.14,75.82],[1.16,119.38]],"id":228749}]}]}
{"op":"mcm","clk":"AOXLqAkA8PuYCgDRv50K","pt":1657539836872,"mc":[{"id":"1.200806927","rc":[{"atb":[[1.16,124.64]],"id":228749}]}]}
{"op":"mcm","clk":"AIDMqAkAi/yYCgDfv50K","pt":1657539837185,"mc":[{"id":"1.200806927","rc":[{"atb":[[1.16,125.17]],"id":228749}]}]}
{"op":"mcm","clk":"AKDMqAkAqPyYCgD1v50K","pt":1657539837601,"mc":[{"id":"1.200806927","rc":[{"atb":[[1.14,73.98]],"id":228749}]}]}
{"op":"mcm","clk":"AK3MqAkAufyYCgCAwJ0K","pt":1657539837799,"mc":[{"id":"1.200806927","rc":[{"atb":[[1.15,0.63]],"id":228749}]}]}
{"op":"mcm","clk":"ANPMqAkA3PyYCgCfwJ0K","pt":1657539838374,"mc":[{"id":"1.200806927","rc":[{"atl":[[7.2,167.1]],"id":2857977}]}]}
{"op":"mcm","clk":"AN/MqAkA7fyYCgCowJ0K","pt":1657539838575,"mc":[{"id":"1.200806927","rc":[{"atb":[[1.12,9.2]],"atl":[[1.23,0]],"id":228749}]}]}
{"op":"mcm","clk":"AOzMqAkAgv2YCgCywJ0K","pt":1657539838794,"mc":[{"id":"1.200806927","rc":[{"atb":[[1.16,176.95]],"id":228749}]}]}
{"op":"mcm","clk":"AKvNqAkAvP2YCgDTwJ0K","pt":1657539839601,"mc":[{"id":"1.200806927","rc":[{"atb":[[1.16,140.14]],"id":228749}]}]}
{"op":"mcm","clk":"AMDNqAkA0f2YCgDawJ0K","pt":1657539839798,"mc":[{"id":"1.200806927","rc":[{"atb":[[1.16,137.51]],"atl":[[1.17,1952.55]],"trd":[[1.17,1796.56]],"tv":17441.09,"id":228749}],"tv":18663.48}]}
{"op":"mcm","clk":"AMfNqAkA3/2YCgDewJ0K","pt":1657539839896,"mc":[{"id":"1.200806927","rc":[{"atb":[[1.16,139.09]],"id":228749}]}]}
{"op":"mcm","clk":"ANzNqAkA9v2YCgDtwJ0K","pt":1657539840210,"mc":[{"id":"1.200806927","rc":[{"atl":[[1.17,1002.55]],"trd":[[1.17,3696.56]],"tv":19341.09,"id":228749}],"tv":20563.48}]}
{"op":"mcm","clk":"AOvNqAkAh/6YCgD+wJ0K","pt":1657539840400,"mc":[{"id":"1.200806927","rc":[{"atb":[[1.16,140.93]],"id":228749}]}]}
{"op":"mcm","clk":"APTNqAkAjf6YCgCEwZ0K","pt":1657539840501,"mc":[{"id":"1.200806927","rc":[{"atb":[[1.14,105.53]],"id":228749}]}]}
{"op":"mcm","clk":"AIHOqAkAlv6YCgCHwZ0K","pt":1657539840608,"mc":[{"id":"1.200806927","rc":[{"atb":[[1.16,138.3]],"id":228749}]}]}
{"op":"mcm","clk":"AIrOqAkAnv6YCgCNwZ0K","pt":1657539840697,"mc":[{"id":"1.200806927","rc":[{"atb":[[1.16,140.93]],"id":228749}]}]}
{"op":"mcm","clk":"AJDOqAkAqP6YCgCQwZ0K","pt":1657539840766,"mc":[{"id":"1.200806927","rc":[{"atl":[[7.6,1.76]],"id":2857977}]}]}
{"op":"mcm","clk":"AJbOqAkAsP6YCgCTwZ0K","pt":1657539840891,"mc":[{"id":"1.200806927","rc":[{"atb":[[1.16,139.88]],"id":228749}]}]}
{"op":"mcm","clk":"AL/OqAkA5v6YCgCwwZ0K","pt":1657539841403,"mc":[{"id":"1.200806927","rc":[{"atb":[[1.16,0]],"trd":[[1.16,361.99]],"ltp":1.16,"tv":19415.02,"id":228749},{"atl":[[7.2,155.74]],"trd":[[7.2,57.51]],"ltp":7.2,"tv":1233.75,"id":2857977}],"tv":20648.77}]}
{"op":"mcm","clk":"AMzOqAkA8/6YCgC3wZ0K","pt":1657539841504,"mc":[{"id":"1.200806927","rc":[{"atl":[[1.17,997.29]],"trd":[[1.17,3707.08]],"ltp":1.17,"tv":19425.54,"id":228749}],"tv":20659.29}]}
{"op":"mcm","clk":"ANXOqAkA/f6YCgC+wZ0K","pt":1657539841611,"mc":[{"id":"1.200806927","rc":[{"atl":[[1.16,926.74]],"trd":[[1.16,1328.66]],"ltp":1.16,"tv":20392.21,"id":228749},{"atl":[[7.2,0]],"trd":[[7.2,213.25]],"tv":1389.49,"id":2857977}],"tv":21781.7}]}
{"op":"mcm","clk":"AKfPqAkA1f+YCgD0wZ0K","pt":1657539842499,"mc":[{"id":"1.200806927","rc":[{"atl":[[1.16,921.48]],"id":228749}]}]}
{"op":"mcm","clk":"AJXQqAkAwoCZCgCywp0K","pt":1657539843809,"mc":[{"id":"1.200806927","rc":[{"atb":[[1.14,104.74]],"atl":[[1.16,0]],"trd":[[1.16,2250.14]],"tv":21313.69,"id":228749},{"atl":[[7.2,61.91]],"trd":[[7.2,361.71]],"tv":1537.95,"id":2857977}],"tv":22851.64}]}
{"op":"mcm","clk":"AJ3QqAkAy4CZCgC2wp0K","pt":1657539843917,"mc":[{"id":"1.200806927","rc":[{"atl":[[1.16,501.5]],"trd":[[1.16,2635.03]],"tv":21698.58,"id":228749},{"atl":[[7.2,0]],"trd":[[7.2,423.72]],"tv":1599.96,"id":2857977}],"tv":23298.54}]}
{"op":"mcm","clk":"AKXQqAkA04CZCgC6wp0K","pt":1657539844007,"mc":[{"id":"1.200806927","rc":[{"atl":[[1.16,500.96]],"trd":[[1.16,2636.09]],"tv":21699.64,"id":228749}],"tv":23299.6}]}
{"op":"mcm","clk":"ALDQqAkA4ICZCgDAwp0K","pt":1657539844117,"mc":[{"id":"1.200806927","rc":[{"atl":[[1.16,500.38]],"trd":[[1.16,2637.26]],"tv":21700.81,"id":228749}],"tv":23300.77}]}
{"op":"mcm","clk":"AI7RqAkAooGZCgD4wp0K","pt":1657539845019,"mc":[{"id":"1.200806927","rc":[{"atl":[[1.16,510.9]],"id":228749}]}]}
{"op":"mcm","clk":"AMjRqAkA04GZCgCiw50K","pt":1657539845608,"mc":[{"id":"1.200806927","rc":[{"atl":[[1.16,508.76]],"trd":[[1.16,2639.4]],"tv":21702.95,"id":228749},{"trd":[[7.2,424.06]],"tv":1600.3,"id":2857977}],"tv":23303.25}]}
{"op":"mcm","clk":"ANjRqAkA44GZCgCsw50K","pt":1657539845803,"mc":[{"id":"1.200806927","rc":[{"atl":[[1.16,508.23]],"trd":[[1.16,2640.46]],"tv":21704.01,"id":228749}],"tv":23304.31}]}
{"op":"mcm","clk":"AIjSqAkAkoKZCgC/w50K","pt":1657539846320,"mc":[{"id":"1.200806927","rc":[{"atl":[[1.17,1177.29]],"id":228749}]}]}
{"op":"mcm","clk":"AKPSqAkAqIKZCgDPw50K","pt":1657539846635,"mc":[{"id":"1.200806927","rc":[{"atl":[[1.16,506.13]],"trd":[[1.16,2644.66]],"tv":21708.21,"id":228749}],"tv":23308.51}]}
{"op":"mcm","clk":"AKjSqAkAsYKZCgDRw50K","pt":1657539846672,"mc":[{"id":"1.200806927","rc":[{"atl":[[1.16,503.5]],"trd":[[1.16,2649.92]],"tv":21713.47,"id":228749}],"tv":23313.77}]}
{"op":"mcm","clk":"ALnSqAkAxoKZCgDcw50K","pt":1657539846900,"mc":[{"id":"1.200806927","rc":[{"atl":[[1.16,477.2]],"trd":[[1.16,2702.52]],"tv":21766.07,"id":228749}],"tv":23366.37}]}
{"op":"mcm","clk":"AODSqAkA5oKZCgDqw50K","pt":1657539847412,"mc":[{"id":"1.200806927","rc":[{"atl":[[1.16,476.54]],"trd":[[1.16,2703.18]],"tv":21766.73,"id":228749},{"trd":[[7.2,424.17]],"tv":1600.41,"id":2857977}],"tv":23367.14}]}
{"op":"mcm","clk":"AOjSqAkA7YKZCgDvw50K","pt":1657539847514,"mc":[{"id":"1.200806927","rc":[{"atl":[[1.16,469.18]],"trd":[[1.16,2717.89]],"tv":21781.44,"id":228749}],"tv":23381.85}]}
{"op":"mcm","clk":"APrSqAkA9IKZCgD4w50K","pt":1657539847705,"mc":[{"id":"1.200806927","rc":[{"atl":[[1.16,468.98]],"trd":[[1.16,2718.3]],"tv":21781.85,"id":228749}],"tv":23382.26}]}
{"op":"mcm","clk":"AIfTqAkAgYOZCgCDxJ0K","pt":1657539847921,"mc":[{"id":"1.200806927","rc":[{"atl":[[1.16,468.19]],"trd":[[1.16,2719.87]],"tv":21783.42,"id":228749}],"tv":23383.83}]}
{"op":"mcm","clk":"AKDTqAkAnoOZCgCaxJ0K","pt":1657539848232,"mc":[{"id":"1.200806927","rc":[{"atl":[[1.17,997.29]],"id":228749}]}]}
{"op":"mcm","clk":"ALbTqAkAsoOZCgCoxJ0K","pt":1657539848493,"mc":[{"id":"1.200806927","rc":[{"atl":[[1.16,468.72]],"id":228749}]}]}
{"op":"mcm","clk":"ANDTqAkAxIOZCgC9xJ0K","pt":1657539848802,"mc":[{"id":"1.200806927","rc":[{"atl":[[1.16,442.42]],"trd":[[1.16,2772.47]],"tv":21836.02,"id":228749}],"tv":23436.43}]}
{"op":"mcm","clk":"ANfTqAkAzoOZCgDGxJ0K","pt":1657539848908,"mc":[{"id":"1.200806927","rc":[{"atb":[[1.14,103.69]],"id":228749}]}]}
{"op":"mcm","clk":"AP3TqAkA7YOZCgDoxJ0K","pt":1657539849495,"mc":[{"id":"1.200806927","rc":[{"atl":[[1.16,441.11]],"trd":[[1.16,2775.09]],"tv":21838.64,"id":228749}],"tv":23439.05}]}
{"op":"mcm","clk":"AJfUqAkAgoSZCgD4xJ0K","pt":1657539849810,"mc":[{"id":"1.200806927","rc":[{"atl":[[1.16,438.44]],"trd":[[1.16,2777.77]],"tv":21841.32,"id":228749},{"trd":[[7.2,424.6]],"tv":1600.84,"id":2857977}],"tv":23442.16}]}
{"op":"mcm","clk":"AKvUqAkAk4SZCgCHxZ0K","pt":1657539850101,"mc":[{"id":"1.200806927","rc":[{"atl":[[1.16,385.85]],"trd":[[1.16,2882.95]],"tv":21946.5,"id":228749}],"tv":23547.34}]}
{"op":"mcm","clk":"AMjUqAkAs4SZCgCZxZ0K","pt":1657539850513,"mc":[{"id":"1.200806927","rc":[{"atl":[[8,5.77]],"id":2857977}]}]}
{"op":"mcm","clk":"AIzVqAkA/4SZCgC9xZ0K","pt":1657539851426,"mc":[{"id":"1.200806927","rc":[{"atl":[[1.16,343.77]],"trd":[[1.16,2967.11]],"tv":22030.66,"id":228749}],"tv":23631.5}]}
{"op":"mcm","clk":"AJPVqAkAioWZCgDBxZ0K","pt":1657539851520,"mc":[{"id":"1.200806927","rc":[{"atb":[[1.15,5.89]],"id":228749}]}]}
{"op":"mcm","clk":"AMrVqAkAvYWZCgDtxZ0K","pt":1657539852218,"mc":[{"id":"1.200806927","rc":[{"atb":[[1.11,845.67]],"id":228749}]}]}
{"op":"mcm","clk":"ANLVqAkAxYWZCgDvxZ0K","pt":1657539852310,"mc":[{"id":"1.200806927","rc":[{"atl":[[1.16,342.77]],"trd":[[1.16,2969.11]],"tv":22032.66,"id":228749}],"tv":23633.5}]}
{"op":"mcm","clk":"ANrVqAkAzYWZCgD5xZ0K","pt":1657539852408,"mc":[{"id":"1.200806927","rc":[{"atl":[[1.16,336.88]],"trd":[[1.16,2975]],"tv":22038.55,"id":228749},{"trd":[[7.2,425.55]],"tv":1601.79,"id":2857977}],"tv":23640.34}]}
{"op":"mcm","clk":"AOLVqAkA04WZCgD6xZ0K","pt":1657539852526,"mc":[{"id":"1.200806927","rc":[{"atl":[[1.16,330.41]],"trd":[[1.16,2987.94]],"tv":22051.49,"id":228749}],"tv":23653.28}]}
{"op":"mcm","clk":"AJ/WqAkAnoaZCgDcxp0K","pt":1657539853405,"mc":[{"id":"1.200806927","rc":[{"atl":[[1.16,329.36]],"trd":[[1.16,2990.04]],"tv":22053.59,"id":228749}],"tv":23655.38}]}
{"op":"mcm","clk":"AKXWqAkAp4aZCgDixp0K","pt":1657539853503,"mc":[{"id":"1.200806927","rc":[{"atl":[[14.5,210.37]],"id":2857977}]}]}
{"op":"mcm","clk":"ALTWqAkAu4aZCgDqxp0K","pt":1657539853705,"mc":[{"id":"1.200806927","rc":[{"atl":[[1.16,539.73]],"id":228749}]}]}
{"op":"mcm","clk":"AKzXqAkAtoeZCgCwx50K","pt":1657539855219,"mc":[{"id":"1.200806927","rc":[{"atl":[[8,6.49]],"id":2857977}]}]}
{"op":"mcm","clk":"ALzXqAkAxoeZCgC4x50K","pt":1657539855417,"mc":[{"id":"1.200806927","rc":[{"atb":[[1.14,51.1],[1.15,0]],"atl":[[1.15,1400.99],[1.16,533.28]],"trd":[[1.16,3002.95],[1.15,1270.89]],"ltp":1.15,"tv":22089.92,"id":228749},{"atl":[[7.6,0]],"trd":[[7.6,28.41]],"ltp":7.6,"tv":1603.55,"id":2857977}],"tv":23693.47}]}
{"op":"mcm","clk":"ANvXqAkAhIiZCgDHx50K","pt":1657539856016,"mc":[{"id":"1.200806927","rc":[{"atl":[[1.15,1394.05]],"trd":[[1.15,1277.83]],"tv":22096.86,"id":228749},{"trd":[[7.6,29.46]],"tv":1604.6,"id":2857977}],"tv":23701.46}]}
{"op":"mcm","clk":"AObXqAkAkYiZCgDOx50K","pt":1657539856114,"mc":[{"id":"1.200806927","rc":[{"atl":[[1.15,3.35]],"trd":[[1.15,2668.96]],"tv":23487.99,"id":228749},{"trd":[[7.6,239.83]],"tv":1814.97,"id":2857977}],"tv":25302.96}]}
{"op":"mcm","clk":"AITYqAkAp4iZCgDhx50K","pt":1657539856422,"mc":[{"id":"1.200806927","rc":[{"atb":[[1.12,54.28]],"id":228749}]}]}
{"op":"mcm","clk":"AKHYqAkAwoiZCgDwx50K","pt":1657539856726,"mc":[{"id":"1.200806927","rc":[{"atl":[[1.15,1.57]],"trd":[[1.15,2672.54]],"tv":23491.57,"id":228749}],"tv":25306.54}]}
{"op":"mcm","clk":"AKzYqAkAxoiZCgD0x50K","pt":1657539856811,"mc":[{"id":"1.200806927","rc":[{"atl":[[1.15,0.52]],"trd":[[1.15,2674.64]],"tv":23493.67,"id":228749}],"tv":25308.64}]}
{"op":"mcm","clk":"ALXYqAkAzoiZCgD3x50K","pt":1657539856929,"mc":[{"id":"1.200806927","rc":[{"atl":[[1.16,530.14],[1.15,0]],"trd":[[1.15,2675.15],[1.16,3006.08]],"ltp":1.16,"tv":23497.31,"id":228749},{"trd":[[7.6,239.91],[7.2,426.06]],"ltp":7.2,"tv":1815.56,"id":2857977}],"tv":25312.87}]}
{"op":"mcm","clk":"AOHYqAkA9oiZCgCZyJ0K","pt":1657539857508,"mc":[{"id":"1.200806927","rc":[{"atl":[[1.16,528.56]],"trd":[[1.16,3009.24]],"tv":23500.47,"id":228749}],"tv":25316.03}]}
{"op":"mcm","clk":"AOrYqAkA/4iZCgCgyJ0K","pt":1657539857621,"mc":[{"id":"1.200806927","rc":[{"atl":[[14.5,0]],"id":2857977}]}]}
{"op":"mcm","clk":"AITZqAkAl4mZCgCsyJ0K","pt":1657539857926,"mc":[{"id":"1.200806927","rc":[{"atl":[[1.16,525.93]],"trd":[[1.16,3014.5]],"tv":23505.73,"id":228749}],"tv":25321.29}]}
{"op":"mcm","clk":"AJfZqAkApYmZCgC1yJ0K","pt":1657539858118,"mc":[{"id":"1.200806927","rc":[{"atl":[[1.16,523.3]],"trd":[[1.16,3019.76]],"tv":23510.99,"id":228749}],"tv":25326.55}]}
{"op":"mcm","clk":"AKvZqAkAsomZCgC8yJ0K","pt":1657539858337,"mc":[{"id":"1.200806927","rc":[{"atl":[[1.16,522.25]],"trd":[[1.16,3021.86]],"tv":23513.09,"id":228749}],"tv":25328.65}]}
{"op":"mcm","clk":"AM3ZqAkAz4mZCgDXyJ0K","pt":1657539858660,"mc":[{"id":"1.200806927","rc":[{"atl":[[1.16,518.62]],"trd":[[1.16,3029.12]],"tv":23520.35,"id":228749}],"tv":25335.91}]}
{"op":"mcm","clk":"ANzZqAkA54mZCgDlyJ0K","pt":1657539858841,"mc":[{"id":"1.200806927","rc":[{"atl":[[1.16,517.04]],"trd":[[1.16,3032.28]],"tv":23523.51,"id":228749}],"tv":25339.07}]}
{"op":"mcm","clk":"AILaqAkAkIqZCgD+yJ0K","pt":1657539859245,"mc":[{"id":"1.200806927","rc":[{"atl":[[1.16,490.74]],"trd":[[1.16,3084.88]],"tv":23576.11,"id":228749}],"tv":25391.67}]}
{"op":"mcm","clk":"ANjaqAkA1IqZCgDCyZ0K","pt":1657539860237,"mc":[{"id":"1.200806927","rc":[{"atl":[[1.16,489.69]],"trd":[[1.16,3086.98]],"tv":23578.21,"id":228749}],"tv":25393.77}]}
{"op":"mcm","clk":"AP3aqAkA9oqZCgDVyZ0K","pt":1657539860737,"mc":[{"id":"1.200806927","rc":[{"atl":[[7.6,0.1]],"id":2857977}]}]}
{"op":"mcm","clk":"AIzbqAkAhYuZCgDdyZ0K","pt":1657539860958,"mc":[{"id":"1.200806927","rc":[{"atb":[[1.14,50.99]],"atl":[[1.16,621.17]],"id":228749}]}]}
{"op":"mcm","clk":"AKzbqAkAsYuZCgDryZ0K","pt":1657539861342,"mc":[{"id":"1.200806927","rc":[{"atl":[[1.16,615.91]],"trd":[[1.16,3097.5]],"tv":23588.73,"id":228749}],"tv":25404.29}]}
{"op":"mcm","clk":"ALXbqAkAt4uZCgDvyZ0K","pt":1657539861427,"mc":[{"id":"1.200806927","rc":[{"atl":[[1.16,611.13]],"trd":[[1.16,3107.06]],"tv":23598.29,"id":228749}],"tv":25413.85}]}
{"op":"mcm","clk":"AL7bqAkAxYuZCgD0yZ0K","pt":1657539861528,"mc":[{"id":"1.200806927","rc":[{"atb":[[1.15,1.8]],"id":228749}]}]}
{"op":"mcm","clk":"AMXbqAkAzYuZCgD6yZ0K","pt":1657539861633,"mc":[{"id":"1.200806927","rc":[{"atl":[[7.6,0]],"id":2857977}]}]}
{"op":"mcm","clk":"AOPbqAkA7YuZCgCSyp0K","pt":1657539862019,"mc":[{"id":"1.200806927","rc":[{"atb":[[1.01,2978.1]],"id":228749}]}]}
{"op":"mcm","clk":"APTbqAkA+4uZCgCZyp0K","pt":1657539862220,"mc":[{"id":"1.200806927","rc":[{"atl":[[1.16,600.61]],"trd":[[1.16,3128.1]],"tv":23619.33,"id":228749}],"tv":25434.89}]}
{"op":"mcm","clk":"ANfcqAkA1YyZCgDayp0K","pt":1657539863343,"mc":[{"id":"1.200806927","rc":[{"atl":[[1.16,600.08]],"trd":[[1.16,3129.16]],"tv":23620.39,"id":228749}],"tv":25435.95}]}
{"op":"mcm","clk":"AO3cqAkA6IyZCgDiyp0K","pt":1657539863559,"mc":[{"id":"1.200806927","rc":[{"atl":[[1.16,598.5]],"trd":[[1.16,3132.33]],"tv":23623.56,"id":228749}],"tv":25439.12}]}
{"op":"mcm","clk":"APbcqAkA8oyZCgDoyp0K","pt":1657539863626,"mc":[{"id":"1.200806927","rc":[{"atl":[[1.16,593.13]],"trd":[[1.16,3143.07]],"tv":23634.3,"id":228749}],"tv":25449.86}]}
{"op":"mcm","clk":"AP7cqAkA+YyZCgDvyp0K","pt":1657539863729,"mc":[{"id":"1.200806927","rc":[{"atl":[[1.16,592.6]],"id":228749}]}]}
{"op":"mcm","clk":"AIjdqAkA/4yZCgD0yp0K","pt":1657539863833,"mc":[{"id":"1.200806927","rc":[{"atl":[[1.16,589.97]],"trd":[[1.16,3148.33]],"tv":23639.56,"id":228749}],"tv":25455.12}]}
{"op":"mcm","clk":"AL7dqAkAp42ZCgCVy50K","pt":1657539864339,"mc":[{"id":"1.200806927","rc":[{"atl":[[1.16,588.39]],"trd":[[1.16,3151.49]],"tv":23642.72,"id":228749}],"tv":25458.28}]}
{"op":"mcm","clk":"ANHdqAkAuY2ZCgCfy50K","pt":1657539864550,"mc":[{"id":"1.200806927","rc":[{"atl":[[1.16,581.25]],"trd":[[1.16,3158.62]],"tv":23649.85,"id":228749},{"trd":[[7.2,427.21]],"tv":1816.71,"id":2857977}],"tv":25466.56}]}
{"op":"mcm","clk":"AOXdqAkAyI2ZCgCsy50K","pt":1657539864734,"mc":[{"id":"1.200806927","rc":[{"atl":[[1.16,574.73]],"trd":[[1.16,3165.14]],"tv":23656.37,"id":228749},{"trd":[[7.2,428.26]],"tv":1817.76,"id":2857977}],"tv":25474.13}]}
{"op":"mcm","clk":"AMreqAkAno6ZCgDiy50K","pt":1657539865958,"mc":[{"id":"1.200806927","rc":[{"atl":[[1.16,0]],"trd":[[1.16,3739.87]],"tv":24231.1,"id":228749},{"atl":[[7.2,117.77]],"trd":[[7.2,520.86]],"tv":1910.36,"id":2857977}],"tv":26141.46}]}
{"op":"mcm","clk":"ANDeqAkAqI6ZCgDjy50K","pt":1657539866021,"mc":[{"id":"1.200806927","rc":[{"atb":[[1.16,2.63]],"id":228749}]}]}
{"op":"mcm","clk":"AOTeqAkAto6ZCgDty50K","pt":1657539866243,"mc":[{"id":"1.200806927","rc":[{"atb":[[1.16,18.41]],"id":228749}]}]}
{"op":"mcm","clk":"AOveqAkAvY6ZCgDyy50K","pt":1657539866332,"mc":[{"id":"1.200806927","rc":[{"atl":[[7.2,119.35]],"id":2857977}]}]}
{"op":"mcm","clk":"AIDfqAkA4o6ZCgCBzJ0K","pt":1657539866645,"mc":[{"id":"1.200806927","rc":[{"atb":[[1.14,51.52]],"id":228749}]}]}
{"op":"mcm","clk":"AMLfqAkArI+ZCgC7zJ0K","pt":1657539867552,"mc":[{"id":"1.200806927","rc":[{"atb":[[1.16,37.87]],"id":228749},{"atl":[[7.2,119.53]],"id":2857977}]}]}
{"op":"mcm","clk":"ALLgqAkAoJCZCgD/zJ0K","pt":1657539868946,"mc":[{"id":"1.200806927","rc":[{"atl":[[7.2,120.06]],"id":2857977}]}]}
{"op":"mcm","clk":"AL7gqAkArJCZCgCEzZ0K","pt":1657539869047,"mc":[{"id":"1.200806927","rc":[{"atb":[[1.16,0]],"trd":[[1.16,3807.18]],"tv":24298.41,"id":228749},{"atl":[[7.2,109.22]],"trd":[[7.2,531.7]],"tv":1921.2,"id":2857977}],"tv":26219.61}]}
{"op":"mcm","clk":"AMrhqAkA45CZCgCpzZ0K","pt":1657539869849,"mc":[{"id":"1.200806927","rc":[{"atl":[[7.2,110.27]],"id":2857977}]}]}
{"op":"mcm","clk":"ANPhqAkA6ZCZCgCuzZ0K","pt":1657539869940,"mc":[{"id":"1.200806927","rc":[{"atb":[[1.16,2.63]],"id":228749}]}]}
{"op":"mcm","clk":"AN/hqAkA8JCZCgC0zZ0K","pt":1657539870055,"mc":[{"id":"1.200806927","rc":[{"atb":[[1.14,0],[1.15,0],[1.16,0]],"atl":[[1.14,1436.08]],"trd":[[1.14,1201.53],[1.16,4496.85],[1.15,2678.75]],"ltp":1.14,"tv":25140.28,"id":228749},{"atl":[[7.2,0],[8,0]],"trd":[[7.2,641.96],[8,25.73]],"ltp":8,"tv":2037.95,"id":2857977}],"tv":27178.23}]}
{"op":"mcm","clk":"AP3hqAkAkpGZCgDKzZ0K","pt":1657539870360,"mc":[{"id":"1.200806927","rc":[{"atl":[[1.14,0]],"id":228749}]}]}
{"op":"mcm","clk":"AJ3iqAkAtJGZCgDlzZ0K","pt":1657539870743,"mc":[{"id":"1.200806927","rc":[{"atb":[[1.15,52.59]],"id":228749}]}]}
{"op":"mcm","clk":"AKziqAkAyJGZCgDtzZ0K","pt":1657539870941,"mc":[{"id":"1.200806927","rc":[{"atb":[[1.16,10.52]],"id":228749}]}]}
{"op":"mcm","clk":"AMbiqAkA35GZCgD4zZ0K","pt":1657539871250,"mc":[{"id":"1.200806927","rc":[{"atl":[[1.17,995.71]],"trd":[[1.17,3710.24]],"ltp":1.17,"tv":25143.44,"id":228749}],"tv":27181.39}]}
{"op":"mcm","clk":"ANniqAkA8ZGZCgCDzp0K","pt":1657539871450,"mc":[{"id":"1.200806927","rc":[{"atb":[[1.15,74.52]],"id":228749},{"atl":[[7.2,0.11]],"id":2857977}]}]}
{"op":"mcm","clk":"AOziqAkAhpKZCgCNzp0K","pt":1657539871656,"mc":[{"id":"1.200806927","rc":[{"atl":[[7.2,0.41]],"id":2857977}]}]}
{"op":"mcm","clk":"APbiqAkAkJKZCgCTzp0K","pt":1657539871767,"mc":[{"id":"1.200806927","rc":[{"atb":[[1.15,79.78]],"id":228749}]}]}
{"op":"mcm","clk":"AJjjqAkAtJKZCgCmzp0K","pt":1657539872141,"mc":[{"id":"1.200806927","rc":[{"atl":[[7.2,0.84]],"id":2857977}]}]}
{"op":"mcm","clk":"AKLjqAkAv5KZCgCuzp0K","pt":1657539872252,"mc":[{"id":"1.200806927","rc":[{"atl":[[1.18,0]],"id":228749}]}]}
{"op":"mcm","clk":"ALTjqAkA2JKZCgDAzp0K","pt":1657539872559,"mc":[{"id":"1.200806927","rc":[{"atb":[[1.16,11.38]],"id":228749}]}]}
{"op":"mcm","clk":"ANPjqAkA9JKZCgDNzp0K","pt":1657539872966,"mc":[{"id":"1.200806927","rc":[{"atb":[[1.16,21.9]],"id":228749}]}]}
{"op":"mcm","clk":"ANzkqAkAkpSZCgCvz50K","pt":1657539874760,"mc":[{"id":"1.200806927","rc":[{"atb":[[1.16,27.16]],"id":228749}]}]}
{"op":"mcm","clk":"APzkqAkAu5SZCgDCz50K","pt":1657539875170,"mc":[{"id":"1.200806927","rc":[{"atb":[[1.16,37.68]],"id":228749}]}]}
{"op":"mcm","clk":"AJflqAkA15SZCgDTz50K","pt":1657539875439,"mc":[{"id":"1.200806927","rc":[{"atb":[[1.16,40.31]],"id":228749},{"atl":[[8,0.1]],"id":2857977}]}]}
{"op":"mcm","clk":"ALDlqAkA+JSZCgDhz50K","pt":1657539875761,"mc":[{"id":"1.200806927","rc":[{"atl":[[8,0]],"id":2857977}]}]}
{"op":"mcm","clk":"AJzmqAkA9ZWZCgCy0J0K","pt":1657539877261,"mc":[{"id":"1.200806927","rc":[{"atb":[[1.15,0],[1.16,0]],"atl":[[1.14,80.42]],"trd":[[1.14,1202.93],[1.16,4503.77]],"ltp":1.14,"tv":25151.76,"id":228749},{"atl":[[7.2,0]],"trd":[[7.2,642.8],[8,25.93]],"tv":2038.99,"id":2857977}],"tv":27190.75}]}
{"op":"mcm","clk":"ANDmqAkArpaZCgDl0J0K","pt":1657539877943,"mc":[{"id":"1.200806927","rc":[{"atl":[[1.14,78.84]],"id":228749}]}]}
{"op":"mcm","clk":"APvmqAkA55aZCgCF0Z0K","pt":1657539878573,"mc":[{"id":"1.200806927","rc":[{"atl":[[1.16,2.25]],"id":228749}]}]}
{"op":"mcm","clk":"AIDnqAkA+JaZCgCI0Z0K","pt":1657539878679,"mc":[{"id":"1.200806927","rc":[{"atl":[[1.16,107.43]],"id":228749}]}]}
{"op":"mcm","clk":"AK7nqAkAxpeZCgC10Z0K","pt":1657539879452,"mc":[{"id":"1.200806927","rc":[{"atl":[[1.16,160.02]],"id":228749}]}]}
{"op":"mcm","clk":"AMbnqAkA8JeZCgDI0Z0K","pt":1657539879960,"mc":[{"id":"1.200806927","rc":[{"atl":[[1.16,493.02]],"id":228749}]}]}
{"op":"mcm","clk":"AL7oqAkAtJiZCgDo0Z0K","pt":1657539880671,"mc":[{"id":"1.200806927","rc":[{"atl":[[1.16,498.28]],"id":228749}]}]}
{"op":"mcm","clk":"AIvpqAkA+5iZCgCf0p0K","pt":1657539881590,"mc":[{"id":"1.200806927","rc":[{"atl":[[1.16,500.43]],"id":228749}]}]}
{"op":"mcm","clk":"AL3pqAkAqpmZCgDL0p0K","pt":1657539882170,"mc":[{"id":"1.200806927","rc":[{"atb":[[1.1,115.58]],"atl":[[1.14,78.09]],"trd":[[1.14,1203.68]],"tv":25152.51,"id":228749},{"trd":[[8,26.04]],"tv":2039.1,"id":2857977}],"tv":27191.61}]}
{"op":"mcm","clk":"APDpqAkA3pmZCgDv0p0K","pt":1657539882777,"mc":[{"id":"1.200806927","rc":[{"atl":[[1.16,500.96]],"id":228749}]}]}
{"op":"mcm","clk":"AJrqqAkAhpqZCgCL050K","pt":1657539883406,"mc":[{"id":"1.200806927","rc":[{"atl":[[1.14,74.74]],"trd":[[1.14,1208.79]],"tv":25157.62,"id":228749}],"tv":27196.72}]}
{"op":"mcm","clk":"ALnqqAkAsZqZCgCl050K","pt":1657539883774,"mc":[{"id":"1.200806927","rc":[{"atl":[[1.16,448.37]],"id":228749}]}]}
{"op":"mcm","clk":"AJrrqAkAlZuZCgDc050K","pt":1657539884986,"mc":[{"id":"1.200806927","rc":[{"atb":[[1.13,200]],"id":228749}]}]}
{"op":"mcm","clk":"ALnrqAkAvJuZCgD/050K","pt":1657539885384,"mc":[{"id":"1.200806927","rc":[{"atb":[[1.12,254.28]],"id":228749}]}]}
{"op":"mcm","clk":"ANvrqAkA35uZCgCZ1J0K","pt":1657539885770,"mc":[{"id":"1.200806927","rc":[{"atb":[[1.11,1045.67]],"atl":[[1.16,453.63]],"id":228749}]}]}
{"op":"mcm","clk":"AJXsqAkAnJyZCgDH1J0K","pt":1657539886481,"mc":[{"id":"1.200806927","rc":[{"atb":[[1.1,315.58]],"id":228749}]}]}
{"op":"mcm","clk":"AJ7sqAkAp5yZCgDM1J0K","pt":1657539886570,"mc":[{"id":"1.200806927","rc":[{"atl":[[1.14,72.11]],"id":228749}]}]}
{"op":"mcm","clk":"ALrsqAkAxZyZCgDk1J0K","pt":1657539887004,"mc":[{"id":"1.200806927","rc":[{"atb":[[1.09,311.11]],"id":228749}]}]}
{"op":"mcm","clk":"AMvsqAkA2JyZCgDy1J0K","pt":1657539887261,"mc":[{"id":"1.200806927","rc":[{"atl":[[1.14,0]],"trd":[[1.14,1280.9]],"tv":25229.73,"id":228749},{"atl":[[8,200.09]],"trd":[[8,36.32]],"tv":2049.38,"id":2857977}],"tv":27279.11}]}
{"op":"mcm","clk":"ANrsqAkA7ZyZCgD61J0K","pt":1657539887502,"mc":[{"id":"1.200806927","rc":[{"atl":[[1.16,454.16]],"id":228749}]}]}
{"op":"mcm","clk":"AODsqAkA+JyZCgD61J0K","pt":1657539887607,"mc":[{"id":"1.200806927","rc":[{"atb":[[1.14,8.61]],"id":228749}]}]}
{"op":"mcm","clk":"ALntqAkA7J2ZCgDD1Z0K","pt":1657539888906,"mc":[{"id":"1.200806927","rc":[{"atl":[[8,200.2]],"id":2857977}]}]}
{"op":"mcm","clk":"ANntqAkAkJ6ZCgDf1Z0K","pt":1657539889387,"mc":[{"id":"1.200806927","rc":[{"atb":[[1.14,9.19]],"id":228749}]}]}
{"op":"mcm","clk":"AOjtqAkAnZ6ZCgDo1Z0K","pt":1657539889597,"mc":[{"id":"1.200806927","rc":[{"atb":[[1.14,14.45]],"id":228749}]}]}
{"op":"mcm","clk":"APztqAkAsp6ZCgDw1Z0K","pt":1657539889900,"mc":[{"id":"1.200806927","rc":[{"atl":[[1.16,348.98]],"id":228749},{"atl":[[8,200.3]],"id":2857977}]}]}
{"op":"mcm","clk":"AILuqAkAup6ZCgD31Z0K","pt":1657539890021,"mc":[{"id":"1.200806927","rc":[{"atb":[[1.14,27.4]],"id":228749}]}]}
{"op":"mcm","clk":"AJfuqAkAzJ6ZCgCD1p0K","pt":1657539890311,"mc":[{"id":"1.200806927","rc":[{"atb":[[1.14,37.92]],"id":228749}]}]}
{"op":"mcm","clk":"AKjuqAkA456ZCgCO1p0K","pt":1657539890587,"mc":[{"id":"1.200806927","rc":[{"atl":[[8,200.83]],"id":2857977}]}]}
{"op":"mcm","clk":"ANzuqAkAiZ+ZCgDE1p0K","pt":1657539891223,"mc":[{"id":"1.200806927","rc":[{"atl":[[1.16,343.72]],"trd":[[1.16,4509.79]],"ltp":1.16,"tv":25235.75,"id":228749}],"tv":27285.13}]}
{"op":"mcm","clk":"AOTuqAkAkJ+ZCgDH1p0K","pt":1657539891326,"mc":[{"id":"1.200806927","rc":[{"atb":[[1.14,43.18]],"id":228749}]}]}
{"op":"mcm","clk":"AOzuqAkAlp+ZCgDO1p0K","pt":1657539891436,"mc":[{"id":"1.200806927","rc":[{"atb":[[1.14,44.23]],"id":228749}]}]}
{"op":"mcm","clk":"APzuqAkAqZ+ZCgDZ1p0K","pt":1657539891622,"mc":[{"id":"1.200806927","rc":[{"atb":[[1.14,54.75]],"id":228749}]}]}
{"op":"mcm","clk":"AKbvqAkAzZ+ZCgD21p0K","pt":1657539892109,"mc":[{"id":"1.200806927","rc":[{"atb":[[1.14,55.28]],"id":228749}]}]}
{"op":"mcm","clk":"AILwqAkAj6CZCgCo150K","pt":1657539893108,"mc":[{"id":"1.200806927","rc":[{"atl":[[8,201.73]],"id":2857977}]}]}
{"op":"mcm","clk":"AMzwqAkA1aCZCgDH150K","pt":1657539893893,"mc":[{"id":"1.200806927","rc":[{"atb":[[1.14,64.3]],"id":228749}]}]}
{"op":"mcm","clk":"APDwqAkA9qCZCgDb150K","pt":1657539894315,"mc":[{"id":"1.200806927","rc":[{"atl":[[8,201.95]],"id":2857977}]}]}
{"op":"mcm","clk":"AP3wqAkAgqGZCgDj150K","pt":1657539894520,"mc":[{"id":"1.200806927","rc":[{"atb":[[1.14,66.09]],"id":228749}]}]}
{"op":"mcm","clk":"AJfxqAkAlaGZCgD3150K","pt":1657539894817,"mc":[{"id":"1.200806927","rc":[{"atb":[[1.14,0]],"trd":[[1.14,1439.14]],"ltp":1.14,"tv":25393.99,"id":228749},{"atl":[[8,181.85]],"trd":[[8,56.42]],"tv":2069.48,"id":2857977}],"tv":27463.47}]}
{"op":"mcm","clk":"AJ/xqAkAn6GZCgD+150K","pt":1657539894915,"mc":[{"id":"1.200806927","rc":[{"atl":[[8,182.38]],"id":2857977}]}]}
{"op":"mcm","clk":"ANbxqAkAy6GZCgCZ2J0K","pt":1657539895618,"mc":[{"id":"1.200806927","rc":[{"atb":[[1.14,5.79]],"id":228749}],"con":true}]}
{"op":"mcm","clk":"ANbxqAkA0KGZCgCk2J0K","pt":1657539895629,"mc":[{"id":"1.200806927","rc":[{"atl":[[1.16,342.75]],"trd":[[1.16,4510.76]],"ltp":1.16,"tv":25394.96,"id":228749},{"trd":[[7.2,642.96]],"ltp":7.2,"tv":2069.64,"id":2857977}],"tv":27464.6}]}
{"op":"mcm","clk":"AOnxqAkA4KGZCgCr2J0K","pt":1657539895831,"mc":[{"id":"1.200806927","rc":[{"atb":[[1.14,6.32]],"id":228749}]}]}
{"op":"mcm","clk":"APLxqAkA5aGZCgCv2J0K","pt":1657539895910,"mc":[{"id":"1.200806927","rc":[{"atb":[[1.14,11.58]],"id":228749}]}]}
{"op":"mcm","clk":"APnxqAkA8aGZCgC02J0K","pt":1657539895992,"mc":[{"id":"1.200806927","rc":[{"atb":[[1.14,12.63]],"id":228749}]}]}
{"op":"mcm","clk":"AI3yqAkAiKKZCgDG2J0K","pt":1657539896293,"mc":[{"id":"1.200806927","rc":[{"atl":[[1.3,103.23]],"id":228749}]}]}
{"op":"mcm","clk":"AMzyqAkAtqKZCgDq2J0K","pt":1657539897029,"mc":[{"id":"1.200806927","rc":[{"atb":[[1.14,0]],"trd":[[1.14,1636.88]],"ltp":1.14,"tv":25592.7,"id":228749},{"atl":[[8,154.2]],"trd":[[8,84.6]],"ltp":8,"tv":2097.82,"id":2857977}],"tv":27690.52}]}
{"op":"mcm","clk":"AOnyqAkA2KKZCgCB2Z0K","pt":1657539897338,"mc":[{"id":"1.200806927","rc":[{"atb":[[1.1,315.05]],"id":228749}]}]}
{"op":"mcm","clk":"AIfzqAkA76KZCgCM2Z0K","pt":1657539897600,"mc":[{"id":"1.200806927","rc":[{"atl":[[1.16,337.49]],"id":228749}]}]}
{"op":"mcm","clk":"AI7zqAkA+KKZCgCQ2Z0K","pt":1657539897716,"mc":[{"id":"1.200806927","rc":[{"atb":[[1.14,5.26]],"id":228749},{"atl":[[8,154.3]],"id":2857977}]}]}
{"op":"mcm","clk":"ALPzqAkAlqOZCgCj2Z0K","pt":1657539898131,"mc":[{"id":"1.200806927","rc":[{"atb":[[1.14,0]],"trd":[[1.14,1684.21]],"tv":25640.03,"id":228749},{"atl":[[8,147.56]],"trd":[[8,91.34]],"tv":2104.56,"id":2857977}],"tv":27744.59}]}
{"op":"mcm","clk":"AMbzqAkAqaOZCgCq2Z0K","pt":1657539898291,"mc":[{"id":"1.200806927","rc":[{"atb":[[1.14,5.26]],"id":228749}]}]}
{"op":"mcm","clk":"AM/zqAkAsaOZCgCy2Z0K","pt":1657539898401,"mc":[{"id":"1.200806927","rc":[{"atb":[[1.14,7.89]],"id":228749}]}]}
{"op":"mcm","clk":"ANbzqAkAuKOZCgC42Z0K","pt":1657539898518,"mc":[{"id":"1.200806927","rc":[{"atl":[[1.32,5.26]],"id":228749}]}]}
{"op":"mcm","clk":"APLzqAkAzKOZCgDH2Z0K","pt":1657539898818,"mc":[{"id":"1.200806927","rc":[{"atl":[[8,147.35]],"id":2857977}]}]}
{"op":"mcm","clk":"AM70qAkApaSZCgCA2p0K","pt":1657539899716,"mc":[{"id":"1.200806927","rc":[{"atl":[[8,147.76]],"id":2857977}]}]}
{"op":"mcm","clk":"AJf1qAkA3qSZCgC02p0K","pt":1657539900516,"mc":[{"id":"1.200806927","rc":[{"atl":[[8,358.13]],"id":2857977}]}]}
{"op":"mcm","clk":"ALb1qAkA/aSZCgDG2p0K","pt":1657539900833,"mc":[{"id":"1.200806927","rc":[{"atb":[[1.14,14]],"id":228749}]}]}
{"op":"mcm","clk":"AL71qAkAiqWZCgDN2p0K","pt":1657539900939,"mc":[{"id":"1.200806927","rc":[{"atl":[[1.16,336.96]],"trd":[[1.16,4511.82]],"ltp":1.16,"tv":25641.09,"id":228749}],"tv":27745.65}]}
{"op":"mcm","clk":"AMn1qAkAkqWZCgDU2p0K","pt":1657539901005,"mc":[{"id":"1.200806927","rc":[{"atl":[[1.16,334.33]],"trd":[[1.16,4517.08]],"tv":25646.35,"id":228749}],"tv":27750.91}]}
{"op":"mcm","clk":"AO71qAkAyqWZCgDw2p0K","pt":1657539901320,"mc":[{"id":"1.200806927","rc":[{"atb":[[1.14,0]],"trd":[[1.14,2672.71]],"ltp":1.14,"tv":26634.85,"id":228749},{"atl":[[8,217.51]],"trd":[[8,231.96]],"tv":2245.18,"id":2857977}],"tv":28880.03}]}
{"op":"mcm","clk":"AKb2qAkA+qWZCgCK250K","pt":1657539901843,"mc":[{"id":"1.200806927","rc":[{"atl":[[1.16,333.54]],"trd":[[1.16,4518.66]],"ltp":1.16,"tv":26636.43,"id":228749}],"tv":28881.61}]}
{"op":"mcm","clk":"AKb3qAkA5qaZCgDI250K","pt":1657539903151,"mc":[{"id":"1.200806927","rc":[{"atb":[[1.15,5.26]],"id":228749}]}]}
{"op":"mcm","clk":"ANz3qAkAmaeZCgDw250K","pt":1657539903634,"mc":[{"id":"1.200806927","rc":[{"atl":[[1.16,438.72]],"id":228749}]}]}
{"op":"mcm","clk":"AOT3qAkApKeZCgD0250K","pt":1657539903738,"mc":[{"id":"1.200806927","rc":[{"atl":[[1.16,438.06]],"trd":[[1.16,4519.32]],"tv":26637.09,"id":228749},{"trd":[[7.2,643.06]],"ltp":7.2,"tv":2245.28,"id":2857977}],"tv":28882.37}]}
{"op":"mcm","clk":"AIP4qAkAxKeZCgCH3J0K","pt":1657539904012,"mc":[{"id":"1.200806927","rc":[{"atb":[[1.15,0]],"atl":[[1.15,205.11]],"id":228749}]}]}
{"op":"mcm","clk":"AJb4qAkA16eZCgCU3J0K","pt":1657539904214,"mc":[{"id":"1.200806927","rc":[{"atl":[[1.15,194.59]],"id":228749}]}]}
{"op":"mcm","clk":"AP34qAkAv6iZCgDL3J0K","pt":1657539905318,"mc":[{"id":"1.200806927","rc":[{"atl":[[8,217.62]],"id":2857977}]}]}
{"op":"mcm","clk":"AIT5qAkAyKiZCgDT3J0K","pt":1657539905413,"mc":[{"id":"1.200806927","rc":[{"atb":[[1.12,209.2]],"id":228749}]}]}
{"op":"mcm","clk":"AK35qAkA6KiZCgD03J0K","pt":1657539905929,"mc":[{"id":"1.200806927","rc":[{"atl":[[1.15,194.19]],"trd":[[1.15,2679.55]],"ltp":1.15,"tv":26637.89,"id":228749}],"tv":28883.17}]}
{"op":"mcm","clk":"AOz5qAkAqamZCgCt3Z0K","pt":1657539906722,"mc":[{"id":"1.200806927","rc":[{"atl":[[1.16,437.53]],"id":228749},{"atl":[[8,217.51]],"id":2857977}]}]}
{"op":"mcm","clk":"AJT6qAkAx6mZCgDV3Z0K","pt":1657539907156,"mc":[{"id":"1.200806927","rc":[{"atl":[[1.15,191.56]],"id":228749}]}]}
{"op":"mcm","clk":"AMP6qAkA/6mZCgD03Z0K","pt":1657539907739,"mc":[{"id":"1.200806927","rc":[{"atb":[[1.1,105.26]],"id":2857977}]}]}
{"op":"mcm","clk":"AOb6qAkAoqqZCgCL3p0K","pt":1657539908255,"mc":[{"id":"1.200806927","rc":[{"trd":[[1.14,2725.3]],"ltp":1.14,"tv":26690.48,"id":228749},{"atl":[[8,210.02]],"trd":[[8,239.45]],"ltp":8,"tv":2252.77,"id":2857977}],"tv":28943.25}]}
{"op":"mcm","clk":"AIv7qAkAxqqZCgCd3p0K","pt":1657539908636,"mc":[{"id":"1.200806927","rc":[{"atl":[[1.16,332.35]],"id":228749}]}]}
{"op":"mcm","clk":"AJ37qAkA1KqZCgCx3p0K","pt":1657539908849,"mc":[{"id":"1.200806927","rc":[{"trd":[[1.14,2932.41]],"tv":26897.59,"id":228749},{"atl":[[8,180.51]],"trd":[[8,268.96]],"tv":2282.28,"id":2857977}],"tv":29179.87}]}
{"op":"mcm","clk":"AMb7qAkA+KqZCgDL3p0K","pt":1657539909347,"mc":[{"id":"1.200806927","rc":[{"atl":[[1.15,188.93]],"id":228749}]}]}
{"op":"mcm","clk":"AIP8qAkAtquZCgD43p0K","pt":1657539910031,"mc":[{"id":"1.200806927","rc":[{"atb":[[7.4,5.26]],"id":2857977}]}]}
{"op":"mcm","clk":"AJf8qAkAyquZCgCB350K","pt":1657539910244,"mc":[{"id":"1.200806927","rc":[{"atl":[[1.16,0],[1.15,0]],"trd":[[1.15,2868.48],[1.16,4851.68]],"ltp":1.16,"tv":27418.88,"id":228749},{"atb":[[7.4,0]],"atl":[[7.2,122.97]],"trd":[[7.6,268.5],[7.2,696.61]],"ltp":7.2,"tv":2364.42,"id":2857977}],"tv":29783.3}]}
{"op":"mcm","clk":"AMb9qAkA4KyZCgDj350K","pt":1657539912048,"mc":[{"id":"1.200806927","rc":[{"atl":[[8,180.4]],"id":2857977}]}]}
{"op":"mcm","clk":"AM/9qAkA6KyZCgDo350K","pt":1657539912142,"mc":[{"id":"1.200806927","rc":[{"trd":[[1.14,4170.75],[1.16,5614.94]],"ltp":1.14,"tv":29420.48,"id":228749},{"atl":[[7.2,0],[8,3.94]],"trd":[[7.2,819.58],[8,445.42]],"ltp":8,"tv":2663.85,"id":2857977}],"tv":32084.33}]}
{"op":"mcm","clk":"APb9qAkAiq2ZCgCA4J0K","pt":1657539912552,"mc":[{"id":"1.200806927","rc":[{"atl":[[7.2,0.53]],"id":2857977}]}]}
{"op":"mcm","clk":"AJL+qAkApq2ZCgCK4J0K","pt":1657539912835,"mc":[{"id":"1.200806927","rc":[{"atb":[[1.16,0.53]],"id":228749}]}]}
{"op":"mcm","clk":"AK3+qAkAxK2ZCgCY4J0K","pt":1657539913154,"mc":[{"id":"1.200806927","rc":[{"atb":[[1.16,2.63]],"id":228749}]}]}
{"op":"mcm","clk":"AJ3/qAkAvK6ZCgDY4J0K","pt":1657539914460,"mc":[{"id":"1.200806927","rc":[{"atb":[[1.16,0]],"trd":[[1.14,4173.44],[1.16,5623.49]],"tv":29431.72,"id":228749},{"atl":[[7.2,0],[8,3.56]],"trd":[[7.2,820.11],[8,445.8]],"tv":2664.76,"id":2857977}],"tv":32096.48}]}
{"op":"mcm","clk":"AJCAqQkAoK+ZCgCZ4Z0K","pt":1657539915734,"mc":[{"id":"1.200806927","rc":[{"atl":[[1.14,75.02]],"trd":[[1.14,4198.42]],"tv":29456.7,"id":228749},{"atl":[[8,0]],"trd":[[8,449.36]],"tv":2668.32,"id":2857977}],"tv":32125.02}]}
{"op":"mcm","clk":"ALaAqQkAwa+ZCgCz4Z0K","pt":1657539916158,"mc":[{"id":"1.200806927","rc":[{"atl":[[1.14,67.72]],"trd":[[1.14,4205.72]],"tv":29464,"id":228749},{"trd":[[8,450.4]],"tv":2669.36,"id":2857977}],"tv":32133.36}]}
{"op":"mcm","clk":"AIKBqQkA+6+ZCgDT4Z0K","pt":1657539916851,"mc":[{"id":"1.200806927","rc":[{"atl":[[1.14,65.93]],"trd":[[1.14,4209.3]],"tv":29467.58,"id":228749}],"tv":32136.94}]}
{"op":"mcm","clk":"AJ6BqQkAkLCZCgDi4Z0K","pt":1657539917142,"mc":[{"id":"1.200806927","rc":[{"atl":[[1.14,39.63]],"trd":[[1.14,4261.9]],"tv":29520.18,"id":228749}],"tv":32189.54}]}
{"op":"mcm","clk":"AMuBqQkAvbCZCgD84Z0K","pt":1657539917625,"mc":[{"id":"1.200806927","rc":[{"atl":[[1.14,37]],"trd":[[1.14,4267.16]],"tv":29525.44,"id":228749}],"tv":32194.8}]}
{"op":"mcm","clk":"ALaCqQkApbGZCgC94p0K","pt":1657539918743,"mc":[{"id":"1.200806927","rc":[{"atl":[[1.14,25.91]],"trd":[[1.14,4278.25]],"tv":29536.53,"id":228749},{"trd":[[8,451.98]],"tv":2670.94,"id":2857977}],"tv":32207.47}]}
{"op":"mcm","clk":"AMCCqQkAtLGZCgDD4p0K","pt":1657539918842,"mc":[{"id":"1.200806927","rc":[{"atl":[[1.14,23.28]],"trd":[[1.14,4283.51]],"tv":29541.79,"id":228749}],"tv":32212.73}]}
{"op":"mcm","clk":"AKmDqQkA/7GZCgD04p0K","pt":1657539919732,"mc":[{"id":"1.200806927","rc":[{"atl":[[1.14,67.14]],"id":228749}]}]}
{"op":"mcm","clk":"APiDqQkAvLKZCgCt450K","pt":1657539920556,"mc":[{"id":"1.200806927","rc":[{"atl":[[1.14,188.86]],"trd":[[1.14,4319.56]],"tv":29577.84,"id":228749},{"trd":[[8,457.12]],"tv":2676.08,"id":2857977}],"tv":32253.92}]}
{"op":"mcm","clk":"AMCEqQkAgbOZCgDX450K","pt":1657539921267,"mc":[{"id":"1.200806927","rc":[{"atl":[[1.14,189.91]],"id":228749}]}]}
{"op":"mcm","clk":"AN2EqQkAoLOZCgDj450K","pt":1657539921527,"mc":[{"id":"1.200806927","rc":[{"atl":[[1.14,397.02]],"id":228749}]}]}
{"op":"mcm","clk":"AIOFqQkAyrOZCgCE5J0K","pt":1657539921946,"mc":[{"id":"1.200806927","rc":[{"atl":[[1.15,210.37]],"id":228749}]}]}
{"op":"mcm","clk":"AK6FqQkA7rOZCgCm5J0K","pt":1657539922365,"mc":[{"id":"1.200806927","rc":[{"atb":[[1.01,2767.73]],"id":2857977}]}]}
{"op":"mcm","clk":"AOWFqQkAo7SZCgDM5J0K","pt":1657539922850,"mc":[{"id":"1.200806927","rc":[{"atl":[[1.16,0.53]],"id":228749}]}]}
{"op":"mcm","clk":"AJeGqQkAy7SZCgDn5J0K","pt":1657539923258,"mc":[{"id":"1.200806927","rc":[{"atl":[[1.14,395.47]],"id":228749}]}]}
{"op":"mcm","clk":"AJ6GqQkA07SZCgDt5J0K","pt":1657539923361,"mc":[{"id":"1.200806927","rc":[{"atl":[[1.14,389.16]],"id":228749}]}]}
{"op":"mcm","clk":"AN+GqQkAjLWZCgCO5Z0K","pt":1657539923949,"mc":[{"id":"1.200806927","rc":[{"atl":[[1.14,388.41]],"trd":[[1.14,4320.31]],"tv":29578.59,"id":228749},{"trd":[[8,457.23]],"tv":2676.19,"id":2857977}],"tv":32254.78}]}
{"op":"mcm","clk":"AOuGqQkAlLWZCgCV5Z0K","pt":1657539924053,"mc":[{"id":"1.200806927","rc":[{"atl":[[1.16,16.31]],"id":228749}]}]}
{"op":"mcm","clk":"AIqHqQkAqrWZCgCq5Z0K","pt":1657539924354,"mc":[{"id":"1.200806927","rc":[{"atl":[[1.14,387.66]],"trd":[[1.14,4321.06]],"tv":29579.34,"id":228749},{"trd":[[8,457.33]],"tv":2676.29,"id":2857977}],"tv":32255.63}]}
{"op":"mcm","clk":"ANuHqQkA7bWZCgDd5Z0K","pt":1657539925162,"mc":[{"id":"1.200806927","rc":[{"atl":[[1.14,377.14]],"id":228749}]}]}
{"op":"mcm","clk":"AK6IqQkAv7aZCgCV5p0K","pt":1657539926054,"mc":[{"id":"1.200806927","rc":[{"atl":[[1.14,0]],"trd":[[1.14,4698.2]],"tv":29956.48,"id":228749},{"atl":[[8,156.63]],"trd":[[8,511.07]],"tv":2730.03,"id":2857977}],"tv":32686.51}]}
{"op":"mcm","clk":"AP6IqQkAjbeZCgDM5p0K","pt":1657539926854,"mc":[{"id":"1.200806927","rc":[{"atl":[[1.15,207.74]],"id":228749}]}]}
{"op":"mcm","clk":"AKqJqQkAr7eZCgDg5p0K","pt":1657539927276,"mc":[{"id":"1.200806927","rc":[{"atb":[[1.14,26.3]],"id":228749}]}]}
{"op":"mcm","clk":"ALqJqQkAureZCgDk5p0K","pt":1657539927385,"mc":[{"id":"1.200806927","rc":[{"atb":[[1.14,285.99]],"id":228749}]}]}
{"op":"mcm","clk":"AMGJqQkAxLeZCgDq5p0K","pt":1657539927473,"mc":[{"id":"1.200806927","rc":[{"atb":[[1.14,307.03]],"id":228749}]}]}
{"op":"mcm","clk":"AJCKqQkAnLiZCgCj550K","pt":1657539928368,"mc":[{"id":"1.200806927","rc":[{"atb":[[1.14,309.66]],"atl":[[1.15,203.44]],"trd":[[1.15,2877.09]],"ltp":1.15,"tv":29965.09,"id":228749}],"tv":32695.12}]}
{"op":"mcm","clk":"AKuKqQkAsbiZCgC0550K","pt":1657539928589,"mc":[{"id":"1.200806927","rc":[{"atb":[[1.14,320.18]],"id":228749}]}]}
{"op":"mcm","clk":"ALuKqQkAwLiZCgDB550K","pt":1657539928772,"mc":[{"id":"1.200806927","rc":[{"atb":[[1.14,325.44]],"id":228749}]}]}
{"op":"mcm","clk":"AMSKqQkAzbiZCgDE550K","pt":1657539928851,"mc":[{"id":"1.200806927","rc":[{"atb":[[1.14,328.07]],"id":228749},{"atl":[[8,157.68]],"id":2857977}]}]}
{"op":"mcm","clk":"AOqKqQkA9biZCgDi550K","pt":1657539929293,"mc":[{"id":"1.200806927","rc":[{"atb":[[1.14,330.7]],"id":228749}]}]}
{"op":"mcm","clk":"AKeLqQkAsLmZCgCD6J0K","pt":1657539929960,"mc":[{"id":"1.200806927","rc":[{"atl":[[8,158.72]],"id":2857977}]}]}
{"op":"mcm","clk":"ALKLqQkAuLmZCgCH6J0K","pt":1657539930054,"mc":[{"id":"1.200806927","rc":[{"atl":[[8,159.62]],"id":2857977}]}]}
{"op":"mcm","clk":"ALqLqQkAwbmZCgCO6J0K","pt":1657539930180,"mc":[{"id":"1.200806927","rc":[{"atb":[[1.14,332.7]],"id":228749}]}]}
{"op":"mcm","clk":"AOGLqQkA7LmZCgCd6J0K","pt":1657539930580,"mc":[{"id":"1.200806927","rc":[{"atl":[[8,160.15]],"id":2857977}]}]}
{"op":"mcm","clk":"APOLqQkA/LmZCgCq6J0K","pt":1657539930806,"mc":[{"id":"1.200806927","rc":[{"atb":[[1.14,330.7]],"id":228749}]}]}
{"op":"mcm","clk":"AIaMqQkAlLqZCgCz6J0K","pt":1657539930962,"mc":[{"id":"1.200806927","rc":[{"atl":[[1.15,177.01]],"trd":[[1.15,2903.52]],"tv":29991.52,"id":228749},{"trd":[[7.6,272.5]],"ltp":7.6,"tv":2734.03,"id":2857977}],"tv":32725.55}]}
{"op":"mcm","clk":"AJiMqQkAqrqZCgDA6J0K","pt":1657539931167,"mc":[{"id":"1.200806927","rc":[{"atb":[[1.14,333.33]],"id":228749}]}]}
{"op":"mcm","clk":"AK6MqQkAvLqZCgDM6J0K","pt":1657539931361,"mc":[{"id":"1.200806927","rc":[{"atb":[[1.14,334.01]],"id":228749}]}]}
{"op":"mcm","clk":"ALqMqQkAyLqZCgDS6J0K","pt":1657539931472,"mc":[{"id":"1.200806927","rc":[{"atl":[[8,160.79]],"id":2857977}]}]}
{"op":"mcm","clk":"AOuMqQkA97qZCgD96J0K","pt":1657539932060,"mc":[{"id":"1.200806927","rc":[{"atb":[[1.14,339.27]],"id":228749}]}]}
{"op":"mcm","clk":"APyMqQkAiruZCgCQ6Z0K","pt":1657539932266,"mc":[{"id":"1.200806927","rc":[{"atb":[[1.13,410.32]],"id":228749}]}]}
{"op":"mcm","clk":"AJqNqQkApruZCgCd6Z0K","pt":1657539932574,"mc":[{"id":"1.200806927","rc":[{"atb":[[1.14,341.9]],"id":228749}]}]}
{"op":"mcm","clk":"ALaNqQkAwbuZCgCw6Z0K","pt":1657539932870,"mc":[{"id":"1.200806927","rc":[{"atb":[[1.14,345.06]],"id":228749}]}]}
{"op":"mcm","clk":"ANCNqQkA3buZCgDE6Z0K","pt":1657539933173,"mc":[{"id":"1.200806927","rc":[{"atl":[[1.15,175.96]],"id":228749}]}]}
{"op":"mcm","clk":"AJCOqQkAkLyZCgDj6Z0K","pt":1657539933767,"mc":[{"id":"1.200806927","rc":[{"atb":[[1.14,348.22]],"id":228749}]}]}
{"op":"mcm","clk":"ALiOqQkAwbyZCgCE6p0K","pt":1657539934278,"mc":[{"id":"1.200806927","rc":[{"atb":[[1.14,399.59]],"id":228749}]}]}
{"op":"mcm","clk":"AM+OqQkA37yZCgCX6p0K","pt":1657539934568,"mc":[{"id":"1.200806927","rc":[{"atb":[[1.14,412.54]],"id":228749}]}]}
{"op":"mcm","clk":"AO6OqQkA9ryZCgCr6p0K","pt":1657539934887,"mc":[{"id":"1.200806927","rc":[{"atl":[[8.6,5.26]],"id":2857977}]}]}
{"op":"mcm","clk":"AJWPqQkAqr2ZCgDP6p0K","pt":1657539935467,"mc":[{"id":"1.200806927","rc":[{"atb":[[1.14,415.17]],"id":228749}]}]}
{"op":"mcm","clk":"ANOPqQkA6r2ZCgD16p0K","pt":1657539936178,"mc":[{"id":"1.200806927","rc":[{"atb":[[1.14,417.32]],"id":228749}]}]}
{"op":"mcm","clk":"AOiPqQkAhr6ZCgCD650K","pt":1657539936452,"mc":[{"id":"1.200806927","rc":[{"atb":[[1.14,417.85]],"id":228749}]}]}
{"op":"mcm","clk":"APqPqQkAnL6ZCgCN650K","pt":1657539936665,"mc":[{"id":"1.200806927","rc":[{"atb":[[1.14,210.74]],"trd":[[1.14,5059.82]],"ltp":1.14,"tv":30353.14,"id":228749}],"tv":33087.17}]}
{"op":"mcm","clk":"AJyQqQkAub6ZCgCk650K","pt":1657539936987,"mc":[{"id":"1.200806927","rc":[{"atb":[[1.14,213.37]],"id":228749}]}]}
{"op":"mcm","clk":"AK2QqQkA0L6ZCgCu650K","pt":1657539937180,"mc":[{"id":"1.200806927","rc":[{"atb":[[1.14,213.9]],"id":228749}]}]}
{"op":"mcm","clk":"APeQqQkAmr+ZCgDk650K","pt":1657539937984,"mc":[{"id":"1.200806927","rc":[{"atl":[[1.16,18.46]],"id":228749}]}]}
{"op":"mcm","clk":"AJGRqQkAtb+ZCgDy650K","pt":1657539938290,"mc":[{"id":"1.200806927","rc":[{"atl":[[8,159.74]],"id":2857977}]}]}
{"op":"mcm","clk":"AKeRqQkAxb+ZCgD9650K","pt":1657539938551,"mc":[{"id":"1.200806927","rc":[{"atb":[[1.14,213.22]],"id":228749}]}]}
{"op":"mcm","clk":"ALGRqQkAzb+ZCgCE7J0K","pt":1657539938700,"mc":[{"id":"1.200806927","rc":[{"atb":[[1.14,200.27]],"id":228749}]}]}
{"op":"mcm","clk":"ALuRqQkA1r+ZCgCI7J0K","pt":1657539938771,"mc":[{"id":"1.200806927","rc":[{"atl":[[8,370.11]],"id":2857977}]}]}
{"op":"mcm","clk":"AIOSqQkAksCZCgC67J0K","pt":1657539939594,"mc":[{"id":"1.200806927","rc":[{"atl":[[1.15,18.19]],"id":228749}]}]}
{"op":"mcm","clk":"ALuSqQkAt8CZCgDj7J0K","pt":1657539940169,"mc":[{"id":"1.200806927","rc":[{"atl":[[1.15,16.6]],"trd":[[1.15,2905.11]],"ltp":1.15,"tv":30354.73,"id":228749},{"trd":[[7.6,272.74]],"tv":2734.27,"id":2857977}],"tv":33089}]}
{"op":"mcm","clk":"ANmSqQkAzsCZCgD37J0K","pt":1657539940481,"mc":[{"id":"1.200806927","rc":[{"atb":[[1.14,204.58]],"id":228749}]}]}
{"op":"mcm","clk":"AOOSqQkA1cCZCgCC7Z0K","pt":1657539940590,"mc":[{"id":"1.200806927","rc":[{"atb":[[1.14,204.05]],"id":228749}]}]}
{"op":"mcm","clk":"AKyTqQkAmsGZCgC17Z0K","pt":1657539941393,"mc":[{"id":"1.200806927","rc":[{"atl":[[1.15,226.97]],"id":228749}]}]}
{"op":"mcm","clk":"AOaTqQkAx8GZCgDS7Z0K","pt":1657539941997,"mc":[{"id":"1.200806927","rc":[{"atb":[[1.14,1.05]],"trd":[[1.14,6129.98]],"ltp":1.14,"tv":31424.89,"id":228749},{"atl":[[8,256.57]],"trd":[[8,624.61]],"ltp":8,"tv":2847.81,"id":2857977}],"tv":34272.7}]}
{"op":"mcm","clk":"AO+TqQkAzsGZCgDX7Z0K","pt":1657539942115,"mc":[{"id":"1.200806927","rc":[{"atl":[[1.15,226.57]],"trd":[[1.15,2905.91]],"ltp":1.15,"tv":31425.69,"id":228749}],"tv":34273.5}]}
{"op":"mcm","clk":"AJ2UqQkA+MGZCgDw7Z0K","pt":1657539942492,"mc":[{"id":"1.200806927","rc":[{"atl":[[1.15,191.81]],"trd":[[1.15,2940.67]],"tv":31460.45,"id":228749},{"atl":[[8,256.67]],"trd":[[7.6,278]],"ltp":7.6,"tv":2853.07,"id":2857977}],"tv":34313.52}]}
{"op":"mcm","clk":"AMuUqQkAp8KZCgCE7p0K","pt":1657539942998,"mc":[{"id":"1.200806927","rc":[{"atl":[[1.15,189.81]],"trd":[[1.15,2944.67]],"tv":31464.45,"id":228749}],"tv":34317.52}]}
{"op":"mcm","clk":"AImVqQkA5MKZCgCo7p0K","pt":1657539943658,"mc":[{"id":"1.200806927","rc":[{"atl":[[1.17,1032.52]],"id":228749}]}]}
{"op":"mcm","clk":"AMSVqQkAscOZCgDQ7p0K","pt":1657539944485,"mc":[{"id":"1.200806927","rc":[{"atl":[[1.15,187.71]],"id":228749}]}]}
{"op":"mcm","clk":"AOWVqQkAzsOZCgDn7p0K","pt":1657539944896,"mc":[{"id":"1.200806927","rc":[{"atl":[[1.15,183.22]],"trd":[[1.15,2949.16]],"tv":31468.94,"id":228749},{"trd":[[7.6,278.68]],"tv":2853.75,"id":2857977}],"tv":34322.69}]}
{"op":"mcm","clk":"AI2WqQkAhMSZCgD97p0K","pt":1657539945483,"mc":[{"id":"1.200806927","rc":[{"atl":[[1.16,16.31]],"id":228749}]}]}
{"op":"mcm","clk":"AKuWqQkAnsSZCgCM750K","pt":1657539945798,"mc":[{"id":"1.200806927","rc":[{"atb":[[1.14,0]],"trd":[[1.14,6140.56]],"ltp":1.14,"tv":31479.52,"id":228749},{"atl":[[8,255.16]],"trd":[[8,626.12]],"ltp":8,"tv":2855.26,"id":2857977}],"tv":34334.78}]}
{"op":"mcm","clk":"ALmWqQkAr8SZCgCV750K","pt":1657539945982,"mc":[{"id":"1.200806927","rc":[{"atl":[[1.16,0.53]],"id":228749},{"atl":[[8,257.31]],"id":2857977}]}]}
{"op":"mcm","clk":"AIiXqQkA98SZCgC5750K","pt":1657539946794,"mc":[{"id":"1.200806927","rc":[{"atl":[[8,257.49]],"id":2857977}]}]}
{"op":"mcm","clk":"ALCXqQkApMWZCgDN750K","pt":1657539947196,"mc":[{"id":"1.200806927","rc":[{"atl":[[1.15,180.59]],"id":228749}]}]}
{"op":"mcm","clk":"AIWYqQkAmsaZCgCP8J0K","pt":1657539948393,"mc":[{"id":"1.200806927","rc":[{"atl":[[8,256.59]],"id":2857977}]}]}
{"op":"mcm","clk":"AMKZqQkA/MeZCgCJ8Z0K","pt":1657539950701,"mc":[{"id":"1.200806927","rc":[{"atb":[[1.14,1.89]],"id":228749}]}]}
{"op":"mcm","clk":"AM2ZqQkAi8iZCgCL8Z0K","pt":1657539950813,"mc":[{"id":"1.200806927","rc":[{"atl":[[1.16,0]],"id":228749}]}]}
{"op":"mcm","clk":"AOqZqQkAqsiZCgCX8Z0K","pt":1657539951079,"mc":[{"id":"1.200806927","rc":[{"atb":[[1.14,0]],"trd":[[1.14,6296.44]],"tv":31635.4,"id":228749},{"atl":[[8,234.38]],"trd":[[8,648.33]],"tv":2877.47,"id":2857977}],"tv":34512.87}]}
{"op":"mcm","clk":"AI6aqQkAz8iZCgCk8Z0K","pt":1657539951483,"mc":[{"id":"1.200806927","rc":[{"atl":[[1.15,170.07]],"id":228749}]}]}
{"op":"mcm","clk":"AJeaqQkA18iZCgCp8Z0K","pt":1657539951601,"mc":[{"id":"1.200806927","rc":[{"atl":[[1.15,167.54]],"trd":[[1.15,2953.16]],"ltp":1.15,"tv":31639.4,"id":228749}],"tv":34516.87}]}
{"op":"mcm","clk":"AKqaqQkA6ciZCgC58Z0K","pt":1657539951794,"mc":[{"id":"1.200806927","rc":[{"atl":[[1.15,163.65]],"id":228749}]}]}
{"op":"mcm","clk":"AN6aqQkAq8mZCgDg8Z0K","pt":1657539952494,"mc":[{"id":"1.200806927","rc":[{"atl":[[8,444.75]],"id":2857977}]}]}
{"op":"mcm","clk":"AO2aqQkAv8mZCgDs8Z0K","pt":1657539952691,"mc":[{"id":"1.200806927","rc":[{"trd":[[1.14,6301.7]],"ltp":1.14,"tv":31644.66,"id":228749},{"atl":[[8,444]],"trd":[[8,649.08]],"tv":2878.22,"id":2857977}],"tv":34522.88}]}
{"op":"mcm","clk":"AIGbqQkA0MmZCgD/8Z0K","pt":1657539952907,"mc":[{"id":"1.200806927","rc":[{"atl":[[1.15,152.43]],"trd":[[1.15,2953.86]],"ltp":1.15,"tv":31645.36,"id":228749},{"trd":[[7.6,278.78]],"ltp":7.6,"tv":2878.32,"id":2857977}],"tv":34523.68}]}
{"op":"mcm","clk":"AJubqQkA7smZCgCW8p0K","pt":1657539953229,"mc":[{"id":"1.200806927","rc":[{"atl":[[1.15,145.49]],"trd":[[1.15,2960.8]],"tv":31652.3,"id":228749},{"trd":[[7.6,279.83]],"tv":2879.37,"id":2857977}],"tv":34531.67}]}
{"op":"mcm","clk":"AMubqQkAscqZCgCu8p0K","pt":1657539953730,"mc":[{"id":"1.200806927","rc":[{"atl":[[1.15,142.17]],"id":228749}]}]}
{"op":"mcm","clk":"ANObqQkAv8qZCgCw8p0K","pt":1657539953788,"mc":[{"id":"1.200806927","rc":[{"atl":[[1.15,141.64]],"trd":[[1.14,6342.77]],"ltp":1.14,"tv":31693.37,"id":228749},{"atl":[[8,438.15]],"trd":[[8,654.93]],"ltp":8,"tv":2885.22,"id":2857977}],"tv":34578.59}]}
{"op":"mcm","clk":"AKqcqQkAxcuZCgDg8p0K","pt":1657539954820,"mc":[{"id":"1.200806927","rc":[{"trd":[[1.14,6343.07]],"tv":31693.67,"id":228749},{"atl":[[8,438.11]],"trd":[[8,654.97]],"tv":2885.26,"id":2857977}],"tv":34578.93}]}
{"op":"mcm","clk":"ALacqQkA0MuZCgDk8p0K","pt":1657539954927,"mc":[{"id":"1.200806927","rc":[{"atb":[[1.04,2.05],[1.05,129.27],[1.07,4.4],[1.08,338.27],[1.1,215.05],[1.09,200],[1.06,253.7],[1.02,99.78],[1.03,66.85],[1.01,1978.1]],"id":228749},{"atb":[[1.04,2.05],[1.05,100],[1.07,4.4],[1.08,0],[1.1,5.26],[1.09,0],[1.06,0],[1.02,99.78],[1.03,66.85],[1.01,1767.73]],"id":2857977}]}]}
{"op":"mcm","clk":"AL+cqQkA6cuZCgDt8p0K","pt":1657539955103,"mc":[{"id":"1.200806927","rc":[{"atl":[[1.15,120.6]],"id":228749}]}]}
{"op":"mcm","clk":"APacqQkAocyZCgCR850K","pt":1657539955696,"mc":[{"id":"1.200806927","rc":[{"trd":[[1.14,6365]],"tv":31715.6,"id":228749},{"atl":[[8,434.98]],"trd":[[8,658.1]],"tv":2888.39,"id":2857977}],"tv":34603.99}]}
{"op":"mcm","clk":"AI+dqQkAvsyZCgCk850K","pt":1657539956004,"mc":[{"id":"1.200806927","rc":[{"atb":[[1.15,772.01]],"atl":[[1.15,0]],"id":228749}]}]}
{"op":"mcm","clk":"AJOdqQkAzsyZCgCn850K","pt":1657539956113,"mc":[{"id":"1.200806927","rc":[{"atb":[[1.15,784.96]],"id":228749}]}]}
{"op":"mcm","clk":"AJqdqQkA2syZCgCt850K","pt":1657539956219,"mc":[{"id":"1.200806927","rc":[{"atb":[[1.15,795.48]],"id":228749}]}]}
{"op":"mcm","clk":"AJOeqQkAns2ZCgDR850K","pt":1657539956807,"mc":[{"id":"1.200806927","rc":[{"atb":[[1.15,0]],"trd":[[1.14,6570.32]],"tv":31920.92,"id":228749},{"atl":[[8,405.72]],"trd":[[8,687.36]],"tv":2917.65,"id":2857977}],"tv":34838.57}]}
{"op":"mcm","clk":"ANyeqQkA9s2ZCgCF9J0K","pt":1657539957623,"mc":[{"id":"1.200806927","rc":[{"atb":[[1.15,21.04]],"id":228749}]}]}
{"op":"mcm","clk":"AO6eqQkAks6ZCgCP9J0K","pt":1657539957834,"mc":[{"id":"1.200806927","rc":[{"atl":[[1.17,1036.82]],"id":228749}]}]}
{"op":"mcm","clk":"APaeqQkAnc6ZCgCQ9J0K","pt":1657539957916,"mc":[{"id":"1.200806927","rc":[{"atb":[[1.15,24.65]],"id":228749}]}]}
{"op":"mcm","clk":"AIafqQkAss6ZCgCf9J0K","pt":1657539958112,"mc":[{"id":"1.200806927","rc":[{"atb":[[1.15,27.16]],"id":228749}]}]}
{"op":"mcm","clk":"AJ2fqQkA1M6ZCgC99J0K","pt":1657539958417,"mc":[{"id":"1.200806927","rc":[{"atb":[[1.15,0]],"trd":[[1.14,7219.38],[1.15,2965.82]],"tv":32575,"id":228749},{"atl":[[8,313.23]],"trd":[[8,779.85]],"tv":3010.14,"id":2857977}],"tv":35585.14}]}
{"op":"mcm","clk":"AKefqQkA5s6ZCgDM9J0K","pt":1657539958620,"mc":[{"id":"1.200806927","rc":[{"atb":[[1.15,9.02]],"id":228749}]}]}
{"op":"mcm","clk":"ANmgqQkA48+ZCgCn9Z0K","pt":1657539959829,"mc":[{"id":"1.200806927","rc":[{"atb":[[1.15,0]],"trd":[[1.14,7226.14]],"tv":32581.76,"id":228749},{"atl":[[8,312.27]],"trd":[[8,780.81]],"tv":3011.1,"id":2857977}],"tv":35592.86}]}
{"op":"mcm","clk":"AOKhqQkAmNGZCgCq9p0K","pt":1657539961524,"mc":[{"id":"1.200806927","rc":[{"atl":[[7.6,0.53]],"id":2857977}]}]}
{"op":"mcm","clk":"AMGiqQkAmNKZCgDs9p0K","pt":1657539962743,"mc":[{"id":"1.200806927","rc":[{"trd":[[1.14,7487.81],[1.15,2969.32]],"tv":32846.93,"id":228749},{"atl":[[7.6,0],[8,274.98]],"trd":[[7.6,280.36],[8,818.1]],"tv":3048.92,"id":2857977}],"tv":35895.85}]}
{"op":"mcm","clk":"AOqiqQkA2NKZCgCC950K","pt":1657539963259,"mc":[{"id":"1.200806927","rc":[{"atb":[[1.15,1.58]],"id":228749},{"atl":[[8,274.81]],"id":2857977}]}]}
{"op":"mcm","clk":"AIWjqQkA+NKZCgCU950K","pt":1657539963553,"mc":[{"id":"1.200806927","rc":[{"atb":[[1.15,27.88]],"id":228749}]}]}
{"op":"mcm","clk":"AI6jqQkAh9OZCgCc950K","pt":1657539963665,"mc":[{"id":"1.200806927","rc":[{"atb":[[1.1,215.68]],"id":228749}]}]}
{"op":"mcm","clk":"ALejqQkAsNOZCgC3950K","pt":1657539964057,"mc":[{"id":"1.200806927","rc":[{"atb":[[1.14,52.59]],"id":228749}]}]}
{"op":"mcm","clk":"AMqjqQkA2tOZCgDN950K","pt":1657539964364,"mc":[{"id":"1.200806927","rc":[{"atb":[[1.15,1.58]],"atl":[[1.17,1032.52]],"id":228749}]}]}
{"op":"mcm","clk":"AIKkqQkAidSZCgDr950K","pt":1657539964869,"mc":[{"id":"1.200806927","rc":[{"atl":[[10,0.41],[8,272.66]],"id":2857977}]}]}
{"op":"mcm","clk":"AKukqQkAsdSZCgCE+J0K","pt":1657539965262,"mc":[{"id":"1.200806927","rc":[{"atb":[[1.15,4.21]],"id":228749}]}]}
{"op":"mcm","clk":"AMKkqQkA1dSZCgCX+J0K","pt":1657539965553,"mc":[{"id":"1.200806927","rc":[{"atl":[[1.16,10.52]],"id":228749}]}]}
{"op":"mcm","clk":"AKqlqQkA5NWZCgDd+J0K","pt":1657539966872,"mc":[{"id":"1.200806927","rc":[{"atb":[[1.14,34.03],[1.15,0]],"id":228749}]}]}
{"op":"mcm","clk":"AN+lqQkArNaZCgD3+J0K","pt":1657539967557,"mc":[{"id":"1.200806927","rc":[{"atb":[[1.15,52.59]],"id":228749}]}]}
{"op":"mcm","clk":"AP+lqQkA2NaZCgCQ+Z0K","pt":1657539967964,"mc":[{"id":"1.200806927","rc":[{"atb":[[1.15,152.59]],"id":228749}]}]}
{"op":"mcm","clk":"AKOmqQkAjteZCgCk+Z0K","pt":1657539968439,"mc":[{"id":"1.200806927","rc":[{"atb":[[1.15,151.01]],"id":228749}]}]}
{"op":"mcm","clk":"AL+mqQkAtdeZCgC2+Z0K","pt":1657539968853,"mc":[{"id":"1.200806927","rc":[{"atb":[[1.15,0]],"atl":[[1.15,1848.99]],"trd":[[1.15,3271.34]],"ltp":1.15,"tv":33148.95,"id":228749}],"tv":36197.87}]}
{"op":"mcm","clk":"ANWmqQkA29eZCgDR+Z0K","pt":1657539969151,"mc":[{"id":"1.200806927","rc":[{"atl":[[1.15,1846.89]],"trd":[[1.15,3275.54]],"tv":33153.15,"id":228749}],"tv":36202.07}]}
{"op":"mcm","clk":"AOOmqQkA8NeZCgDc+Z0K","pt":1657539969364,"mc":[{"id":"1.200806927","rc":[{"atb":[[1.12,211.83]],"id":228749}]}]}
{"op":"mcm","clk":"APKmqQkAidiZCgDu+Z0K","pt":1657539969644,"mc":[{"id":"1.200806927","rc":[{"atl":[[1.15,1820.59]],"trd":[[1.15,3328.14]],"tv":33205.75,"id":228749}],"tv":36254.67}]}
{"op":"mcm","clk":"AIqnqQkAn9iZCgD4+Z0K","pt":1657539969935,"mc":[{"id":"1.200806927","rc":[{"atb":[[1.13,410.43]],"id":228749}]}]}
{"op":"mcm","clk":"AJynqQkAs9iZCgCB+p0K","pt":1657539970139,"mc":[{"id":"1.200806927","rc":[{"atl":[[1.15,1817.96]],"trd":[[1.15,3333.4]],"tv":33211.01,"id":228749}],"tv":36259.93}]}
{"op":"mcm","clk":"AP6nqQkAsNmZCgDP+p0K","pt":1657539971455,"mc":[{"id":"1.200806927","rc":[{"atl":[[1.16,15.78]],"id":228749}]}]}
{"op":"mcm","clk":"AJ+oqQkA1dmZCgDj+p0K","pt":1657539971865,"mc":[{"id":"1.200806927","rc":[{"atl":[[8,483.03]],"id":2857977}]}]}
{"op":"mcm","clk":"AKWoqQkA4NmZCgDp+p0K","pt":1657539971972,"mc":[{"id":"1.200806927","rc":[{"atl":[[1.15,1828.48]],"id":228749}]}]}
{"op":"mcm","clk":"ALWoqQkA9NmZCgDy+p0K","pt":1657539972174,"mc":[{"id":"1.200806927","rc":[{"atl":[[1.15,1820.12]],"trd":[[1.15,3350.12]],"tv":33227.73,"id":228749}],"tv":36276.65}]}
{"op":"mcm","clk":"AMioqQkAltqZCgD/+p0K","pt":1657539972454,"mc":[{"id":"1.200806927","rc":[{"atl":[[8,482.92]],"id":2857977}]}]}
{"op":"mcm","clk":"AIOpqQkA5dqZCgCj+50K","pt":1657539973282,"mc":[{"id":"1.200806927","rc":[{"atl":[[11.5,5.14]],"id":2857977}]}]}
{"op":"mcm","clk":"AJipqQkA/NqZCgCr+50K","pt":1657539973455,"mc":[{"id":"1.200806927","rc":[{"atl":[[1.15,1767.53]],"trd":[[1.15,3455.3]],"tv":33332.91,"id":228749}],"tv":36381.83}]}
{"op":"mcm","clk":"ALipqQkApNuZCgC8+50K","pt":1657539973866,"mc":[{"id":"1.200806927","rc":[{"atl":[[1.15,1767]],"trd":[[1.15,3456.36]],"tv":33333.97,"id":228749}],"tv":36382.89}]}
{"op":"mcm","clk":"AKqqqQkAotyZCgCD/J0K","pt":1657539975170,"mc":[{"id":"1.200806927","rc":[{"atl":[[1.16,10.52]],"id":228749}]}]}
{"op":"mcm","clk":"AMaqqQkAvdyZCgCW/J0K","pt":1657539975467,"mc":[{"id":"1.200806927","rc":[{"atl":[[1.15,1788.93]],"id":228749}]}]}
{"op":"mcm","clk":"AM2qqQkAxtyZCgCZ/J0K","pt":1657539975577,"mc":[{"id":"1.200806927","rc":[{"atb":[[1.14,0]],"trd":[[1.14,7718.95]],"ltp":1.14,"tv":33565.11,"id":228749},{"atl":[[8,449.98]],"trd":[[8,851.04]],"tv":3081.86,"id":2857977}],"tv":36646.97}]}
{"op":"mcm","clk":"AOyqqQkA7tyZCgCq/J0K","pt":1657539976002,"mc":[{"id":"1.200806927","rc":[{"atl":[[1.29,210.65]],"id":228749}]}]}
{"op":"mcm","clk":"APiqqQkAgt2ZCgC1/J0K","pt":1657539976163,"mc":[{"id":"1.200806927","rc":[{"atl":[[1.15,1788.27]],"trd":[[1.15,3457.02]],"ltp":1.15,"tv":33565.77,"id":228749},{"trd":[[7.6,280.46]],"ltp":7.6,"tv":3081.96,"id":2857977}],"tv":36647.73}]}
{"op":"mcm","clk":"ANerqQkA/N2ZCgDm/J0K","pt":1657539977366,"mc":[{"id":"1.200806927","rc":[{"atl":[[1.16,14.82]],"id":228749}]}]}
{"op":"mcm","clk":"AOCrqQkAhd6ZCgDq/J0K","pt":1657539977464,"mc":[{"id":"1.200806927","rc":[{"atl":[[1.15,1787.61]],"trd":[[1.15,3457.68]],"tv":33566.43,"id":228749},{"trd":[[7.6,280.56]],"tv":3082.06,"id":2857977}],"tv":36648.49}]}
{"op":"mcm","clk":"AParqQkAm96ZCgD1/J0K","pt":1657539977667,"mc":[{"id":"1.200806927","rc":[{"atl":[[1.15,1786.51]],"trd":[[1.15,3459.88]],"tv":33568.63,"id":228749}],"tv":36650.69}]}
{"op":"mcm","clk":"AMOsqQkAhN+ZCgCu/Z0K","pt":1657539978600,"mc":[{"id":"1.200806927","rc":[{"atl":[[1.15,1785.85]],"trd":[[1.15,3460.54]],"tv":33569.29,"id":228749},{"trd":[[7.6,280.66]],"tv":3082.16,"id":2857977}],"tv":36651.45}]}
{"op":"mcm","clk":"AIGtqQkA0d+ZCgDX/Z0K","pt":1657539979278,"mc":[{"id":"1.200806927","rc":[{"atl":[[1.15,1783.22]],"trd":[[1.15,3465.8]],"tv":33574.55,"id":228749}],"tv":36656.71}]}
{"op":"mcm","clk":"AKGtqQkAguCZCgDr/Z0K","pt":1657539979697,"mc":[{"id":"1.200806927","rc":[{"atl":[[1.15,1779.33]],"trd":[[1.15,3473.58]],"tv":33582.33,"id":228749}],"tv":36664.49}]}
{"op":"mcm","clk":"ALmtqQkApeCZCgD8/Z0K","pt":1657539979986,"mc":[{"id":"1.200806927","rc":[{"atl":[[1.15,1778.67]],"trd":[[1.15,3474.24]],"tv":33582.99,"id":228749},{"trd":[[7.6,280.76]],"tv":3082.26,"id":2857977}],"tv":36665.25}]}
{"op":"mcm","clk":"AMutqQkAweCZCgCG/p0K","pt":1657539980163,"mc":[{"id":"1.200806927","rc":[{"atl":[[1.15,1777.53]],"trd":[[1.15,3475.38]],"tv":33584.13,"id":228749},{"trd":[[7.6,280.94]],"tv":3082.44,"id":2857977}],"tv":36666.57}]}
{"op":"mcm","clk":"ANetqQkAzuCZCgCL/p0K","pt":1657539980265,"mc":[{"id":"1.200806927","rc":[{"atl":[[1.3,129.12]],"id":228749}]}]}
{"op":"mcm","clk":"APGtqQkA8+CZCgCX/p0K","pt":1657539980581,"mc":[{"id":"1.200806927","rc":[{"atl":[[1.15,1776.87]],"trd":[[1.15,3476.04]],"tv":33584.79,"id":228749},{"trd":[[7.6,281.04]],"tv":3082.54,"id":2857977}],"tv":36667.33}]}
{"op":"mcm","clk":"APytqQkAiuGZCgCi/p0K","pt":1657539980786,"mc":[{"id":"1.200806927","rc":[{"atl":[[1.15,1774.24]],"trd":[[1.15,3481.3]],"tv":33590.05,"id":228749}],"tv":36672.59}]}
{"op":"mcm","clk":"AIquqQkAoOGZCgCt/p0K","pt":1657539980993,"mc":[{"id":"1.200806927","rc":[{"atl":[[1.15,1721.65]],"trd":[[1.15,3586.48]],"tv":33695.23,"id":228749}],"tv":36777.77}]}
{"op":"mcm","clk":"AKquqQkAz+GZCgDG/p0K","pt":1657539981374,"mc":[{"id":"1.200806927","rc":[{"atl":[[1.15,1721.12]],"trd":[[1.15,3587.54]],"tv":33696.29,"id":228749}],"tv":36778.83}]}
{"op":"mcm","clk":"ALmuqQkA3OGZCgDL/p0K","pt":1657539981486,"mc":[{"id":"1.200806927","rc":[{"atl":[[1.15,1720.42]],"trd":[[1.15,3588.24]],"tv":33696.99,"id":228749},{"trd":[[7.6,281.14]],"tv":3082.64,"id":2857977}],"tv":36779.63}]}
{"op":"mcm","clk":"ANeuqQkA++GZCgDX/p0K","pt":1657539981780,"mc":[{"id":"1.200806927","rc":[{"atl":[[1.15,1717.79]],"trd":[[1.15,3593.5]],"tv":33702.25,"id":228749}],"tv":36784.89}]}
{"op":"mcm","clk":"AP2uqQkAouKZCgDv/p0K","pt":1657539982165,"mc":[{"id":"1.200806927","rc":[{"atl":[[1.15,1715.16]],"trd":[[1.15,3598.76]],"tv":33707.51,"id":228749}],"tv":36790.15}]}
{"op":"mcm","clk":"AJCvqQkAvOKZCgD5/p0K","pt":1657539982372,"mc":[{"id":"1.200806927","rc":[{"atb":[[1.14,26.3]],"id":228749}]}]}
{"op":"mcm","clk":"AJivqQkAxuKZCgD+/p0K","pt":1657539982470,"mc":[{"id":"1.200806927","rc":[{"atl":[[1.15,1714.11]],"trd":[[1.15,3600.86]],"tv":33709.61,"id":228749}],"tv":36792.25}]}
{"op":"mcm","clk":"AKOvqQkA0+KZCgCD/50K","pt":1657539982566,"mc":[{"id":"1.200806927","rc":[{"atl":[[1.15,1712.79]],"trd":[[1.15,3602.18]],"tv":33710.93,"id":228749},{"trd":[[7.6,281.34]],"tv":3082.84,"id":2857977}],"tv":36793.77}]}
{"op":"mcm","clk":"AIuwqQkAyeOZCgDR/50K","pt":1657539983785,"mc":[{"id":"1.200806927","rc":[{"atl":[[1.15,1711.37]],"trd":[[1.15,3603.6]],"tv":33712.35,"id":228749},{"trd":[[7.6,281.56]],"tv":3083.06,"id":2857977}],"tv":36795.41}]}
{"op":"mcm","clk":"AJiwqQkA4eOZCgDe/50K","pt":1657539983988,"mc":[{"id":"1.200806927","rc":[{"atl":[[1.15,1709.12]],"trd":[[1.15,3608.1]],"tv":33716.85,"id":228749}],"tv":36799.91}]}
{"op":"mcm","clk":"AMqwqQkAmOSZCgCLgJ4K","pt":1657539984574,"mc":[{"id":"1.200806927","rc":[{"atl":[[1.15,1708.59]],"trd":[[1.15,3609.16]],"tv":33717.91,"id":228749}],"tv":36800.97}]}
{"op":"mcm","clk":"ANmwqQkAqeSZCgCXgJ4K","pt":1657539984767,"mc":[{"id":"1.200806927","rc":[{"atl":[[1000,0.34]],"id":228749}]}]}
{"op":"mcm","clk":"AOuwqQkAuuSZCgCngJ4K","pt":1657539984969,"mc":[{"id":"1.200806927","rc":[{"atl":[[1.15,1705.96]],"trd":[[1.15,3614.42]],"tv":33723.17,"id":228749}],"tv":36806.23}]}
{"op":"mcm","clk":"APmwqQkAz+SZCgCxgJ4K","pt":1657539985207,"mc":[{"id":"1.200806927","rc":[{"atl":[[1000,0.13],[1.15,1704.91]],"trd":[[1.15,3616.52]],"tv":33725.27,"id":228749}],"tv":36808.33}]}
{"op":"mcm","clk":"AP+wqQkA3OSZCgC6gJ4K","pt":1657539985284,"mc":[{"id":"1.200806927","rc":[{"atl":[[1.15,1701.62]],"trd":[[1.15,3622.44]],"tv":33731.19,"id":228749},{"trd":[[7.6,281.66]],"tv":3083.16,"id":2857977}],"tv":36814.35}]}
{"op":"mcm","clk":"AKGxqQkAhuWZCgDRgJ4K","pt":1657539985696,"mc":[{"id":"1.200806927","rc":[{"atb":[[1.14,0]],"trd":[[1.14,7899.76]],"ltp":1.14,"tv":33912,"id":228749},{"atl":[[8,424.21]],"trd":[[8,876.81]],"ltp":8,"tv":3108.93,"id":2857977}],"tv":37020.93}]}
{"op":"mcm","clk":"AIKyqQkA8+WZCgCegZ4K","pt":1657539986996,"mc":[{"id":"1.200806927","rc":[{"atl":[[1.15,1700.76]],"trd":[[1.15,3624.16]],"ltp":1.15,"tv":33913.72,"id":228749}],"tv":37022.65}]}
{"op":"mcm","clk":"AMeyqQkAyuaZCgDdgZ4K","pt":1657539987879,"mc":[{"id":"1.200806927","rc":[{"atl":[[1.15,32.45]],"id":228749}]}]}
{"op":"mcm","clk":"ANeyqQkA3OaZCgDpgZ4K","pt":1657539988086,"mc":[{"id":"1.200806927","rc":[{"atb":[[1.15,20.35]],"atl":[[1.15,0]],"id":228749}]}]}
{"op":"mcm","clk":"AN+yqQkA5+aZCgDvgZ4K","pt":1657539988198,"mc":[{"id":"1.200806927","rc":[{"atb":[[1.15,0]],"trd":[[1.14,8010.89]],"ltp":1.14,"tv":34024.85,"id":228749},{"atl":[[8,408.37]],"trd":[[8,892.65]],"tv":3124.77,"id":2857977}],"tv":37149.62}]}
{"op":"mcm","clk":"AOOyqQkA8uaZCgD3gZ4K","pt":1657539988301,"mc":[{"id":"1.200806927","rc":[{"atb":[[1.15,0.17]],"id":228749}]}]}
{"op":"mcm","clk":"AO2yqQkA+uaZCgD+gZ4K","pt":1657539988394,"mc":[{"id":"1.200806927","rc":[{"atl":[[7.6,0.53]],"id":2857977}]}]}
{"op":"mcm","clk":"AP6yqQkAi+eZCgCNgp4K","pt":1657539988572,"mc":[{"id":"1.200806927","rc":[{"atb":[[1.15,5.43]],"id":228749}]}]}
{"op":"mcm","clk":"AKyzqQkAxOeZCgDEgp4K","pt":1657539989180,"mc":[{"id":"1.200806927","rc":[{"atb":[[1.15,5.96]],"id":228749}]}]}
{"op":"mcm","clk":"ALmzqQkAzeeZCgDKgp4K","pt":1657539989292,"mc":[{"id":"1.200806927","rc":[{"atl":[[7.6,0.73]],"id":2857977}]}]}
{"op":"mcm","clk":"APuzqQkAsuiZCgD+gp4K","pt":1657539990295,"mc":[{"id":"1.200806927","rc":[{"atb":[[1.15,5.76]],"atl":[[1.16,12.49]],"trd":[[1.15,3624.57]],"ltp":1.15,"tv":34025.26,"id":228749}],"tv":37150.03}]}
{"op":"mcm","clk":"AIS0qQkAweiZCgCEg54K","pt":1657539990399,"mc":[{"id":"1.200806927","rc":[{"atl":[[7.6,0.53]],"id":2857977}]}]}
{"op":"mcm","clk":"AJm0qQkA4uiZCgCRg54K","pt":1657539990693,"mc":[{"id":"1.200806927","rc":[{"atb":[[1.15,0]],"trd":[[1.14,8266.8],[1.15,3628.07]],"ltp":1.14,"tv":34284.67,"id":228749},{"atl":[[7.6,0.11],[8,371.9]],"trd":[[7.6,282.19],[8,929.12]],"tv":3161.77,"id":2857977}],"tv":37446.44}]}
{"op":"mcm","clk":"AKC0qQkA7uiZCgCVg54K","pt":1657539990797,"mc":[{"id":"1.200806927","rc":[{"atl":[[7.6,0.64]],"id":2857977}]}]}
{"op":"mcm","clk":"AL+0qQkAlemZCgCog54K","pt":1657539991124,"mc":[{"id":"1.200806927","rc":[{"atl":[[7.6,1.07]],"id":2857977}]}]}
{"op":"mcm","clk":"APG0qQkA4emZCgDJg54K","pt":1657539991818,"mc":[{"id":"1.200806927","rc":[{"atl":[[7.6,0.97]],"id":2857977}]}]}
{"op":"mcm","clk":"APW0qQkA8OmZCgDRg54K","pt":1657539991888,"mc":[{"id":"1.200806927","rc":[{"atb":[[1.15,2.63]],"id":228749},{"atl":[[7.6,1.07]],"id":2857977}]}]}
{"op":"mcm","clk":"APy0qQkA/OmZCgDVg54K","pt":1657539991980,"mc":[{"id":"1.200806927","rc":[{"atl":[[7.6,1.17]],"id":2857977}]}]}
{"op":"mcm","clk":"AMG1qQkA5OqZCgD4g54K","pt":1657539992836,"mc":[{"id":"1.200806927","rc":[{"atb":[[1.15,5.26]],"id":228749}]}]}
{"op":"mcm","clk":"AMS1qQkA7eqZCgD+g54K","pt":1657539992880,"mc":[{"id":"1.200806927","rc":[{"atb":[[1.15,0]],"trd":[[1.14,8280.08],[1.15,3635.83]],"tv":34305.71,"id":228749},{"atl":[[7.6,0],[8,370.01]],"trd":[[7.6,283.36],[8,931.01]],"tv":3164.83,"id":2857977}],"tv":37470.54}]}
{"op":"mcm","clk":"AMy1qQkA++qZCgCChJ4K","pt":1657539993002,"mc":[{"id":"1.200806927","rc":[{"atl":[[1.16,1680.8]],"id":228749}]}]}
{"op":"mcm","clk":"APe1qQkAruuZCgCahJ4K","pt":1657539993494,"mc":[{"id":"1.200806927","rc":[{"atb":[[1.15,1.05]],"id":228749}]}]}
{"op":"mcm","clk":"AIC2qQkAuOuZCgCchJ4K","pt":1657539993587,"mc":[{"id":"1.200806927","rc":[{"atb":[[1.15,2.31]],"id":228749}]}]}
{"op":"mcm","clk":"ANK2qQkAhuyZCgC/hJ4K","pt":1657539994403,"mc":[{"id":"1.200806927","rc":[{"atl":[[7.6,0.11]],"id":2857977}]}]}
{"op":"mcm","clk":"ANe2qQkAk+yZCgDChJ4K","pt":1657539994489,"mc":[{"id":"1.200806927","rc":[{"atb":[[1.15,0]],"trd":[[1.14,8317.56],[1.15,3636.53]],"tv":34343.89,"id":228749},{"atl":[[7.6,0],[8,364.67]],"trd":[[7.6,283.47],[8,936.35]],"tv":3170.28,"id":2857977}],"tv":37514.17}]}
{"op":"mcm","clk":"AKS3qQkA+eyZCgD8hJ4K","pt":1657539995380,"mc":[{"id":"1.200806927","rc":[{"atl":[[7.6,0.11]],"id":2857977}]}]}
{"op":"mcm","clk":"AMC3qQkAoO2ZCgCVhZ4K","pt":1657539995697,"mc":[{"id":"1.200806927","rc":[{"atb":[[1.03,67.69]],"id":228749}]}]}
{"op":"mcm","clk":"AMq3qQkAue2ZCgCghZ4K","pt":1657539995884,"mc":[{"id":"1.200806927","rc":[{"atb":[[1.15,22.55]],"id":228749}]}]}
