{"op":"mcm","clk":"AOq7wRQA5papFACf7r4U","pt":1657018212979,"mc":[{"id":"1.200806927","marketDefinition":{"bspMarket":false,"turnInPlayEnabled":true,"persistenceEnabled":true,"marketBaseRate":5,"eventId":"31573045","eventTypeId":"4","numberOfWinners":1,"bettingType":"ODDS","marketType":"MATCH_ODDS","marketTime":"2022-07-11T11:00:00.000Z","suspendTime":"2022-07-11T11:00:00.000Z","bspReconciled":false,"complete":true,"inPlay":false,"crossMatching":true,"runnersVoidable":false,"numberOfActiveRunners":2,"betDelay":0,"status":"OPEN","runners":[{"status":"ACTIVE","sortPriority":1,"id":228749},{"status":"ACTIVE","sortPriority":2,"id":2857977}],"regulators":["MR_INT"],"countryCode":"GB","discountAllowed":false,"timezone":"GMT","openDate":"2022-07-11T11:00:00.000Z","version":4638141907,"priceLadderDefinition":{"type":"CLASSIC"}},"img":true}]}
{"op":"mcm","clk":"AIu8wRQAipepFAC/7r4U","pt":1657018213373,"mc":[{"id":"1.200806927","rc":[{"atb":[[1.01,20]],"id":228749},{"atb":[[1.01,20]],"id":2857977}]}]}
{"op":"mcm","clk":"AMm9wRQAgJmpFAD3774U","pt":1657018215951,"mc":[{"id":"1.200806927","marketDefinition":{"bspMarket":false,"turnInPlayEnabled":true,"persistenceEnabled":true,"marketBaseRate":5,"eventId":"31573045","eventTypeId":"4","numberOfWinners":1,"bettingType":"ODDS","marketType":"MATCH_ODDS","marketTime":"2022-07-11T11:00:00.000Z","suspendTime":"2022-07-11T11:00:00.000Z","bspReconciled":false,"complete":true,"inPlay":false,"crossMatching":true,"runnersVoidable":false,"numberOfActiveRunners":2,"betDelay":0,"status":"OPEN","runners":[{"status":"ACTIVE","sortPriority":1,"id":228749},{"status":"ACTIVE","sortPriority":2,"id":2857977}],"regulators":["MR_INT"],"countryCode":"GB","discountAllowed":true,"timezone":"GMT","openDate":"2022-07-11T11:00:00.000Z","version":4638141907,"priceLadderDefinition":{"type":"CLASSIC"}}}]}
{"op":"mcm","clk":"AM7ZwRQAmMOpFADTi78U","pt":1657018270321,"mc":[{"id":"1.200806927","rc":[{"atb":[[1.01,21.19]],"id":228749}]}]}
{"op":"mcm","clk":"AN7ZwRQAs8OpFADli78U","pt":1657018270633,"mc":[{"id":"1.200806927","rc":[{"atb":[[1.01,21.19]],"id":2857977}]}]}
{"op":"mcm","clk":"AOiVyBQAxISzFADzkMUU","pt":1657019743613,"mc":[{"id":"1.200806927","rc":[{"atb":[[1.01,227.81]],"id":228749}]}]}
{"op":"mcm","clk":"APyVyBQA24SzFACFkcUU","pt":1657019743775,"mc":[{"id":"1.200806927","rc":[{"atb":[[1.01,227.81]],"id":2857977}]}]}
{"op":"mcm","clk":"AKjd4BQAjojYFACajd4U","pt":1657025317885,"mc":[{"id":"1.200806927","rc":[{"atb":[[1.01,227.82]],"id":228749},{"atb":[[1.01,227.82]],"id":2857977}],"tv":0}]}
{"op":"mcm","clk":"AO3VhxUAmbuFFQCwx5AV","pt":1657036117351,"mc":[{"id":"1.200806927","rc":[{"atb":[[1.01,228.37]],"id":228749},{"atb":[[1.01,228.37]],"id":2857977}]}]}
{"op":"mcm","clk":"AI7GpBUAgJ2aFQDoiqwV","pt":1657041516608,"mc":[{"id":"1.200806927","rc":[{"atb":[[1.01,228.1]],"id":228749},{"atb":[[1.01,228.1]],"id":2857977}]}]}
{"op":"mcm","clk":"ANjJwxUAusG5FQCx9coV","pt":1657046917341,"mc":[{"id":"1.200806927","rc":[{"atb":[[1.01,228.21]],"id":228749},{"atb":[[1.01,228.21]],"id":2857977}]}]}
{"op":"mcm","clk":"AIqczBUAl8fDFQDaz9MV","pt":1657048520243,"mc":[{"id":"1.200806927","rc":[{"atb":[[1.02,1000],[1.01,228.24]],"id":228749},{"atb":[[1.01,228.24]],"id":2857977}]}]}
{"op":"mcm","clk":"ALihzBUA2M3DFQDu1NMV","pt":1657048527485,"mc":[{"id":"1.200806927","rc":[{"atb":[[1.02,1000]],"id":2857977}]}]}
{"op":"mcm","clk":"AISV4BUA/83VFQCQ6eUV","pt":1657052197679,"mc":[{"id":"1.200806927","rc":[{"atb":[[1.03,953.89],[1.01,228.21]],"id":228749},{"atb":[[1.01,228.21]],"id":2857977}]}]}
{"op":"mcm","clk":"AMWX4BUAjdDVFQDH6uUV","pt":1657052201643,"mc":[{"id":"1.200806927","rc":[{"atb":[[1.03,953.89]],"id":2857977}]}]}
{"op":"mcm","clk":"AJ+68xUAi7vfFQDw4vEV","pt":1657057717036,"mc":[{"id":"1.200806927","rc":[{"atb":[[1.03,953.73],[1.01,228.11]],"id":228749},{"atb":[[1.03,953.73],[1.01,228.11]],"id":2857977}]}]}
{"op":"mcm","clk":"APzq9xUAxdjgFQDjgPQV","pt":1657059069890,"mc":[{"id":"1.200806927","rc":[{"atb":[[1.03,0],[1.01,228.14]],"id":228749},{"atb":[[1.03,0],[1.01,228.14]],"id":2857977}]}]}
{"op":"mcm","clk":"ALe0hhYAp6LmFQDnsPoV","pt":1657063117008,"mc":[{"id":"1.200806927","rc":[{"atb":[[1.01,228.22]],"id":228749},{"atb":[[1.01,228.22]],"id":2857977}]}]}
{"op":"mcm","clk":"APHhlRYA89vvFQC3o4YW","pt":1657068517013,"mc":[{"id":"1.200806927","rc":[{"atb":[[1.01,228.09]],"id":228749},{"atb":[[1.01,228.09]],"id":2857977}]}]}
{"op":"mcm","clk":"ANGooRYAw7z5FQCUqpgW","pt":1657073917091,"mc":[{"id":"1.200806927","rc":[{"atb":[[1.01,227.98]],"id":228749},{"atb":[[1.01,227.98]],"id":2857977}]}]}
{"op":"mcm","clk":"AOKArRYA1aSAFgCL06UW","pt":1657079316391,"mc":[{"id":"1.200806927","rc":[{"atb":[[1.01,227.95]],"id":228749},{"atb":[[1.01,227.95]],"id":2857977}]}]}
{"op":"mcm","clk":"AIi0thYA8O+IFgC69q4W","pt":1657084717493,"mc":[{"id":"1.200806927","rc":[{"atb":[[1.01,228.02]],"id":228749},{"atb":[[1.01,228.02]],"id":2857977}]}]}
{"op":"mcm","clk":"AO/CwRYAnIySFgCUkbcW","pt":1657090117505,"mc":[{"id":"1.200806927","rc":[{"atb":[[1.01,228.19]],"id":228749},{"atb":[[1.01,228.19]],"id":2857977}]}]}
{"op":"mcm","clk":"AJ2HzhYAt76eFgCg28EW","pt":1657095517162,"mc":[{"id":"1.200806927","rc":[{"atb":[[1.01,228.28]],"id":228749},{"atb":[[1.01,228.28]],"id":2857977}]}]}
{"op":"mcm","clk":"AMr2hRcAw6jlFgCt1/kW","pt":1657106317763,"mc":[{"id":"1.200806927","rc":[{"atb":[[1.01,228.21]],"id":228749},{"atb":[[1.01,228.21]],"id":2857977}]}]}
{"op":"mcm","clk":"AKTyoxcArbGNFwCJvJgX","pt":1657111717329,"mc":[{"id":"1.200806927","rc":[{"atb":[[1.01,228.4]],"id":228749},{"atb":[[1.01,228.4]],"id":2857977}]}]}
{"op":"mcm","clk":"APyqthcAgbiiFwDG7KoX","pt":1657115679750,"mc":[{"id":"1.200806927","rc":[{"atb":[[1.03,4.46],[1.01,228.54]],"id":228749},{"atb":[[1.01,228.54]],"id":2857977}]}]}
{"op":"mcm","clk":"APmvthcA2ryiFwDQ8qoX","pt":1657115689292,"mc":[{"id":"1.200806927","rc":[{"atb":[[1.03,0]],"id":228749}]}]}
{"op":"mcm","clk":"APa9thcAiMiiFwD+gasX","pt":1657115713496,"mc":[{"id":"1.200806927","rc":[{"atb":[[1.05,4.46]],"id":228749}]}]}
{"op":"mcm","clk":"AK7JthcA+NGiFwDejasX","pt":1657115731180,"mc":[{"id":"1.200806927","rc":[{"atb":[[1.05,0]],"id":228749}]}]}
{"op":"mcm","clk":"AN3UthcA29yiFwCZm6sX","pt":1657115751908,"mc":[{"id":"1.200806927","rc":[{"atb":[[1.05,4.46]],"id":2857977}]}]}
{"op":"mcm","clk":"AOXmthcAze2iFwCcr6sX","pt":1657115784038,"mc":[{"id":"1.200806927","rc":[{"atb":[[1.05,0]],"id":2857977}]}]}
{"op":"mcm","clk":"AN7zthcA2PiiFwChvKsX","pt":1657115805902,"mc":[{"id":"1.200806927","rc":[{"atb":[[1.25,0.89]],"id":228749}]}]}
{"op":"mcm","clk":"AJyGtxcAuYmjFwDl0asX","pt":1657115839421,"mc":[{"id":"1.200806927","rc":[{"atb":[[1.25,0]],"id":228749}]}]}
{"op":"mcm","clk":"AISTtxcA9JSjFwCw36sX","pt":1657115862378,"mc":[{"id":"1.200806927","rc":[{"atl":[[1.8,0.22]],"id":228749}]}]}
{"op":"mcm","clk":"AKastxcAy6ujFwCz+KsX","pt":1657115905949,"mc":[{"id":"1.200806927","rc":[{"atl":[[1.8,0]],"id":228749}]}]}
{"op":"mcm","clk":"AJG0txcAwrOjFwD8gKwX","pt":1657115920647,"mc":[{"id":"1.200806927","rc":[{"atl":[[9,0.22]],"id":228749}]}]}
{"op":"mcm","clk":"ALPCtxcApcCjFwDGkKwX","pt":1657115945688,"mc":[{"id":"1.200806927","rc":[{"atb":[[9,0.61]],"atl":[[9,0]],"trd":[[9,0.45]],"ltp":9,"tv":0.45,"id":228749}],"tv":0.45}]}
{"op":"mcm","clk":"AKTLtxcAxcejFwDUmKwX","pt":1657115960001,"mc":[{"id":"1.200806927","rc":[{"atb":[[9,0]],"id":228749}]}]}
{"op":"mcm","clk":"AIHttxcAseSjFwDSt6wX","pt":1657116013852,"mc":[{"id":"1.200806927","rc":[{"atb":[[1.01,228.07]],"id":228749},{"atb":[[1.01,228.07]],"atl":[[9,1.34]],"id":2857977}]}]}
{"op":"mcm","clk":"AM6GuBcAjfujFwC2zawX","pt":1657116053388,"mc":[{"id":"1.200806927","rc":[{"atl":[[9,0]],"id":2857977}]}]}
{"op":"mcm","clk":"APKduBcAjpGkFwDN5KwX","pt":1657116091224,"mc":[{"id":"1.200806927","rc":[{"atl":[[9,0.16]],"id":2857977}]}]}
{"op":"mcm","clk":"AOWjuBcAlZekFwCI6qwX","pt":1657116101314,"mc":[{"id":"1.200806927","rc":[{"atl":[[9,0]],"id":2857977}]}]}
{"op":"mcm","clk":"AKSyuBcA86WkFwCT+KwX","pt":1657116125664,"mc":[{"id":"1.200806927","rc":[{"atl":[[9,1.34]],"id":2857977}]}]}
{"op":"mcm","clk":"AP27uBcA2LGkFwChgq0X","pt":1657116142114,"mc":[{"id":"1.200806927","rc":[{"atl":[[9,0]],"id":2857977}]}]}
{"op":"mcm","clk":"AITjuBcAstmkFwCRqa0X","pt":1657116206254,"mc":[{"id":"1.200806927","rc":[{"atb":[[1.05,11.14]],"id":228749}]}]}
{"op":"mcm","clk":"ANfouBcA+t6kFwC9rq0X","pt":1657116214789,"mc":[{"id":"1.200806927","rc":[{"atb":[[1.05,0]],"id":228749}]}]}
{"op":"mcm","clk":"AIn6uBcArPCkFwDJvq0X","pt":1657116244895,"mc":[{"id":"1.200806927","rc":[{"atb":[[1.35,4.46]],"id":228749}]}]}
{"op":"mcm","clk":"AOD/uBcApPWkFwCOw60X","pt":1657116252390,"mc":[{"id":"1.200806927","rc":[{"atb":[[1.35,0]],"id":228749}]}]}
{"op":"mcm","clk":"AICOuRcAsYOlFwCMz60X","pt":1657116275547,"mc":[{"id":"1.200806927","rc":[{"atl":[[9,0.22]],"id":2857977}]}]}
{"op":"mcm","clk":"AMquuRcAk6KlFwDq6q0X","pt":1657116327259,"mc":[{"id":"1.200806927","rc":[{"atb":[[9,0.61]],"atl":[[9,0]],"trd":[[9,0.45]],"ltp":9,"tv":0.45,"id":2857977}],"tv":0.9}]}
{"op":"mcm","clk":"AMe0uRcAr6ilFwCZ8K0X","pt":1657116337508,"mc":[{"id":"1.200806927","rc":[{"atb":[[9,0]],"id":2857977}]}]}
{"op":"mcm","clk":"AIzPuRcAtL6lFwDKg64X","pt":1657116376095,"mc":[{"id":"1.200806927","rc":[{"atl":[[9,0.45]],"id":228749}]}]}
{"op":"mcm","clk":"AJ7nuRcA69OlFwCela4X","pt":1657116411507,"mc":[{"id":"1.200806927","rc":[{"atb":[[9,0.39]],"atl":[[9,0]],"trd":[[9,1.34]],"tv":1.34,"id":228749}],"tv":1.79}]}
{"op":"mcm","clk":"AJntuRcAsNmlFwDfma4X","pt":1657116420095,"mc":[{"id":"1.200806927","rc":[{"atb":[[9,0]],"id":228749}]}]}
{"op":"mcm","clk":"ANqTuhcA2vmlFwDSt64X","pt":1657116475200,"mc":[{"id":"1.200806927","rc":[{"atl":[[9,0.45]],"id":2857977}]}]}
{"op":"mcm","clk":"AIuvuhcApJGmFwCHzq4X","pt":1657116513459,"mc":[{"id":"1.200806927","rc":[{"atb":[[9,0.39]],"atl":[[9,0]],"trd":[[9,1.34]],"tv":1.34,"id":2857977}],"tv":2.68}]}
{"op":"mcm","clk":"AI+xuhcA8pKmFwDSz64X","pt":1657116516315,"mc":[{"id":"1.200806927","rc":[{"atb":[[9,0]],"id":2857977}]}]}
{"op":"mcm","clk":"AIjLxBcAzJOxFwD1pbgX","pt":1657118637474,"mc":[{"id":"1.200806927","rc":[{"atb":[[1.03,3.11]],"id":2857977}]}]}
{"op":"mcm","clk":"AOjX2xcAi43JFwD56cUX","pt":1657122517982,"mc":[{"id":"1.200806927","rc":[{"atb":[[1.01,228.47]],"id":228749},{"atb":[[1.01,228.47]],"id":2857977}]}]}
{"op":"mcm","clk":"AIuW+RcA2/ryFwDWtN4X","pt":1657127917439,"mc":[{"id":"1.200806927","rc":[{"atb":[[1.01,227.93]],"id":228749},{"atb":[[1.01,227.93]],"id":2857977}]}]}
{"op":"mcm","clk":"AJ3xjhgAzZCaGACA8PwX","pt":1657133317539,"mc":[{"id":"1.200806927","rc":[{"atb":[[1.03,3.1]],"id":2857977}]}]}
{"op":"mcm","clk":"APuekxgApMmgGACN/IEY","pt":1657134342647,"mc":[{"id":"1.200806927","rc":[{"atb":[[1.01,228.12]],"id":228749},{"atb":[[1.03,2503.11],[1.01,228.12]],"id":2857977}]}]}
{"op":"mcm","clk":"AIKgkxgA3sqgGADB/YEY","pt":1657134344568,"mc":[{"id":"1.200806927","rc":[{"atb":[[1.03,2500]],"id":228749}]}]}
{"op":"mcm","clk":"AI/woxgAiaW8GADBoJIY","pt":1657138717100,"mc":[{"id":"1.200806927","rc":[{"atb":[[1.01,228.07]],"id":228749},{"atb":[[1.01,228.07]],"id":2857977}]}]}
{"op":"mcm","clk":"AKPmsBgA/YHNGACNkpgY","pt":1657144116704,"mc":[{"id":"1.200806927","rc":[{"atb":[[1.01,228.04]],"id":228749},{"atb":[[1.01,228.04]],"id":2857977}]}]}
{"op":"mcm","clk":"APSGBACPtwUAzY0C","pt":1657149516913,"mc":[{"id":"1.200806927","rc":[{"atb":[[1.01,228.06]],"id":228749},{"atb":[[1.01,228.06]],"id":2857977}]}]}
{"op":"mcm","clk":"ANC+DwCH8RkAk6YL","pt":1657154917553,"mc":[{"id":"1.200806927","rc":[{"atb":[[1.01,228.1]],"id":228749},{"atb":[[1.01,228.1]],"id":2857977}]}]}
{"op":"mcm","clk":"AOjcGQDHpy4Az5sV","pt":1657160316583,"mc":[{"id":"1.200806927","rc":[{"atb":[[1.01,228.08]],"id":228749},{"atb":[[1.01,228.08]],"id":2857977}]}]}
{"op":"mcm","clk":"ALn6HwDRujkA2Ooh","pt":1657165716568,"mc":[{"id":"1.200806927","rc":[{"atb":[[1.01,228.1]],"id":228749},{"atb":[[1.03,2503.1],[1.01,228.1]],"id":2857977}]}]}
{"op":"mcm","clk":"AJvTKQC97EEAvu4s","pt":1657171116514,"mc":[{"id":"1.200806927","rc":[{"atb":[[1.01,228.04]],"id":228749},{"atb":[[1.01,228.04]],"id":2857977}]}]}
{"op":"mcm","clk":"AP+YNQDx4kgA1oU5","pt":1657176517245,"mc":[{"id":"1.200806927","rc":[{"atb":[[1.01,228.17]],"id":228749},{"atb":[[1.01,228.17]],"id":2857977}]}]}
{"op":"mcm","clk":"AMO1OgC5p0wAsJs9","pt":1657178471572,"mc":[{"id":"1.200806927","rc":[{"atb":[[1.02,0],[1.01,228.02]],"id":228749},{"atb":[[1.01,228.02]],"id":2857977}]}]}
{"op":"mcm","clk":"AMq1OgC6p0wAs5s9","pt":1657178471678,"mc":[{"id":"1.200806927","rc":[{"atb":[[1.04,1000]],"id":228749}]}]}
{"op":"mcm","clk":"ANC3OgD8qEwAzpw9","pt":1657178477878,"mc":[{"id":"1.200806927","rc":[{"atb":[[1.02,0]],"id":2857977}]}]}
{"op":"mcm","clk":"ANO3OgD/qEwA0Jw9","pt":1657178477967,"mc":[{"id":"1.200806927","rc":[{"atb":[[1.04,1000]],"id":2857977}]}]}
{"op":"mcm","clk":"AJilRQCz0VQAxahE","pt":1657181916807,"mc":[{"id":"1.200806927","rc":[{"atb":[[1.01,227.84]],"id":228749},{"atb":[[1.01,227.84]],"id":2857977}]}]}
{"op":"mcm","clk":"AMaHWwDJ0GkAuJBS","pt":1657187317383,"mc":[{"id":"1.200806927","rc":[{"atb":[[1.01,227.49]],"id":228749},{"atb":[[1.01,227.49]],"id":2857977}]}]}
{"op":"mcm","clk":"AOGgdQC63IUBAJHwZg==","pt":1657192717538,"mc":[{"id":"1.200806927","rc":[{"atb":[[1.01,227.06]],"trd":[[9,1.33]],"tv":1.33,"id":228749},{"atb":[[1.03,2503.09],[1.01,227.06]],"trd":[[9,1.33]],"tv":1.33,"id":2857977}],"tv":2.66}]}
{"op":"mcm","clk":"AP/KjgEAyq2hAQCrkX4=","pt":1657198117490,"mc":[{"id":"1.200806927","rc":[{"atb":[[1.01,227.52]],"id":228749},{"atb":[[1.01,227.52]],"id":2857977}]}]}
{"op":"mcm","clk":"APOjlgEA2YmoAQDaiIYB","pt":1657199781769,"mc":[{"id":"1.200806927","rc":[{"atb":[[1.03,0],[1.01,227]],"id":228749},{"atb":[[1.03,3.09],[1.01,227]],"id":2857977}]}]}
{"op":"mcm","clk":"ANuqlgEA5ZCoAQDuj4YB","pt":1657199795678,"mc":[{"id":"1.200806927","rc":[{"atb":[[1.05,1500]],"id":2857977}]}]}
{"op":"mcm","clk":"AJ2rlgEArJGoAQC2kIYB","pt":1657199796792,"mc":[{"id":"1.200806927","rc":[{"atb":[[1.05,1500]],"id":228749}]}]}
{"op":"mcm","clk":"ANeepQEA+oW4AQC725YB","pt":1657203517479,"mc":[{"id":"1.200806927","rc":[{"atb":[[1.01,226.81]],"id":228749},{"atb":[[1.03,3.08],[1.01,226.81]],"id":2857977}]}]}
{"op":"mcm","clk":"AM6+uwEAl5DTAQC/hbUB","pt":1657208917554,"mc":[{"id":"1.200806927","rc":[{"atb":[[1.01,226.79]],"id":228749},{"atb":[[1.03,3.09],[1.01,226.79]],"id":2857977}]}]}
{"op":"mcm","clk":"APuW2gEA7MTyAQCj0OQB","pt":1657214317208,"mc":[{"id":"1.200806927","rc":[{"atb":[[1.01,226.27]],"id":228749},{"atb":[[1.03,3.08],[1.01,226.27]],"id":2857977}]}]}
{"op":"mcm","clk":"AJbB3QEAvrr3AQDCheoB","pt":1657214933672,"mc":[{"id":"1.200806927","rc":[{"atb":[[1.05,0]],"id":228749},{"atb":[[1.05,0]],"id":2857977}]}]}
{"op":"mcm","clk":"AO+xBgCsqgcAw5AI","pt":1657219716481,"mc":[{"id":"1.200806927","rc":[{"atb":[[1.01,226.37]],"id":228749},{"atb":[[1.01,226.37]],"id":2857977}]}]}
{"op":"mcm","clk":"APKRDwCekQ8AjKcT","pt":1657221462889,"mc":[{"id":"1.200806927","rc":[{"atb":[[1.01,226.31],[1.12,18.6]],"id":228749},{"atb":[[1.01,226.31]],"id":2857977}]}]}
{"op":"mcm","clk":"AJmSDwDCkQ8AsKcT","pt":1657221463299,"mc":[{"id":"1.200806927","rc":[{"atb":[[1.12,37.2]],"id":228749}]}]}
{"op":"mcm","clk":"AKaTDwDPkg8AzqgT","pt":1657221464777,"mc":[{"id":"1.200806927","rc":[{"atb":[[1.12,18.6]],"id":2857977}]}]}
{"op":"mcm","clk":"AMSTDwDwkg8A8agT","pt":1657221465085,"mc":[{"id":"1.200806927","rc":[{"atb":[[1.12,37.2]],"id":2857977}]}]}
{"op":"mcm","clk":"AO2VHwDtyRwAwegm","pt":1657225116770,"mc":[{"id":"1.200806927","rc":[{"atb":[[1.01,226.43],[1.12,37.19]],"id":228749},{"atb":[[1.01,226.43],[1.12,37.19]],"id":2857977}]}]}
{"op":"mcm","clk":"AKG1KQCaxiYA8tUz","pt":1657230516367,"mc":[{"id":"1.200806927","rc":[{"atb":[[1.01,226.44],[1.12,37.18]],"id":228749},{"atb":[[1.01,226.44],[1.12,37.18]],"id":2857977}]}]}
{"op":"mcm","clk":"AOXdKwC9jikAg9s2","pt":1657232099997,"mc":[{"id":"1.200806927","rc":[{"atb":[[1.01,226.57],[1.12,37.19]],"id":228749},{"atb":[[1.05,1000],[1.01,226.57],[1.12,37.19]],"id":2857977}]}]}
{"op":"mcm","clk":"AJreKwD0jikAvNs2","pt":1657232101717,"mc":[{"id":"1.200806927","rc":[{"atb":[[1.05,1000]],"id":228749}]}]}
{"op":"mcm","clk":"APnfKwDPkCkA6dw2","pt":1657232107591,"mc":[{"id":"1.200806927","rc":[{"atb":[[1.05,0]],"id":2857977}]}]}
{"op":"mcm","clk":"AJbgKwC2kSkAi902","pt":1657232108814,"mc":[{"id":"1.200806927","rc":[{"atb":[[1.13,384.62]],"id":2857977}]}]}
{"op":"mcm","clk":"APanLAC6zykAuNc3","pt":1657232399566,"mc":[{"id":"1.200806927","rc":[{"atb":[[1.14,9.45]],"id":2857977}]}]}
{"op":"mcm","clk":"AJCdMwDllTAAzOU+","pt":1657235916981,"mc":[{"id":"1.200806927","rc":[{"atb":[[1.01,226.53]],"id":228749},{"atb":[[1.01,226.53]],"id":2857977}]}]}
{"op":"mcm","clk":"AJavPgDLrTsAhIBO","pt":1657241316415,"mc":[{"id":"1.200806927","rc":[{"atb":[[1.01,226.67],[1.12,37.2]],"id":228749},{"atb":[[1.14,9.44],[1.01,226.67],[1.12,37.2]],"id":2857977}]}]}
{"op":"mcm","clk":"AOeXRwDaokYAg5Vj","pt":1657246716976,"mc":[{"id":"1.200806927","rc":[{"atb":[[1.01,226.62],[1.12,37.19]],"id":228749},{"atb":[[1.14,9.43],[1.01,226.62],[1.12,37.19]],"id":2857977}]}]}
{"op":"mcm","clk":"ALShTwDN0k8AmYhw","pt":1657252117227,"mc":[{"id":"1.200806927","rc":[{"atb":[[1.01,226.6],[1.12,37.17]],"id":228749},{"atb":[[1.14,9.44],[1.01,226.6],[1.12,37.17]],"id":2857977}]}]}
{"op":"mcm","clk":"AIHSVQDVklcAkrt9","pt":1657257516488,"mc":[{"id":"1.200806927","rc":[{"atb":[[1.01,226.65],[1.12,37.19]],"id":228749},{"atb":[[1.14,9.45],[1.01,226.65],[1.12,37.19]],"id":2857977}]}]}
{"op":"mcm","clk":"ANL+XQDf7F4A5NaPAQ==","pt":1657262917047,"mc":[{"id":"1.200806927","rc":[{"atb":[[1.01,226.74],[1.12,37.23]],"id":228749},{"atb":[[1.14,9.46],[1.01,226.74],[1.12,37.23]],"id":2857977}]}]}
{"op":"mcm","clk":"AOu8agDT62kAjeCkAQ==","pt":1657268316716,"mc":[{"id":"1.200806927","rc":[{"atb":[[1.01,226.64]],"trd":[[9,1.34]],"tv":1.34,"id":228749},{"atb":[[1.14,9.51],[1.03,3.1],[1.01,226.64]],"trd":[[9,1.34]],"tv":1.34,"id":2857977}],"tv":2.68}]}
{"op":"mcm","clk":"AK2IewCuw3oAjrXBAQ==","pt":1657273716553,"mc":[{"id":"1.200806927","rc":[{"atb":[[1.01,226.97],[1.12,37.28]],"id":228749},{"atb":[[1.14,9.52],[1.01,226.97],[1.12,37.28]],"id":2857977}]}]}
{"op":"mcm","clk":"AL21fwCz/n4An6nIAQ==","pt":1657274949900,"mc":[{"id":"1.200806927","rc":[{"atb":[[1.01,226.95],[1.12,37.27]],"id":228749},{"atb":[[1.13,0],[1.14,9.51],[1.01,226.95],[1.12,37.27]],"id":2857977}]}]}
{"op":"mcm","clk":"AIW3fwCLgH8A96vIAQ==","pt":1657274952984,"mc":[{"id":"1.200806927","rc":[{"atb":[[1.14,366.65]],"id":2857977}]}]}
{"op":"mcm","clk":"AJ7ckwEA84eQAQCSyt4B","pt":1657279117488,"mc":[{"id":"1.200806927","rc":[{"atb":[[1.01,226.6],[1.12,37.21]],"trd":[[9,1.33]],"tv":1.33,"id":228749},{"atb":[[1.14,366.62],[1.03,3.09],[1.01,226.6],[1.12,37.21]],"trd":[[9,1.33]],"tv":1.33,"id":2857977}],"tv":2.66}]}
{"op":"mcm","clk":"AMi6rwEAy8mqAQDilfsB","pt":1657284516703,"mc":[{"id":"1.200806927","rc":[{"atb":[[1.01,227.32],[1.12,37.23]],"id":228749},{"atb":[[1.14,366.61],[1.01,227.32],[1.12,37.23]],"id":2857977}]}]}
{"op":"mcm","clk":"AJa5xAEA8oO/AQDg9JkC","pt":1657289916951,"mc":[{"id":"1.200806927","rc":[{"atb":[[1.01,227.27],[1.12,37.24]],"id":228749},{"atb":[[1.14,366.62],[1.01,227.27],[1.12,37.24]],"id":2857977}]}]}
{"op":"mcm","clk":"APLn2gEA46bRAQCM1rYC","pt":1657295316836,"mc":[{"id":"1.200806927","rc":[{"atb":[[1.01,226.67],[1.12,37.23]],"id":228749},{"atb":[[1.14,366.59],[1.03,3.08],[1.01,226.67],[1.12,37.23]],"id":2857977}]}]}
{"op":"mcm","clk":"ALvU7QEAzMTcAQDGrMgC","pt":1657298514816,"mc":[{"id":"1.200806927","rc":[{"atb":[[1.01,226.61],[1.12,37.22]],"id":228749},{"atb":[[1.14,366.58],[1.01,226.61],[1.12,0]],"id":2857977}]}]}
{"op":"mcm","clk":"AMjU7QEA08TcAQDTrMgC","pt":1657298514918,"mc":[{"id":"1.200806927","rc":[{"atb":[[1.15,37.22]],"id":2857977}]}]}
{"op":"mcm","clk":"AKrV7QEAkcXcAQCorcgC","pt":1657298515949,"mc":[{"id":"1.200806927","rc":[{"atb":[[1.12,0]],"id":228749}]}]}
{"op":"mcm","clk":"AK/V7QEAmsXcAQCtrcgC","pt":1657298515999,"mc":[{"id":"1.200806927","rc":[{"atb":[[1.15,37.22]],"id":228749}]}]}
{"op":"mcm","clk":"ALDI9gEAxvnhAQDazc8C","pt":1657300026308,"mc":[{"id":"1.200806927","rc":[{"atb":[[1.05,0],[1.01,226.57]],"id":228749},{"atb":[[1.14,9.45],[1.01,226.57]],"id":2857977}]}]}
{"op":"mcm","clk":"AKfL+QEA0YfkAQD5+NEC","pt":1657300524249,"mc":[{"id":"1.200806927","rc":[{"atb":[[1.14,0]],"id":2857977}]}]}
{"op":"mcm","clk":"AJe/lAIA5ob9AQDT6+4C","pt":1657306116746,"mc":[{"id":"1.200806927","rc":[{"atb":[[1.15,37.21],[1.01,226.7]],"id":228749},{"atb":[[1.15,37.21],[1.01,226.7]],"id":2857977}]}]}
{"op":"mcm","clk":"AMq4qgIAwaKVAgCm84QD","pt":1657310886955,"mc":[{"id":"1.200806927","rc":[{"atb":[[1.01,226.59]],"id":228749},{"atb":[[1.16,312.5],[1.01,226.59]],"id":2857977}]}]}
{"op":"mcm","clk":"AKHAqgIAraqVAgDS94QD","pt":1657310900277,"mc":[{"id":"1.200806927","rc":[{"atb":[[1.05,1000]],"id":228749}]}]}
{"op":"mcm","clk":"AO7irAIAmb6YAgD/5oYD","pt":1657311517908,"mc":[{"id":"1.200806927","rc":[{"atb":[[1.15,37.22]],"id":228749},{"atb":[[1.15,37.22]],"id":2857977}]}]}
{"op":"mcm","clk":"AJWUsQIAhf+bAgCssYkD","pt":1657312664898,"mc":[{"id":"1.200806927","rc":[{"atb":[[1.17,10.46]],"id":2857977}]}]}
{"op":"mcm","clk":"AKC0uAIA7M6lAgC6pZYD","pt":1657316916980,"mc":[{"id":"1.200806927","rc":[{"atb":[[1.15,37.24],[1.01,226.7]],"id":228749},{"atb":[[1.17,10.45],[1.15,37.24],[1.01,226.7]],"id":2857977}]}]}
{"op":"mcm","clk":"AIi7xAIAgsGyAgC6r6wD","pt":1657322316594,"mc":[{"id":"1.200806927","rc":[{"atb":[[1.01,226.72]],"id":228749},{"atb":[[1.01,226.72]],"id":2857977}]}]}
{"op":"mcm","clk":"AM2ApAMA6YaeAwCOjKAE","pt":1657356968772,"mc":[{"id":"1.200806927","rc":[{"atb":[[1.05,0]],"id":228749},{"atb":[[1.16,0]],"id":2857977}]}]}
{"op":"mcm","clk":"AN2+pAMA58GeAwDDtaAE","pt":1657357060598,"mc":[{"id":"1.200806927","rc":[{"atb":[[1.17,0]],"id":2857977}]}]}
{"op":"mcm","clk":"AOO+pAMA8MGeAwDHtaAE","pt":1657357060698,"mc":[{"id":"1.200806927","rc":[{"atb":[[1.16,10.45]],"id":2857977}]}]}
{"op":"mcm","clk":"AIWWsgMAk++rAwCDzqsE","pt":1657359377544,"mc":[{"id":"1.200806927","rc":[{"atb":[[1.16,0]],"id":2857977}]}]}
{"op":"mcm","clk":"AJiV1QMAnrXVAwCwndAE","pt":1657365291285,"mc":[{"id":"1.200806927","rc":[{"atb":[[1.03,0]],"id":2857977}]}]}
{"op":"mcm","clk":"AM2q1QMAxcrVAwDxsdAE","pt":1657365313203,"mc":[{"id":"1.200806927","rc":[{"atb":[[1.33,3.42]],"id":2857977}]}]}
{"op":"mcm","clk":"AOX82wMAvM7cAwCd3NYE","pt":1657366275187,"mc":[{"id":"1.200806927","rc":[{"atb":[[1.16,8.21]],"id":2857977}]}]}
{"op":"mcm","clk":"AO2K4QMAmuzhAwCu59sE","pt":1657367085820,"mc":[{"id":"1.200806927","rc":[{"atb":[[1.22,347.59]],"id":228749},{"atb":[[4.7,20.66]],"id":2857977}]}]}
{"op":"mcm","clk":"APOm4QMA9YfiAwC3hNwE","pt":1657367121178,"mc":[{"id":"1.200806927","rc":[{"atb":[[1.33,0]],"id":2857977}]}]}
{"op":"mcm","clk":"AL/n6QMA29DqAwChsOME","pt":1657368552013,"mc":[{"id":"1.200806927","rc":[{"atb":[[1.16,0]],"id":2857977}]}]}
{"op":"mcm","clk":"ANi/4gQAkbWGBQCSztYF","pt":1657386973239,"mc":[{"id":"1.200806927","rc":[{"atb":[[4.7,0]],"atl":[[4.7,4.98]],"trd":[[4.7,41.32]],"ltp":4.7,"tv":42.65,"id":2857977}],"tv":43.98}]}
{"op":"mcm","clk":"AP3C4gQAoLiGBQCU0dYF","pt":1657386977235,"mc":[{"id":"1.200806927","rc":[{"atl":[[4.7,0]],"id":2857977}]}]}
{"op":"mcm","clk":"AKPE4gQAt7mGBQCU0tYF","pt":1657386978606,"mc":[{"id":"1.200806927","rc":[{"atb":[[1.16,5.7]],"id":2857977}]}]}
{"op":"mcm","clk":"AILO6wQAq9uPBQCsuN4F","pt":1657388469751,"mc":[{"id":"1.200806927","rc":[{"atb":[[1.23,8.36]],"id":228749}]}]}
{"op":"mcm","clk":"AOOQ+QQAktCbBQDFveoF","pt":1657390578973,"mc":[{"id":"1.200806927","rc":[{"atb":[[1.16,0]],"id":2857977}]}]}
{"op":"mcm","clk":"AP2Q+QQAstCbBQDXveoF","pt":1657390579259,"mc":[{"id":"1.200806927","rc":[{"atl":[[5.3,5.7]],"id":2857977}]}]}
{"op":"mcm","clk":"AIuR+QQAvdCbBQDfveoF","pt":1657390579374,"mc":[{"id":"1.200806927","rc":[{"atb":[[1.17,5.7]],"id":2857977}]}]}
{"op":"mcm","clk":"AIKvlgUAr/GyBQCW2YEG","pt":1657394179475,"mc":[{"id":"1.200806927","rc":[{"atl":[[5.3,0]],"id":2857977}]}]}
{"op":"mcm","clk":"AK2vlgUA5fGyBQDD2YEG","pt":1657394179788,"mc":[{"id":"1.200806927","rc":[{"atb":[[1.17,0]],"id":2857977}]}]}
{"op":"mcm","clk":"AL+ylgUAqvSyBQDT24EG","pt":1657394182298,"mc":[{"id":"1.200806927","rc":[{"atl":[[5.3,5.7]],"id":2857977}]}]}
{"op":"mcm","clk":"AMqylgUAs/SyBQDZ24EG","pt":1657394182379,"mc":[{"id":"1.200806927","rc":[{"atb":[[1.16,5.7]],"id":2857977}]}]}
{"op":"mcm","clk":"AIi5pAUAnpS/BQDQ4YoG","pt":1657395847571,"mc":[{"id":"1.200806927","rc":[{"atb":[[1.04,1001.05]],"id":228749},{"atb":[[1.04,1001.05]],"id":2857977}]}]}
{"op":"mcm","clk":"ANWrpwUA6IjBBQDAoYwG","pt":1657396117318,"mc":[{"id":"1.200806927","rc":[{"atb":[[1.33,58.32]],"id":2857977}]}]}
{"op":"mcm","clk":"AJLUtAUAgNLLBQCZr5MG","pt":1657397782473,"mc":[{"id":"1.200806927","rc":[{"atl":[[5.3,0]],"id":2857977}]}]}
{"op":"mcm","clk":"ALHUtAUAm9LLBQCor5MG","pt":1657397782694,"mc":[{"id":"1.200806927","rc":[{"atb":[[1.16,0]],"id":2857977}]}]}
{"op":"mcm","clk":"ANPVtAUAm9PLBQD2r5MG","pt":1657397783651,"mc":[{"id":"1.200806927","rc":[{"atb":[[1.34,5.7]],"atl":[[5.3,5.7]],"id":2857977}]}]}
{"op":"mcm","clk":"AKjTywUA8YvfBQCzy58G","pt":1657401383998,"mc":[{"id":"1.200806927","rc":[{"atb":[[1.34,0]],"id":2857977}]}]}
{"op":"mcm","clk":"AM/TywUAgYzfBQDHy58G","pt":1657401384302,"mc":[{"id":"1.200806927","rc":[{"atl":[[5.3,0]],"id":2857977}]}]}
{"op":"mcm","clk":"APnTywUAmozfBQDhy58G","pt":1657401384710,"mc":[{"id":"1.200806927","rc":[{"atb":[[1.35,5.7]],"atl":[[5.2,5.7]],"id":2857977}]}]}
{"op":"mcm","clk":"AP7A2QUA7ZfrBQCS5q4G","pt":1657404985016,"mc":[{"id":"1.200806927","rc":[{"atb":[[1.35,0]],"id":2857977}]}]}
{"op":"mcm","clk":"AJXB2QUA/pfrBQCm5q4G","pt":1657404985348,"mc":[{"id":"1.200806927","rc":[{"atl":[[5.2,0]],"id":2857977}]}]}
{"op":"mcm","clk":"ALjB2QUAnpjrBQDf5q4G","pt":1657404986155,"mc":[{"id":"1.200806927","rc":[{"atb":[[1.34,5.7]],"atl":[[5.3,5.7]],"id":2857977}]}]}
{"op":"mcm","clk":"AJTs2gUAwN/sBQCgwbEG","pt":1657405570569,"mc":[{"id":"1.200806927","rc":[{"atb":[[1.22,388.85]],"id":228749}]}]}
{"op":"mcm","clk":"AJ3s4gUAprn2BQC9gL0G","pt":1657408586450,"mc":[{"id":"1.200806927","rc":[{"atl":[[5.3,0]],"id":2857977}]}]}
{"op":"mcm","clk":"AK/s4gUAurn2BQDLgL0G","pt":1657408586734,"mc":[{"id":"1.200806927","rc":[{"atb":[[1.34,0]],"id":2857977}]}]}
{"op":"mcm","clk":"AMbs4gUA1Ln2BQDrgL0G","pt":1657408587124,"mc":[{"id":"1.200806927","rc":[{"atb":[[1.35,5.7]],"atl":[[5.2,5.7]],"id":2857977}]}]}
{"op":"mcm","clk":"AOfS7gUA/YqIBgDLx8oG","pt":1657412187439,"mc":[{"id":"1.200806927","rc":[{"atl":[[5.2,0]],"id":2857977}]}]}
{"op":"mcm","clk":"APDS7gUAiIuIBgDZx8oG","pt":1657412187639,"mc":[{"id":"1.200806927","rc":[{"atb":[[1.35,0]],"id":2857977}]}]}
{"op":"mcm","clk":"APnS7gUAk4uIBgDsx8oG","pt":1657412187842,"mc":[{"id":"1.200806927","rc":[{"atl":[[5.3,5.7]],"id":2857977}]}]}
{"op":"mcm","clk":"AIPT7gUAmIuIBgD3x8oG","pt":1657412187966,"mc":[{"id":"1.200806927","rc":[{"atb":[[1.34,5.7]],"id":2857977}]}]}
{"op":"mcm","clk":"AL2e/AUAmKWXBgDazdkG","pt":1657415788145,"mc":[{"id":"1.200806927","rc":[{"atl":[[5.3,0]],"id":2857977}]}]}
{"op":"mcm","clk":"AMue/AUAsKWXBgDszdkG","pt":1657415788463,"mc":[{"id":"1.200806927","rc":[{"atb":[[1.34,0]],"id":2857977}]}]}
{"op":"mcm","clk":"ANye/AUAx6WXBgCEztkG","pt":1657415788825,"mc":[{"id":"1.200806927","rc":[{"atb":[[1.35,5.7]],"atl":[[5.2,5.7]],"id":2857977}]}]}
{"op":"mcm","clk":"ANSlhgYAoe6iBgDqyOUG","pt":1657419389099,"mc":[{"id":"1.200806927","rc":[{"atl":[[5.2,0]],"id":2857977}]}]}
{"op":"mcm","clk":"ANylhgYAse6iBgDvyOUG","pt":1657419389314,"mc":[{"id":"1.200806927","rc":[{"atb":[[1.35,0]],"id":2857977}]}]}
{"op":"mcm","clk":"AOylhgYAye6iBgD1yOUG","pt":1657419389611,"mc":[{"id":"1.200806927","rc":[{"atl":[[5.1,5.7]],"id":2857977}]}]}
{"op":"mcm","clk":"APClhgYA0O6iBgD3yOUG","pt":1657419389713,"mc":[{"id":"1.200806927","rc":[{"atb":[[1.36,5.7]],"id":2857977}]}]}
{"op":"mcm","clk":"APuBjAYAhqutBgCit+0G","pt":1657422099934,"mc":[{"id":"1.200806927","rc":[{"atl":[[1000,2]],"id":228749},{"atl":[[1000,2]],"id":2857977}]}]}
{"op":"mcm","clk":"AI6CjAYAlKutBgC2t+0G","pt":1657422100241,"mc":[{"id":"1.200806927","rc":[{"atl":[[1000,0.02]],"id":228749},{"atl":[[1000,0.02]],"id":2857977}]}]}
{"op":"mcm","clk":"AI+HjAYAyLKtBgCiv+0G","pt":1657422119639,"mc":[{"id":"1.200806927","rc":[{"atb":[[1.01,228.72]],"id":228749},{"atb":[[1.01,228.72]],"id":2857977}]}]}
{"op":"mcm","clk":"ANPhjQYAodivBgCmo+8G","pt":1657422990037,"mc":[{"id":"1.200806927","rc":[{"atl":[[5.1,0]],"id":2857977}]}]}
{"op":"mcm","clk":"ANzhjQYArdivBgCuo+8G","pt":1657422990230,"mc":[{"id":"1.200806927","rc":[{"atb":[[1.36,0]],"id":2857977}]}]}
{"op":"mcm","clk":"AOvhjQYAv9ivBgC5o+8G","pt":1657422990513,"mc":[{"id":"1.200806927","rc":[{"atl":[[5,5.7]],"id":2857977}]}]}
{"op":"mcm","clk":"APDhjQYAy9ivBgDCo+8G","pt":1657422990730,"mc":[{"id":"1.200806927","rc":[{"atb":[[1.37,5.7]],"id":2857977}]}]}
{"op":"mcm","clk":"ANjkjgYA2d6wBgCu/+8G","pt":1657423337599,"mc":[{"id":"1.200806927","rc":[{"atb":[[1.33,0]],"id":2857977}]}]}
{"op":"mcm","clk":"APHsjwYAw/myBgCwuvEG","pt":1657424027153,"mc":[{"id":"1.200806927","rc":[{"atb":[[1.16,9.64]],"id":2857977}]}]}
{"op":"mcm","clk":"AJqBkgYA+523BgD1mvQG","pt":1657425356205,"mc":[{"id":"1.200806927","rc":[{"atb":[[1.7,58.32]],"id":2857977}]}]}
{"op":"mcm","clk":"AJ/lkwYAtty6BgDD2fcG","pt":1657426590813,"mc":[{"id":"1.200806927","rc":[{"atl":[[5,0]],"id":2857977}]}]}
{"op":"mcm","clk":"AKblkwYAxdy6BgDM2fcG","pt":1657426591092,"mc":[{"id":"1.200806927","rc":[{"atb":[[1.37,0]],"id":2857977}]}]}
{"op":"mcm","clk":"ALHlkwYA0dy6BgDe2fcG","pt":1657426591498,"mc":[{"id":"1.200806927","rc":[{"atl":[[5.3,5.7]],"id":2857977}]}]}
{"op":"mcm","clk":"ALblkwYA19y6BgDg2fcG","pt":1657426591596,"mc":[{"id":"1.200806927","rc":[{"atb":[[1.71,5.7]],"id":2857977}]}]}
{"op":"mcm","clk":"AKqAlAYAk/26BgDa9fcG","pt":1657426712167,"mc":[{"id":"1.200806927","rc":[{"atb":[[1.16,0]],"id":2857977}]}]}
{"op":"mcm","clk":"AJPTmQYA2e/BBgCztf8G","pt":1657430191853,"mc":[{"id":"1.200806927","rc":[{"atl":[[5.3,0]],"id":2857977}]}]}
{"op":"mcm","clk":"AJ3TmQYA6O/BBgC8tf8G","pt":1657430192127,"mc":[{"id":"1.200806927","rc":[{"atb":[[1.71,0]],"id":2857977}]}]}
{"op":"mcm","clk":"AKPTmQYA8e/BBgDEtf8G","pt":1657430192337,"mc":[{"id":"1.200806927","rc":[{"atb":[[1.72,5.7]],"atl":[[5.3,5.7]],"id":2857977}]}]}
{"op":"mcm","clk":"AOT7ngYAsKvKBgCLsYkH","pt":1657433792659,"mc":[{"id":"1.200806927","rc":[{"atl":[[5.3,0]],"id":2857977}]}]}
{"op":"mcm","clk":"AOf7ngYAvqvKBgCTsYkH","pt":1657433792854,"mc":[{"id":"1.200806927","rc":[{"atb":[[1.72,0]],"id":2857977}]}]}
{"op":"mcm","clk":"AO37ngYA0avKBgCesYkH","pt":1657433793165,"mc":[{"id":"1.200806927","rc":[{"atl":[[5.2,5.7]],"id":2857977}]}]}
{"op":"mcm","clk":"AO77ngYA0qvKBgCgsYkH","pt":1657433793252,"mc":[{"id":"1.200806927","rc":[{"atb":[[1.73,5.7]],"id":2857977}]}]}
{"op":"mcm","clk":"AKLlowYAw6TSBgCIm48H","pt":1657436578081,"mc":[{"id":"1.200806927","rc":[{"atb":[[1.04,1.05]],"id":228749},{"atb":[[1.04,1.05]],"id":2857977}]}]}
{"op":"mcm","clk":"AJ3zpQYA5p3VBgCzsJEH","pt":1657437393372,"mc":[{"id":"1.200806927","rc":[{"atl":[[5.2,0]],"id":2857977}]}]}
{"op":"mcm","clk":"AKDzpQYA7J3VBgC3sJEH","pt":1657437393473,"mc":[{"id":"1.200806927","rc":[{"atb":[[1.73,0]],"id":2857977}]}]}
{"op":"mcm","clk":"ALTzpQYAi57VBgDWsJEH","pt":1657437394002,"mc":[{"id":"1.200806927","rc":[{"atb":[[1.71,5.7]],"atl":[[5.3,5.7]],"id":2857977}]}]}
{"op":"mcm","clk":"ALf3pQYA5aTVBgD7tJEH","pt":1657437408207,"mc":[{"id":"1.200806927","rc":[{"atl":[[2.2,2.05]],"id":228749}]}]}
{"op":"mcm","clk":"AJeSrwYAg4PkBgCpzpsH","pt":1657440994238,"mc":[{"id":"1.200806927","rc":[{"atl":[[5.3,0]],"id":2857977}]}]}
{"op":"mcm","clk":"AJmSrwYAjIPkBgCszpsH","pt":1657440994332,"mc":[{"id":"1.200806927","rc":[{"atb":[[1.71,0]],"id":2857977}]}]}
{"op":"mcm","clk":"AKqSrwYAqYPkBgC2zpsH","pt":1657440994738,"mc":[{"id":"1.200806927","rc":[{"atb":[[1.84,5.7]],"atl":[[5.2,5.7]],"id":2857977}]}]}
{"op":"mcm","clk":"AJOTvAYA7In4BgCx7KYH","pt":1657444595021,"mc":[{"id":"1.200806927","rc":[{"atb":[[1.84,0]],"id":2857977}]}]}
{"op":"mcm","clk":"AKSTvAYAgor4BgC57KYH","pt":1657444595234,"mc":[{"id":"1.200806927","rc":[{"atl":[[5.2,0]],"id":2857977}]}]}
{"op":"mcm","clk":"ALSTvAYAqIr4BgDI7KYH","pt":1657444595523,"mc":[{"id":"1.200806927","rc":[{"atb":[[1.85,5.7]],"atl":[[5.1,5.7]],"id":2857977}]}]}
{"op":"mcm","clk":"AJ2D1AYA/O2SBwCI9LYH","pt":1657448195809,"mc":[{"id":"1.200806927","rc":[{"atl":[[5.1,0]],"id":2857977}]}]}
{"op":"mcm","clk":"ALOD1AYAle6SBwCb9LYH","pt":1657448196005,"mc":[{"id":"1.200806927","rc":[{"atb":[[1.85,0]],"id":2857977}]}]}
{"op":"mcm","clk":"APqD1AYA1O6SBwDP9LYH","pt":1657448196406,"mc":[{"id":"1.200806927","rc":[{"atb":[[1.86,5.7]],"atl":[[5,5.7]],"id":2857977}]}]}
{"op":"mcm","clk":"AIT/7wYAsqSwBwCPr84H","pt":1657451796622,"mc":[{"id":"1.200806927","rc":[{"atb":[[1.86,0]],"id":2857977}]}]}
{"op":"mcm","clk":"AIv/7wYAwqSwBwCWr84H","pt":1657451796723,"mc":[{"id":"1.200806927","rc":[{"atl":[[5,0]],"id":2857977}]}]}
{"op":"mcm","clk":"AO6A8AYA9KWwBwDCsM4H","pt":1657451798510,"mc":[{"id":"1.200806927","rc":[{"atb":[[1.84,5.7]],"atl":[[5.3,5.7]],"id":2857977}]}]}
{"op":"mcm","clk":"APqR/QYAmM2+BwCg8tgH","pt":1657453598772,"mc":[{"id":"1.200806927","rc":[{"atl":[[5.3,0]],"id":2857977}]}]}
{"op":"mcm","clk":"AIuS/QYAps2+BwCx8tgH","pt":1657453598976,"mc":[{"id":"1.200806927","rc":[{"atb":[[1.84,0]],"id":2857977}]}]}
{"op":"mcm","clk":"AM6T/QYAi8++BwDn89gH","pt":1657453601071,"mc":[{"id":"1.200806927","rc":[{"atb":[[1.84,5.7]],"atl":[[5.3,5.7]],"id":2857977}]}]}
{"op":"mcm","clk":"AJPuhAcAq7DJBwDL1d8H","pt":1657455127995,"mc":[{"id":"1.200806927","rc":[{"atb":[[1.23,0]],"atl":[[1.23,53.11]],"trd":[[1.23,41.26]],"ltp":1.23,"tv":42.59,"id":228749},{"atl":[[5.3,0]],"trd":[[5.3,5.7]],"ltp":5.3,"tv":48.35,"id":2857977}],"tv":90.94}]}
{"op":"mcm","clk":"APq9hQcAr97KBwC3n+AH","pt":1657455282390,"mc":[{"id":"1.200806927","rc":[{"atl":[[1.23,0]],"id":228749}]}]}
{"op":"mcm","clk":"AP29hQcAuN7KBwC6n+AH","pt":1657455282483,"mc":[{"id":"1.200806927","rc":[{"atb":[[1.22,335.74]],"trd":[[1.22,106.22]],"ltp":1.22,"tv":148.81,"id":228749}],"tv":197.16}]}
{"op":"mcm","clk":"AL++hQcAxt/KBwDnn+AH","pt":1657455283487,"mc":[{"id":"1.200806927","rc":[{"atb":[[1.22,388.85]],"id":228749}]}]}
{"op":"mcm","clk":"AK7AhQcAl+TKBwDQoeAH","pt":1657455287696,"mc":[{"id":"1.200806927","rc":[{"atl":[[2.18,5.7]],"id":228749}]}]}
{"op":"mcm","clk":"ANX8hQcAt+bLBwCD1uAH","pt":1657455401353,"mc":[{"id":"1.200806927","rc":[{"atb":[[1.84,0]],"id":2857977}]}]}
{"op":"mcm","clk":"AOmEhgcAg/fLBwDz2uAH","pt":1657455415426,"mc":[{"id":"1.200806927","rc":[{"atb":[[1.85,5.7]],"id":2857977}]}]}
{"op":"mcm","clk":"AJmghwcA/rPNBwCHpOEH","pt":1657455593519,"mc":[{"id":"1.200806927","rc":[{"atb":[[1.85,95.59]],"id":2857977}]}]}
{"op":"mcm","clk":"AP3phwcAqLzOBwCG2OEH","pt":1657455725737,"mc":[{"id":"1.200806927","rc":[{"atb":[[1.23,10.79]],"id":228749}]}]}
{"op":"mcm","clk":"AJLqhwcA1rzOBwCS2OEH","pt":1657455726012,"mc":[{"id":"1.200806927","rc":[{"atb":[[1.86,5.53]],"id":2857977}]}]}
{"op":"mcm","clk":"AML+iAcA9OfQBwCBzOIH","pt":1657456000306,"mc":[{"id":"1.200806927","rc":[{"atb":[[1.85,5.7]],"id":2857977}]}]}
{"op":"mcm","clk":"AMj+iAcAhOjQBwCGzOIH","pt":1657456000395,"mc":[{"id":"1.200806927","rc":[{"atb":[[1.86,94.39]],"id":2857977}]}]}
{"op":"mcm","clk":"APOajgcAp4naBwCamuYH","pt":1657457088160,"mc":[{"id":"1.200806927","rc":[{"atl":[[2.18,0]],"id":228749}]}]}
{"op":"mcm","clk":"AI+fjgcA/5DaBwDunOYH","pt":1657457095575,"mc":[{"id":"1.200806927","rc":[{"atl":[[2.16,5.7]],"id":228749}]}]}
{"op":"mcm","clk":"AJfmjgcAo4zbBwDAzeYH","pt":1657457215688,"mc":[{"id":"1.200806927","rc":[{"atb":[[1.85,0]],"id":2857977}]}]}
{"op":"mcm","clk":"AKrsjgcA7pbbBwDS0uYH","pt":1657457226332,"mc":[{"id":"1.200806927","rc":[{"atb":[[1.87,5.7]],"id":2857977}]}]}
{"op":"mcm","clk":"AMbujgcA/JnbBwCm1OYH","pt":1657457229613,"mc":[{"id":"1.200806927","rc":[{"atb":[[1.23,11.64]],"id":228749},{"atb":[[1.86,95.24]],"id":2857977}]}]}
{"op":"mcm","clk":"AMzwjgcA+ZzbBwCa1uYH","pt":1657457232734,"mc":[{"id":"1.200806927","rc":[{"atb":[[1.23,11.24]],"id":228749},{"atb":[[1.86,94.84]],"id":2857977}]}]}
{"op":"mcm","clk":"ALDzkgcA96jhBwCWuuoH","pt":1657458068570,"mc":[{"id":"1.200806927","rc":[{"atb":[[1.15,0]],"id":228749}]}]}
{"op":"mcm","clk":"ANfzkgcAoKnhBwC2uuoH","pt":1657458068979,"mc":[{"id":"1.200806927","rc":[{"atb":[[1.15,0]],"id":2857977}]}]}
{"op":"mcm","clk":"AN6ulwcA17XnBwDlru8H","pt":1657458869291,"mc":[{"id":"1.200806927","rc":[{"atb":[[1.86,5.97]],"id":2857977}]}]}
{"op":"mcm","clk":"APaulwcA/LXnBwCBr+8H","pt":1657458869514,"mc":[{"id":"1.200806927","rc":[{"atb":[[1.87,93.54]],"id":2857977}]}]}
{"op":"mcm","clk":"AIivlwcAo7bnBwCfr+8H","pt":1657458869762,"mc":[{"id":"1.200806927","rc":[{"atb":[[1.86,5.53]],"id":2857977}]}]}
{"op":"mcm","clk":"AJSvlwcAt7bnBwCzr+8H","pt":1657458869884,"mc":[{"id":"1.200806927","rc":[{"atb":[[1.87,93.99]],"id":2857977}]}]}
{"op":"mcm","clk":"ALTDlwcArNHnBwDQxO8H","pt":1657458895834,"mc":[{"id":"1.200806927","rc":[{"atl":[[2.16,0]],"id":228749}]}]}
{"op":"mcm","clk":"ALrHlwcAxdbnBwCRye8H","pt":1657458900893,"mc":[{"id":"1.200806927","rc":[{"atl":[[2.14,5.7]],"id":228749}]}]}
{"op":"mcm","clk":"AOqmmAcAodvoBwCEtPAH","pt":1657459026769,"mc":[{"id":"1.200806927","rc":[{"atb":[[1.87,88.29]],"id":2857977}]}]}
{"op":"mcm","clk":"AJqwmAcAl+foBwD6vPAH","pt":1657459037954,"mc":[{"id":"1.200806927","rc":[{"atb":[[1.88,5.7]],"id":2857977}]}]}
{"op":"mcm","clk":"APTMnwcAtrD0BwCDwPoH","pt":1657460495171,"mc":[{"id":"1.200806927","rc":[{"atb":[[1.01,426.35]],"id":228749},{"atb":[[1.01,426.35]],"id":2857977}]}]}
{"op":"mcm","clk":"AOrUnwcAu730BwDMyPoH","pt":1657460507077,"mc":[{"id":"1.200806927","rc":[{"atb":[[1.02,98.81]],"id":228749},{"atb":[[1.02,98.81]],"id":2857977}]}]}
{"op":"mcm","clk":"AIvcnwcAk8j0BwCT0PoH","pt":1657460517194,"mc":[{"id":"1.200806927","rc":[{"atb":[[1.03,65.88]],"id":228749},{"atb":[[1.03,65.88]],"id":2857977}]}]}
{"op":"mcm","clk":"AJDonwcAzdr0BwCr3voH","pt":1657460535614,"mc":[{"id":"1.200806927","rc":[{"atb":[[1.08,148.22]],"id":228749},{"atb":[[1.25,47.43]],"id":2857977}]}]}
{"op":"mcm","clk":"AL2coAcA6631BwD6oPsH","pt":1657460616920,"mc":[{"id":"1.200806927","rc":[{"atb":[[1.86,0]],"id":2857977}]}]}
{"op":"mcm","clk":"AMGcoAcA9q31BwD9oPsH","pt":1657460616968,"mc":[{"id":"1.200806927","rc":[{"atb":[[1.88,11.22]],"id":2857977}]}]}
{"op":"mcm","clk":"AOicoAcAw671BwCrofsH","pt":1657460617511,"mc":[{"id":"1.200806927","rc":[{"atb":[[1.87,87.84]],"id":2857977}]}]}
{"op":"mcm","clk":"APGcoAcA1q71BwC3ofsH","pt":1657460617625,"mc":[{"id":"1.200806927","rc":[{"atb":[[1.88,11.67]],"id":2857977}]}]}
{"op":"mcm","clk":"APjSoAcA+YT2BwCm4vsH","pt":1657460701157,"mc":[{"id":"1.200806927","rc":[{"atl":[[2.14,0]],"id":228749}]}]}
{"op":"mcm","clk":"AKnToAcAyoX2BwDd4vsH","pt":1657460701624,"mc":[{"id":"1.200806927","rc":[{"atl":[[2.12,5.7]],"id":228749}]}]}
{"op":"mcm","clk":"AN6soQcA+Y33BwDC0/wH","pt":1657460838205,"mc":[{"id":"1.200806927","rc":[{"atb":[[1.88,5.97]],"id":2857977}]}]}
{"op":"mcm","clk":"AL2zoQcA/Jb3BwC72/wH","pt":1657460848648,"mc":[{"id":"1.200806927","rc":[{"atb":[[1.9,5.7]],"id":2857977}]}]}
{"op":"mcm","clk":"AISQqQcAr7+ACADhn4UI","pt":1657462259653,"mc":[{"id":"1.200806927","rc":[{"atb":[[1.87,0]],"id":2857977}]}]}
{"op":"mcm","clk":"AJWQqQcAxr+ACAD9n4UI","pt":1657462259852,"mc":[{"id":"1.200806927","rc":[{"atb":[[1.91,82.71]],"id":2857977}]}]}
{"op":"mcm","clk":"ANKQqQcAksCACADDoIUI","pt":1657462260354,"mc":[{"id":"1.200806927","rc":[{"atb":[[1.88,5.53]],"id":2857977}]}]}
{"op":"mcm","clk":"ANiQqQcAosCACADToIUI","pt":1657462260462,"mc":[{"id":"1.200806927","rc":[{"atb":[[1.91,83.16]],"id":2857977}]}]}
{"op":"mcm","clk":"AMvDqgcAj6yCCACL6IYI","pt":1657462502022,"mc":[{"id":"1.200806927","rc":[{"atl":[[2.12,0]],"id":228749}]}]}
{"op":"mcm","clk":"AKnKqgcAl7WCCAC974YI","pt":1657462510855,"mc":[{"id":"1.200806927","rc":[{"atl":[[2.08,5.7]],"id":228749}]}]}
{"op":"mcm","clk":"AJK6qwcAmsSDCADJ34cI","pt":1657462648988,"mc":[{"id":"1.200806927","rc":[{"atb":[[1.9,0]],"id":2857977}]}]}
{"op":"mcm","clk":"AIDGqwcA5tSDCACs64cI","pt":1657462664044,"mc":[{"id":"1.200806927","rc":[{"atb":[[1.93,5.7]],"id":2857977}]}]}
{"op":"mcm","clk":"AJbbrAcAisGFCADd+ogI","pt":1657462846390,"mc":[{"id":"1.200806927","rc":[{"atb":[[1.88,0]],"id":2857977}]}]}
{"op":"mcm","clk":"AKrbrAcAmMGFCADt+ogI","pt":1657462846508,"mc":[{"id":"1.200806927","rc":[{"atb":[[1.92,5.53]],"id":2857977}]}]}
{"op":"mcm","clk":"APrbrAcA6sGFCAC0+4gI","pt":1657462847202,"mc":[{"id":"1.200806927","rc":[{"atb":[[1.91,82.71]],"id":2857977}]}]}
{"op":"mcm","clk":"AIrcrAcA+8GFCAC9+4gI","pt":1657462847304,"mc":[{"id":"1.200806927","rc":[{"atb":[[1.92,5.97]],"id":2857977}]}]}
{"op":"mcm","clk":"AJfqtQcAlteQCACz3JMI","pt":1657464311147,"mc":[{"id":"1.200806927","rc":[{"atl":[[2.08,0]],"id":228749}]}]}
{"op":"mcm","clk":"AMXstQcA7NuQCACE4ZMI","pt":1657464315863,"mc":[{"id":"1.200806927","rc":[{"atl":[[2.06,5.7]],"id":228749}]}]}
{"op":"mcm","clk":"ANTMtgcA+d+RCACg6pQI","pt":1657464464308,"mc":[{"id":"1.200806927","rc":[{"atb":[[1.93,0]],"id":2857977}]}]}
{"op":"mcm","clk":"ANnVtgcAleuRCADx9ZQI","pt":1657464477860,"mc":[{"id":"1.200806927","rc":[{"atb":[[1.95,5.7]],"id":2857977}]}]}
{"op":"mcm","clk":"AKbavAcArZGYCADB+JsI","pt":1657465622692,"mc":[{"id":"1.200806927","rc":[{"atb":[[1.22,479.85]],"id":228749}]}]}
{"op":"mcm","clk":"AP3fvAcAvZeYCACZ/5sI","pt":1657465631184,"mc":[{"id":"1.200806927","rc":[{"atl":[[1.5,20.02]],"id":228749}]}]}
{"op":"mcm","clk":"AJ3IvwcA8pGbCACms58I","pt":1657466116125,"mc":[{"id":"1.200806927","rc":[{"atl":[[2.06,0]],"id":228749}]}]}
{"op":"mcm","clk":"AMDLvwcAjJabCAD/tp8I","pt":1657466120772,"mc":[{"id":"1.200806927","rc":[{"atl":[[1.49,5.7]],"id":228749}]}]}
{"op":"mcm","clk":"AJW6wAcA/JqcCACgwqAI","pt":1657466278076,"mc":[{"id":"1.200806927","rc":[{"atb":[[1.95,0]],"id":2857977}]}]}
{"op":"mcm","clk":"ALXFwAcAjaicCADI0KAI","pt":1657466294446,"mc":[{"id":"1.200806927","rc":[{"atb":[[3.05,5.7]],"id":2857977}]}]}
{"op":"mcm","clk":"ALmfygcAsISoCADRoKwI","pt":1657467921074,"mc":[{"id":"1.200806927","rc":[{"atl":[[1.49,0]],"id":228749}]}]}
{"op":"mcm","clk":"AIekygcAhoqoCADkp6wI","pt":1657467927542,"mc":[{"id":"1.200806927","rc":[{"atl":[[1.48,5.7]],"id":228749}]}]}
{"op":"mcm","clk":"AMSjywcA76CpCADmtK0I","pt":1657468094724,"mc":[{"id":"1.200806927","rc":[{"atb":[[3.05,0]],"id":2857977}]}]}
{"op":"mcm","clk":"AL2tywcA7K2pCADNv60I","pt":1657468107975,"mc":[{"id":"1.200806927","rc":[{"atb":[[3.1,5.7]],"id":2857977}]}]}
{"op":"mcm","clk":"AKjZ0wcAh+C0CADTlrgI","pt":1657469727905,"mc":[{"id":"1.200806927","rc":[{"atl":[[1.48,0]],"id":228749}]}]}
{"op":"mcm","clk":"ALbZ0wcAsuC0CADqlrgI","pt":1657469728129,"mc":[{"id":"1.200806927","rc":[{"atl":[[1.47,5.7]],"id":228749}]}]}
{"op":"mcm","clk":"ANrE1AcAr/S1CACIs7kI","pt":1657469908368,"mc":[{"id":"1.200806927","rc":[{"atb":[[3.1,0]],"id":2857977}]}]}
{"op":"mcm","clk":"ALPN1AcA5v+1CAC8+LkI","pt":1657469922432,"mc":[{"id":"1.200806927","rc":[{"atb":[[3.15,5.7]],"id":2857977}]}]}
{"op":"mcm","clk":"AOT/1QcA/N23CADlq7wI","pt":1657470255101,"mc":[{"id":"1.200806927","rc":[{"atl":[[1.5,0]],"id":228749}]}]}
{"op":"mcm","clk":"AO//1QcAiN63CAD0q7wI","pt":1657470255160,"mc":[{"id":"1.200806927","rc":[{"atl":[[1.46,20.02]],"id":228749}]}]}
{"op":"mcm","clk":"AMn82gcA5aC/CADXpMUI","pt":1657471528469,"mc":[{"id":"1.200806927","rc":[{"atl":[[1.47,0]],"id":228749}]}]}
{"op":"mcm","clk":"AJn+2gcAn6O/CACJp8UI","pt":1657471531574,"mc":[{"id":"1.200806927","rc":[{"atl":[[1.45,5.7]],"id":228749}]}]}
{"op":"mcm","clk":"APiH3AcA273ACACEvsYI","pt":1657471722775,"mc":[{"id":"1.200806927","rc":[{"atb":[[3.15,0]],"id":2857977}]}]}
{"op":"mcm","clk":"AJKM3AcA9sXACADBxcYI","pt":1657471732970,"mc":[{"id":"1.200806927","rc":[{"atb":[[3.25,5.7]],"id":2857977}]}]}
{"op":"mcm","clk":"AMHz3QcAgJXDCACl88kI","pt":1657472269266,"mc":[{"id":"1.200806927","rc":[{"atl":[[12,10]],"id":2857977}]}]}
{"op":"mcm","clk":"AIzN4gcA+43ICACnmNEI","pt":1657473331878,"mc":[{"id":"1.200806927","rc":[{"atl":[[1.45,0]],"id":228749}]}]}
{"op":"mcm","clk":"AL3O4gcAu4/ICADNmtEI","pt":1657473334277,"mc":[{"id":"1.200806927","rc":[{"atl":[[1.44,5.7]],"id":228749}]}]}
{"op":"mcm","clk":"ANTF4wcAs8rJCADIxNII","pt":1657473534067,"mc":[{"id":"1.200806927","rc":[{"atb":[[3.25,0]],"id":2857977}]}]}
{"op":"mcm","clk":"AL7L4wcAj9HJCACRztII","pt":1657473544731,"mc":[{"id":"1.200806927","rc":[{"atb":[[3.3,5.7]],"id":2857977}]}]}
{"op":"mcm","clk":"AIao5AcAv6/KCACSy9MI","pt":1657473708088,"mc":[{"id":"1.200806927","rc":[{"atl":[[12,0]],"id":2857977}]}]}
{"op":"mcm","clk":"AI2o5AcAwa/KCACXy9MI","pt":1657473708170,"mc":[{"id":"1.200806927","rc":[{"atl":[[11,10]],"id":2857977}]}]}
{"op":"mcm","clk":"ALPH6QcA8NrPCACe+NsI","pt":1657475134685,"mc":[{"id":"1.200806927","rc":[{"atl":[[1.44,0]],"id":228749}]}]}
{"op":"mcm","clk":"AJ3I6QcAz9vPCACk+dsI","pt":1657475136192,"mc":[{"id":"1.200806927","rc":[{"atl":[[1.43,5.7]],"id":228749}]}]}
{"op":"mcm","clk":"ALS36gcA2MDQCACHwt0I","pt":1657475345057,"mc":[{"id":"1.200806927","rc":[{"atb":[[3.3,0]],"id":2857977}]}]}
{"op":"mcm","clk":"APG66gcA78PQCADzxd0I","pt":1657475351879,"mc":[{"id":"1.200806927","rc":[{"atb":[[3.35,5.7]],"id":2857977}]}]}
{"op":"mcm","clk":"AI2F8gcA8PnVCAC71ugI","pt":1657476936502,"mc":[{"id":"1.200806927","rc":[{"atl":[[1.43,0]],"id":228749}]}]}
{"op":"mcm","clk":"AKuF8gcAhPrVCADZ1ugI","pt":1657476936775,"mc":[{"id":"1.200806927","rc":[{"atl":[[1.42,5.7]],"id":228749}]}]}
{"op":"mcm","clk":"AKjj8wcAq+vWCACJw+oI","pt":1657477152257,"mc":[{"id":"1.200806927","rc":[{"atb":[[3.35,0]],"id":2857977}]}]}
{"op":"mcm","clk":"APzn8wcA3u7WCADayeoI","pt":1657477159016,"mc":[{"id":"1.200806927","rc":[{"atb":[[3.4,5.7]],"id":2857977}]}]}
{"op":"mcm","clk":"AL24+gcAleXbCAD1u/MI","pt":1657478307907,"mc":[{"id":"1.200806927","rc":[{"atb":[[1.14,1000]],"id":228749}]}]}
{"op":"mcm","clk":"ANDq/AcAk9vdCADAhPcI","pt":1657478737104,"mc":[{"id":"1.200806927","rc":[{"atl":[[1.42,0]],"id":228749}]}]}
{"op":"mcm","clk":"AI3t/AcA0tzdCADph/cI","pt":1657478740314,"mc":[{"id":"1.200806927","rc":[{"atl":[[1.41,5.7]],"id":228749}]}]}
{"op":"mcm","clk":"APSK/gcAoIHfCACk5/gI","pt":1657478959734,"mc":[{"id":"1.200806927","rc":[{"atb":[[3.4,0]],"id":2857977}]}]}
{"op":"mcm","clk":"AIOS/gcAk4ffCAD78fgI","pt":1657478971179,"mc":[{"id":"1.200806927","rc":[{"atb":[[3.45,5.7]],"id":2857977}]}]}
{"op":"mcm","clk":"AO3WhwgAkOXmCAC0qYQJ","pt":1657480540622,"mc":[{"id":"1.200806927","rc":[{"atl":[[1.41,0]],"id":228749}]}]}
{"op":"mcm","clk":"ANTXhwgA7eXmCAC7qoQJ","pt":1657480541503,"mc":[{"id":"1.200806927","rc":[{"atl":[[1.4,5.7]],"id":228749}]}]}
{"op":"mcm","clk":"AP6riQgAh43oCADI5YYJ","pt":1657480771429,"mc":[{"id":"1.200806927","rc":[{"atb":[[3.45,0]],"id":2857977}]}]}
{"op":"mcm","clk":"AKa1iQgAp5ToCACL8IYJ","pt":1657480780663,"mc":[{"id":"1.200806927","rc":[{"atb":[[3.55,5.7]],"id":2857977}]}]}
{"op":"mcm","clk":"AJeSjggAtOHrCAD+rIwJ","pt":1657481436918,"mc":[{"id":"1.200806927","rc":[{"atb":[[1.14,0]],"id":228749}]}]}
{"op":"mcm","clk":"AMTIlAgA75zwCADJnZMJ","pt":1657482341782,"mc":[{"id":"1.200806927","rc":[{"atl":[[1.4,0]],"id":228749}]}]}
{"op":"mcm","clk":"APLJlAgA453wCACGn5MJ","pt":1657482343482,"mc":[{"id":"1.200806927","rc":[{"atl":[[1.39,5.7]],"id":228749}]}]}
{"op":"mcm","clk":"AKeplggA+JHxCADy3ZQJ","pt":1657482581143,"mc":[{"id":"1.200806927","rc":[{"atb":[[3.55,0]],"id":2857977}]}]}
{"op":"mcm","clk":"AIGxlggAxpbxCADm55QJ","pt":1657482593728,"mc":[{"id":"1.200806927","rc":[{"atb":[[3.6,5.7]],"id":2857977}]}]}
{"op":"mcm","clk":"AMjtmwgAtI/1CADzmZoJ","pt":1657483695284,"mc":[{"id":"1.200806927","rc":[{"atb":[[1.08,148.52],[1.23,11.26],[1.02,99.01],[1.03,66.01],[1.01,427.15]],"trd":[[1.22,106.25],[1.23,41.3]],"tv":148.88,"id":228749},{"atb":[[1.91,0],[1.02,99.01],[1.03,66.01],[1.25,47.53],[1.01,427.15],[1.92,5.98]],"id":2857977}],"tv":197.23}]}
{"op":"mcm","clk":"AJOVnAgAh631CACRuZoJ","pt":1657483749350,"mc":[{"id":"1.200806927","rc":[{"atb":[[3.6,0]],"atl":[[3.6,6.3]],"trd":[[3.6,11.4]],"ltp":3.6,"tv":59.75,"id":2857977}],"tv":208.63}]}
{"op":"mcm","clk":"AKa5nAgAzMT1CACe1ZoJ","pt":1657483795247,"mc":[{"id":"1.200806927","rc":[{"atl":[[1.38,60.01]],"trd":[[1.38,16.44]],"ltp":1.38,"tv":165.32,"id":228749},{"atl":[[3.6,0]],"trd":[[3.6,17.7]],"tv":66.05,"id":2857977}],"tv":231.37}]}
{"op":"mcm","clk":"ALS8nAgA6sb1CACq2JoJ","pt":1657483799619,"mc":[{"id":"1.200806927","rc":[{"atb":[[3.65,3.99]],"atl":[[5.3,5.7]],"id":2857977}]}]}
{"op":"mcm","clk":"APG8nAgAm8f1CADk2JoJ","pt":1657483800359,"mc":[{"id":"1.200806927","rc":[{"atl":[[1.38,0]],"id":228749}]}]}
{"op":"mcm","clk":"ALvtnAgAvuz1CADcgZsJ","pt":1657483865243,"mc":[{"id":"1.200806927","rc":[{"atl":[[1.56,60.01]],"id":228749}]}]}
{"op":"mcm","clk":"APPynAgA6+/1CADqhpsJ","pt":1657483873382,"mc":[{"id":"1.200806927","rc":[{"atl":[[1.56,0]],"id":228749}]}]}
{"op":"mcm","clk":"AIbznAgA+O/1CAD4hpsJ","pt":1657483873555,"mc":[{"id":"1.200806927","rc":[{"atl":[[1.56,60.01]],"id":228749}]}]}
{"op":"mcm","clk":"ANGTnggA4+T2CACVj5wJ","pt":1657484093936,"mc":[{"id":"1.200806927","rc":[{"atl":[[5.5,8.46]],"id":2857977}]}]}
{"op":"mcm","clk":"AOO3nggAgYL3CAC9r5wJ","pt":1657484143783,"mc":[{"id":"1.200806927","rc":[{"atl":[[1.39,0]],"id":228749}]}]}
{"op":"mcm","clk":"AIK7nggA0oT3CACyspwJ","pt":1657484148327,"mc":[{"id":"1.200806927","rc":[{"atl":[[1.37,5.7]],"id":228749}]}]}
{"op":"mcm","clk":"AKKHowgA9o37CAD76aAJ","pt":1657485089552,"mc":[{"id":"1.200806927","rc":[{"atb":[[1.92,0.45]],"id":2857977}]}]}
{"op":"mcm","clk":"AKuHowgA/o37CACE6qAJ","pt":1657485089660,"mc":[{"id":"1.200806927","rc":[{"atb":[[2.8,5.54]],"id":2857977}]}]}
{"op":"mcm","clk":"ANnUpQgAxP38CADHiaMJ","pt":1657485600013,"mc":[{"id":"1.200806927","rc":[{"atb":[[3.65,0]],"id":2857977}]}]}
{"op":"mcm","clk":"AOTUpQgA2/38CADTiaMJ","pt":1657485600214,"mc":[{"id":"1.200806927","rc":[{"atl":[[5.3,0]],"id":2857977}]}]}
{"op":"mcm","clk":"AIjVpQgA+f38CADziaMJ","pt":1657485600581,"mc":[{"id":"1.200806927","rc":[{"atb":[[3.75,3.99]],"atl":[[5.2,5.7]],"id":2857977}]}]}
{"op":"mcm","clk":"AKnVpQgAkP78CACJiqMJ","pt":1657485600938,"mc":[{"id":"1.200806927","rc":[{"atl":[[5.5,0]],"id":2857977}]}]}
{"op":"mcm","clk":"AMGcpwgAq5n+CAD0vqQJ","pt":1657485920884,"mc":[{"id":"1.200806927","rc":[{"atl":[[5.5,8.46]],"id":2857977}]}]}
{"op":"mcm","clk":"AO+upwgA86T+CAC5zqQJ","pt":1657485948643,"mc":[{"id":"1.200806927","rc":[{"atl":[[1.37,0]],"id":228749}]}]}
{"op":"mcm","clk":"APevpwgAx6X+CACIz6QJ","pt":1657485950345,"mc":[{"id":"1.200806927","rc":[{"atl":[[1.36,5.7]],"id":228749}]}]}
{"op":"mcm","clk":"AKSSrAgA6c6CCQCIrasJ","pt":1657487400868,"mc":[{"id":"1.200806927","rc":[{"atb":[[1.08,148.69],[1.23,11.27],[1.02,99.13],[1.03,66.09],[1.01,427.64]],"atl":[[2.2,2.06],[1.36,5.69],[1.56,60.13]],"trd":[[1.38,16.47],[1.22,106.19],[1.23,41.26]],"tv":165.25,"id":228749},{"atb":[[3.75,0],[1.7,58.44],[1.02,99.13],[1.03,66.09],[1.25,47.58],[1.01,427.64]],"atl":[[5.2,5.69],[5.5,8.47]],"trd":[[4.7,41.36],[5.3,5.69],[3.6,17.69]],"tv":66.07,"id":2857977}],"tv":231.32}]}
{"op":"mcm","clk":"AK6SrAgA9c6CCQCXrasJ","pt":1657487401090,"mc":[{"id":"1.200806927","rc":[{"atl":[[5.2,0]],"id":2857977}]}]}
{"op":"mcm","clk":"AM6SrAgAns+CCQC9rasJ","pt":1657487401641,"mc":[{"id":"1.200806927","rc":[{"atl":[[5.5,0]],"id":2857977}]}]}
{"op":"mcm","clk":"AISTrAgA48+CCQCDrqsJ","pt":1657487402699,"mc":[{"id":"1.200806927","rc":[{"atb":[[3.8,3.98]],"atl":[[5.3,5.69]],"id":2857977}]}]}
{"op":"mcm","clk":"AM/0rAgA3NuDCQD62KwJ","pt":1657487696998,"mc":[{"id":"1.200806927","rc":[{"atl":[[5.5,8.47]],"id":2857977}]}]}
{"op":"mcm","clk":"ANKNrQgAjvaDCQC/+awJ","pt":1657487750694,"mc":[{"id":"1.200806927","rc":[{"atl":[[1.36,0]],"id":228749}]}]}
{"op":"mcm","clk":"AM+OrQgAm/eDCQDc+qwJ","pt":1657487752894,"mc":[{"id":"1.200806927","rc":[{"atl":[[1.35,5.69]],"id":228749}]}]}
{"op":"mcm","clk":"AO7gsQgAipyJCQD9orMJ","pt":1657489202956,"mc":[{"id":"1.200806927","rc":[{"atb":[[3.8,0]],"id":2857977}]}]}
{"op":"mcm","clk":"APrgsQgAm5yJCQCeo7MJ","pt":1657489203286,"mc":[{"id":"1.200806927","rc":[{"atl":[[5.3,0]],"id":2857977}]}]}
{"op":"mcm","clk":"AJPhsQgAuZyJCQDFo7MJ","pt":1657489203789,"mc":[{"id":"1.200806927","rc":[{"atl":[[5.5,0]],"id":2857977}]}]}
{"op":"mcm","clk":"AMXhsQgA/pyJCQCxpLMJ","pt":1657489205078,"mc":[{"id":"1.200806927","rc":[{"atb":[[3.9,3.98]],"atl":[[5.3,5.69]],"id":2857977}]}]}
{"op":"mcm","clk":"ALDNsggAqqSKCQCs3LQJ","pt":1657489524554,"mc":[{"id":"1.200806927","rc":[{"atl":[[5.5,8.47]],"id":2857977}]}]}
{"op":"mcm","clk":"AKDWsggAyLKKCQCo6rQJ","pt":1657489553172,"mc":[{"id":"1.200806927","rc":[{"atl":[[1.35,0]],"id":228749}]}]}
{"op":"mcm","clk":"AKrWsggA3rKKCQC86rQJ","pt":1657489553500,"mc":[{"id":"1.200806927","rc":[{"atl":[[1.34,5.69]],"id":228749}]}]}
{"op":"mcm","clk":"AOXiswgA57CMCQD3rrYJ","pt":1657490023894,"mc":[{"id":"1.200806927","rc":[{"atb":[[1.23,10.27]],"trd":[[1.23,43.26]],"ltp":1.23,"tv":167.25,"id":228749}],"tv":233.32}]}
{"op":"mcm","clk":"APDiswgAg7GMCQCNr7YJ","pt":1657490024320,"mc":[{"id":"1.200806927","rc":[{"atl":[[5.5,0]],"id":2857977}]}]}
{"op":"mcm","clk":"AMPkswgAoLOMCQD3sLYJ","pt":1657490029985,"mc":[{"id":"1.200806927","rc":[{"atb":[[1.23,8.27]],"trd":[[1.23,47.26]],"tv":171.25,"id":228749}],"tv":237.32}]}
{"op":"mcm","clk":"AKaItggAzPaPCQD7srkJ","pt":1657490963216,"mc":[{"id":"1.200806927","rc":[{"atb":[[1.08,148.46],[1.23,8.25],[1.02,98.97],[1.03,65.98],[1.01,427],[1.18,42.25]],"atl":[[1.34,5.7],[2.2,2.05],[1.56,60.01]],"trd":[[1.38,16.44],[1.22,106.21],[1.23,47.25]],"tv":171.23,"id":228749},{"atb":[[3.9,3.99],[1.7,58.32],[1.02,98.97],[1.03,65.98],[1.25,47.51],[1.01,427],[4,5.92],[2.8,5.53]],"atl":[[5.3,5.7]],"trd":[[4.7,41.32],[5.3,5.7],[3.6,17.7]],"tv":66.05,"id":2857977}],"tv":237.28}]}
{"op":"mcm","clk":"APiKtggA+vqPCQDEt7kJ","pt":1657490971502,"mc":[{"id":"1.200806927","rc":[{"atb":[[3.5,8.45]],"id":2857977}]}]}
{"op":"mcm","clk":"ALKWtggAho6QCQDox7kJ","pt":1657491005338,"mc":[{"id":"1.200806927","rc":[{"atb":[[3.9,0]],"id":2857977}]}]}
{"op":"mcm","clk":"AL+WtggAnY6QCQD1x7kJ","pt":1657491005642,"mc":[{"id":"1.200806927","rc":[{"atl":[[5.3,0]],"id":2857977}]}]}
{"op":"mcm","clk":"ANCWtggAwI6QCQCMyLkJ","pt":1657491006066,"mc":[{"id":"1.200806927","rc":[{"atb":[[4.1,3.99]],"atl":[[5.2,5.7]],"id":2857977}]}]}
{"op":"mcm","clk":"AOn4tggAgbyRCQCNu7oJ","pt":1657491291695,"mc":[{"id":"1.200806927","rc":[{"atb":[[2.8,0]],"id":2857977}]}]}
{"op":"mcm","clk":"AL+QtwgAvd6RCQCm17oJ","pt":1657491353845,"mc":[{"id":"1.200806927","rc":[{"atl":[[1.34,0]],"id":228749}]}]}
{"op":"mcm","clk":"AMWRtwgAhOCRCQC32LoJ","pt":1657491356522,"mc":[{"id":"1.200806927","rc":[{"atl":[[1.32,5.7]],"id":228749}]}]}
{"op":"mcm","clk":"AOvpuAgAm7SUCQDIir0J","pt":1657491970984,"mc":[{"id":"1.200806927","rc":[{"atb":[[1.22,430.44]],"id":228749}]}]}
{"op":"mcm","clk":"AM+DuwgA5MiXCQCYv78J","pt":1657492806364,"mc":[{"id":"1.200806927","rc":[{"atb":[[4.1,0]],"id":2857977}]}]}
{"op":"mcm","clk":"ANyDuwgA98iXCQCfv78J","pt":1657492806554,"mc":[{"id":"1.200806927","rc":[{"atl":[[5.2,0]],"id":2857977}]}]}
{"op":"mcm","clk":"AOmDuwgAkMmXCQCrv78J","pt":1657492806832,"mc":[{"id":"1.200806927","rc":[{"atb":[[4.2,3.99]],"atl":[[5.1,5.7]],"id":2857977}]}]}
{"op":"mcm","clk":"AIqEuwgAysmXCQDWv78J","pt":1657492807657,"mc":[{"id":"1.200806927","rc":[{"atb":[[1.23,7.8]],"id":228749}]}]}
{"op":"mcm","clk":"AI+EuwgA18mXCQDev78J","pt":1657492807861,"mc":[{"id":"1.200806927","rc":[{"atb":[[1.24,0.45]],"id":228749}]}]}
{"op":"mcm","clk":"AOH2uwgAqfyYCQC+v8AJ","pt":1657493156757,"mc":[{"id":"1.200806927","rc":[{"atl":[[1.32,0]],"id":228749}]}]}
{"op":"mcm","clk":"AOf2uwgAufyYCQDHv8AJ","pt":1657493156956,"mc":[{"id":"1.200806927","rc":[{"atl":[[1.31,5.7]],"id":228749}]}]}
{"op":"mcm","clk":"AP7VvAgAt82ZCQC388AJ","pt":1657493325001,"mc":[{"id":"1.200806927","rc":[{"atb":[[1.23,0]],"id":228749}]}]}
{"op":"mcm","clk":"AN2XvwgAz6adCQC6hsMJ","pt":1657494607201,"mc":[{"id":"1.200806927","rc":[{"atb":[[1.08,148.15],[1.02,98.77],[1.03,65.85],[1.01,426.17],[1.18,42.27]],"atl":[[1.31,5.69],[1.56,60.05]],"trd":[[1.38,16.45]],"tv":171.24,"id":228749},{"atb":[[3.5,8.46],[1.7,58.36],[1.02,98.77],[1.03,65.85],[1.25,47.41],[1.01,426.17]],"atl":[[5.1,0]],"trd":[[4.7,41.33],[5.3,5.69],[3.6,17.69]],"tv":66.04,"id":2857977}]}]}
{"op":"mcm","clk":"AOOXvwgA2qadCQDAhsMJ","pt":1657494607490,"mc":[{"id":"1.200806927","rc":[{"atb":[[4.2,0]],"id":2857977}]}]}
{"op":"mcm","clk":"AOyXvwgA4qadCQDFhsMJ","pt":1657494607706,"mc":[{"id":"1.200806927","rc":[{"atb":[[1.24,0]],"id":228749}]}]}
{"op":"mcm","clk":"AO+XvwgA6qadCQDIhsMJ","pt":1657494607810,"mc":[{"id":"1.200806927","rc":[{"atb":[[1.22,430.89]],"id":228749}]}]}
{"op":"mcm","clk":"AMCYvwgA2aedCQCRh8MJ","pt":1657494610015,"mc":[{"id":"1.200806927","rc":[{"atl":[[5.5,5.69]],"id":2857977}]}]}
{"op":"mcm","clk":"AKT5vwgAqL6eCQD71cMJ","pt":1657494957302,"mc":[{"id":"1.200806927","rc":[{"atl":[[1.31,0]],"id":228749}]}]}
{"op":"mcm","clk":"APf5vwgAnr+eCQCu1sMJ","pt":1657494959289,"mc":[{"id":"1.200806927","rc":[{"atl":[[1.33,5.69]],"id":228749}]}]}
{"op":"mcm","clk":"AIylwAgA0LmfCQDL8sMJ","pt":1657495118099,"mc":[{"id":"1.200806927","rc":[{"atb":[[1.23,1]],"id":228749}]}]}
{"op":"mcm","clk":"APO2wQgA1sWhCQCQ4MQJ","pt":1657495693544,"mc":[{"id":"1.200806927","rc":[{"atb":[[1.23,10.68]],"id":228749}]}]}
{"op":"mcm","clk":"APu2wQgA58WhCQCT4MQJ","pt":1657495693866,"mc":[{"id":"1.200806927","rc":[{"atb":[[2.8,4.99]],"id":2857977}]}]}
{"op":"mcm","clk":"AP+2wQgA88WhCQCU4MQJ","pt":1657495693980,"mc":[{"id":"1.200806927","rc":[{"atb":[[1.22,430.44]],"id":228749}]}]}
{"op":"mcm","clk":"AIO3wQgA9cWhCQCV4MQJ","pt":1657495694073,"mc":[{"id":"1.200806927","rc":[{"atb":[[1.23,11.13]],"id":228749}]}]}
{"op":"mcm","clk":"AJPfwggAvpekCQDk7MUJ","pt":1657496410328,"mc":[{"id":"1.200806927","rc":[{"atl":[[5.5,0]],"id":2857977}]}]}
{"op":"mcm","clk":"AOffwggA05ikCQCz7cUJ","pt":1657496413119,"mc":[{"id":"1.200806927","rc":[{"atb":[[4.1,3.99]],"atl":[[5.3,5.69]],"id":2857977}]}]}
{"op":"mcm","clk":"AOe7wwgAs7ylCQDZrcYJ","pt":1657496759638,"mc":[{"id":"1.200806927","rc":[{"atl":[[1.33,0]],"id":228749}]}]}
{"op":"mcm","clk":"APK7wwgAxLylCQDkrcYJ","pt":1657496759934,"mc":[{"id":"1.200806927","rc":[{"atl":[[1.32,5.69]],"id":228749}]}]}
{"op":"mcm","clk":"AMXWxQgA8OSoCQCBucgJ","pt":1657497918822,"mc":[{"id":"1.200806927","rc":[{"atb":[[1.08,148.08],[1.23,11.14],[1.02,98.72],[1.03,65.81],[1.01,425.96],[1.18,42.31]],"atl":[[1.32,5.7],[1.56,60.1]],"trd":[[1.38,16.46],[1.22,106.23],[1.23,47.27]],"tv":171.29,"id":228749},{"atb":[[1.7,58.41],[1.02,98.72],[1.03,65.81],[1.25,47.38],[1.01,425.96],[2.8,0]],"atl":[[5.3,5.7]],"trd":[[4.7,41.35],[5.3,5.7],[3.6,17.7]],"tv":66.08,"id":2857977}],"tv":237.37}]}
{"op":"mcm","clk":"ANugxggAk8apCQC9+MgJ","pt":1657498213328,"mc":[{"id":"1.200806927","rc":[{"atb":[[4.1,0]],"id":2857977}]}]}
{"op":"mcm","clk":"AN2gxggAmMapCQDB+MgJ","pt":1657498213422,"mc":[{"id":"1.200806927","rc":[{"atl":[[5.3,0]],"id":2857977}]}]}
{"op":"mcm","clk":"AO2gxggAqsapCQDf+MgJ","pt":1657498214234,"mc":[{"id":"1.200806927","rc":[{"atb":[[4.2,3.99]],"atl":[[5.3,5.7]],"id":2857977}]}]}
{"op":"mcm","clk":"AMPrxggAwqmqCQDqy8kJ","pt":1657498560236,"mc":[{"id":"1.200806927","rc":[{"atl":[[1.32,0]],"id":228749}]}]}
{"op":"mcm","clk":"ANXrxggA3qmqCQD8y8kJ","pt":1657498560723,"mc":[{"id":"1.200806927","rc":[{"atl":[[1.31,5.7]],"id":228749}]}]}
{"op":"mcm","clk":"APCDxwgAo8iqCQCa58kJ","pt":1657498664573,"mc":[{"id":"1.200806927","rc":[{"atl":[[1.46,0]],"id":228749}]}]}
{"op":"mcm","clk":"APODxwgApsiqCQCb58kJ","pt":1657498664650,"mc":[{"id":"1.200806927","rc":[{"atl":[[1.31,25.72]],"id":228749}]}]}
{"op":"mcm","clk":"AIeayggAxq6tCQDcqcwJ","pt":1657499964507,"mc":[{"id":"1.200806927","rc":[{"atb":[[1.23,1.45]],"id":228749}]}]}
{"op":"mcm","clk":"AMWoyggA6cCtCQDduswJ","pt":1657500014579,"mc":[{"id":"1.200806927","rc":[{"atb":[[4.2,0]],"id":2857977}]}]}
{"op":"mcm","clk":"AM6oyggA9MCtCQDluswJ","pt":1657500014788,"mc":[{"id":"1.200806927","rc":[{"atl":[[5.3,0]],"id":2857977}]}]}
{"op":"mcm","clk":"ANioyggA/cCtCQDsuswJ","pt":1657500014948,"mc":[{"id":"1.200806927","rc":[{"atb":[[4.3,3.99]],"atl":[[5.2,5.7]],"id":2857977}]}]}
{"op":"mcm","clk":"AOiEywgAhrquCQC3k80J","pt":1657500360990,"mc":[{"id":"1.200806927","rc":[{"atl":[[1.31,20.02]],"id":228749}]}]}
{"op":"mcm","clk":"AJ6FywgAzLquCQD+k80J","pt":1657500362591,"mc":[{"id":"1.200806927","rc":[{"atl":[[1.3,5.7]],"id":228749}]}]}
{"op":"mcm","clk":"AMe6zQgA5pCyCQDkw88J","pt":1657501815243,"mc":[{"id":"1.200806927","rc":[{"atb":[[1.08,147.95],[1.02,98.63],[1.03,65.76],[1.01,425.61],[1.18,42.34]],"atl":[[2.2,2.06],[1.3,5.69],[1.56,60.14]],"trd":[[1.38,16.47],[1.22,106.21]],"tv":171.28,"id":228749},{"atb":[[3.5,8.47],[1.7,58.45],[1.02,98.63],[1.03,65.76],[1.25,47.34],[1.01,425.61],[4,5.93]],"atl":[[5.2,0]],"trd":[[4.7,41.37],[5.3,5.69],[3.6,17.69]],"id":2857977}],"tv":237.36}]}
{"op":"mcm","clk":"AMu6zQgA75CyCQDuw88J","pt":1657501815449,"mc":[{"id":"1.200806927","rc":[{"atb":[[4.3,0]],"id":2857977}]}]}
{"op":"mcm","clk":"AM26zQgA85CyCQDww88J","pt":1657501815632,"mc":[{"id":"1.200806927","rc":[{"atb":[[4.4,3.99]],"atl":[[5.1,5.69]],"id":2857977}]}]}
{"op":"mcm","clk":"AN66zQgAkpGyCQCFxM8J","pt":1657501816611,"mc":[{"id":"1.200806927","rc":[{"atb":[[1.23,1]],"id":228749}]}]}
{"op":"mcm","clk":"AOC6zQgAmJGyCQCGxM8J","pt":1657501816727,"mc":[{"id":"1.200806927","rc":[{"atb":[[1.24,0.45]],"id":228749}]}]}
{"op":"mcm","clk":"AMOCzggApPWyCQDCmNAJ","pt":1657502162811,"mc":[{"id":"1.200806927","rc":[{"atl":[[1.3,0]],"id":228749}]}]}
{"op":"mcm","clk":"ALLfzggAx+uzCQDgyNEJ","pt":1657502621645,"mc":[{"id":"1.200806927","rc":[{"atl":[[5.1,0]],"id":2857977}]}]}
{"op":"mcm","clk":"ALTfzggAzuuzCQDkyNEJ","pt":1657502621852,"mc":[{"id":"1.200806927","rc":[{"atb":[[4.4,0]],"id":2857977}]}]}
{"op":"mcm","clk":"AL3fzggA8euzCQCNydEJ","pt":1657502622672,"mc":[{"id":"1.200806927","rc":[{"atb":[[1.24,0]],"id":228749}]}]}
{"op":"mcm","clk":"AL7fzggA9euzCQCRydEJ","pt":1657502622767,"mc":[{"id":"1.200806927","rc":[{"atb":[[1.22,430.89]],"id":228749}]}]}
{"op":"mcm","clk":"AICP0QgA8+q1CQDTt9QJ","pt":1657503982468,"mc":[{"id":"1.200806927","rc":[{"atb":[[2.8,5]],"id":2857977}]}]}
{"op":"mcm","clk":"AL6j0QgA8Pa1CQC0y9QJ","pt":1657504060678,"mc":[{"id":"1.200806927","rc":[{"atl":[[1.31,19.86]],"trd":[[1.31,0.16]],"ltp":1.31,"tv":171.44,"id":228749},{"trd":[[4.2,0.05]],"ltp":4.2,"tv":66.13,"id":2857977}],"tv":237.57}]}
{"op":"mcm","clk":"AJnW1AgA/964CQCrwtcJ","pt":1657505916092,"mc":[{"id":"1.200806927","rc":[{"atb":[[1.08,148],[1.02,98.66],[1.03,65.78],[1.01,425.74],[1.18,42.43]],"atl":[[1.56,60.26]],"trd":[[1.38,16.51],[1.22,106.2],[1.23,47.29]],"tv":171.49,"id":228749},{"atb":[[3.5,8.49],[1.7,58.57],[1.02,98.66],[1.03,65.78],[1.25,47.36],[1.01,425.74],[2.8,5.01],[4,5.94]],"trd":[[4.7,41.41]],"tv":66.17,"id":2857977}],"tv":237.66}]}
{"op":"mcm","clk":"AMSp1QgAgbG5CQCFlNgJ","pt":1657506328518,"mc":[{"id":"1.200806927","rc":[{"atl":[[1.3,5.69]],"id":228749}]}]}
{"op":"mcm","clk":"AMep1QgAhLG5CQCLlNgJ","pt":1657506328630,"mc":[{"id":"1.200806927","rc":[{"atb":[[4.3,3.99]],"atl":[[5.5,5.69]],"id":2857977}]}]}
{"op":"mcm","clk":"AI2+1wgA7se7CQCypdsJ","pt":1657507970687,"mc":[{"id":"1.200806927","rc":[{"atb":[[2.8,0]],"id":2857977}]}]}
{"op":"mcm","clk":"APXW1wgArOa7CQDkytsJ","pt":1657508128856,"mc":[{"id":"1.200806927","rc":[{"atl":[[1.3,0]],"id":228749}]}]}
{"op":"mcm","clk":"APfW1wgAtOa7CQDqytsJ","pt":1657508129077,"mc":[{"id":"1.200806927","rc":[{"atl":[[5.5,0]],"id":2857977}]}]}
{"op":"mcm","clk":"APrW1wgAuea7CQDuytsJ","pt":1657508129262,"mc":[{"id":"1.200806927","rc":[{"atb":[[4.3,0]],"id":2857977}]}]}
{"op":"mcm","clk":"AP3W1wgAwOa7CQDzytsJ","pt":1657508129475,"mc":[{"id":"1.200806927","rc":[{"atl":[[1.3,5.69]],"id":228749}]}]}
{"op":"mcm","clk":"AP7W1wgAxea7CQD2ytsJ","pt":1657508129586,"mc":[{"id":"1.200806927","rc":[{"atb":[[4.4,3.99]],"atl":[[5.5,5.69]],"id":2857977}]}]}
{"op":"mcm","clk":"APyJ2AgAzKC8CQCdgtwJ","pt":1657508443638,"mc":[{"id":"1.200806927","rc":[{"atb":[[1.08,148.12],[1.02,98.74],[1.03,65.83],[1.01,426.06],[1.2,200],[1.18,42.41]],"atl":[[1.56,60.24]],"trd":[[1.38,16.5],[1.23,47.28]],"tv":171.47,"id":228749},{"atb":[[3.5,8.48],[1.7,58.55],[1.02,98.74],[1.03,65.83],[1.25,47.4],[1.01,426.06]],"trd":[[4.7,41.4]],"tv":66.16,"id":2857977}],"tv":237.63}]}
{"op":"mcm","clk":"AKSB2QgAmeO9CQDAld0J","pt":1657509339312,"mc":[{"id":"1.200806927","rc":[{"atb":[[3.5,0]],"id":2857977}]}]}
{"op":"mcm","clk":"AOyB2QgA8uO9CQDuld0J","pt":1657509342220,"mc":[{"id":"1.200806927","rc":[{"atb":[[4,0]],"id":2857977}]}]}
{"op":"mcm","clk":"AKaC2QgAquS9CQCMlt0J","pt":1657509344320,"mc":[{"id":"1.200806927","rc":[{"atb":[[1.18,0]],"id":228749}]}]}
{"op":"mcm","clk":"AJ/Q2QgAx56+CQCZsN0J","pt":1657509570255,"mc":[{"id":"1.200806927","rc":[{"atb":[[1.7,0]],"id":2857977}]}]}
{"op":"mcm","clk":"AK3+2QgA0vm+CQDE0d0J","pt":1657509929778,"mc":[{"id":"1.200806927","rc":[{"atl":[[1.3,0]],"id":228749}]}]}
{"op":"mcm","clk":"AK3+2QgA3fm+CQDL0d0J","pt":1657509930091,"mc":[{"id":"1.200806927","rc":[{"atl":[[5.5,0]],"id":2857977}]}]}
{"op":"mcm","clk":"AK3+2QgA5fm+CQDP0d0J","pt":1657509930305,"mc":[{"id":"1.200806927","rc":[{"atb":[[4.4,0]],"id":2857977}]}]}
{"op":"mcm","clk":"AOj+2QgA2vq+CQCA0t0J","pt":1657509934497,"mc":[{"id":"1.200806927","rc":[{"atl":[[1.3,5.69]],"id":228749}]}]}
{"op":"mcm","clk":"AOn+2QgA3fq+CQCE0t0J","pt":1657509934605,"mc":[{"id":"1.200806927","rc":[{"atb":[[4.3,3.99]],"atl":[[5.5,5.69]],"id":2857977}]}]}
{"op":"mcm","clk":"AL+Z3AgAzajCCQDgrd8J","pt":1657511734826,"mc":[{"id":"1.200806927","rc":[{"atl":[[1.3,0]],"id":228749}]}]}
{"op":"mcm","clk":"AMKZ3AgA16jCCQDird8J","pt":1657511735137,"mc":[{"id":"1.200806927","rc":[{"atb":[[4.3,0]],"id":2857977}]}]}
{"op":"mcm","clk":"AMWZ3AgA3qjCCQDjrd8J","pt":1657511735335,"mc":[{"id":"1.200806927","rc":[{"atl":[[5.5,0]],"id":2857977}]}]}
{"op":"mcm","clk":"ANuZ3AgAmanCCQD9rd8J","pt":1657511737148,"mc":[{"id":"1.200806927","rc":[{"atl":[[1.3,5.69]],"id":228749},{"atb":[[4.3,3.99]],"atl":[[5.5,5.69]],"id":2857977}]}]}
{"op":"mcm","clk":"ANmj3AgAmrvCCQCVtN8J","pt":1657511809223,"mc":[{"id":"1.200806927","rc":[{"atl":[[1.26,4.56]],"id":228749}]}]}
{"op":"mcm","clk":"ALux3AgA7s/CCQDtu98J","pt":1657511897435,"mc":[{"id":"1.200806927","rc":[{"atl":[[1.3,12.69]],"id":228749}]}]}
{"op":"mcm","clk":"AM3D3ggAn9rECQCKmuEJ","pt":1657513201506,"mc":[{"id":"1.200806927","rc":[{"atb":[[1.02,98.75],[1.01,426.07]],"atl":[[1.26,3.58],[1.56,60.25]],"trd":[[1.26,0.98]],"ltp":1.26,"tv":172.45,"id":228749},{"atb":[[1.02,98.75],[1.01,426.07]],"trd":[[4.8,0.26]],"ltp":4.8,"tv":66.42,"id":2857977}],"tv":238.87}]}
{"op":"mcm","clk":"AIX/3ggAm6zFCQDGz+EJ","pt":1657513537560,"mc":[{"id":"1.200806927","rc":[{"atb":[[4.3,0]],"id":2857977}]}]}
{"op":"mcm","clk":"AIr/3ggAoqzFCQDHz+EJ","pt":1657513537760,"mc":[{"id":"1.200806927","rc":[{"atl":[[1.3,7]],"id":228749}]}]}
{"op":"mcm","clk":"AI3/3ggAqqzFCQDLz+EJ","pt":1657513537968,"mc":[{"id":"1.200806927","rc":[{"atl":[[5.5,0]],"id":2857977}]}]}
{"op":"mcm","clk":"AMv/3ggAqq3FCQCJ0OEJ","pt":1657513541558,"mc":[{"id":"1.200806927","rc":[{"atb":[[4.4,3.99]],"atl":[[5.5,5.69]],"id":2857977}]}]}
{"op":"mcm","clk":"APSk4AgAlZrHCQCn2+IJ","pt":1657514517182,"mc":[{"id":"1.200806927","rc":[{"atl":[[1.26,0]],"trd":[[1.26,4.56]],"tv":176.03,"id":228749},{"atb":[[4.4,3.64]],"trd":[[4.4,0.68],[4.8,1.2]],"ltp":4.4,"tv":68.04,"id":2857977}],"tv":244.07}]}
{"op":"mcm","clk":"ANaQ4ggAm7PICQCM4+MJ","pt":1657515341870,"mc":[{"id":"1.200806927","rc":[{"atb":[[4.4,0]],"id":2857977}]}]}
{"op":"mcm","clk":"ANeQ4ggAoLPICQCN4+MJ","pt":1657515341974,"mc":[{"id":"1.200806927","rc":[{"atl":[[5.5,0]],"id":2857977}]}]}
{"op":"mcm","clk":"APSQ4ggAy7PICQCk4+MJ","pt":1657515343064,"mc":[{"id":"1.200806927","rc":[{"atl":[[1000,0.36]],"id":2857977}]}]}
{"op":"mcm","clk":"AICR4ggA1rPICQCq4+MJ","pt":1657515343380,"mc":[{"id":"1.200806927","rc":[{"atl":[[1000,0.02]],"id":2857977}]}]}
{"op":"mcm","clk":"AIKR4ggA2bPICQCr4+MJ","pt":1657515343475,"mc":[{"id":"1.200806927","rc":[{"atl":[[5.5,0.34]],"id":2857977}]}]}
{"op":"mcm","clk":"AIPm4ggAjZrJCQCrj+QJ","pt":1657515733461,"mc":[{"id":"1.200806927","rc":[{"atb":[[1.08,148.14],[1.02,98.76],[1.03,65.84],[1.01,426.13]],"atl":[[1.56,60.24]],"trd":[[1.22,106.16],[1.23,47.26],[1.26,4.55]],"tv":175.96,"id":228749},{"atb":[[1.02,98.76],[1.03,65.84],[1.25,47.41],[1.01,426.13],[2.8,5.01]],"id":2857977}],"tv":244}]}
{"op":"mcm","clk":"AIuh5AgA+ILMCQCjp+UJ","pt":1657516831166,"mc":[{"id":"1.200806927","rc":[{"atl":[[1.3,6.49]],"trd":[[1.3,1.02]],"ltp":1.3,"tv":176.98,"id":228749}],"tv":245.02}]}
{"op":"mcm","clk":"AKLW5AgAz8rMCQCU7OUJ","pt":1657517143778,"mc":[{"id":"1.200806927","rc":[{"atl":[[5.5,0]],"id":2857977}]}]}
{"op":"mcm","clk":"AJfY5AgAls3MCQCJ7uUJ","pt":1657517154785,"mc":[{"id":"1.200806927","rc":[{"atl":[[1000,0.36]],"id":2857977}]}]}
{"op":"mcm","clk":"AJvY5AgAnM3MCQCL7uUJ","pt":1657517154993,"mc":[{"id":"1.200806927","rc":[{"atl":[[1000,0.02]],"id":2857977}]}]}
{"op":"mcm","clk":"AJzY5AgAoM3MCQCN7uUJ","pt":1657517155086,"mc":[{"id":"1.200806927","rc":[{"atl":[[5.5,0.34]],"id":2857977}]}]}
{"op":"mcm","clk":"AP2I5QgA8qDNCQCqneYJ","pt":1657517464753,"mc":[{"id":"1.200806927","rc":[{"atl":[[1.45,56.9]],"id":228749}]}]}
{"op":"mcm","clk":"AJGJ5QgAkqHNCQCzneYJ","pt":1657517465758,"mc":[{"id":"1.200806927","rc":[{"atb":[[1.92,0]],"id":2857977}]}]}
{"op":"mcm","clk":"AJWJ5QgAlqHNCQC1neYJ","pt":1657517465863,"mc":[{"id":"1.200806927","rc":[{"atb":[[3.2,0.45]],"id":2857977}]}]}
{"op":"mcm","clk":"AOSg5QgAk8HNCQDUq+YJ","pt":1657517586579,"mc":[{"id":"1.200806927","rc":[{"atb":[[1.05,100]],"id":228749}]}]}
{"op":"mcm","clk":"ANaj5QgA9MTNCQDxreYJ","pt":1657517600604,"mc":[{"id":"1.200806927","rc":[{"atb":[[1.05,100]],"id":2857977}]}]}
{"op":"mcm","clk":"ALe55QgA9ODNCQDkuuYJ","pt":1657517701160,"mc":[{"id":"1.200806927","rc":[{"atb":[[2.8,0]],"id":2857977}]}]}
{"op":"mcm","clk":"ALq55QgA+eDNCQDkuuYJ","pt":1657517701263,"mc":[{"id":"1.200806927","rc":[{"atb":[[3.25,5.01]],"id":2857977}]}]}
{"op":"mcm","clk":"AJLe5QgA14/OCQCW0OYJ","pt":1657517863008,"mc":[{"id":"1.200806927","rc":[{"atl":[[1.24,1]],"id":228749}]}]}
{"op":"mcm","clk":"AJve5QgA5Y/OCQCg0OYJ","pt":1657517863274,"mc":[{"id":"1.200806927","rc":[{"atb":[[1.22,430.44]],"id":228749}]}]}
{"op":"mcm","clk":"AJ7e5QgA6Y/OCQCh0OYJ","pt":1657517863377,"mc":[{"id":"1.200806927","rc":[{"atb":[[1.06,0.45]],"id":228749}]}]}
{"op":"mcm","clk":"ALHj5QgAuJXOCQC60+YJ","pt":1657517883696,"mc":[{"id":"1.200806927","rc":[{"atl":[[1.24,0]],"id":228749}]}]}
{"op":"mcm","clk":"AL7j5QgAxpXOCQDD0+YJ","pt":1657517883973,"mc":[{"id":"1.200806927","rc":[{"atb":[[1.06,0]],"id":228749}]}]}
{"op":"mcm","clk":"AMDj5QgAz5XOCQDF0+YJ","pt":1657517884106,"mc":[{"id":"1.200806927","rc":[{"atb":[[1.22,430.89]],"id":228749}]}]}
{"op":"mcm","clk":"AICc5ggA543PCQDmmecJ","pt":1657518215760,"mc":[{"id":"1.200806927","rc":[{"atl":[[1.3,0]],"trd":[[1.3,7.51]],"tv":183.47,"id":228749},{"atl":[[4.3,98.04]],"trd":[[4.3,1.96]],"ltp":4.3,"tv":70,"id":2857977}],"tv":253.47}]}
{"op":"mcm","clk":"AN+e5ggA4JTPCQCsnucJ","pt":1657518234100,"mc":[{"id":"1.200806927","rc":[{"atl":[[1.31,0]],"trd":[[1.31,20.02]],"ltp":1.31,"tv":203.33,"id":228749},{"atl":[[4.2,31.84]],"trd":[[4.2,8.21]],"ltp":4.2,"tv":78.16,"id":2857977}],"tv":281.49}]}
{"op":"mcm","clk":"APme5ggAoJXPCQDYnucJ","pt":1657518235525,"mc":[{"id":"1.200806927","rc":[{"atb":[[1.22,430.44]],"id":228749}]}]}
{"op":"mcm","clk":"AP2e5ggApJXPCQDanucJ","pt":1657518235628,"mc":[{"id":"1.200806927","rc":[{"atb":[[1.31,0.45]],"id":228749}]}]}
{"op":"mcm","clk":"AJaf5ggA0ZXPCQDvnucJ","pt":1657518236504,"mc":[{"id":"1.200806927","rc":[{"atl":[[1.44,5.69]],"id":228749}]}]}
{"op":"mcm","clk":"APr15ggAjbHQCQDat+gJ","pt":1657518718467,"mc":[{"id":"1.200806927","rc":[{"atl":[[4.2,21]],"trd":[[4.2,29.89]],"tv":99.84,"id":2857977}],"tv":303.17}]}
{"op":"mcm","clk":"AJCN5wgA3cXQCQCnxegJ","pt":1657518817029,"mc":[{"id":"1.200806927","rc":[{"atl":[[4.2,17.92]],"trd":[[4.2,36.05]],"tv":106,"id":2857977}],"tv":309.33}]}
{"op":"mcm","clk":"AKKd5wgA9tTQCQC/zegJ","pt":1657518879138,"mc":[{"id":"1.200806927","rc":[{"atl":[[4.2,14.84]],"trd":[[4.2,42.21]],"tv":112.16,"id":2857977}],"tv":315.49}]}
{"op":"mcm","clk":"AImw5wgA8+bQCQDC2OgJ","pt":1657518955330,"mc":[{"id":"1.200806927","rc":[{"atl":[[5.5,0]],"id":2857977}]}]}
{"op":"mcm","clk":"AJ7q5wgAqqbRCQC3h+kJ","pt":1657519248663,"mc":[{"id":"1.200806927","rc":[{"atb":[[1.08,148.09],[1.02,98.72],[1.03,65.82],[1.01,425.98]],"atl":[[1.45,56.87],[1.56,60.27]],"trd":[[1.38,16.51],[1.22,106.13],[1.23,47.25]],"tv":203.3,"id":228749},{"atb":[[1.02,98.72],[1.03,65.82],[1.25,47.39],[1.01,425.98]],"atl":[[4.2,4]],"trd":[[4.7,41.41],[4.2,63.89]],"tv":133.85,"id":2857977}],"tv":337.15}]}
{"op":"mcm","clk":"AIP85wgA3rvRCQCbnOkJ","pt":1657519347233,"mc":[{"id":"1.200806927","rc":[{"atl":[[4.2,0.92]],"trd":[[4.2,70.05]],"tv":140.01,"id":2857977}],"tv":343.31}]}
{"op":"mcm","clk":"ALj+5wgAlr7RCQCpnukJ","pt":1657519359281,"mc":[{"id":"1.200806927","rc":[{"atb":[[1.2,210.26]],"id":228749}]}]}
{"op":"mcm","clk":"AKbE6AgA14PSCQDm5OkJ","pt":1657519673810,"mc":[{"id":"1.200806927","rc":[{"atb":[[1.31,10.74]],"id":228749}]}]}
{"op":"mcm","clk":"ANSS6QgAxvfSCQDmpeoJ","pt":1657520036765,"mc":[{"id":"1.200806927","rc":[{"atl":[[1.44,0]],"id":228749}]}]}
{"op":"mcm","clk":"AL6T6QgA1vjSCQCopuoJ","pt":1657520039598,"mc":[{"id":"1.200806927","rc":[{"atl":[[1.44,5.69]],"id":228749}]}]}
{"op":"mcm","clk":"AMK06QgA8cvTCQD6yOoJ","pt":1657520233313,"mc":[{"id":"1.200806927","rc":[{"atl":[[4.2,0],[4.3,77.96]],"trd":[[4.2,71.89],[4.3,42.12]],"ltp":4.3,"tv":182.01,"id":2857977}],"tv":385.31}]}
{"op":"mcm","clk":"AISP6ggA3M7UCQDImusJ","pt":1657520606116,"mc":[{"id":"1.200806927","rc":[{"atl":[[4.3,48.78]],"trd":[[4.3,100.48]],"tv":240.37,"id":2857977}],"tv":443.67}]}
{"op":"mcm","clk":"ALyg6ggAuOvUCQC5resJ","pt":1657520706157,"mc":[{"id":"1.200806927","rc":[{"atb":[[3.35,25.64]],"id":2857977}]}]}
{"op":"mcm","clk":"AOGg6ggA1+vUCQDdresJ","pt":1657520707437,"mc":[{"id":"1.200806927","rc":[{"atb":[[3.2,0]],"id":2857977}]}]}
{"op":"mcm","clk":"AOOg6ggA2uvUCQDhresJ","pt":1657520707539,"mc":[{"id":"1.200806927","rc":[{"atb":[[3.35,26.09]],"id":2857977}]}]}
{"op":"mcm","clk":"AJSo6ggA/fXUCQDitesJ","pt":1657520745551,"mc":[{"id":"1.200806927","rc":[{"trd":[[1.43,0.77]],"ltp":1.43,"tv":204.07,"id":228749},{"atb":[[3.35,25.76]],"trd":[[3.35,0.33]],"ltp":3.35,"tv":240.7,"id":2857977}],"tv":444.77}]}
{"op":"mcm","clk":"AOPy6ggAscvVCQD05OsJ","pt":1657521076471,"mc":[{"id":"1.200806927","rc":[{"atl":[[4.3,45.86]],"trd":[[4.3,106.32]],"ltp":4.3,"tv":246.54,"id":2857977}],"tv":450.61}]}
{"op":"mcm","clk":"AImW6wgAouPVCQCD9usJ","pt":1657521192073,"mc":[{"id":"1.200806927","rc":[{"atb":[[1.22,91],[1.26,287.22]],"id":228749},{"atb":[[4.2,23.33]],"id":2857977}]}]}
{"op":"mcm","clk":"AJGW6wgAruPVCQCF9usJ","pt":1657521192277,"mc":[{"id":"1.200806927","rc":[{"atb":[[1.31,10.29]],"id":228749}]}]}
{"op":"mcm","clk":"AJaW6wgAs+PVCQCG9usJ","pt":1657521192380,"mc":[{"id":"1.200806927","rc":[{"atb":[[1.06,0.45]],"id":228749}]}]}
{"op":"mcm","clk":"AIGR7AgAiLTWCQCJvuwJ","pt":1657521616030,"mc":[{"id":"1.200806927","rc":[{"atb":[[2,18.36]],"id":2857977}]}]}
{"op":"mcm","clk":"ANKS7AgAt7XWCQCmv+wJ","pt":1657521622028,"mc":[{"id":"1.200806927","rc":[{"atl":[[1000,2.52]],"id":228749}]}]}
{"op":"mcm","clk":"AOOS7AgAvrXWCQC0v+wJ","pt":1657521622353,"mc":[{"id":"1.200806927","rc":[{"atl":[[1000,0.85]],"id":228749}]}]}
{"op":"mcm","clk":"AO2S7AgAxrXWCQC5v+wJ","pt":1657521622763,"mc":[{"id":"1.200806927","rc":[{"atl":[[1000,0.02]],"id":228749}]}]}
{"op":"mcm","clk":"APCS7AgAybXWCQC7v+wJ","pt":1657521622861,"mc":[{"id":"1.200806927","rc":[{"atl":[[1.68,0.83]],"id":228749}]}]}
{"op":"mcm","clk":"APeV7AgAwbfWCQCSwuwJ","pt":1657521636386,"mc":[{"id":"1.200806927","rc":[{"atb":[[1.31,0]],"id":228749}]}]}
{"op":"mcm","clk":"AICW7AgAzrfWCQCiwuwJ","pt":1657521636751,"mc":[{"id":"1.200806927","rc":[{"atb":[[3.25,0]],"id":2857977}]}]}
{"op":"mcm","clk":"APO07AgAgczWCQDu3uwJ","pt":1657521768744,"mc":[{"id":"1.200806927","rc":[{"atb":[[1.21,11.69]],"id":228749}]}]}
{"op":"mcm","clk":"AMfE7AgAldbWCQCi8OwJ","pt":1657521839695,"mc":[{"id":"1.200806927","rc":[{"atl":[[1.44,0]],"id":228749}]}]}
{"op":"mcm","clk":"AJaC7QgAw73XCQCSr+0J","pt":1657522128182,"mc":[{"id":"1.200806927","rc":[{"atl":[[11,0]],"id":2857977}]}]}
{"op":"mcm","clk":"AJiC7QgAx73XCQCWr+0J","pt":1657522128284,"mc":[{"id":"1.200806927","rc":[{"atb":[[4.2,13.33]],"trd":[[4.2,91.89]],"ltp":4.2,"tv":266.54,"id":2857977}],"tv":470.61}]}
{"op":"mcm","clk":"AL+C7QgAgb7XCQDFr+0J","pt":1657522129824,"mc":[{"id":"1.200806927","rc":[{"atb":[[4.2,36.66]],"id":2857977}]}]}
{"op":"mcm","clk":"AMGC7QgAhL7XCQDHr+0J","pt":1657522129925,"mc":[{"id":"1.200806927","rc":[{"atb":[[4.2,23.33]],"id":2857977}]}]}
{"op":"mcm","clk":"ALrB7QgA3P3XCQCH3+0J","pt":1657522407235,"mc":[{"id":"1.200806927","rc":[{"atb":[[4.2,22.72]],"trd":[[4.2,92.5]],"tv":267.15,"id":2857977}],"tv":471.22}]}
{"op":"mcm","clk":"ALLC7QgAxf7XCQDB3+0J","pt":1657522410604,"mc":[{"id":"1.200806927","rc":[{"atb":[[4.2,23.33]],"id":2857977}]}]}
{"op":"mcm","clk":"AMXU7QgAw5DYCQCg7O0J","pt":1657522487297,"mc":[{"id":"1.200806927","rc":[{"atl":[[2.2,0]],"id":228749}]}]}
{"op":"mcm","clk":"AN7j7QgA7p3YCQCN+O0J","pt":1657522555267,"mc":[{"id":"1.200806927","rc":[{"trd":[[1.3,8.51]],"ltp":1.3,"tv":205.07,"id":228749}],"tv":472.22}]}
{"op":"mcm","clk":"AMnP7wgA1+DaCQD87e8J","pt":1657523722717,"mc":[{"id":"1.200806927","rc":[{"atb":[[1.08,147.82],[1.02,98.55],[1.03,65.7],[1.01,425.26]],"atl":[[1.68,0.84],[1.56,60.32]],"trd":[[1.38,16.52],[1.22,106.14],[1.23,47.26]],"tv":205.1,"id":228749},{"atb":[[1.02,98.55],[3.35,25.78],[1.03,65.7],[1.25,0],[1.01,425.26],[2,18.38]],"trd":[[4.7,41.43]],"tv":267.17,"id":2857977}],"tv":472.27}]}
{"op":"mcm","clk":"AOjS7wgAzePaCQDi7+8J","pt":1657523734524,"mc":[{"id":"1.200806927","rc":[{"atb":[[1.8,14.78]],"id":2857977}]}]}
{"op":"mcm","clk":"AJGe8AgA3bfbCQCD7vAJ","pt":1657524103272,"mc":[{"id":"1.200806927","rc":[{"atb":[[3.35,0.45]],"id":2857977}]}]}
{"op":"mcm","clk":"ALWg8AgAzrrbCQCh8vAJ","pt":1657524117309,"mc":[{"id":"1.200806927","rc":[{"atb":[[4.2,23.07]],"trd":[[4.2,93.02]],"tv":267.69,"id":2857977}],"tv":472.79}]}
{"op":"mcm","clk":"AIKh8AgAzLvbCQCn8/AJ","pt":1657524121002,"mc":[{"id":"1.200806927","rc":[{"atb":[[4.2,46.4]],"id":2857977}]}]}
{"op":"mcm","clk":"AISh8AgA0bvbCQCq8/AJ","pt":1657524121109,"mc":[{"id":"1.200806927","rc":[{"atb":[[4.2,23.33]],"id":2857977}]}]}
{"op":"mcm","clk":"AKDJ8AgA8fvbCQDPtvEJ","pt":1657524356308,"mc":[{"id":"1.200806927","rc":[{"atb":[[1.2,200]],"id":228749}]}]}
{"op":"mcm","clk":"APjL8AgA7f/bCQCtuvEJ","pt":1657524372170,"mc":[{"id":"1.200806927","rc":[{"atb":[[1.26,292.35]],"id":228749}]}]}
{"op":"mcm","clk":"AMGE8QgAnd7cCQDz/fEJ","pt":1657524681220,"mc":[{"id":"1.200806927","rc":[{"atb":[[1.26,287.22]],"id":228749}]}]}
{"op":"mcm","clk":"AIH38ggA3+DeCQCZ5/MJ","pt":1657525620504,"mc":[{"id":"1.200806927","rc":[{"atb":[[1.22,0]],"id":228749}]}]}
{"op":"mcm","clk":"AMfl9AgAvevfCQDz8PQJ","pt":1657526219549,"mc":[{"id":"1.200806927","rc":[{"trd":[[1.32,74]],"ltp":1.32,"tv":279.1,"id":228749},{"atb":[[4.2,0.07]],"trd":[[4.2,116.28]],"tv":290.95,"id":2857977}],"tv":570.05}]}
{"op":"mcm","clk":"AKnm9AgA9+vfCQDG8fQJ","pt":1657526221928,"mc":[{"id":"1.200806927","rc":[{"atl":[[1.42,5.69]],"id":228749},{"atb":[[3.35,0]],"id":2857977}]}]}
{"op":"mcm","clk":"AK3m9AgA++vfCQDI8fQJ","pt":1657526222029,"mc":[{"id":"1.200806927","rc":[{"atb":[[3.2,0.45]],"id":2857977}]}]}
{"op":"mcm","clk":"ANHm9AgAkezfCQDe8fQJ","pt":1657526222751,"mc":[{"id":"1.200806927","rc":[{"atb":[[4.2,0]],"id":2857977}]}]}
{"op":"mcm","clk":"AOjy9AgAlvbfCQD3+/QJ","pt":1657526264328,"mc":[{"id":"1.200806927","rc":[{"atl":[[4.3,11.07]],"trd":[[4.3,175.9]],"ltp":4.3,"tv":360.53,"id":2857977}],"tv":639.63}]}
{"op":"mcm","clk":"AJCK9QgA3YXgCQChk/UJ","pt":1657526346411,"mc":[{"id":"1.200806927","rc":[{"atl":[[1.36,180.32]],"id":228749}]}]}
{"op":"mcm","clk":"AKON9QgAhojgCQColvUJ","pt":1657526358212,"mc":[{"id":"1.200806927","rc":[{"atl":[[1.32,180.32]],"id":228749}]}]}
{"op":"mcm","clk":"AMKS9QgAjIvgCQC/mvUJ","pt":1657526374919,"mc":[{"id":"1.200806927","rc":[{"atl":[[1.32,0.32]],"trd":[[1.32,434]],"tv":639.1,"id":228749}],"tv":999.63}]}
{"op":"mcm","clk":"AK+U9QgAoYzgCQCDnPUJ","pt":1657526380946,"mc":[{"id":"1.200806927","rc":[{"atl":[[1.3,141.42]],"trd":[[1.3,47.41]],"ltp":1.3,"tv":678,"id":228749},{"atl":[[4.3,0]],"trd":[[4.3,186.97]],"tv":371.6,"id":2857977}],"tv":1049.6}]}
{"op":"mcm","clk":"AN6U9QgAv4zgCQCqnPUJ","pt":1657526382020,"mc":[{"id":"1.200806927","rc":[{"atb":[[1.06,0]],"id":228749},{"atb":[[3.2,0]],"id":2857977}]}]}
{"op":"mcm","clk":"AOKU9QgAxIzgCQCrnPUJ","pt":1657526382126,"mc":[{"id":"1.200806927","rc":[{"atb":[[1.26,287.67]],"id":228749},{"atb":[[4.3,0.45]],"id":2857977}]}]}
{"op":"mcm","clk":"AOyU9QgAyYzgCQCxnPUJ","pt":1657526382323,"mc":[{"id":"1.200806927","rc":[{"atl":[[1000,0.36]],"id":2857977}]}]}
{"op":"mcm","clk":"APWU9QgAz4zgCQC4nPUJ","pt":1657526382529,"mc":[{"id":"1.200806927","rc":[{"atl":[[1000,0.02]],"id":2857977}]}]}
{"op":"mcm","clk":"APqU9QgA0ozgCQC/nPUJ","pt":1657526382649,"mc":[{"id":"1.200806927","rc":[{"atl":[[4.8,0.34]],"id":2857977}]}]}
{"op":"mcm","clk":"ALmW9QgAso3gCQDbnfUJ","pt":1657526387473,"mc":[{"id":"1.200806927","rc":[{"atl":[[1.3,14.01]],"trd":[[1.3,174.82]],"tv":805.41,"id":228749},{"atb":[[4.3,0]],"trd":[[4.3,226.39]],"tv":411.02,"id":2857977}],"tv":1216.43}]}
{"op":"mcm","clk":"AI2Z9QgAk4/gCQD+n/UJ","pt":1657526396040,"mc":[{"id":"1.200806927","rc":[{"atb":[[1.15,13.36]],"id":228749}]}]}
{"op":"mcm","clk":"AJ2b9QgA1JDgCQDoofUJ","pt":1657526402091,"mc":[{"id":"1.200806927","rc":[{"atl":[[1.68,12.53]],"id":228749}]}]}
{"op":"mcm","clk":"AN2d9QgA3JLgCQC0pPUJ","pt":1657526409453,"mc":[{"id":"1.200806927","rc":[{"atb":[[1.08,147.96],[1.02,98.64],[1.21,11.7],[1.03,65.76],[1.15,13.38],[1.01,425.64]],"atl":[[1.68,12.54],[1.45,56.9],[1.56,60.37]],"trd":[[1.38,16.53],[1.22,106.16],[1.23,47.29]],"tv":805.47,"id":228749},{"atb":[[1.02,98.64],[1.45,37.62],[1.03,65.76],[1.01,425.64],[1.8,14.8],[2,18.39]],"trd":[[4.7,41.45],[4.4,0.69],[4.3,226.41]],"tv":411.07,"id":2857977}],"tv":1216.54}]}
{"op":"mcm","clk":"AIys9QgA2ZvgCQDlsPUJ","pt":1657526451848,"mc":[{"id":"1.200806927","rc":[{"atb":[[1.28,90.16]],"id":228749}]}]}
{"op":"mcm","clk":"AJq19QgAk6LgCQDyuPUJ","pt":1657526480270,"mc":[{"id":"1.200806927","rc":[{"atb":[[1.3,76.15]],"atl":[[1.3,0]],"id":228749}]}]}
{"op":"mcm","clk":"AM619QgAsqLgCQCOufUJ","pt":1657526481352,"mc":[{"id":"1.200806927","rc":[{"atb":[[1.26,287.22]],"id":228749}]}]}
{"op":"mcm","clk":"ANK19QgAtKLgCQCPufUJ","pt":1657526481437,"mc":[{"id":"1.200806927","rc":[{"atb":[[1.3,76.6]],"id":228749}]}]}
{"op":"mcm","clk":"APq49QgA4KTgCQCEvPUJ","pt":1657526492765,"mc":[{"id":"1.200806927","rc":[{"atb":[[1.3,0.45]],"id":228749}]}]}
{"op":"mcm","clk":"AIq59QgA8aTgCQCdvPUJ","pt":1657526493373,"mc":[{"id":"1.200806927","rc":[{"atb":[[1.3,0]],"id":228749}]}]}
{"op":"mcm","clk":"AI659QgA9qTgCQCivPUJ","pt":1657526493470,"mc":[{"id":"1.200806927","rc":[{"atb":[[1.28,90.61]],"id":228749}]}]}
{"op":"mcm","clk":"AMvD9QgA7argCQDVw/UJ","pt":1657526525323,"mc":[{"id":"1.200806927","rc":[{"atb":[[1.3,90.16]],"id":228749}]}]}
{"op":"mcm","clk":"APrD9QgAjKvgCQDrw/UJ","pt":1657526526444,"mc":[{"id":"1.200806927","rc":[{"atb":[[1.28,90.16]],"id":228749}]}]}
{"op":"mcm","clk":"AP/D9QgAlqvgCQDuw/UJ","pt":1657526526562,"mc":[{"id":"1.200806927","rc":[{"atb":[[1.3,90.61]],"id":228749}]}]}
{"op":"mcm","clk":"AOjP9QgAubPgCQC7zfUJ","pt":1657526563768,"mc":[{"id":"1.200806927","rc":[{"atl":[[1.34,17.13]],"id":228749}]}]}
{"op":"mcm","clk":"AOTY9QgAmbrgCQDb1vUJ","pt":1657526597107,"mc":[{"id":"1.200806927","rc":[{"atl":[[1.34,0]],"id":228749}]}]}
{"op":"mcm","clk":"AL7d9QgAhr3gCQDM3PUJ","pt":1657526615216,"mc":[{"id":"1.200806927","rc":[{"atl":[[1.34,13.08]],"id":228749}]}]}
{"op":"mcm","clk":"AMff9QgAxL7gCQDu3vUJ","pt":1657526623436,"mc":[{"id":"1.200806927","rc":[{"atl":[[1.34,0]],"id":228749}]}]}
{"op":"mcm","clk":"AOHi9QgA8sDgCQCH4/UJ","pt":1657526636676,"mc":[{"id":"1.200806927","rc":[{"atl":[[1.34,17.77]],"id":228749}]}]}
{"op":"mcm","clk":"AKep9ggApIThCQDKxfYJ","pt":1657526915567,"mc":[{"id":"1.200806927","rc":[{"atb":[[1.31,90.16]],"id":228749}]}]}
{"op":"mcm","clk":"AK6p9ggAqYThCQDQxfYJ","pt":1657526915768,"mc":[{"id":"1.200806927","rc":[{"atl":[[1.32,0]],"trd":[[1.32,434.64]],"ltp":1.32,"tv":806.11,"id":228749}],"tv":1217.18}]}
{"op":"mcm","clk":"APOH9wgA0NLhCQCtnvcJ","pt":1657527190613,"mc":[{"id":"1.200806927","rc":[{"atb":[[1.32,90.16]],"id":228749}]}]}
{"op":"mcm","clk":"AJGb9wgAsebhCQD3rvcJ","pt":1657527245854,"mc":[{"id":"1.200806927","rc":[{"atb":[[1.34,72.39]],"atl":[[1.34,0]],"id":228749}]}]}
{"op":"mcm","clk":"APel9wgAgfLhCQDKtvcJ","pt":1657527275136,"mc":[{"id":"1.200806927","rc":[{"atb":[[1.34,69.72]],"trd":[[1.34,5.34]],"ltp":1.34,"tv":811.45,"id":228749}],"tv":1222.52}]}
{"op":"mcm","clk":"ALOo9wgAyPThCQCvuPcJ","pt":1657527281542,"mc":[{"id":"1.200806927","rc":[{"atb":[[1.34,67.09]],"trd":[[1.34,10.6]],"tv":816.71,"id":228749}],"tv":1227.78}]}
{"op":"mcm","clk":"AKat9wgA/fjhCQDpu/cJ","pt":1657527294523,"mc":[{"id":"1.200806927","rc":[{"atb":[[1.3,0.45]],"id":228749}]}]}
{"op":"mcm","clk":"AJyu9wgAo/rhCQC8vPcJ","pt":1657527297654,"mc":[{"id":"1.200806927","rc":[{"atb":[[1.28,0]],"id":228749}]}]}
{"op":"mcm","clk":"AKav9wgAtfvhCQCYvfcJ","pt":1657527300832,"mc":[{"id":"1.200806927","rc":[{"atb":[[1.31,0]],"id":228749}]}]}
{"op":"mcm","clk":"AP6y9wgAq//hCQDjv/cJ","pt":1657527310052,"mc":[{"id":"1.200806927","rc":[{"atl":[[1.36,0]],"id":228749}]}]}
{"op":"mcm","clk":"AKOz9wgA3P/hCQCCwPcJ","pt":1657527310870,"mc":[{"id":"1.200806927","rc":[{"atb":[[1.3,0]],"id":228749}]}]}
{"op":"mcm","clk":"AKiz9wgA4v/hCQCIwPcJ","pt":1657527310940,"mc":[{"id":"1.200806927","rc":[{"atb":[[1.34,67.54]],"id":228749}]}]}
{"op":"mcm","clk":"ANfK9wgAv5fiCQC20vcJ","pt":1657527374668,"mc":[{"id":"1.200806927","rc":[{"atl":[[1.38,90.16]],"id":228749}]}]}
{"op":"mcm","clk":"ALHL9wgAnZjiCQDx0vcJ","pt":1657527376821,"mc":[{"id":"1.200806927","rc":[{"atb":[[1.34,67.09]],"id":228749}]}]}
{"op":"mcm","clk":"ALXL9wgApJjiCQD10vcJ","pt":1657527376934,"mc":[{"id":"1.200806927","rc":[{"atb":[[1.06,0.45]],"id":228749}]}]}
{"op":"mcm","clk":"AOrU9wgAxKLiCQDB2/cJ","pt":1657527404413,"mc":[{"id":"1.200806927","rc":[{"atb":[[1.3,34.65]],"id":228749}]}]}
{"op":"mcm","clk":"AOn69wgAxL3iCQCh+PcJ","pt":1657527504012,"mc":[{"id":"1.200806927","rc":[{"atl":[[1.37,9.06]],"id":228749}]}]}
{"op":"mcm","clk":"AO6X+AgA2P7iCQCpkPgJ","pt":1657527579730,"mc":[{"id":"1.200806927","rc":[{"atb":[[1.34,64.09]],"trd":[[1.34,16.6]],"tv":822.71,"id":228749}],"tv":1233.78}]}
{"op":"mcm","clk":"AM21+AgAsZXjCQCnq/gJ","pt":1657527665031,"mc":[{"id":"1.200806927","rc":[{"atl":[[1.38,0]],"id":228749}]}]}
{"op":"mcm","clk":"AN21+AgAvJXjCQC0q/gJ","pt":1657527665349,"mc":[{"id":"1.200806927","rc":[{"atl":[[1.37,0]],"id":228749}]}]}
{"op":"mcm","clk":"AMa2+AgAmJbjCQCqrPgJ","pt":1657527667865,"mc":[{"id":"1.200806927","rc":[{"atb":[[1.06,0]],"id":228749}]}]}
{"op":"mcm","clk":"AMy2+AgAnZbjCQCvrPgJ","pt":1657527667966,"mc":[{"id":"1.200806927","rc":[{"atb":[[1.34,64.54]],"id":228749}]}]}
{"op":"mcm","clk":"ALnP+AgA9KbjCQCkxfgJ","pt":1657527737450,"mc":[{"id":"1.200806927","rc":[{"atb":[[1.18,1.3]],"atl":[[1.74,1.3]],"id":228749}]}]}
{"op":"mcm","clk":"AKLR+AgAlqjjCQCzx/gJ","pt":1657527742355,"mc":[{"id":"1.200806927","rc":[{"atb":[[1.34,37.12]],"trd":[[1.34,44.02]],"tv":850.13,"id":228749},{"trd":[[3.95,9.3]],"ltp":3.95,"tv":420.37,"id":2857977}],"tv":1270.5}]}
{"op":"mcm","clk":"ANyM+QgAiM/jCQDT/fgJ","pt":1657527904781,"mc":[{"id":"1.200806927","rc":[{"atb":[[1.34,0]],"trd":[[1.34,81.14]],"tv":887.25,"id":228749},{"atb":[[3.95,11.12]],"trd":[[3.95,21.89]],"tv":432.96,"id":2857977}],"tv":1320.21}]}
{"op":"mcm","clk":"AOeS+QgAxNLjCQDJgvkJ","pt":1657527922174,"mc":[{"id":"1.200806927","rc":[{"atl":[[1.34,32.33]],"id":228749}]}]}
{"op":"mcm","clk":"ANWW+QgA4NTjCQCDhvkJ","pt":1657527933424,"mc":[{"id":"1.200806927","rc":[{"atb":[[1.27,9.2]],"id":228749}]}]}
{"op":"mcm","clk":"AJ+j+QgAjNzjCQD2j/kJ","pt":1657527968150,"mc":[{"id":"1.200806927","rc":[{"atl":[[1.34,0]],"id":228749}]}]}
{"op":"mcm","clk":"AKej+QgAkNzjCQD5j/kJ","pt":1657527968350,"mc":[{"id":"1.200806927","rc":[{"atl":[[1.34,34.73]],"id":228749}]}]}
{"op":"mcm","clk":"ALSk+QgAwdzjCQDOkPkJ","pt":1657527971168,"mc":[{"id":"1.200806927","rc":[{"atb":[[1.32,0]],"id":228749}]}]}
{"op":"mcm","clk":"AOqn+QgAv97jCQC3k/kJ","pt":1657527980498,"mc":[{"id":"1.200806927","rc":[{"atl":[[1.34,0]],"id":228749}]}]}
{"op":"mcm","clk":"AO+n+QgAxt7jCQC6k/kJ","pt":1657527980602,"mc":[{"id":"1.200806927","rc":[{"atl":[[1.34,32.33]],"id":228749}]}]}
{"op":"mcm","clk":"AMSu+QgAzOTjCQDumfkJ","pt":1657528001742,"mc":[{"id":"1.200806927","rc":[{"atl":[[1.32,9.02]],"id":228749}]}]}
{"op":"mcm","clk":"ANO1+QgAl+vjCQDOofkJ","pt":1657528022153,"mc":[{"id":"1.200806927","rc":[{"atl":[[1.42,0]],"id":228749}]}]}
{"op":"mcm","clk":"AI26+QgA4e7jCQDSpfkJ","pt":1657528032270,"mc":[{"id":"1.200806927","rc":[{"atb":[[1.32,441.79]],"atl":[[1.32,0]],"id":228749}]}]}
{"op":"mcm","clk":"ALHK+QgAjP7jCQCetvkJ","pt":1657528078155,"mc":[{"id":"1.200806927","rc":[{"atb":[[1.32,0]],"id":228749}]}]}
{"op":"mcm","clk":"AIHc+QgA94vkCQD+x/kJ","pt":1657528128461,"mc":[{"id":"1.200806927","rc":[{"atl":[[1.34,0]],"id":228749}]}]}
{"op":"mcm","clk":"AIfc+QgA/ovkCQCJyPkJ","pt":1657528128581,"mc":[{"id":"1.200806927","rc":[{"atl":[[1.34,32.33]],"id":228749}]}]}
{"op":"mcm","clk":"AK/r+QgAiJvkCQCM2vkJ","pt":1657528182860,"mc":[{"id":"1.200806927","rc":[{"atl":[[4.8,0]],"id":2857977}]}]}
{"op":"mcm","clk":"ANyd+ggA9M3kCQD8iPoJ","pt":1657528320168,"mc":[{"id":"1.200806927","rc":[{"atb":[[2.72,103.69]],"id":2857977}]}]}
{"op":"mcm","clk":"AMCL+wgA5rzlCQD24/oJ","pt":1657528608331,"mc":[{"id":"1.200806927","rc":[{"atl":[[1.34,0]],"id":228749}]}]}
{"op":"mcm","clk":"AMeL+wgA6bzlCQD94/oJ","pt":1657528608428,"mc":[{"id":"1.200806927","rc":[{"atl":[[1.31,11]],"id":228749}]}]}
{"op":"mcm","clk":"AJ6d+wgA18rlCQCX8foJ","pt":1657528655353,"mc":[{"id":"1.200806927","rc":[{"atl":[[1.31,0]],"id":228749}]}]}
{"op":"mcm","clk":"AOun+wgA8tHlCQC7+voJ","pt":1657528682196,"mc":[{"id":"1.200806927","rc":[{"atb":[[1.3,23.56]],"trd":[[1.3,197.01]],"ltp":1.3,"tv":909.44,"id":228749}],"tv":1342.4}]}
{"op":"mcm","clk":"ANPk+wgAvZnmCQCIxvsJ","pt":1657528914660,"mc":[{"id":"1.200806927","rc":[{"atb":[[1.3,21.56]],"trd":[[1.3,201.01]],"tv":913.44,"id":228749}],"tv":1346.4}]}
{"op":"mcm","clk":"AJm+/AgAyPTmCQC+rPwJ","pt":1657529220693,"mc":[{"id":"1.200806927","rc":[{"atb":[[1.27,5.85]],"id":228749}]}]}
{"op":"mcm","clk":"AP/U/AgAwIjnCQDUwfwJ","pt":1657529283195,"mc":[{"id":"1.200806927","rc":[{"atb":[[3.95,0]],"atl":[[3.95,0.26]],"trd":[[3.95,44.13]],"tv":455.2,"id":2857977}],"tv":1368.64}]}
{"op":"mcm","clk":"AOne/AgAtZHnCQCayvwJ","pt":1657529311531,"mc":[{"id":"1.200806927","rc":[{"atl":[[3,11.38]],"id":228749}]}]}
{"op":"mcm","clk":"AIXy/AgA/6DnCQDOif0J","pt":1657529360722,"mc":[{"id":"1.200806927","rc":[{"atl":[[1.44,5.69]],"id":228749}]}]}
{"op":"mcm","clk":"AKuC/QgA36/nCQDZl/0J","pt":1657529399682,"mc":[{"id":"1.200806927","rc":[{"atl":[[1.43,9.02]],"id":228749}]}]}
{"op":"mcm","clk":"AOXr/QgAtZDoCQCr6f0J","pt":1657529666298,"mc":[{"id":"1.200806927","rc":[{"atb":[[1.27,16.57]],"id":228749}]}]}
{"op":"mcm","clk":"APzr/QgAyZDoCQC96f0J","pt":1657529666713,"mc":[{"id":"1.200806927","rc":[{"atb":[[3.25,4.32]],"id":2857977}]}]}
{"op":"mcm","clk":"AIr8/QgAvJ3oCQCF9P0J","pt":1657529706875,"mc":[{"id":"1.200806927","rc":[{"atl":[[1.41,17.86]],"id":228749}]}]}
{"op":"mcm","clk":"AMSt/ggA/8voCQDBmf4J","pt":1657529831666,"mc":[{"id":"1.200806927","rc":[{"atl":[[1.43,0]],"id":228749}]}]}
{"op":"mcm","clk":"AL6z/ggA29HoCQDFnf4J","pt":1657529842592,"mc":[{"id":"1.200806927","rc":[{"atl":[[1.4,9.02]],"id":228749}]}]}
{"op":"mcm","clk":"AI/6/ggAnpDpCQDWyv4J","pt":1657530001325,"mc":[{"id":"1.200806927","rc":[{"atb":[[1.27,227.9]],"id":228749},{"atb":[[3.3,36.75]],"id":2857977}]}]}
{"op":"mcm","clk":"ALSw/wgAlMLpCQD/7/4J","pt":1657530121408,"mc":[{"id":"1.200806927","rc":[{"atb":[[1.08,148.16],[1.3,30.02],[1.02,98.77],[1.15,13.37],[1.03,65.85],[1.27,228],[1.01,426.17]],"atl":[[1.68,12.53],[1.56,60.34]],"trd":[[1.3,201],[1.23,47.28]],"tv":913.42,"id":228749},{"atb":[[3.3,36.77],[1.02,98.77],[1.03,65.85],[1.45,37.6],[1.01,426.17],[1.8,14.82],[2,18.38]],"trd":[[4.7,41.44]],"tv":455.19,"id":2857977}],"tv":1368.61}]}
{"op":"mcm","clk":"AIjc/wgAhubpCQDUlP8J","pt":1657530225529,"mc":[{"id":"1.200806927","rc":[{"atl":[[1.41,0]],"id":228749}]}]}
{"op":"mcm","clk":"AJbc/wgAkObpCQDblP8J","pt":1657530225781,"mc":[{"id":"1.200806927","rc":[{"atb":[[3.3,0],[3.25,41.9]],"id":2857977}]}]}
{"op":"mcm","clk":"AObj/wgAhuzpCQDSm/8J","pt":1657530244023,"mc":[{"id":"1.200806927","rc":[{"atl":[[1.4,20.92]],"id":228749}]}]}
{"op":"mcm","clk":"AKTw/wgA4vbpCQCQpv8J","pt":1657530272661,"mc":[{"id":"1.200806927","rc":[{"atl":[[1.4,9.02]],"id":228749}]}]}
{"op":"mcm","clk":"AJHBgAkA28LqCQCy9/8J","pt":1657530480613,"mc":[{"id":"1.200806927","rc":[{"atl":[[1.4,0]],"id":228749}]}]}
{"op":"mcm","clk":"APjzgAkAhfjqCQCip4AK","pt":1657530615992,"mc":[{"id":"1.200806927","rc":[{"atl":[[1.39,180.32]],"id":228749}]}]}
{"op":"mcm","clk":"AID0gAkAmfjqCQCnp4AK","pt":1657530616206,"mc":[{"id":"1.200806927","rc":[{"atb":[[3.25,4.32],[3.6,32.53]],"id":2857977}]}]}
{"op":"mcm","clk":"AMaKgQkAypXrCQCevoAK","pt":1657530687075,"mc":[{"id":"1.200806927","rc":[{"atl":[[1.38,6.76]],"id":228749}]}]}
{"op":"mcm","clk":"AIWOgQkAgprrCQDNwYAK","pt":1657530696982,"mc":[{"id":"1.200806927","rc":[{"atb":[[1.27,222.15]],"id":228749}]}]}
{"op":"mcm","clk":"ANTtggkAoufsCQCryYEK","pt":1657531153877,"mc":[{"id":"1.200806927","rc":[{"atl":[[1.38,0]],"id":228749}]}]}
{"op":"mcm","clk":"ANfwggkA9OnsCQDdyoEK","pt":1657531161091,"mc":[{"id":"1.200806927","rc":[{"atl":[[1.44,0]],"id":228749}]}]}
{"op":"mcm","clk":"AOfwggkAhersCQDmyoEK","pt":1657531161458,"mc":[{"id":"1.200806927","rc":[{"atl":[[1.37,5.69]],"id":228749}]}]}
{"op":"mcm","clk":"AO/wggkAjOrsCQDoyoEK","pt":1657531161568,"mc":[{"id":"1.200806927","rc":[{"atb":[[1.31,5.69]],"id":228749}]}]}
{"op":"mcm","clk":"AJeLhAkA4/7tCQC50oIK","pt":1657531527387,"mc":[{"id":"1.200806927","rc":[{"atb":[[1.27,211.43]],"id":228749}]}]}
{"op":"mcm","clk":"ALGLhAkAif/tCQDH0oIK","pt":1657531527758,"mc":[{"id":"1.200806927","rc":[{"atb":[[3.25,0]],"id":2857977}]}]}
{"op":"mcm","clk":"AK2UhQkApaTvCQCN54MK","pt":1657531898577,"mc":[{"id":"1.200806927","rc":[{"atl":[[1.37,5.52]],"trd":[[1.37,0.33]],"ltp":1.37,"tv":913.75,"id":228749}],"tv":1368.94}]}
{"op":"mcm","clk":"AJeRhgkA5MnwCQDv0oQK","pt":1657532212294,"mc":[{"id":"1.200806927","rc":[{"atl":[[1.39,0]],"id":228749}]}]}
{"op":"mcm","clk":"AKaRhgkA8MnwCQD90oQK","pt":1657532212570,"mc":[{"id":"1.200806927","rc":[{"atb":[[3.25,37.58],[3.6,0]],"id":2857977}]}]}
{"op":"mcm","clk":"AOa9hwkA3pPyCQCQ0oUK","pt":1657532568189,"mc":[{"id":"1.200806927","rc":[{"atb":[[1.31,5.18]],"trd":[[1.31,21.03],[1.33,0.78]],"ltp":1.31,"tv":915.54,"id":228749},{"atl":[[3.95,0]],"trd":[[3.95,44.39]],"tv":455.45,"id":2857977}],"tv":1370.99}]}
{"op":"mcm","clk":"AMj6iAkAw5b0CQC8iocK","pt":1657532961765,"mc":[{"id":"1.200806927","rc":[{"atl":[[1.37,0]],"id":228749}]}]}
{"op":"mcm","clk":"ANT6iAkA15b0CQDHiocK","pt":1657532962063,"mc":[{"id":"1.200806927","rc":[{"atb":[[1.31,0]],"id":228749}]}]}
{"op":"mcm","clk":"AKH/iAkA45v0CQDZjocK","pt":1657532971446,"mc":[{"id":"1.200806927","rc":[{"atl":[[1000,0.36]],"id":228749}]}]}
{"op":"mcm","clk":"AKz/iAkA7Zv0CQDkjocK","pt":1657532971663,"mc":[{"id":"1.200806927","rc":[{"atl":[[1000,0.02]],"id":228749}]}]}
{"op":"mcm","clk":"ALH/iAkA8pv0CQDojocK","pt":1657532971762,"mc":[{"id":"1.200806927","rc":[{"atl":[[1.37,0.34]],"id":228749}]}]}
{"op":"mcm","clk":"ALH0iQkAwYv1CQCc7ocK","pt":1657533193479,"mc":[{"id":"1.200806927","rc":[{"atl":[[1.42,180.32]],"id":228749}]}]}
{"op":"mcm","clk":"AN30iQkA6Yv1CQDH7ocK","pt":1657533194199,"mc":[{"id":"1.200806927","rc":[{"atb":[[3.4,35.24]],"id":2857977}]}]}
{"op":"mcm","clk":"APiUiwkAvrD2CQDS3IgK","pt":1657533494158,"mc":[{"id":"1.200806927","rc":[{"atb":[[1.31,8.46]],"id":228749}]}]}
{"op":"mcm","clk":"AImViwkA0bD2CQDj3IgK","pt":1657533494456,"mc":[{"id":"1.200806927","rc":[{"atb":[[3.45,4.07]],"id":2857977}]}]}
{"op":"mcm","clk":"APS/iwkA/dn2CQDv9ogK","pt":1657533565662,"mc":[{"id":"1.200806927","rc":[{"atl":[[1.42,0]],"id":228749}]}]}
{"op":"mcm","clk":"AJfAiwkArdr2CQCJ94gK","pt":1657533566156,"mc":[{"id":"1.200806927","rc":[{"atb":[[3.4,0]],"id":2857977}]}]}
{"op":"mcm","clk":"ALvViwkA5PD2CQCpg4kK","pt":1657533600988,"mc":[{"id":"1.200806927","rc":[{"atb":[[1.4,24.66]],"atl":[[1.37,0]],"trd":[[1.37,1.01]],"ltp":1.37,"tv":916.22,"id":228749},{"atb":[[1.4,25]],"id":2857977}],"tv":1371.67}]}
{"op":"mcm","clk":"ANbViwkA/fD2CQC+g4kK","pt":1657533601210,"mc":[{"id":"1.200806927","rc":[{"atb":[[1.4,6.77]],"trd":[[1.4,35.78]],"ltp":1.4,"tv":952,"id":228749}],"tv":1407.45}]}
{"op":"mcm","clk":"AI7aiwkAzPX2CQC3hokK","pt":1657533607211,"mc":[{"id":"1.200806927","rc":[{"atb":[[1.08,148.13],[1.31,8.48],[1.02,98.76],[1.21,11.72],[1.15,13.39],[1.03,65.84],[1.27,211.42],[1.01,426.11]],"atl":[[3,11.37],[1.68,12.55],[1.45,56.83],[1.56,60.43]],"trd":[[1.38,16.55],[1.3,201.02],[1.22,106.1],[1.23,47.26],[9,1.34]],"tv":951.97,"id":228749},{"atb":[[1.02,98.76],[1.03,65.84],[1.45,37.66],[1.01,426.11],[1.8,14.81],[3.45,4.08],[2,18.41]],"atl":[[1000,0.36]],"trd":[[4.7,41.47],[5.3,5.68],[3.95,44.34],[9,1.34],[4.3,226.37],[3.6,17.68]],"tv":455.38,"id":2857977}],"tv":1407.35}]}
{"op":"mcm","clk":"AJzaiwkA4fX2CQDAhokK","pt":1657533607408,"mc":[{"id":"1.200806927","rc":[{"atl":[[1000,0.02]],"id":2857977}]}]}
{"op":"mcm","clk":"AKHaiwkA7fX2CQDFhokK","pt":1657533607520,"mc":[{"id":"1.200806927","rc":[{"atl":[[3.5,0.34]],"id":2857977}]}]}
{"op":"mcm","clk":"APP6iwkAv5r3CQDImYkK","pt":1657533659280,"mc":[{"id":"1.200806927","rc":[{"atb":[[1.4,0]],"atl":[[1.4,172.7]],"trd":[[1.4,50.17]],"tv":966.36,"id":228749},{"atl":[[3.5,0]],"trd":[[3.5,0.34]],"ltp":3.5,"tv":455.72,"id":2857977}],"tv":1422.08}]}
{"op":"mcm","clk":"AJT7iwkA45r3CQDdmYkK","pt":1657533659699,"mc":[{"id":"1.200806927","rc":[{"atb":[[3.55,33.17]],"id":2857977}]}]}
{"op":"mcm","clk":"AJf7iwkA55r3CQDgmYkK","pt":1657533659762,"mc":[{"id":"1.200806927","rc":[{"atb":[[3.25,0]],"id":2857977}]}]}
{"op":"mcm","clk":"ALD9iwkA7J33CQDdm4kK","pt":1657533664302,"mc":[{"id":"1.200806927","rc":[{"atl":[[1.4,171.7]],"trd":[[1.4,52.17]],"tv":968.36,"id":228749}],"tv":1424.08}]}
{"op":"mcm","clk":"APj9iwkAv573CQCanIkK","pt":1657533665396,"mc":[{"id":"1.200806927","rc":[{"atl":[[4.2,5.68]],"id":2857977}]}]}
{"op":"mcm","clk":"AIP+iwkAyJ73CQCenIkK","pt":1657533665577,"mc":[{"id":"1.200806927","rc":[{"atb":[[3.6,3.98]],"id":2857977}]}]}
{"op":"mcm","clk":"AIGAjAkA/qD3CQDBnYkK","pt":1657533668983,"mc":[{"id":"1.200806927","rc":[{"atb":[[1.41,1]],"id":2857977}]}]}
{"op":"mcm","clk":"AOqDjAkAzqX3CQDAoIkK","pt":1657533675985,"mc":[{"id":"1.200806927","rc":[{"atb":[[1.2,201]],"id":228749},{"atb":[[1.2,1]],"id":2857977}]}]}
{"op":"mcm","clk":"AK2IjAkAs6r3CQDvo4kK","pt":1657533684237,"mc":[{"id":"1.200806927","rc":[{"atb":[[1.04,2.05]],"id":228749},{"atb":[[1.04,2.05]],"id":2857977}]}]}
{"op":"mcm","clk":"ALuMjAkA7q73CQCJp4kK","pt":1657533692606,"mc":[{"id":"1.200806927","rc":[{"atb":[[1.03,66.84]],"id":228749},{"atb":[[1.03,66.84]],"id":2857977}]}]}
{"op":"mcm","clk":"AI6PjAkAz7H3CQDUqIkK","pt":1657533697220,"mc":[{"id":"1.200806927","rc":[{"atb":[[3.7,29.75]],"id":2857977}]}]}
{"op":"mcm","clk":"ALSPjAkA/LH3CQDrqIkK","pt":1657533697753,"mc":[{"id":"1.200806927","rc":[{"atb":[[3.75,30.75]],"id":2857977}]}]}
{"op":"mcm","clk":"ALuQjAkArbP3CQDoqYkK","pt":1657533699845,"mc":[{"id":"1.200806927","rc":[{"atb":[[1.02,99.76]],"id":228749},{"atb":[[1.02,99.76]],"id":2857977}]}]}
{"op":"mcm","clk":"AMiUjAkAwrf3CQDOrIkK","pt":1657533707236,"mc":[{"id":"1.200806927","rc":[{"atb":[[1.01,427.11]],"id":228749},{"atb":[[1.01,427.11]],"id":2857977}]}]}
{"op":"mcm","clk":"ALWWjAkA9Ln3CQCZrokK","pt":1657533711347,"mc":[{"id":"1.200806927","rc":[{"atb":[[3.7,0]],"id":2857977}]}]}
{"op":"mcm","clk":"ALyWjAkA/bn3CQCfrokK","pt":1657533711466,"mc":[{"id":"1.200806927","rc":[{"atb":[[3.8,29.75]],"id":2857977}]}]}
{"op":"mcm","clk":"AMiWjAkAkrr3CQCsrokK","pt":1657533711760,"mc":[{"id":"1.200806927","rc":[{"atb":[[3.85,29.67]],"id":2857977}]}]}
{"op":"mcm","clk":"AN6YjAkAuLz3CQCZsIkK","pt":1657533715552,"mc":[{"id":"1.200806927","rc":[{"atb":[[3.8,0]],"id":2857977}]}]}
{"op":"mcm","clk":"AOSYjAkAwLz3CQCisIkK","pt":1657533715651,"mc":[{"id":"1.200806927","rc":[{"atb":[[3.9,29.75]],"id":2857977}]}]}
{"op":"mcm","clk":"APaYjAkA0rz3CQCusIkK","pt":1657533715878,"mc":[{"id":"1.200806927","rc":[{"atb":[[3.75,0],[3.85,0]],"id":2857977}]}]}
{"op":"mcm","clk":"AJOZjAkA+bz3CQDLsIkK","pt":1657533716333,"mc":[{"id":"1.200806927","rc":[{"atb":[[3.55,0]],"id":2857977}]}]}
{"op":"mcm","clk":"AKuZjAkAmL33CQDnsIkK","pt":1657533716768,"mc":[{"id":"1.200806927","rc":[{"atb":[[3.9,58.91]],"id":2857977}]}]}
{"op":"mcm","clk":"AIebjAkAob/3CQCEsokK","pt":1657533720049,"mc":[{"id":"1.200806927","rc":[{"atl":[[1.4,0]],"id":228749}]}]}
{"op":"mcm","clk":"AMCtjAkA1NX3CQCfwIkK","pt":1657533755431,"mc":[{"id":"1.200806927","rc":[{"atb":[[1.23,0]],"id":228749}]}]}
{"op":"mcm","clk":"AMatjAkA39X3CQCjwIkK","pt":1657533755531,"mc":[{"id":"1.200806927","rc":[{"atb":[[1.32,1]],"id":228749}]}]}
{"op":"mcm","clk":"AKi2jAkAv+D3CQDhx4kK","pt":1657533773583,"mc":[{"id":"1.200806927","rc":[{"atb":[[1.32,0]],"id":228749}]}]}
{"op":"mcm","clk":"ALPbjAkAio/4CQCO5okK","pt":1657533845740,"mc":[{"id":"1.200806927","rc":[{"atl":[[4.2,0]],"id":2857977}]}]}
{"op":"mcm","clk":"AMfbjAkAn4/4CQCa5okK","pt":1657533846033,"mc":[{"id":"1.200806927","rc":[{"atb":[[3.6,0]],"id":2857977}]}]}
{"op":"mcm","clk":"ANjsjgkA8a77CQC4sosK","pt":1657534377321,"mc":[{"id":"1.200806927","rc":[{"trd":[[1.35,0.69]],"ltp":1.35,"tv":969.05,"id":228749},{"atb":[[3.9,58.67]],"trd":[[3.9,0.24]],"ltp":3.9,"tv":455.96,"id":2857977}],"tv":1425.01}]}
{"op":"mcm","clk":"AM+SjwkAvuH7CQC7yosK","pt":1657534442500,"mc":[{"id":"1.200806927","rc":[{"atb":[[3.9,58.16]],"trd":[[3.9,1.26]],"tv":456.98,"id":2857977}],"tv":1426.03}]}
{"op":"mcm","clk":"ALqljwkAyfz7CQCm1osK","pt":1657534476255,"mc":[{"id":"1.200806927","rc":[{"trd":[[1.35,0.86]],"tv":969.22,"id":228749},{"atb":[[3.9,58.1]],"trd":[[3.9,1.33]],"tv":457.05,"id":2857977}],"tv":1426.27}]}
{"op":"mcm","clk":"ALfzjwkAit78CQD+g4wK","pt":1657534606361,"mc":[{"id":"1.200806927","rc":[{"atb":[[1.31,3.48]],"trd":[[1.31,31.03]],"ltp":1.31,"tv":979.22,"id":228749}],"tv":1436.27}]}
{"op":"mcm","clk":"AKjekAkArdb9CQDJ/YwK","pt":1657534800081,"mc":[{"id":"1.200806927","rc":[{"atb":[[1.26,0]],"id":228749}]}]}
{"op":"mcm","clk":"AMjekAkA1Nb9CQDf/YwK","pt":1657534800502,"mc":[{"id":"1.200806927","rc":[{"atb":[[1.21,223.13],[1.27,0]],"id":228749}]}]}
{"op":"mcm","clk":"ALHhkAkAyNn9CQCXgI0K","pt":1657534805204,"mc":[{"id":"1.200806927","rc":[{"atb":[[1.26,10]],"id":228749}]}]}
{"op":"mcm","clk":"AKzhkgkAkcT/CQDRoo4K","pt":1657535216553,"mc":[{"id":"1.200806927","rc":[{"atb":[[3.9,57.2]],"trd":[[3.9,3.12]],"tv":458.84,"id":2857977}],"tv":1438.06}]}
{"op":"mcm","clk":"ALPykgkA99n/CQCGr44K","pt":1657535250289,"mc":[{"id":"1.200806927","rc":[{"atb":[[3.9,55.4]],"trd":[[3.9,6.73]],"tv":462.45,"id":2857977}],"tv":1441.67}]}
{"op":"mcm","clk":"AIrQkwkA+MCACgDa5o4K","pt":1657535412777,"mc":[{"id":"1.200806927","rc":[{"atb":[[1.31,0],[1.3,0]],"trd":[[1.31,34.51],[1.3,231.04]],"ltp":1.3,"tv":1012.72,"id":228749},{"trd":[[4.4,10.99],[4.3,227.43]],"ltp":4.4,"tv":473.81,"id":2857977}],"tv":1486.53}]}
{"op":"mcm","clk":"AKnQkwkAk8GACgDm5o4K","pt":1657535413093,"mc":[{"id":"1.200806927","rc":[{"atl":[[5.8,0.85]],"id":2857977}]}]}
{"op":"mcm","clk":"AL7QkwkAq8GACgD05o4K","pt":1657535413346,"mc":[{"id":"1.200806927","rc":[{"atb":[[1.21,11.72]],"id":228749},{"atb":[[3.9,26.24]],"id":2857977}]}]}
{"op":"mcm","clk":"AMbSkwkA/cKACgDZ544K","pt":1657535416130,"mc":[{"id":"1.200806927","rc":[{"atl":[[5.8,0.3]],"id":2857977}]}]}
{"op":"mcm","clk":"AKzUkwkA08SACgDS6I4K","pt":1657535418739,"mc":[{"id":"1.200806927","rc":[{"atl":[[4.8,5.68]],"id":2857977}]}]}
{"op":"mcm","clk":"ANPUkwkA98SACgDu6I4K","pt":1657535419282,"mc":[{"id":"1.200806927","rc":[{"atb":[[1.21,223.13]],"id":228749},{"atb":[[3.95,28.67]],"id":2857977}]}]}
{"op":"mcm","clk":"AKfhkwkAjNCACgCu744K","pt":1657535437210,"mc":[{"id":"1.200806927","rc":[{"atb":[[3.45,0]],"id":2857977}]}]}
{"op":"mcm","clk":"AP2nlAkAyZaBCgDZm48K","pt":1657535552276,"mc":[{"id":"1.200806927","rc":[{"atl":[[1.33,0.26]],"id":228749}]}]}
{"op":"mcm","clk":"AO/DlAkAkLKBCgDSro8K","pt":1657535598935,"mc":[{"id":"1.200806927","rc":[{"atl":[[4.8,0]],"id":2857977}]}]}
{"op":"mcm","clk":"AKTElAkAxbKBCgCCr48K","pt":1657535599575,"mc":[{"id":"1.200806927","rc":[{"atb":[[1.21,11.72]],"id":228749},{"atb":[[3.95,0]],"id":2857977}]}]}
{"op":"mcm","clk":"AO/ElAkAj7OBCgC/r48K","pt":1657535600452,"mc":[{"id":"1.200806927","rc":[{"atl":[[4.8,5.68]],"id":2857977}]}]}
{"op":"mcm","clk":"AJXFlAkAw7OBCgDlr48K","pt":1657535600992,"mc":[{"id":"1.200806927","rc":[{"atb":[[1.21,223.13]],"id":228749},{"atb":[[3.95,28.67]],"id":2857977}]}]}
{"op":"mcm","clk":"AOfjlAkA3tKBCgD2xo8K","pt":1657535653180,"mc":[{"id":"1.200806927","rc":[{"atl":[[1.42,90.16]],"id":228749}]}]}
{"op":"mcm","clk":"ANSQlQkAwIOCCgCN7I8K","pt":1657535732103,"mc":[{"id":"1.200806927","rc":[{"atl":[[1.33,0]],"trd":[[1.33,1.04]],"ltp":1.33,"tv":1012.98,"id":228749},{"atb":[[3.95,28.54]],"trd":[[3.95,44.6],[4,0.09]],"ltp":3.95,"tv":474.16,"id":2857977}],"tv":1487.14}]}
{"op":"mcm","clk":"APCWlQkA+4iCCgDL748K","pt":1657535740414,"mc":[{"id":"1.200806927","rc":[{"atb":[[3.95,28.28]],"trd":[[3.95,45.12]],"tv":474.68,"id":2857977}],"tv":1487.66}]}
{"op":"mcm","clk":"AMavlQkAxaGCCgDFgZAK","pt":1657535776351,"mc":[{"id":"1.200806927","rc":[{"atb":[[3.95,28.11]],"trd":[[3.95,45.46]],"tv":475.02,"id":2857977}],"tv":1488}]}
{"op":"mcm","clk":"ALSylQkAkaSCCgC4g5AK","pt":1657535780676,"mc":[{"id":"1.200806927","rc":[{"atl":[[4.8,0]],"id":2857977}]}]}
{"op":"mcm","clk":"ANKylQkAq6SCCgDDg5AK","pt":1657535781016,"mc":[{"id":"1.200806927","rc":[{"atb":[[4,3.98]],"atl":[[4.7,5.68]],"id":2857977}]}]}
{"op":"mcm","clk":"ALu5lQkAxKuCCgDqiJAK","pt":1657535793469,"mc":[{"id":"1.200806927","rc":[{"atl":[[1.56,0]],"id":228749}]}]}
{"op":"mcm","clk":"AMi5lQkAzquCCgDtiJAK","pt":1657535793574,"mc":[{"id":"1.200806927","rc":[{"atl":[[1.61,60.16]],"id":228749}]}]}
{"op":"mcm","clk":"ALPBlQkA6bOCCgDXj5AK","pt":1657535807286,"mc":[{"id":"1.200806927","rc":[{"atl":[[1.61,0]],"id":228749}]}]}
{"op":"mcm","clk":"AMHBlQkA87OCCgDlj5AK","pt":1657535807472,"mc":[{"id":"1.200806927","rc":[{"atl":[[1.89,60.16]],"id":228749}]}]}
{"op":"mcm","clk":"AJ7VlQkA78aCCgCfoJAK","pt":1657535843158,"mc":[{"id":"1.200806927","rc":[{"trd":[[1.27,15.33]],"ltp":1.27,"tv":1028.31,"id":228749},{"atl":[[4.7,1.54]],"trd":[[4.7,45.61]],"ltp":4.7,"tv":479.16,"id":2857977}],"tv":1507.47}]}
{"op":"mcm","clk":"ANnVlQkApseCCgDPoJAK","pt":1657535843943,"mc":[{"id":"1.200806927","rc":[{"atb":[[1.21,11.72]],"id":228749},{"atb":[[3.95,0]],"id":2857977}]}]}
{"op":"mcm","clk":"ALTWlQkAk8iCCgCpoZAK","pt":1657535845295,"mc":[{"id":"1.200806927","rc":[{"atl":[[5.8,0]],"id":2857977}]}]}
{"op":"mcm","clk":"ALvWlQkAnMiCCgCzoZAK","pt":1657535845407,"mc":[{"id":"1.200806927","rc":[{"atl":[[990,0.3]],"id":2857977}]}]}
{"op":"mcm","clk":"AMrXlQkArcmCCgC1opAK","pt":1657535847390,"mc":[{"id":"1.200806927","rc":[{"atb":[[4,3.81]],"trd":[[4,0.43]],"ltp":4,"tv":479.5,"id":2857977}],"tv":1507.81}]}
{"op":"mcm","clk":"AKftlQkAhuCCCgDUtZAK","pt":1657535886152,"mc":[{"id":"1.200806927","rc":[{"atb":[[4,3.7]],"trd":[[4,0.64]],"tv":479.71,"id":2857977}],"tv":1508.02}]}
{"op":"mcm","clk":"ANOIlgkAh4KDCgD/zZAK","pt":1657535937149,"mc":[{"id":"1.200806927","rc":[{"atb":[[1.01,1459.83]],"id":228749},{"atb":[[1.01,1459.83]],"id":2857977}]}]}
{"op":"mcm","clk":"APuVlgkA05GDCgDf2JAK","pt":1657535961293,"mc":[{"id":"1.200806927","rc":[{"atl":[[4.7,0]],"id":2857977}]}]}
{"op":"mcm","clk":"AIOWlgkA55GDCgDq2JAK","pt":1657535961495,"mc":[{"id":"1.200806927","rc":[{"atb":[[4,0]],"id":2857977}]}]}
{"op":"mcm","clk":"AMWblgkAvJiDCgDk3JAK","pt":1657535970128,"mc":[{"id":"1.200806927","rc":[{"atb":[[3.95,3.76]],"trd":[[3.95,45.68]],"ltp":3.95,"tv":479.93,"id":2857977}],"tv":1508.24}]}
{"op":"mcm","clk":"ANmtlgkAs6+DCgDQ6pAK","pt":1657536003194,"mc":[{"id":"1.200806927","rc":[{"atl":[[2,1.08]],"id":228749}]}]}
{"op":"mcm","clk":"AKyulgkAjbCDCgCQ65AK","pt":1657536004179,"mc":[{"id":"1.200806927","rc":[{"atb":[[1.26,287.22]],"id":228749}]}]}
{"op":"mcm","clk":"AMCulgkApLCDCgCg65AK","pt":1657536004477,"mc":[{"id":"1.200806927","rc":[{"atb":[[1.27,211.42]],"id":228749},{"atb":[[3.9,55.4]],"id":2857977}]}]}
{"op":"mcm","clk":"ANLAlgkAociDCgDz95AK","pt":1657536038435,"mc":[{"id":"1.200806927","rc":[{"atb":[[1.01,1543.52]],"id":228749},{"atb":[[1.01,1543.52]],"id":2857977}]}]}
{"op":"mcm","clk":"APnWlgkA3+SDCgCkh5EK","pt":1657536078791,"mc":[{"id":"1.200806927","rc":[{"atb":[[1.27,207.11]],"trd":[[1.27,23.94]],"tv":1036.92,"id":228749}],"tv":1516.85}]}
{"op":"mcm","clk":"ANrYlgkAoOeDCgDKiJEK","pt":1657536082194,"mc":[{"id":"1.200806927","rc":[{"trd":[[1.34,83.3]],"ltp":1.34,"tv":1039.08,"id":228749},{"atb":[[3.95,3.02]],"trd":[[3.95,46.41]],"tv":480.66,"id":2857977}],"tv":1519.74}]}
{"op":"mcm","clk":"ALzflgkA8fCDCgCgjZEK","pt":1657536095427,"mc":[{"id":"1.200806927","rc":[{"trd":[[1.34,83.73]],"tv":1039.51,"id":228749},{"atb":[[3.95,2.88]],"trd":[[3.95,46.56]],"tv":480.81,"id":2857977}],"tv":1520.32}]}
{"op":"mcm","clk":"AOnrlgkA54KECgDelpEK","pt":1657536119759,"mc":[{"id":"1.200806927","rc":[{"atb":[[3.95,2.53]],"trd":[[3.95,47.25]],"tv":481.5,"id":2857977}],"tv":1521.01}]}
{"op":"mcm","clk":"AJv9lgkA+ZqECgCNo5EK","pt":1657536150518,"mc":[{"id":"1.200806927","rc":[{"atb":[[3.95,0]],"id":2857977}]}]}
{"op":"mcm","clk":"AK39lgkAmpuECgCdo5EK","pt":1657536150795,"mc":[{"id":"1.200806927","rc":[{"atb":[[1.01,1546.36]],"id":2857977}]}]}
{"op":"mcm","clk":"ALj9lgkArpuECgCno5EK","pt":1657536151009,"mc":[{"id":"1.200806927","rc":[{"atb":[[1.01,1546.05]],"id":2857977}]}]}
{"op":"mcm","clk":"ANL9lgkAxZuECgC3o5EK","pt":1657536151171,"mc":[{"id":"1.200806927","rc":[{"atb":[[1.01,1543.52]],"id":2857977}]}]}
{"op":"mcm","clk":"AIj+lgkAz5uECgDeo5EK","pt":1657536151283,"mc":[{"id":"1.200806927","rc":[{"atb":[[4,2.53]],"id":2857977}]}]}
{"op":"mcm","clk":"APf/lgkA4J2ECgCfpZEK","pt":1657536153777,"mc":[{"id":"1.200806927","rc":[{"atb":[[4,2.42]],"trd":[[4,0.86]],"ltp":4,"tv":481.72,"id":2857977}],"tv":1521.23}]}
{"op":"mcm","clk":"AKGelwkA+MWECgD8uZEK","pt":1657536207375,"mc":[{"id":"1.200806927","rc":[{"atb":[[1.26,58.29],[1.27,0]],"trd":[[1.26,233.48],[1.27,231.05]],"ltp":1.26,"tv":1475.55,"id":228749},{"trd":[[4.9,58.87],[4.8,56]],"ltp":4.9,"tv":595.39,"id":2857977}],"tv":2070.94}]}
{"op":"mcm","clk":"AL2elwkAmMaECgCHupEK","pt":1657536207693,"mc":[{"id":"1.200806927","rc":[{"atb":[[1.21,223.13]],"id":228749}]}]}
{"op":"mcm","clk":"AO+flwkA4MeECgDiupEK","pt":1657536209893,"mc":[{"id":"1.200806927","rc":[{"atb":[[1.26,287.22]],"id":228749}]}]}
{"op":"mcm","clk":"AO+llwkA+s6ECgCCv5EK","pt":1657536219920,"mc":[{"id":"1.200806927","rc":[{"atb":[[1.26,0]],"id":228749}]}]}
{"op":"mcm","clk":"AIGmlwkAks+ECgCSv5EK","pt":1657536220240,"mc":[{"id":"1.200806927","rc":[{"atb":[[1.21,11.72]],"id":228749},{"atb":[[3.9,26.24]],"id":2857977}]}]}
{"op":"mcm","clk":"AI+mlwkAos+ECgCbv5EK","pt":1657536220399,"mc":[{"id":"1.200806927","rc":[{"atl":[[990,0]],"id":2857977}]}]}
{"op":"mcm","clk":"AJemlwkAr8+ECgCdv5EK","pt":1657536220507,"mc":[{"id":"1.200806927","rc":[{"atl":[[5.8,0.3]],"id":2857977}]}]}
{"op":"mcm","clk":"ANanlwkAtdGECgDdwJEK","pt":1657536223427,"mc":[{"id":"1.200806927","rc":[{"atl":[[5.8,0]],"id":2857977}]}]}
{"op":"mcm","clk":"AN+nlwkAwNGECgDjwJEK","pt":1657536223523,"mc":[{"id":"1.200806927","rc":[{"atl":[[100,0.3]],"id":2857977}]}]}
{"op":"mcm","clk":"AJmplwkA+9OECgCWwpEK","pt":1657536226947,"mc":[{"id":"1.200806927","rc":[{"atb":[[4.9,20.38]],"id":2857977}]}]}
{"op":"mcm","clk":"AKKplwkAmtSECgCmwpEK","pt":1657536227248,"mc":[{"id":"1.200806927","rc":[{"atb":[[5,21.14]],"id":2857977}]}]}
{"op":"mcm","clk":"AIWvlwkAwtuECgCEx5EK","pt":1657536238149,"mc":[{"id":"1.200806927","rc":[{"atb":[[4.9,0]],"id":2857977}]}]}
{"op":"mcm","clk":"ALGvlwkAgNyECgCkx5EK","pt":1657536238725,"mc":[{"id":"1.200806927","rc":[{"atb":[[5,0]],"id":2857977}]}]}
{"op":"mcm","clk":"AISylwkA9d+ECgDmyZEK","pt":1657536244261,"mc":[{"id":"1.200806927","rc":[{"atl":[[5,1.08]],"id":2857977}]}]}
{"op":"mcm","clk":"AIK7lwkAqOyECgCM0pEK","pt":1657536261511,"mc":[{"id":"1.200806927","rc":[{"atb":[[1.25,49.51]],"id":228749}]}]}
{"op":"mcm","clk":"AJO7lwkAv+yECgCb0pEK","pt":1657536261790,"mc":[{"id":"1.200806927","rc":[{"atb":[[1.21,223.13]],"id":228749},{"atb":[[3.95,28.67]],"id":2857977}]}]}
{"op":"mcm","clk":"AMi8lwkA3e6ECgC+05EK","pt":1657536264510,"mc":[{"id":"1.200806927","rc":[{"atb":[[3.9,0]],"id":2857977}]}]}
{"op":"mcm","clk":"AM+8lwkA6O6ECgDC05EK","pt":1657536264640,"mc":[{"id":"1.200806927","rc":[{"atb":[[3.95,54.91]],"id":2857977}]}]}
{"op":"mcm","clk":"ANS8lwkAgu+ECgDN05EK","pt":1657536264782,"mc":[{"id":"1.200806927","rc":[{"atb":[[3.4,35.24],[3.95,26.24]],"id":2857977}]}]}
{"op":"mcm","clk":"APe8lwkAqe+ECgDq05EK","pt":1657536265315,"mc":[{"id":"1.200806927","rc":[{"atb":[[3.4,0],[4,2.25]],"trd":[[4,1.2]],"ltp":4,"tv":595.73,"id":2857977}],"tv":2071.28}]}
{"op":"mcm","clk":"AJK9lwkAz++ECgCI1JEK","pt":1657536265806,"mc":[{"id":"1.200806927","rc":[{"atb":[[4,30.44]],"id":2857977}]}]}
{"op":"mcm","clk":"ALDDlwkAgviECgCK2pEK","pt":1657536279029,"mc":[{"id":"1.200806927","rc":[{"atb":[[3.95,0]],"id":2857977}]}]}
{"op":"mcm","clk":"ALbDlwkAjviECgCS2pEK","pt":1657536279135,"mc":[{"id":"1.200806927","rc":[{"atb":[[4.1,26.24]],"id":2857977}]}]}
{"op":"mcm","clk":"AMHDlwkAnfiECgCZ2pEK","pt":1657536279333,"mc":[{"id":"1.200806927","rc":[{"atb":[[3.4,35.24],[4,2.25]],"id":2857977}]}]}
{"op":"mcm","clk":"AN3DlwkAzviECgC12pEK","pt":1657536279816,"mc":[{"id":"1.200806927","rc":[{"atb":[[3.4,0]],"id":2857977}]}]}
{"op":"mcm","clk":"APzDlwkAiPmECgDZ2pEK","pt":1657536280340,"mc":[{"id":"1.200806927","rc":[{"atb":[[4.2,26.43]],"id":2857977}]}]}
{"op":"mcm","clk":"AOrSlwkA5ouFCgDv55EK","pt":1657536308272,"mc":[{"id":"1.200806927","rc":[{"atb":[[1.01,1627.21]],"id":228749},{"atb":[[1.01,1627.21]],"id":2857977}]}]}
{"op":"mcm","clk":"ANPclwkAkJaFCgCs75EK","pt":1657536325371,"mc":[{"id":"1.200806927","rc":[{"atb":[[1.25,0]],"atl":[[1.25,396.99]],"trd":[[1.25,4.31]],"ltp":1.25,"tv":1479.86,"id":228749},{"atl":[[5,0]],"trd":[[5,1.08]],"ltp":5,"tv":596.81,"id":2857977}],"tv":2076.67}]}
{"op":"mcm","clk":"APXclwkArZaFCgDA75EK","pt":1657536325878,"mc":[{"id":"1.200806927","rc":[{"atb":[[1.21,11.72]],"id":228749},{"atb":[[4.2,0],[5.1,20.63]],"id":2857977}]}]}
{"op":"mcm","clk":"AKXglwkAlpmFCgDa8ZEK","pt":1657536331513,"mc":[{"id":"1.200806927","rc":[{"atb":[[4,0]],"id":2857977}]}]}
{"op":"mcm","clk":"AIDilwkA/pqFCgCh85EK","pt":1657536334608,"mc":[{"id":"1.200806927","rc":[{"atl":[[1.42,0]],"id":228749}]}]}
{"op":"mcm","clk":"AJ3klwkAxZ2FCgCz9ZEK","pt":1657536339214,"mc":[{"id":"1.200806927","rc":[{"atb":[[1.22,132.54]],"id":228749}]}]}
{"op":"mcm","clk":"AMrklwkA9J2FCgDT9ZEK","pt":1657536339784,"mc":[{"id":"1.200806927","rc":[{"atb":[[1.21,223.13]],"id":228749},{"atb":[[4.9,21.68],[5.1,0]],"id":2857977}]}]}
{"op":"mcm","clk":"APvklwkAp56FCgCD9pEK","pt":1657536340490,"mc":[{"id":"1.200806927","rc":[{"atl":[[100,0]],"id":2857977}]}]}
{"op":"mcm","clk":"AILllwkAtZ6FCgCJ9pEK","pt":1657536340631,"mc":[{"id":"1.200806927","rc":[{"atl":[[5.6,0.3]],"id":2857977}]}]}
{"op":"mcm","clk":"APrqlwkAx6WFCgDp+pEK","pt":1657536352239,"mc":[{"id":"1.200806927","rc":[{"atl":[[1.25,396.56]],"trd":[[1.25,4.74]],"tv":1480.29,"id":228749},{"trd":[[5,1.18]],"tv":596.91,"id":2857977}],"tv":2077.2}]}
{"op":"mcm","clk":"AM7ylwkA16+FCgDvgJIK","pt":1657536367260,"mc":[{"id":"1.200806927","rc":[{"atl":[[1.25,385.72]],"trd":[[1.25,15.58]],"tv":1491.13,"id":228749},{"trd":[[5,3.89]],"tv":599.62,"id":2857977}],"tv":2090.75}]}
{"op":"mcm","clk":"AMbzlwkAmLGFCgDagZIK","pt":1657536369344,"mc":[{"id":"1.200806927","rc":[{"atl":[[1.25,385.29]],"trd":[[1.25,16.01]],"tv":1491.56,"id":228749},{"trd":[[5,4]],"tv":599.73,"id":2857977}],"tv":2091.29}]}
{"op":"mcm","clk":"AIb7lwkA2LuFCgCaiJIK","pt":1657536385094,"mc":[{"id":"1.200806927","rc":[{"atl":[[1.25,385.12]],"trd":[[1.25,16.35]],"tv":1491.9,"id":228749}],"tv":2091.63}]}
{"op":"mcm","clk":"ALqDmAkA38WFCgC/jpIK","pt":1657536400970,"mc":[{"id":"1.200806927","rc":[{"atb":[[1.22,265.08]],"id":228749}]}]}
{"op":"mcm","clk":"AJeHmAkAm8qFCgCSkZIK","pt":1657536408034,"mc":[{"id":"1.200806927","rc":[{"atb":[[1.22,132.54]],"id":228749}]}]}
{"op":"mcm","clk":"ALyKmAkAks+FCgCqlJIK","pt":1657536415637,"mc":[{"id":"1.200806927","rc":[{"atb":[[1.1,100]],"id":228749}]}]}
{"op":"mcm","clk":"ANyKmAkAzM+FCgDQlJIK","pt":1657536416252,"mc":[{"id":"1.200806927","rc":[{"atb":[[1.09,111.11]],"id":228749}]}]}
{"op":"mcm","clk":"APqKmAkAhdCFCgDzlJIK","pt":1657536416838,"mc":[{"id":"1.200806927","rc":[{"atb":[[1.08,273.13]],"id":228749}]}]}
{"op":"mcm","clk":"AJmLmAkAuNCFCgCLlZIK","pt":1657536417459,"mc":[{"id":"1.200806927","rc":[{"atb":[[1.07,142.86]],"id":228749}]}]}
{"op":"mcm","clk":"ALWLmAkA5NCFCgCqlZIK","pt":1657536418020,"mc":[{"id":"1.200806927","rc":[{"atb":[[1.06,166.67]],"id":228749}]}]}
{"op":"mcm","clk":"AOqLmAkA6NGFCgDZlZIK","pt":1657536418943,"mc":[{"id":"1.200806927","rc":[{"atb":[[1.05,300]],"id":228749}]}]}
{"op":"mcm","clk":"APqLmAkAgdKFCgDtlZIK","pt":1657536419244,"mc":[{"id":"1.200806927","rc":[{"atb":[[1.23,154.23]],"id":228749}]}]}
{"op":"mcm","clk":"AI6MmAkAndKFCgCGlpIK","pt":1657536419620,"mc":[{"id":"1.200806927","rc":[{"atb":[[1.04,252.05]],"id":228749}]}]}
{"op":"mcm","clk":"ALmMmAkA2dKFCgC6lpIK","pt":1657536420460,"mc":[{"id":"1.200806927","rc":[{"atb":[[1.03,400.17]],"id":228749}]}]}
{"op":"mcm","clk":"AIiNmAkAoNOFCgCAl5IK","pt":1657536421133,"mc":[{"id":"1.200806927","rc":[{"atb":[[1.02,599.76]],"id":228749}]}]}
{"op":"mcm","clk":"AJmNmAkAt9OFCgCYl5IK","pt":1657536421437,"mc":[{"id":"1.200806927","rc":[{"atl":[[5.6,0]],"id":2857977}]}]}
{"op":"mcm","clk":"AJ6NmAkAwNOFCgCcl5IK","pt":1657536421538,"mc":[{"id":"1.200806927","rc":[{"atl":[[5.4,0.3]],"id":2857977}]}]}
{"op":"mcm","clk":"ALaNmAkA3tOFCgCul5IK","pt":1657536421876,"mc":[{"id":"1.200806927","rc":[{"atb":[[1.01,2627.21]],"id":228749}]}]}
{"op":"mcm","clk":"AN2PmAkAudaFCgDBmZIK","pt":1657536426082,"mc":[{"id":"1.200806927","rc":[{"atb":[[1.1,100]],"id":2857977}]}]}
{"op":"mcm","clk":"APWPmAkA8NaFCgDvmZIK","pt":1657536426768,"mc":[{"id":"1.200806927","rc":[{"atb":[[1.09,111.11]],"id":2857977}]}]}
{"op":"mcm","clk":"AJ+QmAkAuteFCgCgmpIK","pt":1657536427549,"mc":[{"id":"1.200806927","rc":[{"atb":[[1.08,125]],"id":2857977}]}]}
{"op":"mcm","clk":"AMqQmAkAgNiFCgDKmpIK","pt":1657536428363,"mc":[{"id":"1.200806927","rc":[{"atb":[[1.07,142.86]],"id":2857977}]}]}
{"op":"mcm","clk":"AOqQmAkAvNiFCgDqmpIK","pt":1657536429058,"mc":[{"id":"1.200806927","rc":[{"atb":[[1.06,166.67]],"id":2857977}]}]}
{"op":"mcm","clk":"AP+QmAkA39iFCgD8mpIK","pt":1657536429460,"mc":[{"id":"1.200806927","rc":[{"atl":[[1.25,384.26]],"trd":[[1.25,17.21]],"tv":1492.76,"id":228749},{"trd":[[5,4.22]],"tv":599.95,"id":2857977}],"tv":2092.71}]}
{"op":"mcm","clk":"AImRmAkA79iFCgCJm5IK","pt":1657536429670,"mc":[{"id":"1.200806927","rc":[{"atb":[[1.05,300]],"id":2857977}]}]}
{"op":"mcm","clk":"AKmRmAkAntmFCgCkm5IK","pt":1657536430283,"mc":[{"id":"1.200806927","rc":[{"atb":[[1.04,252.05]],"id":2857977}]}]}
{"op":"mcm","clk":"ANGRmAkA6tmFCgDNm5IK","pt":1657536430964,"mc":[{"id":"1.200806927","rc":[{"atb":[[1.03,400.17]],"id":2857977}]}]}
{"op":"mcm","clk":"APCRmAkAkNqFCgDrm5IK","pt":1657536431468,"mc":[{"id":"1.200806927","rc":[{"atb":[[1.02,599.76]],"id":2857977}]}]}
{"op":"mcm","clk":"AMSSmAkAl9uFCgDEnJIK","pt":1657536433240,"mc":[{"id":"1.200806927","rc":[{"atb":[[1.01,2627.21]],"id":2857977}]}]}
{"op":"mcm","clk":"AIWTmAkAiNyFCgCKnZIK","pt":1657536434528,"mc":[{"id":"1.200806927","rc":[{"atb":[[1.23,0]],"id":228749}]}]}
{"op":"mcm","clk":"AI2TmAkAn9yFCgCWnZIK","pt":1657536434723,"mc":[{"id":"1.200806927","rc":[{"atb":[[1.23,154.23]],"id":228749}]}]}
{"op":"mcm","clk":"AMuUmAkAxN6FCgDmnpIK","pt":1657536438270,"mc":[{"id":"1.200806927","rc":[{"atl":[[1.25,380.66]],"trd":[[1.25,20.81]],"tv":1496.36,"id":228749},{"trd":[[5,5.12]],"tv":600.85,"id":2857977}],"tv":2097.21}]}
{"op":"mcm","clk":"AIecmAkAtumFCgCQppIK","pt":1657536454280,"mc":[{"id":"1.200806927","rc":[{"atb":[[1.23,0]],"id":228749}]}]}
{"op":"mcm","clk":"AO6dmAkAx+uFCgC1p5IK","pt":1657536457495,"mc":[{"id":"1.200806927","rc":[{"atl":[[5.4,0]],"id":2857977}]}]}
{"op":"mcm","clk":"APSdmAkA0+uFCgC8p5IK","pt":1657536457562,"mc":[{"id":"1.200806927","rc":[{"atl":[[5.6,0.3]],"id":2857977}]}]}
{"op":"mcm","clk":"AJafmAkAhe2FCgDMqJIK","pt":1657536459973,"mc":[{"id":"1.200806927","rc":[{"atb":[[1.23,0.11]],"id":228749}]}]}
{"op":"mcm","clk":"AOKvmAkA1oCGCgCVtpIK","pt":1657536490497,"mc":[{"id":"1.200806927","rc":[{"atl":[[1.25,378.94]],"trd":[[1.25,24.26]],"tv":1499.81,"id":228749}],"tv":2100.66}]}
{"op":"mcm","clk":"AMKymAkAzIOGCgChuJIK","pt":1657536495575,"mc":[{"id":"1.200806927","rc":[{"atl":[[1.25,375.49]],"trd":[[1.25,27.71]],"tv":1503.26,"id":228749},{"trd":[[5,5.98]],"tv":601.71,"id":2857977}],"tv":2104.97}]}
{"op":"mcm","clk":"AMSzmAkA9oSGCgCQuZIK","pt":1657536497498,"mc":[{"id":"1.200806927","rc":[{"atl":[[1.25,373.77]],"trd":[[1.25,31.15]],"tv":1506.7,"id":228749}],"tv":2108.41}]}
{"op":"mcm","clk":"APq1mAkAt4eGCgD+upIK","pt":1657536501778,"mc":[{"id":"1.200806927","rc":[{"atl":[[1.25,370.17]],"trd":[[1.25,34.75]],"tv":1510.3,"id":228749},{"trd":[[5,6.88]],"tv":602.61,"id":2857977}],"tv":2112.91}]}
{"op":"mcm","clk":"AIa4mAkA24mGCgDBvJIK","pt":1657536505507,"mc":[{"id":"1.200806927","rc":[{"atb":[[1.01,2648.13]],"id":228749},{"atb":[[1.01,2648.13]],"id":2857977}]}]}
{"op":"mcm","clk":"AKu4mAkAiIqGCgDevJIK","pt":1657536506094,"mc":[{"id":"1.200806927","rc":[{"atl":[[1.25,369.74]],"trd":[[1.25,35.18]],"tv":1510.73,"id":228749},{"trd":[[5,6.98]],"tv":602.71,"id":2857977}],"tv":2113.44}]}
{"op":"mcm","clk":"AMT8mAkArKOGCgC4zpIK","pt":1657536546464,"mc":[{"id":"1.200806927","rc":[{"atl":[[1.25,368.88]],"trd":[[1.25,36.9]],"tv":1512.45,"id":228749}],"tv":2115.16}]}
{"op":"mcm","clk":"AKz+mAkAyKWGCgDzz5IK","pt":1657536549985,"mc":[{"id":"1.200806927","rc":[{"atl":[[1.25,367.16]],"trd":[[1.25,40.34]],"tv":1515.89,"id":228749}],"tv":2118.6}]}
{"op":"mcm","clk":"AMj/mAkAqaeGCgDI0JIK","pt":1657536552272,"mc":[{"id":"1.200806927","rc":[{"atl":[[5.5,5.4]],"id":2857977}]}]}
{"op":"mcm","clk":"ANr/mAkAv6eGCgDX0JIK","pt":1657536552572,"mc":[{"id":"1.200806927","rc":[{"atb":[[1.22,170.76]],"id":228749},{"atb":[[5.1,1.95]],"id":2857977}]}]}
{"op":"mcm","clk":"AIqAmQkAj6iGCgCG0ZIK","pt":1657536553466,"mc":[{"id":"1.200806927","rc":[{"atl":[[5.6,0]],"id":2857977}]}]}
{"op":"mcm","clk":"AI2AmQkAl6iGCgCI0ZIK","pt":1657536553553,"mc":[{"id":"1.200806927","rc":[{"atl":[[5.5,5.7]],"id":2857977}]}]}
{"op":"mcm","clk":"AOeAmQkAjKmGCgDL0ZIK","pt":1657536555004,"mc":[{"id":"1.200806927","rc":[{"atb":[[1.22,132.54]],"id":228749}]}]}
{"op":"mcm","clk":"AIWGmQkAta+GCgDg1JIK","pt":1657536564504,"mc":[{"id":"1.200806927","rc":[{"atb":[[1.22,170.78]],"id":228749}]}]}
{"op":"mcm","clk":"AMqImQkAq7OGCgCA15IK","pt":1657536569824,"mc":[{"id":"1.200806927","rc":[{"atl":[[5.5,0.3]],"id":2857977}]}]}
{"op":"mcm","clk":"AM+ImQkAsbOGCgCH15IK","pt":1657536569904,"mc":[{"id":"1.200806927","rc":[{"atl":[[5.3,5.4]],"id":2857977}]}]}
{"op":"mcm","clk":"ANeImQkAw7OGCgCO15IK","pt":1657536570022,"mc":[{"id":"1.200806927","rc":[{"atb":[[1.22,132.54]],"id":228749},{"atb":[[5.1,0]],"id":2857977}]}]}
{"op":"mcm","clk":"AKyJmQkArbSGCgDg15IK","pt":1657536571509,"mc":[{"id":"1.200806927","rc":[{"atl":[[5.5,0]],"id":2857977}]}]}
{"op":"mcm","clk":"ALKJmQkAvLSGCgDq15IK","pt":1657536571622,"mc":[{"id":"1.200806927","rc":[{"atl":[[5.3,5.7]],"id":2857977}]}]}
{"op":"mcm","clk":"AICMmQkAgLiGCgD32ZIK","pt":1657536576416,"mc":[{"id":"1.200806927","rc":[{"atb":[[1.22,170.8]],"id":228749}]}]}
{"op":"mcm","clk":"ANqMmQkA8biGCgC12pIK","pt":1657536577619,"mc":[{"id":"1.200806927","rc":[{"atl":[[5.3,0.3]],"id":2857977}]}]}
{"op":"mcm","clk":"AN+MmQkA+7iGCgC82pIK","pt":1657536577716,"mc":[{"id":"1.200806927","rc":[{"atl":[[5.2,5.4]],"id":2857977}]}]}
{"op":"mcm","clk":"AOiMmQkAi7mGCgC+2pIK","pt":1657536577812,"mc":[{"id":"1.200806927","rc":[{"atb":[[1.22,132.54]],"id":228749}]}]}
{"op":"mcm","clk":"AO6MmQkAlrmGCgDG2pIK","pt":1657536577926,"mc":[{"id":"1.200806927","rc":[{"atl":[[5.2,0]],"trd":[[5.2,10.79]],"ltp":5.2,"tv":613.5,"id":2857977}],"tv":2129.39}]}
{"op":"mcm","clk":"AMSimQkAwtKGCgDg6pIK","pt":1657536616517,"mc":[{"id":"1.200806927","rc":[{"atl":[[1.25,367.11]],"trd":[[1.25,40.44]],"tv":1515.99,"id":228749}],"tv":2129.49}]}
{"op":"mcm","clk":"APaomQkA9NmGCgDb7pIK","pt":1657536627107,"mc":[{"id":"1.200806927","rc":[{"atl":[[1.25,366.68]],"trd":[[1.25,40.87]],"tv":1516.42,"id":228749},{"trd":[[5,7.09]],"ltp":5,"tv":613.61,"id":2857977}],"tv":2130.03}]}
{"op":"mcm","clk":"AISsmQkAyt2GCgDr8JIK","pt":1657536632326,"mc":[{"id":"1.200806927","rc":[{"atl":[[1.25,364.96]],"trd":[[1.25,42.59]],"tv":1518.14,"id":228749},{"trd":[[5,7.52]],"tv":614.04,"id":2857977}],"tv":2132.18}]}
{"op":"mcm","clk":"ANysmQkAqN6GCgCo8ZIK","pt":1657536633428,"mc":[{"id":"1.200806927","rc":[{"atl":[[1.25,363.74]],"trd":[[1.25,43.81]],"tv":1519.36,"id":228749},{"trd":[[5,7.83]],"tv":614.35,"id":2857977}],"tv":2133.71}]}
{"op":"mcm","clk":"AKOtmQkAj9+GCgDh8ZIK","pt":1657536634519,"mc":[{"id":"1.200806927","rc":[{"atl":[[1.5,11.37]],"id":228749}]}]}
{"op":"mcm","clk":"APOvmQkA+uGGCgDJ85IK","pt":1657536638818,"mc":[{"id":"1.200806927","rc":[{"atb":[[1.16,1.69]],"id":2857977}]}]}
{"op":"mcm","clk":"AJKwmQkAleKGCgDY85IK","pt":1657536639134,"mc":[{"id":"1.200806927","rc":[{"atb":[[1.16,0.04]],"id":2857977}]}]}
{"op":"mcm","clk":"AKKwmQkAo+KGCgDm85IK","pt":1657536639342,"mc":[{"id":"1.200806927","rc":[{"atb":[[1.16,0]],"id":2857977}]}]}
{"op":"mcm","clk":"AKywmQkAteKGCgDs85IK","pt":1657536639461,"mc":[{"id":"1.200806927","rc":[{"atb":[[1.51,0.04]],"id":2857977}]}]}
{"op":"mcm","clk":"AOSymQkAqeSGCgC49ZIK","pt":1657536643248,"mc":[{"id":"1.200806927","rc":[{"atl":[[1.25,360.14]],"trd":[[1.25,47.41]],"tv":1522.96,"id":228749},{"trd":[[5,8.73]],"tv":615.25,"id":2857977}],"tv":2138.21}]}
{"op":"mcm","clk":"AMmzmQkAjOWGCgCK9pIK","pt":1657536644645,"mc":[{"id":"1.200806927","rc":[{"atb":[[1.51,0]],"id":2857977}]}]}
{"op":"mcm","clk":"ALC0mQkA/OWGCgDW9pIK","pt":1657536646057,"mc":[{"id":"1.200806927","rc":[{"atb":[[1.51,84.57]],"id":2857977}]}]}
{"op":"mcm","clk":"AOi+mQkA6/GGCgDC/ZIK","pt":1657536663082,"mc":[{"id":"1.200806927","rc":[{"atb":[[1.08,357.7]],"id":228749}]}]}
{"op":"mcm","clk":"APS+mQkA/PGGCgDL/ZIK","pt":1657536663233,"mc":[{"id":"1.200806927","rc":[{"atb":[[1.08,442.27]],"id":228749}]}]}
{"op":"mcm","clk":"AIy/mQkAkvKGCgDi/ZIK","pt":1657536663550,"mc":[{"id":"1.200806927","rc":[{"atb":[[1.08,526.83]],"id":228749}]}]}
{"op":"mcm","clk":"AKe/mQkArfKGCgD1/ZIK","pt":1657536663870,"mc":[{"id":"1.200806927","rc":[{"atb":[[1.08,611.4]],"id":228749}]}]}
{"op":"mcm","clk":"ANa/mQkA6PKGCgCq/pIK","pt":1657536664575,"mc":[{"id":"1.200806927","rc":[{"atl":[[5.3,0]],"id":2857977}]}]}
{"op":"mcm","clk":"ANi/mQkA8fKGCgCs/pIK","pt":1657536664674,"mc":[{"id":"1.200806927","rc":[{"atl":[[5.6,0.3]],"id":2857977}]}]}
{"op":"mcm","clk":"AJHAmQkApvOGCgDS/pIK","pt":1657536665261,"mc":[{"id":"1.200806927","rc":[{"atb":[[1.1,184.57]],"id":228749}]}]}
{"op":"mcm","clk":"ALjAmQkA0vOGCgCB/5IK","pt":1657536665870,"mc":[{"id":"1.200806927","rc":[{"atb":[[1.1,269.13]],"id":228749}]}]}
{"op":"mcm","clk":"AMvAmQkA5fOGCgCQ/5IK","pt":1657536666141,"mc":[{"id":"1.200806927","rc":[{"atb":[[1.1,353.7]],"id":228749}]}]}
{"op":"mcm","clk":"AMnCmQkAg/aGCgDEgJMK","pt":1657536669353,"mc":[{"id":"1.200806927","rc":[{"atb":[[1.25,39.86]],"atl":[[1.25,0]],"trd":[[1.25,767.69]],"tv":2243.24,"id":228749}],"tv":2858.49}]}
{"op":"mcm","clk":"AOHCmQkAofaGCgDUgJMK","pt":1657536669764,"mc":[{"id":"1.200806927","rc":[{"atb":[[4.2,26.43]],"id":2857977}]}]}
{"op":"mcm","clk":"AOfCmQkAqfaGCgDZgJMK","pt":1657536669869,"mc":[{"id":"1.200806927","rc":[{"atb":[[4.9,0]],"id":2857977}]}]}
{"op":"mcm","clk":"AKTFmQkAn/mGCgDEgpMK","pt":1657536674077,"mc":[{"id":"1.200806927","rc":[{"atb":[[1.25,0]],"id":228749}]}]}
{"op":"mcm","clk":"AMjFmQkAzPmGCgDigpMK","pt":1657536674647,"mc":[{"id":"1.200806927","rc":[{"atl":[[5.5,0.9]],"id":2857977}]}]}
{"op":"mcm","clk":"AN/FmQkA5fmGCgDsgpMK","pt":1657536675062,"mc":[{"id":"1.200806927","rc":[{"atb":[[1.01,2650.98]],"id":2857977}]}]}
{"op":"mcm","clk":"APDFmQkA9/mGCgD2gpMK","pt":1657536675272,"mc":[{"id":"1.200806927","rc":[{"atb":[[1.01,2650.38]],"id":2857977}]}]}
{"op":"mcm","clk":"APXFmQkAgvqGCgD6gpMK","pt":1657536675374,"mc":[{"id":"1.200806927","rc":[{"atb":[[1.01,2648.13]],"id":2857977}]}]}
{"op":"mcm","clk":"APzFmQkAjPqGCgD/gpMK","pt":1657536675466,"mc":[{"id":"1.200806927","rc":[{"atb":[[4.3,2.25]],"id":2857977}]}]}
{"op":"mcm","clk":"AInImQkAgP2GCgD2hJMK","pt":1657536679997,"mc":[{"id":"1.200806927","rc":[{"atb":[[1.23,11.82]],"id":228749}]}]}
{"op":"mcm","clk":"ALPJmQkAvv6GCgD/hZMK","pt":1657536682599,"mc":[{"id":"1.200806927","rc":[{"atl":[[3.5,11.31]],"id":228749}]}]}
{"op":"mcm","clk":"AMfKmQkArYCHCgCFh5MK","pt":1657536685021,"mc":[{"id":"1.200806927","rc":[{"atb":[[1.22,113.67],[1.23,0]],"trd":[[1.22,124.97],[1.23,59.08]],"ltp":1.22,"tv":2273.93,"id":228749},{"atl":[[5.5,0],[5.6,0]],"trd":[[5.4,2.69],[5.5,1.8],[5.6,4.71]],"ltp":5.6,"tv":624.45,"id":2857977}],"tv":2898.38}]}
{"op":"mcm","clk":"AO3KmQkA3ICHCgCah5MK","pt":1657536685515,"mc":[{"id":"1.200806927","rc":[{"atb":[[4.2,27.27]],"id":2857977}]}]}
{"op":"mcm","clk":"AJPMmQkAkYOHCgC5iJMK","pt":1657536688618,"mc":[{"id":"1.200806927","rc":[{"atb":[[4.2,26.88]],"id":2857977}]}]}
{"op":"mcm","clk":"AK/ZmQkAopWHCgCDk5MK","pt":1657536713869,"mc":[{"id":"1.200806927","rc":[{"atl":[[4.8,0.17]],"id":2857977}]}]}
{"op":"mcm","clk":"AIDamQkAo5aHCgDek5MK","pt":1657536715282,"mc":[{"id":"1.200806927","rc":[{"atb":[[1.23,231.82]],"id":228749}]}]}
{"op":"mcm","clk":"AJPamQkAu5aHCgDsk5MK","pt":1657536715552,"mc":[{"id":"1.200806927","rc":[{"atb":[[1.23,234.77]],"id":228749}]}]}
{"op":"mcm","clk":"AKvamQkA05aHCgD2k5MK","pt":1657536715860,"mc":[{"id":"1.200806927","rc":[{"atb":[[1.24,211.42]],"id":228749},{"atb":[[4.2,0.45],[4.1,53.52]],"id":2857977}]}]}
{"op":"mcm","clk":"ANDbmQkAzZiHCgC1lZMK","pt":1657536718478,"mc":[{"id":"1.200806927","rc":[{"atb":[[4.2,0]],"id":2857977}]}]}
{"op":"mcm","clk":"ANXbmQkA05iHCgC6lZMK","pt":1657536718567,"mc":[{"id":"1.200806927","rc":[{"atb":[[1.06,167.12]],"id":2857977}]}]}
{"op":"mcm","clk":"ALPjmQkA0KOHCgCGnZMK","pt":1657536733168,"mc":[{"id":"1.200806927","rc":[{"atl":[[1.3,49.51]],"id":228749}]}]}
{"op":"mcm","clk":"AMfjmQkA4qOHCgCQnZMK","pt":1657536733390,"mc":[{"id":"1.200806927","rc":[{"atb":[[1.23,231.82]],"id":228749},{"atb":[[4.1,55.21]],"id":2857977}]}]}
{"op":"mcm","clk":"ANHjmQkA7qOHCgCUnZMK","pt":1657536733482,"mc":[{"id":"1.200806927","rc":[{"atb":[[1.06,166.67]],"id":2857977}]}]}
{"op":"mcm","clk":"ANrjmQkA+aOHCgCYnZMK","pt":1657536733597,"mc":[{"id":"1.200806927","rc":[{"atb":[[4.3,2.7]],"id":2857977}]}]}
{"op":"mcm","clk":"AO/jmQkAmKSHCgCinZMK","pt":1657536733900,"mc":[{"id":"1.200806927","rc":[{"atb":[[4.3,28.32]],"id":2857977}]}]}
{"op":"mcm","clk":"AKnkmQkA5qSHCgDRnZMK","pt":1657536734776,"mc":[{"id":"1.200806927","rc":[{"atb":[[1.51,169.13]],"id":2857977}]}]}
{"op":"mcm","clk":"AK3mmQkAj6iHCgCxn5MK","pt":1657536739309,"mc":[{"id":"1.200806927","rc":[{"atb":[[1.01,2669.06]],"id":228749},{"atb":[[1.01,2669.06]],"id":2857977}]}]}
{"op":"mcm","clk":"AILrmQkAr6+HCgD1o5MK","pt":1657536750448,"mc":[{"id":"1.200806927","rc":[{"atb":[[1.24,204.68]],"trd":[[1.24,13.46],[1.26,234.14]],"ltp":1.24,"tv":2288.05,"id":228749},{"atl":[[4.8,0]],"trd":[[4.8,56.17]],"ltp":4.8,"tv":624.62,"id":2857977}],"tv":2912.67}]}
{"op":"mcm","clk":"AM71mQkAmr+HCgCWrJMK","pt":1657536772875,"mc":[{"id":"1.200806927","rc":[{"atb":[[4.1,53.52]],"id":2857977}]}]}
{"op":"mcm","clk":"ALmJmgkA9tmHCgDCu5MK","pt":1657536812272,"mc":[{"id":"1.200806927","rc":[{"atb":[[4.3,27.25]],"trd":[[4.3,229.58]],"ltp":4.3,"tv":626.77,"id":2857977}],"tv":2914.82}]}
{"op":"mcm","clk":"AIeKmgkA79qHCgCMvJMK","pt":1657536813503,"mc":[{"id":"1.200806927","rc":[{"atb":[[4.3,25.52]],"trd":[[4.3,233.03]],"tv":630.22,"id":2857977}],"tv":2918.27}]}
{"op":"mcm","clk":"AK+KmgkAnduHCgCcvJMK","pt":1657536813962,"mc":[{"id":"1.200806927","rc":[{"atb":[[4.3,0]],"id":2857977}]}]}
{"op":"mcm","clk":"ANCKmgkAz9uHCgC3vJMK","pt":1657536814486,"mc":[{"id":"1.200806927","rc":[{"atl":[[5.2,0.85]],"id":2857977}]}]}
{"op":"mcm","clk":"ANeKmgkA29uHCgC8vJMK","pt":1657536814590,"mc":[{"id":"1.200806927","rc":[{"atb":[[4.1,55.21]],"id":2857977}]}]}
{"op":"mcm","clk":"AJ2MmgkA0N2HCgDbvZMK","pt":1657536817475,"mc":[{"id":"1.200806927","rc":[{"atl":[[5.2,0.29]],"id":2857977}]}]}
{"op":"mcm","clk":"AJ+QmgkA5OKHCgD7wJMK","pt":1657536824262,"mc":[{"id":"1.200806927","rc":[{"atl":[[1.3,38.2]],"trd":[[1.3,242.35]],"ltp":1.3,"tv":2299.36,"id":228749},{"trd":[[4.3,236.45]],"tv":633.64,"id":2857977}],"tv":2933}]}
{"op":"mcm","clk":"ALOQmgkAgOOHCgCTwZMK","pt":1657536824569,"mc":[{"id":"1.200806927","rc":[{"atb":[[4.1,53.52]],"id":2857977}]}]}
{"op":"mcm","clk":"ANeQmgkAqOOHCgCywZMK","pt":1657536825124,"mc":[{"id":"1.200806927","rc":[{"atb":[[4.1,55.21]],"id":2857977}]}]}
{"op":"mcm","clk":"APmQmgkA3OOHCgDLwZMK","pt":1657536825584,"mc":[{"id":"1.200806927","rc":[{"atb":[[4.1,53.52]],"id":2857977}]}]}
{"op":"mcm","clk":"AP2UmgkAsumHCgDgxJMK","pt":1657536833394,"mc":[{"id":"1.200806927","rc":[{"atb":[[4.1,55.21]],"id":2857977}]}]}
{"op":"mcm","clk":"AJyVmgkA5emHCgCAxZMK","pt":1657536833920,"mc":[{"id":"1.200806927","rc":[{"atb":[[4.1,53.52]],"id":2857977}]}]}
{"op":"mcm","clk":"AJOWmgkAi+uHCgCSxpMK","pt":1657536836020,"mc":[{"id":"1.200806927","rc":[{"atl":[[1.29,90.16]],"id":228749}]}]}
{"op":"mcm","clk":"ALKWmgkAr+uHCgC4xpMK","pt":1657536836496,"mc":[{"id":"1.200806927","rc":[{"atb":[[4.4,24.87]],"id":2857977}]}]}
{"op":"mcm","clk":"AO6YmgkAj++HCgCAyZMK","pt":1657536841939,"mc":[{"id":"1.200806927","rc":[{"atb":[[4.4,27.6]],"id":2857977}]}]}
{"op":"mcm","clk":"AIqbmgkA8PGHCgDgypMK","pt":1657536845502,"mc":[{"id":"1.200806927","rc":[{"atb":[[1.24,0]],"atl":[[1.24,67.32]],"trd":[[1.24,422.83]],"ltp":1.24,"tv":2708.73,"id":228749}],"tv":3342.37}]}
{"op":"mcm","clk":"AI6bmgkA+PGHCgDmypMK","pt":1657536845604,"mc":[{"id":"1.200806927","rc":[{"atl":[[1.24,65.55]],"trd":[[1.24,424.6]],"tv":2710.5,"id":228749},{"trd":[[5.1,0.43]],"ltp":5.1,"tv":634.07,"id":2857977}],"tv":3344.57}]}
{"op":"mcm","clk":"AJabmgkA//GHCgDnypMK","pt":1657536845729,"mc":[{"id":"1.200806927","rc":[{"atb":[[4.4,24.87]],"id":2857977}]}]}
{"op":"mcm","clk":"AKebmgkAoPKHCgD8ypMK","pt":1657536846004,"mc":[{"id":"1.200806927","rc":[{"atb":[[4.4,0],[4.9,21.68],[4.1,26.24]],"id":2857977}]}]}
{"op":"mcm","clk":"ALSbmgkAsvKHCgCJy5MK","pt":1657536846218,"mc":[{"id":"1.200806927","rc":[{"atl":[[1.24,61.32]],"trd":[[1.24,428.83]],"tv":2714.73,"id":228749},{"trd":[[5.1,1.46]],"tv":635.1,"id":2857977}],"tv":3349.83}]}
{"op":"mcm","clk":"AIGcmgkApvOHCgDay5MK","pt":1657536847500,"mc":[{"id":"1.200806927","rc":[{"atl":[[5.2,0]],"id":2857977}]}]}
{"op":"mcm","clk":"AIacmgkAsfOHCgDey5MK","pt":1657536847603,"mc":[{"id":"1.200806927","rc":[{"atl":[[5.4,0.29]],"id":2857977}]}]}
{"op":"mcm","clk":"AMCcmgkAhfSHCgCPzJMK","pt":1657536848543,"mc":[{"id":"1.200806927","rc":[{"atb":[[4.9,23.37]],"id":2857977}]}]}
{"op":"mcm","clk":"AN6cmgkArPSHCgCozJMK","pt":1657536849051,"mc":[{"id":"1.200806927","rc":[{"atb":[[4.9,21.68]],"id":2857977}]}]}
{"op":"mcm","clk":"ALKemgkA1faHCgD5zZMK","pt":1657536852851,"mc":[{"id":"1.200806927","rc":[{"atl":[[1.24,62.4]],"id":228749}]}]}
{"op":"mcm","clk":"AISgmgkAyPiHCgCrz5MK","pt":1657536855746,"mc":[{"id":"1.200806927","rc":[{"atb":[[4.9,23.37]],"id":2857977}]}]}
{"op":"mcm","clk":"AMmlmgkAvv+HCgCf1JMK","pt":1657536866284,"mc":[{"id":"1.200806927","rc":[{"atl":[[1.24,61.6]],"trd":[[1.24,429.63]],"tv":2715.53,"id":228749},{"trd":[[5.1,1.65]],"tv":635.29,"id":2857977}],"tv":3350.82}]}
{"op":"mcm","clk":"AMComgkA3IOICgDl1pMK","pt":1657536873069,"mc":[{"id":"1.200806927","rc":[{"atl":[[1.29,0]],"id":228749}]}]}
{"op":"mcm","clk":"ANusmgkAsoiICgDp2ZMK","pt":1657536880609,"mc":[{"id":"1.200806927","rc":[{"atl":[[1.24,60.91]],"trd":[[1.24,430.32]],"tv":2716.22,"id":228749},{"trd":[[5.1,1.82]],"tv":635.46,"id":2857977}],"tv":3351.68}]}
{"op":"mcm","clk":"AJitmgkA6oiICgCQ2pMK","pt":1657536881376,"mc":[{"id":"1.200806927","rc":[{"atb":[[4.9,21.68]],"id":2857977}]}]}
{"op":"mcm","clk":"AL6tmgkAkImICgCz2pMK","pt":1657536881886,"mc":[{"id":"1.200806927","rc":[{"atb":[[4.9,23.37]],"id":2857977}]}]}
{"op":"mcm","clk":"AN2tmgkAuomICgDf2pMK","pt":1657536882404,"mc":[{"id":"1.200806927","rc":[{"atb":[[4.9,21.68]],"id":2857977}]}]}
{"op":"mcm","clk":"AIqwmgkAiIyICgDY3JMK","pt":1657536887189,"mc":[{"id":"1.200806927","rc":[{"atl":[[1.24,59.11]],"trd":[[1.24,433.92]],"tv":2719.82,"id":228749}],"tv":3355.28}]}
{"op":"mcm","clk":"AI2xmgkAtI2ICgC33ZMK","pt":1657536889278,"mc":[{"id":"1.200806927","rc":[{"atb":[[4.9,23.37]],"id":2857977}]}]}
{"op":"mcm","clk":"AKexmgkA3Y2ICgDS3ZMK","pt":1657536889794,"mc":[{"id":"1.200806927","rc":[{"atb":[[4.9,21.68]],"id":2857977}]}]}
{"op":"mcm","clk":"APKymgkA34+ICgCb35MK","pt":1657536893221,"mc":[{"id":"1.200806927","rc":[{"atb":[[1.23,201.02]],"trd":[[1.23,120.68]],"ltp":1.23,"tv":2781.42,"id":228749}],"tv":3416.88}]}
{"op":"mcm","clk":"AIezmgkA/Y+ICgCu35MK","pt":1657536893488,"mc":[{"id":"1.200806927","rc":[{"atb":[[1.22,325.09]],"id":228749}]}]}
{"op":"mcm","clk":"AMS0mgkA1pGICgDD4JMK","pt":1657536896318,"mc":[{"id":"1.200806927","rc":[{"atb":[[4.9,23.37]],"id":2857977}]}]}
{"op":"mcm","clk":"ANK0mgkA7JGICgDS4JMK","pt":1657536896597,"mc":[{"id":"1.200806927","rc":[{"atb":[[4.9,21.68]],"id":2857977}]}]}
{"op":"mcm","clk":"AKa1mgkA2JKICgCO4ZMK","pt":1657536897922,"mc":[{"id":"1.200806927","rc":[{"atb":[[4.1,0]],"id":2857977}]}]}
{"op":"mcm","clk":"AK61mgkA4pKICgCW4ZMK","pt":1657536898040,"mc":[{"id":"1.200806927","rc":[{"atb":[[5.2,26.24]],"id":2857977}]}]}
{"op":"mcm","clk":"AMu1mgkAjZOICgCu4ZMK","pt":1657536898505,"mc":[{"id":"1.200806927","rc":[{"atb":[[1.22,113.67]],"id":228749},{"atb":[[5,21.14]],"id":2857977}]}]}
{"op":"mcm","clk":"ALK6mgkAh5mICgCy5ZMK","pt":1657536907626,"mc":[{"id":"1.200806927","rc":[{"atb":[[5.2,25.34]],"trd":[[5.2,12.59]],"ltp":5.2,"tv":637.26,"id":2857977}],"tv":3418.68}]}
{"op":"mcm","clk":"AJS9mgkAwJyICgDj55MK","pt":1657536913431,"mc":[{"id":"1.200806927","rc":[{"atl":[[1.24,58.68]],"trd":[[1.24,434.78]],"ltp":1.24,"tv":2782.28,"id":228749}],"tv":3419.54}]}
{"op":"mcm","clk":"APTBmgkAz6KICgC365MK","pt":1657536922458,"mc":[{"id":"1.200806927","rc":[{"atl":[[6,0.11]],"id":2857977}]}]}
{"op":"mcm","clk":"AMTCmgkArKOICgDf65MK","pt":1657536923533,"mc":[{"id":"1.200806927","rc":[{"atb":[[1.23,177.48]],"trd":[[1.23,167.76]],"ltp":1.23,"tv":2829.36,"id":228749}],"tv":3466.62}]}
{"op":"mcm","clk":"APnCmgkA76OICgCH7JMK","pt":1657536924277,"mc":[{"id":"1.200806927","rc":[{"atl":[[1.24,56.88]],"trd":[[1.24,438.38]],"ltp":1.24,"tv":2832.96,"id":228749}],"tv":3470.22}]}
{"op":"mcm","clk":"AJ3OmgkAgrKICgDV9ZMK","pt":1657536946268,"mc":[{"id":"1.200806927","rc":[{"atl":[[1.24,55.8]],"id":228749}]}]}
{"op":"mcm","clk":"AMbTmgkAhLiICgDD+pMK","pt":1657536956011,"mc":[{"id":"1.200806927","rc":[{"atl":[[1.24,0]],"trd":[[1.24,584.34]],"tv":2978.92,"id":228749},{"atb":[[5.2,17.15]],"trd":[[5.2,20.79]],"tv":645.46,"id":2857977}],"tv":3624.38}]}
{"op":"mcm","clk":"AOTYmgkA4L6ICgC9/pMK","pt":1657536965316,"mc":[{"id":"1.200806927","rc":[{"atb":[[2.72,0]],"id":2857977}]}]}
{"op":"mcm","clk":"AOvemgkArsWICgCVg5QK","pt":1657536976429,"mc":[{"id":"1.200806927","rc":[{"trd":[[1.24,584.48]],"tv":2979.06,"id":228749},{"atb":[[5.2,17.11]],"trd":[[5.2,20.82]],"tv":645.49,"id":2857977}],"tv":3624.55}]}
{"op":"mcm","clk":"AMfgmgkAnMeICgDghJQK","pt":1657536979557,"mc":[{"id":"1.200806927","rc":[{"atb":[[1.22,345.49]],"id":228749}]}]}
{"op":"mcm","clk":"AM3imgkA38mICgDPhpQK","pt":1657536983353,"mc":[{"id":"1.200806927","rc":[{"trd":[[1.24,602.52]],"tv":2997.1,"id":228749},{"atb":[[5.2,12.81]],"trd":[[5.2,25.12]],"tv":649.79,"id":2857977}],"tv":3646.89}]}
{"op":"mcm","clk":"AKbpmgkA+NGICgDyi5QK","pt":1657536995050,"mc":[{"id":"1.200806927","rc":[{"atb":[[5.2,11.95]],"trd":[[5.2,26.85]],"tv":651.52,"id":2857977}],"tv":3648.62}]}
{"op":"mcm","clk":"AMrpmgkAuNKICgCYjJQK","pt":1657536995650,"mc":[{"id":"1.200806927","rc":[{"atb":[[4.9,0],[5,0],[4.3,25.62]],"id":2857977}]}]}
{"op":"mcm","clk":"AODpmgkAzNKICgCijJQK","pt":1657536995850,"mc":[{"id":"1.200806927","rc":[{"atb":[[5.2,0.01]],"trd":[[5.2,50.73]],"tv":675.4,"id":2857977}],"tv":3672.5}]}
{"op":"mcm","clk":"AObpmgkA2tKICgCnjJQK","pt":1657536995961,"mc":[{"id":"1.200806927","rc":[{"atb":[[5.2,0]],"trd":[[5.2,50.75]],"tv":675.42,"id":2857977}],"tv":3672.52}]}
{"op":"mcm","clk":"APXpmgkA8dKICgC2jJQK","pt":1657536996168,"mc":[{"id":"1.200806927","rc":[{"atb":[[4.3,0]],"id":2857977}]}]}
{"op":"mcm","clk":"AJDqmgkAlNOICgDRjJQK","pt":1657536996583,"mc":[{"id":"1.200806927","rc":[{"atb":[[3.2,1.69]],"id":2857977}]}]}
{"op":"mcm","clk":"AJPqmgkAotOICgDUjJQK","pt":1657536996682,"mc":[{"id":"1.200806927","rc":[{"atb":[[3.25,37.58]],"id":2857977}]}]}
{"op":"mcm","clk":"AKzqmgkAx9OICgDnjJQK","pt":1657536997043,"mc":[{"id":"1.200806927","rc":[{"atb":[[3.2,0]],"id":2857977}]}]}
{"op":"mcm","clk":"AMvqmgkA6tOICgD5jJQK","pt":1657536997487,"mc":[{"id":"1.200806927","rc":[{"atb":[[1.23,502.16]],"id":228749},{"atb":[[4.6,20.74]],"id":2857977}]}]}
{"op":"mcm","clk":"ANfqmgkA+9OICgCDjZQK","pt":1657536997673,"mc":[{"id":"1.200806927","rc":[{"atb":[[1.24,211.42]],"id":228749},{"atb":[[3.25,0],[4.5,24.16]],"id":2857977}]}]}
{"op":"mcm","clk":"AKDsmgkA7tWICgC+jpQK","pt":1657537000548,"mc":[{"id":"1.200806927","rc":[{"atl":[[5.4,0]],"id":2857977}]}]}
{"op":"mcm","clk":"AKbsmgkA+dWICgDGjpQK","pt":1657537000682,"mc":[{"id":"1.200806927","rc":[{"atl":[[5.2,0.29]],"id":2857977}]}]}
{"op":"mcm","clk":"ALzvmgkAodmICgDRkJQK","pt":1657537005585,"mc":[{"id":"1.200806927","rc":[{"atb":[[1.12,84.57]],"id":228749}]}]}
{"op":"mcm","clk":"ANjvmgkAwdmICgDfkJQK","pt":1657537005946,"mc":[{"id":"1.200806927","rc":[{"atb":[[1.12,169.13]],"id":228749}]}]}
{"op":"mcm","clk":"APvvmgkA2NmICgDzkJQK","pt":1657537006293,"mc":[{"id":"1.200806927","rc":[{"atb":[[1.12,253.7]],"id":228749}]}]}
{"op":"mcm","clk":"AJPwmgkA69mICgCAkZQK","pt":1657537006580,"mc":[{"id":"1.200806927","rc":[{"atb":[[1.12,338.27]],"id":228749}]}]}
{"op":"mcm","clk":"ANnwmgkAoNqICgCmkZQK","pt":1657537007271,"mc":[{"id":"1.200806927","rc":[{"atl":[[1.89,0]],"id":228749}]}]}
{"op":"mcm","clk":"APDwmgkAsdqICgCwkZQK","pt":1657537007482,"mc":[{"id":"1.200806927","rc":[{"atb":[[1.24,151.25]],"trd":[[1.24,722.86]],"tv":3117.44,"id":228749}],"tv":3792.86}]}
{"op":"mcm","clk":"APj8mgkAsOeICgDAmpQK","pt":1657537027200,"mc":[{"id":"1.200806927","rc":[{"atb":[[4.6,20.52]],"trd":[[4.6,0.44]],"ltp":4.6,"tv":675.86,"id":2857977}],"tv":3793.3}]}
{"op":"mcm","clk":"AKH9mgkAz+eICgDampQK","pt":1657537027621,"mc":[{"id":"1.200806927","rc":[{"atb":[[4.6,20.74]],"id":2857977}]}]}
{"op":"mcm","clk":"AL2kmwkA+pGJCgCmt5QK","pt":1657537093820,"mc":[{"id":"1.200806927","rc":[{"atl":[[1.26,53.06]],"id":228749}]}]}
{"op":"mcm","clk":"AM+kmwkAi5KJCgCst5QK","pt":1657537094028,"mc":[{"id":"1.200806927","rc":[{"atb":[[4.6,22.43]],"id":2857977}]}]}
{"op":"mcm","clk":"AOOkmwkAnJKJCgC4t5QK","pt":1657537094305,"mc":[{"id":"1.200806927","rc":[{"atb":[[1.24,0],[1.23,713.58]],"id":228749},{"atb":[[4.7,22.86]],"id":2857977}]}]}
{"op":"mcm","clk":"AJ6lmwkAvpKJCgDIt5QK","pt":1657537094931,"mc":[{"id":"1.200806927","rc":[{"atb":[[1.23,502.16]],"id":228749}]}]}
{"op":"mcm","clk":"ALmlmwkA05KJCgDdt5QK","pt":1657537095322,"mc":[{"id":"1.200806927","rc":[{"atb":[[1.22,556.91]],"id":228749}]}]}
{"op":"mcm","clk":"AKSmmwkAn5OJCgCTuJQK","pt":1657537096639,"mc":[{"id":"1.200806927","rc":[{"atl":[[5.2,0]],"id":2857977}]}]}
{"op":"mcm","clk":"ALCmmwkAqZOJCgCXuJQK","pt":1657537096739,"mc":[{"id":"1.200806927","rc":[{"atl":[[5.3,0.29]],"id":2857977}]}]}
{"op":"mcm","clk":"ALbFmwkAsKuJCgCMy5QK","pt":1657537145159,"mc":[{"id":"1.200806927","rc":[{"atl":[[1.26,52.24]],"trd":[[1.26,234.96]],"ltp":1.26,"tv":3118.26,"id":228749},{"trd":[[4.8,56.39]],"ltp":4.8,"tv":676.08,"id":2857977}],"tv":3794.34}]}
{"op":"mcm","clk":"AO/FmwkA4auJCgCqy5QK","pt":1657537145854,"mc":[{"id":"1.200806927","rc":[{"atb":[[4.6,20.74]],"id":2857977}]}]}
{"op":"mcm","clk":"AJfGmwkA/quJCgDAy5QK","pt":1657537146344,"mc":[{"id":"1.200806927","rc":[{"atb":[[4.7,24.55]],"id":2857977}]}]}
{"op":"mcm","clk":"AMvGmwkArKyJCgDpy5QK","pt":1657537147068,"mc":[{"id":"1.200806927","rc":[{"atb":[[4.7,22.86]],"id":2857977}]}]}
{"op":"mcm","clk":"AL3ImwkAya2JCgDfzJQK","pt":1657537149753,"mc":[{"id":"1.200806927","rc":[{"atb":[[4.7,24.55]],"id":2857977}]}]}
{"op":"mcm","clk":"AOrImwkA6K2JCgD9zJQK","pt":1657537150358,"mc":[{"id":"1.200806927","rc":[{"atb":[[4.7,22.86]],"id":2857977}]}]}
{"op":"mcm","clk":"ANDKmwkAta+JCgCNzpQK","pt":1657537153144,"mc":[{"id":"1.200806927","rc":[{"atb":[[4.7,24.55]],"id":2857977}]}]}
{"op":"mcm","clk":"APfKmwkA36+JCgCwzpQK","pt":1657537153756,"mc":[{"id":"1.200806927","rc":[{"atb":[[4.7,22.86]],"id":2857977}]}]}
{"op":"mcm","clk":"AL3MmwkAlrGJCgC8z5QK","pt":1657537156351,"mc":[{"id":"1.200806927","rc":[{"atb":[[4.7,24.55]],"id":2857977}]}]}
{"op":"mcm","clk":"AOjMmwkAxLGJCgDgz5QK","pt":1657537156971,"mc":[{"id":"1.200806927","rc":[{"atb":[[4.7,22.86]],"id":2857977}]}]}
{"op":"mcm","clk":"ANPOmwkA97KJCgD10JQK","pt":1657537159735,"mc":[{"id":"1.200806927","rc":[{"atb":[[4.7,24.55]],"id":2857977}]}]}
{"op":"mcm","clk":"AI3PmwkApbOJCgCR0ZQK","pt":1657537160462,"mc":[{"id":"1.200806927","rc":[{"atb":[[4.7,22.86]],"id":2857977}]}]}
{"op":"mcm","clk":"ANXQmwkA4LSJCgDv0ZQK","pt":1657537162967,"mc":[{"id":"1.200806927","rc":[{"atb":[[4.7,24.55]],"id":2857977}]}]}
{"op":"mcm","clk":"AOLQmwkA7bSJCgD60ZQK","pt":1657537163159,"mc":[{"id":"1.200806927","rc":[{"atb":[[1.21,225.97]],"id":228749}]}]}
{"op":"mcm","clk":"AOrQmwkA87SJCgD80ZQK","pt":1657537163266,"mc":[{"id":"1.200806927","rc":[{"atb":[[1.01,2671.9]],"id":2857977}]}]}
{"op":"mcm","clk":"APnQmwkAg7WJCgCE0pQK","pt":1657537163476,"mc":[{"id":"1.200806927","rc":[{"atb":[[1.21,223.16]],"id":228749}]}]}
{"op":"mcm","clk":"AILRmwkAi7WJCgCI0pQK","pt":1657537163584,"mc":[{"id":"1.200806927","rc":[{"atb":[[4.7,22.86],[1.01,2671.21]],"id":2857977}]}]}
{"op":"mcm","clk":"AIjRmwkAlbWJCgCM0pQK","pt":1657537163689,"mc":[{"id":"1.200806927","rc":[{"atb":[[1.21,223.13]],"id":228749}]}]}
{"op":"mcm","clk":"AJrRmwkAorWJCgCX0pQK","pt":1657537163833,"mc":[{"id":"1.200806927","rc":[{"atl":[[1.26,52.21]],"trd":[[1.26,235]],"tv":3118.3,"id":228749}],"tv":3794.38}]}
{"op":"mcm","clk":"AKXRmwkAq7WJCgCd0pQK","pt":1657537163955,"mc":[{"id":"1.200806927","rc":[{"atb":[[1.01,2669.06]],"id":2857977}]}]}
{"op":"mcm","clk":"ALLRmwkAsrWJCgCg0pQK","pt":1657537164042,"mc":[{"id":"1.200806927","rc":[{"atb":[[1.23,493.97]],"trd":[[1.23,175.95]],"ltp":1.23,"tv":3126.49,"id":228749},{"atl":[[5.3,0]],"trd":[[5.4,4.55],[5.3,6.26]],"ltp":5.4,"tv":678.52,"id":2857977}],"tv":3805.01}]}
{"op":"mcm","clk":"AK/SmwkAmLaJCgDv0pQK","pt":1657537165548,"mc":[{"id":"1.200806927","rc":[{"atb":[[4.8,0.85]],"id":2857977}]}]}
{"op":"mcm","clk":"ANbSmwkAvbaJCgCD05QK","pt":1657537166078,"mc":[{"id":"1.200806927","rc":[{"atb":[[4.7,24.55]],"id":2857977}]}]}
{"op":"mcm","clk":"APvSmwkA4baJCgCi05QK","pt":1657537166676,"mc":[{"id":"1.200806927","rc":[{"atb":[[4.7,22.86]],"id":2857977}]}]}
{"op":"mcm","clk":"AJ/UmwkA0LeJCgD505QK","pt":1657537168666,"mc":[{"id":"1.200806927","rc":[{"atb":[[4.8,0.45]],"id":2857977}]}]}
{"op":"mcm","clk":"AMfUmwkA7beJCgCN1JQK","pt":1657537169174,"mc":[{"id":"1.200806927","rc":[{"atb":[[4.7,24.55]],"id":2857977}]}]}
{"op":"mcm","clk":"ANXUmwkA9reJCgCW1JQK","pt":1657537169371,"mc":[{"id":"1.200806927","rc":[{"atb":[[3,2.84]],"id":2857977}]}]}
{"op":"mcm","clk":"AOHUmwkA/beJCgCa1JQK","pt":1657537169576,"mc":[{"id":"1.200806927","rc":[{"atb":[[3,0.01]],"id":2857977}]}]}
{"op":"mcm","clk":"APHUmwkAjriJCgCd1JQK","pt":1657537169781,"mc":[{"id":"1.200806927","rc":[{"atb":[[4.7,22.86],[3,0]],"id":2857977}]}]}
{"op":"mcm","clk":"APnUmwkAnLiJCgCi1JQK","pt":1657537169859,"mc":[{"id":"1.200806927","rc":[{"atb":[[1.23,493.95]],"trd":[[1.23,175.97]],"tv":3126.51,"id":228749},{"trd":[[5.4,4.56]],"tv":678.53,"id":2857977}],"tv":3805.04}]}
{"op":"mcm","clk":"AK/WmwkA4rmJCgCj1ZQK","pt":1657537172365,"mc":[{"id":"1.200806927","rc":[{"atb":[[4.7,24.55]],"id":2857977}]}]}
{"op":"mcm","clk":"AOPWmwkAk7qJCgDG1ZQK","pt":1657537173081,"mc":[{"id":"1.200806927","rc":[{"atb":[[4.7,22.86]],"id":2857977}]}]}
{"op":"mcm","clk":"AOjYmwkAuruJCgDE1pQK","pt":1657537175683,"mc":[{"id":"1.200806927","rc":[{"atb":[[4.7,24.55]],"id":2857977}]}]}
{"op":"mcm","clk":"AKTZmwkA47uJCgDe1pQK","pt":1657537176258,"mc":[{"id":"1.200806927","rc":[{"atb":[[4.7,22.86]],"id":2857977}]}]}
{"op":"mcm","clk":"AI7amwkAq7yJCgCo15QK","pt":1657537177631,"mc":[{"id":"1.200806927","rc":[{"atb":[[4.8,0]],"id":2857977}]}]}
{"op":"mcm","clk":"AJXamwkAtbyJCgCs15QK","pt":1657537177695,"mc":[{"id":"1.200806927","rc":[{"atb":[[1.06,167.12]],"id":2857977}]}]}
{"op":"mcm","clk":"APnamwkAlb2JCgDp15QK","pt":1657537178971,"mc":[{"id":"1.200806927","rc":[{"atb":[[4.7,24.55]],"id":2857977}]}]}
{"op":"mcm","clk":"AKXbmwkAvr2JCgCH2JQK","pt":1657537179550,"mc":[{"id":"1.200806927","rc":[{"atb":[[4.7,22.86]],"id":2857977}]}]}
{"op":"mcm","clk":"AN/cmwkA5b6JCgD52JQK","pt":1657537182086,"mc":[{"id":"1.200806927","rc":[{"atb":[[4.7,24.55]],"id":2857977}]}]}
{"op":"mcm","clk":"APHcmwkA8b6JCgCI2ZQK","pt":1657537182291,"mc":[{"id":"1.200806927","rc":[{"atl":[[1.26,51.8]],"trd":[[1.26,235.41]],"ltp":1.26,"tv":3126.92,"id":228749},{"trd":[[4.8,56.49]],"ltp":4.8,"tv":678.63,"id":2857977}],"tv":3805.55}]}
{"op":"mcm","clk":"AJHdmwkAhr+JCgCX2ZQK","pt":1657537182664,"mc":[{"id":"1.200806927","rc":[{"atb":[[4.7,22.86]],"id":2857977}]}]}
{"op":"mcm","clk":"APremwkAxcCJCgCb2pQK","pt":1657537185485,"mc":[{"id":"1.200806927","rc":[{"atb":[[4.7,24.55]],"id":2857977}]}]}
{"op":"mcm","clk":"AKjfmwkA6cCJCgCr2pQK","pt":1657537186093,"mc":[{"id":"1.200806927","rc":[{"atb":[[4.7,22.86]],"id":2857977}]}]}
{"op":"mcm","clk":"AOzgmwkAosKJCgCf25QK","pt":1657537188589,"mc":[{"id":"1.200806927","rc":[{"atb":[[4.7,24.55]],"id":2857977}]}]}
{"op":"mcm","clk":"AKHhmwkA1sKJCgDE25QK","pt":1657537189269,"mc":[{"id":"1.200806927","rc":[{"atb":[[4.7,22.86]],"id":2857977}]}]}
{"op":"mcm","clk":"APDimwkAlsSJCgDM3JQK","pt":1657537191866,"mc":[{"id":"1.200806927","rc":[{"atb":[[4.7,24.55]],"id":2857977}]}]}
{"op":"mcm","clk":"AJ7jmwkAuMSJCgDt3JQK","pt":1657537192387,"mc":[{"id":"1.200806927","rc":[{"atb":[[4.7,22.86]],"id":2857977}]}]}
{"op":"mcm","clk":"AOPkmwkA1cWJCgDX3ZQK","pt":1657537194899,"mc":[{"id":"1.200806927","rc":[{"atb":[[4.7,24.55]],"id":2857977}]}]}
{"op":"mcm","clk":"AJblmwkAhsaJCgD33ZQK","pt":1657537195514,"mc":[{"id":"1.200806927","rc":[{"atb":[[4.7,22.86]],"id":2857977}]}]}
{"op":"mcm","clk":"AOXlmwkAwcaJCgCZ3pQK","pt":1657537196400,"mc":[{"id":"1.200806927","rc":[{"atl":[[1.26,51.14]],"trd":[[1.26,236.08]],"tv":3127.59,"id":228749},{"trd":[[4.8,56.67]],"tv":678.81,"id":2857977}],"tv":3806.4}]}
{"op":"mcm","clk":"APLmmwkAuceJCgDa3pQK","pt":1657537198074,"mc":[{"id":"1.200806927","rc":[{"atb":[[4.7,24.55]],"id":2857977}]}]}
{"op":"mcm","clk":"AKDnmwkA58eJCgDt3pQK","pt":1657537198683,"mc":[{"id":"1.200806927","rc":[{"atb":[[4.7,22.86]],"id":2857977}]}]}
{"op":"mcm","clk":"AKHpmwkA78mJCgDy35QK","pt":1657537201427,"mc":[{"id":"1.200806927","marketDefinition":{"bspMarket":false,"turnInPlayEnabled":true,"persistenceEnabled":true,"marketBaseRate":5,"eventId":"31573045","eventTypeId":"4","numberOfWinners":1,"bettingType":"ODDS","marketType":"MATCH_ODDS","marketTime":"2022-07-11T11:00:00.000Z","suspendTime":"2022-07-11T11:00:00.000Z","bspReconciled":false,"complete":true,"inPlay":false,"crossMatching":true,"runnersVoidable":false,"numberOfActiveRunners":2,"betDelay":0,"status":"SUSPENDED","runners":[{"status":"ACTIVE","sortPriority":1,"id":228749},{"status":"ACTIVE","sortPriority":2,"id":2857977}],"regulators":["MR_INT"],"countryCode":"GB","discountAllowed":true,"timezone":"GMT","openDate":"2022-07-11T11:00:00.000Z","version":4646297491,"priceLadderDefinition":{"type":"CLASSIC"}}}]}
{"op":"mcm","clk":"ANLpmwkAocqJCgCT4JQK","pt":1657537201989,"mc":[{"id":"1.200806927","rc":[{"atb":[[1.22,345.49],[1.21,11.72]],"id":228749},{"atb":[[4.7,0],[4.5,0]],"id":2857977}]}]}
{"op":"mcm","clk":"AMnqmwkAg8uJCgDT4JQK","pt":1657537203071,"mc":[{"id":"1.200806927","rc":[{"atb":[[1.23,169.27]],"id":228749},{"atb":[[4.6,0]],"id":2857977}]}]}
{"op":"mcm","clk":"ANf3mwkA0deJCgDf55QK","pt":1657537220540,"mc":[{"id":"1.200806927","marketDefinition":{"bspMarket":false,"turnInPlayEnabled":true,"persistenceEnabled":true,"marketBaseRate":5,"eventId":"31573045","eventTypeId":"4","numberOfWinners":1,"bettingType":"ODDS","marketType":"MATCH_ODDS","marketTime":"2022-07-11T11:00:00.000Z","suspendTime":"2022-07-11T11:00:00.000Z","bspReconciled":false,"complete":true,"inPlay":true,"crossMatching":true,"runnersVoidable":false,"numberOfActiveRunners":2,"betDelay":5,"status":"OPEN","runners":[{"status":"ACTIVE","sortPriority":1,"id":228749},{"status":"ACTIVE","sortPriority":2,"id":2857977}],"regulators":["MR_INT"],"countryCode":"GB","discountAllowed":true,"timezone":"GMT","openDate":"2022-07-11T11:00:00.000Z","version":4646297827,"priceLadderDefinition":{"type":"CLASSIC"}},"rc":[{"atb":[[1.08,463.27],[1.22,0],[1.23,169.13],[1.02,599.78],[1.21,0],[1.15,0],[1.03,400.18],[1.01,2668.09],[1.2,1]],"atl":[[3.5,11.29],[1.3,0],[3,0],[1.68,12.54],[1.5,11.35],[1.26,51.1],[1.45,56.74]],"trd":[[1.38,16.54],[1.24,722.8],[1.31,34.5],[1.3,242.34],[1.22,124.89],[1.34,83.72],[1.33,1.03],[1.23,175.85],[1.26,236.07],[9,1.33]],"tv":3127.26,"id":228749},{"atb":[[1.06,166.67],[1.02,599.78],[1.03,400.18],[1.45,37.63],[1.01,2668.09],[1.8,0],[2,18.4]],"trd":[[4.7,45.59],[3.9,6.72],[5.2,50.69],[3.95,47.17],[5,8.72],[4.4,10.97],[4.9,58.77],[5.3,6.25],[9,1.33],[4.3,236.38],[3.6,17.67],[4.8,56.57]],"tv":678.31,"id":2857977}],"tv":3805.57}]}
{"op":"mcm","clk":"ANX+mwkAzt2JCgCa65QK","pt":1657537230130,"mc":[{"id":"1.200806927","rc":[{"atb":[[1.01,2670.93]],"id":228749}]}]}
{"op":"mcm","clk":"AJL/mwkA+92JCgCu65QK","pt":1657537230620,"mc":[{"id":"1.200806927","rc":[{"atb":[[1.01,2670.28]],"id":228749}]}]}
{"op":"mcm","clk":"AMr/mwkAot6JCgDC65QK","pt":1657537231120,"mc":[{"id":"1.200806927","rc":[{"atb":[[1.01,2668.09]],"atl":[[1000,0.58]],"id":228749}]}]}
{"op":"mcm","clk":"AO3/mwkAvd6JCgDU65QK","pt":1657537231431,"mc":[{"id":"1.200806927","rc":[{"atl":[[1000,0.02]],"id":228749}]}]}
{"op":"mcm","clk":"APGCnAkA0eCJCgDv7JQK","pt":1657537235126,"mc":[{"id":"1.200806927","rc":[{"atb":[[4.8,8]],"id":2857977}]}]}
{"op":"mcm","clk":"AOmDnAkAsuGJCgCv7ZQK","pt":1657537236232,"mc":[{"id":"1.200806927","rc":[{"atb":[[1.23,152.79],[1.16,2.18]],"trd":[[1.23,192.19]],"ltp":1.23,"tv":3143.6,"id":228749},{"trd":[[5.4,8.28]],"ltp":5.4,"tv":682.03,"id":2857977}],"tv":3825.63}]}
{"op":"mcm","clk":"AIGEnAkAxeGJCgC77ZQK","pt":1657537236516,"mc":[{"id":"1.200806927","rc":[{"atl":[[2.04,0.56]],"id":228749}]}]}
{"op":"mcm","clk":"AOuEnAkAi+KJCgD87ZQK","pt":1657537237746,"mc":[{"id":"1.200806927","rc":[{"atl":[[1000,1.11]],"id":228749}]}]}
{"op":"mcm","clk":"AJyFnAkArOKJCgCb7pQK","pt":1657537238265,"mc":[{"id":"1.200806927","rc":[{"atl":[[1000,0.02]],"id":228749}]}]}
{"op":"mcm","clk":"AKeHnAkA+OOJCgC875QK","pt":1657537241253,"mc":[{"id":"1.200806927","rc":[{"atb":[[1.23,83.79]],"trd":[[1.23,330.19]],"tv":3281.6,"id":228749}],"tv":3963.63}]}
{"op":"mcm","clk":"AM2InAkAneWJCgCq8JQK","pt":1657537243347,"mc":[{"id":"1.200806927","rc":[{"atl":[[1.33,1.09]],"id":228749}]}]}
{"op":"mcm","clk":"ANmKnAkA9+aJCgDC8ZQK","pt":1657537246050,"mc":[{"id":"1.200806927","rc":[{"atl":[[5,0.11]],"id":2857977}]}]}
{"op":"mcm","clk":"ANWOnAkAkOqJCgCG9JQK","pt":1657537251559,"mc":[{"id":"1.200806927","rc":[{"trd":[[1.25,767.9]],"ltp":1.25,"tv":3281.81,"id":228749},{"atl":[[5,0.05]],"trd":[[5,8.78]],"ltp":5,"tv":682.09,"id":2857977}],"tv":3963.9}]}
{"op":"mcm","clk":"AOSknAkAx/2JCgCBgZUK","pt":1657537284242,"mc":[{"id":"1.200806927","rc":[{"atl":[[1.26,42.08]],"trd":[[1.26,254.11]],"ltp":1.26,"tv":3299.85,"id":228749}],"tv":3981.94}]}
{"op":"mcm","clk":"AMannAkAhICKCgDOgpUK","pt":1657537288223,"mc":[{"id":"1.200806927","rc":[{"atb":[[4.8,0]],"id":2857977}]}]}
{"op":"mcm","clk":"AKqonAkA1YCKCgCRg5UK","pt":1657537289342,"mc":[{"id":"1.200806927","rc":[{"atl":[[5,0.95]],"id":2857977}]}]}
{"op":"mcm","clk":"ANuunAkA1oaKCgCPh5UK","pt":1657537298452,"mc":[{"id":"1.200806927","rc":[{"atb":[[1.23,57.23]],"trd":[[1.23,356.74]],"ltp":1.23,"tv":3326.4,"id":228749},{"atl":[[5,0]],"trd":[[5.4,14.33],[5,10.68]],"ltp":5.4,"tv":690.04,"id":2857977}],"tv":4016.44}]}
{"op":"mcm","clk":"AI21nAkA0oyKCgCWi5UK","pt":1657537308284,"mc":[{"id":"1.200806927","rc":[{"atb":[[1.24,25.68]],"id":228749}]}]}
{"op":"mcm","clk":"AK+3nAkA8Y6KCgDGjJUK","pt":1657537311683,"mc":[{"id":"1.200806927","rc":[{"atl":[[1.26,41.22]],"trd":[[1.26,255.83]],"ltp":1.26,"tv":3328.12,"id":228749}],"tv":4018.16}]}
{"op":"mcm","clk":"AOK/nAkAq5aKCgC+kpUK","pt":1657537325046,"mc":[{"id":"1.200806927","rc":[{"atb":[[1.24,0],[1.23,0],[1.18,0],[1.2,0]],"atl":[[1.23,30.26]],"trd":[[1.24,774.16],[1.23,471.2],[1.2,2.53],[1.18,2.6]],"ltp":1.18,"tv":3499.07,"id":228749},{"atl":[[6,0]],"trd":[[6,0.11]],"ltp":6,"tv":690.15,"id":2857977}],"tv":4189.22}]}
{"op":"mcm","clk":"AN/MnAkAhaCKCgCsm5UK","pt":1657537342790,"mc":[{"id":"1.200806927","rc":[{"atl":[[1.23,26.38]],"trd":[[1.23,475.08]],"ltp":1.23,"tv":3502.95,"id":228749},{"trd":[[5.3,7.15]],"ltp":5.3,"tv":691.05,"id":2857977}],"tv":4194}]}
{"op":"mcm","clk":"ALbOnAkAgKGKCgCmnJUK","pt":1657537345182,"mc":[{"id":"1.200806927","rc":[{"atl":[[1.23,25.92]],"trd":[[1.23,475.54]],"tv":3503.41,"id":228749},{"trd":[[5.3,7.26]],"tv":691.16,"id":2857977}],"tv":4194.57}]}
{"op":"mcm","clk":"AJXQnAkAnqKKCgC0nZUK","pt":1657537347989,"mc":[{"id":"1.200806927","rc":[{"atb":[[1.15,12.54]],"id":228749}]}]}
{"op":"mcm","clk":"AMnSnAkAsKSKCgCXn5UK","pt":1657537352297,"mc":[{"id":"1.200806927","rc":[{"atl":[[1.23,25.49]],"trd":[[1.23,476.4]],"tv":3504.27,"id":228749}],"tv":4195.43}]}
{"op":"mcm","clk":"AJHUnAkAwqWKCgCZoJUK","pt":1657537354836,"mc":[{"id":"1.200806927","rc":[{"atl":[[1.23,0]],"id":228749}]}]}
{"op":"mcm","clk":"AMrWnAkAvKeKCgD6oZUK","pt":1657537358724,"mc":[{"id":"1.200806927","rc":[{"atl":[[5.3,50]],"id":2857977}]}]}
{"op":"mcm","clk":"APvfnAkAz66KCgD7p5UK","pt":1657537373835,"mc":[{"id":"1.200806927","rc":[{"atl":[[1.25,0.9]],"id":228749}]}]}
{"op":"mcm","clk":"ALflnAkA+rKKCgCvq5UK","pt":1657537382646,"mc":[{"id":"1.200806927","rc":[{"atl":[[1.26,40.4],[1.25,0]],"trd":[[1.26,257.47],[1.25,769.7]],"ltp":1.26,"tv":3507.71,"id":228749}],"tv":4198.87}]}
{"op":"mcm","clk":"ANPlnAkAkrOKCgDEq5UK","pt":1657537382945,"mc":[{"id":"1.200806927","rc":[{"atl":[[1.26,39.89]],"trd":[[1.26,257.97]],"tv":3508.21,"id":228749},{"trd":[[4.8,56.71]],"ltp":4.8,"tv":691.3,"id":2857977}],"tv":4199.51}]}
{"op":"mcm","clk":"ANzonAkAkrWKCgClrZUK","pt":1657537387057,"mc":[{"id":"1.200806927","rc":[{"atl":[[1.42,6.69]],"id":228749}]}]}
{"op":"mcm","clk":"AOrqnAkA27aKCgDSrpUK","pt":1657537390368,"mc":[{"id":"1.200806927","rc":[{"trd":[[1.23,476.83]],"ltp":1.23,"tv":3508.64,"id":228749},{"atl":[[5.3,49.9]],"trd":[[5.3,7.36]],"ltp":5.3,"tv":691.4,"id":2857977}],"tv":4200.04}]}
{"op":"mcm","clk":"AJXrnAkAh7eKCgDsrpUK","pt":1657537390969,"mc":[{"id":"1.200806927","rc":[{"trd":[[1.23,477.09]],"tv":3508.9,"id":228749},{"atl":[[5.3,49.84]],"trd":[[5.3,7.42]],"tv":691.46,"id":2857977}],"tv":4200.36}]}
{"op":"mcm","clk":"AI3tnAkA4riKCgCRsJUK","pt":1657537394108,"mc":[{"id":"1.200806927","rc":[{"atl":[[1.26,36.68]],"trd":[[1.26,261.19]],"ltp":1.26,"tv":3512.12,"id":228749},{"trd":[[4.8,57.55]],"ltp":4.8,"tv":692.3,"id":2857977}],"tv":4204.42}]}
{"op":"mcm","clk":"AJ7tnAkA+biKCgCesJUK","pt":1657537394369,"mc":[{"id":"1.200806927","rc":[{"atl":[[6,0.11]],"id":2857977}]}]}
{"op":"mcm","clk":"AN7vnAkAj7uKCgD3sZUK","pt":1657537398290,"mc":[{"id":"1.200806927","rc":[{"atl":[[1.26,35.86]],"trd":[[1.26,262.01]],"tv":3512.94,"id":228749},{"trd":[[4.8,57.77]],"tv":692.52,"id":2857977}],"tv":4205.46}]}
{"op":"mcm","clk":"AIn4nAkA18GKCgDlt5UK","pt":1657537411303,"mc":[{"id":"1.200806927","rc":[{"atb":[[1.26,182.38]],"atl":[[1.26,0]],"trd":[[1.26,333.72]],"tv":3584.65,"id":228749}],"tv":4277.17}]}
{"op":"mcm","clk":"APeEnQkAw86KCgCLwZUK","pt":1657537433710,"mc":[{"id":"1.200806927","rc":[{"atl":[[1.5,11.69]],"id":228749}]}]}
{"op":"mcm","clk":"AIWTnQkA89yKCgDdzJUK","pt":1657537459561,"mc":[{"id":"1.200806927","rc":[{"atl":[[1.33,0.32]],"trd":[[1.33,1.81]],"ltp":1.33,"tv":3585.43,"id":228749},{"trd":[[4,1.46]],"ltp":4,"tv":692.78,"id":2857977}],"tv":4278.21}]}
{"op":"mcm","clk":"ANqUnQkA996KCgC0zpUK","pt":1657537462978,"mc":[{"id":"1.200806927","rc":[{"atb":[[1.26,182.28]],"trd":[[1.26,333.92]],"ltp":1.26,"tv":3585.63,"id":228749}],"tv":4278.41}]}
{"op":"mcm","clk":"ANqXnQkApuKKCgCa0ZUK","pt":1657537468889,"mc":[{"id":"1.200806927","rc":[{"atb":[[1.27,2.15]],"id":228749}]}]}
{"op":"mcm","clk":"ALadnQkAquiKCgCp1pUK","pt":1657537478990,"mc":[{"id":"1.200806927","rc":[{"atl":[[1.4,9.02]],"id":228749}]}]}
{"op":"mcm","clk":"AOumnQkAifKKCgDc3pUK","pt":1657537495515,"mc":[{"id":"1.200806927","rc":[{"atl":[[1.4,99.18]],"id":228749}]}]}
{"op":"mcm","clk":"AMmpnQkAyfWKCgCI4ZUK","pt":1657537500691,"mc":[{"id":"1.200806927","rc":[{"atb":[[1.27,0]],"atl":[[1.27,2.15]],"id":228749}]}]}
{"op":"mcm","clk":"APGsnQkAgfmKCgD945UK","pt":1657537505990,"mc":[{"id":"1.200806927","rc":[{"atl":[[1.27,2.05]],"id":228749}]}]}
{"op":"mcm","clk":"AJivnQkAn/uKCgD85ZUK","pt":1657537510107,"mc":[{"id":"1.200806927","rc":[{"atl":[[1.27,76.47]],"id":228749}]}]}
{"op":"mcm","clk":"AOWwnQkA4fyKCgCT55UK","pt":1657537512606,"mc":[{"id":"1.200806927","rc":[{"atl":[[1.4,90.16]],"id":228749}]}]}
{"op":"mcm","clk":"APC4nQkAooWLCgC+7ZUK","pt":1657537525962,"mc":[{"id":"1.200806927","rc":[{"atl":[[1.32,69.4]],"id":228749}]}]}
{"op":"mcm","clk":"AI+5nQkAx4WLCgDU7ZUK","pt":1657537526331,"mc":[{"id":"1.200806927","rc":[{"atl":[[1.27,65.31]],"trd":[[1.27,242.2]],"ltp":1.27,"tv":3596.78,"id":228749},{"trd":[[4.7,48.6]],"ltp":4.7,"tv":695.79,"id":2857977}],"tv":4292.57}]}
{"op":"mcm","clk":"AP65nQkAwoaLCgCl7pUK","pt":1657537528023,"mc":[{"id":"1.200806927","rc":[{"atl":[[1.4,0]],"id":228749}]}]}
{"op":"mcm","clk":"AJS8nQkA5IiLCgDw75UK","pt":1657537531719,"mc":[{"id":"1.200806927","rc":[{"atl":[[5.3,0]],"id":2857977}]}]}
{"op":"mcm","clk":"ALK/nQkAyYyLCgC28pUK","pt":1657537537340,"mc":[{"id":"1.200806927","rc":[{"atl":[[1.27,64.07]],"trd":[[1.27,244.7]],"tv":3599.28,"id":228749}],"tv":4295.07}]}
{"op":"mcm","clk":"AL7NnQkA2p2LCgCT/pUK","pt":1657537561399,"mc":[{"id":"1.200806927","rc":[{"atl":[[1.27,63.59]],"trd":[[1.27,245.17]],"tv":3599.75,"id":228749},{"trd":[[4.7,48.73]],"tv":695.92,"id":2857977}],"tv":4295.67}]}
{"op":"mcm","clk":"AI/PnQkAyZ+LCgCo/5UK","pt":1657537563817,"mc":[{"id":"1.200806927","rc":[{"atl":[[1.27,63.22]],"trd":[[1.27,245.54]],"tv":3600.12,"id":228749},{"trd":[[4.7,48.83]],"tv":696.02,"id":2857977}],"tv":4296.14}]}
{"op":"mcm","clk":"AJfanQkAp6yLCgD0iJYK","pt":1657537581043,"mc":[{"id":"1.200806927","rc":[{"atl":[[1.27,61.38]],"trd":[[1.27,247.38]],"tv":3601.96,"id":228749},{"trd":[[4.7,49.32]],"tv":696.51,"id":2857977}],"tv":4298.47}]}
{"op":"mcm","clk":"ANzenQkAnbKLCgDTjJYK","pt":1657537588244,"mc":[{"id":"1.200806927","rc":[{"atb":[[1.26,181.68]],"trd":[[1.26,335.12]],"ltp":1.26,"tv":3603.16,"id":228749}],"tv":4299.67}]}
{"op":"mcm","clk":"AMDnnQkAy72LCgDHk5YK","pt":1657537602347,"mc":[{"id":"1.200806927","rc":[{"atb":[[1.26,180.34]],"trd":[[1.26,337.8]],"tv":3605.84,"id":228749}],"tv":4302.35}]}
{"op":"mcm","clk":"AKfvnQkAyMeLCgDsmZYK","pt":1657537615057,"mc":[{"id":"1.200806927","rc":[{"atb":[[1.26,179.54]],"trd":[[1.26,339.4]],"tv":3607.44,"id":228749}],"tv":4303.95}]}
{"op":"mcm","clk":"AJr0nQkAt86LCgD8npYK","pt":1657537624697,"mc":[{"id":"1.200806927","rc":[{"atl":[[1.6,0.34]],"id":228749}]}]}
{"op":"mcm","clk":"AKn0nQkA086LCgCQn5YK","pt":1657537625006,"mc":[{"id":"1.200806927","rc":[{"atb":[[1.26,175.99]],"trd":[[1.26,346.51]],"tv":3614.55,"id":228749}],"tv":4311.06}]}
{"op":"mcm","clk":"AJH1nQkA38+LCgD+n5YK","pt":1657537626412,"mc":[{"id":"1.200806927","rc":[{"atl":[[1.27,60.52]],"trd":[[1.27,249.1]],"ltp":1.27,"tv":3616.27,"id":228749}],"tv":4312.78}]}
{"op":"mcm","clk":"AMCCngkAm+KLCgDwrZYK","pt":1657537651533,"mc":[{"id":"1.200806927","rc":[{"atl":[[1.27,42.49]],"trd":[[1.27,285.18]],"tv":3652.35,"id":228749}],"tv":4348.86}]}
{"op":"mcm","clk":"ALaFngkAv+aLCgD/sJYK","pt":1657537656936,"mc":[{"id":"1.200806927","rc":[{"atb":[[1.26,174.14]],"trd":[[1.26,350.21]],"ltp":1.26,"tv":3656.05,"id":228749}],"tv":4352.56}]}
{"op":"mcm","clk":"AKaGngkA4ueLCgD4sZYK","pt":1657537658488,"mc":[{"id":"1.200806927","rc":[{"atl":[[1.27,38.18]],"trd":[[1.27,293.79]],"ltp":1.27,"tv":3664.66,"id":228749}],"tv":4361.17}]}
{"op":"mcm","clk":"AP6HngkAnuqLCgDVs5YK","pt":1657537661663,"mc":[{"id":"1.200806927","rc":[{"atl":[[1.27,36.59]],"trd":[[1.27,295.38]],"tv":3666.25,"id":228749},{"trd":[[4.7,49.75]],"tv":696.94,"id":2857977}],"tv":4363.19}]}
{"op":"mcm","clk":"AI6IngkAs+qLCgDls5YK","pt":1657537661824,"mc":[{"id":"1.200806927","rc":[{"atl":[[1.6,0]],"id":228749}]}]}
{"op":"mcm","clk":"AKSMngkAvvCLCgDPt5YK","pt":1657537669580,"mc":[{"id":"1.200806927","rc":[{"atb":[[1.27,89.64]],"atl":[[1.27,0]],"trd":[[1.27,368.56]],"tv":3739.43,"id":228749}],"tv":4436.37}]}
{"op":"mcm","clk":"APmMngkAtPGLCgCzuJYK","pt":1657537670869,"mc":[{"id":"1.200806927","rc":[{"atb":[[1.27,90.49]],"id":228749}]}]}
{"op":"mcm","clk":"AI2ZngkAooKMCgCIxJYK","pt":1657537692256,"mc":[{"id":"1.200806927","rc":[{"atl":[[1.32,63.02]],"trd":[[1.32,441.02]],"ltp":1.32,"tv":3745.81,"id":228749},{"trd":[[4.1,2.05]],"ltp":4.1,"tv":698.99,"id":2857977}],"tv":4444.8}]}
{"op":"mcm","clk":"ANWZngkAjoOMCgDXxJYK","pt":1657537693396,"mc":[{"id":"1.200806927","rc":[{"atl":[[1.31,90.16]],"id":228749}]}]}
{"op":"mcm","clk":"ALmgngkA642MCgD4ypYK","pt":1657537706215,"mc":[{"id":"1.200806927","rc":[{"atl":[[1.31,89.61]],"trd":[[1.31,35.05]],"ltp":1.31,"tv":3746.36,"id":228749},{"trd":[[4.2,116.45]],"ltp":4.2,"tv":699.16,"id":2857977}],"tv":4445.52}]}
{"op":"mcm","clk":"AKmkngkAkJOMCgCwzpYK","pt":1657537713050,"mc":[{"id":"1.200806927","rc":[{"atl":[[2.14,0.34]],"id":228749}]}]}
{"op":"mcm","clk":"AIupngkAv5qMCgCR05YK","pt":1657537721902,"mc":[{"id":"1.200806927","rc":[{"atl":[[1.31,89.5]],"trd":[[1.31,35.27]],"tv":3746.58,"id":228749}],"tv":4445.74}]}
{"op":"mcm","clk":"AJKrngkAq52MCgCM1ZYK","pt":1657537725702,"mc":[{"id":"1.200806927","rc":[{"atl":[[1.31,88.12]],"trd":[[1.31,36.65]],"tv":3747.96,"id":228749},{"trd":[[4.2,116.89]],"tv":699.6,"id":2857977}],"tv":4447.56}]}
{"op":"mcm","clk":"AN+rngkApJ6MCgDo1ZYK","pt":1657537727119,"mc":[{"id":"1.200806927","rc":[{"atl":[[12,0.11]],"id":2857977}]}]}
{"op":"mcm","clk":"APKtngkA3KGMCgCt2JYK","pt":1657537731931,"mc":[{"id":"1.200806927","rc":[{"atl":[[1.31,87.78]],"trd":[[1.31,36.99]],"tv":3748.3,"id":228749},{"trd":[[4.2,116.99]],"tv":699.7,"id":2857977}],"tv":4448}]}
{"op":"mcm","clk":"AOa5ngkAz7SMCgDO5JYK","pt":1657537756464,"mc":[{"id":"1.200806927","rc":[{"atb":[[1.3,8.61]],"id":228749}]}]}
{"op":"mcm","clk":"APC6ngkA5bWMCgDH5ZYK","pt":1657537757945,"mc":[{"id":"1.200806927","rc":[{"atb":[[1.3,0],[1.27,0]],"atl":[[1.27,125.41]],"trd":[[1.3,259.55],[1.27,370.26]],"ltp":1.27,"tv":3767.21,"id":228749}],"tv":4466.91}]}
{"op":"mcm","clk":"ANO9ngkA7bmMCgCd6JYK","pt":1657537763076,"mc":[{"id":"1.200806927","rc":[{"atl":[[1.27,104.94]],"trd":[[1.27,411.2]],"tv":3808.15,"id":228749}],"tv":4507.85}]}
{"op":"mcm","clk":"AInEngkA+MOMCgDr7ZYK","pt":1657537776519,"mc":[{"id":"1.200806927","rc":[{"atl":[[1.27,101.81]],"trd":[[1.27,414.33]],"tv":3811.28,"id":228749},{"trd":[[4.7,50.6]],"ltp":4.7,"tv":700.55,"id":2857977}],"tv":4511.83}]}
{"op":"mcm","clk":"AMDEngkA2sSMCgCo7pYK","pt":1657537777404,"mc":[{"id":"1.200806927","rc":[{"atl":[[1.27,101.42]],"trd":[[1.27,414.72]],"tv":3811.67,"id":228749},{"trd":[[4.7,50.71]],"tv":700.66,"id":2857977}],"tv":4512.33}]}
{"op":"mcm","clk":"AL7FngkAscaMCgCk75YK","pt":1657537779615,"mc":[{"id":"1.200806927","rc":[{"atb":[[1.26,154.69]],"trd":[[1.26,369.65]],"ltp":1.26,"tv":3831.11,"id":228749},{"trd":[[4.9,63.77]],"ltp":4.9,"tv":705.66,"id":2857977}],"tv":4536.77}]}
{"op":"mcm","clk":"AP/JngkA7M2MCgCf85YK","pt":1657537789518,"mc":[{"id":"1.200806927","rc":[{"atb":[[1.26,150.43]],"trd":[[1.26,378.17]],"tv":3839.63,"id":228749}],"tv":4545.29}]}
{"op":"mcm","clk":"AKHMngkAlNKMCgDU9ZYK","pt":1657537794623,"mc":[{"id":"1.200806927","rc":[{"atl":[[1.27,101.03]],"trd":[[1.27,415.11]],"ltp":1.27,"tv":3840.02,"id":228749},{"trd":[[4.7,50.81]],"ltp":4.7,"tv":705.76,"id":2857977}],"tv":4545.78}]}
{"op":"mcm","clk":"AMvSngkAot2MCgCp+pYK","pt":1657537806649,"mc":[{"id":"1.200806927","rc":[{"atl":[[1.27,0]],"id":228749}]}]}
{"op":"mcm","clk":"APfSngkAi96MCgDb+pYK","pt":1657537807454,"mc":[{"id":"1.200806927","rc":[{"atb":[[1.27,0.43]],"id":228749}]}]}
{"op":"mcm","clk":"AMzTngkAqt+MCgCl+5YK","pt":1657537808764,"mc":[{"id":"1.200806927","rc":[{"atl":[[4.7,0.11]],"id":2857977}]}]}
{"op":"mcm","clk":"AMHangkA6OmMCgCggJcK","pt":1657537820954,"mc":[{"id":"1.200806927","rc":[{"atb":[[1.26,50.18],[1.27,0]],"trd":[[1.26,578.67],[1.27,416.36]],"ltp":1.26,"tv":4041.77,"id":228749},{"atl":[[4.7,0]],"trd":[[4.7,50.92]],"tv":705.87,"id":2857977}],"tv":4747.64}]}
{"op":"mcm","clk":"AN/angkAnOqMCgCtgJcK","pt":1657537821368,"mc":[{"id":"1.200806927","rc":[{"atl":[[4.8,1.16]],"id":2857977}]}]}
{"op":"mcm","clk":"AOnengkA3PGMCgCHhJcK","pt":1657537829980,"mc":[{"id":"1.200806927","rc":[{"atb":[[1.27,0.34]],"id":228749}]}]}
{"op":"mcm","clk":"ANvlngkAnf6MCgDniZcK","pt":1657537844343,"mc":[{"id":"1.200806927","rc":[{"atl":[[1.42,4.18]],"id":228749}]}]}
{"op":"mcm","clk":"AM3pngkAk4eNCgCxjZcK","pt":1657537853667,"mc":[{"id":"1.200806927","rc":[{"atl":[[1.3,2.51]],"id":228749}]}]}
{"op":"mcm","clk":"AJHqngkApoiNCgDxjZcK","pt":1657537854856,"mc":[{"id":"1.200806927","rc":[{"atl":[[4.8,0]],"id":2857977}]}]}
{"op":"mcm","clk":"APPqngkA84mNCgDJjpcK","pt":1657537856704,"mc":[{"id":"1.200806927","rc":[{"atl":[[1.3,1.09]],"trd":[[1.3,260.98]],"ltp":1.3,"tv":4043.2,"id":228749},{"trd":[[4.3,236.81]],"ltp":4.3,"tv":706.3,"id":2857977}],"tv":4749.5}]}
{"op":"mcm","clk":"AP3zngkAzJqNCgDwlJcK","pt":1657537874791,"mc":[{"id":"1.200806927","rc":[{"atl":[[4.7,0.11]],"id":2857977}]}]}
{"op":"mcm","clk":"AOH8ngkAyqmNCgDGm5cK","pt":1657537891414,"mc":[{"id":"1.200806927","rc":[{"atl":[[1.31,86.13],[1.3,0]],"trd":[[1.31,38.64],[1.3,262.06]],"ltp":1.31,"tv":4045.93,"id":228749},{"trd":[[4.2,117.51],[4.3,237.14]],"ltp":4.2,"tv":707.15,"id":2857977}],"tv":4753.08}]}
{"op":"mcm","clk":"APf9ngkAw6uNCgCjnJcK","pt":1657537893517,"mc":[{"id":"1.200806927","rc":[{"atl":[[4.7,0]],"id":2857977}]}]}
{"op":"mcm","clk":"AOGAnwkArLCNCgC8npcK","pt":1657537898818,"mc":[{"id":"1.200806927","rc":[{"atl":[[1.31,85.79]],"trd":[[1.31,38.98]],"tv":4046.27,"id":228749},{"trd":[[4.2,117.61]],"tv":707.25,"id":2857977}],"tv":4753.52}]}
{"op":"mcm","clk":"APaSnwkA5M+NCgCErZcK","pt":1657537934193,"mc":[{"id":"1.200806927","rc":[{"atb":[[1.17,418.1]],"id":228749}]}]}
{"op":"mcm","clk":"AL6jnwkA+umNCgCAuJcK","pt":1657537962620,"mc":[{"id":"1.200806927","rc":[{"atl":[[1.31,80.02]],"trd":[[1.31,44.75]],"tv":4052.04,"id":228749},{"trd":[[4.2,119.41]],"tv":709.05,"id":2857977}],"tv":4761.09}]}
{"op":"mcm","clk":"AMWjnwkAgeqNCgCCuJcK","pt":1657537962717,"mc":[{"id":"1.200806927","rc":[{"atl":[[1.31,79.23]],"trd":[[1.31,45.54]],"tv":4052.83,"id":228749},{"trd":[[4.2,119.66]],"tv":709.3,"id":2857977}],"tv":4762.13}]}
{"op":"mcm","clk":"ALemnwkAtu6NCgD3uZcK","pt":1657537967554,"mc":[{"id":"1.200806927","rc":[{"atb":[[1.26,48.04],[1.27,0]],"trd":[[1.26,582.95],[1.27,417.04]],"ltp":1.26,"tv":4057.79,"id":228749}],"tv":4767.09}]}
{"op":"mcm","clk":"AMSpnwkAkPONCgCXvJcK","pt":1657537972717,"mc":[{"id":"1.200806927","rc":[{"atb":[[1.25,4.95]],"id":228749}]}]}
{"op":"mcm","clk":"AI2unwkAufqNCgCTv5cK","pt":1657537980496,"mc":[{"id":"1.200806927","rc":[{"atb":[[1.25,0]],"id":228749}]}]}
{"op":"mcm","clk":"AN+wnwkAs/6NCgC0wJcK","pt":1657537984300,"mc":[{"id":"1.200806927","rc":[{"atl":[[1.31,76.52]],"trd":[[1.31,48.25]],"ltp":1.31,"tv":4060.5,"id":228749},{"trd":[[4.2,120.51]],"tv":710.15,"id":2857977}],"tv":4770.65}]}
{"op":"mcm","clk":"AKKznwkAqoKOCgCFwpcK","pt":1657537988299,"mc":[{"id":"1.200806927","rc":[{"atl":[[1.31,76.09]],"trd":[[1.31,49.11]],"tv":4061.36,"id":228749}],"tv":4771.51}]}
{"op":"mcm","clk":"AMu1nwkAm4eOCgD+w5cK","pt":1657537992704,"mc":[{"id":"1.200806927","rc":[{"atb":[[1.27,3]],"id":228749}]}]}
{"op":"mcm","clk":"AMC6nwkAw4+OCgCyx5cK","pt":1657538001427,"mc":[{"id":"1.200806927","rc":[{"atl":[[1.31,75.68]],"trd":[[1.31,49.52]],"tv":4061.77,"id":228749},{"trd":[[4.2,120.63]],"tv":710.27,"id":2857977}],"tv":4772.04}]}
{"op":"mcm","clk":"AMG9nwkA8JOOCgCkyZcK","pt":1657538006262,"mc":[{"id":"1.200806927","rc":[{"atb":[[1.28,4]],"id":228749}]}]}
{"op":"mcm","clk":"AKrBnwkA4JqOCgCQzJcK","pt":1657538012182,"mc":[{"id":"1.200806927","rc":[{"atl":[[1.68,7.53]],"id":228749}]}]}
{"op":"mcm","clk":"AJ/EnwkA1J+OCgC1zpcK","pt":1657538016953,"mc":[{"id":"1.200806927","rc":[{"atb":[[1.3,4]],"id":228749}]}]}
{"op":"mcm","clk":"AKXJnwkA+6aOCgCT0pcK","pt":1657538025106,"mc":[{"id":"1.200806927","rc":[{"atl":[[1.31,74.3]],"trd":[[1.31,50.9]],"tv":4063.15,"id":228749},{"trd":[[4.2,121.07]],"tv":710.71,"id":2857977}],"tv":4773.86}]}
{"op":"mcm","clk":"AI3KnwkAgKiOCgDW0pcK","pt":1657538026382,"mc":[{"id":"1.200806927","rc":[{"atb":[[1.3,1.49]],"trd":[[1.3,267.08]],"ltp":1.3,"tv":4068.17,"id":228749}],"tv":4778.88}]}
{"op":"mcm","clk":"AOPKnwkAjamOCgCa05cK","pt":1657538027690,"mc":[{"id":"1.200806927","rc":[{"atb":[[1.29,3]],"id":228749}]}]}
{"op":"mcm","clk":"AIPOnwkAva2OCgC01ZcK","pt":1657538033210,"mc":[{"id":"1.200806927","rc":[{"atb":[[1.3,0]],"atl":[[1.3,35.64]],"trd":[[1.3,270.06]],"tv":4071.15,"id":228749}],"tv":4781.86}]}
{"op":"mcm","clk":"AMfQnwkA9rCOCgCJ15cK","pt":1657538037401,"mc":[{"id":"1.200806927","rc":[{"atl":[[1.3,31.64]],"trd":[[1.3,278.06]],"tv":4079.15,"id":228749}],"tv":4789.86}]}
{"op":"mcm","clk":"APjWnwkA/biOCgCS25cK","pt":1657538046949,"mc":[{"id":"1.200806927","rc":[{"atb":[[1.28,7]],"id":228749}]}]}
{"op":"mcm","clk":"ALnXnwkAy7mOCgC325cK","pt":1657538047742,"mc":[{"id":"1.200806927","rc":[{"atl":[[1.3,30.22]],"trd":[[1.3,279.48]],"tv":4080.57,"id":228749},{"trd":[[4.3,237.57]],"ltp":4.3,"tv":711.14,"id":2857977}],"tv":4791.71}]}
{"op":"mcm","clk":"AN7bnwkApr6OCgCQ3pcK","pt":1657538054873,"mc":[{"id":"1.200806927","rc":[{"atb":[[1.28,4]],"id":228749}]}]}
{"op":"mcm","clk":"AKLlnwkAsMmOCgC05JcK","pt":1657538070394,"mc":[{"id":"1.200806927","rc":[{"atb":[[1.29,0],[1.27,0],[1.28,0]],"id":228749}]}]}
{"op":"mcm","clk":"APTtnwkAs9OOCgDc6ZcK","pt":1657538084617,"mc":[{"id":"1.200806927","rc":[{"atl":[[1.3,29.65]],"trd":[[1.3,280.05]],"tv":4081.14,"id":228749},{"trd":[[4.3,237.75]],"tv":711.32,"id":2857977}],"tv":4792.46}]}
{"op":"mcm","clk":"APjvnwkArdWOCgCO65cK","pt":1657538087824,"mc":[{"id":"1.200806927","rc":[{"atl":[[1.3,29.3]],"trd":[[1.3,280.4]],"tv":4081.49,"id":228749},{"trd":[[4.3,237.85]],"tv":711.42,"id":2857977}],"tv":4792.91}]}
{"op":"mcm","clk":"APzxnwkAodeOCgCs7JcK","pt":1657538090982,"mc":[{"id":"1.200806927","rc":[{"atb":[[1.26,38.04]],"trd":[[1.26,602.95]],"ltp":1.26,"tv":4101.49,"id":228749}],"tv":4812.91}]}
{"op":"mcm","clk":"AJaFoAkAz+mOCgD+95cK","pt":1657538118421,"mc":[{"id":"1.200806927","rc":[{"atl":[[1.3,28.95]],"trd":[[1.3,280.75]],"ltp":1.3,"tv":4101.84,"id":228749},{"trd":[[4.3,237.96]],"tv":711.53,"id":2857977}],"tv":4813.37}]}
{"op":"mcm","clk":"AL2IoAkAteyOCgDm+ZcK","pt":1657538122998,"mc":[{"id":"1.200806927","rc":[{"atb":[[1.26,18.04]],"trd":[[1.26,642.95]],"ltp":1.26,"tv":4141.84,"id":228749}],"tv":4853.37}]}
{"op":"mcm","clk":"ANKIoAkAyOyOCgD0+ZcK","pt":1657538123207,"mc":[{"id":"1.200806927","rc":[{"atb":[[1.27,15.87]],"id":228749}]}]}
{"op":"mcm","clk":"AJuPoAkA4fKOCgD6/ZcK","pt":1657538132813,"mc":[{"id":"1.200806927","rc":[{"atb":[[1.29,0.11]],"id":228749}]}]}
{"op":"mcm","clk":"AM+SoAkA6/WOCgD9/5cK","pt":1657538136554,"mc":[{"id":"1.200806927","rc":[{"atl":[[1.3,16.04]],"trd":[[1.3,293.66]],"ltp":1.3,"tv":4154.75,"id":228749},{"trd":[[4.3,241.86]],"tv":715.43,"id":2857977}],"tv":4870.18}]}
{"op":"mcm","clk":"ALyUoAkA5PeOCgCQgZgK","pt":1657538139251,"mc":[{"id":"1.200806927","rc":[{"atl":[[1.3,0]],"trd":[[1.3,309.7]],"tv":4170.79,"id":228749},{"atl":[[4.3,0.29]],"trd":[[4.3,246.71]],"tv":720.28,"id":2857977}],"tv":4891.07}]}
{"op":"mcm","clk":"AOOZoAkAiP2OCgC1hJgK","pt":1657538147368,"mc":[{"id":"1.200806927","rc":[{"atl":[[4.3,0.39]],"id":2857977}]}]}
{"op":"mcm","clk":"AMmaoAkA//2OCgDwhJgK","pt":1657538148512,"mc":[{"id":"1.200806927","rc":[{"atl":[[4.3,0.57]],"id":2857977}]}]}
{"op":"mcm","clk":"AOWjoAkAxIePCgCMi5gK","pt":1657538161414,"mc":[{"id":"1.200806927","rc":[{"atl":[[4.3,0.39]],"id":2857977}]}]}
{"op":"mcm","clk":"AIamoAkA8ImPCgCijJgK","pt":1657538164596,"mc":[{"id":"1.200806927","rc":[{"atl":[[1.31,73.31]],"id":228749}]}]}
{"op":"mcm","clk":"AMSooAkAx4yPCgDQjZgK","pt":1657538168203,"mc":[{"id":"1.200806927","rc":[{"atl":[[1.3,2.2]],"trd":[[1.3,311]],"tv":4172.09,"id":228749},{"atl":[[4.3,0]],"trd":[[4.3,247.11]],"tv":720.68,"id":2857977}],"tv":4892.77}]}
{"op":"mcm","clk":"AJasoAkAvpCPCgD7j5gK","pt":1657538173610,"mc":[{"id":"1.200806927","rc":[{"atl":[[1.3,1.85]],"trd":[[1.3,311.35]],"tv":4172.44,"id":228749},{"trd":[[4.3,247.21]],"tv":720.78,"id":2857977}],"tv":4893.22}]}
{"op":"mcm","clk":"AOmxoAkA6ZaPCgCilJgK","pt":1657538182719,"mc":[{"id":"1.200806927","rc":[{"atb":[[1.07,147.26]],"id":228749}]}]}
{"op":"mcm","clk":"AJC5oAkAw56PCgDpmJgK","pt":1657538194608,"mc":[{"id":"1.200806927","rc":[{"atl":[[1000,0.13]],"id":228749}]}]}
{"op":"mcm","clk":"APG6oAkAn6CPCgCAmpgK","pt":1657538197571,"mc":[{"id":"1.200806927","rc":[{"atl":[[1.32,0]],"id":228749}]}]}
{"op":"mcm","clk":"AJq9oAkAx6KPCgCmm5gK","pt":1657538201430,"mc":[{"id":"1.200806927","rc":[{"atl":[[1.3,1.5]],"trd":[[1.3,311.7]],"tv":4172.79,"id":228749},{"trd":[[4.3,247.32]],"tv":720.89,"id":2857977}],"tv":4893.68}]}
{"op":"mcm","clk":"APK9oAkAqqOPCgDom5gK","pt":1657538202568,"mc":[{"id":"1.200806927","rc":[{"atb":[[1.29,0]],"atl":[[1.29,62.91]],"trd":[[1.29,0.22]],"ltp":1.29,"tv":4173.01,"id":228749}],"tv":4893.9}]}
{"op":"mcm","clk":"ANK+oAkAkqSPCgCdnJgK","pt":1657538203863,"mc":[{"id":"1.200806927","rc":[{"atl":[[1.29,62.47]],"trd":[[1.29,0.66]],"tv":4173.45,"id":228749},{"trd":[[4.4,11.1]],"ltp":4.4,"tv":721.02,"id":2857977}],"tv":4894.47}]}
{"op":"mcm","clk":"AI6/oAkAyqSPCgDCnJgK","pt":1657538204567,"mc":[{"id":"1.200806927","rc":[{"atl":[[1.29,61.47]],"trd":[[1.29,2.66]],"tv":4175.45,"id":228749}],"tv":4896.47}]}
{"op":"mcm","clk":"AMi/oAkA+6SPCgDhnJgK","pt":1657538205252,"mc":[{"id":"1.200806927","rc":[{"atb":[[1.07,147.26]],"id":2857977}]}]}
{"op":"mcm","clk":"ALTEoAkA4amPCgDfn5gK","pt":1657538212382,"mc":[{"id":"1.200806927","rc":[{"atl":[[1000,0.13]],"id":2857977}]}]}
{"op":"mcm","clk":"AK3HoAkA36yPCgDboZgK","pt":1657538216982,"mc":[{"id":"1.200806927","rc":[{"atb":[[1.22,231.62]],"id":228749}]}]}
{"op":"mcm","clk":"AP3NoAkAwbKPCgCOppgK","pt":1657538226084,"mc":[{"id":"1.200806927","rc":[{"atl":[[1.29,60.62]],"trd":[[1.29,4.35]],"tv":4177.14,"id":228749}],"tv":4898.16}]}
{"op":"mcm","clk":"AJPRoAkAl7WPCgCvqJgK","pt":1657538230614,"mc":[{"id":"1.200806927","rc":[{"atl":[[1.29,60.26]],"trd":[[1.29,4.71]],"tv":4177.5,"id":228749},{"trd":[[4.4,11.21]],"tv":721.13,"id":2857977}],"tv":4898.63}]}
{"op":"mcm","clk":"AJnSoAkA/7WPCgCRqZgK","pt":1657538232225,"mc":[{"id":"1.200806927","rc":[{"atl":[[1.29,24.24]],"trd":[[1.29,40.73]],"tv":4213.52,"id":228749},{"trd":[[4.4,21.77]],"tv":731.69,"id":2857977}],"tv":4945.21}]}
{"op":"mcm","clk":"APzVoAkA0LmPCgCArJgK","pt":1657538237390,"mc":[{"id":"1.200806927","rc":[{"atl":[[1.29,19.43]],"trd":[[1.29,45.54]],"tv":4218.33,"id":228749},{"trd":[[4.4,23.18]],"tv":733.1,"id":2857977}],"tv":4951.43}]}
{"op":"mcm","clk":"AKLdoAkA/MCPCgCPspgK","pt":1657538248971,"mc":[{"id":"1.200806927","rc":[{"atl":[[1.31,64.17],[1.29,0],[1.3,0]],"trd":[[1.31,60.04],[1.29,64.98],[1.3,313.2]],"ltp":1.31,"tv":4248.41,"id":228749},{"trd":[[4.2,123.92],[4.4,28.88],[4.3,247.77]],"ltp":4.2,"tv":742.1,"id":2857977}],"tv":4990.51}]}
{"op":"mcm","clk":"AKLooAkAsMyPCgCeuZgK","pt":1657538265993,"mc":[{"id":"1.200806927","rc":[{"atb":[[1.28,2.15]],"id":228749}]}]}
{"op":"mcm","clk":"ALP4oAkAt9yPCgDyw5gK","pt":1657538291946,"mc":[{"id":"1.200806927","rc":[{"atl":[[1.3,1.72]],"id":228749}]}]}
{"op":"mcm","clk":"AJT8oAkAkeCPCgCDxpgK","pt":1657538297951,"mc":[{"id":"1.200806927","rc":[{"atl":[[1.31,63.77],[1.3,0]],"trd":[[1.31,60.44],[1.3,314.92]],"tv":4250.53,"id":228749},{"trd":[[4.2,124.04],[4.3,248.29]],"tv":742.74,"id":2857977}],"tv":4993.27}]}
{"op":"mcm","clk":"AO+DoQkAxeePCgCsypgK","pt":1657538309358,"mc":[{"id":"1.200806927","rc":[{"atl":[[1.31,63.08]],"trd":[[1.31,61.13]],"tv":4251.22,"id":228749},{"trd":[[4.2,124.25]],"tv":742.95,"id":2857977}],"tv":4994.17}]}
{"op":"mcm","clk":"APaDoQkAzOePCgCxypgK","pt":1657538309464,"mc":[{"id":"1.200806927","rc":[{"atl":[[1.31,0]],"trd":[[1.31,124.21]],"tv":4314.3,"id":228749},{"atl":[[4.2,7.38]],"trd":[[4.2,143.92]],"tv":762.62,"id":2857977}],"tv":5076.92}]}
{"op":"mcm","clk":"AO+EoQkAyuiPCgCRy5gK","pt":1657538311079,"mc":[{"id":"1.200806927","rc":[{"atl":[[4.2,7.49]],"id":2857977}]}]}
{"op":"mcm","clk":"AJyFoQkAhOmPCgC1y5gK","pt":1657538311749,"mc":[{"id":"1.200806927","rc":[{"atb":[[1.3,2.15]],"id":228749}]}]}
{"op":"mcm","clk":"ALGFoQkAmumPCgDGy5gK","pt":1657538312053,"mc":[{"id":"1.200806927","rc":[{"atl":[[4.2,16.51]],"id":2857977}]}]}
{"op":"mcm","clk":"AOyFoQkA6OmPCgDgy5gK","pt":1657538312949,"mc":[{"id":"1.200806927","rc":[{"atb":[[1.28,0]],"id":228749}]}]}
{"op":"mcm","clk":"ANKIoQkAk5+QCgCuzZgK","pt":1657538317293,"mc":[{"id":"1.200806927","rc":[{"trd":[[1.31,150.27]],"tv":4340.36,"id":228749},{"atl":[[4.2,8.38]],"trd":[[4.2,152.05]],"tv":770.75,"id":2857977}],"tv":5111.11}]}
{"op":"mcm","clk":"AJmOoQkA/6SQCgC+0JgK","pt":1657538325582,"mc":[{"id":"1.200806927","rc":[{"trd":[[1.31,150.41]],"tv":4340.5,"id":228749},{"atl":[[4.2,8.33]],"trd":[[4.2,152.1]],"tv":770.8,"id":2857977}],"tv":5111.3}]}
{"op":"mcm","clk":"AJmPoQkAgaaQCgCO0ZgK","pt":1657538327097,"mc":[{"id":"1.200806927","rc":[{"atl":[[1.37,64.39]],"id":228749}]}]}
{"op":"mcm","clk":"AKqQoQkA6aaQCgDU0ZgK","pt":1657538328520,"mc":[{"id":"1.200806927","rc":[{"atb":[[1.32,2.15]],"id":228749}]}]}
{"op":"mcm","clk":"AMyRoQkA7qeQCgCZ0pgK","pt":1657538330380,"mc":[{"id":"1.200806927","rc":[{"atl":[[1.41,9.02]],"id":228749}]}]}
{"op":"mcm","clk":"AM+SoQkA46iQCgDh0pgK","pt":1657538331896,"mc":[{"id":"1.200806927","rc":[{"atl":[[1.35,4]],"id":228749}]}]}
{"op":"mcm","clk":"AO+UoQkArKuQCgCZ1JgK","pt":1657538335981,"mc":[{"id":"1.200806927","rc":[{"atl":[[1.41,0]],"id":228749}]}]}
{"op":"mcm","clk":"ANaXoQkA2K6QCgDX1ZgK","pt":1657538340939,"mc":[{"id":"1.200806927","rc":[{"atb":[[1.32,1.72]],"id":228749}]}]}
{"op":"mcm","clk":"APiXoQkA966QCgDr1ZgK","pt":1657538341306,"mc":[{"id":"1.200806927","rc":[{"atl":[[1.33,4.32]],"id":228749}]}]}
{"op":"mcm","clk":"ANGZoQkAxrCQCgD01pgK","pt":1657538343837,"mc":[{"id":"1.200806927","rc":[{"atl":[[1.33,3.46]],"trd":[[1.33,3.52]],"ltp":1.33,"tv":4342.21,"id":228749}],"tv":5113.01}]}
{"op":"mcm","clk":"APuaoQkA6bGQCgDI15gK","pt":1657538345807,"mc":[{"id":"1.200806927","rc":[{"atb":[[1.32,1.61]],"id":228749}]}]}
{"op":"mcm","clk":"AJWdoQkA57OQCgDY2JgK","pt":1657538349223,"mc":[{"id":"1.200806927","rc":[{"atb":[[1.32,0]],"atl":[[1.31,224.13]],"trd":[[1.31,177.12],[1.32,444.25]],"ltp":1.31,"tv":4372.15,"id":228749},{"atl":[[4.2,0]],"trd":[[4.2,160.43]],"tv":779.13,"id":2857977}],"tv":5151.28}]}
{"op":"mcm","clk":"AP6doQkA17SQCgCX2ZgK","pt":1657538350637,"mc":[{"id":"1.200806927","rc":[{"atl":[[1.32,10]],"id":228749}]}]}
{"op":"mcm","clk":"APKeoQkA/rWQCgDn2ZgK","pt":1657538352439,"mc":[{"id":"1.200806927","rc":[{"atl":[[1.31,223.79]],"trd":[[1.31,177.46]],"tv":4372.49,"id":228749},{"trd":[[4.2,160.54]],"tv":779.24,"id":2857977}],"tv":5151.73}]}
{"op":"mcm","clk":"AJCgoQkAt7eQCgC22pgK","pt":1657538354497,"mc":[{"id":"1.200806927","rc":[{"atl":[[1000,2.64]],"id":228749}]}]}
{"op":"mcm","clk":"ALegoQkA4reQCgDK2pgK","pt":1657538354921,"mc":[{"id":"1.200806927","rc":[{"atl":[[1000,1.8]],"id":228749}]}]}
{"op":"mcm","clk":"ANqgoQkAh7iQCgDY2pgK","pt":1657538355329,"mc":[{"id":"1.200806927","rc":[{"atl":[[1000,0.13]],"id":228749}]}]}
{"op":"mcm","clk":"AN2ioQkApLqQCgD/25gK","pt":1657538358603,"mc":[{"id":"1.200806927","rc":[{"atl":[[1.31,223.24]],"trd":[[1.31,178.01]],"tv":4373.04,"id":228749},{"trd":[[4.2,160.71]],"tv":779.41,"id":2857977}],"tv":5152.45}]}
{"op":"mcm","clk":"AIqkoQkAt7uQCgDI3JgK","pt":1657538360443,"mc":[{"id":"1.200806927","rc":[{"atl":[[1.32,11.67]],"id":228749}]}]}
{"op":"mcm","clk":"AMWloQkAgL2QCgCj3ZgK","pt":1657538362621,"mc":[{"id":"1.200806927","rc":[{"atl":[[1.32,10]],"id":228749}]}]}
{"op":"mcm","clk":"APaooQkA2cCQCgDz3pgK","pt":1657538367714,"mc":[{"id":"1.200806927","rc":[{"atb":[[1.3,0.48]],"trd":[[1.3,318.27]],"ltp":1.3,"tv":4376.39,"id":228749}],"tv":5155.8}]}
{"op":"mcm","clk":"AL2poQkAq8GQCgCY35gK","pt":1657538368643,"mc":[{"id":"1.200806927","rc":[{"atl":[[1.32,12.15]],"id":228749}]}]}
{"op":"mcm","clk":"ANqpoQkA2MGQCgCk35gK","pt":1657538369115,"mc":[{"id":"1.200806927","rc":[{"atl":[[1.31,220.48]],"trd":[[1.31,180.77]],"ltp":1.31,"tv":4379.15,"id":228749},{"trd":[[4.2,161.57]],"tv":780.27,"id":2857977}],"tv":5159.42}]}
{"op":"mcm","clk":"AK6soQkArcSQCgDs4JgK","pt":1657538372849,"mc":[{"id":"1.200806927","rc":[{"atl":[[1.31,220.05]],"trd":[[1.31,181.63]],"tv":4380.01,"id":228749}],"tv":5160.28}]}
{"op":"mcm","clk":"AOSvoQkA8seQCgDN4pgK","pt":1657538378343,"mc":[{"id":"1.200806927","rc":[{"atl":[[1.31,218.67]],"trd":[[1.31,183.01]],"tv":4381.39,"id":228749},{"trd":[[4.2,162]],"tv":780.7,"id":2857977}],"tv":5162.09}]}
{"op":"mcm","clk":"AJawoQkApMiQCgDq4pgK","pt":1657538378942,"mc":[{"id":"1.200806927","rc":[{"atl":[[1.31,217.97]],"trd":[[1.31,184.41]],"tv":4382.79,"id":228749}],"tv":5163.49}]}
{"op":"mcm","clk":"APCwoQkA8siQCgCe45gK","pt":1657538380044,"mc":[{"id":"1.200806927","rc":[{"atb":[[1.3,0]],"id":228749}]}]}
{"op":"mcm","clk":"AL/AoQkA1NqQCgDV7JgK","pt":1657538405781,"mc":[{"id":"1.200806927","rc":[{"atl":[[1.32,10]],"id":228749}]}]}
{"op":"mcm","clk":"AMXHoQkAruKQCgCp8JgK","pt":1657538416681,"mc":[{"id":"1.200806927","rc":[{"atl":[[1.31,217.63]],"trd":[[1.31,184.75]],"tv":4383.13,"id":228749},{"trd":[[4.2,162.11]],"tv":780.81,"id":2857977}],"tv":5163.94}]}
{"op":"mcm","clk":"AK/IoQkAjOOQCgDp8JgK","pt":1657538417787,"mc":[{"id":"1.200806927","rc":[{"atl":[[1.3,2.15]],"id":228749}]}]}
{"op":"mcm","clk":"AKnKoQkAxOWQCgD88ZgK","pt":1657538420884,"mc":[{"id":"1.200806927","rc":[{"atl":[[1.3,1.8]],"trd":[[1.3,318.62]],"ltp":1.3,"tv":4383.48,"id":228749},{"trd":[[4.3,248.4]],"ltp":4.3,"tv":780.92,"id":2857977}],"tv":5164.4}]}
{"op":"mcm","clk":"APbMoQkArOiQCgC585gK","pt":1657538424788,"mc":[{"id":"1.200806927","rc":[{"atb":[[1.31,175.92]],"atl":[[1.31,0],[1.3,0]],"trd":[[1.31,620.01],[1.3,322.22]],"ltp":1.31,"tv":4822.34,"id":228749}],"tv":5603.26}]}
{"op":"mcm","clk":"AInQoQkAveuQCgCK9ZgK","pt":1657538429313,"mc":[{"id":"1.200806927","rc":[{"atb":[[1.31,0]],"id":228749}]}]}
{"op":"mcm","clk":"AKXQoQkA3euQCgCY9ZgK","pt":1657538429816,"mc":[{"id":"1.200806927","rc":[{"atb":[[1.3,6.46]],"id":228749}]}]}
{"op":"mcm","clk":"AM7RoQkAl+2QCgD99ZgK","pt":1657538431939,"mc":[{"id":"1.200806927","rc":[{"atb":[[1.3,0]],"id":228749}]}]}
{"op":"mcm","clk":"AKjXoQkAvfOQCgCt+ZgK","pt":1657538441329,"mc":[{"id":"1.200806927","rc":[{"atl":[[1.32,3.54]],"trd":[[1.32,457.16]],"ltp":1.32,"tv":4835.25,"id":228749}],"tv":5616.17}]}
{"op":"mcm","clk":"AMTYoQkA9PSQCgCR+pgK","pt":1657538443669,"mc":[{"id":"1.200806927","rc":[{"atb":[[1.32,166.68]],"atl":[[1.32,0]],"trd":[[1.32,464.24]],"tv":4842.33,"id":228749}],"tv":5623.25}]}
{"op":"mcm","clk":"AOHboQkA0fiQCgCV/JgK","pt":1657538449571,"mc":[{"id":"1.200806927","rc":[{"atb":[[1.32,166.58]],"trd":[[1.32,464.44]],"tv":4842.53,"id":228749}],"tv":5623.45}]}
{"op":"mcm","clk":"AMndoQkA3vqQCgCQ/ZgK","pt":1657538452506,"mc":[{"id":"1.200806927","rc":[{"atl":[[4.1,15.41]],"id":2857977}]}]}
{"op":"mcm","clk":"APbeoQkAq/yQCgCY/pgK","pt":1657538454905,"mc":[{"id":"1.200806927","rc":[{"atb":[[1.32,157.56]],"trd":[[1.32,482.49]],"tv":4860.58,"id":228749}],"tv":5641.5}]}
{"op":"mcm","clk":"AMDhoQkA3/+QCgDb/5gK","pt":1657538460006,"mc":[{"id":"1.200806927","rc":[{"atl":[[1.65,0.13]],"id":228749}]}]}
{"op":"mcm","clk":"ANLioQkAsYGRCgC2gJkK","pt":1657538462107,"mc":[{"id":"1.200806927","rc":[{"atl":[[1.42,2.51]],"id":228749}]}]}
{"op":"mcm","clk":"AIrjoQkA84GRCgDagJkK","pt":1657538462797,"mc":[{"id":"1.200806927","rc":[{"atb":[[1.32,0.25]],"id":228749}]}]}
{"op":"mcm","clk":"AK/joQkAn4KRCgDwgJkK","pt":1657538463310,"mc":[{"id":"1.200806927","rc":[{"atb":[[1.32,0]],"trd":[[1.32,483.45]],"tv":4861.54,"id":228749},{"atl":[[4.1,15.26]],"trd":[[4.1,2.21]],"ltp":4.1,"tv":781.08,"id":2857977}],"tv":5642.62}]}
{"op":"mcm","clk":"ALzkoQkA5oORCgDLgZkK","pt":1657538465325,"mc":[{"id":"1.200806927","rc":[{"trd":[[1.32,486.47]],"tv":4864.56,"id":228749},{"atl":[[4.1,14.29]],"trd":[[4.1,3.18]],"tv":782.05,"id":2857977}],"tv":5646.61}]}
{"op":"mcm","clk":"AK3loQkA7ISRCgCMgpkK","pt":1657538466796,"mc":[{"id":"1.200806927","rc":[{"atl":[[1.68,5.85]],"id":228749}]}]}
{"op":"mcm","clk":"AIPnoQkArIaRCgCGg5kK","pt":1657538469497,"mc":[{"id":"1.200806927","rc":[{"atl":[[1000,2.64]],"id":228749}]}]}
{"op":"mcm","clk":"AJnnoQkAyIaRCgCVg5kK","pt":1657538469816,"mc":[{"id":"1.200806927","rc":[{"atl":[[1000,1.8]],"id":228749}]}]}
{"op":"mcm","clk":"AL3noQkA7oaRCgCgg5kK","pt":1657538470236,"mc":[{"id":"1.200806927","rc":[{"atl":[[1000,0.13]],"id":228749}]}]}
{"op":"mcm","clk":"AO3ooQkAy4iRCgCWhJkK","pt":1657538472918,"mc":[{"id":"1.200806927","rc":[{"trd":[[1.32,496.47]],"tv":4874.56,"id":228749},{"atl":[[4.1,11.07]],"trd":[[4.1,6.39]],"tv":785.26,"id":2857977}],"tv":5659.82}]}
{"op":"mcm","clk":"AIHqoQkA9YmRCgD3hJkK","pt":1657538475303,"mc":[{"id":"1.200806927","rc":[{"trd":[[1.32,498.14]],"tv":4876.23,"id":228749},{"atl":[[4.1,10.53]],"trd":[[4.1,6.93]],"tv":785.8,"id":2857977}],"tv":5662.03}]}
{"op":"mcm","clk":"AIrqoQkA+4mRCgD8hJkK","pt":1657538475405,"mc":[{"id":"1.200806927","rc":[{"atl":[[1.95,0.13]],"id":228749}]}]}
{"op":"mcm","clk":"AMnroQkAgYyRCgCMhpkK","pt":1657538478520,"mc":[{"id":"1.200806927","rc":[{"atl":[[1.33,0.43]],"trd":[[1.33,9.26]],"ltp":1.33,"tv":4881.97,"id":228749},{"trd":[[4,1.56]],"ltp":4,"tv":785.9,"id":2857977}],"tv":5667.87}]}
{"op":"mcm","clk":"ALXsoQkAjY2RCgDYhpkK","pt":1657538480244,"mc":[{"id":"1.200806927","rc":[{"atl":[[1.33,0.26]],"trd":[[1.33,9.61]],"tv":4882.32,"id":228749}],"tv":5668.22}]}
{"op":"mcm","clk":"AKTtoQkA/I2RCgCgh5kK","pt":1657538481750,"mc":[{"id":"1.200806927","rc":[{"atl":[[1.35,1.69],[1.33,0]],"trd":[[1.35,3.17],[1.33,9.87]],"ltp":1.35,"tv":4884.89,"id":228749},{"trd":[[3.85,0.81],[4,1.65]],"ltp":3.85,"tv":786.8,"id":2857977}],"tv":5671.69}]}
{"op":"mcm","clk":"AL3toQkAl46RCgC/h5kK","pt":1657538481955,"mc":[{"id":"1.200806927","rc":[{"trd":[[1.32,498.24]],"ltp":1.32,"tv":4884.99,"id":228749},{"atl":[[4.1,10.5]],"trd":[[4.1,6.97]],"ltp":4.1,"tv":786.84,"id":2857977}],"tv":5671.83}]}
{"op":"mcm","clk":"APjtoQkA6Y6RCgCPiJkK","pt":1657538483151,"mc":[{"id":"1.200806927","rc":[{"atl":[[4.1,2.6]],"trd":[[4.1,22.77]],"tv":802.64,"id":2857977}],"tv":5687.63}]}
{"op":"mcm","clk":"AOLxoQkAypKRCgDXipkK","pt":1657538489644,"mc":[{"id":"1.200806927","rc":[{"atl":[[4.1,0]],"id":2857977}]}]}
{"op":"mcm","clk":"APrxoQkA4ZKRCgDhipkK","pt":1657538489961,"mc":[{"id":"1.200806927","rc":[{"atl":[[1.35,0.83]],"trd":[[1.35,4.03]],"ltp":1.35,"tv":4885.85,"id":228749},{"trd":[[3.85,1.11]],"ltp":3.85,"tv":802.94,"id":2857977}],"tv":5688.79}]}
{"op":"mcm","clk":"AIvzoQkAhpSRCgCmi5kK","pt":1657538491969,"mc":[{"id":"1.200806927","rc":[{"atb":[[1.65,0.17]],"id":2857977}]}]}
{"op":"mcm","clk":"ANXzoQkA2ZSRCgDOi5kK","pt":1657538493054,"mc":[{"id":"1.200806927","rc":[{"atl":[[1.32,64.39]],"id":228749}]}]}
{"op":"mcm","clk":"AIn3oQkAu5iRCgD1jZkK","pt":1657538499523,"mc":[{"id":"1.200806927","rc":[{"atl":[[1.32,64.26]],"trd":[[1.32,498.5]],"ltp":1.32,"tv":4886.11,"id":228749}],"tv":5689.05}]}
{"op":"mcm","clk":"AMf6oQkA9puRCgC6kJkK","pt":1657538505910,"mc":[{"id":"1.200806927","rc":[{"atb":[[1.28,9.02]],"id":228749}]}]}
{"op":"mcm","clk":"ANv8oQkAhZ6RCgDlkZkK","pt":1657538509746,"mc":[{"id":"1.200806927","rc":[{"atl":[[1.32,63.42]],"trd":[[1.32,500.19]],"tv":4887.8,"id":228749}],"tv":5690.74}]}
{"op":"mcm","clk":"AI/9oQkAwp6RCgD+kZkK","pt":1657538510485,"mc":[{"id":"1.200806927","rc":[{"atl":[[1.32,62.62]],"trd":[[1.32,500.98]],"tv":4888.59,"id":228749},{"trd":[[4.1,23.02]],"ltp":4.1,"tv":803.19,"id":2857977}],"tv":5691.78}]}
{"op":"mcm","clk":"AMuEogkAl6eRCgDnlpkK","pt":1657538523095,"mc":[{"id":"1.200806927","rc":[{"atl":[[1.32,62.51]],"trd":[[1.32,501.2]],"tv":4888.81,"id":228749}],"tv":5692}]}
{"op":"mcm","clk":"AICHogkArqqRCgC1mJkK","pt":1657538527509,"mc":[{"id":"1.200806927","rc":[{"atb":[[1.28,11.17]],"id":228749}]}]}
{"op":"mcm","clk":"AN2HogkAh6uRCgD1mJkK","pt":1657538528507,"mc":[{"id":"1.200806927","rc":[{"atl":[[1.32,60.72]],"trd":[[1.32,504.8]],"tv":4892.41,"id":228749}],"tv":5695.6}]}
{"op":"mcm","clk":"AIiLogkAkK+RCgC9m5kK","pt":1657538533828,"mc":[{"id":"1.200806927","rc":[{"atb":[[1.28,10.85]],"trd":[[1.28,0.64]],"ltp":1.28,"tv":4893.05,"id":228749}],"tv":5696.24}]}
{"op":"mcm","clk":"APKMogkA/7CRCgDtnJkK","pt":1657538536903,"mc":[{"id":"1.200806927","rc":[{"atl":[[1.32,60.38]],"trd":[[1.32,505.13]],"ltp":1.32,"tv":4893.38,"id":228749},{"trd":[[4.1,23.13]],"tv":803.3,"id":2857977}],"tv":5696.68}]}
{"op":"mcm","clk":"AJiOogkAg7KRCgDRnZkK","pt":1657538538892,"mc":[{"id":"1.200806927","rc":[{"atl":[[1.32,59.04]],"trd":[[1.32,506.47]],"tv":4894.72,"id":228749},{"trd":[[4.1,23.56]],"tv":803.73,"id":2857977}],"tv":5698.45}]}
{"op":"mcm","clk":"AM+OogkArLKRCgDvnZkK","pt":1657538539528,"mc":[{"id":"1.200806927","rc":[{"atl":[[1.3,180.32]],"id":228749}]}]}
{"op":"mcm","clk":"APyRogkAobWRCgCCoJkK","pt":1657538544537,"mc":[{"id":"1.200806927","rc":[{"atl":[[1.3,180.21]],"trd":[[1.3,322.43]],"ltp":1.3,"tv":4894.93,"id":228749}],"tv":5698.66}]}
{"op":"mcm","clk":"AKWUogkAi7iRCgDcoZkK","pt":1657538549162,"mc":[{"id":"1.200806927","rc":[{"atl":[[1.3,179.86]],"trd":[[1.3,322.78]],"tv":4895.28,"id":228749},{"trd":[[4.3,248.5]],"ltp":4.3,"tv":803.83,"id":2857977}],"tv":5699.11}]}
{"op":"mcm","clk":"AImVogkA2biRCgCKopkK","pt":1657538550364,"mc":[{"id":"1.200806927","rc":[{"atl":[[1.3,177.01]],"trd":[[1.3,325.63]],"tv":4898.13,"id":228749},{"trd":[[4.3,249.37]],"tv":804.7,"id":2857977}],"tv":5702.83}]}
{"op":"mcm","clk":"APuWogkA6rqRCgDBo5kK","pt":1657538553144,"mc":[{"id":"1.200806927","rc":[{"atl":[[1.3,176.3]],"trd":[[1.3,326.34]],"tv":4898.84,"id":228749},{"trd":[[4.3,249.58]],"tv":804.91,"id":2857977}],"tv":5703.75}]}
{"op":"mcm","clk":"AIqcogkArMCRCgCCqZkK","pt":1657538556264,"mc":[{"id":"1.200806927","rc":[{"atl":[[1.3,175.95]],"trd":[[1.3,326.69]],"tv":4899.19,"id":228749},{"trd":[[4.3,249.69]],"tv":805.02,"id":2857977}],"tv":5704.21}]}
{"op":"mcm","clk":"ALqfogkAlsORCgCiq5kK","pt":1657538561948,"mc":[{"id":"1.200806927","rc":[{"atl":[[1.3,174.53]],"trd":[[1.3,328.11]],"tv":4900.61,"id":228749},{"trd":[[4.3,250.12]],"tv":805.45,"id":2857977}],"tv":5706.06}]}
{"op":"mcm","clk":"ANOgogkAssSRCgCcrJkK","pt":1657538564256,"mc":[{"id":"1.200806927","rc":[{"atl":[[1.3,173.68]],"trd":[[1.3,329.81]],"tv":4902.31,"id":228749}],"tv":5707.76}]}
{"op":"mcm","clk":"AMShogkAyMWRCgCHrZkK","pt":1657538566248,"mc":[{"id":"1.200806927","rc":[{"atb":[[1.28,0]],"atl":[[1.28,229.52]],"trd":[[1.28,4.94]],"ltp":1.28,"tv":4906.61,"id":228749}],"tv":5712.06}]}
{"op":"mcm","clk":"AP6iogkA+MaRCgCArpkK","pt":1657538568944,"mc":[{"id":"1.200806927","rc":[{"atl":[[1.28,469.89]],"id":228749}]}]}
{"op":"mcm","clk":"AOWjogkA3seRCgDJrpkK","pt":1657538570501,"mc":[{"id":"1.200806927","rc":[{"atl":[[1.28,469.52]],"trd":[[1.28,5.31]],"tv":4906.98,"id":228749},{"trd":[[4.5,0.11]],"ltp":4.5,"tv":805.56,"id":2857977}],"tv":5712.54}]}
{"op":"mcm","clk":"AOmjogkA5ceRCgDNrpkK","pt":1657538570551,"mc":[{"id":"1.200806927","rc":[{"atl":[[1.28,709.89]],"id":228749}]}]}
{"op":"mcm","clk":"AJqqogkAps6RCgDhs5kK","pt":1657538578266,"mc":[{"id":"1.200806927","rc":[{"atb":[[1.27,7.87]],"trd":[[1.27,433.04]],"ltp":1.27,"tv":4922.98,"id":228749}],"tv":5728.54}]}
{"op":"mcm","clk":"ANSqogkA8s6RCgCStJkK","pt":1657538579443,"mc":[{"id":"1.200806927","rc":[{"atl":[[1.28,709.54]],"trd":[[1.28,5.66]],"ltp":1.28,"tv":4923.33,"id":228749},{"trd":[[4.5,0.21]],"tv":805.66,"id":2857977}],"tv":5728.99}]}
{"op":"mcm","clk":"APKqogkAkc+RCgCotJkK","pt":1657538579874,"mc":[{"id":"1.200806927","rc":[{"atl":[[1.28,709.11]],"trd":[[1.28,6.53]],"tv":4924.2,"id":228749}],"tv":5729.86}]}
{"op":"mcm","clk":"AIurogkAtM+RCgC4tJkK","pt":1657538580287,"mc":[{"id":"1.200806927","rc":[{"atl":[[1.28,708.76]],"trd":[[1.28,6.88]],"tv":4924.55,"id":228749},{"trd":[[4.5,0.31]],"tv":805.76,"id":2857977}],"tv":5730.31}]}
{"op":"mcm","clk":"AJWtogkAzNGRCgDFtZkK","pt":1657538583685,"mc":[{"id":"1.200806927","rc":[{"atb":[[1.27,0]],"atl":[[1.27,2.15]],"trd":[[1.27,448.78]],"ltp":1.27,"tv":4940.29,"id":228749}],"tv":5746.05}]}
{"op":"mcm","clk":"ALG0ogkA3NmRCgDvupkK","pt":1657538597679,"mc":[{"id":"1.200806927","rc":[{"atl":[[1.27,0],[1.28,707.63]],"trd":[[1.27,450.93],[1.28,8.01]],"ltp":1.28,"tv":4943.57,"id":228749},{"trd":[[4.7,51.5],[4.5,0.63]],"tv":806.66,"id":2857977}],"tv":5750.23}]}
{"op":"mcm","clk":"ALu0ogkA6tmRCgDzupkK","pt":1657538597791,"mc":[{"id":"1.200806927","rc":[{"atb":[[1.27,5.85]],"id":228749}]}]}
{"op":"mcm","clk":"AOK0ogkAkdqRCgCIu5kK","pt":1657538598314,"mc":[{"id":"1.200806927","rc":[{"atl":[[1.28,707.18]],"trd":[[1.28,8.46]],"tv":4944.02,"id":228749},{"trd":[[4.5,0.76]],"tv":806.79,"id":2857977}],"tv":5750.81}]}
{"op":"mcm","clk":"APy4ogkA/N6RCgCCvpkK","pt":1657538606716,"mc":[{"id":"1.200806927","rc":[{"atb":[[1.27,96.01]],"id":228749}]}]}
{"op":"mcm","clk":"AKfBogkA5OmRCgDGw5kK","pt":1657538622638,"mc":[{"id":"1.200806927","rc":[{"atb":[[1.35,31.78]],"id":2857977}]}]}
{"op":"mcm","clk":"AO/CogkAjOyRCgDfxJkK","pt":1657538625918,"mc":[{"id":"1.200806927","rc":[{"atl":[[1.28,706.96]],"trd":[[1.28,8.89]],"tv":4944.45,"id":228749}],"tv":5751.24}]}
{"op":"mcm","clk":"APTEogkAru6RCgDxxZkK","pt":1657538629397,"mc":[{"id":"1.200806927","rc":[{"atl":[[1.28,700.29]],"id":228749}]}]}
{"op":"mcm","clk":"AP3FogkA8e+RCgDUxpkK","pt":1657538631576,"mc":[{"id":"1.200806927","rc":[{"atl":[[1.28,699.94]],"trd":[[1.28,9.24]],"tv":4944.8,"id":228749},{"trd":[[4.5,0.86]],"tv":806.89,"id":2857977}],"tv":5751.69}]}
{"op":"mcm","clk":"AITGogkA+++RCgDXxpkK","pt":1657538631677,"mc":[{"id":"1.200806927","rc":[{"atl":[[1.28,699.57]],"trd":[[1.28,9.61]],"tv":4945.17,"id":228749},{"trd":[[4.5,0.96]],"tv":806.99,"id":2857977}],"tv":5752.16}]}
{"op":"mcm","clk":"AKLGogkAovCRCgDtxpkK","pt":1657538632094,"mc":[{"id":"1.200806927","rc":[{"atl":[[1.3,0]],"id":228749}]}]}
{"op":"mcm","clk":"AIvPogkA+vyRCgC2z5kK","pt":1657538651133,"mc":[{"id":"1.200806927","rc":[{"atl":[[1.43,0.3]],"id":228749}]}]}
