{"op":"mcm","clk":"AM78sQkA6qKjCgDiwaMK","pt":1657541604422,"mc":[{"id":"1.200806927","rc":[{"atb":[[1.17,1072.89]],"trd":[[1.17,3939.54]],"tv":104743.39,"id":228749}],"tv":111895.9}]}
{"op":"mcm","clk":"AOH8sQkAiaOjCgDswaMK","pt":1657541604734,"mc":[{"id":"1.200806927","rc":[{"atb":[[1.16,1449.5]],"id":228749}]}]}
{"op":"mcm","clk":"AO/8sQkAoaOjCgD2waMK","pt":1657541604934,"mc":[{"id":"1.200806927","rc":[{"atb":[[1.17,542.56]],"id":228749}]}]}
{"op":"mcm","clk":"APz8sQkAq6OjCgD6waMK","pt":1657541605051,"mc":[{"id":"1.200806927","rc":[{"atb":[[1.17,542.03]],"trd":[[1.17,3940.6]],"tv":104744.45,"id":228749}],"tv":111896.96}]}
{"op":"mcm","clk":"AJz9sQkA5aOjCgCSwqMK","pt":1657541605510,"mc":[{"id":"1.200806927","rc":[{"atb":[[1.17,0]],"atl":[[1.17,55.97]],"trd":[[1.17,5024.66]],"tv":105828.51,"id":228749}],"tv":112981.02}]}
{"op":"mcm","clk":"AMj9sQkApaSjCgCpwqMK","pt":1657541606095,"mc":[{"id":"1.200806927","rc":[{"atb":[[1.16,1444.24]],"atl":[[1.17,111.19]],"id":228749}]}]}
{"op":"mcm","clk":"AP79sQkA46SjCgDOwqMK","pt":1657541606728,"mc":[{"id":"1.200806927","rc":[{"atb":[[1.07,78.51]],"id":228749}]}]}
{"op":"mcm","clk":"AMn+sQkA0qWjCgD7wqMK","pt":1657541607906,"mc":[{"id":"1.200806927","rc":[{"atl":[[1.17,107.24]],"trd":[[1.17,5032.56]],"tv":105836.41,"id":228749}],"tv":112988.92}]}
{"op":"mcm","clk":"ANv+sQkA9KWjCgCHw6MK","pt":1657541608146,"mc":[{"id":"1.200806927","rc":[{"atl":[[1.17,104.61]],"trd":[[1.17,5037.82]],"tv":105841.67,"id":228749}],"tv":112994.18}]}
{"op":"mcm","clk":"APX+sQkAmKajCgCXw6MK","pt":1657541608448,"mc":[{"id":"1.200806927","rc":[{"atl":[[1.17,107.24]],"id":228749}]}]}
{"op":"mcm","clk":"APf+sQkApaajCgCZw6MK","pt":1657541608503,"mc":[{"id":"1.200806927","rc":[{"atb":[[1.16,1440.63]],"id":228749}]}]}
{"op":"mcm","clk":"AJP/sQkAxaajCgCqw6MK","pt":1657541608836,"mc":[{"id":"1.200806927","rc":[{"atl":[[1.17,112.5]],"id":228749}]}]}
{"op":"mcm","clk":"ALr/sQkAgqejCgDKw6MK","pt":1657541609448,"mc":[{"id":"1.200806927","rc":[{"atb":[[7,0.53]],"id":2857977}]}]}
{"op":"mcm","clk":"ANz/sQkAqKejCgDcw6MK","pt":1657541609818,"mc":[{"id":"1.200806927","rc":[{"atl":[[1.17,115.13]],"id":228749}]}]}
{"op":"mcm","clk":"AO7/sQkAv6ejCgDhw6MK","pt":1657541610022,"mc":[{"id":"1.200806927","rc":[{"atl":[[1.18,5.79]],"id":228749}]}]}
{"op":"mcm","clk":"APT/sQkAyqejCgDkw6MK","pt":1657541610124,"mc":[{"id":"1.200806927","rc":[{"atl":[[1.17,125.12]],"id":228749}]}]}
{"op":"mcm","clk":"APr/sQkA1aejCgDnw6MK","pt":1657541610230,"mc":[{"id":"1.200806927","rc":[{"atl":[[1.17,71.48]],"id":228749}]}]}
{"op":"mcm","clk":"AJ+AsgkAhKijCgD4w6MK","pt":1657541610761,"mc":[{"id":"1.200806927","rc":[{"atl":[[1.17,29.38]],"trd":[[1.17,5122.02]],"tv":105925.87,"id":228749}],"tv":113078.38}]}
{"op":"mcm","clk":"AL+AsgkAvqijCgCTxKMK","pt":1657541611333,"mc":[{"id":"1.200806927","rc":[{"atl":[[1.17,30.43]],"id":228749}]}]}
{"op":"mcm","clk":"ANKAsgkA1aijCgCcxKMK","pt":1657541611540,"mc":[{"id":"1.200806927","rc":[{"atl":[[1.17,25.17]],"id":228749}]}]}
{"op":"mcm","clk":"AOKAsgkA7qijCgCmxKMK","pt":1657541611850,"mc":[{"id":"1.200806927","rc":[{"atb":[[7,1.58]],"id":2857977}]}]}
{"op":"mcm","clk":"AOqAsgkA+KijCgCpxKMK","pt":1657541611943,"mc":[{"id":"1.200806927","rc":[{"atl":[[1.17,24.17]],"trd":[[1.17,5124.02]],"tv":105927.87,"id":228749}],"tv":113080.38}]}
{"op":"mcm","clk":"APiAsgkAjamjCgCuxKMK","pt":1657541612150,"mc":[{"id":"1.200806927","rc":[{"atb":[[1.07,78.62]],"id":228749}]}]}
{"op":"mcm","clk":"AJGBsgkAt6mjCgC8xKMK","pt":1657541612515,"mc":[{"id":"1.200806927","rc":[{"atb":[[1.07,78.51]],"atl":[[1.17,4.29]],"trd":[[1.17,5143.9]],"tv":105947.75,"id":228749},{"atb":[[7,0]],"trd":[[7,5.82],[6.8,193.88]],"ltp":6.8,"tv":7159.09,"id":2857977}],"tv":113106.84}]}
{"op":"mcm","clk":"AJeBsgkAxamjCgDCxKMK","pt":1657541612625,"mc":[{"id":"1.200806927","rc":[{"atl":[[10,0]],"id":2857977}]}]}
{"op":"mcm","clk":"ANmBsgkAlaqjCgDlxKMK","pt":1657541613458,"mc":[{"id":"1.200806927","rc":[{"atl":[[1.17,8.18]],"id":228749}]}]}
{"op":"mcm","clk":"AMiCsgkAnaujCgCixaMK","pt":1657541614720,"mc":[{"id":"1.200806927","rc":[{"atl":[[1.17,21.33]],"id":228749}]}]}
{"op":"mcm","clk":"AOOCsgkAuqujCgCzxaMK","pt":1657541615036,"mc":[{"id":"1.200806927","rc":[{"atl":[[1.17,20.8]],"id":228749}]}]}
{"op":"mcm","clk":"AOqCsgkAw6ujCgC/xaMK","pt":1657541615140,"mc":[{"id":"1.200806927","rc":[{"atl":[[1.17,22.44]],"id":228749}]}]}
{"op":"mcm","clk":"APiDsgkA2qyjCgCUxqMK","pt":1657541616627,"mc":[{"id":"1.200806927","rc":[{"atl":[[1.17,48.74]],"id":228749}]}]}
{"op":"mcm","clk":"AL+EsgkAzq2jCgDNxqMK","pt":1657541617627,"mc":[{"id":"1.200806927","rc":[{"atl":[[1.17,48.63]],"trd":[[1.17,5144.11]],"tv":105947.96,"id":228749}],"tv":113107.05}]}
{"op":"mcm","clk":"ANiEsgkA6a2jCgDexqMK","pt":1657541617947,"mc":[{"id":"1.200806927","rc":[{"atl":[[1.17,53.89]],"id":228749}]}]}
{"op":"mcm","clk":"ANuEsgkA9K2jCgDixqMK","pt":1657541618053,"mc":[{"id":"1.200806927","rc":[{"atl":[[1.18,6.58]],"id":228749}]}]}
{"op":"mcm","clk":"AOaEsgkA/a2jCgDlxqMK","pt":1657541618169,"mc":[{"id":"1.200806927","rc":[{"atb":[[1.07,77.67]],"id":228749}]}]}
{"op":"mcm","clk":"ALCFsgkA3a6jCgCnx6MK","pt":1657541619049,"mc":[{"id":"1.200806927","rc":[{"atl":[[1.17,50]],"id":228749}]}]}
{"op":"mcm","clk":"AM2GsgkAwLCjCgCoyKMK","pt":1657541621255,"mc":[{"id":"1.200806927","rc":[{"atb":[[1.1,204],[1.16,1385.41]],"id":228749}]}]}
{"op":"mcm","clk":"AI+HsgkA/bCjCgDlyKMK","pt":1657541621981,"mc":[{"id":"1.200806927","rc":[{"atb":[[1.16,1384.25]],"id":228749}]}]}
{"op":"mcm","clk":"ALaHsgkAprGjCgCDyaMK","pt":1657541622459,"mc":[{"id":"1.200806927","rc":[{"atl":[[1.17,48.42]],"id":228749}]}]}
{"op":"mcm","clk":"AMWHsgkAu7GjCgCMyaMK","pt":1657541622666,"mc":[{"id":"1.200806927","rc":[{"atb":[[1.1,4],[1.12,2.63]],"id":228749}]}]}
{"op":"mcm","clk":"AOKHsgkA5bGjCgCiyaMK","pt":1657541623066,"mc":[{"id":"1.200806927","rc":[{"atl":[[1.17,61.36]],"id":228749}]}]}
{"op":"mcm","clk":"ANmIsgkA67KjCgDyyaMK","pt":1657541624466,"mc":[{"id":"1.200806927","rc":[{"atl":[[1.17,48.21]],"id":228749}]}]}
{"op":"mcm","clk":"AJCJsgkAlbOjCgCZyqMK","pt":1657541624944,"mc":[{"id":"1.200806927","rc":[{"atb":[[1.16,1383.2]],"id":228749}]}]}
{"op":"mcm","clk":"AKuJsgkAvLOjCgC3yqMK","pt":1657541625358,"mc":[{"id":"1.200806927","rc":[{"atl":[[1.17,47.68]],"id":228749}]}]}
{"op":"mcm","clk":"AMyJsgkA37OjCgDIyqMK","pt":1657541625669,"mc":[{"id":"1.200806927","rc":[{"atl":[[1.17,45.57]],"trd":[[1.17,5145.23]],"tv":105949.08,"id":228749}],"tv":113108.17}]}
{"op":"mcm","clk":"ANGJsgkA5bOjCgDQyqMK","pt":1657541625767,"mc":[{"id":"1.200806927","rc":[{"atl":[[1000,0.31]],"id":228749}]}]}
{"op":"mcm","clk":"AOiJsgkAgbSjCgDfyqMK","pt":1657541626093,"mc":[{"id":"1.200806927","rc":[{"atl":[[1.17,32.43]],"trd":[[1.17,5145.29]],"tv":105949.14,"id":228749}],"tv":113108.23}]}
{"op":"mcm","clk":"AOqJsgkAiLSjCgDmyqMK","pt":1657541626145,"mc":[{"id":"1.200806927","rc":[{"atl":[[1000,0.13]],"id":228749}]}]}
{"op":"mcm","clk":"AIqKsgkAtbSjCgCFy6MK","pt":1657541626670,"mc":[{"id":"1.200806927","rc":[{"atl":[[1.17,27.17]],"id":228749}]}]}
{"op":"mcm","clk":"AMCKsgkA/LSjCgC4y6MK","pt":1657541627340,"mc":[{"id":"1.200806927","rc":[{"atb":[[1.16,1380.61]],"id":228749}]}]}
{"op":"mcm","clk":"ANmKsgkAmrWjCgDLy6MK","pt":1657541627653,"mc":[{"id":"1.200806927","rc":[{"atb":[[1.15,1347.77]],"id":228749}]}]}
{"op":"mcm","clk":"APeKsgkAvrWjCgDiy6MK","pt":1657541628075,"mc":[{"id":"1.200806927","rc":[{"atl":[[1.17,327.17]],"id":228749}]}]}
{"op":"mcm","clk":"AICLsgkAy7WjCgDly6MK","pt":1657541628182,"mc":[{"id":"1.200806927","rc":[{"atb":[[1.16,1380.08]],"id":228749}]}]}
{"op":"mcm","clk":"APiLsgkA+bajCgDEzKMK","pt":1657541629850,"mc":[{"id":"1.200806927","rc":[{"atb":[[1.06,936.69],[1.16,1379.55]],"atl":[[1.17,326.64]],"id":228749}]}]}
{"op":"mcm","clk":"AJKMsgkAmbejCgDZzKMK","pt":1657541630177,"mc":[{"id":"1.200806927","rc":[{"atl":[[1.18,5.79]],"id":228749}]}]}
{"op":"mcm","clk":"AK2MsgkAtrejCgDvzKMK","pt":1657541630396,"mc":[{"id":"1.200806927","rc":[{"atb":[[1.16,1169.18]],"id":228749}]}]}
{"op":"mcm","clk":"AP+MsgkAkLijCgCnzaMK","pt":1657541631277,"mc":[{"id":"1.200806927","rc":[{"atb":[[1.16,1169]],"trd":[[1.16,6692.68]],"ltp":1.16,"tv":105949.5,"id":228749}],"tv":113108.59}]}
{"op":"mcm","clk":"AIqNsgkAqLijCgC3zaMK","pt":1657541631493,"mc":[{"id":"1.200806927","rc":[{"atb":[[1.15,1164.75]],"id":228749}]}]}
{"op":"mcm","clk":"AJiNsgkAurijCgDBzaMK","pt":1657541631669,"mc":[{"id":"1.200806927","rc":[{"atl":[[1.17,325.06]],"id":228749}]}]}
{"op":"mcm","clk":"ANmNsgkA+rijCgDjzaMK","pt":1657541632290,"mc":[{"id":"1.200806927","rc":[{"atl":[[1.17,319.8]],"id":228749}]}]}
{"op":"mcm","clk":"AP+NsgkAmrmjCgD4zaMK","pt":1657541632648,"mc":[{"id":"1.200806927","rc":[{"atb":[[1.16,1168.66]],"trd":[[1.16,6693.36]],"tv":105950.18,"id":228749}],"tv":113109.27}]}
{"op":"mcm","clk":"ANqOsgkAi7qjCgDAzqMK","pt":1657541633955,"mc":[{"id":"1.200806927","rc":[{"atl":[[7,0.43]],"id":2857977}]}]}
{"op":"mcm","clk":"AOeOsgkAl7qjCgDDzqMK","pt":1657541634117,"mc":[{"id":"1.200806927","rc":[{"atb":[[1.16,1166.03]],"id":228749}]}]}
{"op":"mcm","clk":"APqOsgkArrqjCgDUzqMK","pt":1657541634374,"mc":[{"id":"1.200806927","rc":[{"atl":[[1.17,314.54]],"id":228749}]}]}
{"op":"mcm","clk":"ALePsgkA+7qjCgCOz6MK","pt":1657541635261,"mc":[{"id":"1.200806927","rc":[{"atb":[[1.16,1162.77]],"id":228749}]}]}
{"op":"mcm","clk":"ANyPsgkAmbujCgCfz6MK","pt":1657541635674,"mc":[{"id":"1.200806927","rc":[{"atb":[[1.16,1161.72]],"id":228749}]}]}
{"op":"mcm","clk":"AKWQsgkA67ujCgDXz6MK","pt":1657541636662,"mc":[{"id":"1.200806927","rc":[{"atb":[[1.04,43.89],[1.16,1159.09]],"id":228749}]}]}
{"op":"mcm","clk":"APiQsgkAz7yjCgCY0KMK","pt":1657541637854,"mc":[{"id":"1.200806927","rc":[{"atb":[[1.16,1138.05]],"id":228749}]}]}
{"op":"mcm","clk":"AICRsgkA2LyjCgCb0KMK","pt":1657541637962,"mc":[{"id":"1.200806927","rc":[{"atl":[[1.17,304.02]],"trd":[[1.17,5163.13]],"ltp":1.17,"tv":105968.02,"id":228749}],"tv":113127.11}]}
{"op":"mcm","clk":"ANWRsgkAwb2jCgDU0KMK","pt":1657541639094,"mc":[{"id":"1.200806927","rc":[{"atb":[[1.16,927.68]],"id":228749}]}]}
{"op":"mcm","clk":"AOCRsgkA0b2jCgDj0KMK","pt":1657541639269,"mc":[{"id":"1.200806927","rc":[{"atl":[[1.7,13.53]],"id":228749}]}]}
{"op":"mcm","clk":"AO+SsgkA7r6jCgDH0aMK","pt":1657541640983,"mc":[{"id":"1.200806927","rc":[{"atb":[[1.16,927.36]],"trd":[[1.16,6694.01]],"ltp":1.16,"tv":105968.67,"id":228749}],"tv":113127.76}]}
{"op":"mcm","clk":"APGSsgkA+L6jCgDJ0aMK","pt":1657541641072,"mc":[{"id":"1.200806927","rc":[{"atl":[[1.17,301.51]],"trd":[[1.17,5165.64]],"ltp":1.17,"tv":105971.18,"id":228749},{"trd":[[6.8,194.31]],"tv":7159.52,"id":2857977}],"tv":113130.7}]}
{"op":"mcm","clk":"AK6TsgkAq7+jCgDo0aMK","pt":1657541641701,"mc":[{"id":"1.200806927","rc":[{"atb":[[1.16,916.84]],"atl":[[1.17,296.25]],"trd":[[1.17,5176.16]],"tv":105981.7,"id":228749}],"tv":113141.22}]}
{"op":"mcm","clk":"ALOTsgkAs7+jCgDt0aMK","pt":1657541641764,"mc":[{"id":"1.200806927","rc":[{"atb":[[1.16,0]],"id":228749}]}]}
{"op":"mcm","clk":"AM6TsgkAz7+jCgD70aMK","pt":1657541642074,"mc":[{"id":"1.200806927","rc":[{"atb":[[1.04,44.1]],"id":228749}]}]}
{"op":"mcm","clk":"AP6TsgkA97+jCgCO0qMK","pt":1657541642494,"mc":[{"id":"1.200806927","rc":[{"atb":[[1.04,43.89]],"id":228749}]}]}
{"op":"mcm","clk":"AKiUsgkApsCjCgCo0qMK","pt":1657541643101,"mc":[{"id":"1.200806927","rc":[{"atl":[[1.16,5.74]],"trd":[[1.16,6696.61]],"ltp":1.16,"tv":105984.3,"id":228749},{"atl":[[7,0]],"trd":[[7,6.26]],"ltp":7,"tv":7159.96,"id":2857977}],"tv":113144.26}]}
{"op":"mcm","clk":"AMmUsgkA1cCjCgC50qMK","pt":1657541643485,"mc":[{"id":"1.200806927","rc":[{"atl":[[1.16,6.53]],"id":228749}]}]}
{"op":"mcm","clk":"ANWUsgkA4cCjCgC+0qMK","pt":1657541643592,"mc":[{"id":"1.200806927","rc":[{"atl":[[1.16,3.85]],"trd":[[1.16,6699.29]],"tv":105986.98,"id":228749},{"trd":[[7.2,825.73]],"ltp":7.2,"tv":7160.39,"id":2857977}],"tv":113147.37}]}
{"op":"mcm","clk":"ALGWsgkAu8KjCgCk06MK","pt":1657541645873,"mc":[{"id":"1.200806927","rc":[{"atl":[[1.16,5.43]],"id":228749}]}]}
{"op":"mcm","clk":"ALeWsgkAxcKjCgCq06MK","pt":1657541645978,"mc":[{"id":"1.200806927","rc":[{"atl":[[1.17,275.38],[1.16,0]],"trd":[[1.17,5217.9]],"ltp":1.17,"tv":106028.72,"id":228749}],"tv":113189.11}]}
{"op":"mcm","clk":"AMqWsgkA2sKjCgC006MK","pt":1657541646186,"mc":[{"id":"1.200806927","rc":[{"atl":[[1.16,2.63]],"id":228749}]}]}
{"op":"mcm","clk":"AKGXsgkAr8OjCgDq06MK","pt":1657541647009,"mc":[{"id":"1.200806927","rc":[{"atl":[[1.16,3.16]],"id":228749}]}]}
{"op":"mcm","clk":"AL6XsgkAxcOjCgCC1KMK","pt":1657541647291,"mc":[{"id":"1.200806927","rc":[{"atl":[[1.16,4.74]],"id":228749}]}]}
{"op":"mcm","clk":"ANiXsgkA38OjCgCT1KMK","pt":1657541647601,"mc":[{"id":"1.200806927","rc":[{"atl":[[1.16,4.52]],"trd":[[1.16,6699.73]],"ltp":1.16,"tv":106029.16,"id":228749}],"tv":113189.55}]}
{"op":"mcm","clk":"APyXsgkA/sOjCgCs1KMK","pt":1657541647999,"mc":[{"id":"1.200806927","rc":[{"atb":[[1.04,43.05]],"id":228749}]}]}
{"op":"mcm","clk":"AKuYsgkAq8SjCgDG1KMK","pt":1657541648506,"mc":[{"id":"1.200806927","rc":[{"atl":[[1.16,7.15]],"id":228749}]}]}
{"op":"mcm","clk":"AOCYsgkA6MSjCgDs1KMK","pt":1657541649190,"mc":[{"id":"1.200806927","rc":[{"atl":[[1.16,6.49]],"trd":[[1.16,6700.39]],"tv":106029.82,"id":228749},{"trd":[[7.2,825.83]],"tv":7160.49,"id":2857977}],"tv":113190.31}]}
{"op":"mcm","clk":"AJOZsgkAnsWjCgCN1aMK","pt":1657541649787,"mc":[{"id":"1.200806927","rc":[{"atl":[[1.17,271.35],[1.16,0]],"trd":[[1.17,5225.96]],"ltp":1.17,"tv":106037.88,"id":228749}],"tv":113198.37}]}
{"op":"mcm","clk":"AIeasgkAmcajCgDP1aMK","pt":1657541651008,"mc":[{"id":"1.200806927","rc":[{"atl":[[1.16,0.53]],"id":228749}]}]}
{"op":"mcm","clk":"AJKasgkAw8ajCgDo1aMK","pt":1657541651439,"mc":[{"id":"1.200806927","rc":[{"atl":[[1.17,266.11],[1.16,0]],"trd":[[1.17,5231.73],[1.16,6700.92]],"tv":106044.18,"id":228749},{"trd":[[6.8,195.12],[7.2,825.92]],"ltp":6.8,"tv":7161.39,"id":2857977}],"con":true,"tv":113205.57}]}
{"op":"mcm","clk":"ALiasgkA5MajCgD61aMK","pt":1657541651780,"mc":[{"id":"1.200806927","rc":[{"atl":[[1.16,3.89]],"id":228749}]}]}
{"op":"mcm","clk":"AJCbsgkA0MejCgCj1qMK","pt":1657541652925,"mc":[{"id":"1.200806927","rc":[{"atl":[[1.16,109.07]],"id":228749}]}]}
{"op":"mcm","clk":"ANubsgkAssijCgDN1qMK","pt":1657541653900,"mc":[{"id":"1.200806927","rc":[{"atl":[[1.16,114.33]],"id":228749}]}]}
{"op":"mcm","clk":"AJWcsgkA+cijCgD91qMK","pt":1657541654760,"mc":[{"id":"1.200806927","rc":[{"atl":[[1.16,115.38]],"id":228749}]}]}
{"op":"mcm","clk":"AJ2dsgkAg8qjCgDR16MK","pt":1657541656518,"mc":[{"id":"1.200806927","rc":[{"atb":[[1.15,1164.22]],"id":228749}]}]}
{"op":"mcm","clk":"AKidsgkAjMqjCgDW16MK","pt":1657541656623,"mc":[{"id":"1.200806927","rc":[{"atb":[[1.15,1163.69]],"id":228749}]}]}
{"op":"mcm","clk":"ANKdsgkAx8qjCgD716MK","pt":1657541657292,"mc":[{"id":"1.200806927","rc":[{"atl":[[1.16,111.49]],"id":228749}]}]}
{"op":"mcm","clk":"ALKesgkAoMujCgC02KMK","pt":1657541658411,"mc":[{"id":"1.200806927","rc":[{"atb":[[1.15,1153.69]],"trd":[[1.15,8411.87]],"ltp":1.15,"tv":106064.18,"id":228749}],"tv":113225.57}]}
{"op":"mcm","clk":"AOGesgkA2MujCgDM2KMK","pt":1657541658915,"mc":[{"id":"1.200806927","rc":[{"atb":[[7,5.26]],"id":2857977}]}]}
{"op":"mcm","clk":"APGesgkA7MujCgDT2KMK","pt":1657541659018,"mc":[{"id":"1.200806927","rc":[{"atl":[[1.16,110.96]],"id":228749}]}]}
{"op":"mcm","clk":"AKefsgkArcyjCgDs2KMK","pt":1657541659625,"mc":[{"id":"1.200806927","rc":[{"atb":[[1.15,1153.26]],"trd":[[1.15,8412.73]],"tv":106065.04,"id":228749}],"tv":113226.43}]}
{"op":"mcm","clk":"ANifsgkA7cyjCgCM2aMK","pt":1657541660332,"mc":[{"id":"1.200806927","rc":[{"atl":[[1.16,109.91]],"id":228749}]}]}
{"op":"mcm","clk":"AO2fsgkAi82jCgCf2aMK","pt":1657541660625,"mc":[{"id":"1.200806927","rc":[{"atb":[[1.15,1152.55]],"trd":[[1.15,8414.15]],"tv":106066.46,"id":228749}],"tv":113227.85}]}
{"op":"mcm","clk":"APqfsgkAkc2jCgCn2aMK","pt":1657541660734,"mc":[{"id":"1.200806927","rc":[{"atb":[[1.15,1142.03]],"id":228749}]}]}
{"op":"mcm","clk":"AISgsgkAos2jCgC32aMK","pt":1657541660947,"mc":[{"id":"1.200806927","rc":[{"atl":[[1.16,109.8]],"trd":[[1.16,6701.13]],"ltp":1.16,"tv":106066.67,"id":228749}],"tv":113228.06}]}
{"op":"mcm","clk":"ANKgsgkA882jCgDe2aMK","pt":1657541661821,"mc":[{"id":"1.200806927","rc":[{"atl":[[1000,0.33]],"id":228749}]}]}
{"op":"mcm","clk":"AN6gsgkA/82jCgDg2aMK","pt":1657541661935,"mc":[{"id":"1.200806927","rc":[{"atb":[[1.15,1141.5]],"id":228749}]}]}
{"op":"mcm","clk":"APqgsgkAnc6jCgDq2aMK","pt":1657541662210,"mc":[{"id":"1.200806927","rc":[{"atl":[[1000,0.13]],"id":228749},{"atl":[[7.4,7.72]],"id":2857977}]}]}
{"op":"mcm","clk":"AKehsgkAw86jCgD32aMK","pt":1657541662623,"mc":[{"id":"1.200806927","rc":[{"atl":[[1.16,108.85]],"id":228749}]}]}
{"op":"mcm","clk":"AJSisgkAt8+jCgCv2qMK","pt":1657541664023,"mc":[{"id":"1.200806927","rc":[{"atl":[[1.16,104.34]],"id":228749}]}]}
{"op":"mcm","clk":"AJuisgkAvc+jCgCy2qMK","pt":1657541664123,"mc":[{"id":"1.200806927","rc":[{"atl":[[1.16,93.82]],"id":228749}]}]}
{"op":"mcm","clk":"AOOisgkAi9CjCgDS2qMK","pt":1657541664945,"mc":[{"id":"1.200806927","rc":[{"atl":[[1.16,94.66]],"id":228749}]}]}
{"op":"mcm","clk":"AJOjsgkAwdCjCgDy2qMK","pt":1657541665618,"mc":[{"id":"1.200806927","rc":[{"atl":[[1.16,94.23]],"trd":[[1.16,6701.99]],"tv":106067.53,"id":228749}],"tv":113228.92}]}
{"op":"mcm","clk":"AMWjsgkAhNGjCgCM26MK","pt":1657541666334,"mc":[{"id":"1.200806927","rc":[{"atb":[[1.15,1126.24]],"atl":[[1.16,93.57]],"trd":[[1.16,6702.65]],"tv":106068.19,"id":228749},{"trd":[[7.2,826.03]],"ltp":7.2,"tv":7161.5,"id":2857977}],"tv":113229.69}]}
{"op":"mcm","clk":"ANOjsgkAnNGjCgCd26MK","pt":1657541666639,"mc":[{"id":"1.200806927","rc":[{"atb":[[1.15,1123.08]],"id":228749}]}]}
{"op":"mcm","clk":"APejsgkA0NGjCgC826MK","pt":1657541667218,"mc":[{"id":"1.200806927","rc":[{"atb":[[1.15,1121.82]],"id":228749}]}]}
{"op":"mcm","clk":"AP6jsgkA2NGjCgDB26MK","pt":1657541667318,"mc":[{"id":"1.200806927","rc":[{"atb":[[1.15,1121.62]],"trd":[[1.15,8414.55]],"ltp":1.15,"tv":106068.59,"id":228749}],"tv":113230.09}]}
{"op":"mcm","clk":"AJ+ksgkA+dGjCgDO26MK","pt":1657541667730,"mc":[{"id":"1.200806927","rc":[{"atl":[[1.16,92.91]],"trd":[[1.16,6703.31]],"ltp":1.16,"tv":106069.25,"id":228749},{"trd":[[7.2,826.14]],"tv":7161.61,"id":2857977}],"tv":113230.86}]}
{"op":"mcm","clk":"ANmksgkArNKjCgDx26MK","pt":1657541668430,"mc":[{"id":"1.200806927","rc":[{"atb":[[1.15,1103.58]],"id":228749}]}]}
{"op":"mcm","clk":"AKSlsgkA9dKjCgCb3KMK","pt":1657541669444,"mc":[{"id":"1.200806927","rc":[{"atl":[[1.16,86.39]],"trd":[[1.16,6709.83]],"tv":106075.77,"id":228749},{"trd":[[7.2,827.19]],"tv":7162.66,"id":2857977}],"tv":113238.43}]}
{"op":"mcm","clk":"AKWmsgkAhtSjCgDn3KMK","pt":1657541671156,"mc":[{"id":"1.200806927","rc":[{"atb":[[1.15,1103.05]],"id":228749}]}]}
{"op":"mcm","clk":"AJinsgkAgdWjCgCy3aMK","pt":1657541672764,"mc":[{"id":"1.200806927","rc":[{"atb":[[1.03,88.23]],"id":228749}]}]}
{"op":"mcm","clk":"APansgkA4dWjCgDq3aMK","pt":1657541673948,"mc":[{"id":"1.200806927","rc":[{"atl":[[1.16,79.81]],"id":228749}]}]}
{"op":"mcm","clk":"AIWosgkA6dWjCgDv3aMK","pt":1657541674060,"mc":[{"id":"1.200806927","rc":[{"atl":[[1.16,79.15]],"trd":[[1.16,6710.49]],"tv":106076.43,"id":228749},{"trd":[[7.2,827.29]],"tv":7162.76,"id":2857977}],"tv":113239.19}]}
{"op":"mcm","clk":"ANOosgkAz9ajCgC13qMK","pt":1657541675257,"mc":[{"id":"1.200806927","rc":[{"atl":[[1.16,76.52]],"id":228749}]}]}
{"op":"mcm","clk":"APyosgkA+tajCgDR3qMK","pt":1657541675970,"mc":[{"id":"1.200806927","rc":[{"atl":[[1.16,75.68]],"id":228749}]}]}
{"op":"mcm","clk":"AIOpsgkAgtejCgDY3qMK","pt":1657541676079,"mc":[{"id":"1.200806927","rc":[{"atb":[[1.15,1045.94]],"atl":[[1.16,75.02]],"trd":[[1.16,6711.15]],"tv":106077.09,"id":228749},{"trd":[[7.2,827.4]],"tv":7162.87,"id":2857977}],"tv":113239.96}]}
{"op":"mcm","clk":"AMSpsgkA09ejCgCD36MK","pt":1657541676973,"mc":[{"id":"1.200806927","rc":[{"atl":[[1.16,74.09]],"trd":[[1.16,6712.08]],"tv":106078.02,"id":228749},{"trd":[[7.2,827.55]],"tv":7163.02,"id":2857977}],"tv":113241.04}]}
{"op":"mcm","clk":"ANSpsgkA69ejCgCT36MK","pt":1657541677280,"mc":[{"id":"1.200806927","rc":[{"atl":[[1.16,72.79]],"id":228749}]}]}
{"op":"mcm","clk":"AJaqsgkAsdijCgC936MK","pt":1657541678165,"mc":[{"id":"1.200806927","rc":[{"atb":[[1.03,88.46]],"id":228749}]}]}
{"op":"mcm","clk":"ALaqsgkA0NijCgDS36MK","pt":1657541678575,"mc":[{"id":"1.200806927","rc":[{"atb":[[1.15,1043.84]],"id":228749}]}]}
{"op":"mcm","clk":"AL2qsgkA19ijCgDX36MK","pt":1657541678684,"mc":[{"id":"1.200806927","rc":[{"atb":[[1.03,88.23]],"id":228749}]}]}
{"op":"mcm","clk":"AO6qsgkA+tijCgDw36MK","pt":1657541679255,"mc":[{"id":"1.200806927","rc":[{"atb":[[1.15,1017.54]],"id":228749}]}]}
{"op":"mcm","clk":"APeqsgkA/9ijCgD036MK","pt":1657541679367,"mc":[{"id":"1.200806927","rc":[{"atb":[[1.15,1012.28]],"id":228749}]}]}
{"op":"mcm","clk":"AIqrsgkAj9mjCgD936MK","pt":1657541679566,"mc":[{"id":"1.200806927","rc":[{"atb":[[1.15,1009.65]],"atl":[[1.16,75.58]],"id":228749}]}]}
{"op":"mcm","clk":"ANKrsgkA0dmjCgCW4KMK","pt":1657541680344,"mc":[{"id":"1.200806927","rc":[{"atl":[[1.16,49.28]],"id":228749}]}]}
{"op":"mcm","clk":"AOKrsgkA4tmjCgCg4KMK","pt":1657541680567,"mc":[{"id":"1.200806927","rc":[{"atl":[[1.16,48.43]],"trd":[[1.16,6713.78]],"tv":106079.72,"id":228749}],"tv":113242.74}]}
{"op":"mcm","clk":"AP6rsgkAg9qjCgCv4KMK","pt":1657541680970,"mc":[{"id":"1.200806927","rc":[{"atb":[[1.15,0]],"trd":[[1.15,9408.58]],"ltp":1.15,"tv":107073.75,"id":228749},{"atb":[[7.8,58.72]],"atl":[[7.4,0]],"trd":[[7.8,146.67],[7.4,15.44]],"ltp":7.8,"tv":7325.02,"id":2857977}],"tv":114398.77}]}
{"op":"mcm","clk":"AKCssgkAp9qjCgC+4KMK","pt":1657541681390,"mc":[{"id":"1.200806927","rc":[{"atl":[[1.15,0.53]],"id":228749}]}]}
{"op":"mcm","clk":"APessgkAhtujCgCZ4aMK","pt":1657541682481,"mc":[{"id":"1.200806927","rc":[{"atl":[[1.15,5.79]],"id":228749}]}]}
{"op":"mcm","clk":"AP6ssgkAj9ujCgCb4aMK","pt":1657541682584,"mc":[{"id":"1.200806927","rc":[{"atl":[[1.15,4.16]],"id":228749},{"atl":[[11,0.55]],"id":2857977}]}]}
{"op":"mcm","clk":"AK2tsgkAxdujCgCx4aMK","pt":1657541683170,"mc":[{"id":"1.200806927","rc":[{"atb":[[7.4,0.58]],"id":2857977}]}]}
{"op":"mcm","clk":"AM6tsgkA/tujCgDG4aMK","pt":1657541683786,"mc":[{"id":"1.200806927","rc":[{"atl":[[1.15,3.93]],"trd":[[1.15,9409.04]],"tv":107074.21,"id":228749}],"tv":114399.23}]}
{"op":"mcm","clk":"AOWtsgkApdyjCgDV4aMK","pt":1657541684154,"mc":[{"id":"1.200806927","rc":[{"atb":[[1.03,87.39]],"id":228749}]}]}
{"op":"mcm","clk":"ANqusgkAst2jCgCV4qMK","pt":1657541685687,"mc":[{"id":"1.200806927","rc":[{"atl":[[1.15,3.35]],"id":228749}]}]}
{"op":"mcm","clk":"AJmvsgkA+N2jCgC54qMK","pt":1657541686462,"mc":[{"id":"1.200806927","rc":[{"atl":[[1.16,45.64]],"id":228749}]}]}
{"op":"mcm","clk":"ALSvsgkAnt6jCgDL4qMK","pt":1657541686897,"mc":[{"id":"1.200806927","rc":[{"atb":[[7.8,0]],"trd":[[7.8,146.89]],"tv":7325.24,"id":2857977}],"tv":114399.45}]}
{"op":"mcm","clk":"APKvsgkA596jCgDr4qMK","pt":1657541687670,"mc":[{"id":"1.200806927","rc":[{"atl":[[1.16,43.73],[1.15,0]],"id":228749}]}]}
{"op":"mcm","clk":"AJmwsgkAld+jCgCE46MK","pt":1657541688185,"mc":[{"id":"1.200806927","rc":[{"atl":[[1.16,33.21]],"id":228749}]}]}
{"op":"mcm","clk":"APmwsgkAhOCjCgDA46MK","pt":1657541689678,"mc":[{"id":"1.200806927","rc":[{"atl":[[1.15,10.52]],"id":228749}]}]}
{"op":"mcm","clk":"ALCxsgkAueCjCgDq46MK","pt":1657541690404,"mc":[{"id":"1.200806927","rc":[{"atl":[[1.15,0]],"id":228749}]}]}
{"op":"mcm","clk":"AMSxsgkAyOCjCgDz46MK","pt":1657541690566,"mc":[{"id":"1.200806927","rc":[{"atl":[[7.8,0.11]],"id":2857977}]}]}
{"op":"mcm","clk":"AM+xsgkA0+CjCgD446MK","pt":1657541690670,"mc":[{"id":"1.200806927","rc":[{"atl":[[1.16,34.79]],"id":228749}]}]}
{"op":"mcm","clk":"AIKysgkAhOGjCgCk5KMK","pt":1657541691397,"mc":[{"id":"1.200806927","rc":[{"atb":[[1.15,10.52]],"id":228749}]}]}
{"op":"mcm","clk":"AJ6ysgkAnuGjCgCz5KMK","pt":1657541691766,"mc":[{"id":"1.200806927","rc":[{"atb":[[7.4,1.11]],"id":2857977}]}]}
{"op":"mcm","clk":"ANyysgkA3OGjCgDZ5KMK","pt":1657541692602,"mc":[{"id":"1.200806927","rc":[{"atl":[[7.8,0]],"id":2857977}]}]}
{"op":"mcm","clk":"AIuzsgkAiOKjCgD35KMK","pt":1657541693168,"mc":[{"id":"1.200806927","rc":[{"atl":[[7.8,0.11]],"id":2857977}]}]}
{"op":"mcm","clk":"AJyzsgkAmOKjCgCA5aMK","pt":1657541693368,"mc":[{"id":"1.200806927","rc":[{"atl":[[1.16,34.26]],"id":228749}]}]}
{"op":"mcm","clk":"ANCzsgkAxOKjCgCZ5aMK","pt":1657541693991,"mc":[{"id":"1.200806927","rc":[{"atb":[[1.15,5.26]],"id":228749}]}]}
{"op":"mcm","clk":"ANezsgkAzuKjCgCg5aMK","pt":1657541694098,"mc":[{"id":"1.200806927","rc":[{"atb":[[7,0]],"id":2857977}]}]}
{"op":"mcm","clk":"AIy0sgkAjeOjCgDD5aMK","pt":1657541694771,"mc":[{"id":"1.200806927","rc":[{"atb":[[1.15,6.84]],"id":228749}]}]}
{"op":"mcm","clk":"AJK0sgkAmuOjCgDJ5aMK","pt":1657541694883,"mc":[{"id":"1.200806927","rc":[{"atb":[[1.14,210.37]],"id":228749}]}]}
{"op":"mcm","clk":"AMG0sgkAyeOjCgDm5aMK","pt":1657541695506,"mc":[{"id":"1.200806927","rc":[{"atb":[[1.15,6.19]],"trd":[[1.15,9410.34]],"tv":107075.51,"id":228749}],"tv":114400.75}]}
{"op":"mcm","clk":"AOC0sgkA9+OjCgD+5aMK","pt":1657541696008,"mc":[{"id":"1.200806927","rc":[{"atl":[[7.8,0]],"id":2857977}]}]}
{"op":"mcm","clk":"AIq1sgkApOSjCgCf5qMK","pt":1657541696586,"mc":[{"id":"1.200806927","rc":[{"atb":[[7.4,0.53]],"id":2857977}]}]}
{"op":"mcm","clk":"AK62sgkA1eWjCgCL56MK","pt":1657541698818,"mc":[{"id":"1.200806927","rc":[{"atb":[[1.15,7.24]],"id":228749}]}]}
{"op":"mcm","clk":"AOG2sgkAi+ajCgCj56MK","pt":1657541699586,"mc":[{"id":"1.200806927","rc":[{"atb":[[7.4,0]],"id":2857977}]}]}
{"op":"mcm","clk":"AIa3sgkAteajCgC456MK","pt":1657541700209,"mc":[{"id":"1.200806927","rc":[{"atl":[[1.16,0]],"trd":[[1.16,6748.04]],"ltp":1.16,"tv":107109.77,"id":228749},{"atl":[[7.2,18.25]],"trd":[[7.2,833.07]],"ltp":7.2,"tv":7330.76,"id":2857977}],"tv":114440.53}]}
{"op":"mcm","clk":"ALm4sgkA3+ejCgCS6KMK","pt":1657541702194,"mc":[{"id":"1.200806927","rc":[{"atb":[[1.15,0]],"atl":[[1.15,146.54]],"trd":[[1.16,6861.32]],"tv":107223.05,"id":228749},{"atl":[[7.2,0]],"trd":[[7.2,851.32]],"tv":7349.01,"id":2857977}],"tv":114572.06}]}
{"op":"mcm","clk":"AOC6sgkA7umjCgCu6aMK","pt":1657541705208,"mc":[{"id":"1.200806927","rc":[{"atl":[[1.15,138.99]],"trd":[[1.15,9425.44]],"ltp":1.15,"tv":107238.15,"id":228749}],"tv":114587.16}]}
{"op":"mcm","clk":"AMu7sgkAu+qjCgDg6aMK","pt":1657541706125,"mc":[{"id":"1.200806927","rc":[{"atl":[[1.15,138.28]],"trd":[[1.15,9426.15]],"tv":107238.86,"id":228749},{"trd":[[7.6,305.37]],"ltp":7.6,"tv":7349.12,"id":2857977}],"tv":114587.98}]}
{"op":"mcm","clk":"AM28sgkA2OujCgCz6qMK","pt":1657541707613,"mc":[{"id":"1.200806927","rc":[{"atl":[[1.15,140.38]],"id":228749}]}]}
{"op":"mcm","clk":"ANK8sgkA5OujCgC36qMK","pt":1657541707736,"mc":[{"id":"1.200806927","rc":[{"atl":[[1.15,140.91]],"id":228749}]}]}
{"op":"mcm","clk":"AN68sgkA8eujCgC/6qMK","pt":1657541707832,"mc":[{"id":"1.200806927","rc":[{"atl":[[1.15,141.44]],"id":228749}]}]}
{"op":"mcm","clk":"AOy8sgkAhOyjCgDH6qMK","pt":1657541708037,"mc":[{"id":"1.200806927","rc":[{"atl":[[1.15,142.23]],"id":228749}]}]}
{"op":"mcm","clk":"AKK9sgkAreyjCgDV6qMK","pt":1657541708500,"mc":[{"id":"1.200806927","rc":[{"atl":[[1.15,140.98]],"trd":[[1.15,9429.65]],"tv":107242.36,"id":228749},{"trd":[[7.6,305.9]],"tv":7349.65,"id":2857977}],"tv":114592.01}]}
{"op":"mcm","clk":"AOK9sgkA6uyjCgD36qMK","pt":1657541709201,"mc":[{"id":"1.200806927","rc":[{"atl":[[1.15,140.27]],"trd":[[1.15,9430.36]],"tv":107243.07,"id":228749},{"trd":[[7.6,306.01]],"tv":7349.76,"id":2857977}],"tv":114592.83}]}
{"op":"mcm","clk":"APO9sgkAgO2jCgCD66MK","pt":1657541709422,"mc":[{"id":"1.200806927","rc":[{"atl":[[1.15,143.27]],"id":228749}]}]}
{"op":"mcm","clk":"AIO+sgkAkO2jCgCL66MK","pt":1657541709627,"mc":[{"id":"1.200806927","rc":[{"atl":[[1.16,12.95]],"id":228749}]}]}
{"op":"mcm","clk":"AJ2+sgkAq+2jCgCf66MK","pt":1657541710090,"mc":[{"id":"1.200806927","rc":[{"atb":[[1.14,0]],"id":228749}]}]}
{"op":"mcm","clk":"AL2+sgkAw+2jCgCq66MK","pt":1657541710413,"mc":[{"id":"1.200806927","rc":[{"atl":[[1.39,0]],"id":228749}]}]}
{"op":"mcm","clk":"ANe+sgkA3O2jCgC+66MK","pt":1657541710727,"mc":[{"id":"1.200806927","rc":[{"atl":[[1.15,147.27]],"id":228749}]}]}
{"op":"mcm","clk":"AN2+sgkA5+2jCgC/66MK","pt":1657541710820,"mc":[{"id":"1.200806927","rc":[{"atl":[[1.15,149.9]],"id":228749}]}]}
{"op":"mcm","clk":"AKC/sgkAoe6jCgDl66MK","pt":1657541711531,"mc":[{"id":"1.200806927","rc":[{"atl":[[1.15,144.64]],"id":228749}]}]}
{"op":"mcm","clk":"AKa/sgkAqu6jCgDt66MK","pt":1657541711618,"mc":[{"id":"1.200806927","rc":[{"atl":[[1000,0.23]],"id":228749}]}]}
{"op":"mcm","clk":"ANG/sgkA2e6jCgCL7KMK","pt":1657541712128,"mc":[{"id":"1.200806927","rc":[{"atl":[[1000,0.13]],"id":228749}]}]}
{"op":"mcm","clk":"AKzAsgkAue+jCgC+7KMK","pt":1657541713134,"mc":[{"id":"1.200806927","rc":[{"atb":[[7.2,5.26]],"id":2857977}]}]}
{"op":"mcm","clk":"APbAsgkAkfCjCgDw7KMK","pt":1657541713926,"mc":[{"id":"1.200806927","rc":[{"atl":[[1.17,0]],"id":228749}]}]}
{"op":"mcm","clk":"AJDBsgkAqPCjCgD27KMK","pt":1657541714231,"mc":[{"id":"1.200806927","rc":[{"atl":[[1.15,127.63]],"trd":[[1.15,9447.37]],"tv":107260.08,"id":228749},{"trd":[[7.6,308.58]],"tv":7352.33,"id":2857977}],"tv":114612.41}]}
{"op":"mcm","clk":"AJbBsgkAsfCjCgD57KMK","pt":1657541714316,"mc":[{"id":"1.200806927","rc":[{"atl":[[1.15,125]],"id":228749}]}]}
{"op":"mcm","clk":"AKHBsgkAvvCjCgD97KMK","pt":1657541714399,"mc":[{"id":"1.200806927","rc":[{"atl":[[1.15,122]],"id":228749}]}]}
{"op":"mcm","clk":"ALrCsgkA1fGjCgDj7aMK","pt":1657541715803,"mc":[{"id":"1.200806927","rc":[{"atb":[[8.2,52.59]],"id":2857977}]}]}
{"op":"mcm","clk":"AMvCsgkA5PGjCgDx7aMK","pt":1657541716024,"mc":[{"id":"1.200806927","rc":[{"atl":[[1.14,210.37]],"id":228749}]}]}
{"op":"mcm","clk":"APrCsgkAivKjCgCX7qMK","pt":1657541716531,"mc":[{"id":"1.200806927","rc":[{"atl":[[1.14,184.07]],"id":228749},{"atb":[[7.2,5.79]],"id":2857977}]}]}
{"op":"mcm","clk":"AI7DsgkAmvKjCgCf7qMK","pt":1657541716747,"mc":[{"id":"1.200806927","rc":[{"atb":[[8.2,52.06]],"id":2857977}]}]}
{"op":"mcm","clk":"AJXDsgkAoPKjCgCf7qMK","pt":1657541716791,"mc":[{"id":"1.200806927","rc":[{"atl":[[1.15,118]],"id":228749}]}]}
{"op":"mcm","clk":"AKPDsgkAqvKjCgCo7qMK","pt":1657541716912,"mc":[{"id":"1.200806927","rc":[{"atl":[[1.14,182.78]],"trd":[[1.14,14288.68]],"ltp":1.14,"tv":107262.66,"id":228749}],"tv":114614.99}]}
{"op":"mcm","clk":"AKvDsgkAsPKjCgCt7qMK","pt":1657541717013,"mc":[{"id":"1.200806927","rc":[{"atl":[[1.14,168.06]],"id":228749}]}]}
{"op":"mcm","clk":"AMDDsgkAxPKjCgC57qMK","pt":1657541717224,"mc":[{"id":"1.200806927","rc":[{"atl":[[1.14,168.16]],"id":228749}]}]}
{"op":"mcm","clk":"AMvDsgkAy/KjCgC87qMK","pt":1657541717324,"mc":[{"id":"1.200806927","rc":[{"atl":[[1.15,119.84]],"id":228749}]}]}
{"op":"mcm","clk":"AIvEsgkA/PKjCgDc7qMK","pt":1657541718055,"mc":[{"id":"1.200806927","rc":[{"atl":[[1.14,168.06]],"id":228749}]}]}
{"op":"mcm","clk":"AM3EsgkAuvOjCgCH76MK","pt":1657541718836,"mc":[{"id":"1.200806927","rc":[{"atb":[[8.2,51.95]],"trd":[[8.2,1.18]],"ltp":8.2,"tv":7352.54,"id":2857977}],"tv":114615.2}]}
{"op":"mcm","clk":"ANfEsgkAwfOjCgCN76MK","pt":1657541718926,"mc":[{"id":"1.200806927","rc":[{"atl":[[1.14,165.47]],"id":228749}]}]}
{"op":"mcm","clk":"AIbFsgkA5vOjCgCq76MK","pt":1657541719442,"mc":[{"id":"1.200806927","rc":[{"atl":[[1.14,139.17]],"id":228749}]}]}
{"op":"mcm","clk":"AMDFsgkAmfSjCgDE76MK","pt":1657541720026,"mc":[{"id":"1.200806927","rc":[{"atl":[[1.14,137.75]],"id":228749}]}]}
{"op":"mcm","clk":"AOnFsgkAufSjCgDV76MK","pt":1657541720439,"mc":[{"id":"1.200806927","rc":[{"atl":[[1.14,133.24]],"id":228749}]}]}
{"op":"mcm","clk":"AMPGsgkAovWjCgCP8KMK","pt":1657541721425,"mc":[{"id":"1.200806927","rc":[{"atl":[[1.14,127.98],[1.15,117.74]],"id":228749}]}]}
{"op":"mcm","clk":"AMTHsgkAovajCgDO8KMK","pt":1657541723030,"mc":[{"id":"1.200806927","rc":[{"atb":[[8.2,51.42]],"id":2857977}]}]}
{"op":"mcm","clk":"AM3HsgkAq/ajCgDS8KMK","pt":1657541723137,"mc":[{"id":"1.200806927","rc":[{"atl":[[1.14,126.25]],"id":228749}]}]}
{"op":"mcm","clk":"AL7IsgkAsPejCgCL8aMK","pt":1657541724637,"mc":[{"id":"1.200806927","rc":[{"atb":[[8.2,50.89]],"id":2857977}]}]}
{"op":"mcm","clk":"AM7JsgkAwPijCgDb8aMK","pt":1657541726259,"mc":[{"id":"1.200806927","rc":[{"atb":[[1.13,0]],"id":228749}]}]}
{"op":"mcm","clk":"AL/KsgkA1fmjCgCh8qMK","pt":1657541727803,"mc":[{"id":"1.200806927","rc":[{"atl":[[9,0.53]],"id":2857977}]}]}
{"op":"mcm","clk":"AOLKsgkAhPqjCgC78qMK","pt":1657541728332,"mc":[{"id":"1.200806927","rc":[{"atb":[[1.13,530.33]],"id":228749}]}]}
{"op":"mcm","clk":"ALXLsgkA6fqjCgDo8qMK","pt":1657541729523,"mc":[{"id":"1.200806927","rc":[{"atl":[[1.15,115.49]],"id":228749}]}]}
{"op":"mcm","clk":"APfLsgkAyvujCgCW86MK","pt":1657541730562,"mc":[{"id":"1.200806927","rc":[{"atb":[[8.2,49.85]],"id":2857977}]}]}
{"op":"mcm","clk":"AJ7MsgkAhfyjCgC286MK","pt":1657541731149,"mc":[{"id":"1.200806927","rc":[{"atl":[[1.15,116.12]],"id":228749}]}]}
{"op":"mcm","clk":"APDMsgkA4vyjCgDm86MK","pt":1657541732133,"mc":[{"id":"1.200806927","rc":[{"atb":[[1.11,495.89]],"id":228749}]}]}
{"op":"mcm","clk":"AJTNsgkAhv2jCgD486MK","pt":1657541732545,"mc":[{"id":"1.200806927","rc":[{"atb":[[1.13,477.74]],"id":228749}]}]}
{"op":"mcm","clk":"AN/NsgkAx/2jCgCh9KMK","pt":1657541733331,"mc":[{"id":"1.200806927","rc":[{"atb":[[1.13,688.11]],"id":228749}]}]}
{"op":"mcm","clk":"APXNsgkA3f2jCgCt9KMK","pt":1657541733640,"mc":[{"id":"1.200806927","rc":[{"atb":[[1.13,210.37]],"id":228749}]}]}
{"op":"mcm","clk":"AJvOsgkA+P2jCgC79KMK","pt":1657541734041,"mc":[{"id":"1.200806927","rc":[{"atb":[[1.13,205.11]],"id":228749}]}]}
{"op":"mcm","clk":"AIvPsgkA7f6jCgD99KMK","pt":1657541735457,"mc":[{"id":"1.200806927","rc":[{"atb":[[8.2,47.22]],"id":2857977}]}]}
{"op":"mcm","clk":"AJrPsgkAgP+jCgCG9aMK","pt":1657541735670,"mc":[{"id":"1.200806927","rc":[{"atl":[[1.14,123.62]],"id":228749}]}]}
{"op":"mcm","clk":"AObPsgkA3/+jCgCz9aMK","pt":1657541736756,"mc":[{"id":"1.200806927","rc":[{"atb":[[8.2,46.69]],"id":2857977}]}]}
{"op":"mcm","clk":"AIzQsgkA/f+jCgDG9aMK","pt":1657541737220,"mc":[{"id":"1.200806927","rc":[{"atb":[[8.2,46.58]],"trd":[[8.2,1.4]],"tv":7352.76,"id":2857977}],"tv":114615.42}]}
{"op":"mcm","clk":"AM7QsgkAxICkCgDq9aMK","pt":1657541737951,"mc":[{"id":"1.200806927","rc":[{"atl":[[1000,0.29]],"id":228749}]}]}
{"op":"mcm","clk":"AODQsgkA0ICkCgDx9aMK","pt":1657541738151,"mc":[{"id":"1.200806927","rc":[{"atb":[[8.2,46.05]],"id":2857977}]}]}
{"op":"mcm","clk":"APTQsgkA44CkCgCG9qMK","pt":1657541738380,"mc":[{"id":"1.200806927","rc":[{"atl":[[1000,0.13]],"id":228749}]}]}
{"op":"mcm","clk":"AI3RsgkAiIGkCgCW9qMK","pt":1657541738688,"mc":[{"id":"1.200806927","rc":[{"atb":[[8.2,45.94]],"trd":[[8.2,1.62]],"tv":7352.98,"id":2857977}],"tv":114615.64}]}
{"op":"mcm","clk":"AM7RsgkAyIGkCgC+9qMK","pt":1657541739453,"mc":[{"id":"1.200806927","rc":[{"atb":[[1.12,0]],"id":228749}]}]}
{"op":"mcm","clk":"AIHSsgkAhoKkCgDa9qMK","pt":1657541740021,"mc":[{"id":"1.200806927","rc":[{"atb":[[8.2,45.41]],"id":2857977}]}]}
{"op":"mcm","clk":"ANjSsgkA14KkCgCA96MK","pt":1657541740964,"mc":[{"id":"1.200806927","rc":[{"atl":[[1.14,120.99]],"id":228749}]}]}
{"op":"mcm","clk":"AMXTsgkA5oOkCgDz96MK","pt":1657541742244,"mc":[{"id":"1.200806927","rc":[{"atl":[[1.14,120.97]],"trd":[[1.14,14288.72]],"tv":107262.7,"id":228749}],"tv":114615.68}]}
{"op":"mcm","clk":"AM/TsgkA74OkCgD396MK","pt":1657541742364,"mc":[{"id":"1.200806927","rc":[{"atb":[[8.2,45.3]],"trd":[[8.2,1.83]],"tv":7353.19,"id":2857977}],"tv":114615.89}]}
{"op":"mcm","clk":"APLTsgkAk4SkCgCH+KMK","pt":1657541742761,"mc":[{"id":"1.200806927","rc":[{"atb":[[1.13,114.95]],"id":228749}]}]}
{"op":"mcm","clk":"APvTsgkAmoSkCgCL+KMK","pt":1657541742858,"mc":[{"id":"1.200806927","rc":[{"atl":[[1.14,110.45]],"id":228749}]}]}
{"op":"mcm","clk":"AIHUsgkApoSkCgCR+KMK","pt":1657541742977,"mc":[{"id":"1.200806927","rc":[{"atl":[[1.14,105.19]],"id":228749}]}]}
{"op":"mcm","clk":"AI/UsgkAtYSkCgCY+KMK","pt":1657541743182,"mc":[{"id":"1.200806927","rc":[{"atb":[[8.2,44.25]],"id":2857977}]}]}
{"op":"mcm","clk":"AJrUsgkAxYSkCgCc+KMK","pt":1657541743338,"mc":[{"id":"1.200806927","rc":[{"atb":[[8.2,44.14]],"trd":[[8.2,2.05]],"tv":7353.41,"id":2857977}],"tv":114616.11}]}
{"op":"mcm","clk":"AKjUsgkA0ISkCgCk+KMK","pt":1657541743452,"mc":[{"id":"1.200806927","rc":[{"atb":[[1.13,114.78]],"trd":[[1.13,4250.33]],"ltp":1.13,"tv":107263.04,"id":228749}],"tv":114616.45}]}
{"op":"mcm","clk":"ANjUsgkA/ISkCgC8+KMK","pt":1657541743978,"mc":[{"id":"1.200806927","rc":[{"atb":[[1.13,113.47]],"id":228749}]}]}
{"op":"mcm","clk":"APDUsgkAlYWkCgDI+KMK","pt":1657541744274,"mc":[{"id":"1.200806927","rc":[{"atb":[[1.13,0]],"atl":[[1.13,96.9]],"id":228749}]}]}
{"op":"mcm","clk":"AKbVsgkA3IWkCgDm+KMK","pt":1657541744970,"mc":[{"id":"1.200806927","rc":[{"atl":[[1.13,83.75],[1.15,115.49]],"id":228749}]}]}
{"op":"mcm","clk":"AMzVsgkAioakCgCC+aMK","pt":1657541745495,"mc":[{"id":"1.200806927","rc":[{"atl":[[1.13,78.49]],"id":228749}]}]}
{"op":"mcm","clk":"AO/VsgkArYakCgCV+aMK","pt":1657541745880,"mc":[{"id":"1.200806927","rc":[{"atb":[[1.12,10.52]],"id":228749}]}]}
{"op":"mcm","clk":"AKLWsgkA74akCgDC+aMK","pt":1657541746580,"mc":[{"id":"1.200806927","rc":[{"atl":[[1.13,72.06]],"trd":[[1.13,4256.76]],"tv":107269.47,"id":228749},{"trd":[[8.6,69.18]],"ltp":8.6,"tv":7354.26,"id":2857977}],"tv":114623.73}]}
{"op":"mcm","clk":"ANnWsgkArYekCgDb+aMK","pt":1657541747170,"mc":[{"id":"1.200806927","rc":[{"atb":[[1.11,45.08]],"id":228749}]}]}
{"op":"mcm","clk":"ALHXsgkAiIikCgCN+qMK","pt":1657541748265,"mc":[{"id":"1.200806927","rc":[{"atl":[[1.13,94.38]],"id":228749}]}]}
{"op":"mcm","clk":"ANXXsgkAqYikCgCi+qMK","pt":1657541748667,"mc":[{"id":"1.200806927","rc":[{"atl":[[10,0.11]],"id":2857977}]}]}
{"op":"mcm","clk":"AObXsgkAuoikCgCv+qMK","pt":1657541748887,"mc":[{"id":"1.200806927","rc":[{"atb":[[1.04,43.89]],"atl":[[1.13,91.58]],"trd":[[1.13,4262.36]],"tv":107275.07,"id":228749}],"tv":114629.33}]}
{"op":"mcm","clk":"AJfYsgkA8IikCgDN+qMK","pt":1657541749462,"mc":[{"id":"1.200806927","rc":[{"atl":[[1.13,88.3]],"trd":[[1.13,4265.64]],"tv":107278.35,"id":228749},{"trd":[[8.6,69.61]],"tv":7354.69,"id":2857977}],"tv":114633.04}]}
{"op":"mcm","clk":"AJ/YsgkA/YikCgDU+qMK","pt":1657541749566,"mc":[{"id":"1.200806927","rc":[{"atl":[[1.13,68.28]],"trd":[[1.13,4285.66]],"tv":107298.37,"id":228749},{"trd":[[8.6,72.24]],"tv":7357.32,"id":2857977}],"tv":114655.69}]}
{"op":"mcm","clk":"AKPZsgkAiIqkCgCU+6MK","pt":1657541750970,"mc":[{"id":"1.200806927","rc":[{"atl":[[1.13,68.45]],"id":228749}]}]}
{"op":"mcm","clk":"APPZsgkA1IqkCgC9+6MK","pt":1657541751770,"mc":[{"id":"1.200806927","rc":[{"atb":[[1.13,932.35]],"atl":[[1.13,0]],"trd":[[1.13,4330.64]],"tv":107343.35,"id":228749}],"tv":114700.67}]}
{"op":"mcm","clk":"AMXasgkAnIukCgDn+6MK","pt":1657541752661,"mc":[{"id":"1.200806927","rc":[{"atl":[[1.14,99.93]],"id":228749}]}]}
{"op":"mcm","clk":"ANHasgkAqoukCgDu+6MK","pt":1657541752807,"mc":[{"id":"1.200806927","rc":[{"atl":[[1.14,73.63]],"id":228749}]}]}
{"op":"mcm","clk":"APnasgkA1oukCgCA/KMK","pt":1657541753199,"mc":[{"id":"1.200806927","rc":[{"atl":[[1.14,70.47]],"id":228749}]}]}
{"op":"mcm","clk":"AIDbsgkA4YukCgCC/KMK","pt":1657541753280,"mc":[{"id":"1.200806927","rc":[{"atl":[[1.15,6.32]],"id":228749}]}]}
{"op":"mcm","clk":"ANrbsgkAv4ykCgCw/KMK","pt":1657541754291,"mc":[{"id":"1.200806927","rc":[{"atb":[[1.04,44.09]],"id":228749}]}]}
{"op":"mcm","clk":"AOjbsgkA1oykCgC1/KMK","pt":1657541754472,"mc":[{"id":"1.200806927","rc":[{"atb":[[1.13,906.05]],"id":228749}]}]}
{"op":"mcm","clk":"APnbsgkA8IykCgDA/KMK","pt":1657541754689,"mc":[{"id":"1.200806927","rc":[{"atb":[[1.04,43.89]],"id":228749}]}]}
{"op":"mcm","clk":"ALHcsgkAxI2kCgDl/KMK","pt":1657541755485,"mc":[{"id":"1.200806927","rc":[{"atb":[[1.13,1010.05]],"id":228749}]}]}
{"op":"mcm","clk":"AMXcsgkA2o2kCgDv/KMK","pt":1657541755705,"mc":[{"id":"1.200806927","rc":[{"atb":[[1.13,1012.68]],"id":228749}]}]}
{"op":"mcm","clk":"ANXcsgkA7Y2kCgD6/KMK","pt":1657541755906,"mc":[{"id":"1.200806927","rc":[{"atb":[[1.13,999.53]],"id":228749}]}]}
{"op":"mcm","clk":"AJbdsgkAo46kCgCb/aMK","pt":1657541756561,"mc":[{"id":"1.200806927","rc":[{"atb":[[1.13,1010.05]],"id":228749}]}]}
{"op":"mcm","clk":"AKvdsgkAvo6kCgCr/aMK","pt":1657541756882,"mc":[{"id":"1.200806927","rc":[{"atb":[[1.13,246.59]],"id":228749}]}]}
{"op":"mcm","clk":"APjdsgkAiI+kCgDi/aMK","pt":1657541757792,"mc":[{"id":"1.200806927","rc":[{"atb":[[1.13,142.59]],"id":228749}]}]}
{"op":"mcm","clk":"AKzesgkAxY+kCgCC/qMK","pt":1657541758487,"mc":[{"id":"1.200806927","rc":[{"atl":[[1.15,6.85]],"id":228749},{"atb":[[8.2,32.81]],"trd":[[8.2,24.71]],"ltp":8.2,"tv":7379.98,"id":2857977}],"tv":114723.33}]}
{"op":"mcm","clk":"ANbesgkA7Y+kCgCe/qMK","pt":1657541758905,"mc":[{"id":"1.200806927","rc":[{"atb":[[1.13,140.34]],"id":228749}]}]}
{"op":"mcm","clk":"AIrfsgkAu5CkCgDE/qMK","pt":1657541759580,"mc":[{"id":"1.200806927","rc":[{"atl":[[1.15,6.06]],"id":228749}]}]}
{"op":"mcm","clk":"AJzfsgkAzJCkCgDQ/qMK","pt":1657541759797,"mc":[{"id":"1.200806927","rc":[{"atl":[[1.14,70.27]],"trd":[[1.14,14289.12]],"ltp":1.14,"tv":107343.75,"id":228749}],"tv":114723.73}]}
{"op":"mcm","clk":"AMHfsgkA95CkCgDo/qMK","pt":1657541760192,"mc":[{"id":"1.200806927","rc":[{"atb":[[1.04,43.05]],"id":228749}]}]}
{"op":"mcm","clk":"AMvfsgkAgZGkCgDs/qMK","pt":1657541760291,"mc":[{"id":"1.200806927","rc":[{"atb":[[1.13,141.39]],"id":228749}]}]}
{"op":"mcm","clk":"AOrfsgkAnpGkCgD7/qMK","pt":1657541760610,"mc":[{"id":"1.200806927","rc":[{"atb":[[1.13,136.13]],"id":228749}]}]}
{"op":"mcm","clk":"AMLgsgkAhJKkCgCm/6MK","pt":1657541761604,"mc":[{"id":"1.200806927","rc":[{"atb":[[7.2,0.53]],"id":2857977}]}]}
{"op":"mcm","clk":"AOfgsgkAupKkCgC6/6MK","pt":1657541761987,"mc":[{"id":"1.200806927","rc":[{"atb":[[1.13,134.33]],"id":228749}]}]}
{"op":"mcm","clk":"AIjhsgkA6ZKkCgDR/6MK","pt":1657541762441,"mc":[{"id":"1.200806927","rc":[{"atl":[[8.6,0.17]],"id":2857977}]}]}
{"op":"mcm","clk":"ALnhsgkAoJOkCgDl/6MK","pt":1657541762882,"mc":[{"id":"1.200806927","rc":[{"atb":[[1.13,131.66]],"trd":[[1.13,4335.99]],"ltp":1.13,"tv":107349.1,"id":228749}],"tv":114729.08}]}
{"op":"mcm","clk":"AO/hsgkA45OkCgCNgKQK","pt":1657541763500,"mc":[{"id":"1.200806927","rc":[{"atb":[[1.1,905.62]],"id":228749}]}]}
{"op":"mcm","clk":"APzhsgkA7JOkCgCSgKQK","pt":1657541763617,"mc":[{"id":"1.200806927","rc":[{"atl":[[1.14,0],[1.16,0],[1.15,0]],"trd":[[1.14,14359.39],[1.15,9453.43],[1.16,6874.27]],"ltp":1.16,"tv":107438.38,"id":228749},{"atb":[[8.2,0],[7.2,0]],"atl":[[6.6,153.49]],"trd":[[7.6,309.5],[7.2,853.41],[8,1533.01]],"ltp":7.2,"tv":7393,"id":2857977}],"tv":114831.38}]}
{"op":"mcm","clk":"AIbisgkA/JOkCgCcgKQK","pt":1657541763720,"mc":[{"id":"1.200806927","rc":[{"atb":[[1.13,131.81]],"id":228749}]}]}
{"op":"mcm","clk":"AMHisgkAy5SkCgDGgKQK","pt":1657541764397,"mc":[{"id":"1.200806927","rc":[{"atb":[[1.13,132.34]],"id":228749}]}]}
{"op":"mcm","clk":"AMjisgkA2ZSkCgDRgKQK","pt":1657541764526,"mc":[{"id":"1.200806927","rc":[{"atl":[[8.2,42.27]],"id":2857977}]}]}
{"op":"mcm","clk":"AP3isgkAoJWkCgDugKQK","pt":1657541765097,"mc":[{"id":"1.200806927","rc":[{"trd":[[1.17,5234.36]],"ltp":1.17,"tv":107441.01,"id":228749},{"atl":[[6.6,153.02]],"trd":[[6.6,0.73]],"ltp":6.6,"tv":7393.47,"id":2857977}],"tv":114834.48}]}
{"op":"mcm","clk":"ALrjsgkA1JWkCgCPgaQK","pt":1657541765633,"mc":[{"id":"1.200806927","rc":[{"atb":[[1.13,133.65],[1.15,1200]],"id":228749}]}]}
{"op":"mcm","clk":"AIbksgkAj5akCgCxgaQK","pt":1657541766291,"mc":[{"id":"1.200806927","rc":[{"atb":[[1.17,1200],[1.14,0.43]],"id":228749}]}]}
{"op":"mcm","clk":"AJ7ksgkAp5akCgC7gaQK","pt":1657541766504,"mc":[{"id":"1.200806927","rc":[{"atl":[[1.2,0.53]],"id":228749}]}]}
{"op":"mcm","clk":"AP3ksgkAgZekCgDogaQK","pt":1657541767415,"mc":[{"id":"1.200806927","rc":[{"atl":[[9.2,0.43]],"id":2857977}]}]}
{"op":"mcm","clk":"AJjlsgkAopekCgD1gaQK","pt":1657541767706,"mc":[{"id":"1.200806927","rc":[{"atb":[[1.17,0]],"id":228749}]}]}
{"op":"mcm","clk":"AL3lsgkAypekCgCNgqQK","pt":1657541768091,"mc":[{"id":"1.200806927","rc":[{"trd":[[1.17,5235.2]],"tv":107441.85,"id":228749},{"atl":[[6.6,152.87]],"trd":[[6.6,0.88]],"tv":7393.62,"id":2857977}],"tv":114835.47}]}
{"op":"mcm","clk":"AMblsgkA0ZekCgCQgqQK","pt":1657541768192,"mc":[{"id":"1.200806927","rc":[{"atl":[[8.2,1042.27]],"id":2857977}]}]}
{"op":"mcm","clk":"ANLlsgkA3JekCgCbgqQK","pt":1657541768306,"mc":[{"id":"1.200806927","rc":[{"atb":[[1.15,0]],"id":228749}]}]}
{"op":"mcm","clk":"AIrmsgkAk5ikCgC3gqQK","pt":1657541768812,"mc":[{"id":"1.200806927","rc":[{"atl":[[6.6,148.94]],"trd":[[6.6,8.74]],"tv":7401.48,"id":2857977}],"tv":114843.33}]}
{"op":"mcm","clk":"AK7msgkAvZikCgDOgqQK","pt":1657541769191,"mc":[{"id":"1.200806927","rc":[{"atb":[[1.14,5.69]],"id":228749},{"atl":[[7.2,210.37]],"id":2857977}]}]}
{"op":"mcm","clk":"ALjmsgkAyJikCgDSgqQK","pt":1657541769297,"mc":[{"id":"1.200806927","rc":[{"trd":[[1.17,5344.39]],"tv":107551.04,"id":228749},{"atl":[[6.6,129.58]],"trd":[[6.6,28.1]],"tv":7420.84,"id":2857977}],"tv":114971.88}]}
{"op":"mcm","clk":"APnmsgkA+5ikCgD8gqQK","pt":1657541769945,"mc":[{"id":"1.200806927","rc":[{"atl":[[8.2,42.27]],"id":2857977}]}]}
{"op":"mcm","clk":"AJDnsgkApJmkCgCMg6QK","pt":1657541770301,"mc":[{"id":"1.200806927","rc":[{"trd":[[1.17,5398.49]],"tv":107605.14,"id":228749},{"atl":[[6.6,119.99]],"trd":[[6.6,37.69]],"tv":7430.43,"id":2857977}],"tv":115035.57}]}
{"op":"mcm","clk":"AL3nsgkAz5mkCgCeg6QK","pt":1657541770720,"mc":[{"id":"1.200806927","rc":[{"trd":[[1.17,5805.19]],"tv":108011.84,"id":228749},{"atl":[[6.6,47.89]],"trd":[[6.6,109.79]],"tv":7502.53,"id":2857977}],"tv":115514.37}]}
{"op":"mcm","clk":"ANnnsgkA7pmkCgCvg6QK","pt":1657541770991,"mc":[{"id":"1.200806927","rc":[{"atb":[[1.14,7.79]],"id":228749}]}]}
{"op":"mcm","clk":"AIXosgkAlJqkCgC8g6QK","pt":1657541771403,"mc":[{"id":"1.200806927","rc":[{"atl":[[1.18,0]],"trd":[[1.18,389.4]],"ltp":1.18,"tv":108023.42,"id":228749}],"tv":115525.95}]}
{"op":"mcm","clk":"AJrosgkAqpqkCgDFg6QK","pt":1657541771589,"mc":[{"id":"1.200806927","rc":[{"trd":[[1.17,5805.72]],"ltp":1.17,"tv":108023.95,"id":228749},{"atl":[[6.6,47.8]],"trd":[[6.6,109.88]],"tv":7502.62,"id":2857977}],"tv":115526.57}]}
{"op":"mcm","clk":"AIjpsgkAmZukCgCHhKQK","pt":1657541772818,"mc":[{"id":"1.200806927","rc":[{"atb":[[1.18,1200]],"id":228749}]}]}
{"op":"mcm","clk":"AJ/qsgkAmZykCgDrhKQK","pt":1657541774430,"mc":[{"id":"1.200806927","rc":[{"atb":[[1.2,1443.47]],"atl":[[1.2,0]],"trd":[[1.2,24.22]],"ltp":1.2,"tv":108025.01,"id":228749}],"tv":115527.63}]}
{"op":"mcm","clk":"AKbqsgkAqJykCgDyhKQK","pt":1657541774527,"mc":[{"id":"1.200806927","rc":[{"atl":[[7.2,0]],"id":2857977}]}]}
{"op":"mcm","clk":"AM7qsgkA1ZykCgCNhaQK","pt":1657541775000,"mc":[{"id":"1.200806927","rc":[{"atl":[[1.29,60.81]],"id":228749}]}]}
{"op":"mcm","clk":"APjqsgkA8pykCgCrhaQK","pt":1657541775407,"mc":[{"id":"1.200806927","rc":[{"atb":[[1.14,5.69],[1.2,1423.45]],"trd":[[1.2,64.26]],"tv":108065.05,"id":228749}],"tv":115567.67}]}
{"op":"mcm","clk":"AJnrsgkAmJ2kCgC/haQK","pt":1657541775730,"mc":[{"id":"1.200806927","rc":[{"atb":[[1.18,1700]],"id":228749}]}]}
{"op":"mcm","clk":"AK7rsgkAr52kCgDHhaQK","pt":1657541775940,"mc":[{"id":"1.200806927","rc":[{"atb":[[1.11,0]],"id":228749}]}]}
{"op":"mcm","clk":"ANjrsgkA2p2kCgDhhaQK","pt":1657541776306,"mc":[{"id":"1.200806927","rc":[{"atb":[[1.18,500]],"id":228749}]}]}
{"op":"mcm","clk":"AJrssgkAj56kCgD6haQK","pt":1657541776844,"mc":[{"id":"1.200806927","rc":[{"atb":[[1.18,0]],"id":228749}]}]}
{"op":"mcm","clk":"AMPssgkAsZ6kCgCPhqQK","pt":1657541777210,"mc":[{"id":"1.200806927","rc":[{"atb":[[1.18,0.85]],"id":228749}]}]}
{"op":"mcm","clk":"AIXusgkA6p+kCgCCh6QK","pt":1657541779098,"mc":[{"id":"1.200806927","rc":[{"atb":[[1.2,1422.4]],"trd":[[1.2,66.36]],"tv":108067.15,"id":228749}],"tv":115569.77}]}
{"op":"mcm","clk":"AJjusgkAhKCkCgCUh6QK","pt":1657541779328,"mc":[{"id":"1.200806927","rc":[{"atb":[[1.2,1419.77]],"trd":[[1.2,71.62]],"tv":108072.41,"id":228749}],"tv":115575.03}]}
{"op":"mcm","clk":"ALTusgkAoKCkCgCjh6QK","pt":1657541779639,"mc":[{"id":"1.200806927","rc":[{"atb":[[1.2,1418.19]],"trd":[[1.2,74.78]],"tv":108075.57,"id":228749}],"tv":115578.19}]}
{"op":"mcm","clk":"ALzusgkAqaCkCgCoh6QK","pt":1657541779741,"mc":[{"id":"1.200806927","rc":[{"atb":[[1.13,133.12]],"id":228749}]}]}
{"op":"mcm","clk":"AN3usgkAwqCkCgC2h6QK","pt":1657541779995,"mc":[{"id":"1.200806927","rc":[{"atb":[[1.2,1417.4]],"trd":[[1.2,76.36]],"tv":108077.15,"id":228749}],"tv":115579.77}]}
{"op":"mcm","clk":"ALnvsgkAjaGkCgDhh6QK","pt":1657541780841,"mc":[{"id":"1.200806927","rc":[{"atb":[[1.2,1391.1]],"trd":[[1.2,128.96]],"tv":108129.75,"id":228749}],"tv":115632.37}]}
{"op":"mcm","clk":"AMfvsgkAoqGkCgDqh6QK","pt":1657541781040,"mc":[{"id":"1.200806927","rc":[{"atb":[[1.18,45.93]],"id":228749}]}]}
{"op":"mcm","clk":"ANDvsgkArKGkCgDuh6QK","pt":1657541781109,"mc":[{"id":"1.200806927","rc":[{"atb":[[1.2,1388.47]],"trd":[[1.2,134.22]],"tv":108135.01,"id":228749}],"tv":115637.63}]}
{"op":"mcm","clk":"APjvsgkA1KGkCgCJiKQK","pt":1657541781536,"mc":[{"id":"1.200806927","rc":[{"atb":[[1.2,1385.82]],"trd":[[1.2,136.87]],"tv":108137.66,"id":228749},{"trd":[[6,1.24]],"ltp":6,"tv":7503.15,"id":2857977}],"tv":115640.81}]}
{"op":"mcm","clk":"AJrwsgkA/aGkCgChiKQK","pt":1657541781943,"mc":[{"id":"1.200806927","rc":[{"atb":[[1.2,0]],"id":228749}]}]}
{"op":"mcm","clk":"AP3wsgkA3KKkCgDgiKQK","pt":1657541782963,"mc":[{"id":"1.200806927","rc":[{"atb":[[1.18,43.34]],"trd":[[1.18,391.09]],"ltp":1.18,"tv":108139.35,"id":228749}],"tv":115642.5}]}
{"op":"mcm","clk":"AL3xsgkApKOkCgCFiaQK","pt":1657541783552,"mc":[{"id":"1.200806927","rc":[{"atl":[[8.2,44.84]],"id":2857977}]}]}
{"op":"mcm","clk":"AOjxsgkA06OkCgCaiaQK","pt":1657541783974,"mc":[{"id":"1.200806927","rc":[{"atb":[[1.21,499.61],[1.18,43.17]],"atl":[[1.21,0]],"trd":[[1.21,169.44],[1.18,391.44]],"ltp":1.21,"tv":108140.48,"id":228749}],"tv":115643.63}]}
{"op":"mcm","clk":"AI3ysgkA86OkCgCqiaQK","pt":1657541784230,"mc":[{"id":"1.200806927","rc":[{"atl":[[6.6,0]],"id":2857977}]}]}
{"op":"mcm","clk":"AM3ysgkAr6SkCgDHiaQK","pt":1657541784870,"mc":[{"id":"1.200806927","rc":[{"atb":[[1.21,0]],"id":228749}]}]}
{"op":"mcm","clk":"AO/0sgkAsqakCgDniqQK","pt":1657541787439,"mc":[{"id":"1.200806927","rc":[{"atl":[[1.2,0.72]],"id":228749}]}]}
{"op":"mcm","clk":"AKz1sgkAh6ekCgCTi6QK","pt":1657541788320,"mc":[{"id":"1.200806927","rc":[{"atl":[[1.28,52.59]],"id":228749}]}]}
{"op":"mcm","clk":"AMX1sgkAr6ekCgCoi6QK","pt":1657541788651,"mc":[{"id":"1.200806927","rc":[{"atl":[[1.27,26.3]],"id":228749}]}]}
{"op":"mcm","clk":"AOv1sgkA5qekCgDGi6QK","pt":1657541789176,"mc":[{"id":"1.200806927","rc":[{"atl":[[1.28,57.85]],"id":228749}]}]}
{"op":"mcm","clk":"AIb2sgkAg6ikCgDdi6QK","pt":1657541789527,"mc":[{"id":"1.200806927","rc":[{"atb":[[1.19,500]],"id":228749}]}]}
{"op":"mcm","clk":"AJ/2sgkAqaikCgDyi6QK","pt":1657541789842,"mc":[{"id":"1.200806927","rc":[{"atb":[[1.1,4]],"id":228749}]}]}
{"op":"mcm","clk":"AK72sgkAvqikCgD8i6QK","pt":1657541790059,"mc":[{"id":"1.200806927","rc":[{"atl":[[1.2,3.35]],"id":228749}]}]}
{"op":"mcm","clk":"AMP2sgkA1qikCgCHjKQK","pt":1657541790264,"mc":[{"id":"1.200806927","rc":[{"atl":[[1.28,83.59]],"id":228749}]}]}
{"op":"mcm","clk":"AMr2sgkA4qikCgCMjKQK","pt":1657541790369,"mc":[{"id":"1.200806927","rc":[{"atl":[[1.2,2.26]],"trd":[[1.2,137.96]],"ltp":1.2,"tv":108141.57,"id":228749},{"trd":[[6,1.46]],"tv":7503.37,"id":2857977}],"tv":115644.94}]}
{"op":"mcm","clk":"ANj2sgkA9aikCgCUjKQK","pt":1657541790544,"mc":[{"id":"1.200806927","rc":[{"atb":[[1.18,45.8]],"id":228749}]}]}
{"op":"mcm","clk":"AOf2sgkAjqmkCgCbjKQK","pt":1657541790765,"mc":[{"id":"1.200806927","rc":[{"atb":[[5.3,5.26]],"id":2857977}]}]}
{"op":"mcm","clk":"AI/3sgkAvamkCgCyjKQK","pt":1657541791286,"mc":[{"id":"1.200806927","rc":[{"atl":[[1.25,598]],"id":228749}]}]}
{"op":"mcm","clk":"AKf4sgkAvaqkCgDtjKQK","pt":1657541792619,"mc":[{"id":"1.200806927","rc":[{"atl":[[1.28,94.11]],"id":228749}]}]}
{"op":"mcm","clk":"ANL5sgkAvaukCgDJjaQK","pt":1657541793969,"mc":[{"id":"1.200806927","rc":[{"atl":[[1.2,2.79]],"id":228749}]}]}
{"op":"mcm","clk":"ANH6sgkA36ykCgCljqQK","pt":1657541795553,"mc":[{"id":"1.200806927","rc":[{"atb":[[1.19,499.89]],"trd":[[1.19,91.77]],"ltp":1.19,"tv":108141.78,"id":228749}],"tv":115645.15}]}
{"op":"mcm","clk":"AIb7sgkAj62kCgDBjqQK","pt":1657541796167,"mc":[{"id":"1.200806927","rc":[{"atb":[[1.18,2.63]],"id":228749}]}]}
{"op":"mcm","clk":"AOn7sgkA962kCgD2jqQK","pt":1657541797062,"mc":[{"id":"1.200806927","rc":[{"atb":[[1.14,0.43]],"id":228749}]}]}
{"op":"mcm","clk":"ALr8sgkAxK6kCgCbj6QK","pt":1657541797755,"mc":[{"id":"1.200806927","rc":[{"atb":[[1.19,346.28]],"trd":[[1.19,398.99]],"tv":108449,"id":228749}],"tv":115952.37}]}
{"op":"mcm","clk":"ANf8sgkA3a6kCgCqj6QK","pt":1657541798063,"mc":[{"id":"1.200806927","rc":[{"atb":[[1.05,200.59]],"id":228749}]}]}
{"op":"mcm","clk":"AOj8sgkA9K6kCgC2j6QK","pt":1657541798282,"mc":[{"id":"1.200806927","rc":[{"atb":[[1.02,156.03]],"id":228749}]}]}
{"op":"mcm","clk":"APv8sgkAi6+kCgDBj6QK","pt":1657541798471,"mc":[{"id":"1.200806927","rc":[{"atb":[[1.03,84.8]],"id":228749}]}]}
{"op":"mcm","clk":"AKT+sgkAorCkCgCmkKQK","pt":1657541800189,"mc":[{"id":"1.200806927","rc":[{"atb":[[1.19,0]],"id":228749}]}]}
{"op":"mcm","clk":"AND+sgkAyLCkCgDFkKQK","pt":1657541800669,"mc":[{"id":"1.200806927","rc":[{"atl":[[1.2,0.69]],"id":228749}]}]}
{"op":"mcm","clk":"AJuAswkArLKkCgDXkaQK","pt":1657541803073,"mc":[{"id":"1.200806927","rc":[{"atl":[[1.19,0.53]],"id":228749}]}]}
{"op":"mcm","clk":"AKeAswkAuLKkCgDekaQK","pt":1657541803175,"mc":[{"id":"1.200806927","rc":[{"atl":[[1.25,0]],"id":228749}]}]}
{"op":"mcm","clk":"ALGAswkAxbKkCgDhkaQK","pt":1657541803241,"mc":[{"id":"1.200806927","rc":[{"atl":[[1.24,124.33]],"id":228749}]}]}
{"op":"mcm","clk":"AL6AswkAzbKkCgDrkaQK","pt":1657541803348,"mc":[{"id":"1.200806927","rc":[{"atb":[[1.2,3.51]],"atl":[[1.19,0],[1.2,0]],"id":228749}]}]}
{"op":"mcm","clk":"AOSAswkA87KkCgCEkqQK","pt":1657541803763,"mc":[{"id":"1.200806927","rc":[{"atl":[[1.3,347.37]],"id":228749}]}]}
{"op":"mcm","clk":"AO6AswkA/7KkCgCLkqQK","pt":1657541803868,"mc":[{"id":"1.200806927","rc":[{"atb":[[1.2,4.04]],"id":228749}]}]}
{"op":"mcm","clk":"AImBswkAnrOkCgCekqQK","pt":1657541804176,"mc":[{"id":"1.200806927","rc":[{"atb":[[1.2,1.39]],"atl":[[1.28,41.52]],"trd":[[1.2,140.61]],"ltp":1.2,"tv":108451.65,"id":228749},{"trd":[[6,1.99]],"tv":7503.9,"id":2857977}],"tv":115955.55}]}
{"op":"mcm","clk":"AJWBswkArrOkCgClkqQK","pt":1657541804299,"mc":[{"id":"1.200806927","rc":[{"atl":[[1.29,8.22]],"id":228749}]}]}
{"op":"mcm","clk":"AKqBswkAybOkCgCtkqQK","pt":1657541804544,"mc":[{"id":"1.200806927","rc":[{"atb":[[1.2,0.34]],"id":228749}]}]}
{"op":"mcm","clk":"ALmBswkA4rOkCgC4kqQK","pt":1657541804789,"mc":[{"id":"1.200806927","rc":[{"atb":[[1.2,2524.89]],"id":228749}]}]}
{"op":"mcm","clk":"ANaBswkAirSkCgDLkqQK","pt":1657541805097,"mc":[{"id":"1.200806927","rc":[{"atb":[[1.2,1814.52]],"trd":[[1.2,1140.61]],"tv":109451.65,"id":228749}],"tv":116955.55}]}
{"op":"mcm","clk":"ANuBswkAjbSkCgDMkqQK","pt":1657541805140,"mc":[{"id":"1.200806927","rc":[{"atb":[[1.2,1825.57]],"id":228749}]}]}
{"op":"mcm","clk":"AKeCswkA6LSkCgCNk6QK","pt":1657541806050,"mc":[{"id":"1.200806927","rc":[{"atb":[[1.2,1829.88]],"atl":[[1.22,0.53]],"id":228749}]}]}
{"op":"mcm","clk":"AOOCswkArrWkCgC5k6QK","pt":1657541806777,"mc":[{"id":"1.200806927","rc":[{"atb":[[1.14,90.59]],"id":228749}]}]}
{"op":"mcm","clk":"APCCswkAxLWkCgDEk6QK","pt":1657541806974,"mc":[{"id":"1.200806927","rc":[{"atl":[[1.26,1.05]],"id":228749}]}]}
{"op":"mcm","clk":"APiCswkAz7WkCgDJk6QK","pt":1657541807082,"mc":[{"id":"1.200806927","rc":[{"atb":[[1.2,1827.25]],"id":228749}]}]}
{"op":"mcm","clk":"AJ2DswkA8rWkCgDlk6QK","pt":1657541807467,"mc":[{"id":"1.200806927","rc":[{"atb":[[1.2,1823.04]],"id":228749}]}]}
{"op":"mcm","clk":"AMCDswkAmLakCgD8k6QK","pt":1657541807907,"mc":[{"id":"1.200806927","rc":[{"atb":[[1.2,1822.93]],"trd":[[1.2,1140.83]],"tv":109451.87,"id":228749}],"tv":116955.77}]}
{"op":"mcm","clk":"AOSDswkAwLakCgCelKQK","pt":1657541808356,"mc":[{"id":"1.200806927","rc":[{"atb":[[1.2,1813.25]],"id":228749}]}]}
{"op":"mcm","clk":"APWDswkAzLakCgCslKQK","pt":1657541808551,"mc":[{"id":"1.200806927","rc":[{"atb":[[1.2,1811.74]],"trd":[[1.2,1143.85]],"tv":109454.89,"id":228749}],"tv":116958.79}]}
{"op":"mcm","clk":"AJCEswkA4bakCgC4lKQK","pt":1657541808785,"mc":[{"id":"1.200806927","rc":[{"atb":[[1.2,1810.66]],"trd":[[1.2,1146.01]],"tv":109457.05,"id":228749}],"tv":116960.95}]}
{"op":"mcm","clk":"AJiEswkA6bakCgC8lKQK","pt":1657541808874,"mc":[{"id":"1.200806927","rc":[{"atb":[[1.2,1805.82]],"trd":[[1.2,1147.07]],"tv":109458.11,"id":228749}],"tv":116962.01}]}
{"op":"mcm","clk":"AKCFswkA1rekCgCLlaQK","pt":1657541810188,"mc":[{"id":"1.200806927","rc":[{"atl":[[1.23,598]],"id":228749}]}]}
{"op":"mcm","clk":"AK+FswkA6bekCgCTlaQK","pt":1657541810333,"mc":[{"id":"1.200806927","rc":[{"atb":[[1.2,1806.35]],"id":228749}]}]}
{"op":"mcm","clk":"AJKGswkAyrikCgDIlaQK","pt":1657541811349,"mc":[{"id":"1.200806927","rc":[{"atb":[[1.2,1806.88]],"id":228749}]}]}
{"op":"mcm","clk":"AMKGswkA+LikCgD0laQK","pt":1657541811984,"mc":[{"id":"1.200806927","rc":[{"atb":[[1.2,1804.29]],"id":228749}]}]}
{"op":"mcm","clk":"AKqHswkA3rmkCgCslqQK","pt":1657541813170,"mc":[{"id":"1.200806927","rc":[{"atl":[[1.26,1.16]],"id":228749}]}]}
{"op":"mcm","clk":"AOeHswkAmLqkCgDSlqQK","pt":1657541813750,"mc":[{"id":"1.200806927","rc":[{"atb":[[1.05,200.41]],"atl":[[1.23,0]],"id":228749}]}]}
{"op":"mcm","clk":"APGHswkAo7qkCgDblqQK","pt":1657541813862,"mc":[{"id":"1.200806927","rc":[{"atb":[[5.3,0]],"id":2857977}]}]}
{"op":"mcm","clk":"AKiIswkA2rqkCgCGl6QK","pt":1657541814599,"mc":[{"id":"1.200806927","rc":[{"atl":[[9,0]],"id":2857977}]}]}
{"op":"mcm","clk":"ANWIswkAkLukCgCsl6QK","pt":1657541815163,"mc":[{"id":"1.200806927","rc":[{"atb":[[1.13,131.81]],"id":228749}]}]}
{"op":"mcm","clk":"AJCJswkAy7ukCgDMl6QK","pt":1657541815804,"mc":[{"id":"1.200806927","rc":[{"atb":[[1.2,1593.92]],"id":228749}]}]}
{"op":"mcm","clk":"AJiJswkA1LukCgDRl6QK","pt":1657541815905,"mc":[{"id":"1.200806927","rc":[{"atb":[[1.2,1593.39]],"trd":[[1.2,1147.6]],"tv":109458.64,"id":228749},{"trd":[[6,2.09]],"tv":7504,"id":2857977}],"tv":116962.64}]}
{"op":"mcm","clk":"APiJswkA1LykCgCGmKQK","pt":1657541817042,"mc":[{"id":"1.200806927","rc":[{"atb":[[1.2,1592.86]],"trd":[[1.2,1148.13]],"tv":109459.17,"id":228749},{"trd":[[6,2.2]],"tv":7504.11,"id":2857977}],"tv":116963.28}]}
{"op":"mcm","clk":"AL6KswkAob2kCgDBmKQK","pt":1657541817795,"mc":[{"id":"1.200806927","rc":[{"atb":[[1.2,1591.13]],"trd":[[1.2,1151.59]],"tv":109462.63,"id":228749}],"tv":116966.74}]}
{"op":"mcm","clk":"APOKswkA0L2kCgDnmKQK","pt":1657541818279,"mc":[{"id":"1.200806927","rc":[{"atb":[[1.2,1585.87]],"id":228749}]}]}
{"op":"mcm","clk":"AIeLswkA372kCgDumKQK","pt":1657541818486,"mc":[{"id":"1.200806927","rc":[{"atl":[[1.23,0.65]],"id":228749}]}]}
{"op":"mcm","clk":"AJ+LswkAgL6kCgCImaQK","pt":1657541818692,"mc":[{"id":"1.200806927","rc":[{"atl":[[1.42,5.26]],"id":228749}]}]}
{"op":"mcm","clk":"AKuLswkAh76kCgCPmaQK","pt":1657541818803,"mc":[{"id":"1.200806927","rc":[{"atl":[[1.39,52.59]],"id":228749}]}]}
{"op":"mcm","clk":"ALuLswkAnr6kCgCZmaQK","pt":1657541819011,"mc":[{"id":"1.200806927","rc":[{"atl":[[1.22,0],[1.23,0.13]],"trd":[[1.23,748.17]],"ltp":1.23,"tv":109463.67,"id":228749}],"tv":116967.78}]}
{"op":"mcm","clk":"ALqMswkAlr+kCgDPmaQK","pt":1657541820211,"mc":[{"id":"1.200806927","rc":[{"atb":[[1.2,1582.77]],"trd":[[1.2,1154.16]],"ltp":1.2,"tv":109466.24,"id":228749},{"trd":[[6,2.71]],"tv":7504.62,"id":2857977}],"tv":116970.86}]}
{"op":"mcm","clk":"AOSMswkAxb+kCgDqmaQK","pt":1657541820705,"mc":[{"id":"1.200806927","rc":[{"atb":[[1.2,1580.79]],"atl":[[1.23,0]],"trd":[[1.23,748.3],[1.2,1158.12]],"ltp":1.23,"tv":109470.33,"id":228749},{"atl":[[5.3,0.08]],"trd":[[5.3,16.33]],"ltp":5.3,"tv":7504.65,"id":2857977}],"tv":116974.98}]}
{"op":"mcm","clk":"AImNswkA97+kCgCEmqQK","pt":1657541821209,"mc":[{"id":"1.200806927","rc":[{"atl":[[1.22,2.92]],"trd":[[1.23,748.63]],"tv":109470.66,"id":228749},{"atl":[[5.3,0]],"trd":[[5.3,16.4]],"tv":7504.72,"id":2857977}],"tv":116975.38}]}
{"op":"mcm","clk":"AKSNswkAmMCkCgCRmqQK","pt":1657541821497,"mc":[{"id":"1.200806927","rc":[{"atb":[[1.2,1579.15]],"trd":[[1.2,1161.4]],"ltp":1.2,"tv":109473.94,"id":228749}],"tv":116978.66}]}
{"op":"mcm","clk":"ALuNswkAscCkCgCdmqQK","pt":1657541821818,"mc":[{"id":"1.200806927","rc":[{"atb":[[1.2,1578.1]],"id":228749}]}]}
{"op":"mcm","clk":"ANONswkAyMCkCgCnmqQK","pt":1657541822091,"mc":[{"id":"1.200806927","rc":[{"atb":[[1.23,23.38]],"atl":[[1.22,0]],"id":228749}]}]}
{"op":"mcm","clk":"AO6NswkA68CkCgC1mqQK","pt":1657541822382,"mc":[{"id":"1.200806927","rc":[{"atl":[[5.3,0.53]],"id":2857977}]}]}
{"op":"mcm","clk":"AJqOswkAkMGkCgDFmqQK","pt":1657541822798,"mc":[{"id":"1.200806927","rc":[{"atl":[[5.3,0.64]],"id":2857977}]}]}
{"op":"mcm","clk":"AOOOswkA1MGkCgDpmqQK","pt":1657541823536,"mc":[{"id":"1.200806927","rc":[{"atl":[[8.2,42.27]],"id":2857977}]}]}
{"op":"mcm","clk":"AJOPswkAlMKkCgCHm6QK","pt":1657541824104,"mc":[{"id":"1.200806927","rc":[{"atb":[[1.23,21.8]],"id":228749}]}]}
{"op":"mcm","clk":"AKWPswkAosKkCgCRm6QK","pt":1657541824295,"mc":[{"id":"1.200806927","rc":[{"atb":[[1.23,0],[1.2,352.64]],"atl":[[1.28,46.78]],"trd":[[1.23,794.97],[1.2,3612.32]],"tv":111971.2,"id":228749},{"atl":[[5.3,0]],"trd":[[5.3,17.04]],"tv":7505.36,"id":2857977}],"tv":119476.56}]}
{"op":"mcm","clk":"AIqQswkAgcOkCgDLm6QK","pt":1657541825306,"mc":[{"id":"1.200806927","rc":[{"atb":[[1.2,352.11]],"id":228749}]}]}
{"op":"mcm","clk":"ALOQswkArcOkCgDmm6QK","pt":1657541825863,"mc":[{"id":"1.200806927","rc":[{"atb":[[1.2,141.74]],"id":228749}]}]}
{"op":"mcm","clk":"AOWQswkA78OkCgCPnKQK","pt":1657541826615,"mc":[{"id":"1.200806927","rc":[{"atl":[[1.24,123.88]],"trd":[[1.24,1622.01]],"ltp":1.24,"tv":111971.66,"id":228749},{"trd":[[5.1,2.36]],"ltp":5.1,"tv":7505.47,"id":2857977}],"tv":119477.13}]}
{"op":"mcm","clk":"AOyQswkA+cOkCgCUnKQK","pt":1657541826710,"mc":[{"id":"1.200806927","rc":[{"atb":[[1.2,139.11]],"id":228749}]}]}
{"op":"mcm","clk":"AK+RswkAtcSkCgC4nKQK","pt":1657541827499,"mc":[{"id":"1.200806927","rc":[{"atl":[[1.95,26.43]],"id":228749}]}]}
{"op":"mcm","clk":"APmSswkAiMakCgC7naQK","pt":1657541829920,"mc":[{"id":"1.200806927","rc":[{"atb":[[1.2,138.58]],"id":228749}]}]}
{"op":"mcm","clk":"AKGTswkAtsakCgDUnaQK","pt":1657541830325,"mc":[{"id":"1.200806927","rc":[{"atb":[[1.2,112.28]],"id":228749}]}]}
{"op":"mcm","clk":"AOKTswkA9MakCgDsnaQK","pt":1657541831000,"mc":[{"id":"1.200806927","rc":[{"atb":[[1.2,111.75]],"atl":[[1.23,210.37]],"id":228749}]}]}
{"op":"mcm","clk":"AJ6UswkAy8ekCgCOnqQK","pt":1657541831734,"mc":[{"id":"1.200806927","rc":[{"atl":[[1.23,207.74]],"id":228749}]}]}
{"op":"mcm","clk":"ALuUswkA78ekCgCfnqQK","pt":1657541832094,"mc":[{"id":"1.200806927","rc":[{"atl":[[1.23,181.44]],"id":228749}]}]}
{"op":"mcm","clk":"AM+UswkAjMikCgCrnqQK","pt":1657541832411,"mc":[{"id":"1.200806927","rc":[{"atb":[[1.22,0.11]],"id":228749}]}]}
{"op":"mcm","clk":"AN+UswkAncikCgC1nqQK","pt":1657541832610,"mc":[{"id":"1.200806927","rc":[{"atl":[[1.26,1.5]],"id":228749}]}]}
{"op":"mcm","clk":"AImVswkA0MikCgDNnqQK","pt":1657541833125,"mc":[{"id":"1.200806927","rc":[{"atl":[[1.23,180.98]],"trd":[[1.23,795.43]],"ltp":1.23,"tv":111972.12,"id":228749},{"trd":[[5.3,17.15]],"ltp":5.3,"tv":7505.58,"id":2857977}],"tv":119477.7}]}
{"op":"mcm","clk":"AJKVswkA2sikCgDSnqQK","pt":1657541833232,"mc":[{"id":"1.200806927","rc":[{"atl":[[1.23,178.35]],"id":228749}]}]}
{"op":"mcm","clk":"AKmVswkA7sikCgDenqQK","pt":1657541833422,"mc":[{"id":"1.200806927","rc":[{"atl":[[1.23,178.48]],"id":228749}]}]}
{"op":"mcm","clk":"AOiVswkAqcmkCgCMn6QK","pt":1657541834105,"mc":[{"id":"1.200806927","rc":[{"atl":[[1.23,173.65]],"id":228749}]}]}
{"op":"mcm","clk":"AKaWswkA+smkCgC8n6QK","pt":1657541834846,"mc":[{"id":"1.200806927","rc":[{"atb":[[5.2,5.26]],"id":2857977}]}]}
{"op":"mcm","clk":"ALaWswkAj8qkCgDFn6QK","pt":1657541835049,"mc":[{"id":"1.200806927","rc":[{"atb":[[1.24,582.03]],"atl":[[1.24,0],[1.23,0]],"trd":[[1.24,1891.82],[1.23,795.68]],"ltp":1.24,"tv":112242.18,"id":228749},{"atb":[[5.2,0]],"trd":[[5.2,55.94]],"ltp":5.2,"tv":7510.84,"id":2857977}],"tv":119753.02}]}
{"op":"mcm","clk":"ANuWswkAyMqkCgDbn6QK","pt":1657541835536,"mc":[{"id":"1.200806927","rc":[{"atb":[[1.24,564.15]],"id":228749}]}]}
{"op":"mcm","clk":"ALCXswkAo8ukCgCKoKQK","pt":1657541836317,"mc":[{"id":"1.200806927","rc":[{"atb":[[1.24,353.78]],"id":228749}]}]}
{"op":"mcm","clk":"ALiXswkArcukCgCPoKQK","pt":1657541836417,"mc":[{"id":"1.200806927","rc":[{"atb":[[1.24,352.2]],"id":228749}]}]}
{"op":"mcm","clk":"AL6YswkAzcykCgDnoKQK","pt":1657541837845,"mc":[{"id":"1.200806927","rc":[{"atb":[[1.24,352]],"trd":[[1.24,1892.22]],"tv":112242.58,"id":228749}],"tv":119753.42}]}
{"op":"mcm","clk":"ANqYswkA6MykCgD9oKQK","pt":1657541838152,"mc":[{"id":"1.200806927","rc":[{"atb":[[1.24,351.47]],"id":228749}]}]}
{"op":"mcm","clk":"APCYswkAh82kCgCKoaQK","pt":1657541838423,"mc":[{"id":"1.200806927","rc":[{"atl":[[1.28,21.04]],"id":228749}]}]}
{"op":"mcm","clk":"ALiZswkAy82kCgC5oaQK","pt":1657541839349,"mc":[{"id":"1.200806927","rc":[{"atb":[[1.2,101.23]],"id":228749}]}]}
{"op":"mcm","clk":"AL+ZswkA1s2kCgC+oaQK","pt":1657541839429,"mc":[{"id":"1.200806927","rc":[{"atb":[[1.12,0]],"id":228749}]}]}
{"op":"mcm","clk":"AOSZswkA9M2kCgDPoaQK","pt":1657541839731,"mc":[{"id":"1.200806927","rc":[{"atb":[[1.24,347.47]],"id":228749}]}]}
{"op":"mcm","clk":"AJCaswkAnc6kCgD4oaQK","pt":1657541840246,"mc":[{"id":"1.200806927","rc":[{"atb":[[1.1,55.48]],"id":228749}]}]}
{"op":"mcm","clk":"AMuaswkAyc6kCgCZoqQK","pt":1657541840835,"mc":[{"id":"1.200806927","rc":[{"atl":[[1.28,15.78]],"id":228749}]}]}
{"op":"mcm","clk":"ALOcswkAvtCkCgCjo6QK","pt":1657541843564,"mc":[{"id":"1.200806927","rc":[{"atb":[[1.24,340.86]],"trd":[[1.24,1905.45]],"tv":112255.81,"id":228749}],"tv":119766.65}]}
{"op":"mcm","clk":"AMKcswkA0tCkCgCvo6QK","pt":1657541843752,"mc":[{"id":"1.200806927","rc":[{"atb":[[1.24,130.49]],"id":228749}]}]}
{"op":"mcm","clk":"ANqcswkA5tCkCgC5o6QK","pt":1657541843952,"mc":[{"id":"1.200806927","rc":[{"atb":[[1.24,124.55]],"trd":[[1.24,1908.76]],"tv":112259.12,"id":228749},{"trd":[[5.2,56.73]],"tv":7511.63,"id":2857977}],"tv":119770.75}]}
{"op":"mcm","clk":"ANucswkA69CkCgC7o6QK","pt":1657541844007,"mc":[{"id":"1.200806927","rc":[{"atl":[[5.3,0.53]],"id":2857977}]}]}
{"op":"mcm","clk":"APacswkAgdGkCgDHo6QK","pt":1657541844313,"mc":[{"id":"1.200806927","rc":[{"atl":[[5.3,1.06]],"id":2857977}]}]}
{"op":"mcm","clk":"AImdswkAltGkCgDSo6QK","pt":1657541844530,"mc":[{"id":"1.200806927","rc":[{"atb":[[1.24,129.81]],"id":228749}]}]}
{"op":"mcm","clk":"AL2dswkAytGkCgD0o6QK","pt":1657541845161,"mc":[{"id":"1.200806927","rc":[{"atb":[[1.15,45.08]],"id":228749}]}]}
{"op":"mcm","clk":"APWdswkA9tGkCgCVpKQK","pt":1657541845725,"mc":[{"id":"1.200806927","rc":[{"atb":[[1.24,127.59]],"trd":[[1.24,1910.98]],"tv":112261.34,"id":228749},{"trd":[[5.2,57.26]],"tv":7512.16,"id":2857977}],"tv":119773.5}]}
{"op":"mcm","clk":"AJ+eswkAp9KkCgCzpKQK","pt":1657541846361,"mc":[{"id":"1.200806927","rc":[{"atb":[[1.23,5.61]],"id":228749}]}]}
{"op":"mcm","clk":"ANKeswkA1tKkCgDSpKQK","pt":1657541846925,"mc":[{"id":"1.200806927","rc":[{"atb":[[1.24,127.06]],"id":228749}]}]}
{"op":"mcm","clk":"AOqeswkA7dKkCgDhpKQK","pt":1657541847249,"mc":[{"id":"1.200806927","rc":[{"atb":[[1.24,126.53]],"id":228749}]}]}
{"op":"mcm","clk":"APieswkA+dKkCgDppKQK","pt":1657541847444,"mc":[{"id":"1.200806927","rc":[{"atb":[[1.2,1.59]],"id":228749}]}]}
{"op":"mcm","clk":"AJ+fswkAotOkCgD7pKQK","pt":1657541847914,"mc":[{"id":"1.200806927","rc":[{"atb":[[1.24,113]],"atl":[[1.26,0],[1.27,22.54]],"trd":[[1.26,680.03]],"ltp":1.26,"tv":112262.25,"id":228749}],"tv":119774.41}]}
{"op":"mcm","clk":"AKefswkArNOkCgD+pKQK","pt":1657541848010,"mc":[{"id":"1.200806927","rc":[{"atb":[[1.24,86.7]],"id":228749}]}]}
{"op":"mcm","clk":"ALqfswkAwdOkCgCQpaQK","pt":1657541848338,"mc":[{"id":"1.200806927","rc":[{"atb":[[1.24,84.07]],"id":228749}]}]}
{"op":"mcm","clk":"AMGfswkAytOkCgCSpaQK","pt":1657541848439,"mc":[{"id":"1.200806927","rc":[{"atb":[[1.24,0],[1.23,5.08]],"atl":[[1.24,496.18]],"trd":[[1.23,796.74]],"ltp":1.23,"tv":112263.31,"id":228749}],"tv":119775.47}]}
{"op":"mcm","clk":"AN+fswkA7tOkCgClpaQK","pt":1657541848845,"mc":[{"id":"1.200806927","rc":[{"atl":[[5.3,0.53]],"id":2857977}]}]}
{"op":"mcm","clk":"AOWfswkA+NOkCgCspaQK","pt":1657541848965,"mc":[{"id":"1.200806927","rc":[{"atl":[[1.3,346.51]],"id":228749}]}]}
{"op":"mcm","clk":"AO+fswkAgNSkCgCzpaQK","pt":1657541849047,"mc":[{"id":"1.200806927","rc":[{"atl":[[1.24,496.7]],"id":228749}]}]}
{"op":"mcm","clk":"AIGgswkAj9SkCgC8paQK","pt":1657541849217,"mc":[{"id":"1.200806927","rc":[{"atl":[[1.24,499.29]],"id":228749}]}]}
{"op":"mcm","clk":"AJGgswkAntSkCgDFpaQK","pt":1657541849427,"mc":[{"id":"1.200806927","rc":[{"atl":[[1.24,504.55]],"id":228749}]}]}
{"op":"mcm","clk":"AJqgswkAqNSkCgDNpaQK","pt":1657541849538,"mc":[{"id":"1.200806927","rc":[{"atl":[[1.24,517.17]],"id":228749}]}]}
{"op":"mcm","clk":"ALigswkAv9SkCgDjpaQK","pt":1657541849861,"mc":[{"id":"1.200806927","rc":[{"atl":[[1.24,517.7]],"id":228749}]}]}
{"op":"mcm","clk":"AMGgswkAy9SkCgDppaQK","pt":1657541849976,"mc":[{"id":"1.200806927","rc":[{"atl":[[1.24,520.33]],"id":228749}]}]}
{"op":"mcm","clk":"AM+gswkA2NSkCgDypaQK","pt":1657541850146,"mc":[{"id":"1.200806927","rc":[{"atl":[[5.3,0]],"id":2857977}]}]}
{"op":"mcm","clk":"ANSgswkA5NSkCgD8paQK","pt":1657541850290,"mc":[{"id":"1.200806927","rc":[{"atl":[[1.24,521.19]],"id":228749}]}]}
{"op":"mcm","clk":"ANqgswkA6dSkCgCFpqQK","pt":1657541850350,"mc":[{"id":"1.200806927","rc":[{"atl":[[1.24,531.19]],"id":228749}]}]}
{"op":"mcm","clk":"AO6gswkAhNWkCgCWpqQK","pt":1657541850628,"mc":[{"id":"1.200806927","rc":[{"atb":[[1.15,255.4]],"id":228749}]}]}
{"op":"mcm","clk":"AIahswkAnNWkCgCkpqQK","pt":1657541850934,"mc":[{"id":"1.200806927","rc":[{"atl":[[1.24,982]],"id":228749}]}]}
{"op":"mcm","clk":"AKmhswkAs9WkCgC8pqQK","pt":1657541851343,"mc":[{"id":"1.200806927","rc":[{"atl":[[1.24,982.53]],"id":228749}]}]}
{"op":"mcm","clk":"AL2hswkAxdWkCgDGpqQK","pt":1657541851550,"mc":[{"id":"1.200806927","rc":[{"atl":[[1.26,10.52]],"id":228749}]}]}
{"op":"mcm","clk":"AN2hswkA6NWkCgDYpqQK","pt":1657541851918,"mc":[{"id":"1.200806927","rc":[{"atl":[[1.24,985.16]],"id":228749}]}]}
{"op":"mcm","clk":"APyhswkA/9WkCgDkpqQK","pt":1657541852232,"mc":[{"id":"1.200806927","rc":[{"atb":[[1.21,124.33]],"atl":[[1.24,995.46]],"id":228749}]}]}
{"op":"mcm","clk":"AIWiswkAjNakCgDtpqQK","pt":1657541852352,"mc":[{"id":"1.200806927","rc":[{"atl":[[1.24,1205.83]],"id":228749}]}]}
{"op":"mcm","clk":"AIqiswkAkNakCgDwpqQK","pt":1657541852441,"mc":[{"id":"1.200806927","rc":[{"atl":[[1.24,1413.99]],"id":228749}]}]}
{"op":"mcm","clk":"AJyiswkAodakCgD9pqQK","pt":1657541852646,"mc":[{"id":"1.200806927","rc":[{"atl":[[1.24,1414.1]],"id":228749}]}]}
{"op":"mcm","clk":"AKuiswkAptakCgCAp6QK","pt":1657541852736,"mc":[{"id":"1.200806927","rc":[{"atl":[[1.24,1424.62]],"id":228749}]}]}
{"op":"mcm","clk":"ALiiswkAsdakCgCGp6QK","pt":1657541852862,"mc":[{"id":"1.200806927","rc":[{"atb":[[5.2,0.53]],"id":2857977}]}]}
{"op":"mcm","clk":"AN+iswkA3dakCgChp6QK","pt":1657541853435,"mc":[{"id":"1.200806927","rc":[{"atl":[[1.24,1448.02]],"id":228749}]}]}
{"op":"mcm","clk":"APyiswkA/NakCgC1p6QK","pt":1657541853849,"mc":[{"id":"1.200806927","rc":[{"atl":[[1.24,1452.75]],"id":228749}]}]}
{"op":"mcm","clk":"AJyjswkAltekCgDGp6QK","pt":1657541854245,"mc":[{"id":"1.200806927","rc":[{"atl":[[1.28,41.52]],"id":228749}]}]}
{"op":"mcm","clk":"AKWjswkAndekCgDNp6QK","pt":1657541854358,"mc":[{"id":"1.200806927","rc":[{"atl":[[1.24,2053.86]],"id":228749}]}]}
{"op":"mcm","clk":"ANujswkAxdekCgDyp6QK","pt":1657541855043,"mc":[{"id":"1.200806927","rc":[{"atl":[[1.24,2057.02]],"id":228749}]}]}
{"op":"mcm","clk":"AOajswkAztekCgD5p6QK","pt":1657541855147,"mc":[{"id":"1.200806927","rc":[{"atb":[[1.23,0]],"atl":[[1.23,205.29]],"trd":[[1.23,806.9]],"tv":112273.47,"id":228749}],"tv":119785.63}]}
{"op":"mcm","clk":"AO+jswkA1NekCgD8p6QK","pt":1657541855252,"mc":[{"id":"1.200806927","rc":[{"atb":[[1.14,0.43]],"id":228749}]}]}
{"op":"mcm","clk":"APmjswkA4NekCgCEqKQK","pt":1657541855358,"mc":[{"id":"1.200806927","rc":[{"atl":[[1.23,204.43]],"trd":[[1.23,807.76]],"tv":112274.33,"id":228749},{"trd":[[5.3,17.35]],"ltp":5.3,"tv":7512.36,"id":2857977}],"tv":119786.69}]}
{"op":"mcm","clk":"AI6kswkA+9ekCgCeqKQK","pt":1657541855726,"mc":[{"id":"1.200806927","rc":[{"atl":[[1.24,2033.62]],"id":228749}]}]}
{"op":"mcm","clk":"AKqkswkAk9ikCgCrqKQK","pt":1657541856041,"mc":[{"id":"1.200806927","rc":[{"atl":[[1.24,2035.72]],"id":228749}]}]}
{"op":"mcm","clk":"AL6kswkApdikCgC4qKQK","pt":1657541856258,"mc":[{"id":"1.200806927","rc":[{"atl":[[1.23,161.34]],"trd":[[1.23,850.85]],"tv":112317.42,"id":228749},{"trd":[[5.3,27.35]],"tv":7522.36,"id":2857977}],"tv":119839.78}]}
{"op":"mcm","clk":"AMOkswkAq9ikCgC9qKQK","pt":1657541856353,"mc":[{"id":"1.200806927","rc":[{"atb":[[1.21,0]],"atl":[[1.24,2036.77],[1.55,0]],"id":228749}]}]}
{"op":"mcm","clk":"AMukswkAtNikCgDDqKQK","pt":1657541856455,"mc":[{"id":"1.200806927","rc":[{"atl":[[1.23,160.81]],"id":228749}]}]}
{"op":"mcm","clk":"ANekswkAvNikCgDNqKQK","pt":1657541856577,"mc":[{"id":"1.200806927","rc":[{"atl":[[1.24,1829.66]],"id":228749}]}]}
{"op":"mcm","clk":"AIKlswkA19ikCgDrqKQK","pt":1657541857049,"mc":[{"id":"1.200806927","rc":[{"atl":[[1.24,1832.24]],"id":228749}]}]}
{"op":"mcm","clk":"AJqlswkA69ikCgDyqKQK","pt":1657541857254,"mc":[{"id":"1.200806927","rc":[{"atl":[[1.23,149.72]],"trd":[[1.23,861.94]],"tv":112328.51,"id":228749},{"trd":[[5.3,29.92]],"tv":7524.93,"id":2857977}],"tv":119853.44}]}
{"op":"mcm","clk":"AKGlswkA79ikCgD2qKQK","pt":1657541857344,"mc":[{"id":"1.200806927","rc":[{"atl":[[1.24,1832.77]],"id":228749}]}]}
{"op":"mcm","clk":"AMalswkAitmkCgCEqaQK","pt":1657541857759,"mc":[{"id":"1.200806927","rc":[{"atl":[[1.24,1833.3]],"id":228749}]}]}
{"op":"mcm","clk":"AISmswkAvNmkCgClqaQK","pt":1657541858356,"mc":[{"id":"1.200806927","rc":[{"atl":[[1.23,148.43]],"trd":[[1.23,864.53]],"tv":112331.1,"id":228749}],"tv":119856.03}]}
{"op":"mcm","clk":"AJWmswkAzNmkCgCxqaQK","pt":1657541858554,"mc":[{"id":"1.200806927","rc":[{"atl":[[1.23,143.17]],"id":228749}]}]}
{"op":"mcm","clk":"ANOmswkAitqkCgDXqaQK","pt":1657541859381,"mc":[{"id":"1.200806927","rc":[{"atl":[[1.24,1232.19]],"id":228749}]}]}
{"op":"mcm","clk":"AOCmswkAltqkCgDeqaQK","pt":1657541859531,"mc":[{"id":"1.200806927","rc":[{"atl":[[1.24,1230.09]],"id":228749}]}]}
{"op":"mcm","clk":"APmmswkAqNqkCgDoqaQK","pt":1657541859745,"mc":[{"id":"1.200806927","rc":[{"atl":[[1.23,140.54]],"id":228749}]}]}
{"op":"mcm","clk":"AKKnswkAztqkCgCCqqQK","pt":1657541860267,"mc":[{"id":"1.200806927","rc":[{"atl":[[1.24,1229.04]],"id":228749}]}]}
{"op":"mcm","clk":"AKinswkA0tqkCgCIqqQK","pt":1657541860350,"mc":[{"id":"1.200806927","rc":[{"atl":[[1.24,1226.41]],"id":228749}]}]}
{"op":"mcm","clk":"AOWnswkA/dqkCgCyqqQK","pt":1657541860968,"mc":[{"id":"1.200806927","rc":[{"atl":[[1.23,350.91]],"id":228749}]}]}
{"op":"mcm","clk":"AICoswkAmNukCgDKqqQK","pt":1657541861340,"mc":[{"id":"1.200806927","rc":[{"atl":[[1.23,332.5]],"id":228749}]}]}
{"op":"mcm","clk":"AIuoswkAo9ukCgDOqqQK","pt":1657541861449,"mc":[{"id":"1.200806927","rc":[{"atb":[[1.17,124.33]],"id":228749}]}]}
{"op":"mcm","clk":"ALCoswkAytukCgDoqqQK","pt":1657541861879,"mc":[{"id":"1.200806927","rc":[{"atl":[[1.24,1226.94]],"id":228749}]}]}
{"op":"mcm","clk":"AOaoswkA69ukCgCRq6QK","pt":1657541862455,"mc":[{"id":"1.200806927","rc":[{"atl":[[1.23,332.72]],"id":228749}]}]}
{"op":"mcm","clk":"AO2oswkA+dukCgCYq6QK","pt":1657541862561,"mc":[{"id":"1.200806927","rc":[{"atl":[[1.23,334.07]],"id":228749}]}]}
{"op":"mcm","clk":"AKipswkAodykCgDHq6QK","pt":1657541863274,"mc":[{"id":"1.200806927","rc":[{"atl":[[1.24,1226.41]],"id":228749}]}]}
{"op":"mcm","clk":"ALSpswkAqtykCgDMq6QK","pt":1657541863375,"mc":[{"id":"1.200806927","rc":[{"atl":[[1.23,333.32]],"trd":[[1.23,865.28]],"tv":112331.85,"id":228749},{"trd":[[5.3,30.09]],"tv":7525.1,"id":2857977}],"tv":119856.95}]}
{"op":"mcm","clk":"AI+qswkA9NykCgCCrKQK","pt":1657541864173,"mc":[{"id":"1.200806927","rc":[{"atl":[[1.24,1227.04]],"id":228749}]}]}
{"op":"mcm","clk":"AK6qswkAjN2kCgCMrKQK","pt":1657541864481,"mc":[{"id":"1.200806927","rc":[{"atl":[[1.23,332.79]],"id":228749}]}]}
{"op":"mcm","clk":"ANuqswkAvN2kCgCzrKQK","pt":1657541865057,"mc":[{"id":"1.200806927","rc":[{"atl":[[1.23,297.8]],"trd":[[1.23,900.27]],"tv":112366.84,"id":228749},{"trd":[[5.3,38.21]],"tv":7533.22,"id":2857977}],"tv":119900.06}]}
{"op":"mcm","clk":"AOGqswkAx92kCgC9rKQK","pt":1657541865164,"mc":[{"id":"1.200806927","rc":[{"atl":[[1.24,1097.6],[1.3,346.62]],"id":228749}]}]}
{"op":"mcm","clk":"APSqswkAz92kCgDIrKQK","pt":1657541865364,"mc":[{"id":"1.200806927","rc":[{"atb":[[5.2,0]],"id":2857977}]}]}
{"op":"mcm","clk":"AJGrswkA492kCgDWrKQK","pt":1657541865668,"mc":[{"id":"1.200806927","rc":[{"atl":[[1.23,299.95]],"id":228749}]}]}
{"op":"mcm","clk":"ALerswkAht6kCgDvrKQK","pt":1657541866069,"mc":[{"id":"1.200806927","rc":[{"atb":[[1.19,10.52]],"id":228749}]}]}
{"op":"mcm","clk":"AOGrswkArN6kCgCNraQK","pt":1657541866594,"mc":[{"id":"1.200806927","rc":[{"atb":[[1.22,0]],"atl":[[1.22,68.89]],"trd":[[1.22,875.85]],"ltp":1.22,"tv":112367.06,"id":228749}],"tv":119900.28}]}
{"op":"mcm","clk":"AIGsswkAzd6kCgCwraQK","pt":1657541867050,"mc":[{"id":"1.200806927","rc":[{"atl":[[1.24,1094.44],[1.22,66.5]],"trd":[[1.22,878.24]],"tv":112369.45,"id":228749},{"trd":[[5.5,4.2]],"ltp":5.5,"tv":7533.75,"id":2857977}],"tv":119903.2}]}
{"op":"mcm","clk":"ALmsswkAn9+kCgDWraQK","pt":1657541867982,"mc":[{"id":"1.200806927","rc":[{"atl":[[1.24,1091.81]],"id":228749}]}]}
{"op":"mcm","clk":"AMusswkAst+kCgDjraQK","pt":1657541868235,"mc":[{"id":"1.200806927","rc":[{"atl":[[1.22,63.87]],"trd":[[1.22,883.5]],"tv":112374.71,"id":228749}],"tv":119908.46}]}
{"op":"mcm","clk":"ANqsswkAvN+kCgDoraQK","pt":1657541868359,"mc":[{"id":"1.200806927","rc":[{"atl":[[1.23,300.64]],"id":228749}]}]}
{"op":"mcm","clk":"AO+sswkA1N+kCgD8raQK","pt":1657541868668,"mc":[{"id":"1.200806927","rc":[{"atl":[[1.22,63.09]],"trd":[[1.22,884.28]],"tv":112375.49,"id":228749},{"trd":[[5.5,4.38]],"tv":7533.93,"id":2857977}],"tv":119909.42}]}
{"op":"mcm","clk":"ALCtswkAkuCkCgCtrqQK","pt":1657541869579,"mc":[{"id":"1.200806927","rc":[{"atl":[[1.23,310.2]],"id":228749}]}]}
{"op":"mcm","clk":"AMatswkApOCkCgC6rqQK","pt":1657541869841,"mc":[{"id":"1.200806927","rc":[{"atl":[[1.24,1091.71]],"id":228749}]}]}
{"op":"mcm","clk":"AOitswkAyuCkCgDPrqQK","pt":1657541870371,"mc":[{"id":"1.200806927","rc":[{"atl":[[1.22,59.28],[1.23,309.98]],"trd":[[1.22,888.09]],"tv":112379.3,"id":228749},{"trd":[[5.5,5.22]],"tv":7534.77,"id":2857977}],"tv":119914.07}]}
{"op":"mcm","clk":"ANWuswkAreGkCgCHr6QK","pt":1657541871769,"mc":[{"id":"1.200806927","rc":[{"atl":[[1.24,1081.72]],"id":228749}]}]}
{"op":"mcm","clk":"ANmuswkAteGkCgCMr6QK","pt":1657541871871,"mc":[{"id":"1.200806927","rc":[{"atb":[[1.19,6.85],[1.2,0]],"id":228749}]}]}
{"op":"mcm","clk":"AO6uswkAw+GkCgCer6QK","pt":1657541872174,"mc":[{"id":"1.200806927","rc":[{"atb":[[1.19,4.22]],"id":228749}]}]}
{"op":"mcm","clk":"APyuswkA0OGkCgCnr6QK","pt":1657541872384,"mc":[{"id":"1.200806927","rc":[{"atl":[[1.22,56.89]],"trd":[[1.22,890.48]],"tv":112381.69,"id":228749},{"trd":[[5.5,5.75]],"tv":7535.3,"id":2857977}],"tv":119916.99}]}
{"op":"mcm","clk":"AIyvswkA3+GkCgCvr6QK","pt":1657541872579,"mc":[{"id":"1.200806927","rc":[{"atl":[[1.22,56.41]],"trd":[[1.22,890.96]],"tv":112382.17,"id":228749},{"trd":[[5.5,5.86]],"tv":7535.41,"id":2857977}],"tv":119917.58}]}
{"op":"mcm","clk":"AJSvswkA5uGkCgC1r6QK","pt":1657541872671,"mc":[{"id":"1.200806927","rc":[{"atl":[[1.22,53.78]],"trd":[[1.22,896.22]],"tv":112387.43,"id":228749}],"tv":119922.84}]}
{"op":"mcm","clk":"AJ2vswkA7uGkCgC6r6QK","pt":1657541872761,"mc":[{"id":"1.200806927","rc":[{"atl":[[1.22,48.52]],"trd":[[1.22,906.74]],"tv":112397.95,"id":228749}],"tv":119933.36}]}
{"op":"mcm","clk":"AKuwswkA7eKkCgCesKQK","pt":1657541874468,"mc":[{"id":"1.200806927","rc":[{"atl":[[1.23,300.42]],"id":228749}]}]}
{"op":"mcm","clk":"APawswkAuOOkCgDmsKQK","pt":1657541875469,"mc":[{"id":"1.200806927","rc":[{"atl":[[1.22,35.53]],"trd":[[1.22,919.73]],"tv":112410.94,"id":228749},{"trd":[[5.5,8.74]],"tv":7538.29,"id":2857977}],"tv":119949.23}]}
{"op":"mcm","clk":"AO6xswkAiOSkCgCisaQK","pt":1657541876759,"mc":[{"id":"1.200806927","rc":[{"atl":[[1.21,0.53]],"id":228749}]}]}
{"op":"mcm","clk":"APyxswkAkuSkCgCpsaQK","pt":1657541876976,"mc":[{"id":"1.200806927","rc":[{"atb":[[1.21,2.1],[1.2,225.41]],"atl":[[1.21,0]],"id":228749}]}]}
{"op":"mcm","clk":"ANGyswkA2uSkCgDisaQK","pt":1657541877979,"mc":[{"id":"1.200806927","rc":[{"atl":[[1.23,300.95]],"id":228749}]}]}
{"op":"mcm","clk":"AOCyswkA6eSkCgDssaQK","pt":1657541878166,"mc":[{"id":"1.200806927","rc":[{"atl":[[1.24,1081.19]],"id":228749}]}]}
{"op":"mcm","clk":"AIyzswkAjOWkCgCOsqQK","pt":1657541878697,"mc":[{"id":"1.200806927","rc":[{"atl":[[1.22,30.27]],"trd":[[1.22,930.25]],"tv":112421.46,"id":228749}],"tv":119959.75}]}
{"op":"mcm","clk":"AL6zswkAr+WkCgCjsqQK","pt":1657541879194,"mc":[{"id":"1.200806927","rc":[{"atb":[[1.13,2.37]],"id":228749}]}]}
{"op":"mcm","clk":"AOCzswkA0+WkCgC6sqQK","pt":1657541879678,"mc":[{"id":"1.200806927","rc":[{"atl":[[1.22,0]],"trd":[[1.22,960.52]],"tv":112451.73,"id":228749},{"atl":[[5.5,2.31]],"trd":[[5.5,15.45]],"tv":7545,"id":2857977}],"tv":119996.73}]}
{"op":"mcm","clk":"APKzswkA5eWkCgDIsqQK","pt":1657541879899,"mc":[{"id":"1.200806927","rc":[{"atb":[[1.22,1.05]],"id":228749}]}]}
{"op":"mcm","clk":"AMK0swkApeakCgD0sqQK","pt":1657541880672,"mc":[{"id":"1.200806927","rc":[{"atl":[[1.23,299.6]],"id":228749}]}]}
{"op":"mcm","clk":"ALS1swkA9OakCgCzs6QK","pt":1657541881782,"mc":[{"id":"1.200806927","rc":[{"atb":[[1.22,6.31]],"id":228749}]}]}
{"op":"mcm","clk":"AO+1swkAm+ekCgDbs6QK","pt":1657541882401,"mc":[{"id":"1.200806927","rc":[{"atb":[[1.22,11.57]],"id":228749}]}]}
{"op":"mcm","clk":"AJW2swkAv+ekCgD9s6QK","pt":1657541882776,"mc":[{"id":"1.200806927","rc":[{"atl":[[5.5,2.84]],"id":2857977}]}]}
{"op":"mcm","clk":"AKy2swkA2eekCgCStKQK","pt":1657541882995,"mc":[{"id":"1.200806927","rc":[{"atl":[[5.5,3.25]],"id":2857977}]}]}
{"op":"mcm","clk":"AOW2swkAjOikCgCytKQK","pt":1657541883597,"mc":[{"id":"1.200806927","rc":[{"atb":[[1.22,16.83]],"id":228749}]}]}
{"op":"mcm","clk":"APu2swkAneikCgC+tKQK","pt":1657541883815,"mc":[{"id":"1.200806927","rc":[{"atb":[[1.19,0]],"id":228749}]}]}
{"op":"mcm","clk":"AIO3swkAqeikCgDFtKQK","pt":1657541883919,"mc":[{"id":"1.200806927","rc":[{"atb":[[1.22,34.87]],"id":228749}]}]}
{"op":"mcm","clk":"AJC3swkAueikCgDMtKQK","pt":1657541884074,"mc":[{"id":"1.200806927","rc":[{"atb":[[1.22,0],[1.21,0],[1.2,0]],"atl":[[1.2,722.95]],"trd":[[1.22,1044.93],[1.21,173.64],[1.2,4063.14]],"ltp":1.2,"tv":112991.16,"id":228749},{"atl":[[5.5,0]],"trd":[[5.5,18.71]],"tv":7548.26,"id":2857977}],"tv":120539.42}]}
{"op":"mcm","clk":"AKS3swkAz+ikCgDbtKQK","pt":1657541884287,"mc":[{"id":"1.200806927","rc":[{"atl":[[1.24,1070.89]],"id":228749}]}]}
{"op":"mcm","clk":"AKy3swkA1uikCgDftKQK","pt":1657541884395,"mc":[{"id":"1.200806927","rc":[{"atl":[[1.2,719.77]],"trd":[[1.2,4066.32]],"tv":112994.34,"id":228749},{"trd":[[6,3.35]],"ltp":6,"tv":7548.9,"id":2857977}],"tv":120543.24}]}
{"op":"mcm","clk":"ANy3swkAgemkCgD8tKQK","pt":1657541884922,"mc":[{"id":"1.200806927","rc":[{"atl":[[1.33,2.36]],"id":228749}]}]}
{"op":"mcm","clk":"AOa3swkAjOmkCgCJtaQK","pt":1657541885090,"mc":[{"id":"1.200806927","rc":[{"atl":[[1.28,44.15]],"id":228749}]}]}
{"op":"mcm","clk":"ANe4swkA7umkCgDNtaQK","pt":1657541886416,"mc":[{"id":"1.200806927","rc":[{"atl":[[1.2,698.73]],"trd":[[1.2,4108.4]],"tv":113036.42,"id":228749}],"tv":120585.32}]}
{"op":"mcm","clk":"AOK4swkA9umkCgDRtaQK","pt":1657541886534,"mc":[{"id":"1.200806927","rc":[{"atl":[[1.24,1071.42]],"id":228749}]}]}
{"op":"mcm","clk":"AOe4swkA+emkCgDTtaQK","pt":1657541886569,"mc":[{"id":"1.200806927","rc":[{"atl":[[1.19,1.58]],"id":228749}]}]}
{"op":"mcm","clk":"ALG5swkAveqkCgD9taQK","pt":1657541887511,"mc":[{"id":"1.200806927","rc":[{"atl":[[1.21,0.9]],"id":228749}]}]}
{"op":"mcm","clk":"AMa5swkAzOqkCgCFtqQK","pt":1657541887691,"mc":[{"id":"1.200806927","rc":[{"atl":[[1.2,909.1]],"id":228749}]}]}
{"op":"mcm","clk":"APi5swkA/eqkCgCetqQK","pt":1657541888299,"mc":[{"id":"1.200806927","rc":[{"atl":[[1.19,0],[1.2,858.09]],"trd":[[1.2,4210.42]],"tv":113138.44,"id":228749}],"tv":120687.34}]}
{"op":"mcm","clk":"AIm6swkAjOukCgCltqQK","pt":1657541888464,"mc":[{"id":"1.200806927","rc":[{"atl":[[1.19,2.63]],"id":228749}]}]}
{"op":"mcm","clk":"AMG6swkAyeukCgDGtqQK","pt":1657541888899,"mc":[{"id":"1.200806927","rc":[{"atl":[[1.19,0],[1.2,855.54]],"trd":[[1.2,4215.52]],"tv":113143.54,"id":228749}],"tv":120692.44}]}
{"op":"mcm","clk":"AP66swkA/OukCgD1tqQK","pt":1657541889333,"mc":[{"id":"1.200806927","rc":[{"atl":[[1.24,620.61],[1.21,1.43]],"id":228749}]}]}
{"op":"mcm","clk":"AJu7swkAmuykCgCKt6QK","pt":1657541889514,"mc":[{"id":"1.200806927","rc":[{"atl":[[1.22,10.3]],"id":228749}]}]}
{"op":"mcm","clk":"AK67swkAseykCgCTt6QK","pt":1657541889631,"mc":[{"id":"1.200806927","rc":[{"atb":[[1.19,265.17]],"id":228749}]}]}
{"op":"mcm","clk":"AIG8swkAiu2kCgDGt6QK","pt":1657541890222,"mc":[{"id":"1.200806927","rc":[{"atb":[[1.13,2.22]],"atl":[[1.28,33.63]],"id":228749}]}]}
{"op":"mcm","clk":"AJu8swkApe2kCgDVt6QK","pt":1657541890443,"mc":[{"id":"1.200806927","rc":[{"atb":[[1.08,6.21]],"id":228749}]}]}
{"op":"mcm","clk":"ALm8swkA2+2kCgDpt6QK","pt":1657541890694,"mc":[{"id":"1.200806927","rc":[{"atl":[[1.21,4.06]],"id":228749}]}]}
{"op":"mcm","clk":"AIm9swkAqO6kCgCcuKQK","pt":1657541891324,"mc":[{"id":"1.200806927","rc":[{"atl":[[1.22,10.82]],"id":228749}]}]}
{"op":"mcm","clk":"APC9swkAlu+kCgDluKQK","pt":1657541892220,"mc":[{"id":"1.200806927","rc":[{"atl":[[1.22,11.35]],"id":228749}]}]}
{"op":"mcm","clk":"AJ2+swkAxe+kCgCIuaQK","pt":1657541892635,"mc":[{"id":"1.200806927","rc":[{"atl":[[1.2,853.38]],"trd":[[1.2,4217.68]],"tv":113145.7,"id":228749},{"trd":[[6,3.78]],"tv":7549.33,"id":2857977}],"tv":120695.03}]}
{"op":"mcm","clk":"AM2+swkA+u+kCgCouaQK","pt":1657541893198,"mc":[{"id":"1.200806927","rc":[{"atl":[[1.22,11.88]],"id":228749}]}]}
{"op":"mcm","clk":"ANu+swkAhvCkCgCxuaQK","pt":1657541893335,"mc":[{"id":"1.200806927","rc":[{"atb":[[5.5,2.63]],"id":2857977}]}]}
{"op":"mcm","clk":"AKC/swkAwPCkCgDduaQK","pt":1657541894100,"mc":[{"id":"1.200806927","rc":[{"atl":[[1.23,297.45]],"id":228749}]}]}
{"op":"mcm","clk":"ALm/swkA2vCkCgDsuaQK","pt":1657541894417,"mc":[{"id":"1.200806927","rc":[{"atl":[[1.22,37.02]],"id":228749}]}]}
{"op":"mcm","clk":"AM+/swkA6PCkCgDzuaQK","pt":1657541894622,"mc":[{"id":"1.200806927","rc":[{"atl":[[1.36,0]],"id":228749}]}]}
{"op":"mcm","clk":"APy/swkAj/GkCgCSuqQK","pt":1657541895129,"mc":[{"id":"1.200806927","rc":[{"atl":[[1.2,852.38]],"trd":[[1.2,4218.68]],"tv":113146.7,"id":228749},{"trd":[[6,3.98]],"tv":7549.53,"id":2857977}],"tv":120696.23}]}
{"op":"mcm","clk":"AIzAswkAnfGkCgCfuqQK","pt":1657541895297,"mc":[{"id":"1.200806927","rc":[{"atb":[[1.19,258.7]],"id":228749}]}]}
{"op":"mcm","clk":"ALjAswkA1vGkCgC+uqQK","pt":1657541895942,"mc":[{"id":"1.200806927","rc":[{"atl":[[1.23,302.71]],"id":228749}]}]}
{"op":"mcm","clk":"APDAswkA9fGkCgDjuqQK","pt":1657541896224,"mc":[{"id":"1.200806927","rc":[{"atb":[[1.19,258.44]],"trd":[[1.19,399.51]],"ltp":1.19,"tv":113147.22,"id":228749}],"tv":120696.75}]}
{"op":"mcm","clk":"AJ7BswkAo/KkCgCGu6QK","pt":1657541896811,"mc":[{"id":"1.200806927","rc":[{"atl":[[1.2,849.73]],"trd":[[1.2,4221.33]],"ltp":1.2,"tv":113149.87,"id":228749},{"trd":[[6,4.51]],"tv":7550.06,"id":2857977}],"tv":120699.93}]}
{"op":"mcm","clk":"AMzBswkAyfKkCgCiu6QK","pt":1657541897322,"mc":[{"id":"1.200806927","rc":[{"atl":[[1.2,349.33]],"trd":[[1.2,5222.13]],"tv":114150.67,"id":228749}],"tv":121700.73}]}
{"op":"mcm","clk":"APrBswkA+vKkCgC3u6QK","pt":1657541897809,"mc":[{"id":"1.200806927","rc":[{"atl":[[1.22,37.55]],"id":228749}]}]}
{"op":"mcm","clk":"ALjCswkAvfOkCgDiu6QK","pt":1657541898540,"mc":[{"id":"1.200806927","rc":[{"atl":[[1.2,348.83]],"trd":[[1.2,5222.63]],"tv":114151.17,"id":228749},{"trd":[[6,4.61]],"tv":7550.16,"id":2857977}],"tv":121701.33}]}
{"op":"mcm","clk":"AMjCswkAzfOkCgDsu6QK","pt":1657541898733,"mc":[{"id":"1.200806927","rc":[{"atl":[[1.2,358.4]],"id":228749}]}]}
{"op":"mcm","clk":"AODCswkA6POkCgD8u6QK","pt":1657541899004,"mc":[{"id":"1.200806927","rc":[{"atl":[[1.2,355.5]],"trd":[[1.2,5225.53]],"tv":114154.07,"id":228749},{"trd":[[6,5.19]],"tv":7550.74,"id":2857977}],"tv":121704.81}]}
{"op":"mcm","clk":"AJHDswkAlPSkCgCTvKQK","pt":1657541899526,"mc":[{"id":"1.200806927","rc":[{"atl":[[1.23,302.18]],"id":228749}]}]}
{"op":"mcm","clk":"AKHDswkAqfSkCgCfvKQK","pt":1657541899736,"mc":[{"id":"1.200806927","rc":[{"atl":[[1.2,352.87]],"trd":[[1.2,5230.79]],"tv":114159.33,"id":228749}],"tv":121710.07}]}
{"op":"mcm","clk":"ALrDswkAwfSkCgCsvKQK","pt":1657541899999,"mc":[{"id":"1.200806927","rc":[{"atl":[[1.2,352.81]],"trd":[[1.2,5230.91]],"tv":114159.45,"id":228749}],"tv":121710.19}]}
{"op":"mcm","clk":"ANnDswkA3PSkCgC4vKQK","pt":1657541900324,"mc":[{"id":"1.200806927","rc":[{"atb":[[1.17,0]],"id":228749}]}]}
{"op":"mcm","clk":"AKPEswkAo/WkCgDZvKQK","pt":1657541901097,"mc":[{"id":"1.200806927","rc":[{"atb":[[1.19,131.67]],"trd":[[1.19,653.05]],"ltp":1.19,"tv":114412.99,"id":228749}],"tv":121963.73}]}
{"op":"mcm","clk":"AOPEswkA2fWkCgCBvaQK","pt":1657541901821,"mc":[{"id":"1.200806927","rc":[{"atl":[[1.2,351.81]],"trd":[[1.2,5231.91]],"ltp":1.2,"tv":114413.99,"id":228749},{"trd":[[6,5.39]],"tv":7550.94,"id":2857977}],"tv":121964.93}]}
{"op":"mcm","clk":"AO7EswkA4vWkCgCIvaQK","pt":1657541901936,"mc":[{"id":"1.200806927","rc":[{"atl":[[1.2,351.92]],"id":228749}]}]}
{"op":"mcm","clk":"APHEswkA7PWkCgCMvaQK","pt":1657541902021,"mc":[{"id":"1.200806927","rc":[{"atb":[[1.19,0]],"atl":[[1000,0.29],[1.19,76.54]],"trd":[[1.19,657.37]],"ltp":1.19,"tv":114418.31,"id":228749}],"tv":121969.25}]}
{"op":"mcm","clk":"APvEswkA9fWkCgCSvaQK","pt":1657541902124,"mc":[{"id":"1.200806927","rc":[{"atl":[[1.19,78.12]],"id":228749}]}]}
{"op":"mcm","clk":"AIfFswkAgvakCgCXvaQK","pt":1657541902241,"mc":[{"id":"1.200806927","rc":[{"atl":[[1.19,76.54]],"id":228749}]}]}
{"op":"mcm","clk":"AJjFswkAjPakCgChvaQK","pt":1657541902432,"mc":[{"id":"1.200806927","rc":[{"atl":[[1000,0.13]],"id":228749}]}]}
{"op":"mcm","clk":"ANnFswkAwvakCgDLvaQK","pt":1657541903133,"mc":[{"id":"1.200806927","rc":[{"atb":[[1.17,10.52]],"id":228749}]}]}
{"op":"mcm","clk":"AIHGswkA6PakCgDcvaQK","pt":1657541903454,"mc":[{"id":"1.200806927","rc":[{"atl":[[1.19,75.42]],"trd":[[1.19,658.49]],"tv":114419.43,"id":228749},{"trd":[[6.2,1.48]],"ltp":6.2,"tv":7551.16,"id":2857977}],"tv":121970.59}]}
{"op":"mcm","clk":"AIzGswkA//akCgDovaQK","pt":1657541903660,"mc":[{"id":"1.200806927","rc":[{"atl":[[1.19,74.86]],"trd":[[1.19,659.05]],"tv":114419.99,"id":228749},{"trd":[[6.2,1.58]],"tv":7551.26,"id":2857977}],"tv":121971.25}]}
{"op":"mcm","clk":"AKHGswkAjvekCgDxvaQK","pt":1657541903736,"mc":[{"id":"1.200806927","rc":[{"atb":[[1.18,7.89]],"id":228749}]}]}
{"op":"mcm","clk":"APLGswkA1fekCgCavqQK","pt":1657541904376,"mc":[{"id":"1.200806927","rc":[{"atl":[[1.19,70.55]],"trd":[[1.19,667.67]],"tv":114428.61,"id":228749}],"tv":121979.87}]}
{"op":"mcm","clk":"AO3HswkA6/ikCgDvvqQK","pt":1657541905586,"mc":[{"id":"1.200806927","rc":[{"atl":[[1.19,0],[1.2,294.77]],"trd":[[1.19,808.77],[1.2,5346.21]],"ltp":1.2,"tv":114684.01,"id":228749}],"tv":122235.27}]}
{"op":"mcm","clk":"ALvIswkAwfmkCgCev6QK","pt":1657541906346,"mc":[{"id":"1.200806927","rc":[{"atl":[[1.2,289.52]],"trd":[[1.2,5351.46]],"tv":114689.26,"id":228749},{"trd":[[6,6.44]],"ltp":6,"tv":7552.31,"id":2857977}],"tv":122241.57}]}
{"op":"mcm","clk":"AMLIswkAy/mkCgCkv6QK","pt":1657541906445,"mc":[{"id":"1.200806927","rc":[{"atl":[[1.19,0.53],[1.2,288.47]],"trd":[[1.2,5353.56]],"tv":114691.36,"id":228749}],"tv":122243.67}]}
{"op":"mcm","clk":"AN3IswkA3fmkCgCwv6QK","pt":1657541906660,"mc":[{"id":"1.200806927","rc":[{"atb":[[1.2,211.4]],"atl":[[1.19,0],[1.2,0]],"trd":[[1.2,5490.62]],"tv":114828.42,"id":228749}],"tv":122380.73}]}
{"op":"mcm","clk":"AKrJswkAr/qkCgDqv6QK","pt":1657541907437,"mc":[{"id":"1.200806927","rc":[{"atl":[[6,0.22]],"id":2857977}]}]}
{"op":"mcm","clk":"ALLJswkAuPqkCgDvv6QK","pt":1657541907521,"mc":[{"id":"1.200806927","rc":[{"atb":[[1.2,211.24]],"trd":[[1.2,5490.94]],"tv":114828.74,"id":228749}],"tv":122381.05}]}
{"op":"mcm","clk":"ALnJswkAwPqkCgDzv6QK","pt":1657541907606,"mc":[{"id":"1.200806927","rc":[{"atl":[[1.24,620.08]],"id":228749}]}]}
{"op":"mcm","clk":"AMjJswkAy/qkCgD9v6QK","pt":1657541907731,"mc":[{"id":"1.200806927","rc":[{"atb":[[1.2,211.35]],"atl":[[1.21,3.53]],"id":228749}]}]}
{"op":"mcm","clk":"ANTJswkA1PqkCgCGwKQK","pt":1657541907830,"mc":[{"id":"1.200806927","rc":[{"atb":[[1.2,215.35]],"id":228749}]}]}
{"op":"mcm","clk":"AOvJswkA6/qkCgCSwKQK","pt":1657541908043,"mc":[{"id":"1.200806927","rc":[{"atl":[[6,7.61]],"id":2857977}]}]}
{"op":"mcm","clk":"AIfKswkAjfukCgChwKQK","pt":1657541908448,"mc":[{"id":"1.200806927","rc":[{"atl":[[1.24,619.55]],"id":228749}]}]}
{"op":"mcm","clk":"AJXKswkAl/ukCgCowKQK","pt":1657541908561,"mc":[{"id":"1.200806927","rc":[{"atl":[[6,8.51]],"id":2857977}]}]}
{"op":"mcm","clk":"ALLKswkAvPukCgC5wKQK","pt":1657541908912,"mc":[{"id":"1.200806927","rc":[{"atl":[[1.3,320.73],[1.22,37.02]],"id":228749}]}]}
{"op":"mcm","clk":"ANjKswkA1/ukCgDMwKQK","pt":1657541909229,"mc":[{"id":"1.200806927","rc":[{"atl":[[1.24,618.5]],"id":228749}]}]}
{"op":"mcm","clk":"AMbLswkAzfykCgCNwaQK","pt":1657541910429,"mc":[{"id":"1.200806927","rc":[{"atl":[[1.22,33.32],[1.21,0]],"trd":[[1.22,1048.63],[1.21,177.17]],"ltp":1.22,"tv":114835.97,"id":228749},{"atb":[[5.5,0]],"atl":[[6,8.61]],"trd":[[5.7,19.79],[5.5,24.79]],"ltp":5.5,"tv":7559.14,"id":2857977}],"tv":122395.11}]}
{"op":"mcm","clk":"AOTLswkA6fykCgCjwaQK","pt":1657541910740,"mc":[{"id":"1.200806927","rc":[{"atl":[[6,8.72]],"id":2857977}]}]}
{"op":"mcm","clk":"AN3MswkAwf2kCgDcwaQK","pt":1657541911844,"mc":[{"id":"1.200806927","rc":[{"atb":[[1.2,214.3]],"id":228749}]}]}
{"op":"mcm","clk":"AJ7NswkAhv6kCgD+waQK","pt":1657541912522,"mc":[{"id":"1.200806927","rc":[{"atb":[[1.2,265.78]],"id":228749}]}]}
{"op":"mcm","clk":"AMbNswkAqv6kCgCYwqQK","pt":1657541912948,"mc":[{"id":"1.200806927","rc":[{"atb":[[1.04,43.89]],"id":228749}]}]}
{"op":"mcm","clk":"AIXRswkAzf+kCgDwwqQK","pt":1657541914489,"mc":[{"id":"1.200806927","rc":[{"atl":[[1.22,8.18]],"id":228749}]}]}
{"op":"mcm","clk":"AO3YswkAloClCgCYw6QK","pt":1657541915164,"mc":[{"id":"1.200806927","rc":[{"atb":[[1.25,71.14]],"atl":[[1.24,0],[1.22,0],[1.23,0]],"trd":[[1.24,3147.98],[1.22,1064.98],[1.23,1504.63]],"ltp":1.24,"tv":116693.68,"id":228749}],"tv":124252.82}]}
{"op":"mcm","clk":"APTbswkAq4ClCgCkw6QK","pt":1657541915376,"mc":[{"id":"1.200806927","rc":[{"atb":[[1.25,0]],"id":228749}]}]}
{"op":"mcm","clk":"AI3fswkAvIClCgCqw6QK","pt":1657541915577,"mc":[{"id":"1.200806927","rc":[{"atl":[[6,7.82]],"id":2857977}]}]}
{"op":"mcm","clk":"AI3fswkAyIClCgCzw6QK","pt":1657541915687,"mc":[{"id":"1.200806927","rc":[{"atb":[[1.2,264.72]],"id":228749}]}]}
{"op":"mcm","clk":"AMLxswkArYGlCgDrw6QK","pt":1657541916785,"mc":[{"id":"1.200806927","rc":[{"atb":[[1.19,231.89]],"id":228749}]}]}
{"op":"mcm","clk":"AMLxswkAyoGlCgD5w6QK","pt":1657541917067,"mc":[{"id":"1.200806927","rc":[{"atb":[[1.2,291.02]],"id":228749}]}]}
{"op":"mcm","clk":"AMLxswkA1IGlCgCBxKQK","pt":1657541917159,"mc":[{"id":"1.200806927","rc":[{"atb":[[1.2,290.49]],"id":228749}]}]}
{"op":"mcm","clk":"AIOCtAkAroKlCgDNxKQK","pt":1657541918341,"mc":[{"id":"1.200806927","rc":[{"atb":[[1.04,44.06]],"id":228749}]}]}
{"op":"mcm","clk":"ALWCtAkA04KlCgDmxKQK","pt":1657541918757,"mc":[{"id":"1.200806927","rc":[{"atb":[[1.04,43.89]],"id":228749}]}]}
{"op":"mcm","clk":"ALeCtAkA2IKlCgDuxKQK","pt":1657541918839,"mc":[{"id":"1.200806927","rc":[{"atb":[[1.2,286.49]],"id":228749}]}]}
{"op":"mcm","clk":"AM+CtAkA6oKlCgD8xKQK","pt":1657541919064,"mc":[{"id":"1.200806927","rc":[{"atb":[[1.2,282.18]],"trd":[[1.2,5499.56]],"ltp":1.2,"tv":116702.3,"id":228749},{"atl":[[6.2,1.29]],"id":2857977}],"tv":124261.44}]}
{"op":"mcm","clk":"ALODtAkAvIOlCgCtxaQK","pt":1657541919865,"mc":[{"id":"1.200806927","rc":[{"atb":[[1.2,71.81]],"trd":[[1.2,5514.34]],"tv":116717.08,"id":228749}],"tv":124276.22}]}
{"op":"mcm","clk":"ALuDtAkAxYOlCgCwxaQK","pt":1657541919916,"mc":[{"id":"1.200806927","rc":[{"atb":[[1.2,70.5]],"id":228749}]}]}
{"op":"mcm","clk":"AOeFtAkAxoWlCgDrxqQK","pt":1657541922940,"mc":[{"id":"1.200806927","rc":[{"atb":[[1.2,67.87]],"trd":[[1.2,5519.6]],"tv":116722.34,"id":228749}],"tv":124281.48}]}
{"op":"mcm","clk":"AMmGtAkAgIalCgChx6QK","pt":1657541923902,"mc":[{"id":"1.200806927","rc":[{"atb":[[1.21,0.18]],"id":228749}]}]}
{"op":"mcm","clk":"AKaHtAkAzIalCgDZx6QK","pt":1657541924802,"mc":[{"id":"1.200806927","rc":[{"atb":[[1.22,7.5]],"id":228749}]}]}
{"op":"mcm","clk":"AMOHtAkA44alCgDpx6QK","pt":1657541925106,"mc":[{"id":"1.200806927","rc":[{"atb":[[1.22,4.91]],"trd":[[1.22,1070.16]],"ltp":1.22,"tv":116727.52,"id":228749}],"tv":124286.66}]}
{"op":"mcm","clk":"AOKHtAkA+4alCgCByKQK","pt":1657541925381,"mc":[{"id":"1.200806927","rc":[{"atb":[[1.22,0],[1.21,0],[1.2,47.82]],"trd":[[1.22,1079.98],[1.21,177.52],[1.2,5559.7]],"ltp":1.2,"tv":116777.79,"id":228749}],"tv":124336.93}]}
{"op":"mcm","clk":"ANiItAkA1IelCgDJyKQK","pt":1657541926466,"mc":[{"id":"1.200806927","rc":[{"atl":[[9.2,0]],"id":2857977}]}]}
{"op":"mcm","clk":"AKCJtAkAmYilCgDxyKQK","pt":1657541927287,"mc":[{"id":"1.200806927","rc":[{"atb":[[1.19,233.2]],"id":228749}]}]}
{"op":"mcm","clk":"ANuJtAkAzoilCgCUyaQK","pt":1657541927766,"mc":[{"id":"1.200806927","rc":[{"atb":[[1.2,47.72]],"trd":[[1.2,5559.9]],"tv":116777.99,"id":228749}],"tv":124337.13}]}
{"op":"mcm","clk":"APmJtAkA4oilCgChyaQK","pt":1657541927998,"mc":[{"id":"1.200806927","rc":[{"atb":[[1.17,10.65]],"id":228749}]}]}
{"op":"mcm","clk":"AMiKtAkArImlCgDOyaQK","pt":1657541928759,"mc":[{"id":"1.200806927","rc":[{"atb":[[1.2,47.19]],"trd":[[1.2,5560.96]],"tv":116779.05,"id":228749}],"tv":124338.19}]}
{"op":"mcm","clk":"AOyKtAkA0omlCgDnyaQK","pt":1657541929176,"mc":[{"id":"1.200806927","rc":[{"atl":[[6.6,15.44]],"id":2857977}]}]}
{"op":"mcm","clk":"APiKtAkA4omlCgDzyaQK","pt":1657541929394,"mc":[{"id":"1.200806927","rc":[{"atl":[[6,7.71]],"id":2857977}]}]}
{"op":"mcm","clk":"AJGLtAkA9omlCgCCyqQK","pt":1657541929614,"mc":[{"id":"1.200806927","rc":[{"atb":[[1.04,43.05]],"id":228749}]}]}
{"op":"mcm","clk":"AOGLtAkA3IqlCgC0yqQK","pt":1657541930592,"mc":[{"id":"1.200806927","rc":[{"atb":[[1.19,108.59],[1.2,0]],"trd":[[1.2,5641.31]],"tv":116859.4,"id":228749},{"atl":[[6,0]],"trd":[[6,14.16]],"ltp":6,"tv":7566.86,"id":2857977}],"tv":124426.26}]}
{"op":"mcm","clk":"AK2MtAkAloulCgDpyqQK","pt":1657541931380,"mc":[{"id":"1.200806927","rc":[{"atl":[[1.2,1.05]],"id":228749}]}]}
{"op":"mcm","clk":"AOqMtAkAwIulCgCAy6QK","pt":1657541931976,"mc":[{"id":"1.200806927","rc":[{"atb":[[1.18,2.63]],"atl":[[1.2,0]],"id":228749}]}]}
{"op":"mcm","clk":"APCMtAkAx4ulCgCFy6QK","pt":1657541932074,"mc":[{"id":"1.200806927","rc":[{"atl":[[1.26,10.11]],"trd":[[1.26,680.44]],"ltp":1.26,"tv":116859.81,"id":228749},{"trd":[[4.8,57.87]],"ltp":4.8,"tv":7566.97,"id":2857977}],"tv":124426.78}]}
{"op":"mcm","clk":"AP6MtAkA0IulCgCKy6QK","pt":1657541932172,"mc":[{"id":"1.200806927","rc":[{"atl":[[1.24,5.26]],"id":228749}]}]}
{"op":"mcm","clk":"AIONtAkA2oulCgCPy6QK","pt":1657541932273,"mc":[{"id":"1.200806927","rc":[{"atl":[[1.2,2.07]],"id":228749}]}]}
{"op":"mcm","clk":"AN2NtAkArIylCgDDy6QK","pt":1657541933273,"mc":[{"id":"1.200806927","rc":[{"atl":[[1.54,25.89]],"id":228749}]}]}
{"op":"mcm","clk":"AOKNtAkAt4ylCgDGy6QK","pt":1657541933362,"mc":[{"id":"1.200806927","rc":[{"atl":[[1.25,5.26]],"id":228749}]}]}
{"op":"mcm","clk":"AIGOtAkA0YylCgDSy6QK","pt":1657541933680,"mc":[{"id":"1.200806927","rc":[{"atl":[[1.24,7.96]],"id":228749}]}]}
{"op":"mcm","clk":"AL+OtAkAgI2lCgCFzKQK","pt":1657541934308,"mc":[{"id":"1.200806927","rc":[{"atb":[[6,0.53]],"id":2857977}]}]}
{"op":"mcm","clk":"ALGPtAkA142lCgDMzKQK","pt":1657541935417,"mc":[{"id":"1.200806927","rc":[{"atl":[[1.2,5.96]],"id":228749}]}]}
{"op":"mcm","clk":"ALyPtAkA6I2lCgDSzKQK","pt":1657541935648,"mc":[{"id":"1.200806927","rc":[{"atl":[[1.2,4.65]],"id":228749}]}]}
{"op":"mcm","clk":"ANqPtAkAhY6lCgDlzKQK","pt":1657541935918,"mc":[{"id":"1.200806927","rc":[{"atl":[[1.2,5.51]],"id":228749}]}]}
{"op":"mcm","clk":"APSPtAkAo46lCgD2zKQK","pt":1657541936184,"mc":[{"id":"1.200806927","rc":[{"atb":[[6,1.06]],"id":2857977}]}]}
{"op":"mcm","clk":"ANOQtAkA6Y6lCgCrzaQK","pt":1657541937207,"mc":[{"id":"1.200806927","rc":[{"atb":[[5,1.04]],"id":2857977}]}]}
{"op":"mcm","clk":"ALORtAkAso+lCgDlzaQK","pt":1657541938113,"mc":[{"id":"1.200806927","rc":[{"atb":[[1.2,20.74]],"atl":[[1.2,0]],"trd":[[1.2,5648.34]],"ltp":1.2,"tv":116866.84,"id":228749},{"atb":[[6,0]],"trd":[[6,15.22]],"ltp":6,"tv":7568.03,"id":2857977}],"tv":124434.87}]}
{"op":"mcm","clk":"AIyStAkAgpClCgCUzqQK","pt":1657541938981,"mc":[{"id":"1.200806927","rc":[{"atl":[[1.26,11.69]],"id":228749}]}]}
{"op":"mcm","clk":"AJSStAkAjZClCgCXzqQK","pt":1657541939071,"mc":[{"id":"1.200806927","rc":[{"atb":[[1.2,0]],"atl":[[1.2,14.76]],"trd":[[1.2,5689.82]],"tv":116908.32,"id":228749}],"tv":124476.35}]}
{"op":"mcm","clk":"ALGStAkAp5ClCgCuzqQK","pt":1657541939405,"mc":[{"id":"1.200806927","rc":[{"atb":[[1.19,107.28]],"id":228749}]}]}
{"op":"mcm","clk":"AOGStAkAzJClCgDHzqQK","pt":1657541939921,"mc":[{"id":"1.200806927","rc":[{"atl":[[1.2,14.93]],"id":228749}]}]}
{"op":"mcm","clk":"APqStAkA4pClCgDVzqQK","pt":1657541940222,"mc":[{"id":"1.200806927","rc":[{"atl":[[1.24,11.56]],"id":228749}]}]}
{"op":"mcm","clk":"ALiTtAkAn5GlCgD3zqQK","pt":1657541940915,"mc":[{"id":"1.200806927","rc":[{"atl":[[1.2,9.67]],"trd":[[1.2,5700.34]],"tv":116918.84,"id":228749}],"tv":124486.87}]}
{"op":"mcm","clk":"AJ6UtAkA85GlCgCmz6QK","pt":1657541942113,"mc":[{"id":"1.200806927","rc":[{"atl":[[1.2,11.47]],"id":228749}]}]}
{"op":"mcm","clk":"AL2UtAkAnZKlCgC/z6QK","pt":1657541942539,"mc":[{"id":"1.200806927","rc":[{"atl":[[1.2,17.86]],"trd":[[1.2,5705.6]],"tv":116924.1,"id":228749}],"tv":124492.13}]}
{"op":"mcm","clk":"AMyUtAkAq5KlCgDEz6QK","pt":1657541942699,"mc":[{"id":"1.200806927","rc":[{"atl":[[1.2,16.28]],"trd":[[1.2,5708.76]],"tv":116927.26,"id":228749}],"tv":124495.29}]}
{"op":"mcm","clk":"ALWVtAkAhZOlCgCC0KQK","pt":1657541943817,"mc":[{"id":"1.200806927","rc":[{"atl":[[1.2,11.02]],"trd":[[1.2,5719.28]],"tv":116937.78,"id":228749}],"tv":124505.81}]}
{"op":"mcm","clk":"AL+VtAkAjJOlCgCG0KQK","pt":1657541943881,"mc":[{"id":"1.200806927","rc":[{"atl":[[1.2,10.99]],"id":228749}]}]}
{"op":"mcm","clk":"AN6VtAkArZOlCgCj0KQK","pt":1657541944213,"mc":[{"id":"1.200806927","rc":[{"atl":[[1.2,8.65]],"trd":[[1.2,5723.96]],"tv":116942.46,"id":228749}],"tv":124510.49}]}
{"op":"mcm","clk":"AIqWtAkA1ZOlCgDG0KQK","pt":1657541944630,"mc":[{"id":"1.200806927","rc":[{"atl":[[1.2,7.61]],"id":228749}]}]}
{"op":"mcm","clk":"AKqWtAkA85OlCgDS0KQK","pt":1657541944931,"mc":[{"id":"1.200806927","rc":[{"atb":[[1.2,2.91]],"atl":[[1.2,0]],"id":228749}]}]}
{"op":"mcm","clk":"AMqWtAkAlZSlCgDs0KQK","pt":1657541945397,"mc":[{"id":"1.200806927","rc":[{"atb":[[1.19,0],[1.2,0]],"atl":[[1.19,93.44]],"trd":[[1.19,815.51]],"ltp":1.19,"tv":116949.2,"id":228749},{"atl":[[6.2,0]],"trd":[[6.2,2.88]],"ltp":6.2,"tv":7569.33,"id":2857977}],"tv":124518.53}]}
{"op":"mcm","clk":"AOaWtAkAsJSlCgD20KQK","pt":1657541945717,"mc":[{"id":"1.200806927","rc":[{"atl":[[1.19,82.92]],"id":228749}]}]}
{"op":"mcm","clk":"AJSXtAkA3JSlCgCQ0aQK","pt":1657541946237,"mc":[{"id":"1.200806927","rc":[{"atb":[[1.18,5.53]],"id":228749}]}]}
{"op":"mcm","clk":"AKyXtAkAgJWlCgCl0aQK","pt":1657541946715,"mc":[{"id":"1.200806927","rc":[{"atl":[[1.24,681.97]],"id":228749}]}]}
{"op":"mcm","clk":"AOWXtAkAmJWlCgC10aQK","pt":1657541947005,"mc":[{"id":"1.200806927","rc":[{"atb":[[1.2,768]],"atl":[[1.19,0]],"trd":[[1.19,981.35]],"tv":117115.04,"id":228749}],"tv":124684.37}]}
{"op":"mcm","clk":"AJqYtAkAuZWlCgDT0aQK","pt":1657541947437,"mc":[{"id":"1.200806927","rc":[{"atl":[[1.24,679.79]],"trd":[[1.24,3150.16]],"ltp":1.24,"tv":117117.22,"id":228749},{"trd":[[5.1,2.89]],"ltp":5.1,"tv":7569.86,"id":2857977}],"tv":124687.08}]}
{"op":"mcm","clk":"ALeYtAkA0ZWlCgDc0aQK","pt":1657541947729,"mc":[{"id":"1.200806927","rc":[{"atb":[[1.2,776.01]],"id":228749}]}]}
{"op":"mcm","clk":"AMeYtAkA2ZWlCgDj0aQK","pt":1657541947794,"mc":[{"id":"1.200806927","rc":[{"atl":[[1.25,5.79]],"id":228749}]}]}
{"op":"mcm","clk":"AMyYtAkA4JWlCgDn0aQK","pt":1657541947898,"mc":[{"id":"1.200806927","rc":[{"atb":[[1.2,771.5]],"trd":[[1.2,5732.98]],"ltp":1.2,"tv":117126.24,"id":228749}],"tv":124696.1}]}
{"op":"mcm","clk":"AIaZtAkAj5alCgCa0qQK","pt":1657541948623,"mc":[{"id":"1.200806927","rc":[{"atl":[[1.23,129.44]],"id":228749}]}]}
{"op":"mcm","clk":"AI+ZtAkAk5alCgCh0qQK","pt":1657541948719,"mc":[{"id":"1.200806927","rc":[{"atl":[[1.23,127.16]],"trd":[[1.23,1506.91]],"ltp":1.23,"tv":117128.52,"id":228749},{"trd":[[5.3,38.74]],"ltp":5.3,"tv":7570.39,"id":2857977}],"tv":124698.91}]}
{"op":"mcm","clk":"ANuZtAkAz5alCgDF0qQK","pt":1657541949418,"mc":[{"id":"1.200806927","rc":[{"atl":[[6.2,0.43]],"id":2857977}]}]}
{"op":"mcm","clk":"AI+atAkAgZelCgDj0qQK","pt":1657541950013,"mc":[{"id":"1.200806927","rc":[{"atb":[[1.2,760.98]],"trd":[[1.2,5754.02]],"ltp":1.2,"tv":117149.56,"id":228749},{"atl":[[6,0.2]],"id":2857977}],"tv":124719.95}]}
{"op":"mcm","clk":"AJOatAkAh5elCgDm0qQK","pt":1657541950086,"mc":[{"id":"1.200806927","rc":[{"atb":[[1.2,787.28]],"id":228749},{"atb":[[5,0]],"id":2857977}]}]}
{"op":"mcm","clk":"AMCatAkAqZelCgD90qQK","pt":1657541950514,"mc":[{"id":"1.200806927","rc":[{"atl":[[6,0.46]],"id":2857977}]}]}
{"op":"mcm","clk":"AOeatAkA1JelCgCV06QK","pt":1657541950933,"mc":[{"id":"1.200806927","rc":[{"atl":[[1.24,890.16]],"id":228749},{"atl":[[6,9.48]],"id":2857977}]}]}
{"op":"mcm","clk":"AO+atAkA3JelCgCe06QK","pt":1657541951034,"mc":[{"id":"1.200806927","rc":[{"atl":[[6,20]],"id":2857977}]}]}
{"op":"mcm","clk":"APmatAkA5ZelCgCi06QK","pt":1657541951099,"mc":[{"id":"1.200806927","rc":[{"atb":[[1.2,788.12]],"id":228749}]}]}
{"op":"mcm","clk":"AIGbtAkA7ZelCgCo06QK","pt":1657541951200,"mc":[{"id":"1.200806927","rc":[{"atb":[[1.2,803.9]],"id":228749}]}]}
{"op":"mcm","clk":"AIWbtAkA9pelCgCs06QK","pt":1657541951292,"mc":[{"id":"1.200806927","rc":[{"atb":[[1.2,803.69]],"trd":[[1.2,5754.45]],"tv":117149.99,"id":228749}],"tv":124720.38}]}
{"op":"mcm","clk":"AJSbtAkAgJilCgCx06QK","pt":1657541951411,"mc":[{"id":"1.200806927","rc":[{"atb":[[1.2,814.21]],"id":228749}]}]}
{"op":"mcm","clk":"ALibtAkApJilCgDE06QK","pt":1657541951832,"mc":[{"id":"1.200806927","rc":[{"atb":[[1.2,813.78]],"trd":[[1.2,5755.31]],"tv":117150.85,"id":228749}],"tv":124721.24}]}
{"op":"mcm","clk":"AMWbtAkArpilCgDK06QK","pt":1657541951921,"mc":[{"id":"1.200806927","rc":[{"atl":[[6,19.8]],"id":2857977}]}]}
{"op":"mcm","clk":"AOibtAkAzJilCgDm06QK","pt":1657541952299,"mc":[{"id":"1.200806927","rc":[{"atl":[[6,21.38]],"id":2857977}]}]}
{"op":"mcm","clk":"AOybtAkA1ZilCgDt06QK","pt":1657541952381,"mc":[{"id":"1.200806927","rc":[{"atb":[[1.2,819.04]],"id":228749}]}]}
{"op":"mcm","clk":"AK+ctAkAlJmlCgCT1KQK","pt":1657541953136,"mc":[{"id":"1.200806927","rc":[{"atl":[[1.23,126.73]],"trd":[[1.23,1507.34]],"ltp":1.23,"tv":117151.28,"id":228749},{"trd":[[5.3,38.84]],"tv":7570.49,"id":2857977}],"tv":124721.77}]}
{"op":"mcm","clk":"ALGctAkAm5mlCgCT1KQK","pt":1657541953213,"mc":[{"id":"1.200806927","rc":[{"atl":[[1.25,0.53]],"id":228749}]}]}
{"op":"mcm","clk":"ANCctAkAtJmlCgCo1KQK","pt":1657541953540,"mc":[{"id":"1.200806927","rc":[{"atl":[[1.24,219.75]],"id":228749}]}]}
{"op":"mcm","clk":"AKedtAkA/JmlCgDP1KQK","pt":1657541954422,"mc":[{"id":"1.200806927","rc":[{"atl":[[1.24,220.18],[1.23,122.85]],"trd":[[1.23,1511.22]],"tv":117155.16,"id":228749},{"trd":[[5.3,39.74]],"tv":7571.39,"id":2857977}],"tv":124726.55}]}
{"op":"mcm","clk":"AI+etAkA0pqlCgD81KQK","pt":1657541955404,"mc":[{"id":"1.200806927","rc":[{"atl":[[6,10.86]],"id":2857977}]}]}
{"op":"mcm","clk":"AKietAkA7pqlCgCH1aQK","pt":1657541955722,"mc":[{"id":"1.200806927","rc":[{"atb":[[1.2,818.61]],"trd":[[1.2,5756.17]],"ltp":1.2,"tv":117156.02,"id":228749}],"tv":124727.41}]}
{"op":"mcm","clk":"AO2etAkAqJulCgCn1aQK","pt":1657541956351,"mc":[{"id":"1.200806927","rc":[{"atl":[[6.2,0.54]],"id":2857977}]}]}
{"op":"mcm","clk":"AJiftAkAyZulCgC21aQK","pt":1657541956719,"mc":[{"id":"1.200806927","rc":[{"atl":[[6.6,16.31]],"id":2857977}]}]}
{"op":"mcm","clk":"AO6ftAkAo5ylCgDt1aQK","pt":1657541957700,"mc":[{"id":"1.200806927","rc":[{"atl":[[1.23,121.36]],"trd":[[1.23,1512.71]],"ltp":1.23,"tv":117157.51,"id":228749},{"trd":[[5.3,40.09]],"tv":7571.74,"id":2857977}],"tv":124729.25}]}
{"op":"mcm","clk":"AIegtAkAuJylCgD31aQK","pt":1657541958004,"mc":[{"id":"1.200806927","rc":[{"atb":[[1.2,816.51]],"trd":[[1.2,5760.37]],"ltp":1.2,"tv":117161.71,"id":228749}],"tv":124733.45}]}
{"op":"mcm","clk":"AL+gtAkA35ylCgCO1qQK","pt":1657541958547,"mc":[{"id":"1.200806927","rc":[{"atb":[[1.18,2.63]],"id":228749}]}]}
{"op":"mcm","clk":"AMagtAkA6ZylCgCQ1qQK","pt":1657541958638,"mc":[{"id":"1.200806927","rc":[{"atl":[[1.23,119.56]],"id":228749}]}]}
{"op":"mcm","clk":"AOCgtAkAg52lCgCe1qQK","pt":1657541958951,"mc":[{"id":"1.200806927","rc":[{"atb":[[1.2,812.2]],"trd":[[1.2,5769]],"tv":117170.34,"id":228749}],"tv":124742.08}]}
{"op":"mcm","clk":"AOegtAkAjp2lCgCj1qQK","pt":1657541959009,"mc":[{"id":"1.200806927","rc":[{"atl":[[1.22,0.53]],"id":228749},{"atl":[[6,10.33]],"trd":[[6,15.73]],"ltp":6,"tv":7572.25,"id":2857977}],"tv":124742.59}]}
{"op":"mcm","clk":"AOahtAkA+Z2lCgDc1qQK","pt":1657541960413,"mc":[{"id":"1.200806927","rc":[{"atb":[[1.2,810.4]],"trd":[[1.2,5772.59]],"tv":117173.93,"id":228749}],"tv":124746.18}]}
{"op":"mcm","clk":"APGhtAkAgZ6lCgDj1qQK","pt":1657541960521,"mc":[{"id":"1.200806927","rc":[{"atb":[[1.2,808.82]],"trd":[[1.2,5775.76]],"tv":117177.1,"id":228749}],"tv":124749.35}]}
{"op":"mcm","clk":"AK6itAkArp6lCgD21qQK","pt":1657541961038,"mc":[{"id":"1.200806927","rc":[{"atb":[[1.2,806.22]],"trd":[[1.2,5780.94]],"tv":117182.28,"id":228749}],"tv":124754.53}]}
{"op":"mcm","clk":"ALeitAkAt56lCgD91qQK","pt":1657541961153,"mc":[{"id":"1.200806927","rc":[{"atl":[[6.2,0.43]],"id":2857977}]}]}
{"op":"mcm","clk":"ANSitAkAzZ6lCgCM16QK","pt":1657541961456,"mc":[{"id":"1.200806927","rc":[{"atb":[[1.2,803.59]],"trd":[[1.2,5786.2]],"tv":117187.54,"id":228749}],"tv":124759.79}]}
{"op":"mcm","clk":"AOWitAkA456lCgCV16QK","pt":1657541961619,"mc":[{"id":"1.200806927","rc":[{"atl":[[1.22,0],[1.23,93.79]],"id":228749}]}]}
{"op":"mcm","clk":"AJGjtAkAip+lCgCi16QK","pt":1657541962027,"mc":[{"id":"1.200806927","rc":[{"atb":[[1.2,803.16]],"trd":[[1.2,5787.06]],"tv":117188.4,"id":228749}],"tv":124760.65}]}
{"op":"mcm","clk":"AJ6jtAkAk5+lCgCl16QK","pt":1657541962133,"mc":[{"id":"1.200806927","rc":[{"atb":[[1.2,537.99]],"trd":[[1.2,6317.4]],"tv":117718.74,"id":228749}],"tv":125290.99}]}
{"op":"mcm","clk":"ALujtAkAqJ+lCgCx16QK","pt":1657541962456,"mc":[{"id":"1.200806927","rc":[{"atb":[[1.2,535.36]],"trd":[[1.2,6322.66]],"tv":117724,"id":228749}],"tv":125296.25}]}
{"op":"mcm","clk":"ANejtAkAv5+lCgDB16QK","pt":1657541962771,"mc":[{"id":"1.200806927","rc":[{"atb":[[1.2,534.51]],"atl":[[1.23,92.3]],"trd":[[1.23,1514.2],[1.2,6324.35]],"tv":117727.18,"id":228749},{"trd":[[5.3,40.43]],"ltp":5.3,"tv":7572.59,"id":2857977}],"tv":125299.77}]}
{"op":"mcm","clk":"AKWktAkA/5+lCgDk16QK","pt":1657541963655,"mc":[{"id":"1.200806927","rc":[{"atb":[[1.2,526.51]],"id":228749}]}]}
{"op":"mcm","clk":"AK6ktAkAjaClCgDn16QK","pt":1657541963748,"mc":[{"id":"1.200806927","rc":[{"atb":[[1.17,13.55]],"id":228749}]}]}
{"op":"mcm","clk":"ANCktAkAqqClCgDw16QK","pt":1657541964163,"mc":[{"id":"1.200806927","rc":[{"atb":[[1.2,316.14]],"trd":[[1.2,6745.09]],"tv":118147.92,"id":228749}],"tv":125720.51}]}
{"op":"mcm","clk":"ANektAkAs6ClCgDz16QK","pt":1657541964224,"mc":[{"id":"1.200806927","rc":[{"atb":[[1.2,314.13]],"trd":[[1.2,6749.1]],"tv":118151.93,"id":228749}],"tv":125724.52}]}
{"op":"mcm","clk":"AKKltAkA8qClCgCb2KQK","pt":1657541965060,"mc":[{"id":"1.200806927","rc":[{"atb":[[1.2,312.82]],"trd":[[1.2,6751.72]],"tv":118154.55,"id":228749}],"tv":125727.14}]}
{"op":"mcm","clk":"ALWltAkA/6ClCgCm2KQK","pt":1657541965254,"mc":[{"id":"1.200806927","rc":[{"atb":[[1.2,310.85]],"trd":[[1.2,6755.67]],"tv":118158.5,"id":228749}],"tv":125731.09}]}
{"op":"mcm","clk":"ANGltAkAmqGlCgC62KQK","pt":1657541965520,"mc":[{"id":"1.200806927","rc":[{"atl":[[1.22,25.74]],"id":228749}]}]}
{"op":"mcm","clk":"APiltAkAuqGlCgDY2KQK","pt":1657541965949,"mc":[{"id":"1.200806927","rc":[{"atb":[[1.2,58.71]],"id":228749}]}]}
{"op":"mcm","clk":"ANumtAkAi6KlCgCH2aQK","pt":1657541966739,"mc":[{"id":"1.200806927","rc":[{"atb":[[1.2,57.71]],"trd":[[1.2,6757.67]],"tv":118160.5,"id":228749}],"tv":125733.09}]}
{"op":"mcm","clk":"APKmtAkAr6KlCgCX2aQK","pt":1657541967025,"mc":[{"id":"1.200806927","rc":[{"atl":[[1.23,97.56]],"id":228749}]}]}
{"op":"mcm","clk":"AICotAkAwKOlCgCD2qQK","pt":1657541968550,"mc":[{"id":"1.200806927","rc":[{"atl":[[1.21,3.11]],"id":228749}]}]}
{"op":"mcm","clk":"AN+otAkAkKSlCgDB2qQK","pt":1657541969548,"mc":[{"id":"1.200806927","rc":[{"atb":[[1.2,52.45]],"id":228749}]}]}
{"op":"mcm","clk":"AOCptAkAjaWlCgCA26QK","pt":1657541970971,"mc":[{"id":"1.200806927","rc":[{"atb":[[1.18,4.79]],"id":228749}]}]}
{"op":"mcm","clk":"AOSptAkAmaWlCgCF26QK","pt":1657541971060,"mc":[{"id":"1.200806927","rc":[{"atb":[[1.23,125.73],[1.2,51.4]],"atl":[[1.22,0],[1.23,0],[1.21,0]],"trd":[[1.22,1131.47],[1.23,1709.32],[1.21,183.74]],"ltp":1.23,"tv":118413.33,"id":228749}],"tv":125985.92}]}
{"op":"mcm","clk":"AN+qtAkAjKalCgC926QK","pt":1657541972290,"mc":[{"id":"1.200806927","rc":[{"atb":[[1.23,120.47]],"trd":[[1.23,1719.83]],"tv":118423.84,"id":228749}],"tv":125996.43}]}
{"op":"mcm","clk":"AOiqtAkAkqalCgC/26QK","pt":1657541972378,"mc":[{"id":"1.200806927","rc":[{"atb":[[1.23,118.47]],"trd":[[1.23,1723.84]],"tv":118427.85,"id":228749}],"tv":126000.44}]}
{"op":"mcm","clk":"AKGrtAkAyaalCgDc26QK","pt":1657541972962,"mc":[{"id":"1.200806927","rc":[{"atb":[[1.23,111.63]],"trd":[[1.23,1737.52]],"tv":118441.53,"id":228749}],"tv":126014.12}]}
{"op":"mcm","clk":"AMmrtAkA5qalCgDr26QK","pt":1657541973364,"mc":[{"id":"1.200806927","rc":[{"atb":[[1.23,117.15]],"id":228749}]}]}
{"op":"mcm","clk":"AOCrtAkA/KalCgDz26QK","pt":1657541973577,"mc":[{"id":"1.200806927","rc":[{"atb":[[1.19,22.55]],"id":228749}]}]}
{"op":"mcm","clk":"APirtAkAkKelCgD/26QK","pt":1657541973790,"mc":[{"id":"1.200806927","rc":[{"atb":[[1.2,55.29]],"id":228749}]}]}
{"op":"mcm","clk":"AIWstAkAmaelCgCD3KQK","pt":1657541973884,"mc":[{"id":"1.200806927","rc":[{"atb":[[1.23,71.6]],"trd":[[1.23,1828.15]],"tv":118532.16,"id":228749},{"trd":[[5.4,14.44]],"ltp":5.4,"tv":7572.69,"id":2857977}],"tv":126104.85}]}
{"op":"mcm","clk":"ALystAkA2KelCgCf3KQK","pt":1657541974467,"mc":[{"id":"1.200806927","rc":[{"atb":[[1.22,10.52]],"id":228749}]}]}
{"op":"mcm","clk":"ANSstAkA86elCgCy3KQK","pt":1657541974696,"mc":[{"id":"1.200806927","rc":[{"atb":[[1.22,0],[1.23,0],[1.2,0]],"atl":[[1.2,21.31]],"trd":[[1.23,1960.31],[1.2,6811.01]],"ltp":1.2,"tv":118717.66,"id":228749},{"atl":[[6,0]],"trd":[[6,26.06]],"ltp":6,"tv":7583.02,"id":2857977}],"tv":126300.68}]}
{"op":"mcm","clk":"AIyttAkAqqilCgDa3KQK","pt":1657541975355,"mc":[{"id":"1.200806927","rc":[{"atl":[[1.2,0.27]],"id":228749}]}]}
{"op":"mcm","clk":"AIOutAkAg6mlCgCc3aQK","pt":1657541976457,"mc":[{"id":"1.200806927","rc":[{"atl":[[1.2,0.8]],"id":228749}]}]}
{"op":"mcm","clk":"AKGutAkApqmlCgCs3aQK","pt":1657541976863,"mc":[{"id":"1.200806927","rc":[{"atl":[[10,0]],"id":2857977}]}]}
{"op":"mcm","clk":"AO+vtAkA46qlCgCV3qQK","pt":1657541978980,"mc":[{"id":"1.200806927","rc":[{"atl":[[1.33,0]],"id":228749}]}]}
{"op":"mcm","clk":"AIawtAkAgKulCgCd3qQK","pt":1657541979312,"mc":[{"id":"1.200806927","rc":[{"atl":[[1.2,0]],"trd":[[1.2,6811.81]],"tv":118718.46,"id":228749},{"atl":[[6,0.7]],"trd":[[6,26.22]],"tv":7583.18,"id":2857977}],"tv":126301.64}]}
{"op":"mcm","clk":"AMCwtAkAwqulCgC83qQK","pt":1657541979945,"mc":[{"id":"1.200806927","rc":[{"atl":[[1.2,1.75]],"trd":[[1.2,6815.32]],"tv":118721.97,"id":228749},{"atl":[[6,0]],"trd":[[6,26.93]],"tv":7583.89,"id":2857977}],"tv":126305.86}]}
{"op":"mcm","clk":"AKqxtAkAr6ylCgD73qQK","pt":1657541980847,"mc":[{"id":"1.200806927","rc":[{"atl":[[1000,0.26]],"id":228749}]}]}
{"op":"mcm","clk":"AM2xtAkA2aylCgCW36QK","pt":1657541981170,"mc":[{"id":"1.200806927","rc":[{"atl":[[1.23,0.53]],"id":228749}]}]}
{"op":"mcm","clk":"ANaxtAkA5aylCgCZ36QK","pt":1657541981272,"mc":[{"id":"1.200806927","rc":[{"atl":[[1000,0.13]],"id":228749}]}]}
{"op":"mcm","clk":"APyxtAkAga2lCgCs36QK","pt":1657541981683,"mc":[{"id":"1.200806927","rc":[{"atl":[[8.2,0]],"id":2857977}]}]}
{"op":"mcm","clk":"ALaytAkAp62lCgDI36QK","pt":1657541982250,"mc":[{"id":"1.200806927","rc":[{"atl":[[1.22,0.53]],"id":228749}]}]}
{"op":"mcm","clk":"AMOytAkAr62lCgDR36QK","pt":1657541982378,"mc":[{"id":"1.200806927","rc":[{"atl":[[1.23,271.02]],"id":228749}]}]}
{"op":"mcm","clk":"ANKytAkAvK2lCgDc36QK","pt":1657541982583,"mc":[{"id":"1.200806927","rc":[{"atl":[[1.23,271.55]],"id":228749}]}]}
{"op":"mcm","clk":"AOmytAkAza2lCgDo36QK","pt":1657541982775,"mc":[{"id":"1.200806927","rc":[{"atl":[[1.23,274.18]],"id":228749}]}]}
{"op":"mcm","clk":"AIiztAkA8K2lCgD/36QK","pt":1657541983187,"mc":[{"id":"1.200806927","rc":[{"atb":[[1.21,3.51]],"atl":[[1.2,0]],"id":228749}]}]}
{"op":"mcm","clk":"ANC0tAkAp6+lCgDk4KQK","pt":1657541985291,"mc":[{"id":"1.200806927","rc":[{"atl":[[1.24,220.71]],"id":228749}]}]}
{"op":"mcm","clk":"APi0tAkAxq+lCgD44KQK","pt":1657541985671,"mc":[{"id":"1.200806927","rc":[{"atl":[[1.22,0],[1.23,269.45]],"id":228749}]}]}
{"op":"mcm","clk":"ANC1tAkAhLClCgCc4aQK","pt":1657541986398,"mc":[{"id":"1.200806927","rc":[{"atl":[[1.23,269.58]],"id":228749}]}]}
{"op":"mcm","clk":"ANm1tAkAjrClCgCg4aQK","pt":1657541986475,"mc":[{"id":"1.200806927","rc":[{"atb":[[1.19,27.06]],"id":228749}]}]}
{"op":"mcm","clk":"APS1tAkAq7ClCgCs4aQK","pt":1657541986778,"mc":[{"id":"1.200806927","rc":[{"atl":[[6,42.27]],"id":2857977}]}]}
{"op":"mcm","clk":"AIW2tAkAvLClCgC44aQK","pt":1657541986986,"mc":[{"id":"1.200806927","rc":[{"atl":[[1.23,274.71]],"id":228749}]}]}
{"op":"mcm","clk":"ANW2tAkAhLGlCgDz4aQK","pt":1657541987878,"mc":[{"id":"1.200806927","rc":[{"atb":[[1.2,8.01]],"id":228749}]}]}
{"op":"mcm","clk":"AN+2tAkAkbGlCgD34aQK","pt":1657541987976,"mc":[{"id":"1.200806927","rc":[{"atl":[[1.23,301.76]],"id":228749}]}]}
{"op":"mcm","clk":"AKm3tAkAx7GlCgCm4qQK","pt":1657541988675,"mc":[{"id":"1.200806927","rc":[{"atl":[[1.23,300.18]],"id":228749}]}]}
{"op":"mcm","clk":"APC3tAkAibKlCgDD4qQK","pt":1657541989390,"mc":[{"id":"1.200806927","rc":[{"atb":[[1.21,0.88]],"id":228749}]}]}
{"op":"mcm","clk":"APe4tAkA9LKlCgCi46QK","pt":1657541990763,"mc":[{"id":"1.200806927","rc":[{"atl":[[6.6,15.44]],"id":2857977}]}]}
{"op":"mcm","clk":"AMK5tAkAvLOlCgDa46QK","pt":1657541991601,"mc":[{"id":"1.200806927","rc":[{"atl":[[1.23,301.23]],"id":228749}]}]}
{"op":"mcm","clk":"AOi5tAkA3rOlCgDw46QK","pt":1657541991978,"mc":[{"id":"1.200806927","rc":[{"atb":[[1.21,0],[1.2,0]],"atl":[[1.2,186.46]],"trd":[[1.21,185.5],[1.2,7042.68]],"tv":118951.09,"id":228749},{"atl":[[6,0]],"trd":[[6,69.2]],"tv":7626.16,"id":2857977}],"tv":126577.25}]}
{"op":"mcm","clk":"AJO6tAkA/7OlCgCG5KQK","pt":1657541992397,"mc":[{"id":"1.200806927","rc":[{"atl":[[1.24,221.24]],"id":228749}]}]}
{"op":"mcm","clk":"APq7tAkA1bWlCgCV5aQK","pt":1657541995061,"mc":[{"id":"1.200806927","rc":[{"atl":[[1.2,185.41]],"trd":[[1.2,7044.78]],"tv":118953.19,"id":228749}],"tv":126579.35}]}
{"op":"mcm","clk":"AKK8tAkA9LWlCgCs5aQK","pt":1657541995406,"mc":[{"id":"1.200806927","rc":[{"atl":[[1.2,184.88]],"trd":[[1.2,7045.31]],"tv":118953.72,"id":228749},{"atl":[[8.6,0]],"trd":[[6,69.3]],"tv":7626.26,"id":2857977}],"tv":126579.98}]}
{"op":"mcm","clk":"ALS8tAkAhLalCgC25aQK","pt":1657541995586,"mc":[{"id":"1.200806927","rc":[{"atb":[[1.18,15.31]],"id":228749}]}]}
{"op":"mcm","clk":"AKy9tAkA6ralCgDm5aQK","pt":1657541996786,"mc":[{"id":"1.200806927","rc":[{"atl":[[1.23,301.36]],"id":228749}]}]}
{"op":"mcm","clk":"ALy9tAkA+LalCgDt5aQK","pt":1657541996977,"mc":[{"id":"1.200806927","rc":[{"atl":[[1.23,298.73]],"id":228749}]}]}
{"op":"mcm","clk":"APm9tAkAsrelCgCB5qQK","pt":1657541997713,"mc":[{"id":"1.200806927","rc":[{"atl":[[1.21,0.52]],"id":228749}]}]}
{"op":"mcm","clk":"ANS+tAkAirilCgCv5qQK","pt":1657541998774,"mc":[{"id":"1.200806927","rc":[{"atl":[[1.21,2.32]],"id":228749}]}]}
{"op":"mcm","clk":"AIa/tAkAx7ilCgDJ5qQK","pt":1657541999198,"mc":[{"id":"1.200806927","rc":[{"atl":[[1.2,153.33]],"trd":[[1.2,7108.41]],"tv":119016.82,"id":228749}],"tv":126643.08}]}
{"op":"mcm","clk":"AI+/tAkAz7ilCgDM5qQK","pt":1657541999306,"mc":[{"id":"1.200806927","rc":[{"atl":[[1.2,150.7]],"trd":[[1.2,7113.67]],"tv":119022.08,"id":228749}],"tv":126648.34}]}
{"op":"mcm","clk":"AKe/tAkA67ilCgDX5qQK","pt":1657541999583,"mc":[{"id":"1.200806927","rc":[{"atl":[[6.2,10.95]],"id":2857977}]}]}
{"op":"mcm","clk":"ALO/tAkA97ilCgDa5qQK","pt":1657541999687,"mc":[{"id":"1.200806927","rc":[{"atl":[[1.2,149.62]],"trd":[[1.2,7114.75]],"tv":119023.16,"id":228749},{"trd":[[6,69.52]],"tv":7626.48,"id":2857977}],"tv":126649.64}]}
{"op":"mcm","clk":"AIPAtAkAyLmlCgD65qQK","pt":1657542000575,"mc":[{"id":"1.200806927","rc":[{"atl":[[1.2,148.98]],"trd":[[1.2,7115.4]],"tv":119023.81,"id":228749},{"trd":[[6,69.65]],"tv":7626.61,"id":2857977}],"tv":126650.42}]}
{"op":"mcm","clk":"AKjAtAkA77mlCgCR56QK","pt":1657542001001,"mc":[{"id":"1.200806927","rc":[{"atb":[[1.19,40.01]],"id":228749}]}]}
{"op":"mcm","clk":"AOjAtAkAsLqlCgC156QK","pt":1657542001675,"mc":[{"id":"1.200806927","rc":[{"atl":[[1.2,147.97]],"trd":[[1.2,7116.4]],"tv":119024.81,"id":228749},{"trd":[[6,69.85]],"tv":7626.81,"id":2857977}],"tv":126651.62}]}
{"op":"mcm","clk":"AI7BtAkA1bqlCgDI56QK","pt":1657542002185,"mc":[{"id":"1.200806927","rc":[{"atl":[[1.21,3.15]],"id":228749}]}]}
{"op":"mcm","clk":"AL7BtAkA+7qlCgDX56QK","pt":1657542002699,"mc":[{"id":"1.200806927","rc":[{"atl":[[1.21,3.68]],"id":228749}]}]}
{"op":"mcm","clk":"ANTBtAkAlLulCgDd56QK","pt":1657542002969,"mc":[{"id":"1.200806927","rc":[{"atl":[[1.2,146.17]],"trd":[[1.2,7120]],"tv":119028.41,"id":228749}],"tv":126655.22}]}
{"op":"mcm","clk":"AOHBtAkAnrulCgDg56QK","pt":1657542003086,"mc":[{"id":"1.200806927","rc":[{"atl":[[1.2,145.64]],"trd":[[1.2,7120.53]],"tv":119028.94,"id":228749},{"trd":[[6,69.95]],"tv":7626.91,"id":2857977}],"tv":126655.85}]}
{"op":"mcm","clk":"AIrCtAkAz7ulCgDy56QK","pt":1657542003597,"mc":[{"id":"1.200806927","rc":[{"atl":[[1.2,0]],"trd":[[1.2,7266.17]],"tv":119174.58,"id":228749},{"atl":[[6,23.46]],"trd":[[6,99.08]],"tv":7656.04,"id":2857977}],"tv":126830.62}]}
{"op":"mcm","clk":"AJTCtAkA27ulCgD256QK","pt":1657542003710,"mc":[{"id":"1.200806927","rc":[{"atb":[[1.2,52.59]],"id":228749}]}]}
{"op":"mcm","clk":"ALvCtAkA/rulCgCJ6KQK","pt":1657542004068,"mc":[{"id":"1.200806927","rc":[{"atl":[[6,23.63]],"id":2857977}]}]}
{"op":"mcm","clk":"AMbCtAkAi7ylCgCR6KQK","pt":1657542004176,"mc":[{"id":"1.200806927","rc":[{"atb":[[1.2,78.89]],"id":228749}]}]}
{"op":"mcm","clk":"AOHCtAkApbylCgCd6KQK","pt":1657542004468,"mc":[{"id":"1.200806927","rc":[{"atl":[[5.8,0.43]],"id":2857977}]}]}
{"op":"mcm","clk":"AJzDtAkAy7ylCgC66KQK","pt":1657542004998,"mc":[{"id":"1.200806927","rc":[{"atl":[[6,23.96]],"id":2857977}]}]}
{"op":"mcm","clk":"ALbDtAkA2rylCgDC6KQK","pt":1657542005211,"mc":[{"id":"1.200806927","rc":[{"atb":[[1.2,80.89]],"id":228749}]}]}
{"op":"mcm","clk":"ANLDtAkA9bylCgDM6KQK","pt":1657542005459,"mc":[{"id":"1.200806927","rc":[{"atb":[[1.2,96.67]],"id":228749}]}]}
{"op":"mcm","clk":"AIzEtAkAsr2lCgDj6KQK","pt":1657542006085,"mc":[{"id":"1.200806927","rc":[{"atl":[[6,24.06]],"id":2857977}]}]}
{"op":"mcm","clk":"AJvEtAkAur2lCgDn6KQK","pt":1657542006198,"mc":[{"id":"1.200806927","rc":[{"atl":[[1.21,2.52]],"id":228749}]}]}
{"op":"mcm","clk":"AKfEtAkAw72lCgDr6KQK","pt":1657542006303,"mc":[{"id":"1.200806927","rc":[{"atb":[[1.2,97.41]],"id":228749}]}]}
{"op":"mcm","clk":"AK3EtAkAy72lCgDs6KQK","pt":1657542006398,"mc":[{"id":"1.200806927","rc":[{"atb":[[1.2,96.88]],"id":228749}]}]}
{"op":"mcm","clk":"ALXEtAkA172lCgDy6KQK","pt":1657542006516,"mc":[{"id":"1.200806927","rc":[{"atb":[[1.2,99.09]],"id":228749}]}]}
{"op":"mcm","clk":"AMHEtAkA5L2lCgD16KQK","pt":1657542006624,"mc":[{"id":"1.200806927","rc":[{"atb":[[1.2,97.09]],"id":228749}]}]}
{"op":"mcm","clk":"AObEtAkAk76lCgCP6aQK","pt":1657542006981,"mc":[{"id":"1.200806927","rc":[{"atl":[[1.25,2.63]],"id":228749}]}]}
{"op":"mcm","clk":"APDEtAkAnL6lCgCS6aQK","pt":1657542007084,"mc":[{"id":"1.200806927","rc":[{"atb":[[1.2,107.61]],"id":228749}]}]}
{"op":"mcm","clk":"AJXFtAkAxb6lCgCe6aQK","pt":1657542007503,"mc":[{"id":"1.200806927","rc":[{"atb":[[1.2,118.13]],"id":228749}]}]}
{"op":"mcm","clk":"AKXFtAkA176lCgCn6aQK","pt":1657542007717,"mc":[{"id":"1.200806927","rc":[{"atb":[[1.2,120.76]],"id":228749},{"atl":[[6,24.59]],"id":2857977}]}]}
{"op":"mcm","clk":"AMHFtAkA8b6lCgC36aQK","pt":1657542008028,"mc":[{"id":"1.200806927","rc":[{"atl":[[1.23,293.47]],"id":228749}]}]}
{"op":"mcm","clk":"APnGtAkAxsClCgCL6qQK","pt":1657542010032,"mc":[{"id":"1.200806927","rc":[{"atl":[[6,24.72]],"id":2857977}]}]}
{"op":"mcm","clk":"AIXHtAkA1cClCgCO6qQK","pt":1657542010219,"mc":[{"id":"1.200806927","rc":[{"atl":[[1.4,12.87]],"id":228749}]}]}
{"op":"mcm","clk":"AJnHtAkA6cClCgCY6qQK","pt":1657542010424,"mc":[{"id":"1.200806927","rc":[{"atl":[[6,24.83]],"id":2857977}]}]}
{"op":"mcm","clk":"AKPHtAkA9MClCgCb6qQK","pt":1657542010483,"mc":[{"id":"1.200806927","rc":[{"atb":[[1.2,118.13]],"id":228749}]}]}
{"op":"mcm","clk":"AKvHtAkA/MClCgCe6qQK","pt":1657542010585,"mc":[{"id":"1.200806927","rc":[{"atb":[[1.2,102.35]],"id":228749}]}]}
{"op":"mcm","clk":"AJ7ItAkA18GlCgDR6qQK","pt":1657542011759,"mc":[{"id":"1.200806927","rc":[{"atb":[[1.2,110.24]],"id":228749},{"atl":[[5.8,0]],"id":2857977}],"con":true}]}
{"op":"mcm","clk":"AN/ItAkAn8KlCgDy6qQK","pt":1657542012640,"mc":[{"id":"1.200806927","rc":[{"atb":[[1.21,2.74]],"atl":[[1.21,0]],"id":228749}]}]}
{"op":"mcm","clk":"AIrJtAkA0MKlCgCD66QK","pt":1657542013107,"mc":[{"id":"1.200806927","rc":[{"atb":[[1.2,109.34]],"id":228749}]}]}
{"op":"mcm","clk":"APTJtAkAqcOlCgCu66QK","pt":1657542014222,"mc":[{"id":"1.200806927","rc":[{"atb":[[1.21,0.94]],"id":228749}]}]}
{"op":"mcm","clk":"AIbKtAkAusOlCgCz66QK","pt":1657542014425,"mc":[{"id":"1.200806927","rc":[{"atb":[[1.2,108.03]],"id":228749}]}]}
{"op":"mcm","clk":"ALjKtAkA8sOlCgDM66QK","pt":1657542014998,"mc":[{"id":"1.200806927","rc":[{"atb":[[1.21,0],[1.2,104.05]],"trd":[[1.21,187.38],[1.2,7274.13]],"tv":119184.42,"id":228749}],"tv":126840.46}]}
{"op":"mcm","clk":"AMfKtAkAh8SlCgDU66QK","pt":1657542015223,"mc":[{"id":"1.200806927","rc":[{"atb":[[1.2,51.46]],"id":228749}]}]}
{"op":"mcm","clk":"ANLKtAkAkMSlCgDZ66QK","pt":1657542015317,"mc":[{"id":"1.200806927","rc":[{"atl":[[6.2,10.52]],"id":2857977}]}]}
{"op":"mcm","clk":"AI/LtAkAysSlCgDs66QK","pt":1657542015996,"mc":[{"id":"1.200806927","rc":[{"atb":[[1.2,50.86]],"trd":[[1.2,7275.33]],"tv":119185.62,"id":228749}],"tv":126841.66}]}
{"op":"mcm","clk":"ALbLtAkA8sSlCgD966QK","pt":1657542016422,"mc":[{"id":"1.200806927","rc":[{"atl":[[6,25.36]],"id":2857977}]}]}
{"op":"mcm","clk":"ANLLtAkAicWlCgCF7KQK","pt":1657542016733,"mc":[{"id":"1.200806927","rc":[{"atl":[[6,26.22]],"id":2857977}]}]}
{"op":"mcm","clk":"AIDMtAkAscWlCgCR7KQK","pt":1657542017103,"mc":[{"id":"1.200806927","rc":[{"atl":[[1.25,0.53]],"id":228749}]}]}
{"op":"mcm","clk":"ANfMtAkA+MWlCgC07KQK","pt":1657542017934,"mc":[{"id":"1.200806927","rc":[{"atl":[[1.23,293.01]],"trd":[[1.23,1960.77]],"ltp":1.23,"tv":119186.08,"id":228749},{"trd":[[5.3,40.54]],"ltp":5.3,"tv":7656.15,"id":2857977}],"tv":126842.23}]}
{"op":"mcm","clk":"AOXMtAkAg8alCgC67KQK","pt":1657542018055,"mc":[{"id":"1.200806927","rc":[{"atb":[[1.2,50.33]],"id":228749}]}]}
{"op":"mcm","clk":"APfMtAkAj8alCgDF7KQK","pt":1657542018193,"mc":[{"id":"1.200806927","rc":[{"atb":[[1.2,60.85]],"id":228749}]}]}
{"op":"mcm","clk":"APnNtAkAj8elCgCU7aQK","pt":1657542019714,"mc":[{"id":"1.200806927","rc":[{"atb":[[1.2,34.55]],"id":228749}]}]}
{"op":"mcm","clk":"AKbOtAkAucelCgCw7aQK","pt":1657542020227,"mc":[{"id":"1.200806927","rc":[{"atb":[[1.2,18.77]],"id":228749}]}]}
{"op":"mcm","clk":"AIrQtAkAnMmlCgCk7qQK","pt":1657542022772,"mc":[{"id":"1.200806927","rc":[{"atb":[[1.2,18.57]],"trd":[[1.2,7275.73]],"ltp":1.2,"tv":119186.48,"id":228749}],"tv":126842.63}]}
{"op":"mcm","clk":"ANPQtAkA18mlCgDG7qQK","pt":1657542023442,"mc":[{"id":"1.200806927","rc":[{"atb":[[1.2,17.52]],"id":228749}]}]}
{"op":"mcm","clk":"AIXRtAkAh8qlCgDe7qQK","pt":1657542023949,"mc":[{"id":"1.200806927","rc":[{"atl":[[1.21,2.63]],"id":228749}]}]}
{"op":"mcm","clk":"AK7RtAkAq8qlCgDw7qQK","pt":1657542024432,"mc":[{"id":"1.200806927","rc":[{"atb":[[1.2,18.57]],"id":228749}]}]}
{"op":"mcm","clk":"AL7RtAkAscqlCgDy7qQK","pt":1657542024542,"mc":[{"id":"1.200806927","rc":[{"atl":[[1.21,2.1]],"id":228749}]}]}
{"op":"mcm","clk":"AKrStAkAi8ulCgCT76QK","pt":1657542025550,"mc":[{"id":"1.200806927","rc":[{"atb":[[1.08,5.78]],"id":228749}]}]}
{"op":"mcm","clk":"AMvStAkArMulCgCf76QK","pt":1657542025845,"mc":[{"id":"1.200806927","rc":[{"atb":[[1.2,15.94]],"id":228749}]}]}
{"op":"mcm","clk":"AObStAkAvsulCgCo76QK","pt":1657542026061,"mc":[{"id":"1.200806927","rc":[{"atl":[[1.23,293.54]],"id":228749}]}]}
{"op":"mcm","clk":"AO7StAkAx8ulCgCs76QK","pt":1657542026160,"mc":[{"id":"1.200806927","rc":[{"atl":[[1.21,1.6]],"trd":[[1.21,187.88]],"ltp":1.21,"tv":119186.98,"id":228749},{"atl":[[6,25.69]],"trd":[[5.7,19.89]],"ltp":5.7,"tv":7656.25,"id":2857977}],"tv":126843.23}]}
{"op":"mcm","clk":"APvStAkAzsulCgCu76QK","pt":1657542026265,"mc":[{"id":"1.200806927","rc":[{"atl":[[6,25.56]],"id":2857977}]}]}
{"op":"mcm","clk":"AIXTtAkA0sulCgCx76QK","pt":1657542026363,"mc":[{"id":"1.200806927","rc":[{"atb":[[1.2,5.42]],"id":228749}]}]}
{"op":"mcm","clk":"AK/TtAkA98ulCgC976QK","pt":1657542026731,"mc":[{"id":"1.200806927","rc":[{"atb":[[1.15,210.32]],"id":228749}]}]}
{"op":"mcm","clk":"AMrTtAkAkcylCgDJ76QK","pt":1657542027039,"mc":[{"id":"1.200806927","rc":[{"atl":[[1.23,293.01]],"id":228749}]}]}
{"op":"mcm","clk":"ANnVtAkA282lCgDY8KQK","pt":1657542029653,"mc":[{"id":"1.200806927","rc":[{"atl":[[1.23,291.98],[1.21,0]],"id":228749}]}]}
{"op":"mcm","clk":"APvVtAkA+s2lCgDs8KQK","pt":1657542030068,"mc":[{"id":"1.200806927","rc":[{"atl":[[6,25.99]],"id":2857977}]}]}
{"op":"mcm","clk":"AI7WtAkAj86lCgD38KQK","pt":1657542030257,"mc":[{"id":"1.200806927","rc":[{"atl":[[7.2,5.26]],"id":2857977}]}]}
{"op":"mcm","clk":"AKPWtAkApM6lCgD/8KQK","pt":1657542030425,"mc":[{"id":"1.200806927","rc":[{"atb":[[1.2,0.16]],"id":228749}]}]}
{"op":"mcm","clk":"AOvWtAkA286lCgCc8aQK","pt":1657542031079,"mc":[{"id":"1.200806927","rc":[{"atb":[[5.8,0.53]],"id":2857977}]}]}
{"op":"mcm","clk":"AKHXtAkA/M6lCgCy8aQK","pt":1657542031457,"mc":[{"id":"1.200806927","rc":[{"atb":[[1.2,0]],"trd":[[1.2,7278.2]],"ltp":1.2,"tv":119189.45,"id":228749},{"atl":[[6,25.5]],"trd":[[6,99.57]],"ltp":6,"tv":7656.74,"id":2857977}],"tv":126846.19}]}
{"op":"mcm","clk":"ALTXtAkAks+lCgC78aQK","pt":1657542031643,"mc":[{"id":"1.200806927","rc":[{"atl":[[1.23,290.93]],"id":228749}]}]}
{"op":"mcm","clk":"AMbXtAkAqc+lCgDB8aQK","pt":1657542031858,"mc":[{"id":"1.200806927","rc":[{"atb":[[1.2,0.85]],"id":228749}]}]}
{"op":"mcm","clk":"ANXXtAkAts+lCgDN8aQK","pt":1657542031995,"mc":[{"id":"1.200806927","rc":[{"atl":[[1.21,0.73]],"id":228749}]}]}
{"op":"mcm","clk":"AJDYtAkA+8+lCgDp8aQK","pt":1657542032529,"mc":[{"id":"1.200806927","rc":[{"atb":[[1.2,0]],"trd":[[1.2,7281.15]],"tv":119192.4,"id":228749},{"atl":[[6,25.25]],"trd":[[6,99.82]],"tv":7656.99,"id":2857977}],"tv":126849.39}]}
{"op":"mcm","clk":"ALDYtAkAodClCgD08aQK","pt":1657542032845,"mc":[{"id":"1.200806927","rc":[{"atl":[[6,24.72]],"id":2857977}]}]}
{"op":"mcm","clk":"AL7ZtAkAntGlCgCf8qQK","pt":1657542034264,"mc":[{"id":"1.200806927","rc":[{"atl":[[1.22,5.26]],"id":228749}]}]}
{"op":"mcm","clk":"AMTZtAkAptGlCgCh8qQK","pt":1657542034363,"mc":[{"id":"1.200806927","rc":[{"trd":[[1.2,7281.28]],"tv":119192.53,"id":228749},{"atl":[[6,24.16]],"trd":[[6,99.85]],"tv":7657.02,"id":2857977}],"tv":126849.55}]}
{"op":"mcm","clk":"ANLZtAkArNGlCgCk8qQK","pt":1657542034465,"mc":[{"id":"1.200806927","rc":[{"atl":[[6,24.59]],"id":2857977}]}]}
{"op":"mcm","clk":"APXZtAkAyNGlCgC68qQK","pt":1657542034831,"mc":[{"id":"1.200806927","rc":[{"atl":[[1.21,45.81]],"id":228749}]}]}
{"op":"mcm","clk":"AIbatAkA3dGlCgDG8qQK","pt":1657542035042,"mc":[{"id":"1.200806927","rc":[{"atl":[[1.21,45.08]],"id":228749}]}]}
{"op":"mcm","clk":"ALbatAkAjdKlCgDp8qQK","pt":1657542035575,"mc":[{"id":"1.200806927","rc":[{"atl":[[6.6,15.97]],"id":2857977}]}]}
{"op":"mcm","clk":"ANzbtAkAltOlCgCt86QK","pt":1657542037239,"mc":[{"id":"1.200806927","rc":[{"atl":[[1.21,41.9]],"trd":[[1.21,190.04]],"ltp":1.21,"tv":119194.69,"id":228749}],"tv":126851.71}]}
{"op":"mcm","clk":"AOrbtAkAptOlCgC286QK","pt":1657542037429,"mc":[{"id":"1.200806927","rc":[{"atl":[[1.21,5.09]],"id":228749}]}]}
{"op":"mcm","clk":"ALbctAkA89OlCgDg86QK","pt":1657542038344,"mc":[{"id":"1.200806927","rc":[{"trd":[[1.2,7281.88]],"ltp":1.2,"tv":119195.29,"id":228749},{"atl":[[6,24.47]],"trd":[[6,99.97]],"tv":7657.14,"id":2857977}],"tv":126852.43}]}
{"op":"mcm","clk":"ALXdtAkA59SlCgCb9KQK","pt":1657542039675,"mc":[{"id":"1.200806927","rc":[{"trd":[[1.2,7294.96]],"tv":119208.37,"id":228749},{"atl":[[6,21.85]],"trd":[[6,102.59]],"tv":7659.76,"id":2857977}],"tv":126868.13}]}
{"op":"mcm","clk":"ALDetAkA3tWlCgDb9KQK","pt":1657542041059,"mc":[{"id":"1.200806927","rc":[{"atb":[[5.8,0]],"id":2857977}]}]}
{"op":"mcm","clk":"AL/etAkA7tWlCgDs9KQK","pt":1657542041241,"mc":[{"id":"1.200806927","rc":[{"trd":[[1.2,7296.01]],"tv":119209.42,"id":228749},{"atl":[[6,21.64]],"trd":[[6,102.8]],"tv":7659.97,"id":2857977}],"tv":126869.39}]}
{"op":"mcm","clk":"APvetAkAqtalCgCL9aQK","pt":1657542041867,"mc":[{"id":"1.200806927","rc":[{"atb":[[1.19,46.91]],"id":228749}]}]}
{"op":"mcm","clk":"ALjftAkA5NalCgC19aQK","pt":1657542042665,"mc":[{"id":"1.200806927","rc":[{"atl":[[1.21,4.19]],"id":228749}]}]}
{"op":"mcm","clk":"AM/ftAkAkNelCgDO9aQK","pt":1657542043197,"mc":[{"id":"1.200806927","rc":[{"atl":[[1.23,263.88]],"trd":[[1.2,7297.39]],"tv":119210.8,"id":228749},{"atl":[[6,21.36]],"trd":[[6,103.08]],"tv":7660.25,"id":2857977}],"tv":126871.05}]}
{"op":"mcm","clk":"AOjftAkAldelCgDU9aQK","pt":1657542043254,"mc":[{"id":"1.200806927","rc":[{"trd":[[1.2,7298.34]],"tv":119211.75,"id":228749},{"atl":[[6,21.17]],"trd":[[6,103.27]],"tv":7660.44,"id":2857977}],"tv":126872.19}]}
{"op":"mcm","clk":"AIHgtAkAs9elCgDi9aQK","pt":1657542043549,"mc":[{"id":"1.200806927","rc":[{"atb":[[1.21,1.07]],"atl":[[1.21,0]],"id":228749}]}]}
{"op":"mcm","clk":"AJ3gtAkA2NelCgD29aQK","pt":1657542043961,"mc":[{"id":"1.200806927","rc":[{"atb":[[1.21,106.25]],"id":228749}]}]}
{"op":"mcm","clk":"ALPgtAkA7delCgCH9qQK","pt":1657542044167,"mc":[{"id":"1.200806927","rc":[{"atl":[[1.22,2.87]],"trd":[[1.22,1133.86]],"ltp":1.22,"tv":119214.14,"id":228749},{"trd":[[5.5,25.32]],"ltp":5.5,"tv":7660.97,"id":2857977}],"tv":126875.11}]}
{"op":"mcm","clk":"ANfgtAkAjdilCgCd9qQK","pt":1657542044569,"mc":[{"id":"1.200806927","rc":[{"atb":[[1.21,103.62]],"id":228749}]}]}
{"op":"mcm","clk":"AOTgtAkAlNilCgCi9qQK","pt":1657542044660,"mc":[{"id":"1.200806927","rc":[{"atl":[[1.22,0],[1.23,243.97]],"trd":[[1.22,1136.73],[1.23,1980.68]],"ltp":1.23,"tv":119236.92,"id":228749},{"trd":[[5.5,25.96],[5.3,45.16]],"ltp":5.3,"tv":7666.23,"id":2857977}],"tv":126903.15}]}
{"op":"mcm","clk":"AOvgtAkAo9ilCgCn9qQK","pt":1657542044763,"mc":[{"id":"1.200806927","rc":[{"atb":[[1.21,104.15]],"id":228749}]}]}
{"op":"mcm","clk":"AK7htAkA39ilCgDE9qQK","pt":1657542045436,"mc":[{"id":"1.200806927","rc":[{"atb":[[1.21,105.73]],"id":228749}]}]}
{"op":"mcm","clk":"ANrhtAkA+tilCgDT9qQK","pt":1657542045847,"mc":[{"id":"1.200806927","rc":[{"atb":[[1.21,108.36]],"id":228749}]}]}
{"op":"mcm","clk":"AOrhtAkAgtmlCgDa9qQK","pt":1657542045959,"mc":[{"id":"1.200806927","rc":[{"atb":[[1.21,107.4]],"trd":[[1.21,190.9]],"ltp":1.21,"tv":119237.78,"id":228749}],"tv":126904.01}]}
{"op":"mcm","clk":"AI3itAkAodmlCgDx9qQK","pt":1657542046384,"mc":[{"id":"1.200806927","rc":[{"atb":[[1.19,40.01]],"id":228749}]}]}
{"op":"mcm","clk":"AJbitAkAqNmlCgD09qQK","pt":1657542046475,"mc":[{"id":"1.200806927","rc":[{"atb":[[1.21,106.87]],"id":228749}]}]}
{"op":"mcm","clk":"ALjitAkAwdmlCgCF96QK","pt":1657542046765,"mc":[{"id":"1.200806927","rc":[{"atb":[[1.21,108.45]],"id":228749}]}]}
{"op":"mcm","clk":"APLitAkA7dmlCgCp96QK","pt":1657542047461,"mc":[{"id":"1.200806927","rc":[{"atb":[[1.21,111.08]],"id":228749}]}]}
{"op":"mcm","clk":"AKzjtAkAp9qlCgDJ96QK","pt":1657542048054,"mc":[{"id":"1.200806927","rc":[{"atb":[[1.21,110.35]],"trd":[[1.21,192.37]],"tv":119239.25,"id":228749}],"tv":126905.48}]}
{"op":"mcm","clk":"ALXjtAkAr9qlCgDO96QK","pt":1657542048161,"mc":[{"id":"1.200806927","rc":[{"atl":[[5.7,1.8]],"id":2857977}]}]}
{"op":"mcm","clk":"AP7jtAkA6tqlCgD196QK","pt":1657542048887,"mc":[{"id":"1.200806927","rc":[{"atb":[[1.21,110.24]],"trd":[[1.21,192.58]],"tv":119239.46,"id":228749}],"tv":126905.69}]}
{"op":"mcm","clk":"AJXktAkAidulCgCu+KQK","pt":1657542049195,"mc":[{"id":"1.200806927","rc":[{"atb":[[1.21,110.77]],"id":228749}]}]}
{"op":"mcm","clk":"AKHktAkAkdulCgCx+KQK","pt":1657542049302,"mc":[{"id":"1.200806927","rc":[{"atb":[[1.21,58.18]],"id":228749}]}]}
{"op":"mcm","clk":"ALzktAkAsNulCgDC+KQK","pt":1657542049575,"mc":[{"id":"1.200806927","rc":[{"atb":[[1.21,55.55]],"id":228749}]}]}
{"op":"mcm","clk":"ANDktAkAxdulCgDO+KQK","pt":1657542049782,"mc":[{"id":"1.200806927","rc":[{"atl":[[5.7,1.27]],"id":2857977}]}]}
{"op":"mcm","clk":"AN3ktAkA1NulCgDZ+KQK","pt":1657542049970,"mc":[{"id":"1.200806927","rc":[{"atb":[[1.21,29.25]],"id":228749}]}]}
{"op":"mcm","clk":"AJrltAkAmdylCgD++KQK","pt":1657542050671,"mc":[{"id":"1.200806927","rc":[{"atb":[[1.21,29.78]],"id":228749}]}]}
{"op":"mcm","clk":"AMvltAkA0dylCgCJ+aQK","pt":1657542051180,"mc":[{"id":"1.200806927","rc":[{"atb":[[1.2,1.35]],"id":228749}]}]}
{"op":"mcm","clk":"AJrmtAkAnd2lCgCm+aQK","pt":1657542052056,"mc":[{"id":"1.200806927","rc":[{"atb":[[1.21,27.15]],"id":228749}]}]}
{"op":"mcm","clk":"AMrmtAkAyd2lCgC++aQK","pt":1657542052581,"mc":[{"id":"1.200806927","rc":[{"atb":[[1.21,26.98]],"trd":[[1.21,192.93]],"tv":119239.81,"id":228749}],"tv":126906.04}]}
{"op":"mcm","clk":"AIjntAkAh96lCgDt+aQK","pt":1657542053260,"mc":[{"id":"1.200806927","rc":[{"atb":[[1.21,37.5]],"id":228749}]}]}
{"op":"mcm","clk":"AK3ntAkAp96lCgCC+qQK","pt":1657542053583,"mc":[{"id":"1.200806927","rc":[{"atb":[[1.21,39.34]],"id":228749}]}]}
{"op":"mcm","clk":"ALHntAkAsN6lCgCE+qQK","pt":1657542053676,"mc":[{"id":"1.200806927","rc":[{"atl":[[5.7,0.74]],"id":2857977}]}]}
{"op":"mcm","clk":"APHntAkA+96lCgCk+qQK","pt":1657542054472,"mc":[{"id":"1.200806927","rc":[{"atb":[[1.21,38.81]],"id":228749}]}]}
{"op":"mcm","clk":"AKbotAkAsN+lCgDH+qQK","pt":1657542055079,"mc":[{"id":"1.200806927","rc":[{"atb":[[1.22,1.08]],"id":228749}]}]}
{"op":"mcm","clk":"ALLotAkAut+lCgDN+qQK","pt":1657542055191,"mc":[{"id":"1.200806927","rc":[{"atb":[[1.22,0],[1.21,29.37]],"trd":[[1.22,1138.89]],"ltp":1.22,"tv":119241.97,"id":228749}],"tv":126908.2}]}
{"op":"mcm","clk":"ANHotAkA3N+lCgDh+qQK","pt":1657542055555,"mc":[{"id":"1.200806927","rc":[{"atb":[[1.04,31.95]],"id":228749}]}]}
{"op":"mcm","clk":"AOjotAkAgOClCgDu+qQK","pt":1657542055865,"mc":[{"id":"1.200806927","rc":[{"atb":[[1.21,26.74]],"id":228749}]}]}
{"op":"mcm","clk":"AJLqtAkAr+GlCgC5+6QK","pt":1657542057760,"mc":[{"id":"1.200806927","rc":[{"atl":[[1.23,241.69]],"trd":[[1.23,1982.96]],"ltp":1.23,"tv":119244.25,"id":228749},{"trd":[[5.3,45.69]],"tv":7666.76,"id":2857977}],"tv":126911.01}]}
{"op":"mcm","clk":"AOXqtAkA8uGlCgDT+6QK","pt":1657542058688,"mc":[{"id":"1.200806927","rc":[{"atl":[[1.23,239.69]],"trd":[[1.23,1986.96]],"tv":119248.25,"id":228749}],"tv":126915.01}]}
{"op":"mcm","clk":"AOvqtAkA+OGlCgDX+6QK","pt":1657542058787,"mc":[{"id":"1.200806927","rc":[{"atl":[[1.22,6.9]],"id":228749}]}]}
{"op":"mcm","clk":"ALDrtAkAweKlCgCF/KQK","pt":1657542059477,"mc":[{"id":"1.200806927","rc":[{"atb":[[1.21,25.43]],"id":228749}]}]}
{"op":"mcm","clk":"AMXrtAkA2uKlCgCN/KQK","pt":1657542059700,"mc":[{"id":"1.200806927","rc":[{"atb":[[1.21,24.9]],"id":228749}]}]}
{"op":"mcm","clk":"APjrtAkAg+OlCgCh/KQK","pt":1657542060160,"mc":[{"id":"1.200806927","rc":[{"atl":[[1.22,0]],"id":228749}]}]}
{"op":"mcm","clk":"AKLstAkAqOOlCgC0/KQK","pt":1657542060563,"mc":[{"id":"1.200806927","rc":[{"atb":[[1.21,23.32]],"id":228749}]}]}
{"op":"mcm","clk":"ANHstAkA0eOlCgDI/KQK","pt":1657542060985,"mc":[{"id":"1.200806927","rc":[{"atl":[[1.23,230.67]],"id":228749}]}]}
{"op":"mcm","clk":"AL3ttAkAu+SlCgCH/aQK","pt":1657542062165,"mc":[{"id":"1.200806927","rc":[{"atb":[[1.21,24.17]],"id":228749}]}]}
{"op":"mcm","clk":"AMfttAkAxuSlCgCN/aQK","pt":1657542062251,"mc":[{"id":"1.200806927","rc":[{"atb":[[1.21,22.59]],"id":228749}]}]}
{"op":"mcm","clk":"ANvttAkA1+SlCgCb/aQK","pt":1657542062453,"mc":[{"id":"1.200806927","rc":[{"atl":[[1.23,230.14]],"id":228749}]}]}
{"op":"mcm","clk":"ALnutAkAr+WlCgDN/aQK","pt":1657542063355,"mc":[{"id":"1.200806927","rc":[{"atl":[[1.23,214.36]],"id":228749}]}]}
{"op":"mcm","clk":"AMXutAkAveWlCgDX/aQK","pt":1657542063467,"mc":[{"id":"1.200806927","rc":[{"atl":[[1.23,211.2]],"id":228749}]}]}
{"op":"mcm","clk":"AJPvtAkAi+alCgCE/qQK","pt":1657542064288,"mc":[{"id":"1.200806927","rc":[{"atl":[[1.23,210.67]],"id":228749}]}]}
{"op":"mcm","clk":"AMjvtAkAxOalCgCg/qQK","pt":1657542064866,"mc":[{"id":"1.200806927","rc":[{"atl":[[1.23,209.18]],"trd":[[1.23,1988.45]],"tv":119249.74,"id":228749},{"trd":[[5.3,46.03]],"tv":7667.1,"id":2857977}],"tv":126916.84}]}
{"op":"mcm","clk":"AIHwtAkAg+elCgDG/qQK","pt":1657542065484,"mc":[{"id":"1.200806927","rc":[{"atl":[[1.31,240.9]],"id":228749}]}]}
{"op":"mcm","clk":"AJTwtAkAmuelCgDN/qQK","pt":1657542065671,"mc":[{"id":"1.200806927","rc":[{"atb":[[1.21,19.96]],"atl":[[1.23,77.7]],"id":228749}]}]}
{"op":"mcm","clk":"AOnwtAkA7+elCgD4/qQK","pt":1657542066546,"mc":[{"id":"1.200806927","rc":[{"atl":[[1.23,55.03]],"trd":[[1.23,2011.12]],"tv":119272.41,"id":228749},{"trd":[[5.3,51.29]],"tv":7672.36,"id":2857977}],"tv":126944.77}]}
{"op":"mcm","clk":"APnwtAkAgeilCgCI/6QK","pt":1657542066783,"mc":[{"id":"1.200806927","rc":[{"atb":[[1.21,19.43]],"id":228749}]}]}
{"op":"mcm","clk":"AJzxtAkApuilCgCc/6QK","pt":1657542067274,"mc":[{"id":"1.200806927","rc":[{"atb":[[1.21,17.85]],"id":228749}]}]}
{"op":"mcm","clk":"AL/xtAkAyuilCgC1/6QK","pt":1657542067710,"mc":[{"id":"1.200806927","rc":[{"atl":[[1.23,53.98]],"id":228749}]}]}
{"op":"mcm","clk":"AMrxtAkA0uilCgC5/6QK","pt":1657542067814,"mc":[{"id":"1.200806927","rc":[{"atl":[[1.23,53.52]],"trd":[[1.23,2011.58]],"tv":119272.87,"id":228749},{"trd":[[5.3,51.4]],"tv":7672.47,"id":2857977}],"tv":126945.34}]}
{"op":"mcm","clk":"AJPytAkAk+mlCgDS/6QK","pt":1657542068523,"mc":[{"id":"1.200806927","rc":[{"atl":[[1.23,50.89]],"id":228749}]}]}
{"op":"mcm","clk":"AJfytAkAmemlCgDV/6QK","pt":1657542068606,"mc":[{"id":"1.200806927","rc":[{"atb":[[1.21,0],[1.2,0]],"trd":[[1.21,198.11],[1.2,7377.25]],"ltp":1.2,"tv":119356.96,"id":228749},{"atl":[[5.7,0],[6,5.39]],"trd":[[5.7,20.63],[6,119.05]],"ltp":6,"tv":7688.99,"id":2857977}],"tv":127045.95}]}
{"op":"mcm","clk":"ALjytAkAt+mlCgDk/6QK","pt":1657542069022,"mc":[{"id":"1.200806927","rc":[{"atl":[[1.21,0.17]],"id":228749}]}]}
{"op":"mcm","clk":"AMHytAkAvumlCgDl/6QK","pt":1657542069063,"mc":[{"id":"1.200806927","rc":[{"atl":[[1.21,4.75]],"id":228749}]}]}
{"op":"mcm","clk":"AL7ztAkAo+qlCgCjgKUK","pt":1657542070186,"mc":[{"id":"1.200806927","rc":[{"atl":[[1.21,10.01]],"id":228749}]}]}
{"op":"mcm","clk":"AKv0tAkAgeulCgDegKUK","pt":1657542071383,"mc":[{"id":"1.200806927","rc":[{"atl":[[1.21,9.51]],"trd":[[1.21,198.61]],"ltp":1.21,"tv":119357.46,"id":228749},{"trd":[[5.7,20.74]],"ltp":5.7,"tv":7689.1,"id":2857977}],"tv":127046.56}]}
{"op":"mcm","clk":"ANf0tAkAqeulCgD9gKUK","pt":1657542071912,"mc":[{"id":"1.200806927","rc":[{"atl":[[1.23,34.1],[1.21,0]],"id":228749}]}]}
{"op":"mcm","clk":"AOH1tAkAleylCgC9gaUK","pt":1657542073322,"mc":[{"id":"1.200806927","rc":[{"atl":[[6,5.18]],"id":2857977}]}]}
{"op":"mcm","clk":"AOv1tAkAn+ylCgDFgaUK","pt":1657542073423,"mc":[{"id":"1.200806927","rc":[{"atl":[[5.7,1.73]],"id":2857977}]}]}
{"op":"mcm","clk":"ALr2tAkA1+ylCgDmgaUK","pt":1657542074189,"mc":[{"id":"1.200806927","rc":[{"atl":[[1.23,26.14]],"trd":[[1.23,2019.01]],"ltp":1.23,"tv":119364.89,"id":228749},{"trd":[[5.3,53.13]],"ltp":5.3,"tv":7690.83,"id":2857977}],"tv":127055.72}]}
{"op":"mcm","clk":"AI73tAkAhu2lCgCIgqUK","pt":1657542074869,"mc":[{"id":"1.200806927","rc":[{"atl":[[1.23,23.51]],"id":228749}]}]}
{"op":"mcm","clk":"ALT3tAkAne2lCgCQgqUK","pt":1657542075201,"mc":[{"id":"1.200806927","rc":[{"atb":[[5.8,0.9]],"atl":[[5.7,0]],"trd":[[5.7,24.2]],"ltp":5.7,"tv":7694.29,"id":2857977}],"tv":127059.18}]}
{"op":"mcm","clk":"AMn3tAkAqu2lCgCYgqUK","pt":1657542075386,"mc":[{"id":"1.200806927","rc":[{"atl":[[1.23,21.79]],"trd":[[1.23,2020.73]],"tv":119366.61,"id":228749},{"atb":[[5.8,0]],"trd":[[5.3,53.53]],"ltp":5.3,"tv":7694.69,"id":2857977}],"tv":127061.3}]}
{"op":"mcm","clk":"AP/3tAkAzu2lCgC0gqUK","pt":1657542076016,"mc":[{"id":"1.200806927","rc":[{"atl":[[1.21,5.26]],"id":228749}]}]}
{"op":"mcm","clk":"ALv4tAkAh+6lCgDOgqUK","pt":1657542076587,"mc":[{"id":"1.200806927","rc":[{"atl":[[1.21,10.52]],"id":228749}]}]}
{"op":"mcm","clk":"ANH4tAkAmu6lCgDYgqUK","pt":1657542076809,"mc":[{"id":"1.200806927","rc":[{"atl":[[1.21,75.25]],"id":228749}]}]}
{"op":"mcm","clk":"ANv4tAkAou6lCgDjgqUK","pt":1657542076920,"mc":[{"id":"1.200806927","rc":[{"atl":[[1.26,1.58]],"id":228749}]}]}
{"op":"mcm","clk":"AIj5tAkAwO6lCgD6gqUK","pt":1657542077416,"mc":[{"id":"1.200806927","rc":[{"atl":[[1.21,76.15]],"id":228749}]}]}
{"op":"mcm","clk":"AN75tAkAiO+lCgClg6UK","pt":1657542078224,"mc":[{"id":"1.200806927","rc":[{"atl":[[1.21,76.68]],"id":228749}]}]}
{"op":"mcm","clk":"APr6tAkAm/ClCgDzg6UK","pt":1657542079993,"mc":[{"id":"1.200806927","rc":[{"atl":[[1.21,76.57]],"trd":[[1.21,198.83]],"ltp":1.21,"tv":119366.83,"id":228749}],"tv":127061.52}]}
{"op":"mcm","clk":"AID9tAkA3fGlCgD/hKUK","pt":1657542082384,"mc":[{"id":"1.200806927","rc":[{"atl":[[1.21,72.33]],"trd":[[1.21,203.07]],"tv":119371.07,"id":228749},{"trd":[[5.7,25.1]],"ltp":5.7,"tv":7695.59,"id":2857977}],"tv":127066.66}]}
{"op":"mcm","clk":"AMX9tAkAlvKlCgCdhaUK","pt":1657542083023,"mc":[{"id":"1.200806927","rc":[{"atb":[[1.21,927.67]],"atl":[[1.21,0]],"trd":[[1.21,347.73]],"tv":119515.73,"id":228749}],"tv":127211.32}]}
{"op":"mcm","clk":"AND9tAkAnvKlCgCfhaUK","pt":1657542083123,"mc":[{"id":"1.200806927","rc":[{"atl":[[1.22,52.59]],"id":228749}]}]}
{"op":"mcm","clk":"AIb+tAkAyvKlCgC3haUK","pt":1657542083608,"mc":[{"id":"1.200806927","rc":[{"atl":[[1.22,52.06]],"id":228749}]}]}
{"op":"mcm","clk":"AKD+tAkA1/KlCgC7haUK","pt":1657542083821,"mc":[{"id":"1.200806927","rc":[{"atb":[[1.21,927.56]],"trd":[[1.21,347.95]],"tv":119515.95,"id":228749}],"tv":127211.54}]}
{"op":"mcm","clk":"AMX+tAkA/PKlCgDOhaUK","pt":1657542084223,"mc":[{"id":"1.200806927","rc":[{"atl":[[1.22,51.86]],"trd":[[1.22,1139.29]],"ltp":1.22,"tv":119516.35,"id":228749}],"tv":127211.94}]}
{"op":"mcm","clk":"APv+tAkAn/OlCgDjhaUK","pt":1657542084720,"mc":[{"id":"1.200806927","rc":[{"atl":[[1.22,51.85]],"trd":[[1.22,1139.31]],"tv":119516.37,"id":228749}],"tv":127211.96}]}
{"op":"mcm","clk":"AML/tAkA4fOlCgCKhqUK","pt":1657542085536,"mc":[{"id":"1.200806927","rc":[{"atb":[[1.21,928.09]],"id":228749}]}]}
{"op":"mcm","clk":"AKmAtQkAwfSlCgDDhqUK","pt":1657542087023,"mc":[{"id":"1.200806927","rc":[{"atl":[[1.22,49.75]],"id":228749}]}]}
{"op":"mcm","clk":"AMiAtQkA2fSlCgDUhqUK","pt":1657542087424,"mc":[{"id":"1.200806927","rc":[{"atb":[[5.4,1.73]],"id":2857977}]}]}
{"op":"mcm","clk":"ANiAtQkA7fSlCgDhhqUK","pt":1657542087650,"mc":[{"id":"1.200806927","rc":[{"atb":[[1.21,954.39]],"id":228749}]}]}
{"op":"mcm","clk":"AImBtQkAkvWlCgD6hqUK","pt":1657542088104,"mc":[{"id":"1.200806927","rc":[{"atb":[[1.21,951.76]],"trd":[[1.21,353.21]],"ltp":1.21,"tv":119521.63,"id":228749}],"tv":127217.22}]}
{"op":"mcm","clk":"ALqBtQkAt/WlCgCLh6UK","pt":1657542088612,"mc":[{"id":"1.200806927","rc":[{"atb":[[1.21,941.24]],"trd":[[1.21,374.25]],"tv":119542.67,"id":228749}],"tv":127238.26}]}
{"op":"mcm","clk":"AOmBtQkA1/WlCgChh6UK","pt":1657542089093,"mc":[{"id":"1.200806927","rc":[{"atb":[[1.21,942.53]],"id":228749},{"atl":[[5.7,0.53]],"id":2857977}]}]}
{"op":"mcm","clk":"AJKCtQkA+vWlCgCth6UK","pt":1657542089528,"mc":[{"id":"1.200806927","rc":[{"atb":[[1.21,943.06]],"id":228749}]}]}
{"op":"mcm","clk":"AMCCtQkAqvalCgC8h6UK","pt":1657542090127,"mc":[{"id":"1.200806927","rc":[{"atb":[[1.21,948.32]],"id":228749}]}]}
{"op":"mcm","clk":"AOCCtQkAyvalCgDOh6UK","pt":1657542090533,"mc":[{"id":"1.200806927","rc":[{"atb":[[1.21,949.37]],"id":228749}]}]}
{"op":"mcm","clk":"AKiDtQkAjvelCgDyh6UK","pt":1657542091324,"mc":[{"id":"1.200806927","rc":[{"atl":[[5.7,1.16]],"id":2857977}]}]}
{"op":"mcm","clk":"AN6DtQkAtPelCgCFiKUK","pt":1657542091805,"mc":[{"id":"1.200806927","rc":[{"atb":[[1.21,938.85]],"trd":[[1.21,395.29]],"tv":119563.71,"id":228749}],"tv":127259.3}]}
{"op":"mcm","clk":"AO+DtQkAxfelCgCNiKUK","pt":1657542092008,"mc":[{"id":"1.200806927","rc":[{"atb":[[1.21,940.95]],"id":228749}]}]}
{"op":"mcm","clk":"AJ+EtQkA7/elCgChiKUK","pt":1657542092630,"mc":[{"id":"1.200806927","rc":[{"atb":[[1.21,939.15]],"trd":[[1.21,398.89]],"tv":119567.31,"id":228749}],"tv":127262.9}]}
{"op":"mcm","clk":"ALOEtQkAgvilCgCriKUK","pt":1657542092848,"mc":[{"id":"1.200806927","rc":[{"atb":[[5.4,0]],"id":2857977}]}]}
{"op":"mcm","clk":"AOeEtQkAqvilCgDFiKUK","pt":1657542093411,"mc":[{"id":"1.200806927","rc":[{"atl":[[5.7,3.79]],"id":2857977}]}]}
{"op":"mcm","clk":"AP+EtQkAxfilCgDZiKUK","pt":1657542093736,"mc":[{"id":"1.200806927","rc":[{"atb":[[1.21,953.87]],"id":228749}]}]}
{"op":"mcm","clk":"AIWFtQkAzPilCgDciKUK","pt":1657542093829,"mc":[{"id":"1.200806927","rc":[{"atb":[[1.21,948.61]],"id":228749}]}]}
{"op":"mcm","clk":"AJaFtQkA1/ilCgDkiKUK","pt":1657542094039,"mc":[{"id":"1.200806927","rc":[{"atb":[[1.21,950.19]],"id":228749}]}]}
{"op":"mcm","clk":"ANWFtQkAl/mlCgCMiaUK","pt":1657542094818,"mc":[{"id":"1.200806927","rc":[{"atb":[[1.21,948.7]],"trd":[[1.21,401.86]],"tv":119570.28,"id":228749}],"tv":127265.87}]}
{"op":"mcm","clk":"APKFtQkAtvmlCgCriaUK","pt":1657542095330,"mc":[{"id":"1.200806927","rc":[{"atb":[[1.21,947.65]],"trd":[[1.21,403.96]],"tv":119572.38,"id":228749}],"tv":127267.97}]}
{"op":"mcm","clk":"AIOHtQkAvvqlCgD8iaUK","pt":1657542097112,"mc":[{"id":"1.200806927","rc":[{"atb":[[1.21,942.39]],"trd":[[1.21,414.48]],"tv":119582.9,"id":228749}],"tv":127278.49}]}
{"op":"mcm","clk":"AIuHtQkAyvqlCgCDiqUK","pt":1657542097219,"mc":[{"id":"1.200806927","rc":[{"atl":[[1.22,4.67]],"id":228749}]}]}
{"op":"mcm","clk":"AJSHtQkA1fqlCgCGiqUK","pt":1657542097353,"mc":[{"id":"1.200806927","rc":[{"atb":[[5.5,1.73]],"id":2857977}]}]}
{"op":"mcm","clk":"AKWHtQkA5fqlCgCQiqUK","pt":1657542097535,"mc":[{"id":"1.200806927","rc":[{"atl":[[1.22,3.62]],"id":228749}]}]}
{"op":"mcm","clk":"APKHtQkAr/ulCgC9iqUK","pt":1657542098557,"mc":[{"id":"1.200806927","rc":[{"atb":[[1.21,939.76]],"trd":[[1.21,419.74]],"tv":119588.16,"id":228749}],"tv":127283.75}]}
{"op":"mcm","clk":"APuHtQkAtfulCgDBiqUK","pt":1657542098610,"mc":[{"id":"1.200806927","rc":[{"atb":[[1.21,937.13]],"trd":[[1.21,425]],"tv":119593.42,"id":228749}],"tv":127289.01}]}
{"op":"mcm","clk":"AIGItQkAzfulCgDLiqUK","pt":1657542098937,"mc":[{"id":"1.200806927","rc":[{"atl":[[1.28,31]],"id":228749}]}]}
{"op":"mcm","clk":"AJ6ItQkA2PulCgDRiqUK","pt":1657542099126,"mc":[{"id":"1.200806927","rc":[{"atb":[[1.21,936.6]],"trd":[[1.21,426.06]],"tv":119594.48,"id":228749}],"tv":127290.07}]}
{"op":"mcm","clk":"ALyItQkA8fulCgDfiqUK","pt":1657542099458,"mc":[{"id":"1.200806927","rc":[{"atb":[[1.21,921.88]],"id":228749}]}]}
{"op":"mcm","clk":"AN6JtQkA+PylCgCyi6UK","pt":1657542101409,"mc":[{"id":"1.200806927","rc":[{"atb":[[1.21,911.94]],"trd":[[1.21,445.94]],"tv":119614.36,"id":228749}],"tv":127309.95}]}
{"op":"mcm","clk":"AO+JtQkAhP2lCgC/i6UK","pt":1657542101626,"mc":[{"id":"1.200806927","rc":[{"atl":[[5.7,3.26]],"id":2857977}]}]}
{"op":"mcm","clk":"AK+KtQkAuP2lCgDdi6UK","pt":1657542102273,"mc":[{"id":"1.200806927","rc":[{"atb":[[1.22,2.37]],"atl":[[1.22,0]],"trd":[[1.22,1141.74]],"ltp":1.22,"tv":119616.79,"id":228749},{"trd":[[5.6,5.24]],"ltp":5.6,"tv":7696.12,"id":2857977}],"tv":127312.91}]}
{"op":"mcm","clk":"AMeKtQkA2v2lCgDqi6UK","pt":1657542102606,"mc":[{"id":"1.200806927","rc":[{"atb":[[1.22,4.53]],"id":228749}]}]}
{"op":"mcm","clk":"AO2KtQkAjf6lCgCEjKUK","pt":1657542103240,"mc":[{"id":"1.200806927","rc":[{"atb":[[1.22,3.29]],"trd":[[1.22,1142.98]],"tv":119618.03,"id":228749},{"trd":[[5.6,5.51]],"tv":7696.39,"id":2857977}],"tv":127314.42}]}
{"op":"mcm","clk":"APiKtQkAof6lCgCNjKUK","pt":1657542103441,"mc":[{"id":"1.200806927","rc":[{"atb":[[5.5,1.29]],"id":2857977}]}]}
{"op":"mcm","clk":"AKWLtQkA1/6lCgCjjKUK","pt":1657542104070,"mc":[{"id":"1.200806927","rc":[{"atb":[[1.22,2.76]],"id":228749}]}]}
{"op":"mcm","clk":"ALOLtQkA5/6lCgCqjKUK","pt":1657542104269,"mc":[{"id":"1.200806927","rc":[{"atb":[[1.21,901.42]],"id":228749}]}]}
{"op":"mcm","clk":"AO6LtQkAtf+lCgDTjKUK","pt":1657542105265,"mc":[{"id":"1.200806927","rc":[{"atl":[[1.23,5.8]],"trd":[[1.23,2036.72]],"ltp":1.23,"tv":119634.02,"id":228749},{"atb":[[5.5,0]],"trd":[[5.5,28.54],[5.3,57.24]],"ltp":5.3,"tv":7702.68,"id":2857977}],"tv":127336.7}]}
{"op":"mcm","clk":"AIOMtQkA2f+lCgDgjKUK","pt":1657542105659,"mc":[{"id":"1.200806927","rc":[{"atb":[[1.18,13.15]],"id":228749}]}]}
{"op":"mcm","clk":"AKSNtQkA6YCmCgCsjaUK","pt":1657542107624,"mc":[{"id":"1.200806927","rc":[{"atb":[[1.21,898.79]],"id":228749}]}]}
{"op":"mcm","clk":"ALSNtQkA+ICmCgC0jaUK","pt":1657542107833,"mc":[{"id":"1.200806927","rc":[{"atb":[[1.22,3.29]],"id":228749}]}]}
{"op":"mcm","clk":"ALmNtQkAgIGmCgC5jaUK","pt":1657542107934,"mc":[{"id":"1.200806927","rc":[{"atb":[[1.22,8.55]],"id":228749}]}]}
{"op":"mcm","clk":"APWNtQkAx4GmCgDljaUK","pt":1657542108785,"mc":[{"id":"1.200806927","rc":[{"atb":[[1.22,0],[1.21,896.82]],"trd":[[1.22,1147.29],[1.21,449.88]],"ltp":1.21,"tv":119642.27,"id":228749}],"tv":127344.95}]}
{"op":"mcm","clk":"AIeOtQkA24GmCgDyjaUK","pt":1657542109026,"mc":[{"id":"1.200806927","rc":[{"atb":[[1.21,896.29]],"trd":[[1.21,450.94]],"tv":119643.33,"id":228749}],"tv":127346.01}]}
{"op":"mcm","clk":"AI6OtQkA5oGmCgD5jaUK","pt":1657542109147,"mc":[{"id":"1.200806927","rc":[{"atb":[[1.21,894.71]],"id":228749}]}]}
{"op":"mcm","clk":"AKGOtQkA+YGmCgCFjqUK","pt":1657542109387,"mc":[{"id":"1.200806927","rc":[{"atb":[[1.21,894.18]],"trd":[[1.21,452]],"tv":119644.39,"id":228749}],"tv":127347.07}]}
{"op":"mcm","clk":"ANqPtQkA64OmCgCEj6UK","pt":1657542111937,"mc":[{"id":"1.200806927","rc":[{"atl":[[1.3,315.47]],"id":228749},{"atl":[[6,5.07]],"id":2857977}]}]}
{"op":"mcm","clk":"AIKQtQkApISmCgCgj6UK","pt":1657542112459,"mc":[{"id":"1.200806927","rc":[{"atb":[[1.21,892.34]],"trd":[[1.21,455.68]],"tv":119648.07,"id":228749}],"tv":127350.75}]}
{"op":"mcm","clk":"AKCQtQkAyISmCgCuj6UK","pt":1657542112870,"mc":[{"id":"1.200806927","rc":[{"atl":[[5.5,0.65]],"id":2857977}]}]}
{"op":"mcm","clk":"AL+QtQkA4YSmCgDGj6UK","pt":1657542113240,"mc":[{"id":"1.200806927","rc":[{"atl":[[5.7,3.01],[5.5,0]],"trd":[[5.5,29.84]],"ltp":5.5,"tv":7703.98,"id":2857977}],"tv":127352.05}]}
{"op":"mcm","clk":"AM2QtQkA8YSmCgDNj6UK","pt":1657542113440,"mc":[{"id":"1.200806927","rc":[{"atl":[[5.5,0.26]],"id":2857977}]}]}
{"op":"mcm","clk":"ANmQtQkA94SmCgDVj6UK","pt":1657542113559,"mc":[{"id":"1.200806927","rc":[{"atb":[[1.22,0.53]],"id":228749}]}]}
{"op":"mcm","clk":"AI+RtQkApoWmCgDvj6UK","pt":1657542114266,"mc":[{"id":"1.200806927","rc":[{"atb":[[1.22,0],[1.21,891.29]],"id":228749}]}]}
{"op":"mcm","clk":"ANeRtQkA5YWmCgCbkKUK","pt":1657542115135,"mc":[{"id":"1.200806927","rc":[{"atl":[[1.24,218.16]],"id":228749}]}]}
{"op":"mcm","clk":"AIWStQkAm4amCgC7kKUK","pt":1657542115878,"mc":[{"id":"1.200806927","rc":[{"atb":[[1.23,4.72]],"atl":[[1.23,0]],"trd":[[1.23,2036.98]],"ltp":1.23,"tv":119648.33,"id":228749}],"tv":127352.31}]}
{"op":"mcm","clk":"ANuStQkA8IamCgDokKUK","pt":1657542117166,"mc":[{"id":"1.200806927","rc":[{"atl":[[1.24,186.4]],"trd":[[1.24,3181.92]],"ltp":1.24,"tv":119680.09,"id":228749},{"trd":[[5.1,10.62]],"ltp":5.1,"tv":7711.71,"id":2857977}],"tv":127391.8}]}
{"op":"mcm","clk":"AJSTtQkAtYemCgCAkaUK","pt":1657542118107,"mc":[{"id":"1.200806927","rc":[{"atb":[[1.23,0.41]],"trd":[[1.23,2045.6]],"ltp":1.23,"tv":119688.71,"id":228749}],"tv":127400.42}]}
{"op":"mcm","clk":"AKCTtQkAxYemCgCJkaUK","pt":1657542118265,"mc":[{"id":"1.200806927","rc":[{"atb":[[1.23,0]],"trd":[[1.22,1148.18]],"ltp":1.22,"tv":119689.6,"id":228749},{"atl":[[5.5,0.06]],"trd":[[5.5,30.04]],"ltp":5.5,"tv":7711.91,"id":2857977}],"tv":127401.51}]}
{"op":"mcm","clk":"ANSTtQkAiYimCgCukaUK","pt":1657542119179,"mc":[{"id":"1.200806927","rc":[{"atl":[[5.6,3.45]],"id":2857977}]}]}
{"op":"mcm","clk":"APyTtQkAwYimCgDZkaUK","pt":1657542119951,"mc":[{"id":"1.200806927","rc":[{"atl":[[1.22,2.36]],"trd":[[1.22,1148.45]],"tv":119689.87,"id":228749},{"atl":[[5.5,0]],"trd":[[5.5,30.1]],"tv":7711.97,"id":2857977}],"tv":127401.84}]}
{"op":"mcm","clk":"AJOUtQkA4YimCgD1kaUK","pt":1657542120362,"mc":[{"id":"1.200806927","rc":[{"atl":[[5.6,1.35]],"trd":[[5.6,9.71]],"ltp":5.6,"tv":7716.17,"id":2857977}],"tv":127406.04}]}
{"op":"mcm","clk":"ALaUtQkAiYmmCgCKkqUK","pt":1657542120881,"mc":[{"id":"1.200806927","rc":[{"atl":[[15,0.34]],"id":2857977}]}]}
{"op":"mcm","clk":"AMyUtQkAoommCgCZkqUK","pt":1657542121232,"mc":[{"id":"1.200806927","rc":[{"atl":[[5.7,2.63]],"id":2857977}]}]}
{"op":"mcm","clk":"AI+VtQkA/4mmCgDCkqUK","pt":1657542122286,"mc":[{"id":"1.200806927","rc":[{"atb":[[1.24,311.24],[1.21,846.21]],"atl":[[1.24,0],[1.22,0]],"trd":[[1.24,3554.72],[1.22,1153.17],[1.21,545.84]],"ltp":1.24,"tv":120157.55,"id":228749}],"tv":127873.72}]}
{"op":"mcm","clk":"AKGVtQkAl4qmCgDTkqUK","pt":1657542122608,"mc":[{"id":"1.200806927","rc":[{"atl":[[5.1,0.26]],"id":2857977}]}]}
{"op":"mcm","clk":"AKKVtQkAmoqmCgDTkqUK","pt":1657542122675,"mc":[{"id":"1.200806927","rc":[{"atb":[[1.24,309.56]],"trd":[[1.24,3558.08]],"tv":120160.91,"id":228749}],"tv":127877.08}]}
{"op":"mcm","clk":"AKqVtQkAooqmCgDWkqUK","pt":1657542122725,"mc":[{"id":"1.200806927","rc":[{"atb":[[1.24,309.03]],"trd":[[1.24,3559.14]],"tv":120161.97,"id":228749}],"tv":127878.14}]}
{"op":"mcm","clk":"AJqWtQkAmIumCgCYk6UK","pt":1657542124363,"mc":[{"id":"1.200806927","rc":[{"atb":[[1.24,309.53]],"id":228749}]}]}
{"op":"mcm","clk":"ALaWtQkAvoumCgCmk6UK","pt":1657542124780,"mc":[{"id":"1.200806927","rc":[{"atb":[[1.24,309.03]],"id":228749}]}]}
{"op":"mcm","clk":"AL2WtQkAxoumCgCqk6UK","pt":1657542124881,"mc":[{"id":"1.200806927","rc":[{"atb":[[1.24,306.4]],"trd":[[1.24,3564.4]],"tv":120167.23,"id":228749}],"tv":127883.4}]}
{"op":"mcm","clk":"AMmWtQkA3oumCgC0k6UK","pt":1657542125173,"mc":[{"id":"1.200806927","rc":[{"atb":[[1.24,303.77]],"trd":[[1.24,3569.66]],"tv":120172.49,"id":228749}],"tv":127888.66}]}
{"op":"mcm","clk":"ANiWtQkA7YumCgC7k6UK","pt":1657542125399,"mc":[{"id":"1.200806927","rc":[{"atl":[[5.6,0]],"id":2857977}]}]}
{"op":"mcm","clk":"AJKXtQkAuYymCgDfk6UK","pt":1657542126478,"mc":[{"id":"1.200806927","rc":[{"atb":[[1.24,347.47]],"trd":[[1.24,3572.41]],"tv":120175.24,"id":228749}],"tv":127891.41}]}
{"op":"mcm","clk":"ALOXtQkA2oymCgDyk6UK","pt":1657542126992,"mc":[{"id":"1.200806927","rc":[{"atb":[[1.22,0.53]],"id":228749}]}]}
{"op":"mcm","clk":"AMCXtQkA64ymCgD4k6UK","pt":1657542127139,"mc":[{"id":"1.200806927","rc":[{"atb":[[1.24,346.57]],"trd":[[1.24,3574.21]],"tv":120177.04,"id":228749}],"tv":127893.21}]}
{"op":"mcm","clk":"AOCXtQkAgY2mCgCDlKUK","pt":1657542127550,"mc":[{"id":"1.200806927","rc":[{"atb":[[1.23,15.78]],"id":228749}]}]}
{"op":"mcm","clk":"AOOXtQkAh42mCgCHlKUK","pt":1657542127652,"mc":[{"id":"1.200806927","rc":[{"atl":[[6,4.96]],"id":2857977}]}]}
{"op":"mcm","clk":"APeXtQkAnI2mCgCUlKUK","pt":1657542127971,"mc":[{"id":"1.200806927","rc":[{"atb":[[1.24,346.04]],"trd":[[1.24,3575.27]],"tv":120178.1,"id":228749}],"tv":127894.27}]}
{"op":"mcm","clk":"APuXtQkAoI2mCgCXlKUK","pt":1657542128060,"mc":[{"id":"1.200806927","rc":[{"atb":[[1.24,348.67]],"id":228749}]}]}
{"op":"mcm","clk":"AIOYtQkApY2mCgCZlKUK","pt":1657542128176,"mc":[{"id":"1.200806927","rc":[{"atb":[[1.21,17.6]],"id":228749}]}]}
{"op":"mcm","clk":"ALGYtQkA0I2mCgC4lKUK","pt":1657542128847,"mc":[{"id":"1.200806927","rc":[{"atb":[[1.24,348.15]],"trd":[[1.24,3576.31]],"tv":120179.14,"id":228749}],"tv":127895.31}]}
{"op":"mcm","clk":"AP6YtQkAmI6mCgDhlKUK","pt":1657542129791,"mc":[{"id":"1.200806927","rc":[{"atb":[[1.24,361.3]],"id":228749}]}]}
{"op":"mcm","clk":"ALuZtQkA5I6mCgD9lKUK","pt":1657542130566,"mc":[{"id":"1.200806927","rc":[{"atb":[[1.22,3.16]],"id":228749}]}]}
{"op":"mcm","clk":"ALyatQkA7o+mCgCqlaUK","pt":1657542132158,"mc":[{"id":"1.200806927","rc":[{"atl":[[6,4.53]],"id":2857977}]}]}
{"op":"mcm","clk":"AMaatQkA9o+mCgCwlaUK","pt":1657542132265,"mc":[{"id":"1.200806927","rc":[{"atb":[[1.24,466.48]],"id":228749}]}]}
{"op":"mcm","clk":"AOeatQkAoJCmCgDGlaUK","pt":1657542132778,"mc":[{"id":"1.200806927","rc":[{"atl":[[1.25,50.53]],"id":228749}]}]}
{"op":"mcm","clk":"APeatQkArZCmCgDKlaUK","pt":1657542132976,"mc":[{"id":"1.200806927","rc":[{"atb":[[1.24,465.95]],"trd":[[1.24,3577.37]],"tv":120180.2,"id":228749}],"tv":127896.37}]}
{"op":"mcm","clk":"AIWbtQkAuZCmCgDRlaUK","pt":1657542133181,"mc":[{"id":"1.200806927","rc":[{"atb":[[1.22,18.94]],"id":228749}]}]}
{"op":"mcm","clk":"AKWbtQkA2ZCmCgDllaUK","pt":1657542133603,"mc":[{"id":"1.200806927","rc":[{"atl":[[5.3,0.13]],"id":2857977}]}]}
{"op":"mcm","clk":"ALCbtQkA6JCmCgDtlaUK","pt":1657542133774,"mc":[{"id":"1.200806927","rc":[{"atb":[[1.24,429.21]],"trd":[[1.24,3614.11]],"tv":120216.94,"id":228749},{"atl":[[5.1,0]],"trd":[[5.2,66.02],[5.1,11.13]],"ltp":5.2,"tv":7725.44,"id":2857977}],"tv":127942.38}]}
{"op":"mcm","clk":"AL2btQkA95CmCgD4laUK","pt":1657542133972,"mc":[{"id":"1.200806927","rc":[{"atb":[[1.24,426.58]],"trd":[[1.24,3619.37]],"tv":120222.2,"id":228749}],"tv":127947.64}]}
{"op":"mcm","clk":"AOubtQkAnJGmCgCGlqUK","pt":1657542134489,"mc":[{"id":"1.200806927","rc":[{"atb":[[1.22,24.2]],"id":228749}]}]}
{"op":"mcm","clk":"AIqctQkAv5GmCgCWlqUK","pt":1657542134885,"mc":[{"id":"1.200806927","rc":[{"atb":[[1.24,418.43]],"trd":[[1.24,3632.78]],"tv":120235.61,"id":228749},{"trd":[[5.2,66.71]],"tv":7726.13,"id":2857977}],"tv":127961.74}]}
{"op":"mcm","clk":"AJGctQkAyJGmCgCflqUK","pt":1657542135005,"mc":[{"id":"1.200806927","rc":[{"atb":[[1.22,24.73]],"id":228749}]}]}
{"op":"mcm","clk":"AL2ctQkA/5GmCgCxlqUK","pt":1657542135578,"mc":[{"id":"1.200806927","rc":[{"atb":[[1.22,22.1]],"id":228749}]}]}
{"op":"mcm","clk":"APGctQkAwZKmCgDRlqUK","pt":1657542136296,"mc":[{"id":"1.200806927","rc":[{"atl":[[1.25,49.48]],"trd":[[1.25,1366.15]],"ltp":1.25,"tv":120236.65,"id":228749}],"tv":127962.78}]}
{"op":"mcm","clk":"APOctQkAyZKmCgDTlqUK","pt":1657542136385,"mc":[{"id":"1.200806927","rc":[{"atl":[[1.25,23.18]],"trd":[[1.25,1418.75]],"tv":120289.25,"id":228749}],"tv":128015.38}]}
{"op":"mcm","clk":"APectQkA1pKmCgDVlqUK","pt":1657542136496,"mc":[{"id":"1.200806927","rc":[{"atb":[[1.24,391.38]],"trd":[[1.24,3686.88]],"ltp":1.24,"tv":120343.35,"id":228749}],"tv":128069.48}]}
{"op":"mcm","clk":"AIWdtQkA95KmCgDhlqUK","pt":1657542136756,"mc":[{"id":"1.200806927","rc":[{"atb":[[1.21,16.31]],"id":228749}]}]}
{"op":"mcm","clk":"AIudtQkA/5KmCgDllqUK","pt":1657542136861,"mc":[{"id":"1.200806927","rc":[{"atb":[[1.24,391.9]],"trd":[[1.24,3687.94]],"tv":120344.41,"id":228749}],"tv":128070.54}]}
{"op":"mcm","clk":"AISetQkA+5OmCgCtl6UK","pt":1657542138306,"mc":[{"id":"1.200806927","rc":[{"atb":[[1.24,389.27],[1.06,931.43]],"trd":[[1.24,3693.2]],"tv":120349.67,"id":228749}],"tv":128075.8}]}
{"op":"mcm","clk":"AJSetQkAjpSmCgC0l6UK","pt":1657542138448,"mc":[{"id":"1.200806927","rc":[{"atb":[[1.24,387.02]],"trd":[[1.24,3697.7]],"tv":120354.17,"id":228749}],"tv":128080.3}]}
{"op":"mcm","clk":"AKGetQkAn5SmCgC5l6UK","pt":1657542138655,"mc":[{"id":"1.200806927","rc":[{"atb":[[1.23,16.31]],"id":228749}]}]}
{"op":"mcm","clk":"ALWetQkAspSmCgDMl6UK","pt":1657542138984,"mc":[{"id":"1.200806927","rc":[{"atb":[[1.22,6.32]],"id":228749}]}]}
{"op":"mcm","clk":"AL+etQkAupSmCgDPl6UK","pt":1657542139087,"mc":[{"id":"1.200806927","rc":[{"atl":[[1.25,22.66]],"trd":[[1.25,1419.27]],"ltp":1.25,"tv":120354.69,"id":228749},{"trd":[[5,16.08]],"ltp":5,"tv":7726.26,"id":2857977}],"tv":128080.95}]}
{"op":"mcm","clk":"APqetQkA/pSmCgDpl6UK","pt":1657542139815,"mc":[{"id":"1.200806927","rc":[{"atb":[[1.24,341.94]],"id":228749}]}]}
{"op":"mcm","clk":"AOmftQkA8pWmCgCUmKUK","pt":1657542141195,"mc":[{"id":"1.200806927","rc":[{"atb":[[1.17,24.07]],"id":228749}]}]}
{"op":"mcm","clk":"AIigtQkAi5amCgCcmKUK","pt":1657542141502,"mc":[{"id":"1.200806927","rc":[{"atb":[[1.24,337.54]],"trd":[[1.24,3702.1]],"ltp":1.24,"tv":120359.09,"id":228749},{"trd":[[5.2,67.76]],"ltp":5.2,"tv":7727.31,"id":2857977}],"tv":128086.4}]}
{"op":"mcm","clk":"AJmgtQkAnJamCgClmKUK","pt":1657542141666,"mc":[{"id":"1.200806927","rc":[{"atb":[[1.24,337.01]],"trd":[[1.24,3703.16]],"tv":120360.15,"id":228749}],"tv":128087.46}]}
{"op":"mcm","clk":"AMKgtQkAxpamCgC7mKUK","pt":1657542142168,"mc":[{"id":"1.200806927","rc":[{"atb":[[1.24,331.75]],"trd":[[1.24,3713.68]],"tv":120370.67,"id":228749}],"tv":128097.98}]}
{"op":"mcm","clk":"AMugtQkA0JamCgDFmKUK","pt":1657542142286,"mc":[{"id":"1.200806927","rc":[{"atb":[[1.24,328.86]],"trd":[[1.24,3716.57]],"tv":120373.56,"id":228749},{"trd":[[5.2,68.45]],"tv":7728,"id":2857977}],"tv":128101.56}]}
{"op":"mcm","clk":"AM+gtQkA3ZamCgDKmKUK","pt":1657542142396,"mc":[{"id":"1.200806927","rc":[{"atb":[[1.24,327.81]],"trd":[[1.24,3718.67]],"tv":120375.66,"id":228749}],"tv":128103.66}]}
{"op":"mcm","clk":"AOGgtQkA7pamCgDUmKUK","pt":1657542142605,"mc":[{"id":"1.200806927","rc":[{"atl":[[1.25,27.92]],"id":228749}]}]}
{"op":"mcm","clk":"AKChtQkAwpemCgD5mKUK","pt":1657542143579,"mc":[{"id":"1.200806927","rc":[{"atb":[[1.22,5.79]],"id":228749}]}]}
{"op":"mcm","clk":"ALihtQkA5JemCgCHmaUK","pt":1657542143891,"mc":[{"id":"1.200806927","rc":[{"atb":[[1.24,327.28]],"trd":[[1.24,3719.73]],"tv":120376.72,"id":228749}],"tv":128104.72}]}
{"op":"mcm","clk":"ANWhtQkAkZimCgCZmaUK","pt":1657542144303,"mc":[{"id":"1.200806927","rc":[{"atb":[[1.24,327.26]],"trd":[[1.24,3719.78]],"tv":120376.77,"id":228749}],"tv":128104.77}]}
{"op":"mcm","clk":"APuhtQkAwJimCgC+maUK","pt":1657542144879,"mc":[{"id":"1.200806927","rc":[{"atb":[[1.25,17.16]],"atl":[[1.25,0]],"trd":[[1.25,1464.59]],"ltp":1.25,"tv":120422.09,"id":228749}],"tv":128150.09}]}
{"op":"mcm","clk":"AIeitQkA0JimCgDImaUK","pt":1657542145081,"mc":[{"id":"1.200806927","rc":[{"atb":[[1.24,0],[1.25,0]],"atl":[[1.24,62.27]],"trd":[[1.24,4374.3],[1.25,1498.91]],"ltp":1.24,"tv":121110.93,"id":228749}],"tv":128838.93}]}
{"op":"mcm","clk":"AKaitQkA95imCgDZmaUK","pt":1657542145596,"mc":[{"id":"1.200806927","rc":[{"atl":[[1.24,262.12]],"id":228749}]}]}
{"op":"mcm","clk":"AKejtQkAk5qmCgCpmqUK","pt":1657542147420,"mc":[{"id":"1.200806927","rc":[{"atl":[[1.24,256.94]],"trd":[[1.24,4384.66]],"tv":121121.29,"id":228749}],"tv":128849.29}]}
{"op":"mcm","clk":"AMOjtQkAuJqmCgC5mqUK","pt":1657542147924,"mc":[{"id":"1.200806927","rc":[{"atb":[[1.23,15.19]],"atl":[[1.24,254.31]],"trd":[[1.24,4389.92],[1.23,2047.84]],"ltp":1.23,"tv":121128.79,"id":228749}],"tv":128856.79}]}
{"op":"mcm","clk":"APGjtQkA55qmCgDVmqUK","pt":1657542148580,"mc":[{"id":"1.200806927","rc":[{"atl":[[1.24,254.71]],"id":228749}]}]}
{"op":"mcm","clk":"APujtQkA8JqmCgDZmqUK","pt":1657542148708,"mc":[{"id":"1.200806927","rc":[{"atl":[[1.26,0]],"id":228749}]}]}
{"op":"mcm","clk":"AI2ktQkA/5qmCgDhmqUK","pt":1657542148906,"mc":[{"id":"1.200806927","rc":[{"atl":[[1.24,254.8]],"trd":[[1.24,4390.36]],"ltp":1.24,"tv":121129.23,"id":228749},{"trd":[[5.1,11.24]],"ltp":5.1,"tv":7728.11,"id":2857977}],"tv":128857.34}]}
{"op":"mcm","clk":"AKKktQkAkJumCgDrmqUK","pt":1657542149215,"mc":[{"id":"1.200806927","rc":[{"atl":[[1.24,254.4]],"id":228749}]}]}
{"op":"mcm","clk":"AKWktQkAlZumCgDtmqUK","pt":1657542149305,"mc":[{"id":"1.200806927","rc":[{"atb":[[1.2,1.05]],"atl":[[1.24,255.3]],"id":228749}]}]}
{"op":"mcm","clk":"ANyktQkA1JumCgCRm6UK","pt":1657542150095,"mc":[{"id":"1.200806927","rc":[{"atl":[[1.24,253.72],[1.25,1.58]],"trd":[[1.24,4393.52]],"tv":121132.39,"id":228749}],"tv":128860.5}]}
{"op":"mcm","clk":"AO6ktQkA4JumCgCVm6UK","pt":1657542150298,"mc":[{"id":"1.200806927","rc":[{"atl":[[1.24,257.4]],"id":228749}]}]}
{"op":"mcm","clk":"AP+ktQkA9pumCgCem6UK","pt":1657542150531,"mc":[{"id":"1.200806927","rc":[{"atb":[[1.17,13.55]],"id":228749},{"atb":[[5,1.04]],"id":2857977}]}]}
{"op":"mcm","clk":"AIultQkAhpymCgCjm6UK","pt":1657542150714,"mc":[{"id":"1.200806927","rc":[{"atl":[[5.3,0]],"id":2857977}]}]}
{"op":"mcm","clk":"AKyltQkApZymCgC9m6UK","pt":1657542151183,"mc":[{"id":"1.200806927","rc":[{"atl":[[1.24,241.62]],"trd":[[1.24,4425.08]],"tv":121163.95,"id":228749}],"tv":128892.06}]}
{"op":"mcm","clk":"AL6ltQkAuZymCgDNm6UK","pt":1657542151496,"mc":[{"id":"1.200806927","rc":[{"atb":[[1.18,58.23]],"id":228749}]}]}
{"op":"mcm","clk":"AM6ltQkAzJymCgDXm6UK","pt":1657542151702,"mc":[{"id":"1.200806927","rc":[{"atb":[[1.18,47.71]],"id":228749}]}]}
{"op":"mcm","clk":"ANSltQkA2ZymCgDbm6UK","pt":1657542151813,"mc":[{"id":"1.200806927","rc":[{"atl":[[1.24,241.13]],"trd":[[1.24,4426.08]],"tv":121164.95,"id":228749}],"tv":128893.06}]}
{"op":"mcm","clk":"AOqltQkA7pymCgDmm6UK","pt":1657542152111,"mc":[{"id":"1.200806927","rc":[{"atb":[[5.2,0.69]],"id":2857977}]}]}
{"op":"mcm","clk":"AP2ltQkAiZ2mCgDvm6UK","pt":1657542152410,"mc":[{"id":"1.200806927","rc":[{"atb":[[5.2,0.16]],"trd":[[5.2,69.51]],"ltp":5.2,"tv":7729.17,"id":2857977}],"tv":128894.12}]}
{"op":"mcm","clk":"ALqmtQkAzJ2mCgCHnKUK","pt":1657542153211,"mc":[{"id":"1.200806927","rc":[{"atl":[[1.24,240.45]],"trd":[[1.24,4427.44]],"tv":121166.31,"id":228749}],"tv":128895.48}]}
{"op":"mcm","clk":"AL+mtQkA1Z2mCgCJnKUK","pt":1657542153302,"mc":[{"id":"1.200806927","rc":[{"atb":[[5.2,0.05]],"id":2857977}]}]}
{"op":"mcm","clk":"AI6ntQkAqp6mCgCwnKUK","pt":1657542154402,"mc":[{"id":"1.200806927","rc":[{"atb":[[5,0]],"id":2857977}]}]}
{"op":"mcm","clk":"AJWntQkAsp6mCgC2nKUK","pt":1657542154500,"mc":[{"id":"1.200806927","rc":[{"atl":[[1.24,243.98]],"id":228749}]}]}
{"op":"mcm","clk":"AJKotQkAvJ+mCgCKnaUK","pt":1657542156127,"mc":[{"id":"1.200806927","rc":[{"atl":[[1.24,254.5]],"id":228749}]}]}
{"op":"mcm","clk":"AKuotQkA35+mCgCVnaUK","pt":1657542156483,"mc":[{"id":"1.200806927","rc":[{"atl":[[1.24,259.23]],"id":228749}]}]}
{"op":"mcm","clk":"APiotQkAsKCmCgC/naUK","pt":1657542157437,"mc":[{"id":"1.200806927","rc":[{"atb":[[1.23,17.82]],"id":228749}]}]}
{"op":"mcm","clk":"AKaptQkA3aCmCgDenaUK","pt":1657542158093,"mc":[{"id":"1.200806927","rc":[{"atl":[[1.25,4.21]],"id":228749}]}]}
{"op":"mcm","clk":"AKmptQkA5KCmCgDknaUK","pt":1657542158196,"mc":[{"id":"1.200806927","rc":[{"atl":[[1.24,258.7]],"trd":[[1.24,4428.5]],"tv":121167.37,"id":228749}],"tv":128896.54}]}
{"op":"mcm","clk":"AMiptQkAiqGmCgD0naUK","pt":1657542158608,"mc":[{"id":"1.200806927","rc":[{"atl":[[1.24,258.2]],"trd":[[1.24,4429.5]],"tv":121168.37,"id":228749}],"tv":128897.54}]}
{"op":"mcm","clk":"AOaptQkAo6GmCgCDnqUK","pt":1657542158936,"mc":[{"id":"1.200806927","rc":[{"atl":[[1.24,245.05]],"trd":[[1.24,4455.8]],"tv":121194.67,"id":228749}],"tv":128923.84}]}
{"op":"mcm","clk":"AJ6qtQkA46GmCgCgnqUK","pt":1657542159596,"mc":[{"id":"1.200806927","rc":[{"atb":[[1.23,12.56]],"id":228749}]}]}
{"op":"mcm","clk":"AMGqtQkAkKKmCgC3nqUK","pt":1657542160113,"mc":[{"id":"1.200806927","rc":[{"atl":[[5.7,0]],"id":2857977}]}]}
{"op":"mcm","clk":"ANmqtQkAn6KmCgDCnqUK","pt":1657542160418,"mc":[{"id":"1.200806927","rc":[{"atl":[[1.24,244.18]],"trd":[[1.24,4457.52]],"tv":121196.39,"id":228749}],"tv":128925.56}]}
{"op":"mcm","clk":"AJyrtQkA0aKmCgDdnqUK","pt":1657542161079,"mc":[{"id":"1.200806927","rc":[{"atl":[[1.24,244.71]],"id":228749}]}]}
{"op":"mcm","clk":"AKurtQkA5aKmCgDjnqUK","pt":1657542161303,"mc":[{"id":"1.200806927","rc":[{"atl":[[1.24,242.08]],"trd":[[1.24,4462.78]],"tv":121201.65,"id":228749}],"tv":128930.82}]}
{"op":"mcm","clk":"AMSrtQkA/qKmCgDsnqUK","pt":1657542161612,"mc":[{"id":"1.200806927","rc":[{"atl":[[1.24,257.75]],"trd":[[1.24,4465.94]],"tv":121204.81,"id":228749}],"tv":128933.98}]}
{"op":"mcm","clk":"AOqrtQkAraOmCgCBn6UK","pt":1657542162231,"mc":[{"id":"1.200806927","rc":[{"atb":[[1.23,10.98]],"id":228749}]}]}
{"op":"mcm","clk":"APKrtQkAtqOmCgCGn6UK","pt":1657542162286,"mc":[{"id":"1.200806927","rc":[{"atb":[[1.2,3.21]],"id":228749}]}]}
{"op":"mcm","clk":"AIestQkAyKOmCgCWn6UK","pt":1657542162599,"mc":[{"id":"1.200806927","rc":[{"atb":[[1.23,8.65]],"trd":[[1.23,2050.17]],"ltp":1.23,"tv":121207.14,"id":228749},{"trd":[[5.4,14.97]],"ltp":5.4,"tv":7729.7,"id":2857977}],"tv":128936.84}]}
{"op":"mcm","clk":"AIustQkAz6OmCgCen6UK","pt":1657542162705,"mc":[{"id":"1.200806927","rc":[{"atl":[[1.24,260.38]],"id":228749}]}]}
{"op":"mcm","clk":"AMmstQkAoaSmCgDJn6UK","pt":1657542163647,"mc":[{"id":"1.200806927","rc":[{"atl":[[1.24,259.86]],"trd":[[1.24,4467]],"ltp":1.24,"tv":121208.2,"id":228749}],"tv":128937.9}]}
{"op":"mcm","clk":"AM+stQkApaSmCgDJn6UK","pt":1657542163675,"mc":[{"id":"1.200806927","rc":[{"atb":[[1.22,1006.59]],"id":228749}]}]}
{"op":"mcm","clk":"APOstQkAzqSmCgDkn6UK","pt":1657542164306,"mc":[{"id":"1.200806927","rc":[{"atl":[[1.28,25.74]],"id":228749}]}]}
{"op":"mcm","clk":"AKattQkAjqWmCgD+n6UK","pt":1657542165139,"mc":[{"id":"1.200806927","rc":[{"atb":[[1.23,8.22]],"trd":[[1.23,2051.03]],"ltp":1.23,"tv":121209.06,"id":228749}],"tv":128938.76}]}
{"op":"mcm","clk":"AL+ttQkArqWmCgCQoKUK","pt":1657542165519,"mc":[{"id":"1.200806927","rc":[{"atl":[[1.24,209.85]],"trd":[[1.24,4567]],"ltp":1.24,"tv":121309.06,"id":228749}],"tv":129038.76}]}
{"op":"mcm","clk":"AOWttQkA1aWmCgCjoKUK","pt":1657542165923,"mc":[{"id":"1.200806927","rc":[{"atb":[[1.23,7.17]],"id":228749}]}]}
{"op":"mcm","clk":"APuttQkA4qWmCgCxoKUK","pt":1657542166215,"mc":[{"id":"1.200806927","rc":[{"atb":[[1.22,1136.03]],"id":228749}]}]}
{"op":"mcm","clk":"AO+utQkAxKamCgD6oKUK","pt":1657542167642,"mc":[{"id":"1.200806927","rc":[{"atl":[[1.25,14.73]],"id":228749}]}]}
{"op":"mcm","clk":"APiutQkAzqamCgD7oKUK","pt":1657542167833,"mc":[{"id":"1.200806927","rc":[{"atl":[[1.24,186.19]],"id":228749}]}]}
{"op":"mcm","clk":"AJCvtQkA7aamCgCJoaUK","pt":1657542168209,"mc":[{"id":"1.200806927","rc":[{"atb":[[1.23,6.12]],"id":228749}]}]}
{"op":"mcm","clk":"AMGvtQkAoaemCgCioaUK","pt":1657542168833,"mc":[{"id":"1.200806927","rc":[{"atb":[[1.23,3.49]],"id":228749}]}]}
{"op":"mcm","clk":"AM2vtQkAr6emCgCroaUK","pt":1657542169034,"mc":[{"id":"1.200806927","rc":[{"atl":[[1.24,180.93]],"id":228749}]}]}
{"op":"mcm","clk":"ANmvtQkAwaemCgC1oaUK","pt":1657542169243,"mc":[{"id":"1.200806927","rc":[{"atb":[[1.23,0]],"atl":[[1.23,6.46]],"trd":[[1.23,2058.01]],"ltp":1.23,"tv":121316.04,"id":228749}],"tv":129045.74}]}
{"op":"mcm","clk":"AIuwtQkAgKimCgDioaUK","pt":1657542170048,"mc":[{"id":"1.200806927","rc":[{"atb":[[1.21,0.53]],"atl":[[1.23,4.17]],"trd":[[1.23,2060.3]],"tv":121318.33,"id":228749},{"trd":[[5.3,57.77]],"ltp":5.3,"tv":7730.23,"id":2857977}],"tv":129048.56}]}
{"op":"mcm","clk":"ALSwtQkAsKimCgCEoqUK","pt":1657542170609,"mc":[{"id":"1.200806927","rc":[{"atl":[[1.24,135.59],[1.23,0]],"trd":[[1.23,2068.64]],"tv":121326.67,"id":228749}],"tv":129056.9}]}
{"op":"mcm","clk":"AKOxtQkApKmmCgDJoqUK","pt":1657542172310,"mc":[{"id":"1.200806927","rc":[{"atl":[[1.24,134.54]],"id":228749}]}]}
{"op":"mcm","clk":"ANCxtQkA16mmCgDloqUK","pt":1657542172953,"mc":[{"id":"1.200806927","rc":[{"atl":[[1.23,0.22]],"id":228749}]}]}
{"op":"mcm","clk":"ANWxtQkA4ammCgDroqUK","pt":1657542173066,"mc":[{"id":"1.200806927","rc":[{"atl":[[1.23,0.75]],"id":228749}]}]}
{"op":"mcm","clk":"AL+ytQkA0aqmCgCpo6UK","pt":1657542174445,"mc":[{"id":"1.200806927","rc":[{"atl":[[1.24,130.03],[1.23,0]],"trd":[[1.23,2069.07]],"tv":121327.1,"id":228749}],"tv":129057.33}]}
{"op":"mcm","clk":"ANeytQkA56qmCgC2o6UK","pt":1657542174769,"mc":[{"id":"1.200806927","rc":[{"atl":[[1.23,2.07]],"trd":[[1.23,2069.63]],"tv":121327.66,"id":228749},{"trd":[[5.3,57.9]],"tv":7730.36,"id":2857977}],"tv":129058.02}]}
{"op":"mcm","clk":"ANiytQkA7qqmCgC3o6UK","pt":1657542174858,"mc":[{"id":"1.200806927","rc":[{"atl":[[1.24,121.39],[1.23,0]],"trd":[[1.24,4575.64],[1.23,2071.7]],"ltp":1.24,"tv":121338.37,"id":228749},{"atb":[[5.2,0]],"trd":[[5.2,69.62],[5.3,58.38],[5.1,13.34]],"ltp":5.1,"tv":7733.05,"id":2857977}],"tv":129071.42}]}
{"op":"mcm","clk":"AK2ztQkAzqumCgDwo6UK","pt":1657542176243,"mc":[{"id":"1.200806927","rc":[{"atl":[[1.24,120.68]],"trd":[[1.24,4576.35]],"tv":121339.08,"id":228749},{"trd":[[5.1,13.51]],"tv":7733.22,"id":2857977}],"tv":129072.3}]}
{"op":"mcm","clk":"AIa0tQkAlKymCgCopKUK","pt":1657542177323,"mc":[{"id":"1.200806927","rc":[{"atb":[[1.22,1133.6]],"trd":[[1.22,1155.6]],"ltp":1.22,"tv":121341.51,"id":228749},{"trd":[[5.6,10.24]],"ltp":5.6,"tv":7733.75,"id":2857977}],"tv":129075.26}]}
{"op":"mcm","clk":"ALe0tQkAwKymCgC8pKUK","pt":1657542177951,"mc":[{"id":"1.200806927","rc":[{"atl":[[1.23,1.05]],"id":228749}]}]}
{"op":"mcm","clk":"AM20tQkA0qymCgDLpKUK","pt":1657542178261,"mc":[{"id":"1.200806927","rc":[{"atl":[[1.24,119.49],[1.23,0]],"trd":[[1.24,4577.54],[1.23,2072.75]],"ltp":1.24,"tv":121343.75,"id":228749},{"trd":[[5.3,58.62],[5.1,13.8]],"ltp":5.1,"tv":7734.28,"id":2857977}],"tv":129078.03}]}
{"op":"mcm","clk":"ALe1tQkAtK2mCgCUpaUK","pt":1657542179648,"mc":[{"id":"1.200806927","rc":[{"atl":[[1.24,115.96]],"id":228749}]}]}
{"op":"mcm","clk":"APq1tQkA+K2mCgC+paUK","pt":1657542180543,"mc":[{"id":"1.200806927","rc":[{"atl":[[1.3,314.86]],"id":228749}]}]}
{"op":"mcm","clk":"AI+2tQkAkq6mCgDNpaUK","pt":1657542180857,"mc":[{"id":"1.200806927","rc":[{"atl":[[1.23,2.1]],"id":228749}]}]}
{"op":"mcm","clk":"ALi2tQkAya6mCgDrpaUK","pt":1657542181428,"mc":[{"id":"1.200806927","rc":[{"atl":[[1.25,13.15]],"id":228749}]}]}
{"op":"mcm","clk":"AIu3tQkApa+mCgCfpqUK","pt":1657542182579,"mc":[{"id":"1.200806927","rc":[{"atb":[[1.22,1130.97]],"id":228749}]}]}
{"op":"mcm","clk":"AM+3tQkA8K+mCgDDpqUK","pt":1657542183413,"mc":[{"id":"1.200806927","rc":[{"atb":[[1.22,1001.53]],"id":228749}]}]}
{"op":"mcm","clk":"AOG3tQkAkbCmCgDSpqUK","pt":1657542183745,"mc":[{"id":"1.200806927","rc":[{"atb":[[1.22,999.1]],"trd":[[1.22,1158.03]],"ltp":1.22,"tv":121346.18,"id":228749},{"trd":[[5.6,10.77]],"ltp":5.6,"tv":7734.81,"id":2857977}],"tv":129080.99}]}
{"op":"mcm","clk":"AOe3tQkAnbCmCgDYpqUK","pt":1657542183846,"mc":[{"id":"1.200806927","rc":[{"atl":[[1.24,115.43],[1.23,0]],"id":228749}]}]}
{"op":"mcm","clk":"AJK4tQkA2LCmCgDspqUK","pt":1657542184563,"mc":[{"id":"1.200806927","rc":[{"atb":[[5.2,0.11]],"id":2857977}]}]}
{"op":"mcm","clk":"AJO5tQkA27GmCgDGp6UK","pt":1657542186298,"mc":[{"id":"1.200806927","rc":[{"atl":[[1.23,2.63]],"id":228749},{"atb":[[5.4,1.04]],"id":2857977}]}]}
{"op":"mcm","clk":"ALC5tQkA/LGmCgDTp6UK","pt":1657542186750,"mc":[{"id":"1.200806927","rc":[{"atb":[[5.4,0.61]],"trd":[[5.4,15.83]],"ltp":5.4,"tv":7735.67,"id":2857977}],"tv":129081.85}]}
{"op":"mcm","clk":"AL25tQkAj7KmCgDbp6UK","pt":1657542186967,"mc":[{"id":"1.200806927","rc":[{"atb":[[1.13,1.17]],"id":228749}]}]}
{"op":"mcm","clk":"AM25tQkAn7KmCgDop6UK","pt":1657542187239,"mc":[{"id":"1.200806927","rc":[{"atb":[[1.22,990.56]],"trd":[[1.22,1175.12]],"tv":121363.27,"id":228749}],"tv":129098.94}]}
{"op":"mcm","clk":"AP+5tQkA3LKmCgCGqKUK","pt":1657542187934,"mc":[{"id":"1.200806927","rc":[{"atl":[[1.24,98.18]],"id":228749}]}]}
{"op":"mcm","clk":"AJS6tQkA77KmCgCVqKUK","pt":1657542188225,"mc":[{"id":"1.200806927","rc":[{"atb":[[5.4,0.39]],"trd":[[5.4,16.27]],"tv":7736.11,"id":2857977}],"tv":129099.38}]}
{"op":"mcm","clk":"AOe7tQkAn7SmCgCdqaUK","pt":1657542190841,"mc":[{"id":"1.200806927","rc":[{"atl":[[1.24,95.55]],"id":228749}]}]}
{"op":"mcm","clk":"AMq8tQkA+7SmCgDHqaUK","pt":1657542192131,"mc":[{"id":"1.200806927","rc":[{"atb":[[1.23,6.18]],"atl":[[1.23,0]],"trd":[[1.23,2074.46]],"ltp":1.23,"tv":121364.98,"id":228749},{"atb":[[5.4,0]],"trd":[[5.4,16.66]],"tv":7736.5,"id":2857977}],"tv":129101.48}]}
{"op":"mcm","clk":"AI+9tQkAwLWmCgDyqaUK","pt":1657542193070,"mc":[{"id":"1.200806927","rc":[{"atb":[[1.22,986.22],[1.23,0]],"id":228749}]}]}
{"op":"mcm","clk":"ALW9tQkA5bWmCgCJqqUK","pt":1657542193485,"mc":[{"id":"1.200806927","rc":[{"atl":[[1.24,90.82]],"id":228749}]}]}
{"op":"mcm","clk":"APO9tQkApbamCgC0qqUK","pt":1657542194273,"mc":[{"id":"1.200806927","rc":[{"atb":[[1.24,320.58]],"atl":[[1.24,0]],"trd":[[1.24,4759.63]],"ltp":1.24,"tv":121547.07,"id":228749},{"atb":[[5.2,0]],"trd":[[5.2,69.72]],"ltp":5.2,"tv":7736.6,"id":2857977}],"tv":129283.67}]}
{"op":"mcm","clk":"ALG/tQkA27emCgDDq6UK","pt":1657542196713,"mc":[{"id":"1.200806927","rc":[{"atb":[[1.23,0.53]],"id":228749}]}]}
{"op":"mcm","clk":"AMC/tQkA6LemCgDNq6UK","pt":1657542196901,"mc":[{"id":"1.200806927","rc":[{"atb":[[1.24,347.63]],"id":228749}]}]}
{"op":"mcm","clk":"AMDAtQkA2rimCgCNrKUK","pt":1657542198407,"mc":[{"id":"1.200806927","rc":[{"atb":[[1.24,1347.63]],"id":228749}]}]}
{"op":"mcm","clk":"AMfAtQkA4rimCgCSrKUK","pt":1657542198504,"mc":[{"id":"1.200806927","rc":[{"atb":[[1.23,1.06]],"id":228749}]}]}
{"op":"mcm","clk":"AIvBtQkAmbmmCgC9rKUK","pt":1657542199391,"mc":[{"id":"1.200806927","rc":[{"atb":[[1.24,1337.11]],"trd":[[1.24,4780.67]],"tv":121568.11,"id":228749}],"tv":129304.71}]}
{"op":"mcm","clk":"AMfBtQkAyrmmCgDXrKUK","pt":1657542200130,"mc":[{"id":"1.200806927","rc":[{"atb":[[1.23,211.43]],"id":228749}]}]}
{"op":"mcm","clk":"ALPCtQkArbqmCgCMraUK","pt":1657542201334,"mc":[{"id":"1.200806927","rc":[{"atb":[[1.24,337.11]],"id":228749}]}]}
{"op":"mcm","clk":"AOnCtQkA5LqmCgCtraUK","pt":1657542202018,"mc":[{"id":"1.200806927","rc":[{"atb":[[1.24,331.85]],"trd":[[1.24,4791.19]],"tv":121578.63,"id":228749}],"tv":129315.23}]}
{"op":"mcm","clk":"AOzDtQkAgrymCgCOrqUK","pt":1657542203820,"mc":[{"id":"1.200806927","rc":[{"atl":[[1.25,12.72]],"trd":[[1.25,1499.34]],"ltp":1.25,"tv":121579.06,"id":228749},{"trd":[[5,16.19]],"ltp":5,"tv":7736.71,"id":2857977}],"tv":129315.77}]}
{"op":"mcm","clk":"AIbEtQkAqLymCgCdrqUK","pt":1657542204186,"mc":[{"id":"1.200806927","rc":[{"atb":[[1.24,332.64]],"id":228749},{"atl":[[5.3,0.72]],"id":2857977}]}]}
{"op":"mcm","clk":"ALTEtQkA5rymCgC7rqUK","pt":1657542204906,"mc":[{"id":"1.200806927","rc":[{"atb":[[1.23,210.9]],"id":228749}]}]}
{"op":"mcm","clk":"AMLEtQkA8rymCgDGrqUK","pt":1657542205113,"mc":[{"id":"1.200806927","rc":[{"atb":[[1.24,332.11]],"trd":[[1.24,4792.25]],"ltp":1.24,"tv":121580.12,"id":228749}],"tv":129316.83}]}
{"op":"mcm","clk":"AJ7FtQkAyr2mCgDkrqUK","pt":1657542206301,"mc":[{"id":"1.200806927","rc":[{"atb":[[1.18,2.63]],"id":228749}]}]}
{"op":"mcm","clk":"AK/FtQkA1L2mCgDorqUK","pt":1657542206430,"mc":[{"id":"1.200806927","rc":[{"atb":[[1.25,987.28]],"atl":[[1.25,0]],"trd":[[1.25,1524.78]],"ltp":1.25,"tv":121605.56,"id":228749}],"tv":129342.27}]}
{"op":"mcm","clk":"ANvFtQkA/72mCgD8rqUK","pt":1657542207031,"mc":[{"id":"1.200806927","rc":[{"atb":[[1.25,982.02]],"trd":[[1.25,1535.3]],"tv":121616.08,"id":228749}],"tv":129352.79}]}
{"op":"mcm","clk":"AOLFtQkAib6mCgCAr6UK","pt":1657542207122,"mc":[{"id":"1.200806927","rc":[{"atb":[[1.25,979.5]],"trd":[[1.25,1537.82]],"tv":121618.6,"id":228749},{"trd":[[5,16.82]],"tv":7737.34,"id":2857977}],"tv":129355.94}]}
{"op":"mcm","clk":"AJPGtQkAvr6mCgCdr6UK","pt":1657542207827,"mc":[{"id":"1.200806927","rc":[{"atb":[[1.25,979.1]],"trd":[[1.25,1538.62]],"tv":121619.4,"id":228749}],"tv":129356.74}]}
{"op":"mcm","clk":"AKDGtQkA0b6mCgCqr6UK","pt":1657542208012,"mc":[{"id":"1.200806927","rc":[{"atb":[[1.25,974.37]],"trd":[[1.25,1548.08]],"tv":121628.86,"id":228749}],"tv":129366.2}]}
{"op":"mcm","clk":"ALDGtQkA476mCgCxr6UK","pt":1657542208220,"mc":[{"id":"1.200806927","rc":[{"atb":[[1.25,973.84]],"trd":[[1.25,1549.14]],"tv":121629.92,"id":228749}],"tv":129367.26}]}
{"op":"mcm","clk":"ALjGtQkA676mCgC1r6UK","pt":1657542208337,"mc":[{"id":"1.200806927","rc":[{"atb":[[1.25,973.31]],"trd":[[1.25,1550.2]],"tv":121630.98,"id":228749}],"tv":129368.32}]}
{"op":"mcm","clk":"AMLGtQkA/b6mCgC7r6UK","pt":1657542208539,"mc":[{"id":"1.200806927","rc":[{"atb":[[1.21,0],[1.25,962.79]],"trd":[[1.25,1571.24]],"tv":121652.02,"id":228749}],"tv":129389.36}]}
{"op":"mcm","clk":"AMbGtQkAiL+mCgC/r6UK","pt":1657542208606,"mc":[{"id":"1.200806927","rc":[{"atb":[[1.25,959.19]],"trd":[[1.25,1574.84]],"tv":121655.62,"id":228749},{"trd":[[5,17.72]],"tv":7738.24,"id":2857977}],"tv":129393.86}]}
{"op":"mcm","clk":"AODGtQkApb+mCgDRr6UK","pt":1657542209011,"mc":[{"id":"1.200806927","rc":[{"atl":[[5,1.8]],"id":2857977}]}]}
{"op":"mcm","clk":"AOnGtQkArb+mCgDVr6UK","pt":1657542209130,"mc":[{"id":"1.200806927","rc":[{"atl":[[5,2.33]],"id":2857977}]}]}
{"op":"mcm","clk":"AInHtQkAw7+mCgDlr6UK","pt":1657542209612,"mc":[{"id":"1.200806927","rc":[{"atb":[[1.25,958.66]],"trd":[[1.25,1575.9]],"tv":121656.68,"id":228749}],"tv":129394.92}]}
{"op":"mcm","clk":"AKbHtQkA3L+mCgDzr6UK","pt":1657542210039,"mc":[{"id":"1.200806927","rc":[{"atb":[[1.25,950.77]],"trd":[[1.25,1591.68]],"tv":121672.46,"id":228749}],"tv":129410.7}]}
{"op":"mcm","clk":"AODHtQkAiMCmCgCasKUK","pt":1657542210721,"mc":[{"id":"1.200806927","rc":[{"atb":[[1.25,934.99]],"trd":[[1.25,1623.24]],"tv":121704.02,"id":228749}],"tv":129442.26}]}
{"op":"mcm","clk":"APXHtQkAnsCmCgCrsKUK","pt":1657542211020,"mc":[{"id":"1.200806927","rc":[{"atb":[[1.25,939.2]],"id":228749}]}]}
{"op":"mcm","clk":"AIPItQkAqcCmCgCzsKUK","pt":1657542211227,"mc":[{"id":"1.200806927","rc":[{"atb":[[1.23,210.37],[1.25,912.9]],"trd":[[1.25,1675.84]],"tv":121756.62,"id":228749}],"tv":129494.86}]}
{"op":"mcm","clk":"AIvItQkAscCmCgC0sKUK","pt":1657542211304,"mc":[{"id":"1.200806927","rc":[{"atl":[[5,2.44]],"id":2857977}]}]}
{"op":"mcm","clk":"AKHItQkAy8CmCgDCsKUK","pt":1657542211615,"mc":[{"id":"1.200806927","rc":[{"atb":[[1.25,910.27]],"trd":[[1.25,1681.1]],"tv":121761.88,"id":228749}],"tv":129500.12}]}
{"op":"mcm","clk":"AKjItQkA1cCmCgDFsKUK","pt":1657542211727,"mc":[{"id":"1.200806927","rc":[{"atb":[[1.22,0]],"id":228749}]}]}
{"op":"mcm","clk":"AMfItQkA9cCmCgDTsKUK","pt":1657542212128,"mc":[{"id":"1.200806927","rc":[{"atb":[[1.25,910.01]],"trd":[[1.25,1681.61]],"tv":121762.39,"id":228749}],"tv":129500.63}]}
{"op":"mcm","clk":"AMDJtQkA9sGmCgCGsaUK","pt":1657542213735,"mc":[{"id":"1.200806927","rc":[{"atb":[[1.25,907.38]],"trd":[[1.25,1686.87]],"tv":121767.65,"id":228749}],"tv":129505.89}]}
{"op":"mcm","clk":"AMnJtQkAg8KmCgCJsaUK","pt":1657542213830,"mc":[{"id":"1.200806927","rc":[{"atb":[[1.25,907.19]],"trd":[[1.25,1687.26]],"tv":121768.04,"id":228749}],"tv":129506.28}]}
{"op":"mcm","clk":"APTJtQkAr8KmCgCjsaUK","pt":1657542214413,"mc":[{"id":"1.200806927","rc":[{"atb":[[1.25,907.09]],"trd":[[1.25,1687.46]],"tv":121768.24,"id":228749}],"tv":129506.48}]}
{"op":"mcm","clk":"AMTKtQkA/cKmCgDZsaUK","pt":1657542215542,"mc":[{"id":"1.200806927","rc":[{"atl":[[5,0.64]],"id":2857977}]}]}
{"op":"mcm","clk":"AKHLtQkAycOmCgCZsqUK","pt":1657542216637,"mc":[{"id":"1.200806927","rc":[{"atb":[[1.25,906.3]],"trd":[[1.25,1689.04]],"tv":121769.82,"id":228749}],"tv":129508.06}]}
{"op":"mcm","clk":"AK/LtQkA18OmCgCisqUK","pt":1657542216844,"mc":[{"id":"1.200806927","rc":[{"atb":[[4.8,0.11]],"id":2857977}]}]}
{"op":"mcm","clk":"AMHLtQkA7cOmCgC0sqUK","pt":1657542217103,"mc":[{"id":"1.200806927","rc":[{"atb":[[1.25,905.77]],"trd":[[1.25,1690.1]],"tv":121770.88,"id":228749}],"tv":129509.12}]}
{"op":"mcm","clk":"AN/LtQkAjsSmCgDJsqUK","pt":1657542217532,"mc":[{"id":"1.200806927","rc":[{"atb":[[1.25,904.04]],"trd":[[1.25,1693.55]],"tv":121774.33,"id":228749}],"tv":129512.57}]}
{"op":"mcm","clk":"APLLtQkAmsSmCgDOsqUK","pt":1657542217735,"mc":[{"id":"1.200806927","rc":[{"atb":[[1.25,704.19]],"trd":[[1.25,2093.25]],"tv":122174.03,"id":228749}],"tv":129912.27}]}
{"op":"mcm","clk":"AJnMtQkAtcSmCgDtsqUK","pt":1657542218232,"mc":[{"id":"1.200806927","rc":[{"atb":[[1.25,701.29]],"trd":[[1.25,2099.05]],"tv":122179.83,"id":228749}],"tv":129918.07}]}
{"op":"mcm","clk":"AMDMtQkA28SmCgCIs6UK","pt":1657542218735,"mc":[{"id":"1.200806927","rc":[{"atb":[[1.25,701.18]],"trd":[[1.25,2099.27]],"tv":122180.05,"id":228749}],"tv":129918.29}]}
{"op":"mcm","clk":"AM7MtQkA6cSmCgCNs6UK","pt":1657542218923,"mc":[{"id":"1.200806927","rc":[{"atb":[[1.25,698.55]],"trd":[[1.25,2104.53]],"tv":122185.31,"id":228749}],"tv":129923.55}]}
{"op":"mcm","clk":"ALDNtQkAucWmCgC2s6UK","pt":1657542220018,"mc":[{"id":"1.200806927","rc":[{"atl":[[1.27,18.65]],"id":228749}]}]}
{"op":"mcm","clk":"ANnNtQkA5cWmCgDRs6UK","pt":1657542220558,"mc":[{"id":"1.200806927","rc":[{"atb":[[1.25,696.71]],"trd":[[1.25,2108.21]],"tv":122188.99,"id":228749}],"tv":129927.23}]}
{"op":"mcm","clk":"AOvNtQkA9MWmCgDbs6UK","pt":1657542220737,"mc":[{"id":"1.200806927","rc":[{"atb":[[1.25,695.66]],"trd":[[1.25,2110.31]],"tv":122191.09,"id":228749}],"tv":129929.33}]}
{"op":"mcm","clk":"AJ/OtQkAoMamCgD2s6UK","pt":1657542221344,"mc":[{"id":"1.200806927","rc":[{"atb":[[1.25,693.56]],"trd":[[1.25,2114.51]],"tv":122195.29,"id":228749}],"tv":129933.53}]}
{"op":"mcm","clk":"AKjOtQkAqsamCgD5s6UK","pt":1657542221418,"mc":[{"id":"1.200806927","rc":[{"atl":[[1.26,17.25]],"id":228749}]}]}
{"op":"mcm","clk":"ALDOtQkAucamCgD/s6UK","pt":1657542221536,"mc":[{"id":"1.200806927","rc":[{"atb":[[1.24,27.84]],"id":228749}]}]}
{"op":"mcm","clk":"AOHOtQkA88amCgCXtKUK","pt":1657542222142,"mc":[{"id":"1.200806927","rc":[{"atb":[[1.2,2.16]],"id":228749}]}]}
{"op":"mcm","clk":"AI3PtQkAlsemCgCytKUK","pt":1657542222675,"mc":[{"id":"1.200806927","rc":[{"atl":[[1.26,17]],"trd":[[1.26,680.69]],"ltp":1.26,"tv":122195.54,"id":228749},{"atb":[[4.8,0]],"trd":[[4.8,57.93]],"ltp":4.8,"tv":7738.3,"id":2857977}],"tv":129933.84}]}
{"op":"mcm","clk":"AK7PtQkAwMemCgDLtKUK","pt":1657542223155,"mc":[{"id":"1.200806927","rc":[{"atb":[[1.25,683.04]],"trd":[[1.25,2135.55]],"ltp":1.25,"tv":122216.58,"id":228749}],"tv":129954.88}]}
{"op":"mcm","clk":"AM7PtQkA58emCgDltKUK","pt":1657542223638,"mc":[{"id":"1.200806927","rc":[{"atl":[[1.26,16.42]],"trd":[[1.26,681.85]],"ltp":1.26,"tv":122217.74,"id":228749}],"tv":129956.04}]}
{"op":"mcm","clk":"AK3QtQkAscimCgCdtaUK","pt":1657542224943,"mc":[{"id":"1.200806927","rc":[{"atb":[[1.25,677.78]],"trd":[[1.25,2146.07]],"ltp":1.25,"tv":122228.26,"id":228749}],"tv":129966.56}]}
{"op":"mcm","clk":"APLQtQkA+8imCgDNtaUK","pt":1657542225927,"mc":[{"id":"1.200806927","rc":[{"atl":[[1.27,19.18]],"id":228749}]}]}
{"op":"mcm","clk":"AJLRtQkAncmmCgDltaUK","pt":1657542226435,"mc":[{"id":"1.200806927","rc":[{"atb":[[1.25,440.34]],"trd":[[1.25,2383.51]],"tv":122465.7,"id":228749},{"atl":[[5,0]],"trd":[[5,78.36]],"ltp":5,"tv":7798.94,"id":2857977}],"tv":130264.64}]}
{"op":"mcm","clk":"AKrRtQkAs8mmCgD1taUK","pt":1657542226746,"mc":[{"id":"1.200806927","rc":[{"atb":[[1.26,292.47]],"atl":[[1.26,0]],"trd":[[1.26,714.69]],"ltp":1.26,"tv":122498.54,"id":228749}],"tv":130297.48}]}
{"op":"mcm","clk":"ALHRtQkAvsmmCgD5taUK","pt":1657542226855,"mc":[{"id":"1.200806927","rc":[{"atl":[[1.27,13.92]],"id":228749}]}]}
{"op":"mcm","clk":"AIXStQkAkMqmCgC3tqUK","pt":1657542228062,"mc":[{"id":"1.200806927","rc":[{"atl":[[1.27,7.26]],"trd":[[1.27,694.97]],"ltp":1.27,"tv":122505.2,"id":228749},{"trd":[[4.7,59.44]],"ltp":4.7,"tv":7800.74,"id":2857977}],"tv":130305.94}]}
{"op":"mcm","clk":"AIvStQkAlsqmCgC5tqUK","pt":1657542228144,"mc":[{"id":"1.200806927","rc":[{"atb":[[1.26,290.41]],"atl":[[1.35,0.86]],"trd":[[1.26,716.75]],"ltp":1.26,"tv":122507.26,"id":228749},{"trd":[[4.9,64.29]],"ltp":4.9,"tv":7801.27,"id":2857977}],"tv":130308.53}]}
{"op":"mcm","clk":"AJ3StQkAt8qmCgDOtqUK","pt":1657542228535,"mc":[{"id":"1.200806927","rc":[{"atb":[[1.26,290.31]],"trd":[[1.26,716.95]],"tv":122507.46,"id":228749}],"tv":130308.73}]}
{"op":"mcm","clk":"AL/StQkA5cqmCgDmtqUK","pt":1657542229084,"mc":[{"id":"1.200806927","rc":[{"atb":[[1.26,287.67]],"trd":[[1.26,722.21]],"tv":122512.72,"id":228749}],"tv":130313.99}]}
{"op":"mcm","clk":"AMrStQkA98qmCgDstqUK","pt":1657542229250,"mc":[{"id":"1.200806927","rc":[{"atb":[[1.26,282.41]],"trd":[[1.26,732.73]],"tv":122523.24,"id":228749}],"tv":130324.51}]}
{"op":"mcm","clk":"AM/StQkA/cqmCgDutqUK","pt":1657542229347,"mc":[{"id":"1.200806927","rc":[{"atb":[[1.26,82.57]],"trd":[[1.26,1132.43]],"tv":122922.94,"id":228749}],"tv":130724.21}]}
{"op":"mcm","clk":"APXStQkAncumCgD9tqUK","pt":1657542229770,"mc":[{"id":"1.200806927","rc":[{"atb":[[1.24,0.79]],"id":228749}]}]}
{"op":"mcm","clk":"AI/TtQkAwMumCgCMt6UK","pt":1657542230133,"mc":[{"id":"1.200806927","rc":[{"atb":[[1.23,0]],"id":228749}]}]}
{"op":"mcm","clk":"AJnTtQkA0cumCgCTt6UK","pt":1657542230329,"mc":[{"id":"1.200806927","rc":[{"atb":[[1.26,79.93]],"trd":[[1.26,1137.69]],"tv":122928.2,"id":228749}],"tv":130729.47}]}
{"op":"mcm","clk":"ALXTtQkA78umCgClt6UK","pt":1657542230749,"mc":[{"id":"1.200806927","rc":[{"atb":[[1.26,75.52]],"atl":[[1.27,6.85]],"trd":[[1.26,1146.53],[1.27,695.38]],"tv":122937.45,"id":228749},{"trd":[[4.7,59.55]],"ltp":4.7,"tv":7801.38,"id":2857977}],"tv":130738.83}]}
{"op":"mcm","clk":"ALjTtQkA+sumCgCot6UK","pt":1657542230846,"mc":[{"id":"1.200806927","rc":[{"atb":[[1.26,72.88]],"trd":[[1.26,1151.79]],"tv":122942.71,"id":228749}],"tv":130744.09}]}
{"op":"mcm","clk":"AL7TtQkAg8ymCgCst6UK","pt":1657542230958,"mc":[{"id":"1.200806927","rc":[{"atl":[[1.27,4.89]],"trd":[[1.27,697.34]],"ltp":1.27,"tv":122944.67,"id":228749},{"trd":[[4.7,60.08]],"tv":7801.91,"id":2857977}],"tv":130746.58}]}
{"op":"mcm","clk":"AL3UtQkAiM2mCgCCuKUK","pt":1657542232957,"mc":[{"id":"1.200806927","rc":[{"atb":[[1.26,70.82]],"trd":[[1.26,1153.85]],"ltp":1.26,"tv":122946.73,"id":228749},{"trd":[[4.9,64.82]],"ltp":4.9,"tv":7802.44,"id":2857977}],"tv":130749.17}]}
{"op":"mcm","clk":"ANLVtQkA+c2mCgDYuKUK","pt":1657542234846,"mc":[{"id":"1.200806927","rc":[{"atb":[[1.26,97.87]],"id":228749},{"atl":[[20,0.26]],"id":2857977}]}]}
{"op":"mcm","clk":"AN3VtQkAgs6mCgDcuKUK","pt":1657542235046,"mc":[{"id":"1.200806927","rc":[{"atb":[[1.26,98.71]],"id":228749}]}]}
{"op":"mcm","clk":"AMzWtQkA+M6mCgCcuaUK","pt":1657542236572,"mc":[{"id":"1.200806927","rc":[{"atl":[[1.27,3.1]],"id":228749}]}]}
{"op":"mcm","clk":"AOvWtQkAnM+mCgCwuaUK","pt":1657542237074,"mc":[{"id":"1.200806927","rc":[{"atl":[[4.8,0.11]],"id":2857977}]}]}
{"op":"mcm","clk":"APvWtQkAq8+mCgC8uaUK","pt":1657542237284,"mc":[{"id":"1.200806927","rc":[{"atb":[[1.26,0],[1.25,0]],"atl":[[1.25,660.54]],"trd":[[1.26,1351.68],[1.25,3264.19]],"ltp":1.25,"tv":124025.24,"id":228749},{"atl":[[4.8,0]],"trd":[[4.8,58.04]],"ltp":4.8,"tv":7802.55,"id":2857977}],"tv":131827.79}]}
{"op":"mcm","clk":"AP7WtQkAsM+mCgDBuaUK","pt":1657542237322,"mc":[{"id":"1.200806927","rc":[{"atl":[[1.27,5.73]],"id":228749}]}]}
{"op":"mcm","clk":"AITXtQkAuc+mCgDGuaUK","pt":1657542237444,"mc":[{"id":"1.200806927","rc":[{"atb":[[1.24,0]],"atl":[[1.23,35.96]],"trd":[[1.24,4793.83],[1.23,2077.57]],"ltp":1.23,"tv":124029.93,"id":228749},{"atl":[[5.3,0]],"trd":[[5.3,59.34]],"ltp":5.3,"tv":7803.27,"id":2857977}],"tv":131833.2}]}
{"op":"mcm","clk":"ALnXtQkA9s+mCgDvuaUK","pt":1657542238254,"mc":[{"id":"1.200806927","rc":[{"atl":[[1.25,661.84]],"id":228749}]}]}
{"op":"mcm","clk":"ANHXtQkAjNCmCgCAuqUK","pt":1657542238564,"mc":[{"id":"1.200806927","rc":[{"atl":[[1.26,210.37]],"id":228749}]}]}
{"op":"mcm","clk":"AOjXtQkAoNCmCgCKuqUK","pt":1657542238833,"mc":[{"id":"1.200806927","rc":[{"atl":[[1.25,1.3]],"id":228749}]}]}
{"op":"mcm","clk":"AKvYtQkA2dCmCgCkuqUK","pt":1657542239664,"mc":[{"id":"1.200806927","rc":[{"atl":[[1.25,130.74]],"id":228749}]}]}
{"op":"mcm","clk":"AN7YtQkAl9GmCgC9uqUK","pt":1657542240359,"mc":[{"id":"1.200806927","rc":[{"atl":[[1.23,35.43]],"trd":[[1.23,2078.63]],"tv":124030.99,"id":228749}],"tv":131834.26}]}
{"op":"mcm","clk":"APbYtQkAtdGmCgDNuqUK","pt":1657542240655,"mc":[{"id":"1.200806927","rc":[{"atl":[[1.23,30.22]],"trd":[[1.23,2089.05]],"tv":124041.41,"id":228749}],"tv":131844.68}]}
{"op":"mcm","clk":"AKTZtQkA3dGmCgDpuqUK","pt":1657542241154,"mc":[{"id":"1.200806927","rc":[{"atl":[[1.25,131.27]],"id":228749}]}]}
{"op":"mcm","clk":"AL7ZtQkA99GmCgD6uqUK","pt":1657542241470,"mc":[{"id":"1.200806927","rc":[{"atl":[[1.26,210.9]],"id":228749}]}]}
{"op":"mcm","clk":"AO/ZtQkArdKmCgCau6UK","pt":1657542242163,"mc":[{"id":"1.200806927","rc":[{"atl":[[1.26,211.43]],"id":228749}]}]}
{"op":"mcm","clk":"APLZtQkAttKmCgCfu6UK","pt":1657542242272,"mc":[{"id":"1.200806927","rc":[{"atl":[[1.26,221.73]],"id":228749}]}]}
{"op":"mcm","clk":"AI3atQkA3NKmCgCuu6UK","pt":1657542242674,"mc":[{"id":"1.200806927","rc":[{"atl":[[1.26,226.73]],"id":228749}]}]}
{"op":"mcm","clk":"ANfatQkAptOmCgDSu6UK","pt":1657542243561,"mc":[{"id":"1.200806927","rc":[{"atl":[[1.23,230.07]],"id":228749}]}]}
{"op":"mcm","clk":"AITbtQkA1dOmCgDhu6UK","pt":1657542244079,"mc":[{"id":"1.200806927","rc":[{"atl":[[1.23,186.98]],"trd":[[1.23,2132.14]],"tv":124084.5,"id":228749},{"trd":[[5.3,69.34]],"tv":7813.27,"id":2857977}],"tv":131897.77}]}
{"op":"mcm","clk":"AInbtQkA39OmCgDnu6UK","pt":1657542244181,"mc":[{"id":"1.200806927","rc":[{"atl":[[1.26,235.15]],"id":228749}]}]}
{"op":"mcm","clk":"ALnbtQkAjtSmCgCAvKUK","pt":1657542244785,"mc":[{"id":"1.200806927","rc":[{"atl":[[1.26,240.41],[1.25,381.27]],"id":228749}]}]}
{"op":"mcm","clk":"ANzbtQkAtNSmCgCTvKUK","pt":1657542245186,"mc":[{"id":"1.200806927","rc":[{"atl":[[1.22,577]],"id":228749}]}]}
{"op":"mcm","clk":"AI3ctQkA29SmCgClvKUK","pt":1657542245649,"mc":[{"id":"1.200806927","rc":[{"atb":[[1.21,5.26]],"id":228749}]}]}
{"op":"mcm","clk":"ALbctQkAjNWmCgC+vKUK","pt":1657542246271,"mc":[{"id":"1.200806927","rc":[{"atl":[[1.22,377]],"trd":[[1.22,1575.12]],"ltp":1.22,"tv":124484.5,"id":228749}],"tv":132297.77}]}
{"op":"mcm","clk":"ALfdtQkAiNamCgCCvaUK","pt":1657542247975,"mc":[{"id":"1.200806927","rc":[{"atb":[[1.19,35.5]],"id":228749}]}]}
{"op":"mcm","clk":"AOvdtQkAsNamCgCavaUK","pt":1657542248558,"mc":[{"id":"1.200806927","rc":[{"atb":[[1.21,0]],"atl":[[1.26,241.72]],"trd":[[1.21,545.92]],"ltp":1.21,"tv":124484.58,"id":228749},{"trd":[[5.8,0.02]],"ltp":5.8,"tv":7813.29,"id":2857977}],"tv":132297.87}]}
{"op":"mcm","clk":"AJretQkA2tamCgCuvaUK","pt":1657542249178,"mc":[{"id":"1.200806927","rc":[{"atl":[[1.26,233.3]],"id":228749}]}]}
{"op":"mcm","clk":"AMfetQkA/tamCgDIvaUK","pt":1657542249681,"mc":[{"id":"1.200806927","rc":[{"atl":[[1.22,374.37],[1.25,380.74]],"trd":[[1.22,1580.38]],"ltp":1.22,"tv":124489.84,"id":228749}],"tv":132303.13}]}
{"op":"mcm","clk":"AN/etQkAlNemCgDWvaUK","pt":1657542249969,"mc":[{"id":"1.200806927","rc":[{"atb":[[1.2,1002.96]],"atl":[[1.22,373.84]],"trd":[[1.22,1581.44]],"tv":124490.9,"id":228749}],"tv":132304.19}]}
{"op":"mcm","clk":"AIrftQkAxtemCgD1vaUK","pt":1657542250480,"mc":[{"id":"1.200806927","rc":[{"atl":[[1.25,251.3]],"id":228749}]}]}
{"op":"mcm","clk":"AKbftQkA7NemCgCKvqUK","pt":1657542250888,"mc":[{"id":"1.200806927","rc":[{"atl":[[1.22,373.26]],"trd":[[1.22,1582.02]],"tv":124491.48,"id":228749},{"trd":[[5.5,30.23]],"ltp":5.5,"tv":7813.42,"id":2857977}],"tv":132304.9}]}
{"op":"mcm","clk":"AMTftQkAkdimCgCevqUK","pt":1657542251260,"mc":[{"id":"1.200806927","rc":[{"atb":[[1.2,1132.4]],"atl":[[1.22,372.81]],"trd":[[1.22,1582.47]],"tv":124491.93,"id":228749},{"trd":[[5.5,30.33]],"tv":7813.52,"id":2857977}],"tv":132305.45}]}
{"op":"mcm","clk":"AM/ftQkApdimCgCovqUK","pt":1657542251470,"mc":[{"id":"1.200806927","rc":[{"atl":[[1.22,370.81]],"trd":[[1.22,1586.47]],"tv":124495.93,"id":228749}],"tv":132309.45}]}
{"op":"mcm","clk":"APjftQkA5NimCgDMvqUK","pt":1657542252186,"mc":[{"id":"1.200806927","rc":[{"atb":[[1.21,10.52]],"id":228749}]}]}
{"op":"mcm","clk":"AJHgtQkA+dimCgDavqUK","pt":1657542252487,"mc":[{"id":"1.200806927","rc":[{"atl":[[1.25,1.3]],"id":228749}]}]}
{"op":"mcm","clk":"AKDgtQkAjNmmCgDnvqUK","pt":1657542252696,"mc":[{"id":"1.200806927","rc":[{"atb":[[1.21,0]],"atl":[[1.21,94.66]],"id":228749}]}]}
{"op":"mcm","clk":"ALHgtQkAmNmmCgDwvqUK","pt":1657542252862,"mc":[{"id":"1.200806927","rc":[{"atb":[[1.2,1106.1]],"atl":[[1.35,0]],"trd":[[1.2,7381.57]],"ltp":1.2,"tv":124500.25,"id":228749}],"tv":132313.77}]}
