{"op":"mcm","clk":"APa3qQkAke6ZCgC9hZ4K","pt":1657539996486,"mc":[{"id":"1.200806927","rc":[{"atb":[[1.15,24.65]],"id":228749}]}]}
{"op":"mcm","clk":"AK64qQkA6O6ZCgDkhZ4K","pt":1657539997200,"mc":[{"id":"1.200806927","rc":[{"atl":[[7.6,2.26]],"id":2857977}]}]}
{"op":"mcm","clk":"ANi4qQkApO+ZCgD7hZ4K","pt":1657539997693,"mc":[{"id":"1.200806927","rc":[{"atl":[[7.6,2.79]],"id":2857977}]}]}
{"op":"mcm","clk":"AIC5qQkA2e+ZCgCZhp4K","pt":1657539998105,"mc":[{"id":"1.200806927","rc":[{"atb":[[1.15,2246.65]],"id":228749}]}]}
{"op":"mcm","clk":"AMq5qQkAz/CZCgDKhp4K","pt":1657539999094,"mc":[{"id":"1.200806927","rc":[{"atb":[[1.15,2257.17]],"id":228749}]}]}
{"op":"mcm","clk":"ANG5qQkA3PCZCgDQhp4K","pt":1657539999205,"mc":[{"id":"1.200806927","rc":[{"atl":[[7.6,3.32]],"id":2857977}]}]}
{"op":"mcm","clk":"APO5qQkAiPGZCgDrhp4K","pt":1657539999723,"mc":[{"id":"1.200806927","rc":[{"atb":[[1.15,2144.22]],"trd":[[1.15,3813.13]],"ltp":1.15,"tv":34520.49,"id":228749}],"tv":37690.77}]}
{"op":"mcm","clk":"AJm6qQkAuvGZCgCEh54K","pt":1657540000192,"mc":[{"id":"1.200806927","rc":[{"atb":[[1.15,1143.42]],"trd":[[1.15,5814.73]],"tv":36522.09,"id":228749}],"tv":39692.37}]}
{"op":"mcm","clk":"AMC6qQkA7vGZCgCgh54K","pt":1657540000604,"mc":[{"id":"1.200806927","rc":[{"atb":[[1.15,552.5]],"atl":[[1.16,1686.06]],"trd":[[1.15,7016.95]],"tv":37724.31,"id":228749}],"con":true,"tv":40894.59}]}
{"op":"mcm","clk":"ANu6qQkAjvKZCgC1h54K","pt":1657540000919,"mc":[{"id":"1.200806927","rc":[{"atl":[[1.16,1685.44]],"trd":[[1.16,5624.11]],"ltp":1.16,"tv":37724.93,"id":228749},{"trd":[[7.2,820.21]],"ltp":7.2,"tv":3170.38,"id":2857977}],"tv":40895.31}]}
{"op":"mcm","clk":"AN+6qQkAmvKZCgDAh54K","pt":1657540001017,"mc":[{"id":"1.200806927","rc":[{"atb":[[1.15,580.9]],"id":228749}]}]}
{"op":"mcm","clk":"AOe6qQkAo/KZCgDJh54K","pt":1657540001095,"mc":[{"id":"1.200806927","rc":[{"atb":[[1.03,67.92]],"id":228749}]}]}
{"op":"mcm","clk":"AJa7qQkA2PKZCgDoh54K","pt":1657540001619,"mc":[{"id":"1.200806927","rc":[{"atb":[[1.03,67.69]],"atl":[[1.16,1684.39]],"id":228749},{"atb":[[5,1.2]],"id":2857977}]}]}
{"op":"mcm","clk":"AMe7qQkAh/OZCgCKiJ4K","pt":1657540002219,"mc":[{"id":"1.200806927","rc":[{"atl":[[1.16,1671.98]],"trd":[[1.16,5636.52]],"tv":37737.34,"id":228749},{"trd":[[7.2,822.21]],"tv":3172.38,"id":2857977}],"tv":40909.72}]}
{"op":"mcm","clk":"APG7qQkAvfOZCgCjiJ4K","pt":1657540002792,"mc":[{"id":"1.200806927","rc":[{"atl":[[1.16,1669.31]],"trd":[[1.16,5639.19]],"tv":37740.01,"id":228749},{"trd":[[7.2,822.65]],"tv":3172.82,"id":2857977}],"tv":40912.83}]}
{"op":"mcm","clk":"AKW9qQkAxfWZCgCciZ4K","pt":1657540005307,"mc":[{"id":"1.200806927","rc":[{"atb":[[1.15,582.21]],"id":228749}]}]}
{"op":"mcm","clk":"AK29qQkA0fWZCgCgiZ4K","pt":1657540005399,"mc":[{"id":"1.200806927","rc":[{"atl":[[1.16,1663.72]],"trd":[[1.16,5644.78]],"tv":37745.6,"id":228749},{"trd":[[7.2,823.55]],"tv":3173.72,"id":2857977}],"tv":40919.32}]}
{"op":"mcm","clk":"ALa9qQkA3vWZCgCkiZ4K","pt":1657540005513,"mc":[{"id":"1.200806927","rc":[{"atb":[[1.15,591.23]],"atl":[[1.16,1661.05]],"trd":[[1.16,5647.45]],"tv":37748.27,"id":228749},{"trd":[[7.2,823.98]],"tv":3174.15,"id":2857977}],"tv":40922.42}]}
{"op":"mcm","clk":"ANW9qQkAgvaZCgC0iZ4K","pt":1657540005901,"mc":[{"id":"1.200806927","rc":[{"atl":[[1.16,1655.79]],"id":228749}]}]}
{"op":"mcm","clk":"AOa9qQkAmfaZCgC4iZ4K","pt":1657540006110,"mc":[{"id":"1.200806927","rc":[{"atb":[[1.15,569.3]],"trd":[[1.15,7060.81]],"ltp":1.15,"tv":37792.13,"id":228749}],"tv":40966.28}]}
{"op":"mcm","clk":"AO69qQkAqfaZCgC+iZ4K","pt":1657540006227,"mc":[{"id":"1.200806927","rc":[{"atb":[[1.15,558.78]],"trd":[[1.15,7081.85]],"tv":37813.17,"id":228749}],"tv":40987.32}]}
{"op":"mcm","clk":"AIu+qQkAz/aZCgDNiZ4K","pt":1657540006587,"mc":[{"id":"1.200806927","rc":[{"atl":[[7.6,2.79]],"id":2857977}]}]}
{"op":"mcm","clk":"AJO+qQkA4faZCgDWiZ4K","pt":1657540006701,"mc":[{"id":"1.200806927","rc":[{"atl":[[1.16,1655.56]],"trd":[[1.16,5647.91]],"ltp":1.16,"tv":37813.63,"id":228749}],"tv":40987.78}]}
{"op":"mcm","clk":"ALi+qQkAjveZCgDxiZ4K","pt":1657540007103,"mc":[{"id":"1.200806927","rc":[{"atb":[[1.03,66.85]],"id":228749}]}]}
{"op":"mcm","clk":"ANq+qQkAvPeZCgCLip4K","pt":1657540007507,"mc":[{"id":"1.200806927","rc":[{"atl":[[8,575.04]],"id":2857977}]}]}
{"op":"mcm","clk":"AIG/qQkA5feZCgCjip4K","pt":1657540007927,"mc":[{"id":"1.200806927","rc":[{"atl":[[1.16,1650.3]],"trd":[[1.16,5658.43]],"tv":37824.15,"id":228749}],"tv":40998.3}]}
{"op":"mcm","clk":"AJO/qQkA/PeZCgC0ip4K","pt":1657540008117,"mc":[{"id":"1.200806927","rc":[{"atl":[[1.16,1649.06]],"trd":[[1.16,5659.67]],"tv":37825.39,"id":228749},{"trd":[[7.2,824.18]],"tv":3174.35,"id":2857977}],"tv":40999.74}]}
{"op":"mcm","clk":"AJu/qQkAiviZCgC6ip4K","pt":1657540008226,"mc":[{"id":"1.200806927","rc":[{"atl":[[1.16,1648.53]],"trd":[[1.16,5660.73]],"tv":37826.45,"id":228749}],"tv":41000.8}]}
{"op":"mcm","clk":"ALS/qQkArPiZCgDSip4K","pt":1657540008520,"mc":[{"id":"1.200806927","rc":[{"atl":[[1.16,1644.64]],"trd":[[1.16,5668.51]],"tv":37834.23,"id":228749}],"tv":41008.58}]}
{"op":"mcm","clk":"AIDAqQkA+viZCgCIi54K","pt":1657540009335,"mc":[{"id":"1.200806927","rc":[{"atl":[[1.16,1644.02]],"trd":[[1.16,5669.13]],"tv":37834.85,"id":228749},{"trd":[[7.2,824.28]],"tv":3174.45,"id":2857977}],"tv":41009.3}]}
{"op":"mcm","clk":"AIrAqQkAgvmZCgCLi54K","pt":1657540009428,"mc":[{"id":"1.200806927","rc":[{"atb":[[1.15,293.61]],"trd":[[1.15,7612.19]],"ltp":1.15,"tv":38365.19,"id":228749}],"tv":41539.64}]}
{"op":"mcm","clk":"AJnAqQkAjvmZCgCRi54K","pt":1657540009545,"mc":[{"id":"1.200806927","rc":[{"atb":[[5,0]],"id":2857977}]}]}
{"op":"mcm","clk":"AMjAqQkAuPmZCgCqi54K","pt":1657540009931,"mc":[{"id":"1.200806927","rc":[{"atb":[[1.15,59.44]],"atl":[[1.16,1638.43]],"trd":[[1.16,5674.72]],"ltp":1.16,"tv":38370.78,"id":228749},{"trd":[[7.2,825.18]],"tv":3175.35,"id":2857977}],"tv":41546.13}]}
{"op":"mcm","clk":"AOLAqQkA2fmZCgDBi54K","pt":1657540010229,"mc":[{"id":"1.200806927","rc":[{"atb":[[1.15,0.99]],"trd":[[1.15,7729.09]],"ltp":1.15,"tv":38487.68,"id":228749}],"tv":41663.03}]}
{"op":"mcm","clk":"APXAqQkA5/mZCgDNi54K","pt":1657540010410,"mc":[{"id":"1.200806927","rc":[{"atl":[[1.16,1637.77]],"trd":[[1.16,5675.38]],"ltp":1.16,"tv":38488.34,"id":228749},{"trd":[[7.2,825.28]],"tv":3175.45,"id":2857977}],"tv":41663.79}]}
{"op":"mcm","clk":"AIbBqQkA+vmZCgDZi54K","pt":1657540010631,"mc":[{"id":"1.200806927","rc":[{"atb":[[1.15,0]],"atl":[[1.15,6.88]],"trd":[[1.15,7747.52]],"ltp":1.15,"tv":38506.77,"id":228749},{"atl":[[7.6,0]],"trd":[[7.6,286.26]],"ltp":7.6,"tv":3178.24,"id":2857977}],"tv":41685.01}]}
{"op":"mcm","clk":"AMnBqQkAxfqZCgCDjJ4K","pt":1657540011405,"mc":[{"id":"1.200806927","rc":[{"atl":[[1.15,188.69]],"id":228749}]}]}
{"op":"mcm","clk":"AOzBqQkA9fqZCgCVjJ4K","pt":1657540011829,"mc":[{"id":"1.200806927","rc":[{"atb":[[1.12,202.63]],"id":228749}]}]}
{"op":"mcm","clk":"APLBqQkAg/uZCgCZjJ4K","pt":1657540011956,"mc":[{"id":"1.200806927","rc":[{"atl":[[1.15,188.16]],"id":228749}]}]}
{"op":"mcm","clk":"AKPCqQkAyvuZCgC8jJ4K","pt":1657540012535,"mc":[{"id":"1.200806927","rc":[{"atl":[[1.15,190.79]],"id":228749}]}]}
{"op":"mcm","clk":"AKXDqQkA+/yZCgCYjZ4K","pt":1657540014256,"mc":[{"id":"1.200806927","rc":[{"atl":[[1.15,173.82]],"trd":[[1.15,7764.49]],"tv":38523.74,"id":228749},{"trd":[[7.6,288.83]],"tv":3180.81,"id":2857977}],"tv":41704.55}]}
{"op":"mcm","clk":"AKLEqQkAjP6ZCgDqjZ4K","pt":1657540015626,"mc":[{"id":"1.200806927","rc":[{"atl":[[1.16,2238.88]],"id":228749}]}]}
{"op":"mcm","clk":"ANTEqQkAzP6ZCgCOjp4K","pt":1657540016243,"mc":[{"id":"1.200806927","rc":[{"atl":[[1.15,179.08]],"id":228749}]}]}
{"op":"mcm","clk":"AO3EqQkA5P6ZCgCYjp4K","pt":1657540016467,"mc":[{"id":"1.200806927","rc":[{"atl":[[1.15,176.24]],"trd":[[1.15,7767.33]],"tv":38526.58,"id":228749},{"trd":[[7.6,289.26]],"tv":3181.24,"id":2857977}],"tv":41707.82}]}
{"op":"mcm","clk":"APHEqQkA7f6ZCgCfjp4K","pt":1657540016535,"mc":[{"id":"1.200806927","rc":[{"atb":[[1.11,200]],"atl":[[1000,0.33]],"id":228749}]}]}
{"op":"mcm","clk":"AJrFqQkAmv+ZCgC/jp4K","pt":1657540017019,"mc":[{"id":"1.200806927","rc":[{"atl":[[1000,0.13]],"id":228749}]}]}
{"op":"mcm","clk":"AIXGqQkAj4CaCgDxjp4K","pt":1657540018246,"mc":[{"id":"1.200806927","rc":[{"atl":[[1.15,173.61]],"trd":[[1.15,7772.59]],"tv":38531.84,"id":228749}],"tv":41713.08}]}
{"op":"mcm","clk":"AJnGqQkAqoCaCgD6jp4K","pt":1657540018553,"mc":[{"id":"1.200806927","rc":[{"atl":[[1.15,172.91]],"trd":[[1.15,7773.29]],"tv":38532.54,"id":228749},{"trd":[[7.6,289.36]],"tv":3181.34,"id":2857977}],"tv":41713.88}]}
{"op":"mcm","clk":"AL/GqQkA5YCaCgCQj54K","pt":1657540019023,"mc":[{"id":"1.200806927","rc":[{"atl":[[1.15,13.15]],"id":228749}]}]}
{"op":"mcm","clk":"AN7GqQkAloGaCgCnj54K","pt":1657540019452,"mc":[{"id":"1.200806927","rc":[{"atl":[[1.15,11.73]],"trd":[[1.15,7774.71]],"tv":38533.96,"id":228749},{"trd":[[7.6,289.58]],"tv":3181.56,"id":2857977}],"tv":41715.52}]}
{"op":"mcm","clk":"AJ3HqQkA74GaCgDQj54K","pt":1657540020241,"mc":[{"id":"1.200806927","rc":[{"atl":[[1.15,511.73]],"id":228749}]}]}
{"op":"mcm","clk":"ANDHqQkAqIKaCgDxj54K","pt":1657540020851,"mc":[{"id":"1.200806927","rc":[{"atl":[[1.15,510.52]],"id":228749}]}]}
{"op":"mcm","clk":"AO3HqQkA0YKaCgCEkJ4K","pt":1657540021241,"mc":[{"id":"1.200806927","rc":[{"atl":[[1.15,509.38]],"trd":[[1.15,7775.85]],"tv":38535.1,"id":228749},{"trd":[[7.6,289.75]],"tv":3181.73,"id":2857977}],"tv":41716.83}]}
{"op":"mcm","clk":"APXHqQkA2oKaCgCKkJ4K","pt":1657540021349,"mc":[{"id":"1.200806927","rc":[{"atl":[[1.15,507.23]],"trd":[[1.15,7780.15]],"tv":38539.4,"id":228749}],"tv":41721.13}]}
{"op":"mcm","clk":"AILIqQkA54KaCgCOkJ4K","pt":1657540021441,"mc":[{"id":"1.200806927","rc":[{"atl":[[1.15,529.16]],"id":228749}]}]}
{"op":"mcm","clk":"AILIqQkA8YKaCgCTkJ4K","pt":1657540021517,"mc":[{"id":"1.200806927","rc":[{"atl":[[1.15,518.23]],"trd":[[1.15,7791.08]],"tv":38550.33,"id":228749},{"trd":[[7.6,291.4]],"tv":3183.38,"id":2857977}],"tv":41733.71}]}
{"op":"mcm","clk":"AI7IqQkAg4OaCgCYkJ4K","pt":1657540021649,"mc":[{"id":"1.200806927","rc":[{"atb":[[1.08,1183.93]],"id":228749}]}]}
{"op":"mcm","clk":"ALPIqQkAr4OaCgCvkJ4K","pt":1657540022121,"mc":[{"id":"1.200806927","rc":[{"atl":[[1.15,518.43]],"id":228749}]}]}
{"op":"mcm","clk":"APHIqQkA54OaCgDQkJ4K","pt":1657540022750,"mc":[{"id":"1.200806927","rc":[{"atl":[[1.15,518.23]],"id":228749}]}]}
{"op":"mcm","clk":"AMPJqQkAt4SaCgD1kJ4K","pt":1657540023545,"mc":[{"id":"1.200806927","rc":[{"trd":[[1.14,9219.18]],"ltp":1.14,"tv":39451.95,"id":228749},{"atl":[[8,446.56]],"trd":[[8,1064.83]],"ltp":8,"tv":3311.86,"id":2857977}],"tv":42763.81}]}
{"op":"mcm","clk":"ANTJqQkAzoSaCgD9kJ4K","pt":1657540023760,"mc":[{"id":"1.200806927","rc":[{"atl":[[1.15,507.71]],"trd":[[1.15,7812.12]],"ltp":1.15,"tv":39472.99,"id":228749}],"tv":42784.85}]}
{"op":"mcm","clk":"AOfJqQkA5ISaCgCJkZ4K","pt":1657540023969,"mc":[{"id":"1.200806927","rc":[{"atl":[[1.15,511.45]],"trd":[[1.15,7814.22]],"tv":39475.09,"id":228749}],"tv":42786.95}]}
{"op":"mcm","clk":"APXJqQkA/oSaCgCTkZ4K","pt":1657540024179,"mc":[{"id":"1.200806927","rc":[{"atl":[[1.15,503.27]],"trd":[[1.15,7830.58]],"tv":39491.45,"id":228749}],"tv":42803.31}]}
{"op":"mcm","clk":"ALzKqQkAxYWaCgC6kZ4K","pt":1657540024866,"mc":[{"id":"1.200806927","rc":[{"atb":[[1.13,200.11]],"id":228749}]}]}
{"op":"mcm","clk":"AJ3LqQkAm4aaCgDqkZ4K","pt":1657540025749,"mc":[{"id":"1.200806927","rc":[{"atl":[[1.15,500.56]],"trd":[[1.15,7836]],"tv":39496.87,"id":228749}],"tv":42808.73}]}
{"op":"mcm","clk":"AIbMqQkAooeaCgCpkp4K","pt":1657540026955,"mc":[{"id":"1.200806927","rc":[{"atl":[[1.15,499.5]],"trd":[[1.14,9426.29],[1.15,7837.06]],"ltp":1.14,"tv":39705.04,"id":228749},{"atl":[[8,417.05]],"trd":[[7.6,291.56],[8,1094.34]],"tv":3341.53,"id":2857977}],"tv":43046.57}]}
{"op":"mcm","clk":"AMnMqQkA9YeaCgDhkp4K","pt":1657540027840,"mc":[{"id":"1.200806927","rc":[{"atl":[[1.15,498.8]],"trd":[[1.15,7837.76]],"ltp":1.15,"tv":39705.74,"id":228749},{"trd":[[7.6,291.67]],"ltp":7.6,"tv":3341.64,"id":2857977}],"tv":43047.38}]}
{"op":"mcm","clk":"APDMqQkAqoiaCgD9kp4K","pt":1657540028340,"mc":[{"id":"1.200806927","rc":[{"trd":[[1.14,9691.46]],"ltp":1.14,"tv":39970.91,"id":228749},{"atl":[[8,379.26]],"trd":[[8,1132.13]],"ltp":8,"tv":3379.43,"id":2857977}],"tv":43350.34}]}
{"op":"mcm","clk":"AKLNqQkA7IiaCgChk54K","pt":1657540028978,"mc":[{"id":"1.200806927","rc":[{"atl":[[1.15,497.62]],"trd":[[1.15,7840.12]],"ltp":1.15,"tv":39973.27,"id":228749}],"tv":43352.7}]}
{"op":"mcm","clk":"ALPNqQkA/YiaCgCqk54K","pt":1657540029177,"mc":[{"id":"1.200806927","rc":[{"atl":[[1.15,494.12]],"trd":[[1.15,7843.62]],"tv":39976.77,"id":228749},{"trd":[[7.6,292.2]],"ltp":7.6,"tv":3379.96,"id":2857977}],"tv":43356.73}]}
{"op":"mcm","clk":"ANLNqQkAo4maCgDHk54K","pt":1657540029533,"mc":[{"id":"1.200806927","rc":[{"atl":[[1.15,483.6]],"trd":[[1.15,7864.66]],"tv":39997.81,"id":228749}],"tv":43377.77}]}
{"op":"mcm","clk":"AN/NqQkAsImaCgDRk54K","pt":1657540029658,"mc":[{"id":"1.200806927","rc":[{"atl":[[1.15,477.65]],"trd":[[1.15,7870.61]],"tv":40003.76,"id":228749},{"trd":[[7.6,293.1]],"tv":3380.86,"id":2857977}],"tv":43384.62}]}
{"op":"mcm","clk":"AOXNqQkAzYmaCgDrk54K","pt":1657540029966,"mc":[{"id":"1.200806927","rc":[{"atb":[[1.11,410.32]],"id":228749}]}]}
{"op":"mcm","clk":"AP/NqQkA1omaCgD0k54K","pt":1657540030068,"mc":[{"id":"1.200806927","rc":[{"atl":[[1.15,472.39]],"trd":[[1.15,7881.13]],"tv":40014.28,"id":228749}],"tv":43395.14}]}
{"op":"mcm","clk":"AJPOqQkA74maCgCGlJ4K","pt":1657540030276,"mc":[{"id":"1.200806927","rc":[{"atl":[[1.15,471.25]],"trd":[[1.14,9717.76],[1.15,7882.27]],"tv":40041.72,"id":228749},{"atl":[[8,375.51]],"trd":[[7.6,293.27],[8,1135.88]],"tv":3384.78,"id":2857977}],"tv":43426.5}]}
{"op":"mcm","clk":"APDOqQkAgIuaCgDflJ4K","pt":1657540031547,"mc":[{"id":"1.200806927","rc":[{"atl":[[1.15,468.62]],"trd":[[1.15,7887.53]],"tv":40046.98,"id":228749}],"tv":43431.76}]}
{"op":"mcm","clk":"ALnPqQkA0YuaCgCSlZ4K","pt":1657540032264,"mc":[{"id":"1.200806927","rc":[{"atl":[[1.17,1027.7]],"id":228749}]}]}
{"op":"mcm","clk":"AO7PqQkAjIyaCgC2lZ4K","pt":1657540032832,"mc":[{"id":"1.200806927","rc":[{"atl":[[1.15,467.57]],"trd":[[1.15,7889.63]],"tv":40049.08,"id":228749}],"tv":43433.86}]}
{"op":"mcm","clk":"AIHQqQkAoIyaCgDDlZ4K","pt":1657540033038,"mc":[{"id":"1.200806927","rc":[{"atl":[[1.15,390.58]],"trd":[[1.15,7966.62]],"tv":40126.07,"id":228749},{"trd":[[7.6,304.92]],"tv":3396.43,"id":2857977}],"tv":43522.5}]}
{"op":"mcm","clk":"AJXQqQkAsIyaCgDNlZ4K","pt":1657540033242,"mc":[{"id":"1.200806927","rc":[{"atl":[[1.15,374.8]],"trd":[[1.15,7998.18]],"tv":40157.63,"id":228749}],"tv":43554.06}]}
{"op":"mcm","clk":"ALPQqQkA1YyaCgDdlZ4K","pt":1657540033552,"mc":[{"id":"1.200806927","rc":[{"atl":[[1000,0.34]],"id":228749}]}]}
{"op":"mcm","clk":"ANPQqQkA+YyaCgD3lZ4K","pt":1657540033945,"mc":[{"id":"1.200806927","rc":[{"atl":[[1000,0.13],[1.15,337.99]],"trd":[[1.15,8071.8]],"tv":40231.25,"id":228749}],"tv":43627.68}]}
{"op":"mcm","clk":"AN7QqQkAhY2aCgCBlp4K","pt":1657540034089,"mc":[{"id":"1.200806927","rc":[{"atl":[[1.15,332.73]],"trd":[[1.15,8082.32]],"tv":40241.77,"id":228749}],"tv":43638.2}]}
{"op":"mcm","clk":"APLQqQkAnI2aCgCRlp4K","pt":1657540034251,"mc":[{"id":"1.200806927","rc":[{"atl":[[1.15,322.21]],"trd":[[1.15,8103.36]],"tv":40262.81,"id":228749}],"tv":43659.24}]}
{"op":"mcm","clk":"AP/QqQkAro2aCgCelp4K","pt":1657540034450,"mc":[{"id":"1.200806927","rc":[{"atl":[[1.15,923.32]],"id":228749}]}]}
{"op":"mcm","clk":"AOTSqQkAoI+aCgC8l54K","pt":1657540036867,"mc":[{"id":"1.200806927","rc":[{"trd":[[1.14,9770.35]],"ltp":1.14,"tv":40315.4,"id":228749},{"atl":[[8,368.02]],"trd":[[8,1143.37]],"ltp":8,"tv":3403.92,"id":2857977}],"tv":43719.32}]}
{"op":"mcm","clk":"AITTqQkAyI+aCgDYl54K","pt":1657540037277,"mc":[{"id":"1.200806927","rc":[{"atl":[[1.15,923.02]],"trd":[[1.15,8103.96]],"ltp":1.15,"tv":40316,"id":228749}],"tv":43719.92}]}
{"op":"mcm","clk":"AJfUqQkA05CaCgCzmJ4K","pt":1657540038658,"mc":[{"id":"1.200806927","rc":[{"atl":[[1.15,922.76]],"trd":[[1.15,8104.47]],"tv":40316.51,"id":228749}],"tv":43720.43}]}
{"op":"mcm","clk":"AL7UqQkA+5CaCgDbmJ4K","pt":1657540039047,"mc":[{"id":"1.200806927","rc":[{"atl":[[1.15,919.08]],"trd":[[1.14,11992.56],[1.15,8111.83]],"tv":42546.08,"id":228749},{"atl":[[8,51.36]],"trd":[[8,1460.03]],"tv":3720.58,"id":2857977}],"tv":46266.66}]}
{"op":"mcm","clk":"AN/UqQkAp5GaCgDymJ4K","pt":1657540039471,"mc":[{"id":"1.200806927","rc":[{"atl":[[1.3,129.41]],"id":228749}]}]}
{"op":"mcm","clk":"AL/VqQkAspKaCgDAmZ4K","pt":1657540040584,"mc":[{"id":"1.200806927","rc":[{"atl":[[1.15,917.35]],"trd":[[1.15,8115.29]],"tv":42549.54,"id":228749}],"tv":46270.12}]}
{"op":"mcm","clk":"AMjVqQkAwpKaCgDGmZ4K","pt":1657540040691,"mc":[{"id":"1.200806927","rc":[{"atl":[[1.15,901.57]],"trd":[[1.15,8146.85]],"tv":42581.1,"id":228749}],"tv":46301.68}]}
{"op":"mcm","clk":"AMvVqQkAzJKaCgDKmZ4K","pt":1657540040780,"mc":[{"id":"1.200806927","rc":[{"atl":[[1.15,848.98]],"trd":[[1.15,8252.03]],"tv":42686.28,"id":228749}],"tv":46406.86}]}
{"op":"mcm","clk":"ANjVqQkA35KaCgDTmZ4K","pt":1657540040901,"mc":[{"id":"1.200806927","rc":[{"atl":[[1.56,0.26]],"id":228749}]}]}
{"op":"mcm","clk":"AIfWqQkAoZOaCgD3mZ4K","pt":1657540041572,"mc":[{"id":"1.200806927","rc":[{"atl":[[1.15,827.94]],"trd":[[1.14,12015.11],[1.15,8294.11]],"tv":42750.91,"id":228749},{"atl":[[8,48.15]],"trd":[[8,1463.24]],"tv":3723.79,"id":2857977}],"tv":46474.7}]}
{"op":"mcm","clk":"AK/WqQkA1ZOaCgCcmp4K","pt":1657540042091,"mc":[{"id":"1.200806927","rc":[{"atl":[[1.15,827.24]],"trd":[[1.15,8294.81]],"tv":42751.61,"id":228749},{"trd":[[7.6,305.03]],"ltp":7.6,"tv":3723.9,"id":2857977}],"tv":46475.51}]}
{"op":"mcm","clk":"AOPWqQkAlJSaCgC5mp4K","pt":1657540042666,"mc":[{"id":"1.200806927","rc":[{"atl":[[1.15,805.31]],"id":228749}]}]}
{"op":"mcm","clk":"AMHXqQkA+ZSaCgD6mp4K","pt":1657540043681,"mc":[{"id":"1.200806927","rc":[{"atl":[[1.15,802.68]],"trd":[[1.15,8300.07]],"tv":42756.87,"id":228749}],"tv":46480.77}]}
{"op":"mcm","clk":"AMrXqQkAhpWaCgCCm54K","pt":1657540043787,"mc":[{"id":"1.200806927","rc":[{"atl":[[1.15,776.38]],"trd":[[1.15,8352.67]],"tv":42809.47,"id":228749}],"tv":46533.37}]}
{"op":"mcm","clk":"AIHYqQkA0pWaCgCim54K","pt":1657540044466,"mc":[{"id":"1.200806927","rc":[{"atb":[[1.03,67.69]],"id":228749}]}]}
{"op":"mcm","clk":"ANDYqQkAv5aaCgDym54K","pt":1657540045464,"mc":[{"id":"1.200806927","rc":[{"trd":[[1.14,12016.71]],"ltp":1.14,"tv":42811.07,"id":228749},{"atl":[[8,47.92]],"trd":[[8,1463.47]],"ltp":8,"tv":3724.13,"id":2857977}],"tv":46535.2}]}
{"op":"mcm","clk":"AO7YqQkA7JaaCgCOnJ4K","pt":1657540045871,"mc":[{"id":"1.200806927","rc":[{"atl":[[1.15,775.72]],"trd":[[1.15,8353.33]],"ltp":1.15,"tv":42811.73,"id":228749},{"trd":[[7.6,305.13]],"ltp":7.6,"tv":3724.23,"id":2857977}],"tv":46535.96}]}
{"op":"mcm","clk":"AJjZqQkAo5eaCgCvnJ4K","pt":1657540046408,"mc":[{"id":"1.200806927","rc":[{"trd":[[1.14,12176.47]],"ltp":1.14,"tv":42971.49,"id":228749},{"atl":[[8,25.15]],"trd":[[8,1486.24]],"ltp":8,"tv":3747,"id":2857977}],"tv":46718.49}]}
{"op":"mcm","clk":"ALTZqQkAzZeaCgDJnJ4K","pt":1657540046762,"mc":[{"id":"1.200806927","rc":[{"atl":[[1.15,605.9]],"id":228749}]}]}
{"op":"mcm","clk":"AK3aqQkA3JiaCgCZnZ4K","pt":1657540048075,"mc":[{"id":"1.200806927","rc":[{"atl":[[1.15,603.9]],"trd":[[1.15,8357.33]],"ltp":1.15,"tv":42975.49,"id":228749}],"tv":46722.49}]}
{"op":"mcm","clk":"ALraqQkA85iaCgChnZ4K","pt":1657540048277,"mc":[{"id":"1.200806927","rc":[{"atl":[[1.15,603.79]],"trd":[[1.15,8357.55]],"tv":42975.71,"id":228749}],"tv":46722.71}]}
{"op":"mcm","clk":"AMPaqQkAgJmaCgCqnZ4K","pt":1657540048383,"mc":[{"id":"1.200806927","rc":[{"atl":[[1.15,603.09]],"trd":[[1.15,8358.25]],"tv":42976.41,"id":228749},{"trd":[[7.6,305.24]],"ltp":7.6,"tv":3747.11,"id":2857977}],"tv":46723.52}]}
{"op":"mcm","clk":"ANnaqQkAp5maCgC+nZ4K","pt":1657540048655,"mc":[{"id":"1.200806927","rc":[{"atl":[[1.14,725.13]],"trd":[[1.14,12352.96]],"ltp":1.14,"tv":43152.9,"id":228749},{"atl":[[8,0]],"trd":[[8,1511.39]],"ltp":8,"tv":3772.26,"id":2857977}],"tv":46925.16}]}
{"op":"mcm","clk":"AI3bqQkA5JmaCgDknZ4K","pt":1657540049278,"mc":[{"id":"1.200806927","rc":[{"atl":[[1.14,1626.75]],"id":228749}]}]}
{"op":"mcm","clk":"AKjbqQkA/ZmaCgDxnZ4K","pt":1657540049498,"mc":[{"id":"1.200806927","rc":[{"atl":[[1.14,1626.22]],"id":228749}]}]}
{"op":"mcm","clk":"ALjbqQkAk5qaCgCCnp4K","pt":1657540049699,"mc":[{"id":"1.200806927","rc":[{"atl":[[1.14,1625.69]],"id":228749}]}]}
{"op":"mcm","clk":"AMnbqQkAp5qaCgCLnp4K","pt":1657540049858,"mc":[{"id":"1.200806927","rc":[{"atb":[[1.03,67.93]],"id":228749}]}]}
{"op":"mcm","clk":"AN/bqQkAvZqaCgCfnp4K","pt":1657540050074,"mc":[{"id":"1.200806927","rc":[{"atl":[[1.15,1244.69]],"id":228749}]}]}
{"op":"mcm","clk":"AOzbqQkAz5qaCgCunp4K","pt":1657540050276,"mc":[{"id":"1.200806927","rc":[{"atb":[[1.03,67.69]],"id":228749}]}]}
{"op":"mcm","clk":"AMPcqQkAs5uaCgDhnp4K","pt":1657540051199,"mc":[{"id":"1.200806927","rc":[{"atl":[[1.14,1890.86]],"id":228749}]}]}
{"op":"mcm","clk":"AIrdqQkAiZyaCgCSn54K","pt":1657540051990,"mc":[{"id":"1.200806927","rc":[{"atl":[[1.14,1869.82]],"id":228749}]}]}
{"op":"mcm","clk":"AJHdqQkAk5yaCgCan54K","pt":1657540052092,"mc":[{"id":"1.200806927","rc":[{"atl":[[1.14,1871.03]],"id":228749}]}]}
{"op":"mcm","clk":"AP/dqQkAhJ2aCgDon54K","pt":1657540053387,"mc":[{"id":"1.200806927","rc":[{"atb":[[5,0.86]],"id":2857977}]}]}
{"op":"mcm","clk":"AMveqQkA252aCgCjoJ4K","pt":1657540054289,"mc":[{"id":"1.200806927","rc":[{"atl":[[1.14,1923.62]],"id":228749}]}]}
{"op":"mcm","clk":"APreqQkAo56aCgDEoJ4K","pt":1657540054964,"mc":[{"id":"1.200806927","rc":[{"atl":[[1.14,1913.1]],"id":228749}]}]}
{"op":"mcm","clk":"AKHfqQkAxp6aCgDYoJ4K","pt":1657540055365,"mc":[{"id":"1.200806927","rc":[{"atl":[[1.14,1912.86]],"trd":[[1.14,12353.44]],"tv":43153.38,"id":228749}],"tv":46925.64}]}
{"op":"mcm","clk":"AMLfqQkA7Z6aCgDvoJ4K","pt":1657540055788,"mc":[{"id":"1.200806927","rc":[{"atb":[[1.03,66.85]],"id":228749}]}]}
{"op":"mcm","clk":"AOzgqQkArKCaCgDQoZ4K","pt":1657540057596,"mc":[{"id":"1.200806927","rc":[{"atl":[[1.14,1912.36]],"trd":[[1.14,12354.44]],"tv":43154.38,"id":228749}],"tv":46926.64}]}
{"op":"mcm","clk":"AJjiqQkA6KGaCgC4op4K","pt":1657540059569,"mc":[{"id":"1.200806927","rc":[{"atb":[[1.13,202.11]],"id":228749}]}]}
{"op":"mcm","clk":"AMXiqQkAo6KaCgDYop4K","pt":1657540060094,"mc":[{"id":"1.200806927","rc":[{"atb":[[1.13,66.48]],"trd":[[1.13,371.26]],"ltp":1.13,"tv":43425.64,"id":228749}],"tv":47197.9}]}
{"op":"mcm","clk":"ANXiqQkAuaKaCgDiop4K","pt":1657540060289,"mc":[{"id":"1.200806927","rc":[{"atl":[[1.14,1910.78]],"id":228749}]}]}
{"op":"mcm","clk":"AK7jqQkAsqOaCgCxo54K","pt":1657540061402,"mc":[{"id":"1.200806927","rc":[{"atl":[[1.14,1907.06]],"trd":[[1.14,12358.16]],"ltp":1.14,"tv":43429.36,"id":228749},{"trd":[[8,1511.92]],"tv":3772.79,"id":2857977}],"tv":47202.15}]}
{"op":"mcm","clk":"ALXjqQkAvKOaCgC1o54K","pt":1657540061503,"mc":[{"id":"1.200806927","rc":[{"atl":[[1.14,1904.43]],"id":228749}]}]}
{"op":"mcm","clk":"AOTjqQkAkaSaCgDfo54K","pt":1657540062179,"mc":[{"id":"1.200806927","rc":[{"atl":[[1.14,1903.03]],"trd":[[1.14,12359.56]],"tv":43430.76,"id":228749},{"trd":[[8,1512.12]],"tv":3772.99,"id":2857977}],"tv":47203.75}]}
{"op":"mcm","clk":"APPjqQkAoKSaCgDjo54K","pt":1657540062292,"mc":[{"id":"1.200806927","rc":[{"atl":[[1.14,1898.63]],"id":228749}]}]}
{"op":"mcm","clk":"AJjkqQkA5KSaCgCLpJ4K","pt":1657540062870,"mc":[{"id":"1.200806927","rc":[{"atl":[[1.14,1894.91]],"trd":[[1.14,12363.28]],"tv":43434.48,"id":228749},{"trd":[[8,1512.65]],"tv":3773.52,"id":2857977}],"tv":47208}]}
{"op":"mcm","clk":"AMnkqQkAp6WaCgC4pJ4K","pt":1657540063496,"mc":[{"id":"1.200806927","rc":[{"atl":[[1.14,1889.65]],"id":228749}]}]}
{"op":"mcm","clk":"ANHkqQkAtKWaCgC+pJ4K","pt":1657540063607,"mc":[{"id":"1.200806927","rc":[{"atb":[[1.13,44.55]],"atl":[[1.14,1889.12]],"trd":[[1.13,415.12]],"ltp":1.13,"tv":43478.34,"id":228749}],"tv":47251.86}]}
{"op":"mcm","clk":"APvkqQkA5qWaCgDipJ4K","pt":1657540064074,"mc":[{"id":"1.200806927","rc":[{"atl":[[1.14,1888.42]],"trd":[[1.14,12363.98]],"ltp":1.14,"tv":43479.04,"id":228749},{"trd":[[8,1512.75]],"tv":3773.62,"id":2857977}],"tv":47252.66}]}
{"op":"mcm","clk":"ANHlqQkAyKaaCgCnpZ4K","pt":1657540065174,"mc":[{"id":"1.200806927","rc":[{"atl":[[1.14,1883.16]],"id":228749}]}]}
{"op":"mcm","clk":"AOzlqQkA4qaaCgC/pZ4K","pt":1657540065485,"mc":[{"id":"1.200806927","rc":[{"atb":[[1.13,0]],"atl":[[1.13,817.04]],"trd":[[1.13,544.25]],"ltp":1.13,"tv":43608.17,"id":228749},{"atl":[[8.6,0]],"trd":[[8.6,5.26]],"ltp":8.6,"tv":3778.88,"id":2857977}],"tv":47387.05}]}
{"op":"mcm","clk":"APTlqQkA6aaaCgDDpZ4K","pt":1657540065575,"mc":[{"id":"1.200806927","rc":[{"atl":[[1.13,810.27]],"trd":[[1.13,551.02]],"tv":43614.94,"id":228749},{"trd":[[8.6,6.15]],"tv":3779.77,"id":2857977}],"tv":47394.71}]}
{"op":"mcm","clk":"APvlqQkA8aaaCgDJpZ4K","pt":1657540065688,"mc":[{"id":"1.200806927","rc":[{"atl":[[1.13,808.85]],"trd":[[1.13,553.86]],"tv":43617.78,"id":228749}],"tv":47397.55}]}
{"op":"mcm","clk":"ALzmqQkA1aeaCgCLpp4K","pt":1657540066740,"mc":[{"id":"1.200806927","rc":[{"atl":[[1.13,807.32]],"trd":[[1.13,555.86]],"tv":43619.78,"id":228749}],"tv":47399.55}]}
{"op":"mcm","clk":"AMvmqQkA5aeaCgCZpp4K","pt":1657540066892,"mc":[{"id":"1.200806927","rc":[{"atl":[[1.13,806.79]],"id":228749}]}]}
{"op":"mcm","clk":"ANzmqQkA96eaCgCnpp4K","pt":1657540067106,"mc":[{"id":"1.200806927","rc":[{"atl":[[1.13,884.53]],"id":228749}]}]}
{"op":"mcm","clk":"AOPmqQkA/aeaCgCqpp4K","pt":1657540067207,"mc":[{"id":"1.200806927","rc":[{"atl":[[1000,0.29]],"id":228749}]}]}
{"op":"mcm","clk":"APLmqQkAjqiaCgC0pp4K","pt":1657540067375,"mc":[{"id":"1.200806927","rc":[{"atl":[[1.13,1149.17],[1.14,1881.95]],"id":228749}]}]}
{"op":"mcm","clk":"APfmqQkAl6iaCgC8pp4K","pt":1657540067478,"mc":[{"id":"1.200806927","rc":[{"atl":[[1.13,1147.86],[1.14,1934.54]],"trd":[[1.13,557.17]],"tv":43621.09,"id":228749},{"trd":[[8.6,6.32]],"tv":3779.94,"id":2857977}],"tv":47401.03}]}
{"op":"mcm","clk":"APzmqQkApqiaCgDApp4K","pt":1657540067576,"mc":[{"id":"1.200806927","rc":[{"atl":[[1.13,1145.23]],"id":228749}]}]}
{"op":"mcm","clk":"AILnqQkAsKiaCgDEpp4K","pt":1657540067680,"mc":[{"id":"1.200806927","rc":[{"atl":[[1000,0.13],[1.13,1142.94]],"trd":[[1.13,559.46]],"tv":43623.38,"id":228749},{"trd":[[8.6,6.62]],"tv":3780.24,"id":2857977}],"tv":47403.62}]}
{"op":"mcm","clk":"ALHnqQkA96iaCgDnpp4K","pt":1657540068411,"mc":[{"id":"1.200806927","rc":[{"atl":[[1.13,1142.41]],"id":228749}]}]}
{"op":"mcm","clk":"AKfoqQkAmKqaCgDPp54K","pt":1657540070249,"mc":[{"id":"1.200806927","rc":[{"atl":[[1.15,1204.2]],"id":228749}]}]}
{"op":"mcm","clk":"AMfoqQkA0KqaCgDtp54K","pt":1657540070734,"mc":[{"id":"1.200806927","rc":[{"atl":[[1.13,1141.6],[1.14,1669.37]],"trd":[[1.13,560.27]],"tv":43624.19,"id":228749},{"trd":[[8.6,6.73]],"tv":3780.35,"id":2857977}],"tv":47404.54}]}
{"op":"mcm","clk":"AM/oqQkA46qaCgD0p54K","pt":1657540070884,"mc":[{"id":"1.200806927","rc":[{"atl":[[1.6,5.6]],"id":228749}]}]}
{"op":"mcm","clk":"AIrpqQkAmauaCgCtqJ4K","pt":1657540071706,"mc":[{"id":"1.200806927","rc":[{"atl":[[1.13,1137.3]],"trd":[[1.13,568.87]],"tv":43632.79,"id":228749}],"tv":47413.14}]}
{"op":"mcm","clk":"AJHpqQkApauaCgC0qJ4K","pt":1657540071813,"mc":[{"id":"1.200806927","rc":[{"atl":[[1.14,767.75]],"id":228749}]}]}
{"op":"mcm","clk":"AKvpqQkA0quaCgDUqJ4K","pt":1657540072302,"mc":[{"id":"1.200806927","rc":[{"atl":[[1.13,1133.27]],"trd":[[1.13,572.9]],"tv":43636.82,"id":228749},{"trd":[[8.6,7.26]],"tv":3780.88,"id":2857977}],"tv":47417.7}]}
{"op":"mcm","clk":"AM3pqQkAgayaCgDvqJ4K","pt":1657540072810,"mc":[{"id":"1.200806927","rc":[{"atl":[[1.13,1133.44]],"id":228749}]}]}
{"op":"mcm","clk":"APfpqQkAwKyaCgCNqZ4K","pt":1657540073433,"mc":[{"id":"1.200806927","rc":[{"atl":[[1.13,1126.89]],"trd":[[1.13,579.45]],"tv":43643.37,"id":228749},{"trd":[[8.6,8.12]],"tv":3781.74,"id":2857977}],"tv":47425.11}]}
{"op":"mcm","clk":"AP3pqQkAyqyaCgCSqZ4K","pt":1657540073485,"mc":[{"id":"1.200806927","rc":[{"atl":[[1.13,1126.72]],"id":228749}]}]}
{"op":"mcm","clk":"AIXqqQkA16yaCgCVqZ4K","pt":1657540073586,"mc":[{"id":"1.200806927","rc":[{"atb":[[1.09,0]],"atl":[[1.14,715.16]],"id":228749}]}]}
{"op":"mcm","clk":"AL3qqQkAqK2aCgC1qZ4K","pt":1657540074389,"mc":[{"id":"1.200806927","rc":[{"atl":[[1.13,1013.24]],"trd":[[1.13,806.41]],"tv":43870.33,"id":228749}],"tv":47652.07}]}
{"op":"mcm","clk":"ANHqqQkAwK2aCgDBqZ4K","pt":1657540074593,"mc":[{"id":"1.200806927","rc":[{"atl":[[1.5,185.35]],"id":228749}]}]}
{"op":"mcm","clk":"APvqqQkAgK6aCgDdqZ4K","pt":1657540075118,"mc":[{"id":"1.200806927","rc":[{"atl":[[1.13,1012.43]],"trd":[[1.13,807.22]],"tv":43871.14,"id":228749},{"trd":[[8.6,8.23]],"tv":3781.85,"id":2857977}],"tv":47652.99}]}
{"op":"mcm","clk":"AJjrqQkAna6aCgDyqZ4K","pt":1657540075424,"mc":[{"id":"1.200806927","rc":[{"atb":[[1.11,412.32]],"atl":[[1.13,1004.44]],"trd":[[1.13,815.21]],"tv":43879.13,"id":228749},{"trd":[[8.6,9.28]],"tv":3782.9,"id":2857977}],"tv":47662.03}]}
{"op":"mcm","clk":"AITsqQkArq+aCgDKqp4K","pt":1657540076889,"mc":[{"id":"1.200806927","rc":[{"atl":[[1.13,999.18]],"id":228749}]}]}
{"op":"mcm","clk":"ALPsqQkA5a+aCgDmqp4K","pt":1657540077523,"mc":[{"id":"1.200806927","rc":[{"atl":[[1.13,995.97]],"id":228749}]}]}
{"op":"mcm","clk":"AMjsqQkAibCaCgD+qp4K","pt":1657540077891,"mc":[{"id":"1.200806927","rc":[{"atb":[[1.12,202.1]],"trd":[[1.12,46.22]],"ltp":1.12,"tv":43880.19,"id":228749}],"tv":47663.09}]}
{"op":"mcm","clk":"AOTsqQkArbCaCgCSq54K","pt":1657540078311,"mc":[{"id":"1.200806927","rc":[{"atl":[[1.13,985.45]],"id":228749}]}]}
{"op":"mcm","clk":"AIDtqQkA0LCaCgCjq54K","pt":1657540078715,"mc":[{"id":"1.200806927","rc":[{"atl":[[1.13,785.45]],"trd":[[1.13,1215.21]],"ltp":1.13,"tv":44280.19,"id":228749}],"tv":48063.09}]}
{"op":"mcm","clk":"AJvtqQkA9bCaCgC+q54K","pt":1657540079095,"mc":[{"id":"1.200806927","rc":[{"atl":[[1.13,781.42]],"trd":[[1.13,1219.24]],"tv":44284.22,"id":228749},{"trd":[[8.6,9.81]],"tv":3783.43,"id":2857977}],"tv":48067.65}]}
{"op":"mcm","clk":"AK/tqQkAkbGaCgDKq54K","pt":1657540079409,"mc":[{"id":"1.200806927","rc":[{"atl":[[1.13,776.16]],"id":228749}]}]}
{"op":"mcm","clk":"AO/tqQkA37GaCgDtq54K","pt":1657540080201,"mc":[{"id":"1.200806927","rc":[{"atl":[[1.13,776.03]],"trd":[[1.13,1219.5]],"tv":44284.48,"id":228749}],"tv":48067.91}]}
{"op":"mcm","clk":"AP7tqQkA67GaCgDxq54K","pt":1657540080307,"mc":[{"id":"1.200806927","rc":[{"atl":[[1.13,770.77]],"id":228749}]}]}
{"op":"mcm","clk":"AKHuqQkAmrKaCgCLrJ4K","pt":1657540080728,"mc":[{"id":"1.200806927","rc":[{"atl":[[1.13,769.87]],"id":228749}]}]}
{"op":"mcm","clk":"AK3uqQkAqLKaCgCPrJ4K","pt":1657540080853,"mc":[{"id":"1.200806927","rc":[{"atl":[[1.13,769.11]],"trd":[[1.13,1220.26]],"tv":44285.24,"id":228749},{"trd":[[8.6,9.91]],"tv":3783.53,"id":2857977}],"tv":48068.77}]}
{"op":"mcm","clk":"AJPvqQkAq7OaCgDerJ4K","pt":1657540082213,"mc":[{"id":"1.200806927","rc":[{"atl":[[1.13,768.06]],"id":228749}]}]}
{"op":"mcm","clk":"ALDvqQkA4LOaCgD6rJ4K","pt":1657540082729,"mc":[{"id":"1.200806927","rc":[{"atl":[[1.13,757.54]],"id":228749}]}]}
{"op":"mcm","clk":"AMHvqQkA87OaCgCKrZ4K","pt":1657540082911,"mc":[{"id":"1.200806927","rc":[{"atl":[[1.13,749.55],[1.14,52.59]],"trd":[[1.13,1228.25]],"tv":44293.23,"id":228749},{"trd":[[8.6,10.96]],"tv":3784.58,"id":2857977}],"tv":48077.81}]}
{"op":"mcm","clk":"AMvvqQkA+rOaCgCPrZ4K","pt":1657540082996,"mc":[{"id":"1.200806927","rc":[{"atl":[[1.13,739.03]],"id":228749}]}]}
{"op":"mcm","clk":"AODvqQkAiLSaCgCcrZ4K","pt":1657540083204,"mc":[{"id":"1.200806927","rc":[{"atb":[[1.11,202]],"atl":[[1.16,601.11]],"id":228749}]}]}
{"op":"mcm","clk":"AK/wqQkA1LSaCgDUrZ4K","pt":1657540084095,"mc":[{"id":"1.200806927","rc":[{"atl":[[1.13,738.22]],"trd":[[1.13,1229.06]],"tv":44294.04,"id":228749},{"trd":[[8.6,11.06]],"tv":3784.68,"id":2857977}],"tv":48078.72}]}
{"op":"mcm","clk":"ALjwqQkA27SaCgDbrZ4K","pt":1657540084205,"mc":[{"id":"1.200806927","rc":[{"atb":[[1.12,149.51]],"trd":[[1.12,151.4]],"ltp":1.12,"tv":44399.22,"id":228749}],"tv":48183.9}]}
{"op":"mcm","clk":"APjwqQkAn7WaCgCGrp4K","pt":1657540084936,"mc":[{"id":"1.200806927","rc":[{"atb":[[1.12,136.36]],"atl":[[1.13,736.06]],"trd":[[1.13,1230.7],[1.12,177.7]],"ltp":1.13,"tv":44427.16,"id":228749},{"trd":[[8.6,11.28]],"tv":3784.9,"id":2857977}],"tv":48212.06}]}
{"op":"mcm","clk":"AMbxqQkAkLaaCgCwrp4K","pt":1657540085890,"mc":[{"id":"1.200806927","rc":[{"atl":[[1.13,735.53]],"id":228749}]}]}
{"op":"mcm","clk":"ANDxqQkAnraaCgC2rp4K","pt":1657540086003,"mc":[{"id":"1.200806927","rc":[{"atl":[[1.13,727.92]],"trd":[[1.13,1238.31]],"tv":44434.77,"id":228749},{"trd":[[8.6,12.28]],"tv":3785.9,"id":2857977}],"tv":48220.67}]}
{"op":"mcm","clk":"AOPxqQkAr7aaCgDBrp4K","pt":1657540086200,"mc":[{"id":"1.200806927","rc":[{"atl":[[1.13,722.45]],"trd":[[1.13,1243.78]],"tv":44440.24,"id":228749},{"trd":[[8.6,13]],"tv":3786.62,"id":2857977}],"tv":48226.86}]}
{"op":"mcm","clk":"APzxqQkAzbaaCgDUrp4K","pt":1657540086543,"mc":[{"id":"1.200806927","rc":[{"atl":[[1.13,721.92]],"id":228749}]}]}
{"op":"mcm","clk":"AKfyqQkAjbeaCgD5rp4K","pt":1657540087144,"mc":[{"id":"1.200806927","rc":[{"atb":[[1.12,83.77]],"trd":[[1.12,282.88]],"ltp":1.12,"tv":44545.42,"id":228749}],"tv":48332.04}]}
{"op":"mcm","clk":"AO3yqQkA6LeaCgCwr54K","pt":1657540088030,"mc":[{"id":"1.200806927","rc":[{"atl":[[1000,0.24],[1.13,721.39]],"id":228749}]}]}
{"op":"mcm","clk":"AIXzqQkAhbiaCgDCr54K","pt":1657540088331,"mc":[{"id":"1.200806927","rc":[{"atb":[[1.1,426],[1.12,0]],"atl":[[1.12,1553.14]],"trd":[[1.12,451.28]],"tv":44713.82,"id":228749},{"atl":[[9,0]],"trd":[[9,1.44]],"ltp":9,"tv":3786.73,"id":2857977}],"tv":48500.55}]}
{"op":"mcm","clk":"AIvzqQkAjriaCgDEr54K","pt":1657540088390,"mc":[{"id":"1.200806927","rc":[{"atl":[[1000,0.13],[1.14,0]],"id":228749}]}]}
{"op":"mcm","clk":"AKTzqQkArLiaCgDXr54K","pt":1657540088718,"mc":[{"id":"1.200806927","rc":[{"atb":[[1.09,2]],"id":228749}]}]}
{"op":"mcm","clk":"AOrzqQkA/riaCgCKsJ4K","pt":1657540089516,"mc":[{"id":"1.200806927","rc":[{"atl":[[1.13,643.72]],"id":228749}]}]}
{"op":"mcm","clk":"AJH0qQkApbmaCgCfsJ4K","pt":1657540089928,"mc":[{"id":"1.200806927","rc":[{"atb":[[1.06,0]],"id":228749}]}]}
{"op":"mcm","clk":"ANH0qQkA/LmaCgDQsJ4K","pt":1657540090705,"mc":[{"id":"1.200806927","rc":[{"atl":[[1.12,1552.29]],"trd":[[1.12,452.98]],"tv":44715.52,"id":228749}],"tv":48502.25}]}
{"op":"mcm","clk":"APn0qQkAobqaCgDrsJ4K","pt":1657540091129,"mc":[{"id":"1.200806927","rc":[{"atl":[[1.12,1550.87]],"trd":[[1.12,454.4]],"tv":44716.94,"id":228749},{"trd":[[9.2,0.17]],"ltp":9.2,"tv":3786.9,"id":2857977}],"tv":48503.84}]}
{"op":"mcm","clk":"AI/1qQkAwLqaCgD9sJ4K","pt":1657540091438,"mc":[{"id":"1.200806927","rc":[{"atl":[[1.12,1548.24]],"trd":[[1.12,459.66]],"tv":44722.2,"id":228749}],"tv":48509.1}]}
{"op":"mcm","clk":"AKn1qQkA37qaCgCOsZ4K","pt":1657540091708,"mc":[{"id":"1.200806927","rc":[{"atl":[[1.12,1544.7]],"trd":[[1.12,463.2]],"tv":44725.74,"id":228749},{"trd":[[9.2,0.6]],"tv":3787.33,"id":2857977}],"tv":48513.07}]}
{"op":"mcm","clk":"ALL1qQkA6LqaCgCSsZ4K","pt":1657540091801,"mc":[{"id":"1.200806927","rc":[{"atb":[[1.11,2]],"id":228749}]}]}
{"op":"mcm","clk":"AOv1qQkAqbuaCgC6sZ4K","pt":1657540092524,"mc":[{"id":"1.200806927","rc":[{"atb":[[1.08,845.67]],"id":228749}]}]}
{"op":"mcm","clk":"AKT2qQkA6ruaCgDusZ4K","pt":1657540093209,"mc":[{"id":"1.200806927","rc":[{"atl":[[1.12,1523.66]],"trd":[[1.12,505.28]],"tv":44767.82,"id":228749}],"tv":48555.15}]}
{"op":"mcm","clk":"ALn2qQkAhryaCgCGsp4K","pt":1657540093516,"mc":[{"id":"1.200806927","rc":[{"atl":[[1.12,1523.78]],"id":228749}]}]}
{"op":"mcm","clk":"AO72qQkAxryaCgCrsp4K","pt":1657540094197,"mc":[{"id":"1.200806927","rc":[{"atl":[[1.12,1523.66]],"id":228749}]}]}
{"op":"mcm","clk":"AKr3qQkAhb2aCgDcsp4K","pt":1657540094943,"mc":[{"id":"1.200806927","rc":[{"atl":[[1.12,1518.4]],"trd":[[1.12,515.8]],"tv":44778.34,"id":228749}],"tv":48565.67}]}
{"op":"mcm","clk":"ALX3qQkAlb2aCgDhsp4K","pt":1657540095030,"mc":[{"id":"1.200806927","rc":[{"atl":[[1.16,636.45],[1.12,1516.76]],"trd":[[1.12,517.44]],"tv":44779.98,"id":228749},{"trd":[[9.2,0.8]],"tv":3787.53,"id":2857977}],"tv":48567.51}]}
{"op":"mcm","clk":"ANL3qQkAw72aCgD8sp4K","pt":1657540095461,"mc":[{"id":"1.200806927","rc":[{"atl":[[1.12,1516.66]],"trd":[[1.12,517.64]],"tv":44780.18,"id":228749}],"tv":48567.71}]}
{"op":"mcm","clk":"AL74qQkA1r6aCgDHs54K","pt":1657540096858,"mc":[{"id":"1.200806927","rc":[{"atl":[[1.12,1643.93]],"trd":[[1.12,526.06]],"tv":44788.6,"id":228749}],"tv":48576.13}]}
{"op":"mcm","clk":"APP4qQkAor+aCgDzs54K","pt":1657540097538,"mc":[{"id":"1.200806927","rc":[{"atl":[[1.12,1639.72]],"trd":[[1.12,534.48]],"tv":44797.02,"id":228749}],"tv":48584.55}]}
{"op":"mcm","clk":"APn4qQkAqb+aCgD3s54K","pt":1657540097628,"mc":[{"id":"1.200806927","rc":[{"atl":[[1.56,0]],"id":228749}]}]}
{"op":"mcm","clk":"AJP5qQkAwb+aCgCLtJ4K","pt":1657540097914,"mc":[{"id":"1.200806927","rc":[{"atl":[[1.12,1637.62]],"trd":[[1.12,538.68]],"tv":44801.22,"id":228749}],"tv":48588.75}]}
{"op":"mcm","clk":"AMb5qQkAicCaCgC4tJ4K","pt":1657540098642,"mc":[{"id":"1.200806927","rc":[{"atl":[[1.12,1633.41]],"trd":[[1.12,547.1]],"tv":44809.64,"id":228749}],"tv":48597.17}]}
{"op":"mcm","clk":"ALf6qQkAnsGaCgCItZ4K","pt":1657540100117,"mc":[{"id":"1.200806927","rc":[{"atl":[[1.12,1616.16]],"trd":[[1.12,564.35]],"tv":44826.89,"id":228749},{"trd":[[9.2,2.9]],"tv":3789.63,"id":2857977}],"tv":48616.52}]}
{"op":"mcm","clk":"AL76qQkAqsGaCgCLtZ4K","pt":1657540100209,"mc":[{"id":"1.200806927","rc":[{"atl":[[1.12,1611.74]],"trd":[[1.12,573.19]],"tv":44835.73,"id":228749}],"tv":48625.36}]}
{"op":"mcm","clk":"APL6qQkA9MGaCgCytZ4K","pt":1657540101044,"mc":[{"id":"1.200806927","rc":[{"atl":[[1.12,1480.26]],"id":228749}]}]}
{"op":"mcm","clk":"AKX7qQkAscKaCgDetZ4K","pt":1657540101726,"mc":[{"id":"1.200806927","rc":[{"atl":[[1.12,1478.49]],"trd":[[1.12,574.96]],"tv":44837.5,"id":228749},{"trd":[[9.2,3.12]],"tv":3789.85,"id":2857977}],"tv":48627.35}]}
{"op":"mcm","clk":"AMb7qQkA4sKaCgDytZ4K","pt":1657540102230,"mc":[{"id":"1.200806927","rc":[{"atb":[[1.11,2.54]],"id":228749}]}]}
{"op":"mcm","clk":"AIf8qQkAp8OaCgCVtp4K","pt":1657540102927,"mc":[{"id":"1.200806927","rc":[{"atl":[[1.12,1476.91]],"trd":[[1.12,578.12]],"tv":44840.66,"id":228749}],"tv":48630.51}]}
{"op":"mcm","clk":"ANP8qQkA/cOaCgDAtp4K","pt":1657540103723,"mc":[{"id":"1.200806927","rc":[{"atl":[[1.12,1468.29]],"trd":[[1.12,586.74]],"tv":44849.28,"id":228749},{"trd":[[9.2,4.17]],"tv":3790.9,"id":2857977}],"tv":48640.18}]}
{"op":"mcm","clk":"AID9qQkAosSaCgDftp4K","pt":1657540104249,"mc":[{"id":"1.200806927","rc":[{"atl":[[1.12,1463.03]],"trd":[[1.12,597.26]],"tv":44859.8,"id":228749}],"tv":48650.7}]}
{"op":"mcm","clk":"APL9qQkAiMWaCgCqt54K","pt":1657540105443,"mc":[{"id":"1.200806927","rc":[{"atl":[[1.12,1454.41]],"trd":[[1.12,605.88]],"tv":44868.42,"id":228749},{"trd":[[9.2,5.22]],"tv":3791.95,"id":2857977}],"tv":48660.37}]}
{"op":"mcm","clk":"APn9qQkAk8WaCgCyt54K","pt":1657540105548,"mc":[{"id":"1.200806927","rc":[{"atl":[[1.12,1453.63]],"trd":[[1.12,607.44]],"tv":44869.98,"id":228749}],"tv":48661.93}]}
{"op":"mcm","clk":"ALT+qQkA1MWaCgDkt54K","pt":1657540106225,"mc":[{"id":"1.200806927","rc":[{"atl":[[1.12,1452.81]],"trd":[[1.12,608.26]],"tv":44870.8,"id":228749},{"trd":[[9.2,5.32]],"tv":3792.05,"id":2857977}],"tv":48662.85}]}
{"op":"mcm","clk":"AMf+qQkA5cWaCgD8t54K","pt":1657540106452,"mc":[{"id":"1.200806927","rc":[{"atb":[[1.11,0]],"trd":[[1.11,6.84]],"ltp":1.11,"tv":44877.64,"id":228749},{"atl":[[10,0.22]],"trd":[[10,0.2]],"ltp":10,"tv":3792.25,"id":2857977}],"tv":48669.89}]}
{"op":"mcm","clk":"AOj+qQkAjMaaCgCRuJ4K","pt":1657540106812,"mc":[{"id":"1.200806927","rc":[{"atl":[[1.12,1447.02]],"trd":[[1.12,619.84]],"ltp":1.12,"tv":44889.22,"id":228749}],"tv":48681.47}]}
{"op":"mcm","clk":"AJL/qQkAtcaaCgCwuJ4K","pt":1657540107334,"mc":[{"id":"1.200806927","rc":[{"atl":[[1.12,1449.5]],"id":228749}]}]}
{"op":"mcm","clk":"AOP/qQkAj8eaCgDmuJ4K","pt":1657540108427,"mc":[{"id":"1.200806927","rc":[{"atl":[[1.12,1444.11]],"trd":[[1.12,629.74]],"tv":44899.12,"id":228749},{"trd":[[9.2,5.42]],"ltp":9.2,"tv":3792.35,"id":2857977}],"tv":48691.47}]}
{"op":"mcm","clk":"AOn/qQkAmseaCgDpuJ4K","pt":1657540108549,"mc":[{"id":"1.200806927","rc":[{"atl":[[10.5,52.59]],"id":2857977}]}]}
{"op":"mcm","clk":"APj/qQkAr8eaCgD4uJ4K","pt":1657540108736,"mc":[{"id":"1.200806927","rc":[{"atl":[[1.12,1435.43]],"trd":[[1.12,647.1]],"tv":44916.48,"id":228749}],"tv":48708.83}]}
{"op":"mcm","clk":"AJGAqgkAy8eaCgCLuZ4K","pt":1657540109057,"mc":[{"id":"1.200806927","rc":[{"atl":[[1.12,1430.17]],"trd":[[1.12,657.62]],"tv":44927,"id":228749}],"tv":48719.35}]}
{"op":"mcm","clk":"AN+AqgkAq8iaCgDLuZ4K","pt":1657540110097,"mc":[{"id":"1.200806927","rc":[{"atl":[[1.12,1429.74]],"trd":[[1.12,658.48]],"tv":44927.86,"id":228749}],"tv":48720.21}]}
{"op":"mcm","clk":"ANaBqgkAq8maCgCLup4K","pt":1657540111511,"mc":[{"id":"1.200806927","rc":[{"atl":[[1.12,1424.48]],"trd":[[1.12,669]],"tv":44938.38,"id":228749}],"tv":48730.73}]}
{"op":"mcm","clk":"AO+BqgkAxsmaCgCbup4K","pt":1657540111831,"mc":[{"id":"1.200806927","rc":[{"atb":[[1.09,7.26]],"atl":[[1.12,1420.8]],"trd":[[1.12,676.36]],"tv":44945.74,"id":228749}],"tv":48738.09}]}
{"op":"mcm","clk":"APuBqgkA1smaCgCoup4K","pt":1657540112036,"mc":[{"id":"1.200806927","rc":[{"atl":[[1.12,1416.5]],"trd":[[1.12,684.96]],"tv":44954.34,"id":228749}],"tv":48746.69}]}
{"op":"mcm","clk":"AIiCqgkA7MmaCgCwup4K","pt":1657540112201,"mc":[{"id":"1.200806927","rc":[{"atl":[[1.12,1413.87]],"trd":[[1.12,690.22]],"tv":44959.6,"id":228749}],"tv":48751.95}]}
{"op":"mcm","clk":"AKiCqgkAosqaCgDHup4K","pt":1657540112822,"mc":[{"id":"1.200806927","rc":[{"atl":[[1.12,1413.34]],"trd":[[1.12,691.28]],"tv":44960.66,"id":228749}],"tv":48753.01}]}
{"op":"mcm","clk":"AK+CqgkAp8qaCgDLup4K","pt":1657540112910,"mc":[{"id":"1.200806927","rc":[{"atl":[[1.12,1412.46]],"trd":[[1.12,692.16]],"tv":44961.54,"id":228749},{"trd":[[9.2,5.53]],"tv":3792.46,"id":2857977}],"tv":48754}]}
{"op":"mcm","clk":"APGDqgkAhcyaCgDFxJ4K","pt":1657540115427,"mc":[{"id":"1.200806927","rc":[{"atl":[[1.12,1411.04]],"trd":[[1.12,693.58]],"tv":44962.96,"id":228749},{"trd":[[9.2,5.7]],"tv":3792.63,"id":2857977}],"tv":48755.59}]}
{"op":"mcm","clk":"APSEqgkAzc2aCgCD7Z4K","pt":1657540117334,"mc":[{"id":"1.200806927","rc":[{"atl":[[1.12,1410.51]],"trd":[[1.12,694.64]],"tv":44964.02,"id":228749}],"tv":48756.65}]}
{"op":"mcm","clk":"AImFqgkA8s2aCgCa7Z4K","pt":1657540117655,"mc":[{"id":"1.200806927","rc":[{"atl":[[1.12,1408.51]],"trd":[[1.12,698.64]],"tv":44968.02,"id":228749}],"tv":48760.65}]}
{"op":"mcm","clk":"APaFqgkAgc+aCgD37Z4K","pt":1657540119048,"mc":[{"id":"1.200806927","rc":[{"atl":[[1.12,1404.45]],"trd":[[1.12,702.7]],"tv":44972.08,"id":228749},{"trd":[[9.2,6.2]],"tv":3793.13,"id":2857977}],"tv":48765.21}]}
{"op":"mcm","clk":"AImGqgkAoc+aCgCC7p4K","pt":1657540119313,"mc":[{"id":"1.200806927","rc":[{"atl":[[1.12,1401.82]],"trd":[[1.12,707.96]],"tv":44977.34,"id":228749}],"tv":48770.47}]}
{"op":"mcm","clk":"AJCGqgkAq8+aCgCF7p4K","pt":1657540119431,"mc":[{"id":"1.200806927","rc":[{"atl":[[1.12,1381.82]],"trd":[[1.12,747.96]],"tv":45017.34,"id":228749}],"tv":48810.47}]}
{"op":"mcm","clk":"AJqGqgkAtc+aCgCK7p4K","pt":1657540119531,"mc":[{"id":"1.200806927","rc":[{"atl":[[1.12,1379.34]],"id":228749}]}]}
{"op":"mcm","clk":"AO2GqgkAo9CaCgC67p4K","pt":1657540120547,"mc":[{"id":"1.200806927","rc":[{"atl":[[1.12,1378.46]],"trd":[[1.12,748.84]],"tv":45018.22,"id":228749},{"trd":[[9.2,6.3]],"tv":3793.23,"id":2857977}],"tv":48811.45}]}
{"op":"mcm","clk":"AP2GqgkAudCaCgDG7p4K","pt":1657540120727,"mc":[{"id":"1.200806927","rc":[{"atl":[[1.12,1374.92]],"trd":[[1.12,752.38]],"tv":45021.76,"id":228749},{"trd":[[9.2,6.73]],"tv":3793.66,"id":2857977}],"tv":48815.42}]}
{"op":"mcm","clk":"AMeHqgkAo9GaCgCB754K","pt":1657540121724,"mc":[{"id":"1.200806927","rc":[{"atl":[[1.12,2374.92]],"id":228749}]}]}
{"op":"mcm","clk":"AN+HqgkAvNGaCgCN754K","pt":1657540122044,"mc":[{"id":"1.200806927","rc":[{"trd":[[1.11,8.42]],"ltp":1.11,"tv":45023.34,"id":228749},{"atl":[[10,0.04]],"trd":[[10,0.37]],"ltp":10,"tv":3793.83,"id":2857977}],"tv":48817.17}]}
{"op":"mcm","clk":"AOmHqgkAztGaCgCW754K","pt":1657540122250,"mc":[{"id":"1.200806927","rc":[{"atl":[[1.12,2372.81]],"trd":[[1.12,754.49]],"ltp":1.12,"tv":45025.45,"id":228749},{"trd":[[9.2,6.99]],"ltp":9.2,"tv":3794.09,"id":2857977}],"tv":48819.54}]}
{"op":"mcm","clk":"AI+IqgkA/tGaCgCw754K","pt":1657540122723,"mc":[{"id":"1.200806927","rc":[{"atl":[[1.12,2367.55]],"trd":[[1.12,765.01]],"tv":45035.97,"id":228749}],"tv":48830.06}]}
{"op":"mcm","clk":"AJmIqgkAidKaCgC1754K","pt":1657540122819,"mc":[{"id":"1.200806927","rc":[{"atl":[[1.12,2366.73]],"trd":[[1.12,765.83]],"tv":45036.79,"id":228749},{"trd":[[9.2,7.09]],"tv":3794.19,"id":2857977}],"tv":48830.98}]}
{"op":"mcm","clk":"ALuIqgkAvdKaCgDS754K","pt":1657540123340,"mc":[{"id":"1.200806927","rc":[{"atl":[[1.12,2365.15]],"trd":[[1.12,768.99]],"tv":45039.95,"id":228749}],"tv":48834.14}]}
{"op":"mcm","clk":"ANuIqgkA4tKaCgDj754K","pt":1657540123742,"mc":[{"id":"1.200806927","rc":[{"atl":[[1.12,2338.85]],"trd":[[1.12,821.59]],"tv":45092.55,"id":228749}],"tv":48886.74}]}
{"op":"mcm","clk":"AMuKqgkAh9WaCgD/8J4K","pt":1657540126844,"mc":[{"id":"1.200806927","rc":[{"atl":[[1.12,2338.32]],"trd":[[1.12,822.65]],"tv":45093.61,"id":228749}],"tv":48887.8}]}
{"op":"mcm","clk":"AOGKqgkAtdWaCgCW8Z4K","pt":1657540127252,"mc":[{"id":"1.200806927","rc":[{"atl":[[1.12,2335.69]],"trd":[[1.12,827.91]],"tv":45098.87,"id":228749}],"tv":48893.06}]}
{"op":"mcm","clk":"AOmKqgkAwNWaCgCZ8Z4K","pt":1657540127329,"mc":[{"id":"1.200806927","rc":[{"atl":[[1.12,2334.81]],"trd":[[1.12,828.79]],"tv":45099.75,"id":228749},{"trd":[[9.2,7.2]],"tv":3794.3,"id":2857977}],"tv":48894.05}]}
{"op":"mcm","clk":"APyKqgkA3tWaCgCp8Z4K","pt":1657540127625,"mc":[{"id":"1.200806927","rc":[{"atl":[[1.12,2330.08]],"trd":[[1.12,838.25]],"tv":45109.21,"id":228749}],"tv":48903.51}]}
{"op":"mcm","clk":"ALSLqgkAo9aaCgDJ8Z4K","pt":1657540128360,"mc":[{"id":"1.200806927","rc":[{"atl":[[1.12,2307.15]],"trd":[[1.12,875.9]],"tv":45146.86,"id":228749},{"trd":[[9.2,8.2]],"tv":3795.3,"id":2857977}],"tv":48942.16}]}
{"op":"mcm","clk":"AMaLqgkAudaaCgDP8Z4K","pt":1657540128539,"mc":[{"id":"1.200806927","rc":[{"atl":[[1.12,2301.89]],"trd":[[1.12,886.42]],"tv":45157.38,"id":228749}],"tv":48952.68}]}
{"op":"mcm","clk":"AMyLqgkAxNaaCgDV8Z4K","pt":1657540128627,"mc":[{"id":"1.200806927","rc":[{"atl":[[1.12,2300.12]],"trd":[[1.12,888.19]],"tv":45159.15,"id":228749},{"trd":[[9.2,8.41]],"tv":3795.51,"id":2857977}],"tv":48954.66}]}
{"op":"mcm","clk":"AOOLqgkA5taaCgDh8Z4K","pt":1657540128938,"mc":[{"id":"1.200806927","rc":[{"atl":[[1.12,571.2]],"trd":[[1.12,2617.11]],"tv":46888.07,"id":228749},{"trd":[[9.2,218.89]],"tv":4005.99,"id":2857977}],"tv":50894.06}]}
{"op":"mcm","clk":"AIKMqgkAi9eaCgD08Z4K","pt":1657540129357,"mc":[{"id":"1.200806927","rc":[{"atl":[[1.12,569.43]],"trd":[[1.12,2618.88]],"tv":46889.84,"id":228749},{"trd":[[9.2,219.11]],"tv":4006.21,"id":2857977}],"tv":50896.05}]}
{"op":"mcm","clk":"AKyMqgkAxdeaCgCT8p4K","pt":1657540129936,"mc":[{"id":"1.200806927","rc":[{"atl":[[1.12,568.55]],"trd":[[1.12,2619.76]],"tv":46890.72,"id":228749},{"trd":[[9.2,219.21]],"tv":4006.31,"id":2857977}],"tv":50897.03}]}
{"op":"mcm","clk":"ALmMqgkA3NeaCgCY8p4K","pt":1657540130130,"mc":[{"id":"1.200806927","rc":[{"atl":[[1.12,568.02]],"trd":[[1.12,2620.82]],"tv":46891.78,"id":228749}],"tv":50898.09}]}
{"op":"mcm","clk":"APqMqgkArNiaCgC68p4K","pt":1657540131021,"mc":[{"id":"1.200806927","rc":[{"atl":[[1.12,563.67]],"trd":[[1.12,2625.17]],"tv":46896.13,"id":228749},{"trd":[[9.2,219.74]],"tv":4006.84,"id":2857977}],"tv":50902.97}]}
{"op":"mcm","clk":"AIGNqgkAstiaCgC/8p4K","pt":1657540131117,"mc":[{"id":"1.200806927","rc":[{"atl":[[1.12,563.14]],"trd":[[1.12,2626.23]],"tv":46897.19,"id":228749}],"tv":50904.03}]}
{"op":"mcm","clk":"AJWNqgkAyNiaCgDI8p4K","pt":1657540131356,"mc":[{"id":"1.200806927","rc":[{"atl":[[1.12,536.84]],"trd":[[1.12,2678.83]],"tv":46949.79,"id":228749}],"tv":50956.63}]}
{"op":"mcm","clk":"AJuOqgkAgtqaCgCM854K","pt":1657540132937,"mc":[{"id":"1.200806927","rc":[{"atl":[[1.12,535.96]],"trd":[[1.12,2679.71]],"tv":46950.67,"id":228749},{"trd":[[9.2,219.85]],"tv":4006.95,"id":2857977}],"tv":50957.62}]}
{"op":"mcm","clk":"ANSOqgkA3dqaCgDA854K","pt":1657540133716,"mc":[{"id":"1.200806927","rc":[{"atl":[[1.12,527.42]],"trd":[[1.12,2688.25]],"tv":46959.21,"id":228749},{"trd":[[9.2,220.89]],"tv":4007.99,"id":2857977}],"tv":50967.2}]}
{"op":"mcm","clk":"AOCOqgkA7dqaCgDE854K","pt":1657540133847,"mc":[{"id":"1.200806927","rc":[{"atl":[[1.12,524.79]],"trd":[[1.12,2693.51]],"tv":46964.47,"id":228749}],"tv":50972.46}]}
{"op":"mcm","clk":"AKOPqgkArNuaCgD1854K","pt":1657540134538,"mc":[{"id":"1.200806927","rc":[{"atl":[[1.12,523.97]],"trd":[[1.12,2694.33]],"tv":46965.29,"id":228749},{"trd":[[9.2,220.99]],"tv":4008.09,"id":2857977}],"tv":50973.38}]}
{"op":"mcm","clk":"AMiPqgkA0duaCgCL9J4K","pt":1657540134948,"mc":[{"id":"1.200806927","rc":[{"atl":[[1.12,521.6]],"trd":[[1.12,2699.07]],"tv":46970.03,"id":228749}],"tv":50978.12}]}
{"op":"mcm","clk":"ANOPqgkA29uaCgCP9J4K","pt":1657540135052,"mc":[{"id":"1.200806927","rc":[{"atl":[[1.12,520.72]],"trd":[[1.12,2699.95]],"tv":46970.91,"id":228749},{"trd":[[9.2,221.09]],"tv":4008.19,"id":2857977}],"tv":50979.1}]}
{"op":"mcm","clk":"AOePqgkA7NuaCgCX9J4K","pt":1657540135243,"mc":[{"id":"1.200806927","rc":[{"atl":[[10.5,0]],"id":2857977}]}]}
{"op":"mcm","clk":"ALaQqgkAr9yaCgDC9J4K","pt":1657540136133,"mc":[{"id":"1.200806927","rc":[{"atb":[[1.1,395.16]],"trd":[[1.1,61.68],[1.11,8.8]],"ltp":1.1,"tv":47032.97,"id":228749},{"atl":[[10,0]],"trd":[[10,0.41]],"ltp":10,"tv":4008.23,"id":2857977}],"tv":51041.2}]}
{"op":"mcm","clk":"AMaQqgkAw9yaCgDS9J4K","pt":1657540136338,"mc":[{"id":"1.200806927","rc":[{"atb":[[1.12,381.43]],"atl":[[1.12,0]],"trd":[[1.12,3741.39]],"ltp":1.12,"tv":48074.41,"id":228749}],"tv":52082.64}]}
{"op":"mcm","clk":"ANWQqgkA19yaCgDh9J4K","pt":1657540136553,"mc":[{"id":"1.200806927","rc":[{"atl":[[9.2,0.26]],"id":2857977}]}]}
{"op":"mcm","clk":"APOQqgkA8NyaCgD59J4K","pt":1657540136957,"mc":[{"id":"1.200806927","rc":[{"atb":[[1.11,8.61]],"id":228749}]}]}
{"op":"mcm","clk":"AKaRqgkAv92aCgCu9Z4K","pt":1657540137838,"mc":[{"id":"1.200806927","rc":[{"atb":[[1.12,384.06]],"id":228749}]}]}
{"op":"mcm","clk":"AM2RqgkA8d2aCgDE9Z4K","pt":1657540138349,"mc":[{"id":"1.200806927","rc":[{"atb":[[1.12,384.16]],"id":228749}]}]}
{"op":"mcm","clk":"AIuSqgkAuN6aCgDm9Z4K","pt":1657540139008,"mc":[{"id":"1.200806927","rc":[{"atl":[[9.2,210.63]],"id":2857977}]}]}
{"op":"mcm","clk":"AJ+SqgkAz96aCgD09Z4K","pt":1657540139245,"mc":[{"id":"1.200806927","rc":[{"atb":[[1.12,385.43]],"id":228749}]}]}
{"op":"mcm","clk":"AImTqgkAud+aCgC+9p4K","pt":1657540140627,"mc":[{"id":"1.200806927","rc":[{"atb":[[1.07,7.03]],"id":228749}]}]}
{"op":"mcm","clk":"AKCTqgkA19+aCgDP9p4K","pt":1657540140939,"mc":[{"id":"1.200806927","rc":[{"atb":[[1.12,386.48]],"id":228749}]}]}
{"op":"mcm","clk":"AKeTqgkA5N+aCgDT9p4K","pt":1657540141053,"mc":[{"id":"1.200806927","rc":[{"atb":[[1.12,386.59]],"id":228749}]}]}
{"op":"mcm","clk":"APGTqgkAreCaCgCF954K","pt":1657540141941,"mc":[{"id":"1.200806927","rc":[{"atb":[[1.11,34.5]],"id":228749}]}]}
{"op":"mcm","clk":"APyTqgkAs+CaCgCK954K","pt":1657540142041,"mc":[{"id":"1.200806927","rc":[{"atb":[[1.12,391.32]],"id":228749}]}]}
{"op":"mcm","clk":"AIyUqgkAw+CaCgCV954K","pt":1657540142231,"mc":[{"id":"1.200806927","rc":[{"atl":[[11,0.72]],"id":2857977}]}]}
{"op":"mcm","clk":"AJGUqgkAy+CaCgCc954K","pt":1657540142336,"mc":[{"id":"1.200806927","rc":[{"atb":[[1.12,390.79]],"id":228749}]}]}
{"op":"mcm","clk":"AL2UqgkAhOGaCgCz954K","pt":1657540142849,"mc":[{"id":"1.200806927","rc":[{"atl":[[9.2,0.26]],"id":2857977}]}]}
{"op":"mcm","clk":"AMWUqgkAj+GaCgC2954K","pt":1657540142960,"mc":[{"id":"1.200806927","rc":[{"atb":[[1.12,388.31]],"id":228749}]}]}
{"op":"mcm","clk":"ANyUqgkApOGaCgDH954K","pt":1657540143259,"mc":[{"id":"1.200806927","rc":[{"atl":[[9.2,0.79]],"id":2857977}]}]}
{"op":"mcm","clk":"AOiUqgkArOGaCgDU954K","pt":1657540143356,"mc":[{"id":"1.200806927","rc":[{"atl":[[9.2,3.42]],"id":2857977}]}]}
{"op":"mcm","clk":"APCUqgkAueGaCgDY954K","pt":1657540143456,"mc":[{"id":"1.200806927","rc":[{"atb":[[1.12,389.15]],"id":228749}]}]}
{"op":"mcm","clk":"AIGVqgkAz+GaCgDm954K","pt":1657540143671,"mc":[{"id":"1.200806927","rc":[{"atb":[[1.12,394.41]],"id":228749}]}]}
{"op":"mcm","clk":"AIeWqgkA1uKaCgC7+J4K","pt":1657540145141,"mc":[{"id":"1.200806927","rc":[{"atl":[[1.13,642.91]],"trd":[[1.13,1244.59]],"ltp":1.13,"tv":48075.22,"id":228749},{"trd":[[8.6,13.11]],"ltp":8.6,"tv":4008.34,"id":2857977}],"tv":52083.56}]}
{"op":"mcm","clk":"ALqWqgkAmeOaCgDr+J4K","pt":1657540145867,"mc":[{"id":"1.200806927","rc":[{"atb":[[1.12,394.94]],"id":228749}]}]}
{"op":"mcm","clk":"AJeXqgkAgeSaCgCy+Z4K","pt":1657540146833,"mc":[{"id":"1.200806927","rc":[{"atl":[[1000,0.3]],"id":228749}]}]}
{"op":"mcm","clk":"ALmXqgkAp+SaCgDF+Z4K","pt":1657540147266,"mc":[{"id":"1.200806927","rc":[{"atb":[[1.12,401.25]],"id":228749}]}]}
{"op":"mcm","clk":"AMSXqgkAsuSaCgDJ+Z4K","pt":1657540147360,"mc":[{"id":"1.200806927","rc":[{"atl":[[1000,0.13]],"id":228749}]}]}
{"op":"mcm","clk":"AIyYqgkAhuWaCgDt+Z4K","pt":1657540148240,"mc":[{"id":"1.200806927","rc":[{"atb":[[1.11,37.13]],"id":228749}]}]}
{"op":"mcm","clk":"AMWYqgkAwuWaCgCL+p4K","pt":1657540148975,"mc":[{"id":"1.200806927","rc":[{"atb":[[9.2,5.6]],"atl":[[9.2,0]],"trd":[[9.2,221.61]],"ltp":9.2,"tv":4008.86,"id":2857977}],"tv":52084.08}]}
{"op":"mcm","clk":"AKSZqgkAquaaCgC7+p4K","pt":1657540150055,"mc":[{"id":"1.200806927","rc":[{"atl":[[1.13,641.33]],"id":228749}]}]}
{"op":"mcm","clk":"APuZqgkA8uaaCgDq+p4K","pt":1657540150959,"mc":[{"id":"1.200806927","rc":[{"atl":[[1.3,134.67]],"id":228749}]}]}
{"op":"mcm","clk":"AJeaqgkAjOeaCgD9+p4K","pt":1657540151263,"mc":[{"id":"1.200806927","rc":[{"atb":[[1.1,396.74]],"id":228749}]}]}
{"op":"mcm","clk":"ANCaqgkAuOeaCgCo+54K","pt":1657540151844,"mc":[{"id":"1.200806927","rc":[{"atb":[[1.12,318.25]],"trd":[[1.12,3907.39]],"ltp":1.12,"tv":48241.22,"id":228749}],"tv":52250.08}]}
{"op":"mcm","clk":"ANeaqgkAv+eaCgCp+54K","pt":1657540151936,"mc":[{"id":"1.200806927","rc":[{"atl":[[1.13,851.7]],"id":228749}]}]}
{"op":"mcm","clk":"APCaqgkA3OeaCgC7+54K","pt":1657540152260,"mc":[{"id":"1.200806927","rc":[{"atb":[[1.12,307.73]],"id":228749}]}]}
{"op":"mcm","clk":"AICbqgkA6ueaCgDF+54K","pt":1657540152463,"mc":[{"id":"1.200806927","rc":[{"atb":[[1.12,307.55]],"trd":[[1.12,3907.75]],"tv":48241.58,"id":228749}],"tv":52250.44}]}
{"op":"mcm","clk":"AKubqgkAluiaCgDb+54K","pt":1657540153084,"mc":[{"id":"1.200806927","rc":[{"atb":[[1.12,312.81]],"id":228749}]}]}
{"op":"mcm","clk":"ALubqgkArOiaCgDo+54K","pt":1657540153244,"mc":[{"id":"1.200806927","rc":[{"atb":[[1.1,397.25]],"id":228749}]}]}
{"op":"mcm","clk":"ANubqgkAz+iaCgD3+54K","pt":1657540153657,"mc":[{"id":"1.200806927","rc":[{"atb":[[1.12,311.44]],"id":228749}]}]}
{"op":"mcm","clk":"APqbqgkA9uiaCgCN/J4K","pt":1657540154070,"mc":[{"id":"1.200806927","rc":[{"atb":[[9.2,4.55]],"id":2857977}]}]}
{"op":"mcm","clk":"AJucqgkAn+maCgCj/J4K","pt":1657540154468,"mc":[{"id":"1.200806927","rc":[{"atb":[[1.12,306.18]],"id":228749}]}]}
{"op":"mcm","clk":"APGcqgkAw+qaCgDT/J4K","pt":1657540155682,"mc":[{"id":"1.200806927","rc":[{"atb":[[1.05,131.9]],"id":228749}]}]}
{"op":"mcm","clk":"AIadqgkA3OqaCgDj/J4K","pt":1657540155984,"mc":[{"id":"1.200806927","rc":[{"atb":[[1.12,279.88]],"id":228749}]}]}
{"op":"mcm","clk":"AKOdqgkA9OqaCgDy/J4K","pt":1657540156267,"mc":[{"id":"1.200806927","rc":[{"atb":[[1.12,279.04]],"id":228749}]}]}
{"op":"mcm","clk":"AKmeqgkAgeyaCgDI/Z4K","pt":1657540157880,"mc":[{"id":"1.200806927","rc":[{"atb":[[1.04,2.89]],"id":228749}]}]}
{"op":"mcm","clk":"ALeeqgkAkOyaCgDR/Z4K","pt":1657540158078,"mc":[{"id":"1.200806927","rc":[{"atl":[[1.13,825.4]],"id":228749}]}]}
{"op":"mcm","clk":"AMWeqgkAouyaCgDZ/Z4K","pt":1657540158278,"mc":[{"id":"1.200806927","rc":[{"atl":[[1.13,1426.51]],"id":228749}]}]}
{"op":"mcm","clk":"ANyeqgkAweyaCgDk/Z4K","pt":1657540158554,"mc":[{"id":"1.200806927","rc":[{"atb":[[1.12,277.68]],"trd":[[1.12,3910.47]],"tv":48244.3,"id":228749}],"tv":52253.16}]}
{"op":"mcm","clk":"AI2fqgkA9uyaCgCE/p4K","pt":1657540159081,"mc":[{"id":"1.200806927","rc":[{"atb":[[1.12,272.95]],"id":228749}]}]}
{"op":"mcm","clk":"AJyfqgkAg+2aCgCJ/p4K","pt":1657540159274,"mc":[{"id":"1.200806927","rc":[{"atb":[[1.1,396.74],[1.12,270.32]],"id":228749}]}]}
{"op":"mcm","clk":"AMefqgkAr+2aCgCk/p4K","pt":1657540159846,"mc":[{"id":"1.200806927","rc":[{"atb":[[1.12,256.1]],"trd":[[1.12,3938.9]],"tv":48272.73,"id":228749}],"tv":52281.59}]}
{"op":"mcm","clk":"ANCfqgkAwO2aCgCs/p4K","pt":1657540160054,"mc":[{"id":"1.200806927","rc":[{"atb":[[9.2,0]],"atl":[[9.2,205.82]],"id":2857977}]}]}
{"op":"mcm","clk":"AI6gqgkAke6aCgDX/p4K","pt":1657540160922,"mc":[{"id":"1.200806927","rc":[{"atl":[[9.2,203.19]],"id":2857977}]}]}
{"op":"mcm","clk":"AJ+gqgkArO6aCgDg/p4K","pt":1657540161086,"mc":[{"id":"1.200806927","rc":[{"atl":[[9.2,203.72]],"id":2857977}]}]}
{"op":"mcm","clk":"AKygqgkAwu6aCgDs/p4K","pt":1657540161260,"mc":[{"id":"1.200806927","rc":[{"atb":[[1.12,45.73]],"id":228749}]}]}
{"op":"mcm","clk":"ALKgqgkAzO6aCgDw/p4K","pt":1657540161380,"mc":[{"id":"1.200806927","rc":[{"atb":[[1.12,45.2]],"id":228749}]}]}
{"op":"mcm","clk":"AL+gqgkA2e6aCgD0/p4K","pt":1657540161474,"mc":[{"id":"1.200806927","rc":[{"atl":[[9.2,203.83]],"id":2857977}]}]}
{"op":"mcm","clk":"AMKhqgkA+u+aCgDU/54K","pt":1657540163278,"mc":[{"id":"1.200806927","rc":[{"atb":[[1.04,3.1]],"id":228749}]}]}
{"op":"mcm","clk":"ANyhqgkAl/CaCgDf/54K","pt":1657540163548,"mc":[{"id":"1.200806927","rc":[{"atl":[[9.2,203.93]],"id":2857977}]}]}
{"op":"mcm","clk":"AOyhqgkAqvCaCgDx/54K","pt":1657540163758,"mc":[{"id":"1.200806927","rc":[{"atb":[[1.04,2.89]],"id":228749}]}]}
{"op":"mcm","clk":"AJaiqgkA3/CaCgCJgJ8K","pt":1657540164277,"mc":[{"id":"1.200806927","rc":[{"atl":[[1.13,1425.98]],"id":228749}]}]}
{"op":"mcm","clk":"ANWiqgkAsPGaCgCzgJ8K","pt":1657540165061,"mc":[{"id":"1.200806927","rc":[{"atl":[[9.2,204.46]],"id":2857977}]}]}
{"op":"mcm","clk":"AOSiqgkAx/GaCgDDgJ8K","pt":1657540165275,"mc":[{"id":"1.200806927","rc":[{"atb":[[1.12,44.67]],"id":228749}]}]}
{"op":"mcm","clk":"AI6jqgkA/fGaCgDjgJ8K","pt":1657540165789,"mc":[{"id":"1.200806927","rc":[{"atl":[[9.2,204.57]],"id":2857977}]}]}
{"op":"mcm","clk":"AJijqgkAiPKaCgDogJ8K","pt":1657540165896,"mc":[{"id":"1.200806927","rc":[{"atl":[[1.13,1478.57]],"id":228749}]}]}
{"op":"mcm","clk":"AKKjqgkAkfKaCgDtgJ8K","pt":1657540165987,"mc":[{"id":"1.200806927","rc":[{"atl":[[1.13,1478.04]],"id":228749}]}]}
{"op":"mcm","clk":"AKajqgkAmPKaCgDvgJ8K","pt":1657540166058,"mc":[{"id":"1.200806927","rc":[{"atl":[[1.13,1472.78]],"id":228749}]}]}
{"op":"mcm","clk":"ALGjqgkAovKaCgD2gJ8K","pt":1657540166170,"mc":[{"id":"1.200806927","rc":[{"atl":[[1.13,1471.78]],"id":228749}]}]}
{"op":"mcm","clk":"AM+jqgkAzPKaCgD/gJ8K","pt":1657540166571,"mc":[{"id":"1.200806927","rc":[{"atl":[[9.2,204.46]],"id":2857977}]}]}
{"op":"mcm","clk":"ANajqgkA1/KaCgCNgZ8K","pt":1657540166689,"mc":[{"id":"1.200806927","rc":[{"atb":[[1.12,43.21]],"trd":[[1.12,3941.83]],"tv":48275.66,"id":228749}],"tv":52284.52}]}
{"op":"mcm","clk":"ANujqgkA4fKaCgCUgZ8K","pt":1657540166782,"mc":[{"id":"1.200806927","rc":[{"atl":[[9.2,204.68]],"id":2857977}]}]}
{"op":"mcm","clk":"APqjqgkAjfOaCgCugZ8K","pt":1657540167194,"mc":[{"id":"1.200806927","rc":[{"atl":[[9.2,205.73]],"id":2857977}]}]}
{"op":"mcm","clk":"AJGkqgkAqfOaCgC7gZ8K","pt":1657540167459,"mc":[{"id":"1.200806927","rc":[{"atl":[[1.13,1470.88]],"id":228749}]}]}
{"op":"mcm","clk":"AK2kqgkAzPOaCgDXgZ8K","pt":1657540167878,"mc":[{"id":"1.200806927","rc":[{"atb":[[1.12,0]],"trd":[[1.12,4004.01]],"tv":48337.84,"id":228749},{"atl":[[9.2,198.19]],"trd":[[9.2,229.15]],"tv":4016.4,"id":2857977}],"tv":52354.24}]}
{"op":"mcm","clk":"AL6kqgkA4POaCgDfgZ8K","pt":1657540168087,"mc":[{"id":"1.200806927","rc":[{"atl":[[9.2,197.66]],"id":2857977}]}]}
{"op":"mcm","clk":"ANSkqgkAgPSaCgDugZ8K","pt":1657540168395,"mc":[{"id":"1.200806927","rc":[{"atl":[[1.13,1465.62]],"id":228749}]}]}
{"op":"mcm","clk":"AIWlqgkAtfSaCgCOgp8K","pt":1657540168906,"mc":[{"id":"1.200806927","rc":[{"atl":[[1.13,1465.4]],"trd":[[1.13,1245.03]],"ltp":1.13,"tv":48338.28,"id":228749}],"tv":52354.68}]}
{"op":"mcm","clk":"AKelqgkA3vSaCgCggp8K","pt":1657540169281,"mc":[{"id":"1.200806927","rc":[{"atb":[[1.04,2.05]],"id":228749},{"atl":[[9.2,197.55]],"id":2857977}]}]}
{"op":"mcm","clk":"AOalqgkAmvWaCgDEgp8K","pt":1657540169992,"mc":[{"id":"1.200806927","rc":[{"atl":[[9.2,197.02]],"id":2857977}]}]}
{"op":"mcm","clk":"APqlqgkAsPWaCgDOgp8K","pt":1657540170195,"mc":[{"id":"1.200806927","rc":[{"atl":[[9.2,197.15]],"id":2857977}]}]}
{"op":"mcm","clk":"AKemqgkA2/WaCgDfgp8K","pt":1657540170597,"mc":[{"id":"1.200806927","rc":[{"atl":[[1.13,1463.76]],"trd":[[1.13,1248.3]],"tv":48341.55,"id":228749}],"tv":52357.95}]}
{"op":"mcm","clk":"AM6mqgkAkPaaCgD1gp8K","pt":1657540171076,"mc":[{"id":"1.200806927","rc":[{"trd":[[1.12,4009.27]],"ltp":1.12,"tv":48346.81,"id":228749},{"atl":[[9.2,196.51]],"trd":[[9.2,229.79]],"tv":4017.04,"id":2857977}],"tv":52363.85}]}
{"op":"mcm","clk":"APimqgkAvfaaCgCWg58K","pt":1657540171602,"mc":[{"id":"1.200806927","rc":[{"trd":[[1.12,4610.38]],"tv":48947.92,"id":228749},{"atl":[[9.2,123.33]],"trd":[[9.2,302.97]],"tv":4090.22,"id":2857977}],"tv":53038.14}]}
{"op":"mcm","clk":"AKqnqgkA//aaCgCwg58K","pt":1657540172194,"mc":[{"id":"1.200806927","rc":[{"atl":[[9.2,123.2]],"id":2857977}]}]}
{"op":"mcm","clk":"AOWnqgkAxveaCgDOg58K","pt":1657540172921,"mc":[{"id":"1.200806927","rc":[{"atl":[[1.13,1253.39]],"id":228749}]}]}
{"op":"mcm","clk":"AP2nqgkA4/eaCgDbg58K","pt":1657540173196,"mc":[{"id":"1.200806927","rc":[{"trd":[[1.12,4610.49]],"tv":48948.03,"id":228749},{"atl":[[9.2,123.19]],"trd":[[9.2,302.98]],"tv":4090.23,"id":2857977}],"tv":53038.26}]}
{"op":"mcm","clk":"AIWoqgkA7PeaCgDgg58K","pt":1657540173308,"mc":[{"id":"1.200806927","rc":[{"atl":[[1.13,1252.34]],"id":228749}]}]}
{"op":"mcm","clk":"AKWoqgkAjviaCgDtg58K","pt":1657540173594,"mc":[{"id":"1.200806927","rc":[{"atl":[[1.13,1223.41]],"id":228749}]}]}
{"op":"mcm","clk":"AMaoqgkAr/iaCgCDhJ8K","pt":1657540173975,"mc":[{"id":"1.200806927","rc":[{"atb":[[3,6.69]],"id":2857977}]}]}
{"op":"mcm","clk":"ANGoqgkAvfiaCgCOhJ8K","pt":1657540174176,"mc":[{"id":"1.200806927","rc":[{"atl":[[1.13,1219.38]],"trd":[[1.13,1252.33]],"ltp":1.13,"tv":48952.06,"id":228749},{"trd":[[8.6,13.64]],"ltp":8.6,"tv":4090.76,"id":2857977}],"tv":53042.82}]}
{"op":"mcm","clk":"APqqqgkA7vqaCgC5hZ8K","pt":1657540177506,"mc":[{"id":"1.200806927","rc":[{"atb":[[1.12,10.52]],"id":228749}]}]}
{"op":"mcm","clk":"APurqgkA9PuaCgCVhp8K","pt":1657540179024,"mc":[{"id":"1.200806927","rc":[{"atl":[[9.2,123.09]],"id":2857977}]}]}
{"op":"mcm","clk":"AISsqgkA//uaCgCbhp8K","pt":1657540179088,"mc":[{"id":"1.200806927","rc":[{"atb":[[1.12,8.52]],"trd":[[1.12,4614.49]],"ltp":1.12,"tv":48956.06,"id":228749}],"tv":53046.82}]}
{"op":"mcm","clk":"AJCtqgkAi/2aCgCTh58K","pt":1657540180804,"mc":[{"id":"1.200806927","rc":[{"atb":[[1.12,0]],"trd":[[1.12,4921.54]],"tv":49263.11,"id":228749},{"atl":[[9.2,85.71]],"trd":[[9.2,340.36]],"ltp":9.2,"tv":4128.14,"id":2857977}],"tv":53391.25}]}
{"op":"mcm","clk":"ALStqgkAuv2aCgCoh58K","pt":1657540181310,"mc":[{"id":"1.200806927","rc":[{"atl":[[1.13,1218.57]],"trd":[[1.13,1253.14]],"ltp":1.13,"tv":49263.92,"id":228749},{"trd":[[8.6,13.74]],"ltp":8.6,"tv":4128.24,"id":2857977}],"tv":53392.16}]}
{"op":"mcm","clk":"APutqgkAjf6aCgDOh58K","pt":1657540182097,"mc":[{"id":"1.200806927","rc":[{"atl":[[1.13,1201.66]],"trd":[[1.13,1286.97],[1.12,4921.97]],"ltp":1.12,"tv":49298.18,"id":228749},{"atl":[[9.2,85.66]],"trd":[[9.2,340.41]],"ltp":9.2,"tv":4128.29,"id":2857977}],"tv":53426.47}]}
{"op":"mcm","clk":"AJ6uqgkAr/6aCgDeh58K","pt":1657540182508,"mc":[{"id":"1.200806927","rc":[{"atl":[[1.13,1199.51]],"trd":[[1.13,1291.27]],"ltp":1.13,"tv":49302.48,"id":228749}],"tv":53430.77}]}
{"op":"mcm","clk":"ALOuqgkAwv6aCgDth58K","pt":1657540182720,"mc":[{"id":"1.200806927","rc":[{"trd":[[1.12,4922.5]],"ltp":1.12,"tv":49303.01,"id":228749},{"atl":[[9.2,85.6]],"trd":[[9.2,340.47]],"tv":4128.35,"id":2857977}],"tv":53431.36}]}
{"op":"mcm","clk":"AL2uqgkAyP6aCgD0h58K","pt":1657540182802,"mc":[{"id":"1.200806927","rc":[{"atl":[[1.13,1197.87]],"trd":[[1.13,1292.91]],"ltp":1.13,"tv":49304.65,"id":228749},{"trd":[[8.6,13.96]],"ltp":8.6,"tv":4128.57,"id":2857977}],"tv":53433.22}]}
{"op":"mcm","clk":"AKmvqgkAp/+aCgCriJ8K","pt":1657540183914,"mc":[{"id":"1.200806927","rc":[{"atl":[[1.12,1796.9]],"trd":[[1.12,5625.6]],"ltp":1.12,"tv":50007.75,"id":228749},{"atl":[[9.2,0]],"trd":[[9.2,426.07]],"ltp":9.2,"tv":4214.17,"id":2857977}],"tv":54221.92}]}
{"op":"mcm","clk":"ALevqgkAvf+aCgCziJ8K","pt":1657540184122,"mc":[{"id":"1.200806927","rc":[{"atl":[[1.12,1794.9]],"trd":[[1.12,5629.6]],"tv":50011.75,"id":228749}],"tv":54225.92}]}
{"op":"mcm","clk":"AMivqgkA0v+aCgC8iJ8K","pt":1657540184326,"mc":[{"id":"1.200806927","rc":[{"atl":[[1.18,12.95]],"id":228749}]}]}
{"op":"mcm","clk":"AJmwqgkAooCbCgDviJ8K","pt":1657540185331,"mc":[{"id":"1.200806927","rc":[{"atl":[[1.12,1730.09]],"trd":[[1.12,5694.41]],"tv":50076.56,"id":228749},{"trd":[[9.2,433.96]],"tv":4222.06,"id":2857977}],"tv":54298.62}]}
{"op":"mcm","clk":"ANOwqgkA5YCbCgCgiZ8K","pt":1657540186007,"mc":[{"id":"1.200806927","rc":[{"atl":[[1000,0.3]],"id":228749}]}]}
{"op":"mcm","clk":"APewqgkAiYGbCgCziZ8K","pt":1657540186413,"mc":[{"id":"1.200806927","rc":[{"atl":[[1000,0.13]],"id":228749}]}]}
{"op":"mcm","clk":"AIyxqgkAmoGbCgC8iZ8K","pt":1657540186640,"mc":[{"id":"1.200806927","rc":[{"atl":[[1.12,1729.87]],"trd":[[1.12,5694.84]],"tv":50076.99,"id":228749}],"tv":54299.05}]}
{"op":"mcm","clk":"AKuxqgkAwoGbCgDSiZ8K","pt":1657540187035,"mc":[{"id":"1.200806927","rc":[{"atl":[[1.12,1728.45]],"trd":[[1.12,5697.68]],"tv":50079.83,"id":228749}],"tv":54301.89}]}
{"op":"mcm","clk":"ANSxqgkA+4GbCgDviZ8K","pt":1657540187521,"mc":[{"id":"1.200806927","rc":[{"atl":[[1.12,1726.45]],"trd":[[1.12,5701.68]],"tv":50083.83,"id":228749}],"tv":54305.89}]}
{"op":"mcm","clk":"ALayqgkA2oKbCgCvip8K","pt":1657540188513,"mc":[{"id":"1.200806927","rc":[{"atl":[[1.12,2327.56]],"id":228749}]}]}
{"op":"mcm","clk":"AMWyqgkA5IKbCgC0ip8K","pt":1657540188644,"mc":[{"id":"1.200806927","rc":[{"atl":[[1.12,2327.34]],"trd":[[1.12,5702.12]],"tv":50084.27,"id":228749}],"tv":54306.33}]}
{"op":"mcm","clk":"APqyqgkAm4ObCgDRip8K","pt":1657540189254,"mc":[{"id":"1.200806927","rc":[{"atb":[[1.1,397.27]],"id":228749}]}]}
{"op":"mcm","clk":"AIuzqgkAsIObCgDWip8K","pt":1657540189448,"mc":[{"id":"1.200806927","rc":[{"atl":[[1.12,2322.08]],"trd":[[1.12,5712.64]],"tv":50094.79,"id":228749}],"tv":54316.85}]}
{"op":"mcm","clk":"AKOzqgkAxIObCgDiip8K","pt":1657540189649,"mc":[{"id":"1.200806927","rc":[{"atl":[[1.12,2321.55]],"trd":[[1.12,5713.7]],"tv":50095.85,"id":228749}],"tv":54317.91}]}
{"op":"mcm","clk":"ALuzqgkA1YObCgDqip8K","pt":1657540189815,"mc":[{"id":"1.200806927","rc":[{"atl":[[1.12,2312.93]],"trd":[[1.12,5722.32]],"tv":50104.47,"id":228749},{"trd":[[9.2,435.01]],"tv":4223.11,"id":2857977}],"tv":54327.58}]}
{"op":"mcm","clk":"AO6zqgkAkISbCgCJi58K","pt":1657540190456,"mc":[{"id":"1.200806927","rc":[{"atl":[[1.12,2112.93]],"trd":[[1.12,6122.32]],"tv":50504.47,"id":228749}],"tv":54727.58}]}
{"op":"mcm","clk":"AIC0qgkAoISbCgCRi58K","pt":1657540190643,"mc":[{"id":"1.200806927","rc":[{"atl":[[1.12,2108.58]],"trd":[[1.12,6126.67]],"tv":50508.82,"id":228749},{"trd":[[9.2,435.54]],"tv":4223.64,"id":2857977}],"tv":54732.46}]}
{"op":"mcm","clk":"AJq0qgkAvoSbCgChi58K","pt":1657540190921,"mc":[{"id":"1.200806927","rc":[{"atl":[[1.12,2090.9]],"trd":[[1.12,6144.35]],"tv":50526.5,"id":228749},{"trd":[[9.2,437.69]],"tv":4225.79,"id":2857977}],"tv":54752.29}]}
{"op":"mcm","clk":"AKW0qgkAx4SbCgCsi58K","pt":1657540191028,"mc":[{"id":"1.200806927","rc":[{"atl":[[1.12,2117.95]],"id":228749}]}]}
{"op":"mcm","clk":"ANG0qgkA9oSbCgDCi58K","pt":1657540191570,"mc":[{"id":"1.200806927","rc":[{"atl":[[1.12,2118.13]],"id":228749}]}]}
{"op":"mcm","clk":"APO0qgkAnoWbCgDRi58K","pt":1657540191935,"mc":[{"id":"1.200806927","rc":[{"atl":[[1.12,2118.03]],"trd":[[1.12,6144.55]],"tv":50526.7,"id":228749}],"tv":54752.49}]}
{"op":"mcm","clk":"AIm1qgkAu4WbCgDgi58K","pt":1657540192228,"mc":[{"id":"1.200806927","rc":[{"atl":[[1.12,2117.85]],"id":228749}]}]}
{"op":"mcm","clk":"ALS1qgkA54WbCgD4i58K","pt":1657540192863,"mc":[{"id":"1.200806927","rc":[{"atl":[[1.12,2114.31]],"trd":[[1.12,6148.09]],"tv":50530.24,"id":228749},{"trd":[[9.2,438.12]],"tv":4226.22,"id":2857977}],"tv":54756.46}]}
{"op":"mcm","clk":"AOC1qgkAmYabCgCOjJ8K","pt":1657540193325,"mc":[{"id":"1.200806927","rc":[{"atl":[[1.12,2379.48]],"id":228749}]}]}
{"op":"mcm","clk":"AMy2qgkAioebCgDXjJ8K","pt":1657540194533,"mc":[{"id":"1.200806927","rc":[{"atl":[[1.12,2375.13]],"trd":[[1.12,6152.44]],"tv":50534.59,"id":228749},{"trd":[[9.2,438.65]],"tv":4226.75,"id":2857977}],"tv":54761.34}]}
{"op":"mcm","clk":"AIS3qgkAzoebCgD6jJ8K","pt":1657540195161,"mc":[{"id":"1.200806927","rc":[{"atl":[[2.96,6.53]],"id":228749}]}]}
{"op":"mcm","clk":"AI23qgkA24ebCgCGjZ8K","pt":1657540195276,"mc":[{"id":"1.200806927","rc":[{"atl":[[1.12,647.09]],"trd":[[1.12,7880.48]],"tv":52262.63,"id":228749},{"trd":[[9.2,649.02]],"tv":4437.12,"id":2857977}],"tv":56699.75}]}
{"op":"mcm","clk":"ALG3qgkAiIibCgCbjZ8K","pt":1657540195650,"mc":[{"id":"1.200806927","rc":[{"atl":[[1.12,645.33]],"trd":[[1.12,7882.24]],"tv":52264.39,"id":228749},{"trd":[[9.2,649.23]],"tv":4437.33,"id":2857977}],"tv":56701.72}]}
{"op":"mcm","clk":"AMm3qgkAm4ibCgCtjZ8K","pt":1657540195845,"mc":[{"id":"1.200806927","rc":[{"atl":[[1.12,855.7]],"id":228749}]}]}
{"op":"mcm","clk":"AOm3qgkAxoibCgDHjZ8K","pt":1657540196318,"mc":[{"id":"1.200806927","rc":[{"atb":[[1.11,34.5]],"id":228749}]}]}
{"op":"mcm","clk":"AP+3qgkA1IibCgDQjZ8K","pt":1657540196529,"mc":[{"id":"1.200806927","rc":[{"atl":[[1.12,851.35]],"trd":[[1.12,7886.59]],"tv":52268.74,"id":228749},{"trd":[[9.2,649.76]],"tv":4437.86,"id":2857977}],"tv":56706.6}]}
{"op":"mcm","clk":"ALy4qgkAm4mbCgD0jZ8K","pt":1657540197336,"mc":[{"id":"1.200806927","rc":[{"atl":[[1.12,844.28]],"trd":[[1.12,7893.66]],"tv":52275.81,"id":228749},{"trd":[[9.2,650.62]],"tv":4438.72,"id":2857977}],"tv":56714.53}]}
{"op":"mcm","clk":"AKe5qgkA/ImbCgCYjp8K","pt":1657540198248,"mc":[{"id":"1.200806927","rc":[{"atl":[[1.12,840.74]],"trd":[[1.12,7897.2]],"tv":52279.35,"id":228749},{"trd":[[9.2,651.05]],"tv":4439.15,"id":2857977}],"tv":56718.5}]}
{"op":"mcm","clk":"AIy6qgkA9oqbCgDRjp8K","pt":1657540199342,"mc":[{"id":"1.200806927","rc":[{"atl":[[1.36,25.89]],"id":228749}]}]}
{"op":"mcm","clk":"AJu6qgkAkIubCgDajp8K","pt":1657540199555,"mc":[{"id":"1.200806927","rc":[{"atl":[[1.12,838.74]],"trd":[[1.12,7901.2]],"tv":52283.35,"id":228749}],"tv":56722.5}]}
{"op":"mcm","clk":"ANe6qgkA4oubCgCJj58K","pt":1657540200331,"mc":[{"id":"1.200806927","rc":[{"atl":[[1.12,837.86]],"trd":[[1.12,7902.08]],"tv":52284.23,"id":228749},{"trd":[[9.2,651.16]],"tv":4439.26,"id":2857977}],"tv":56723.49}]}
{"op":"mcm","clk":"AOy6qgkAgIybCgCYj58K","pt":1657540200651,"mc":[{"id":"1.200806927","rc":[{"atl":[[1.12,836.55]],"id":228749}]}]}
{"op":"mcm","clk":"AJm7qgkAv4ybCgC7j58K","pt":1657540201233,"mc":[{"id":"1.200806927","rc":[{"atl":[[1.12,835.5]],"id":228749}]}]}
{"op":"mcm","clk":"AKS7qgkAzYybCgDCj58K","pt":1657540201344,"mc":[{"id":"1.200806927","rc":[{"atl":[[1.12,835.39]],"trd":[[1.12,7902.3]],"tv":52284.45,"id":228749}],"tv":56723.71}]}
{"op":"mcm","clk":"AK67qgkA14ybCgDKj58K","pt":1657540201441,"mc":[{"id":"1.200806927","rc":[{"atl":[[1.12,831.85]],"trd":[[1.12,7905.84]],"tv":52287.99,"id":228749},{"trd":[[9.2,651.59]],"tv":4439.69,"id":2857977}],"tv":56727.68}]}
{"op":"mcm","clk":"AN67qgkAl42bCgD2j58K","pt":1657540202081,"mc":[{"id":"1.200806927","rc":[{"atl":[[1.12,830.97]],"trd":[[1.12,7906.72]],"tv":52288.87,"id":228749},{"trd":[[9.2,651.7]],"tv":4439.8,"id":2857977}],"tv":56728.67}]}
{"op":"mcm","clk":"AOa7qgkApY2bCgD8j58K","pt":1657540202178,"mc":[{"id":"1.200806927","rc":[{"atl":[[1.12,830.44]],"id":228749}]}]}
{"op":"mcm","clk":"AOq7qgkAtI2bCgCBkJ8K","pt":1657540202275,"mc":[{"id":"1.200806927","rc":[{"atl":[[1.12,829.62]],"trd":[[1.12,7907.54]],"tv":52289.69,"id":228749},{"trd":[[9.2,651.8]],"tv":4439.9,"id":2857977}],"tv":56729.59}]}
{"op":"mcm","clk":"ALq8qgkAsI6bCgC7kJ8K","pt":1657540203241,"mc":[{"id":"1.200806927","rc":[{"atl":[[1.13,932.7],[1.12,797.58]],"trd":[[1.12,7950.57]],"tv":52332.72,"id":228749}],"tv":56772.62}]}
{"op":"mcm","clk":"AIK9qgkAjY+bCgDokJ8K","pt":1657540204091,"mc":[{"id":"1.200806927","rc":[{"atb":[[1.11,35.08]],"id":228749}]}]}
{"op":"mcm","clk":"AKa9qgkAxY+bCgCDkZ8K","pt":1657540204595,"mc":[{"id":"1.200806927","rc":[{"atb":[[1.1,186.95]],"id":228749}]}]}
{"op":"mcm","clk":"AKu9qgkAzo+bCgCIkZ8K","pt":1657540204659,"mc":[{"id":"1.200806927","rc":[{"atl":[[1.12,796.79]],"id":228749}]}]}
{"op":"mcm","clk":"ANG9qgkA/I+bCgCtkZ8K","pt":1657540205081,"mc":[{"id":"1.200806927","rc":[{"atl":[[1.12,792.74]],"trd":[[1.12,7951.99]],"tv":52334.14,"id":228749},{"trd":[[9.2,651.97]],"tv":4440.07,"id":2857977}],"tv":56774.21}]}
{"op":"mcm","clk":"AN69qgkAjZCbCgC1kZ8K","pt":1657540205229,"mc":[{"id":"1.200806927","rc":[{"atl":[[1.12,1003.11]],"id":228749}]}]}
{"op":"mcm","clk":"AOq9qgkAnJCbCgC+kZ8K","pt":1657540205332,"mc":[{"id":"1.200806927","rc":[{"atl":[[1.12,996.91]],"trd":[[1.12,7952.93]],"tv":52335.08,"id":228749},{"trd":[[9.2,652.08]],"tv":4440.18,"id":2857977}],"tv":56775.26}]}
{"op":"mcm","clk":"APa9qgkAp5CbCgDEkZ8K","pt":1657540205452,"mc":[{"id":"1.200806927","rc":[{"atl":[[1.12,992.56]],"trd":[[1.12,7957.28]],"tv":52339.43,"id":228749},{"trd":[[9.2,652.61]],"tv":4440.71,"id":2857977}],"tv":56780.14}]}
{"op":"mcm","clk":"AKS+qgkA1JCbCgDnkZ8K","pt":1657540205959,"mc":[{"id":"1.200806927","rc":[{"atl":[[1.12,0]],"trd":[[1.12,8949.84]],"tv":53331.99,"id":228749},{"atl":[[9.2,89.54]],"trd":[[9.2,773.44]],"tv":4561.54,"id":2857977}],"tv":57893.53}]}
{"op":"mcm","clk":"AK++qgkA4ZCbCgDwkZ8K","pt":1657540206076,"mc":[{"id":"1.200806927","rc":[{"atb":[[1.12,12.95]],"id":228749}]}]}
{"op":"mcm","clk":"AMO+qgkAiJGbCgCEkp8K","pt":1657540206369,"mc":[{"id":"1.200806927","rc":[{"atb":[[1.12,17.46]],"id":228749}]}]}
{"op":"mcm","clk":"AKu/qgkA/ZGbCgDNkp8K","pt":1657540207593,"mc":[{"id":"1.200806927","rc":[{"atl":[[9.2,89.76]],"id":2857977}]}]}
{"op":"mcm","clk":"ALu/qgkAmpKbCgDckp8K","pt":1657540207844,"mc":[{"id":"1.200806927","rc":[{"atb":[[1.12,20.09]],"id":228749}]}]}
{"op":"mcm","clk":"ANG/qgkAuJKbCgDzkp8K","pt":1657540208155,"mc":[{"id":"1.200806927","rc":[{"atl":[[9.2,118.13]],"id":2857977}]}]}
{"op":"mcm","clk":"APK/qgkA5ZKbCgCdk58K","pt":1657540208677,"mc":[{"id":"1.200806927","rc":[{"atl":[[9.2,118.34]],"id":2857977}]}]}
{"op":"mcm","clk":"AKPAqgkAnJObCgC/k58K","pt":1657540209179,"mc":[{"id":"1.200806927","rc":[{"atb":[[1.12,25.35]],"id":228749}]}]}
{"op":"mcm","clk":"AKfAqgkAoZObCgDCk58K","pt":1657540209257,"mc":[{"id":"1.200806927","rc":[{"atb":[[1.11,40.34],[1.12,26.4]],"id":228749}]}]}
{"op":"mcm","clk":"AMHAqgkAy5ObCgDfk58K","pt":1657540209698,"mc":[{"id":"1.200806927","rc":[{"atb":[[1.09,217.58]],"id":228749}]}]}
{"op":"mcm","clk":"AM/AqgkA3pObCgDlk58K","pt":1657540209842,"mc":[{"id":"1.200806927","rc":[{"atb":[[1.12,52.7]],"id":228749}]}]}
{"op":"mcm","clk":"ANfAqgkA5pObCgDrk58K","pt":1657540209946,"mc":[{"id":"1.200806927","rc":[{"atb":[[1.12,57.96]],"id":228749}]}]}
{"op":"mcm","clk":"AOPAqgkA9pObCgD4k58K","pt":1657540210152,"mc":[{"id":"1.200806927","rc":[{"atb":[[1.12,84.26]],"id":228749}]}]}
{"op":"mcm","clk":"APrAqgkAkpSbCgCMlJ8K","pt":1657540210460,"mc":[{"id":"1.200806927","rc":[{"atl":[[9.2,118.51]],"id":2857977}]}]}
{"op":"mcm","clk":"AIjBqgkAnpSbCgCVlJ8K","pt":1657540210595,"mc":[{"id":"1.200806927","rc":[{"atb":[[1.12,84.39]],"id":228749}]}]}
{"op":"mcm","clk":"AO7BqgkAsZWbCgDflJ8K","pt":1657540211892,"mc":[{"id":"1.200806927","rc":[{"atb":[[1.12,79.88]],"id":228749}]}]}
{"op":"mcm","clk":"APXBqgkAxpWbCgDqlJ8K","pt":1657540212075,"mc":[{"id":"1.200806927","rc":[{"atl":[[9.2,119.04]],"id":2857977}]}]}
{"op":"mcm","clk":"AJDCqgkA6pWbCgD7lJ8K","pt":1657540212353,"mc":[{"id":"1.200806927","rc":[{"atb":[[1.12,90.4]],"id":228749}]}]}
{"op":"mcm","clk":"AJvCqgkAgZabCgCHlZ8K","pt":1657540212553,"mc":[{"id":"1.200806927","rc":[{"atb":[[1.12,90.27]],"id":228749}]}]}
{"op":"mcm","clk":"AMPCqgkAsZabCgCnlZ8K","pt":1657540213065,"mc":[{"id":"1.200806927","rc":[{"atb":[[1.09,262.66]],"id":228749}]}]}
{"op":"mcm","clk":"AMnCqgkAvpabCgCtlZ8K","pt":1657540213178,"mc":[{"id":"1.200806927","rc":[{"atb":[[1.12,91.85]],"id":228749}]}]}
{"op":"mcm","clk":"APbCqgkA9ZabCgDClZ8K","pt":1657540213673,"mc":[{"id":"1.200806927","rc":[{"atb":[[1.12,97.2]],"id":228749}]}]}
{"op":"mcm","clk":"AJLDqgkAq5ebCgDhlZ8K","pt":1657540214075,"mc":[{"id":"1.200806927","rc":[{"atl":[[9.2,118.87]],"id":2857977}]}]}
{"op":"mcm","clk":"AOfDqgkAqJibCgCqlp8K","pt":1657540215285,"mc":[{"id":"1.200806927","rc":[{"atl":[[9.2,129.15]],"id":2857977}]}]}
{"op":"mcm","clk":"AO7DqgkAsZibCgCwlp8K","pt":1657540215397,"mc":[{"id":"1.200806927","rc":[{"atb":[[1.12,70.9]],"id":228749}]}]}
{"op":"mcm","clk":"AMvEqgkAoZmbCgDqlp8K","pt":1657540216390,"mc":[{"id":"1.200806927","rc":[{"atb":[[1.12,68.27]],"id":228749},{"atl":[[9.2,128.62]],"id":2857977}]}]}
{"op":"mcm","clk":"AIvFqgkA/JmbCgCbl58K","pt":1657540217281,"mc":[{"id":"1.200806927","rc":[{"atl":[[1.13,880.11]],"id":228749}]}]}
{"op":"mcm","clk":"AO7FqgkAi5ubCgDml58K","pt":1657540218652,"mc":[{"id":"1.200806927","rc":[{"atl":[[9.2,128.4]],"id":2857977}]}]}
{"op":"mcm","clk":"ALfGqgkA8JubCgCXmJ8K","pt":1657540219660,"mc":[{"id":"1.200806927","rc":[{"atb":[[1.12,41.97]],"id":228749}]}]}
{"op":"mcm","clk":"AOvGqgkAnJybCgC7mJ8K","pt":1657540220261,"mc":[{"id":"1.200806927","rc":[{"atb":[[1.12,68.27]],"id":228749}]}]}
{"op":"mcm","clk":"APfGqgkAqJybCgDGmJ8K","pt":1657540220396,"mc":[{"id":"1.200806927","rc":[{"atl":[[1.13,879.35]],"trd":[[1.13,1293.67]],"ltp":1.13,"tv":53332.75,"id":228749},{"trd":[[8.6,14.06]],"ltp":8.6,"tv":4561.64,"id":2857977}],"tv":57894.39}]}
{"op":"mcm","clk":"AKHHqgkA1ZybCgDgmJ8K","pt":1657540220865,"mc":[{"id":"1.200806927","rc":[{"atb":[[1.12,66.69]],"id":228749}]}]}
{"op":"mcm","clk":"ALXHqgkA95ybCgDwmJ8K","pt":1657540221172,"mc":[{"id":"1.200806927","rc":[{"atl":[[1000,0.3]],"id":228749}]}]}
{"op":"mcm","clk":"ANnHqgkAo52bCgCTmZ8K","pt":1657540221682,"mc":[{"id":"1.200806927","rc":[{"atl":[[1000,0.13]],"id":228749}]}]}
{"op":"mcm","clk":"AOrHqgkAuJ2bCgCfmZ8K","pt":1657540221866,"mc":[{"id":"1.200806927","rc":[{"atl":[[9.2,100.03]],"id":2857977}]}]}
{"op":"mcm","clk":"AILIqgkA4p2bCgCsmZ8K","pt":1657540222164,"mc":[{"id":"1.200806927","rc":[{"atl":[[1.13,878.17]],"trd":[[1.13,1294.85]],"tv":53333.93,"id":228749},{"trd":[[8.6,14.21]],"tv":4561.79,"id":2857977}],"tv":57895.72}]}
{"op":"mcm","clk":"AKbIqgkAl56bCgDBmZ8K","pt":1657540222663,"mc":[{"id":"1.200806927","rc":[{"atl":[[1.13,851.87]],"id":228749}]}]}
{"op":"mcm","clk":"AMnIqgkAxp6bCgDVmZ8K","pt":1657540223147,"mc":[{"id":"1.200806927","rc":[{"atl":[[1.13,812.43]],"id":228749}]}]}
{"op":"mcm","clk":"AOfIqgkA4J6bCgDmmZ8K","pt":1657540223464,"mc":[{"id":"1.200806927","rc":[{"atb":[[1.12,1.96]],"atl":[[1.13,810.85]],"trd":[[1.12,8958.45]],"ltp":1.12,"tv":53342.54,"id":228749}],"tv":57904.33}]}
{"op":"mcm","clk":"APXIqgkA8J6bCgDymZ8K","pt":1657540223688,"mc":[{"id":"1.200806927","rc":[{"atl":[[1.13,810.72]],"trd":[[1.13,1295.11]],"ltp":1.13,"tv":53342.8,"id":228749}],"tv":57904.59}]}
{"op":"mcm","clk":"AMTJqgkAxZ+bCgCgmp8K","pt":1657540224672,"mc":[{"id":"1.200806927","rc":[{"atb":[[1.12,3.54]],"id":228749}]}]}
{"op":"mcm","clk":"ANfJqgkA25+bCgCvmp8K","pt":1657540224893,"mc":[{"id":"1.200806927","rc":[{"atl":[[9.2,100.14]],"id":2857977}]}]}
{"op":"mcm","clk":"AITKqgkAlaCbCgDSmp8K","pt":1657540225466,"mc":[{"id":"1.200806927","rc":[{"atl":[[1.13,809.91]],"trd":[[1.13,1295.92]],"tv":53343.61,"id":228749},{"trd":[[8.6,14.32]],"tv":4561.9,"id":2857977}],"tv":57905.51}]}
{"op":"mcm","clk":"ALzKqgkA4qCbCgCDm58K","pt":1657540226314,"mc":[{"id":"1.200806927","rc":[{"atl":[[1.13,807.91]],"id":228749}]}]}
{"op":"mcm","clk":"ANjKqgkAk6GbCgCbm58K","pt":1657540226779,"mc":[{"id":"1.200806927","rc":[{"atb":[[1.12,3.36]],"trd":[[1.12,8958.8]],"ltp":1.12,"tv":53343.96,"id":228749}],"tv":57905.86}]}
{"op":"mcm","clk":"AOjKqgkArqGbCgCom58K","pt":1657540226983,"mc":[{"id":"1.200806927","rc":[{"atl":[[1.13,587.48]],"trd":[[1.13,1511.84]],"ltp":1.13,"tv":53559.88,"id":228749},{"trd":[[8.6,42.69]],"tv":4590.27,"id":2857977}],"tv":58150.15}]}
{"op":"mcm","clk":"AIjLqgkA16GbCgDGm58K","pt":1657540227403,"mc":[{"id":"1.200806927","rc":[{"atb":[[1.12,0]],"trd":[[1.12,9170.16]],"ltp":1.12,"tv":53771.24,"id":228749},{"atl":[[9.2,75.23]],"trd":[[9.2,798.35]],"ltp":9.2,"tv":4615.18,"id":2857977}],"tv":58386.42}]}
{"op":"mcm","clk":"AOTLqgkA4KKbCgCMnJ8K","pt":1657540228597,"mc":[{"id":"1.200806927","rc":[{"trd":[[1.12,9172.26]],"tv":53773.34,"id":228749},{"atl":[[9.2,74.97]],"trd":[[9.2,798.61]],"tv":4615.44,"id":2857977}],"tv":58388.78}]}
{"op":"mcm","clk":"AM/MqgkA86ObCgDYnJ8K","pt":1657540229967,"mc":[{"id":"1.200806927","rc":[{"atl":[[1.13,583.27]],"id":228749}]}]}
{"op":"mcm","clk":"AO3MqgkAnKSbCgDynJ8K","pt":1657540230371,"mc":[{"id":"1.200806927","rc":[{"atl":[[1.13,553.79]],"trd":[[1.13,1541.32]],"ltp":1.13,"tv":53802.82,"id":228749},{"trd":[[8.6,46.56]],"ltp":8.6,"tv":4619.31,"id":2857977}],"tv":58422.13}]}
{"op":"mcm","clk":"AKbNqgkA2aSbCgCdnZ8K","pt":1657540231091,"mc":[{"id":"1.200806927","rc":[{"atl":[[1.13,549.76]],"trd":[[1.13,1545.35]],"tv":53806.85,"id":228749},{"trd":[[8.6,47.09]],"tv":4619.84,"id":2857977}],"tv":58426.69}]}
{"op":"mcm","clk":"AO/NqgkAq6WbCgDbnZ8K","pt":1657540231996,"mc":[{"id":"1.200806927","rc":[{"atl":[[9.2,73.39]],"id":2857977}]}]}
{"op":"mcm","clk":"AILOqgkAwaWbCgDqnZ8K","pt":1657540232172,"mc":[{"id":"1.200806927","rc":[{"atb":[[1.04,2.89]],"id":228749}]}]}
{"op":"mcm","clk":"AMPOqgkAmqabCgCVnp8K","pt":1657540233092,"mc":[{"id":"1.200806927","rc":[{"atl":[[1.13,549.33]],"trd":[[1.13,1546.21]],"tv":53807.71,"id":228749}],"tv":58427.55}]}
{"op":"mcm","clk":"AMbPqgkApaebCgD7np8K","pt":1657540234576,"mc":[{"id":"1.200806927","rc":[{"trd":[[1.12,9174.89]],"ltp":1.12,"tv":53810.34,"id":228749},{"atl":[[9.2,73.07]],"trd":[[9.2,798.93]],"ltp":9.2,"tv":4620.16,"id":2857977}],"tv":58430.5}]}
{"op":"mcm","clk":"AOvPqgkA0qebCgCSn58K","pt":1657540234995,"mc":[{"id":"1.200806927","rc":[{"atl":[[1.13,544.07]],"id":228749}]}]}
{"op":"mcm","clk":"AIHRqgkAgqmbCgDun58K","pt":1657540236692,"mc":[{"id":"1.200806927","rc":[{"atl":[[1.13,540.04]],"trd":[[1.13,1550.24]],"ltp":1.13,"tv":53814.37,"id":228749},{"trd":[[8.6,47.62]],"ltp":8.6,"tv":4620.69,"id":2857977}],"tv":58435.06}]}
{"op":"mcm","clk":"AIzRqgkAlambCgD3n58K","pt":1657540236902,"mc":[{"id":"1.200806927","rc":[{"atl":[[1.13,539.41]],"id":228749}]}]}
{"op":"mcm","clk":"AKnRqgkAt6mbCgCRoJ8K","pt":1657540237317,"mc":[{"id":"1.200806927","rc":[{"atb":[[1.12,52.59]],"id":228749}]}]}
{"op":"mcm","clk":"AMbRqgkA16mbCgCnoJ8K","pt":1657540237604,"mc":[{"id":"1.200806927","rc":[{"atb":[[1.04,3.1]],"id":228749}]}]}
{"op":"mcm","clk":"ANbRqgkA7qmbCgC1oJ8K","pt":1657540237823,"mc":[{"id":"1.200806927","rc":[{"atl":[[1.13,537.31]],"id":228749}]}]}
{"op":"mcm","clk":"AO7RqgkAj6qbCgDJoJ8K","pt":1657540238079,"mc":[{"id":"1.200806927","rc":[{"atb":[[1.04,2.89]],"id":228749}]}]}
{"op":"mcm","clk":"AIfSqgkArKqbCgDdoJ8K","pt":1657540238383,"mc":[{"id":"1.200806927","rc":[{"atb":[[1.12,262.96]],"id":228749}]}]}
{"op":"mcm","clk":"AKLSqgkA0KqbCgDtoJ8K","pt":1657540238722,"mc":[{"id":"1.200806927","rc":[{"atl":[[1.13,534.68]],"id":228749}]}]}
{"op":"mcm","clk":"AK3SqgkA26qbCgD3oJ8K","pt":1657540238816,"mc":[{"id":"1.200806927","rc":[{"atl":[[1.13,518.3]],"trd":[[1.13,1566.62]],"tv":53830.75,"id":228749},{"trd":[[8.6,49.77]],"tv":4622.84,"id":2857977}],"tv":58453.59}]}
{"op":"mcm","clk":"ALfTqgkAkKybCgD+oZ8K","pt":1657540240608,"mc":[{"id":"1.200806927","rc":[{"atl":[[1.13,465.71]],"id":228749}]}]}
{"op":"mcm","clk":"AOHTqgkAuaybCgCcop8K","pt":1657540241114,"mc":[{"id":"1.200806927","rc":[{"atl":[[1.13,464.9]],"trd":[[1.13,1567.43]],"tv":53831.56,"id":228749},{"trd":[[8.6,49.88]],"tv":4622.95,"id":2857977}],"tv":58454.51}]}
{"op":"mcm","clk":"AJzUqgkA6qybCgDIop8K","pt":1657540241812,"mc":[{"id":"1.200806927","rc":[{"atb":[[1.12,54.96]],"trd":[[1.12,9590.89]],"ltp":1.12,"tv":54247.56,"id":228749}],"tv":58870.51}]}
{"op":"mcm","clk":"ALrUqgkAj62bCgDqop8K","pt":1657540242333,"mc":[{"id":"1.200806927","rc":[{"atl":[[1.13,458.59]],"id":228749}]}]}
{"op":"mcm","clk":"AOTUqgkAtq2bCgCCo58K","pt":1657540242817,"mc":[{"id":"1.200806927","rc":[{"atl":[[1.13,452.78]],"id":228749},{"atl":[[8.8,1.67]],"id":2857977}]}]}
{"op":"mcm","clk":"APvUqgkA4K2bCgCUo58K","pt":1657540243213,"mc":[{"id":"1.200806927","rc":[{"atl":[[1.13,452.56]],"trd":[[1.13,1567.87]],"ltp":1.13,"tv":54248,"id":228749}],"tv":58870.95}]}
{"op":"mcm","clk":"AI3VqgkA9q2bCgCio58K","pt":1657540243426,"mc":[{"id":"1.200806927","rc":[{"atl":[[1.13,662.93]],"id":228749}]}]}
{"op":"mcm","clk":"AJnVqgkAka6bCgCvo58K","pt":1657540243638,"mc":[{"id":"1.200806927","rc":[{"atb":[[1.04,2.05]],"id":228749}]}]}
{"op":"mcm","clk":"AJ/VqgkAna6bCgC1o58K","pt":1657540243701,"mc":[{"id":"1.200806927","rc":[{"atl":[[1.13,662.5]],"trd":[[1.13,1568.73]],"tv":54248.86,"id":228749}],"tv":58871.81}]}
{"op":"mcm","clk":"AOLXqgkAtrGbCgCopZ8K","pt":1657540247847,"mc":[{"id":"1.200806927","rc":[{"atb":[[1.12,0]],"atl":[[1.12,531.71]],"trd":[[1.12,10314.14]],"ltp":1.12,"tv":54972.11,"id":228749},{"atl":[[8.8,0],[9.2,0]],"trd":[[8.8,1.67],[9.2,872]],"ltp":9.2,"tv":4697.69,"id":2857977}],"tv":59669.8}]}
{"op":"mcm","clk":"AInYqgkA8LGbCgDEpZ8K","pt":1657540248319,"mc":[{"id":"1.200806927","rc":[{"atl":[[1.12,0]],"id":228749}]}]}
{"op":"mcm","clk":"AJ7aqgkApbSbCgDspp8K","pt":1657540251412,"mc":[{"id":"1.200806927","rc":[{"atl":[[1.13,650.93]],"id":228749}]}]}
{"op":"mcm","clk":"AKnaqgkAsbSbCgDzpp8K","pt":1657540251518,"mc":[{"id":"1.200806927","rc":[{"atb":[[1.09,462.66]],"id":228749}]}]}
{"op":"mcm","clk":"AMTaqgkAz7SbCgCEp58K","pt":1657540251843,"mc":[{"id":"1.200806927","rc":[{"atl":[[1.13,645.67]],"id":228749}]}]}
{"op":"mcm","clk":"APnaqgkAmrWbCgCop58K","pt":1657540252517,"mc":[{"id":"1.200806927","rc":[{"atb":[[1.07,207.03]],"id":228749},{"atl":[[9.2,0.11]],"id":2857977}]}]}
{"op":"mcm","clk":"ALfbqgkA8bWbCgDXp58K","pt":1657540253378,"mc":[{"id":"1.200806927","rc":[{"atb":[[1.12,1.58]],"id":228749}]}]}
{"op":"mcm","clk":"AN3bqgkAoLabCgDvp58K","pt":1657540253836,"mc":[{"id":"1.200806927","rc":[{"atb":[[1.12,6.84]],"id":228749}]}]}
{"op":"mcm","clk":"AJDcqgkA4rabCgCRqJ8K","pt":1657540254563,"mc":[{"id":"1.200806927","rc":[{"atb":[[1.11,240.34],[1.12,0]],"atl":[[1.12,993.08]],"trd":[[1.12,10315.02]],"tv":54972.99,"id":228749},{"atl":[[9.2,0]],"trd":[[9.2,872.11]],"tv":4697.8,"id":2857977}],"tv":59670.79}]}
{"op":"mcm","clk":"AKLcqgkA9LabCgCdqJ8K","pt":1657540254760,"mc":[{"id":"1.200806927","rc":[{"atl":[[1.12,1201.68]],"trd":[[1.12,10316.79]],"tv":54974.76,"id":228749},{"trd":[[9.2,872.32]],"tv":4698.01,"id":2857977}],"tv":59672.77}]}
{"op":"mcm","clk":"AKvcqgkAgbebCgCgqJ8K","pt":1657540254858,"mc":[{"id":"1.200806927","rc":[{"atl":[[1.12,1194.29]],"trd":[[1.12,10324.18]],"tv":54982.15,"id":228749},{"trd":[[9.2,873.22]],"tv":4698.91,"id":2857977}],"tv":59681.06}]}
{"op":"mcm","clk":"APLcqgkA7rebCgDaqJ8K","pt":1657540255744,"mc":[{"id":"1.200806927","rc":[{"atl":[[1.12,2095.91]],"id":228749}]}]}
{"op":"mcm","clk":"AI/dqgkAoLibCgDuqJ8K","pt":1657540256138,"mc":[{"id":"1.200806927","rc":[{"atb":[[1.08,1045.67]],"id":228749}]}]}
{"op":"mcm","clk":"AKbdqgkAsLibCgD2qJ8K","pt":1657540256355,"mc":[{"id":"1.200806927","rc":[{"atl":[[1.12,2094.33]],"id":228749}]}]}
{"op":"mcm","clk":"ALbdqgkAxLibCgD+qJ8K","pt":1657540256561,"mc":[{"id":"1.200806927","rc":[{"atl":[[1000,0.24]],"id":228749}]}]}
{"op":"mcm","clk":"ANHdqgkA3LibCgCJqZ8K","pt":1657540256771,"mc":[{"id":"1.200806927","rc":[{"atl":[[1.12,2092.75]],"id":228749}]}]}
{"op":"mcm","clk":"AOfdqgkA7LibCgCRqZ8K","pt":1657540256966,"mc":[{"id":"1.200806927","rc":[{"atl":[[1000,0.13]],"id":228749}]}]}
{"op":"mcm","clk":"ANLeqgkA4bmbCgDJqZ8K","pt":1657540258233,"mc":[{"id":"1.200806927","rc":[{"atl":[[1.12,2096.43]],"id":228749}]}]}
{"op":"mcm","clk":"APXeqgkAhbqbCgDgqZ8K","pt":1657540258655,"mc":[{"id":"1.200806927","rc":[{"atb":[[1.11,227.08]],"trd":[[1.11,35.31]],"ltp":1.11,"tv":55008.66,"id":228749}],"tv":59707.57}]}
{"op":"mcm","clk":"ANLfqgkA/rqbCgCmqp8K","pt":1657540259756,"mc":[{"id":"1.200806927","rc":[{"atl":[[1.12,2457.76]],"id":228749}]}]}
{"op":"mcm","clk":"AJ/gqgkA37ubCgDmqp8K","pt":1657540260655,"mc":[{"id":"1.200806927","rc":[{"atl":[[1.12,2668.13]],"id":228749}]}]}
{"op":"mcm","clk":"AMbhqgkAtr2bCgCyq58K","pt":1657540262098,"mc":[{"id":"1.200806927","rc":[{"atl":[[1.12,940.21]],"trd":[[1.12,12052.22]],"ltp":1.12,"tv":56736.7,"id":228749},{"trd":[[9.2,1083.59]],"tv":4909.28,"id":2857977}],"tv":61645.98}]}
{"op":"mcm","clk":"ALXiqgkAxb6bCgD8q58K","pt":1657540262880,"mc":[{"id":"1.200806927","rc":[{"atl":[[1.12,940.09]],"id":228749}]}]}
{"op":"mcm","clk":"ANzjqgkA6L+bCgDprJ8K","pt":1657540263948,"mc":[{"id":"1.200806927","rc":[{"atl":[[1.12,939.03]],"trd":[[1.12,12053.28]],"tv":56737.76,"id":228749},{"trd":[[9.2,1083.72]],"tv":4909.41,"id":2857977}],"tv":61647.17}]}
{"op":"mcm","clk":"ANHkqgkA9sCbCgDArZ8K","pt":1657540265072,"mc":[{"id":"1.200806927","rc":[{"atl":[[1.12,917.39]],"id":228749}]}]}
{"op":"mcm","clk":"AI7lqgkAwMGbCgDrrZ8K","pt":1657540265662,"mc":[{"id":"1.200806927","rc":[{"atl":[[1.12,759.62]],"id":228749}]}]}
{"op":"mcm","clk":"AKHlqgkA18GbCgD1rZ8K","pt":1657540265866,"mc":[{"id":"1.200806927","rc":[{"atb":[[1.11,16.71]],"atl":[[1.12,753.57]],"trd":[[1.11,401.89],[1.12,12059.33]],"tv":57110.39,"id":228749},{"trd":[[9.2,1084.46]],"tv":4910.15,"id":2857977}],"tv":62020.54}]}
{"op":"mcm","clk":"AKblqgkA4cGbCgD4rZ8K","pt":1657540265950,"mc":[{"id":"1.200806927","rc":[{"atl":[[1.12,752.69]],"trd":[[1.12,12060.21]],"tv":57111.27,"id":228749},{"trd":[[9.2,1084.56]],"tv":4910.25,"id":2857977}],"tv":62021.52}]}
{"op":"mcm","clk":"ALPlqgkA7cGbCgCArp8K","pt":1657540266065,"mc":[{"id":"1.200806927","rc":[{"atl":[[1.12,700.1]],"id":228749}]}]}
{"op":"mcm","clk":"AM3lqgkAicKbCgCMrp8K","pt":1657540266336,"mc":[{"id":"1.200806927","rc":[{"atb":[[1.11,0]],"atl":[[1.12,651.84]],"trd":[[1.11,435.31]],"ltp":1.11,"tv":57144.69,"id":228749}],"tv":62054.94}]}
{"op":"mcm","clk":"AM/lqgkAlcKbCgCRrp8K","pt":1657540266433,"mc":[{"id":"1.200806927","rc":[{"atl":[[1.11,208]],"id":228749}]}]}
{"op":"mcm","clk":"AN/lqgkApcKbCgCXrp8K","pt":1657540266544,"mc":[{"id":"1.200806927","rc":[{"atl":[[1.11,156.63]],"trd":[[1.11,538.06]],"tv":57247.44,"id":228749}],"tv":62157.69}]}
{"op":"mcm","clk":"AILmqgkAy8KbCgCurp8K","pt":1657540266851,"mc":[{"id":"1.200806927","rc":[{"atl":[[1.11,155.67]],"trd":[[1.11,539.02]],"tv":57248.4,"id":228749},{"trd":[[10,0.52]],"ltp":10,"tv":4910.36,"id":2857977}],"tv":62158.76}]}
{"op":"mcm","clk":"AKXmqgkA/cKbCgDHrp8K","pt":1657540267286,"mc":[{"id":"1.200806927","rc":[{"atl":[[1.11,154.77]],"trd":[[1.11,539.92]],"tv":57249.3,"id":228749},{"trd":[[10,0.62]],"tv":4910.46,"id":2857977}],"tv":62159.76}]}
{"op":"mcm","clk":"AMbmqgkAr8ObCgDZrp8K","pt":1657540267642,"mc":[{"id":"1.200806927","rc":[{"atl":[[1.11,123.7]],"trd":[[1.11,597.29]],"tv":57306.67,"id":228749},{"trd":[[10,1.15]],"tv":4910.99,"id":2857977}],"tv":62217.66}]}
{"op":"mcm","clk":"AM/nqgkA0cSbCgChr58K","pt":1657540269063,"mc":[{"id":"1.200806927","rc":[{"atl":[[1.11,139.48]],"id":228749}]}]}
{"op":"mcm","clk":"APjnqgkA+cSbCgC7r58K","pt":1657540269469,"mc":[{"id":"1.200806927","rc":[{"atl":[[1.11,138.58]],"trd":[[1.11,598.19]],"tv":57307.57,"id":228749},{"trd":[[10,1.25]],"tv":4911.09,"id":2857977}],"tv":62218.66}]}
{"op":"mcm","clk":"AN7oqgkA58WbCgCDsJ8K","pt":1657540270583,"mc":[{"id":"1.200806927","rc":[{"atl":[[1.11,132.5]],"trd":[[1.11,605.58]],"tv":57314.96,"id":228749},{"trd":[[10,1.78]],"tv":4911.62,"id":2857977}],"tv":62226.58}]}
{"op":"mcm","clk":"ALfpqgkA1MabCgCzsJ8K","pt":1657540271569,"mc":[{"id":"1.200806927","rc":[{"atl":[[1.11,128.97]],"trd":[[1.11,612.64]],"tv":57322.02,"id":228749}],"tv":62233.64}]}
{"op":"mcm","clk":"AODpqgkA/MabCgDMsJ8K","pt":1657540271974,"mc":[{"id":"1.200806927","rc":[{"atl":[[1.11,128.87]],"trd":[[1.11,612.84]],"tv":57322.22,"id":228749}],"tv":62233.84}]}
{"op":"mcm","clk":"AILqqgkAm8ebCgDbsJ8K","pt":1657540272243,"mc":[{"id":"1.200806927","rc":[{"atl":[[11,0]],"id":2857977}]}]}
{"op":"mcm","clk":"ALzqqgkA2cebCgCBsZ8K","pt":1657540272878,"mc":[{"id":"1.200806927","rc":[{"atb":[[10,1.67]],"id":2857977}]}]}
{"op":"mcm","clk":"AMzqqgkA5cebCgCHsZ8K","pt":1657540272976,"mc":[{"id":"1.200806927","rc":[{"atl":[[1.11,102.57]],"trd":[[1.11,665.44]],"tv":57374.82,"id":228749}],"tv":62286.44}]}
{"op":"mcm","clk":"AOvqqgkAg8ibCgCasZ8K","pt":1657540273278,"mc":[{"id":"1.200806927","rc":[{"atl":[[1.11,124.5]],"id":228749}]}]}
{"op":"mcm","clk":"APTqqgkAjcibCgCgsZ8K","pt":1657540273381,"mc":[{"id":"1.200806927","rc":[{"atl":[[1.11,71.91]],"trd":[[1.11,770.62]],"tv":57480,"id":228749}],"tv":62391.62}]}
{"op":"mcm","clk":"AIHrqgkAl8ibCgCjsZ8K","pt":1657540273460,"mc":[{"id":"1.200806927","rc":[{"atl":[[1.11,71.81]],"trd":[[1.11,770.82]],"tv":57480.2,"id":228749}],"tv":62391.82}]}
{"op":"mcm","clk":"AJXrqgkAqMibCgCrsZ8K","pt":1657540273665,"mc":[{"id":"1.200806927","rc":[{"atl":[[1.14,6.54]],"id":228749}]}]}
{"op":"mcm","clk":"AJ/rqgkAscibCgCzsZ8K","pt":1657540273758,"mc":[{"id":"1.200806927","rc":[{"atl":[[1.12,648.16]],"id":228749}]}]}
{"op":"mcm","clk":"AKbrqgkAusibCgC5sZ8K","pt":1657540273859,"mc":[{"id":"1.200806927","rc":[{"atl":[[1.11,56.03]],"id":228749}]}]}
{"op":"mcm","clk":"ANnrqgkA88ibCgDfsZ8K","pt":1657540274492,"mc":[{"id":"1.200806927","rc":[{"atl":[[1.13,435.3],[1.11,53.4]],"trd":[[1.11,776.08]],"tv":57485.46,"id":228749}],"tv":62397.08}]}
{"op":"mcm","clk":"AP/rqgkAqMmbCgCGsp8K","pt":1657540274968,"mc":[{"id":"1.200806927","rc":[{"atb":[[10,0]],"id":2857977}]}]}
{"op":"mcm","clk":"ANjsqgkAlcqbCgC5sp8K","pt":1657540275952,"mc":[{"id":"1.200806927","rc":[{"atl":[[1.12,286.83]],"id":228749}]}]}
{"op":"mcm","clk":"AMbtqgkAqcubCgCMs58K","pt":1657540277366,"mc":[{"id":"1.200806927","rc":[{"atl":[[12,0.72]],"id":2857977}]}]}
{"op":"mcm","clk":"AIPuqgkA8subCgCzs58K","pt":1657540278086,"mc":[{"id":"1.200806927","rc":[{"atb":[[1.1,165.91]],"trd":[[1.1,103.76]],"ltp":1.1,"tv":57527.54,"id":228749}],"tv":62439.16}]}
{"op":"mcm","clk":"ANPuqgkAzcybCgDls58K","pt":1657540278876,"mc":[{"id":"1.200806927","rc":[{"atl":[[1.11,52.87]],"trd":[[1.11,777.14]],"ltp":1.11,"tv":57528.6,"id":228749}],"tv":62440.22}]}
{"op":"mcm","clk":"AKzvqgkAu82bCgCQtJ8K","pt":1657540279777,"mc":[{"id":"1.200806927","rc":[{"atl":[[1.11,51.5]],"trd":[[1.11,779.88]],"tv":57531.34,"id":228749}],"tv":62442.96}]}
{"op":"mcm","clk":"AO7vqgkAoc6bCgDEtJ8K","pt":1657540280598,"mc":[{"id":"1.200806927","rc":[{"atl":[[1.11,46.24]],"trd":[[1.11,790.4]],"tv":57541.86,"id":228749}],"tv":62453.48}]}
{"op":"mcm","clk":"AKDwqgkA286bCgDotJ8K","pt":1657540281099,"mc":[{"id":"1.200806927","rc":[{"atb":[[1.1,155.39]],"trd":[[1.1,124.8]],"ltp":1.1,"tv":57562.9,"id":228749}],"tv":62474.52}]}
{"op":"mcm","clk":"AKbwqgkA5s6bCgDutJ8K","pt":1657540281186,"mc":[{"id":"1.200806927","rc":[{"atl":[[1.11,45.28]],"trd":[[1.11,791.36]],"ltp":1.11,"tv":57563.86,"id":228749},{"trd":[[10,1.89]],"tv":4911.73,"id":2857977}],"tv":62475.59}]}
{"op":"mcm","clk":"ALHwqgkA9M6bCgD3tJ8K","pt":1657540281295,"mc":[{"id":"1.200806927","rc":[{"atl":[[1.11,0]],"trd":[[1.11,836.64]],"tv":57609.14,"id":228749},{"atl":[[10,205.34]],"trd":[[10,6.92]],"tv":4916.76,"id":2857977}],"tv":62525.9}]}
{"op":"mcm","clk":"ANHwqgkAlc+bCgCEtZ8K","pt":1657540281588,"mc":[{"id":"1.200806927","rc":[{"atl":[[10,206.11]],"id":2857977}]}]}
{"op":"mcm","clk":"AJfxqgkA3s+bCgCntZ8K","pt":1657540282303,"mc":[{"id":"1.200806927","rc":[{"atb":[[1.11,8]],"id":228749}]}]}
{"op":"mcm","clk":"AKzxqgkA9s+bCgCxtZ8K","pt":1657540282491,"mc":[{"id":"1.200806927","rc":[{"atl":[[10,233.8]],"id":2857977}]}]}
{"op":"mcm","clk":"AMjxqgkAkdCbCgDAtZ8K","pt":1657540282767,"mc":[{"id":"1.200806927","rc":[{"atl":[[10,233.9]],"id":2857977}]}]}
{"op":"mcm","clk":"APTxqgkAy9CbCgDctZ8K","pt":1657540283306,"mc":[{"id":"1.200806927","rc":[{"atl":[[10,234.22]],"id":2857977}]}]}
{"op":"mcm","clk":"AMjzqgkAuNKbCgDKtp8K","pt":1657540285483,"mc":[{"id":"1.200806927","rc":[{"atb":[[1.11,0]],"trd":[[1.11,974.08]],"tv":57746.58,"id":228749},{"atl":[[10,220.74]],"trd":[[10,20.4]],"tv":4930.24,"id":2857977}],"tv":62676.82}]}
{"op":"mcm","clk":"AIr1qgkAm9SbCgC4t58K","pt":1657540287279,"mc":[{"id":"1.200806927","rc":[{"trd":[[1.11,974.97]],"tv":57747.47,"id":228749},{"atl":[[10,220.64]],"trd":[[10,20.5]],"tv":4930.34,"id":2857977}],"tv":62677.81}]}
{"op":"mcm","clk":"AMf1qgkA5dSbCgDat58K","pt":1657540287891,"mc":[{"id":"1.200806927","rc":[{"atl":[[10,220.86]],"id":2857977}]}]}
{"op":"mcm","clk":"AOH1qgkAjdWbCgDrt58K","pt":1657540288208,"mc":[{"id":"1.200806927","rc":[{"atl":[[10,218.86]],"id":2857977}]}]}
{"op":"mcm","clk":"ALL2qgkA9NWbCgCVuJ8K","pt":1657540289098,"mc":[{"id":"1.200806927","rc":[{"atb":[[1.11,2.63]],"id":228749}]}]}
{"op":"mcm","clk":"AMr2qgkAktabCgCiuJ8K","pt":1657540289368,"mc":[{"id":"1.200806927","rc":[{"atb":[[1.11,7.15]],"id":228749},{"atl":[[10,219.39]],"id":2857977}]}]}
{"op":"mcm","clk":"AN72qgkAqNabCgCruJ8K","pt":1657540289593,"mc":[{"id":"1.200806927","rc":[{"atb":[[1.11,8.11]],"id":228749}]}]}
{"op":"mcm","clk":"AOb2qgkAs9abCgCuuJ8K","pt":1657540289704,"mc":[{"id":"1.200806927","rc":[{"atb":[[1.1,154.76]],"id":228749}]}]}
{"op":"mcm","clk":"AO32qgkAvdabCgCxuJ8K","pt":1657540289799,"mc":[{"id":"1.200806927","rc":[{"atb":[[1.11,0]],"trd":[[1.11,1083.09]],"tv":57855.59,"id":228749},{"atl":[[10,209.19]],"trd":[[10,30.7]],"tv":4940.54,"id":2857977}],"tv":62796.13}]}
{"op":"mcm","clk":"AJ/3qgkA/tabCgDLuJ8K","pt":1657540290409,"mc":[{"id":"1.200806927","rc":[{"atl":[[1.12,186.83]],"trd":[[1.12,12260.21]],"ltp":1.12,"tv":58055.59,"id":228749}],"tv":62996.13}]}
{"op":"mcm","clk":"ALb3qgkAm9ebCgDYuJ8K","pt":1657540290676,"mc":[{"id":"1.200806927","rc":[{"trd":[[1.11,1087.3]],"ltp":1.11,"tv":58059.8,"id":228749},{"atl":[[10,208.72]],"trd":[[10,31.17]],"tv":4941.01,"id":2857977}],"tv":63000.81}]}
{"op":"mcm","clk":"ALr3qgkApdebCgDfuJ8K","pt":1657540290768,"mc":[{"id":"1.200806927","rc":[{"atl":[[10,210.82]],"id":2857977}]}]}
{"op":"mcm","clk":"AMb3qgkAtNebCgDkuJ8K","pt":1657540290894,"mc":[{"id":"1.200806927","rc":[{"atl":[[1000,0.25]],"id":228749}]}]}
{"op":"mcm","clk":"ANz3qgkA1debCgD4uJ8K","pt":1657540291199,"mc":[{"id":"1.200806927","rc":[{"atb":[[1.09,252.34]],"id":228749}]}]}
{"op":"mcm","clk":"AOP3qgkA5debCgCAuZ8K","pt":1657540291303,"mc":[{"id":"1.200806927","rc":[{"atl":[[1000,0.13]],"id":228749}]}]}
{"op":"mcm","clk":"ALX4qgkAudibCgC5uZ8K","pt":1657540292213,"mc":[{"id":"1.200806927","rc":[{"atb":[[1.11,0.53]],"id":228749}]}]}
{"op":"mcm","clk":"AMD5qgkAgdqbCgCeup8K","pt":1657540294114,"mc":[{"id":"1.200806927","rc":[{"atl":[[1.12,184.58]],"id":228749}]}]}
{"op":"mcm","clk":"ALr6qgkAstubCgDuup8K","pt":1657540295718,"mc":[{"id":"1.200806927","rc":[{"atb":[[1.11,0]],"trd":[[1.11,1089.83]],"tv":58062.33,"id":228749},{"atl":[[10,210.66]],"trd":[[10,31.33]],"tv":4941.17,"id":2857977}],"tv":63003.5}]}
{"op":"mcm","clk":"AMX6qgkAzdubCgD2up8K","pt":1657540295883,"mc":[{"id":"1.200806927","rc":[{"atl":[[1.12,785.69]],"id":228749}]}]}
{"op":"mcm","clk":"AOL6qgkA8NubCgCMu58K","pt":1657540296297,"mc":[{"id":"1.200806927","rc":[{"atb":[[1.07,417.35]],"id":228749}]}]}
{"op":"mcm","clk":"AOv6qgkA/dubCgCUu58K","pt":1657540296403,"mc":[{"id":"1.200806927","rc":[{"atl":[[1.12,784.27]],"trd":[[1.11,1089.95],[1.12,12261.63]],"tv":58063.87,"id":228749},{"atl":[[10,210.65]],"trd":[[9.2,1084.74],[10,31.34]],"tv":4941.36,"id":2857977}],"tv":63005.23}]}
{"op":"mcm","clk":"AKf7qgkAtNybCgC3u58K","pt":1657540297125,"mc":[{"id":"1.200806927","rc":[{"atb":[[1.11,52.59]],"id":228749}]}]}
{"op":"mcm","clk":"AK77qgkAvdybCgC9u58K","pt":1657540297225,"mc":[{"id":"1.200806927","rc":[{"atl":[[1.12,730.62]],"trd":[[1.12,12262.69]],"ltp":1.12,"tv":58064.93,"id":228749},{"trd":[[9.2,1084.86]],"ltp":9.2,"tv":4941.48,"id":2857977}],"tv":63006.41}]}
{"op":"mcm","clk":"AND7qgkA5tybCgDWu58K","pt":1657540297607,"mc":[{"id":"1.200806927","rc":[{"atl":[[2,1.51]],"id":228749}]}]}
{"op":"mcm","clk":"APH7qgkAl92bCgDvu58K","pt":1657540298017,"mc":[{"id":"1.200806927","rc":[{"atl":[[1.12,729.2]],"trd":[[1.12,12264.11]],"tv":58066.35,"id":228749},{"trd":[[9.2,1085.04]],"tv":4941.66,"id":2857977}],"tv":63008.01}]}
{"op":"mcm","clk":"AJX8qgkAw92bCgD/u58K","pt":1657540298423,"mc":[{"id":"1.200806927","rc":[{"atl":[[10,421.02]],"id":2857977}]}]}
{"op":"mcm","clk":"APj8qgkAyt6bCgC/vJ8K","pt":1657540299738,"mc":[{"id":"1.200806927","rc":[{"atl":[[1.12,711.95]],"trd":[[1.12,12281.36]],"tv":58083.6,"id":228749},{"trd":[[9.2,1087.14]],"tv":4943.76,"id":2857977}],"tv":63027.36}]}
{"op":"mcm","clk":"AM79qgkAxd+bCgCGvZ8K","pt":1657540301030,"mc":[{"id":"1.200806927","rc":[{"atl":[[1.12,922.32]],"id":228749}]}]}
{"op":"mcm","clk":"ANP9qgkAzt+bCgCLvZ8K","pt":1657540301142,"mc":[{"id":"1.200806927","rc":[{"atl":[[1.12,920.55]],"trd":[[1.12,12283.13]],"tv":58085.37,"id":228749},{"trd":[[9.2,1087.35]],"tv":4943.97,"id":2857977}],"tv":63029.34}]}
{"op":"mcm","clk":"AO/9qgkA89+bCgCYvZ8K","pt":1657540301520,"mc":[{"id":"1.200806927","rc":[{"atl":[[1.12,914.76]],"id":228749}]}]}
{"op":"mcm","clk":"AIn+qgkAjeCbCgCivZ8K","pt":1657540301815,"mc":[{"id":"1.200806927","rc":[{"atb":[[1.04,2.89]],"id":228749}]}]}
{"op":"mcm","clk":"AJT+qgkAl+CbCgCmvZ8K","pt":1657540301929,"mc":[{"id":"1.200806927","rc":[{"atl":[[1.12,904]],"trd":[[1.12,12293.89]],"tv":58096.13,"id":228749},{"trd":[[9.2,1088.66]],"tv":4945.28,"id":2857977}],"tv":63041.41}]}
{"op":"mcm","clk":"AKf+qgkArOCbCgCtvZ8K","pt":1657540302133,"mc":[{"id":"1.200806927","rc":[{"atb":[[1.11,54.66]],"id":228749}]}]}
{"op":"mcm","clk":"AI3/qgkAq+GbCgDlvZ8K","pt":1657540303439,"mc":[{"id":"1.200806927","rc":[{"atl":[[10,420.8]],"id":2857977}]}]}
{"op":"mcm","clk":"AMb/qgkA+OGbCgCJvp8K","pt":1657540304219,"mc":[{"id":"1.200806927","rc":[{"atl":[[1.12,900.81]],"trd":[[1.12,12297.08]],"tv":58099.32,"id":228749},{"trd":[[9.2,1089.05]],"tv":4945.67,"id":2857977}],"tv":63044.99}]}
{"op":"mcm","clk":"ANT/qgkAi+KbCgCQvp8K","pt":1657540304415,"mc":[{"id":"1.200806927","rc":[{"atl":[[1.12,895.55]],"id":228749}]}]}
{"op":"mcm","clk":"AOj/qgkAm+KbCgCdvp8K","pt":1657540304626,"mc":[{"id":"1.200806927","rc":[{"atl":[[1.12,873.29]],"trd":[[1.12,12319.34]],"tv":58121.58,"id":228749},{"trd":[[9.2,1091.76]],"tv":4948.38,"id":2857977}],"tv":63069.96}]}
{"op":"mcm","clk":"APuAqwkA5uObCgCFv58K","pt":1657540306424,"mc":[{"id":"1.200806927","rc":[{"atl":[[1.12,872.34]],"id":228749}]}]}
{"op":"mcm","clk":"AJeBqwkAjuSbCgCdv58K","pt":1657540306734,"mc":[{"id":"1.200806927","rc":[{"atl":[[1.12,859.72]],"id":228749}]}]}
{"op":"mcm","clk":"AJ6BqwkAneSbCgClv58K","pt":1657540306847,"mc":[{"id":"1.200806927","rc":[{"atl":[[1.12,858.9]],"trd":[[1.12,12320.16]],"tv":58122.4,"id":228749},{"trd":[[9.2,1091.86]],"tv":4948.48,"id":2857977}],"tv":63070.88}]}
{"op":"mcm","clk":"ALWBqwkAwuSbCgC0v58K","pt":1657540307200,"mc":[{"id":"1.200806927","rc":[{"atb":[[1.04,3.05]],"id":228749}]}]}
{"op":"mcm","clk":"AMKBqwkAy+SbCgC7v58K","pt":1657540307305,"mc":[{"id":"1.200806927","rc":[{"atl":[[1.12,858.08]],"trd":[[1.12,12320.98]],"tv":58123.22,"id":228749},{"trd":[[9.2,1091.96]],"tv":4948.58,"id":2857977}],"tv":63071.8}]}
{"op":"mcm","clk":"AMiBqwkA1eSbCgDCv58K","pt":1657540307414,"mc":[{"id":"1.200806927","rc":[{"atl":[[1.12,852.82]],"id":228749}]}]}
{"op":"mcm","clk":"ANCBqwkA5uSbCgDNv58K","pt":1657540307596,"mc":[{"id":"1.200806927","rc":[{"atb":[[1.04,2.89]],"atl":[[1.12,851.24]],"id":228749}]}]}
{"op":"mcm","clk":"AKGCqwkAzOWbCgCEwJ8K","pt":1657540308508,"mc":[{"id":"1.200806927","rc":[{"atl":[[1.12,980.68]],"id":228749}]}]}
{"op":"mcm","clk":"AKWCqwkA1OWbCgCLwJ8K","pt":1657540308600,"mc":[{"id":"1.200806927","rc":[{"atb":[[1.1,155.2]],"id":228749}]}]}
{"op":"mcm","clk":"AP2CqwkA2+abCgDZwJ8K","pt":1657540309781,"mc":[{"id":"1.200806927","rc":[{"atl":[[1.12,979.86]],"trd":[[1.12,12321.8]],"tv":58124.04,"id":228749},{"trd":[[9.2,1092.06]],"tv":4948.68,"id":2857977}],"tv":63072.72}]}
{"op":"mcm","clk":"AIWDqwkA5eabCgDhwJ8K","pt":1657540309902,"mc":[{"id":"1.200806927","rc":[{"atb":[[1.11,52.59]],"id":228749}]}]}
{"op":"mcm","clk":"AJ6DqwkAhOebCgD1wJ8K","pt":1657540310177,"mc":[{"id":"1.200806927","rc":[{"atl":[[1.12,979.04]],"trd":[[1.12,12322.62]],"tv":58124.86,"id":228749},{"trd":[[9.2,1092.16]],"tv":4948.78,"id":2857977}],"tv":63073.64}]}
{"op":"mcm","clk":"ANyDqwkA0eebCgCrwZ8K","pt":1657540311006,"mc":[{"id":"1.200806927","rc":[{"atl":[[10,420.7]],"id":2857977}]}]}
{"op":"mcm","clk":"APqDqwkA++ebCgDCwZ8K","pt":1657540311392,"mc":[{"id":"1.200806927","rc":[{"atl":[[10,631.07]],"id":2857977}]}]}
{"op":"mcm","clk":"AI2EqwkAmOibCgDQwZ8K","pt":1657540311686,"mc":[{"id":"1.200806927","rc":[{"atl":[[1.12,978.84]],"trd":[[1.12,12323.02]],"tv":58125.26,"id":228749}],"tv":63074.04}]}
{"op":"mcm","clk":"ANeEqwkAgembCgCKwp8K","pt":1657540312704,"mc":[{"id":"1.200806927","rc":[{"atl":[[1.12,978.67]],"trd":[[1.12,12323.36]],"tv":58125.6,"id":228749}],"tv":63074.38}]}
{"op":"mcm","clk":"AOyEqwkApembCgCbwp8K","pt":1657540313094,"mc":[{"id":"1.200806927","rc":[{"atb":[[1.04,2.05]],"id":228749}]}]}
{"op":"mcm","clk":"AKyFqwkA6umbCgDLwp8K","pt":1657540313784,"mc":[{"id":"1.200806927","rc":[{"atl":[[1.12,976.04]],"id":228749}]}]}
{"op":"mcm","clk":"AMiFqwkAleqbCgDkwp8K","pt":1657540314187,"mc":[{"id":"1.200806927","rc":[{"atl":[[1.12,974.46]],"id":228749}]}]}
{"op":"mcm","clk":"AN6FqwkAv+qbCgD4wp8K","pt":1657540314517,"mc":[{"id":"1.200806927","rc":[{"atl":[[1.12,970.92]],"trd":[[1.12,12326.9]],"tv":58129.14,"id":228749},{"trd":[[9.2,1092.59]],"tv":4949.21,"id":2857977}],"tv":63078.35}]}
{"op":"mcm","clk":"AKyGqwkAtuubCgCxw58K","pt":1657540315605,"mc":[{"id":"1.200806927","rc":[{"atb":[[1.11,4.21]],"trd":[[1.11,3364.54]],"ltp":1.11,"tv":60403.73,"id":228749},{"atl":[[10,390.26]],"trd":[[10,272.14]],"ltp":10,"tv":5190.01,"id":2857977}],"tv":65593.74}]}
{"op":"mcm","clk":"AOyGqwkAmeybCgDhw58K","pt":1657540316491,"mc":[{"id":"1.200806927","rc":[{"atl":[[1.12,945.37]],"trd":[[1.12,12352.45]],"ltp":1.12,"tv":60429.28,"id":228749},{"trd":[[9.2,1095.7]],"ltp":9.2,"tv":5193.12,"id":2857977}],"tv":65622.4}]}
{"op":"mcm","clk":"APeGqwkArOybCgDow58K","pt":1657540316695,"mc":[{"id":"1.200806927","rc":[{"atl":[[1.12,949.58]],"id":228749}]}]}
{"op":"mcm","clk":"ALuHqwkAmO2bCgCdxJ8K","pt":1657540317894,"mc":[{"id":"1.200806927","rc":[{"atl":[[1.12,948.76]],"trd":[[1.12,12353.27]],"tv":60430.1,"id":228749},{"trd":[[9.2,1095.8]],"tv":5193.22,"id":2857977}],"tv":65623.32}]}
{"op":"mcm","clk":"ALSIqwkAwu6bCgCVxZ8K","pt":1657540319904,"mc":[{"id":"1.200806927","rc":[{"atl":[[10,390.37]],"id":2857977}]}]}
{"op":"mcm","clk":"AM+IqwkA8u6bCgCpxZ8K","pt":1657540320340,"mc":[{"id":"1.200806927","rc":[{"atl":[[1.12,944.41]],"trd":[[1.12,12357.62]],"tv":60434.45,"id":228749},{"trd":[[9.2,1096.33]],"tv":5193.75,"id":2857977}],"tv":65628.2}]}
{"op":"mcm","clk":"AN6IqwkAiO+bCgC0xZ8K","pt":1657540320530,"mc":[{"id":"1.200806927","rc":[{"atl":[[1.12,943.53]],"trd":[[1.12,12358.5]],"tv":60435.33,"id":228749},{"trd":[[9.2,1096.44]],"tv":5193.86,"id":2857977}],"tv":65629.19}]}
{"op":"mcm","clk":"AIeJqwkAze+bCgDMxZ8K","pt":1657540321114,"mc":[{"id":"1.200806927","rc":[{"atb":[[9.8,1.67]],"id":2857977}]}]}
{"op":"mcm","clk":"AI6JqwkA2u+bCgDRxZ8K","pt":1657540321223,"mc":[{"id":"1.200806927","rc":[{"atl":[[1.13,382.71]],"id":228749}]}]}
{"op":"mcm","clk":"AJiJqwkA9O+bCgDexZ8K","pt":1657540321415,"mc":[{"id":"1.200806927","rc":[{"atb":[[1.11,0]],"trd":[[1.11,3576.75]],"ltp":1.11,"tv":60647.54,"id":228749},{"atl":[[10,367.75]],"trd":[[10,294.76]],"ltp":10,"tv":5216.48,"id":2857977}],"tv":65864.02}]}
{"op":"mcm","clk":"AKCJqwkAgvCbCgDkxZ8K","pt":1657540321532,"mc":[{"id":"1.200806927","rc":[{"trd":[[1.11,3787.12]],"tv":60857.91,"id":228749},{"atl":[[10,344.4]],"trd":[[10,318.11]],"tv":5239.83,"id":2857977}],"tv":66097.74}]}
{"op":"mcm","clk":"ALiJqwkAs/CbCgD+xZ8K","pt":1657540321843,"mc":[{"id":"1.200806927","rc":[{"atl":[[1.12,1072.97]],"id":228749}]}]}
{"op":"mcm","clk":"ANyJqwkA+vCbCgCbxp8K","pt":1657540322324,"mc":[{"id":"1.200806927","rc":[{"atl":[[10,554.77]],"id":2857977}]}]}
{"op":"mcm","clk":"AIWKqwkAv/GbCgC9xp8K","pt":1657540322899,"mc":[{"id":"1.200806927","rc":[{"atl":[[1.12,1071.92]],"id":228749}]}]}
{"op":"mcm","clk":"AIyKqwkAy/GbCgDFxp8K","pt":1657540322997,"mc":[{"id":"1.200806927","rc":[{"atl":[[1.12,1071.39]],"trd":[[1.11,4688.74]],"tv":61759.53,"id":228749},{"atl":[[10,454.69]],"trd":[[10,418.19]],"tv":5339.91,"id":2857977}],"tv":67099.44}]}
{"op":"mcm","clk":"AKKKqwkA8/GbCgDZxp8K","pt":1657540323309,"mc":[{"id":"1.200806927","rc":[{"atl":[[1.12,1070.34]],"id":228749}]}]}
{"op":"mcm","clk":"ALaKqwkAjPKbCgDoxp8K","pt":1657540323527,"mc":[{"id":"1.200806927","rc":[{"atl":[[1000,0.25]],"id":228749}]}]}
{"op":"mcm","clk":"AMaKqwkApPKbCgD1xp8K","pt":1657540323744,"mc":[{"id":"1.200806927","rc":[{"atl":[[1.16,638.93]],"id":228749}]}]}
{"op":"mcm","clk":"AOKKqwkAyPKbCgCLx58K","pt":1657540324052,"mc":[{"id":"1.200806927","rc":[{"atl":[[1000,0.13]],"id":228749}]}]}
{"op":"mcm","clk":"APuKqwkA1fKbCgCcx58K","pt":1657540324300,"mc":[{"id":"1.200806927","rc":[{"atb":[[1.1,655.2]],"id":228749}]}]}
{"op":"mcm","clk":"AJWLqwkAlfObCgCyx58K","pt":1657540324626,"mc":[{"id":"1.200806927","rc":[{"atb":[[1.09,752.34]],"id":228749}]}]}
{"op":"mcm","clk":"AKaLqwkArPObCgDAx58K","pt":1657540324828,"mc":[{"id":"1.200806927","rc":[{"trd":[[1.11,4693.04]],"tv":61763.83,"id":228749},{"atl":[[10,454.21]],"trd":[[10,418.67]],"tv":5340.39,"id":2857977}],"tv":67104.22}]}
{"op":"mcm","clk":"ALiLqwkAxPObCgDNx58K","pt":1657540325056,"mc":[{"id":"1.200806927","rc":[{"atl":[[1.12,1065.08]],"id":228749},{"atb":[[9.8,0]],"id":2857977}]}]}
{"op":"mcm","clk":"APKLqwkAjfSbCgDwx58K","pt":1657540325730,"mc":[{"id":"1.200806927","rc":[{"trd":[[1.11,4714.97]],"tv":61785.76,"id":228749},{"atl":[[10,451.78]],"trd":[[10,421.1]],"tv":5342.82,"id":2857977}],"tv":67128.58}]}
{"op":"mcm","clk":"APeLqwkAlfSbCgD3x58K","pt":1657540325867,"mc":[{"id":"1.200806927","rc":[{"trd":[[1.11,5316.08]],"tv":62386.87,"id":228749},{"atl":[[10,385.06]],"trd":[[10,487.82]],"tv":5409.54,"id":2857977}],"tv":67796.41}]}
{"op":"mcm","clk":"AJqMqwkAxfSbCgCNyJ8K","pt":1657540326345,"mc":[{"id":"1.200806927","rc":[{"trd":[[1.11,5316.61]],"tv":62387.4,"id":228749},{"atl":[[10,385]],"trd":[[10,487.88]],"tv":5409.6,"id":2857977}],"tv":67797}]}
{"op":"mcm","clk":"AMiMqwkAnfWbCgDEyJ8K","pt":1657540327020,"mc":[{"id":"1.200806927","rc":[{"trd":[[1.11,5446.05]],"tv":62516.84,"id":228749},{"atl":[[10,370.63]],"trd":[[10,502.25]],"tv":5423.97,"id":2857977}],"tv":67940.81}]}
{"op":"mcm","clk":"AOyMqwkA1/WbCgDhyJ8K","pt":1657540327532,"mc":[{"id":"1.200806927","rc":[{"atl":[[1.12,1059.82]],"id":228749}]}]}
{"op":"mcm","clk":"AIiNqwkAhfabCgDyyJ8K","pt":1657540327904,"mc":[{"id":"1.200806927","rc":[{"atl":[[1.12,1046.34]],"id":228749}]}]}
{"op":"mcm","clk":"ALiNqwkA1/abCgCkyZ8K","pt":1657540328746,"mc":[{"id":"1.200806927","rc":[{"atl":[[1.12,1033.36]],"trd":[[1.12,12371.48]],"ltp":1.12,"tv":62529.82,"id":228749},{"trd":[[9.2,1098.02]],"ltp":9.2,"tv":5425.55,"id":2857977}],"tv":67955.37}]}
{"op":"mcm","clk":"AL6NqwkA4vabCgCryZ8K","pt":1657540328840,"mc":[{"id":"1.200806927","rc":[{"trd":[[1.11,5579.05]],"ltp":1.11,"tv":62662.82,"id":228749},{"atl":[[10,355.87]],"trd":[[10,517.01]],"ltp":10,"tv":5440.31,"id":2857977}],"tv":68103.13}]}
{"op":"mcm","clk":"ANCNqwkAhPebCgC9yZ8K","pt":1657540329122,"mc":[{"id":"1.200806927","rc":[{"trd":[[1.11,5579.18]],"tv":62662.95,"id":228749},{"atl":[[10,355.86]],"trd":[[10,517.02]],"tv":5440.32,"id":2857977}],"tv":68103.27}]}
{"op":"mcm","clk":"APCOqwkA9/ibCgDayp8K","pt":1657540331531,"mc":[{"id":"1.200806927","rc":[{"atl":[[1.12,1032.93]],"trd":[[1.12,12372.34]],"ltp":1.12,"tv":62663.81,"id":228749}],"tv":68104.13}]}
{"op":"mcm","clk":"AI+PqwkAo/mbCgDwyp8K","pt":1657540331931,"mc":[{"id":"1.200806927","rc":[{"atl":[[1.12,1031.21]],"trd":[[1.12,12375.78]],"tv":62667.25,"id":228749}],"tv":68107.57}]}
{"op":"mcm","clk":"AJaPqwkArvmbCgD2yp8K","pt":1657540332026,"mc":[{"id":"1.200806927","rc":[{"trd":[[1.11,5786.29]],"ltp":1.11,"tv":62874.36,"id":228749},{"atl":[[10,332.87]],"trd":[[10,540.01]],"tv":5463.31,"id":2857977}],"tv":68337.67}]}
{"op":"mcm","clk":"AMKPqwkA//mbCgCby58K","pt":1657540332642,"mc":[{"id":"1.200806927","rc":[{"atl":[[1.12,1004.91]],"id":228749}]}]}
{"op":"mcm","clk":"AJqQqwkAg/ubCgDTy58K","pt":1657540333862,"mc":[{"id":"1.200806927","rc":[{"trd":[[1.11,5791.55]],"tv":62879.62,"id":228749},{"atl":[[10,332.29]],"trd":[[10,540.59]],"tv":5463.89,"id":2857977}],"tv":68343.51}]}
{"op":"mcm","clk":"ALaQqwkAq/ubCgDyy58K","pt":1657540334074,"mc":[{"id":"1.200806927","rc":[{"atl":[[10,542.66]],"id":2857977}]}]}
{"op":"mcm","clk":"ANGQqwkA0/ubCgCGzJ8K","pt":1657540334425,"mc":[{"id":"1.200806927","rc":[{"atl":[[1.12,1000.56]],"trd":[[1.11,5999.55],[1.12,12380.13]],"tv":63091.97,"id":228749},{"atl":[[10,519.57]],"trd":[[9.2,1098.55],[10,563.68]],"tv":5487.51,"id":2857977}],"tv":68579.48}]}
{"op":"mcm","clk":"ANiQqwkA4/ubCgCLzJ8K","pt":1657540334530,"mc":[{"id":"1.200806927","rc":[{"atb":[[1.04,2.89]],"id":228749}]}]}
{"op":"mcm","clk":"APeQqwkAivybCgCqzJ8K","pt":1657540334936,"mc":[{"id":"1.200806927","rc":[{"trd":[[1.11,6052.14]],"tv":63144.56,"id":228749},{"atl":[[10,513.73]],"trd":[[10,569.52]],"tv":5493.35,"id":2857977}],"tv":68637.91}]}
{"op":"mcm","clk":"AKKRqwkAxvybCgDKzJ8K","pt":1657540335485,"mc":[{"id":"1.200806927","rc":[{"trd":[[1.11,6183.62]],"tv":63276.04,"id":228749},{"atl":[[10,499.14]],"trd":[[10,584.11]],"tv":5507.94,"id":2857977}],"tv":68783.98}]}
{"op":"mcm","clk":"AOqRqwkAm/2bCgD8zJ8K","pt":1657540336247,"mc":[{"id":"1.200806927","rc":[{"atl":[[1.39,2.63]],"id":228749}]}]}
{"op":"mcm","clk":"AP2RqwkAsf2bCgCNzZ8K","pt":1657540336458,"mc":[{"id":"1.200806927","rc":[{"atl":[[1.12,961.13]],"trd":[[1.12,12419.56]],"ltp":1.12,"tv":63315.47,"id":228749},{"trd":[[9.2,1103.35]],"ltp":9.2,"tv":5512.74,"id":2857977}],"tv":68828.21}]}
{"op":"mcm","clk":"AICSqwkAvP2bCgCTzZ8K","pt":1657540336560,"mc":[{"id":"1.200806927","rc":[{"atl":[[1.12,957.55]],"trd":[[1.12,12423.14]],"tv":63319.05,"id":228749},{"trd":[[9.2,1103.78]],"tv":5513.17,"id":2857977}],"tv":68832.22}]}
{"op":"mcm","clk":"APGSqwkA4/6bCgDwzZ8K","pt":1657540337863,"mc":[{"id":"1.200806927","rc":[{"atl":[[1.12,955.97]],"id":228749}]}]}
{"op":"mcm","clk":"AIOTqwkAhv+bCgCBzp8K","pt":1657540338149,"mc":[{"id":"1.200806927","rc":[{"atl":[[1.12,954.92]],"id":228749}]}]}
{"op":"mcm","clk":"AKiTqwkAuv+bCgCbzp8K","pt":1657540338642,"mc":[{"id":"1.200806927","rc":[{"trd":[[1.11,6315.16]],"ltp":1.11,"tv":63450.59,"id":228749},{"atl":[[10,484.54]],"trd":[[10,598.71]],"ltp":10,"tv":5527.77,"id":2857977}],"tv":68978.36}]}
{"op":"mcm","clk":"AM+TqwkA/P+bCgC5zp8K","pt":1657540339262,"mc":[{"id":"1.200806927","rc":[{"trd":[[1.11,6916.27]],"tv":64051.7,"id":228749},{"atl":[[10,417.81]],"trd":[[10,665.44]],"tv":5594.5,"id":2857977}],"tv":69646.2}]}
{"op":"mcm","clk":"AICUqwkA0oCcCgDdzp8K","pt":1657540339946,"mc":[{"id":"1.200806927","rc":[{"atb":[[1.04,3.05]],"id":228749}]}]}
{"op":"mcm","clk":"AIaUqwkA3YCcCgDgzp8K","pt":1657540340055,"mc":[{"id":"1.200806927","rc":[{"atl":[[1.12,954.39]],"id":228749}]}]}
{"op":"mcm","clk":"AJiUqwkAh4GcCgDwzp8K","pt":1657540340344,"mc":[{"id":"1.200806927","rc":[{"atb":[[1.04,2.89]],"id":228749}]}]}
{"op":"mcm","clk":"AKaUqwkApIGcCgD5zp8K","pt":1657540340534,"mc":[{"id":"1.200806927","rc":[{"atl":[[1.12,953.86]],"id":228749}]}]}
{"op":"mcm","clk":"AK6UqwkAsoGcCgD9zp8K","pt":1657540340641,"mc":[{"id":"1.200806927","rc":[{"atl":[[1.12,952.09]],"trd":[[1.12,12424.91]],"ltp":1.12,"tv":64053.47,"id":228749},{"trd":[[9.2,1104]],"ltp":9.2,"tv":5594.72,"id":2857977}],"tv":69648.19}]}
{"op":"mcm","clk":"AMCVqwkA5IKcCgDZz58K","pt":1657540342469,"mc":[{"id":"1.200806927","rc":[{"trd":[[1.11,6958.35]],"ltp":1.11,"tv":64095.55,"id":228749},{"atl":[[10,413.14]],"trd":[[10,670.11]],"ltp":10,"tv":5599.39,"id":2857977}],"tv":69694.94}]}
{"op":"mcm","clk":"AJCWqwkA2oOcCgCZ0J8K","pt":1657540343659,"mc":[{"id":"1.200806927","rc":[{"atl":[[1.12,951.19]],"trd":[[1.12,12425.81]],"ltp":1.12,"tv":64096.45,"id":228749},{"trd":[[9.2,1104.11]],"ltp":9.2,"tv":5599.5,"id":2857977}],"tv":69695.95}]}
{"op":"mcm","clk":"AM+WqwkAxYScCgDT0J8K","pt":1657540344553,"mc":[{"id":"1.200806927","rc":[{"atl":[[1.12,950.31]],"trd":[[1.12,12426.69]],"tv":64097.33,"id":228749},{"trd":[[9.2,1104.21]],"tv":5599.6,"id":2857977}],"tv":69696.93}]}
{"op":"mcm","clk":"ANaWqwkA0IScCgDX0J8K","pt":1657540344644,"mc":[{"id":"1.200806927","rc":[{"atl":[[10,623.51]],"id":2857977}]}]}
{"op":"mcm","clk":"AJKXqwkAo4WcCgCF0Z8K","pt":1657540345473,"mc":[{"id":"1.200806927","rc":[{"atl":[[1.12,950.14]],"trd":[[1.12,12427.03]],"tv":64097.67,"id":228749}],"tv":69697.27}]}
{"op":"mcm","clk":"ALiXqwkAyYWcCgCc0Z8K","pt":1657540345956,"mc":[{"id":"1.200806927","rc":[{"atb":[[1.04,2.05]],"id":228749}]}]}
{"op":"mcm","clk":"AIGYqwkAp4acCgDR0Z8K","pt":1657540346841,"mc":[{"id":"1.200806927","rc":[{"atl":[[1.12,948.73]],"trd":[[1.12,12427.91]],"tv":64098.55,"id":228749},{"trd":[[9.2,1104.32]],"tv":5599.71,"id":2857977}],"tv":69698.26}]}
{"op":"mcm","clk":"ALGYqwkA6IacCgD20Z8K","pt":1657540347471,"mc":[{"id":"1.200806927","rc":[{"trd":[[1.11,6960.45]],"ltp":1.11,"tv":64100.65,"id":228749},{"atl":[[10,623.28]],"trd":[[10,670.34]],"ltp":10,"tv":5599.94,"id":2857977}],"tv":69700.59}]}
{"op":"mcm","clk":"ALiYqwkA9IacCgD90Z8K","pt":1657540347584,"mc":[{"id":"1.200806927","rc":[{"atl":[[1.12,948.62]],"trd":[[1.12,12428.13]],"ltp":1.12,"tv":64100.87,"id":228749}],"tv":69700.81}]}
{"op":"mcm","clk":"ANaYqwkAqYecCgCW0p8K","pt":1657540348034,"mc":[{"id":"1.200806927","rc":[{"atl":[[1.12,1155.73]],"id":228749}]}]}
{"op":"mcm","clk":"AOyYqwkAyoecCgCr0p8K","pt":1657540348350,"mc":[{"id":"1.200806927","rc":[{"atl":[[1.12,1153.1]],"id":228749}]}]}
{"op":"mcm","clk":"ANqZqwkA8IicCgCM058K","pt":1657540349861,"mc":[{"id":"1.200806927","rc":[{"atl":[[1.12,1151.68]],"trd":[[1.12,12429.55]],"tv":64102.29,"id":228749},{"trd":[[9.2,1104.49]],"ltp":9.2,"tv":5600.11,"id":2857977}],"tv":69702.4}]}
{"op":"mcm","clk":"AOiZqwkAhImcCgCc058K","pt":1657540350072,"mc":[{"id":"1.200806927","rc":[{"trd":[[1.11,7460.45]],"ltp":1.11,"tv":64602.29,"id":228749},{"atl":[[10,567.78]],"trd":[[10,725.84]],"ltp":10,"tv":5655.61,"id":2857977}],"tv":70257.9}]}
{"op":"mcm","clk":"APuZqwkAoYmcCgCr058K","pt":1657540350340,"mc":[{"id":"1.200806927","rc":[{"atl":[[1.12,1147.09]],"trd":[[1.12,12434.14]],"ltp":1.12,"tv":64606.88,"id":228749},{"trd":[[9.2,1105.05]],"ltp":9.2,"tv":5656.17,"id":2857977}],"tv":70263.05}]}
{"op":"mcm","clk":"ALyaqwkAjoqcCgDo058K","pt":1657540351373,"mc":[{"id":"1.200806927","rc":[{"atl":[[1.12,1144.04]],"id":228749}]}]}
{"op":"mcm","clk":"AOCaqwkAtIqcCgD0058K","pt":1657540351737,"mc":[{"id":"1.200806927","rc":[{"atl":[[1.3,135.72]],"id":228749}]}]}
{"op":"mcm","clk":"AOiaqwkAwYqcCgD7058K","pt":1657540351847,"mc":[{"id":"1.200806927","rc":[{"atl":[[1.12,933.67]],"id":228749}]}]}
{"op":"mcm","clk":"APuaqwkA4IqcCgCL1J8K","pt":1657540352164,"mc":[{"id":"1.200806927","rc":[{"trd":[[1.11,7960.45]],"ltp":1.11,"tv":65106.88,"id":228749},{"atl":[[10,512.28]],"trd":[[10,781.34]],"ltp":10,"tv":5711.67,"id":2857977}],"tv":70818.55}]}
{"op":"mcm","clk":"AIObqwkA7YqcCgCT1J8K","pt":1657540352271,"mc":[{"id":"1.200806927","rc":[{"atl":[[1.12,917.89]],"id":228749}]}]}
{"op":"mcm","clk":"AJubqwkAlIucCgCt1J8K","pt":1657540352641,"mc":[{"id":"1.200806927","rc":[{"atl":[[1.12,1417.89]],"id":228749}]}]}
{"op":"mcm","clk":"AKqbqwkAqoucCgC51J8K","pt":1657540352853,"mc":[{"id":"1.200806927","rc":[{"trd":[[1.11,7968.44]],"tv":65114.87,"id":228749},{"atl":[[10,511.39]],"trd":[[10,782.23]],"tv":5712.56,"id":2857977}],"tv":70827.43}]}
{"op":"mcm","clk":"AMGbqwkA04ucCgDR1J8K","pt":1657540353264,"mc":[{"id":"1.200806927","rc":[{"atl":[[1.12,917.89]],"id":228749}]}]}
{"op":"mcm","clk":"ANSbqwkA5YucCgDa1J8K","pt":1657540353476,"mc":[{"id":"1.200806927","rc":[{"trd":[[1.11,7988.44]],"tv":65134.87,"id":228749},{"atl":[[10,509.17]],"trd":[[10,784.45]],"tv":5714.78,"id":2857977}],"tv":70849.65}]}
{"op":"mcm","clk":"AN+bqwkA74ucCgDe1J8K","pt":1657540353581,"mc":[{"id":"1.200806927","rc":[{"atl":[[1.5,185.78],[1.12,917.36]],"id":228749}]}]}
{"op":"mcm","clk":"AI6cqwkAuYycCgCL1Z8K","pt":1657540354260,"mc":[{"id":"1.200806927","rc":[{"atl":[[1.12,882.44]],"trd":[[1.12,12442.76]],"ltp":1.12,"tv":65143.49,"id":228749},{"trd":[[9.2,1106.1]],"ltp":9.2,"tv":5715.83,"id":2857977}],"tv":70859.32}]}
{"op":"mcm","clk":"AKOcqwkA2YycCgCb1Z8K","pt":1657540354561,"mc":[{"id":"1.200806927","rc":[{"atb":[[9.4,12.31]],"trd":[[9.4,1.06]],"ltp":9.4,"tv":5716.89,"id":2857977}],"tv":70860.38}]}
{"op":"mcm","clk":"AKqcqwkA5IycCgCk1Z8K","pt":1657540354673,"mc":[{"id":"1.200806927","rc":[{"atl":[[1.12,882.1]],"trd":[[1.12,12443.44]],"tv":65144.17,"id":228749}],"tv":70861.06}]}
{"op":"mcm","clk":"ANCcqwkAh42cCgC71Z8K","pt":1657540355051,"mc":[{"id":"1.200806927","rc":[{"atb":[[1.1,789.39]],"id":228749}]}]}
{"op":"mcm","clk":"AOKcqwkAmI2cCgDG1Z8K","pt":1657540355260,"mc":[{"id":"1.200806927","rc":[{"trd":[[1.11,8032.3]],"ltp":1.11,"tv":65188.03,"id":228749},{"atl":[[10,714.67]],"trd":[[10,789.32]],"ltp":10,"tv":5721.76,"id":2857977}],"tv":70909.79}]}
{"op":"mcm","clk":"AIKdqwkAvY2cCgDk1Z8K","pt":1657540355686,"mc":[{"id":"1.200806927","rc":[{"trd":[[1.11,8052.3]],"tv":65208.03,"id":228749},{"atl":[[10,712.45]],"trd":[[10,791.54]],"tv":5723.98,"id":2857977}],"tv":70932.01}]}
{"op":"mcm","clk":"AK6dqwkAhY6cCgCH1p8K","pt":1657540356254,"mc":[{"id":"1.200806927","rc":[{"trd":[[1.11,8053.88]],"tv":65209.61,"id":228749},{"atl":[[10,712.27]],"trd":[[10,791.72]],"tv":5724.16,"id":2857977}],"tv":70933.77}]}
{"op":"mcm","clk":"AMWdqwkAsI6cCgCY1p8K","pt":1657540356571,"mc":[{"id":"1.200806927","rc":[{"atb":[[9.4,11.88]],"trd":[[9.4,1.92]],"ltp":9.4,"tv":5725.02,"id":2857977}],"tv":70934.63}]}
{"op":"mcm","clk":"AN2dqwkA046cCgCm1p8K","pt":1657540356879,"mc":[{"id":"1.200806927","rc":[{"trd":[[1.11,8183.32]],"tv":65339.05,"id":228749},{"atl":[[10,697.9]],"trd":[[10,806.09]],"ltp":10,"tv":5739.39,"id":2857977}],"tv":71078.44}]}
{"op":"mcm","clk":"AISeqwkAj4+cCgC71p8K","pt":1657540357359,"mc":[{"id":"1.200806927","rc":[{"atl":[[1000,0.25]],"id":228749}]}]}
{"op":"mcm","clk":"AK2eqwkAuI+cCgDQ1p8K","pt":1657540357763,"mc":[{"id":"1.200806927","rc":[{"atl":[[1000,0.13]],"id":228749}]}]}
{"op":"mcm","clk":"AMieqwkA1Y+cCgDg1p8K","pt":1657540358077,"mc":[{"id":"1.200806927","rc":[{"trd":[[1.11,8784.43]],"tv":65940.16,"id":228749},{"atl":[[10,631.18]],"trd":[[10,872.81]],"tv":5806.11,"id":2857977}],"tv":71746.27}]}
{"op":"mcm","clk":"AP6eqwkAlZCcCgD81p8K","pt":1657540358652,"mc":[{"id":"1.200806927","rc":[{"trd":[[1.11,8787.06]],"tv":65942.79,"id":228749},{"atl":[[10,630.89]],"trd":[[10,873.1]],"tv":5806.4,"id":2857977}],"tv":71749.19}]}
{"op":"mcm","clk":"AIefqwkAn5CcCgCB158K","pt":1657540358759,"mc":[{"id":"1.200806927","rc":[{"trd":[[1.11,8995.06]],"tv":66150.79,"id":228749},{"atl":[[10,607.8]],"trd":[[10,896.19]],"tv":5829.49,"id":2857977}],"tv":71980.28}]}
{"op":"mcm","clk":"AIugqwkAsZGcCgDl158K","pt":1657540360271,"mc":[{"id":"1.200806927","rc":[{"atb":[[1.05,117.68]],"id":228749}]}]}
{"op":"mcm","clk":"AJagqwkAvpGcCgDt158K","pt":1657540360383,"mc":[{"id":"1.200806927","rc":[{"trd":[[1.11,9205.43]],"tv":66361.16,"id":228749},{"atl":[[10,584.45]],"trd":[[10,919.54]],"tv":5852.84,"id":2857977}],"tv":72214}]}
{"op":"mcm","clk":"AKmgqwkA4ZGcCgD7158K","pt":1657540360688,"mc":[{"id":"1.200806927","rc":[{"trd":[[1.11,11705.43]],"tv":68861.16,"id":228749},{"atl":[[10,306.95]],"trd":[[10,1197.04]],"tv":6130.34,"id":2857977}],"tv":74991.5}]}
{"op":"mcm","clk":"AOGgqwkAuJKcCgCm2J8K","pt":1657540361472,"mc":[{"id":"1.200806927","rc":[{"trd":[[1.11,11915.8]],"tv":69071.53,"id":228749},{"atl":[[10,283.6]],"trd":[[10,1220.39]],"tv":6153.69,"id":2857977}],"tv":75225.22}]}
{"op":"mcm","clk":"AJahqwkA+5KcCgDN2J8K","pt":1657540362159,"mc":[{"id":"1.200806927","rc":[{"trd":[[1.11,11919.24]],"tv":69074.97,"id":228749},{"atl":[[10,283.22]],"trd":[[10,1220.77]],"tv":6154.07,"id":2857977}],"tv":75229.04}]}
{"op":"mcm","clk":"AJuhqwkAhpOcCgDS2J8K","pt":1657540362264,"mc":[{"id":"1.200806927","rc":[{"trd":[[1.11,12126.35]],"tv":69282.08,"id":228749},{"atl":[[10,260.23]],"trd":[[10,1243.76]],"tv":6177.06,"id":2857977}],"tv":75459.14}]}
{"op":"mcm","clk":"AM+hqwkAw5OcCgD32J8K","pt":1657540362887,"mc":[{"id":"1.200806927","rc":[{"trd":[[1.11,12126.48]],"tv":69282.21,"id":228749},{"atl":[[10,260.22]],"trd":[[10,1243.77]],"tv":6177.07,"id":2857977}],"tv":75459.28}]}
{"op":"mcm","clk":"AO6hqwkA7ZOcCgCS2Z8K","pt":1657540363278,"mc":[{"id":"1.200806927","rc":[{"atl":[[1.12,881.57]],"id":228749}]}]}
{"op":"mcm","clk":"AImjqwkAl5WcCgCL2p8K","pt":1657540365074,"mc":[{"id":"1.200806927","rc":[{"atl":[[1.12,881.04]],"id":228749}]}]}
{"op":"mcm","clk":"ALijqwkAxZWcCgCk2p8K","pt":1657540365585,"mc":[{"id":"1.200806927","rc":[{"atl":[[1.12,876.74]],"trd":[[1.12,12452.04]],"ltp":1.12,"tv":69290.81,"id":228749}],"tv":75467.88}]}
{"op":"mcm","clk":"AMOjqwkAz5WcCgCp2p8K","pt":1657540365689,"mc":[{"id":"1.200806927","rc":[{"atl":[[1.12,871.48]],"trd":[[1.11,12131.74]],"ltp":1.11,"tv":69296.07,"id":228749},{"atl":[[10,259.64]],"trd":[[10,1244.35]],"tv":6177.65,"id":2857977}],"tv":75473.72}]}
{"op":"mcm","clk":"AMmjqwkA2JWcCgCw2p8K","pt":1657540365791,"mc":[{"id":"1.200806927","rc":[{"trd":[[1.11,12132.74]],"tv":69297.07,"id":228749},{"atl":[[10,259.53]],"trd":[[10,1244.46]],"tv":6177.76,"id":2857977}],"tv":75474.83}]}
{"op":"mcm","clk":"AOujqwkA/5WcCgDB2p8K","pt":1657540366174,"mc":[{"id":"1.200806927","rc":[{"trd":[[1.11,12185.33]],"tv":69349.66,"id":228749},{"atl":[[10,253.69]],"trd":[[10,1250.3]],"tv":6183.6,"id":2857977}],"tv":75533.26}]}
{"op":"mcm","clk":"ALukqwkAgZecCgD/2p8K","pt":1657540367275,"mc":[{"id":"1.200806927","rc":[{"trd":[[1.11,12395.7]],"tv":69560.03,"id":228749},{"atl":[[10,230.34]],"trd":[[10,1273.65]],"tv":6206.95,"id":2857977}],"tv":75766.98}]}
{"op":"mcm","clk":"AMWkqwkAjZecCgCG258K","pt":1657540367379,"mc":[{"id":"1.200806927","rc":[{"trd":[[1.11,13297.32]],"tv":70461.65,"id":228749},{"atl":[[10,130.26]],"trd":[[10,1373.73]],"tv":6307.03,"id":2857977}],"tv":76768.68}]}
{"op":"mcm","clk":"ANakqwkApZecCgCR258K","pt":1657540367591,"mc":[{"id":"1.200806927","rc":[{"trd":[[1.11,13302.58]],"tv":70466.91,"id":228749},{"atl":[[10,129.68]],"trd":[[10,1374.31]],"tv":6307.61,"id":2857977}],"tv":76774.52}]}
{"op":"mcm","clk":"AOWkqwkAtpecCgCe258K","pt":1657540367809,"mc":[{"id":"1.200806927","rc":[{"trd":[[1.11,13328.88]],"tv":70493.21,"id":228749},{"atl":[[10,126.76]],"trd":[[10,1377.23]],"tv":6310.53,"id":2857977}],"tv":76803.74}]}
{"op":"mcm","clk":"AIylqwkA7JecCgDA258K","pt":1657540368286,"mc":[{"id":"1.200806927","rc":[{"atb":[[1.04,2.89]],"id":228749}]}]}
{"op":"mcm","clk":"AJalqwkA+ZecCgDH258K","pt":1657540368378,"mc":[{"id":"1.200806927","rc":[{"atl":[[10,248.09]],"id":2857977}]}]}
{"op":"mcm","clk":"AMqlqwkAsZicCgDx258K","pt":1657540368983,"mc":[{"id":"1.200806927","rc":[{"trd":[[1.11,13331.51]],"tv":70495.84,"id":228749},{"atl":[[10,247.8]],"trd":[[10,1377.52]],"tv":6310.82,"id":2857977}],"tv":76806.66}]}
{"op":"mcm","clk":"AOelqwkAxpicCgCB3J8K","pt":1657540369201,"mc":[{"id":"1.200806927","rc":[{"atl":[[11,0.11]],"id":2857977}]}]}
{"op":"mcm","clk":"AO+lqwkA05icCgCI3J8K","pt":1657540369305,"mc":[{"id":"1.200806927","rc":[{"atl":[[1.44,4.18]],"id":228749}]}]}
{"op":"mcm","clk":"AI2mqwkA/picCgCd3J8K","pt":1657540369687,"mc":[{"id":"1.200806927","rc":[{"trd":[[1.11,13332.56]],"tv":70496.89,"id":228749},{"atl":[[10,247.68]],"trd":[[10,1377.64]],"tv":6310.94,"id":2857977}],"tv":76807.83}]}
{"op":"mcm","clk":"ALWmqwkAqJmcCgC93J8K","pt":1657540370117,"mc":[{"id":"1.200806927","rc":[{"trd":[[1.11,13337.82]],"tv":70502.15,"id":228749},{"atl":[[10,247.1]],"trd":[[10,1378.22]],"tv":6311.52,"id":2857977}],"tv":76813.67}]}
{"op":"mcm","clk":"AMamqwkAyZmcCgDU3J8K","pt":1657540370372,"mc":[{"id":"1.200806927","rc":[{"atb":[[9.4,11.45]],"trd":[[9.4,2.78]],"ltp":9.4,"tv":6312.38,"id":2857977}],"tv":76814.53}]}
{"op":"mcm","clk":"AN6mqwkA65mcCgDl3J8K","pt":1657540370675,"mc":[{"id":"1.200806927","rc":[{"atb":[[9.4,6.94]],"trd":[[9.4,11.8]],"tv":6321.4,"id":2857977}],"tv":76823.55}]}
{"op":"mcm","clk":"AKqoqwkAwpucCgCD3p8K","pt":1657540373294,"mc":[{"id":"1.200806927","rc":[{"trd":[[1.11,13381.68]],"tv":70546.01,"id":228749},{"atl":[[10,242.23]],"trd":[[10,1383.09]],"ltp":10,"tv":6326.27,"id":2857977}],"tv":76872.28}]}
{"op":"mcm","clk":"AK+oqwkAzpucCgCJ3p8K","pt":1657540373397,"mc":[{"id":"1.200806927","rc":[{"trd":[[1.11,13434.27]],"tv":70598.6,"id":228749},{"atl":[[10,236.39]],"trd":[[10,1388.93]],"tv":6332.11,"id":2857977}],"tv":76930.71}]}
{"op":"mcm","clk":"AL6oqwkA5JucCgCa3p8K","pt":1657540373663,"mc":[{"id":"1.200806927","rc":[{"atb":[[1.04,3.05]],"id":228749}]}]}
{"op":"mcm","clk":"AOioqwkAjpycCgC03p8K","pt":1657540374177,"mc":[{"id":"1.200806927","rc":[{"atb":[[1.04,2.89]],"id":228749}]}]}
{"op":"mcm","clk":"AO2oqwkAmJycCgC33p8K","pt":1657540374230,"mc":[{"id":"1.200806927","rc":[{"trd":[[1.11,13644.64]],"tv":70808.97,"id":228749},{"atl":[[10,213.04]],"trd":[[10,1412.28]],"tv":6355.46,"id":2857977}],"tv":77164.43}]}
{"op":"mcm","clk":"AIKpqwkArJycCgDE3p8K","pt":1657540374452,"mc":[{"id":"1.200806927","rc":[{"atb":[[9.4,6.83]],"trd":[[9.4,12.02]],"ltp":9.4,"tv":6355.68,"id":2857977}],"tv":77164.65}]}
{"op":"mcm","clk":"ALGpqwkA95ycCgDs3p8K","pt":1657540375279,"mc":[{"id":"1.200806927","rc":[{"atl":[[10,202.77]],"trd":[[10,1432.83]],"ltp":10,"tv":6376.23,"id":2857977}],"tv":77185.2}]}
{"op":"mcm","clk":"AM6pqwkAk52cCgD63p8K","pt":1657540375544,"mc":[{"id":"1.200806927","rc":[{"trd":[[1.11,13673.4]],"tv":70837.73,"id":228749},{"atl":[[10,199.58]],"trd":[[10,1436.02]],"tv":6379.42,"id":2857977}],"tv":77217.15}]}
{"op":"mcm","clk":"AJaqqwkA652cCgC1358K","pt":1657540376479,"mc":[{"id":"1.200806927","rc":[{"trd":[[1.11,13881.4]],"tv":71045.73,"id":228749},{"atl":[[10,176.49]],"trd":[[10,1459.11]],"tv":6402.51,"id":2857977}],"tv":77448.24}]}
{"op":"mcm","clk":"AMqqqwkAsp6cCgDe358K","pt":1657540377170,"mc":[{"id":"1.200806927","rc":[{"trd":[[1.11,13907.7]],"tv":71072.03,"id":228749},{"atl":[[10,173.57]],"trd":[[10,1462.03]],"tv":6405.43,"id":2857977}],"tv":77477.46}]}
{"op":"mcm","clk":"APiqqwkA9J6cCgCF4J8K","pt":1657540377875,"mc":[{"id":"1.200806927","rc":[{"atb":[[9.4,6.3]],"trd":[[9.4,13.08]],"ltp":9.4,"tv":6406.49,"id":2857977}],"tv":77478.52}]}
{"op":"mcm","clk":"AJ+rqwkAqJ+cCgCc4J8K","pt":1657540378372,"mc":[{"id":"1.200806927","rc":[{"trd":[[1.11,13908.23]],"tv":71072.56,"id":228749},{"atl":[[10,173.51]],"trd":[[10,1462.09]],"ltp":10,"tv":6406.55,"id":2857977}],"tv":77479.11}]}
{"op":"mcm","clk":"ALurqwkAyJ+cCgC24J8K","pt":1657540378768,"mc":[{"id":"1.200806927","rc":[{"atb":[[9.4,5.44]],"trd":[[9.4,14.8]],"ltp":9.4,"tv":6408.27,"id":2857977}],"tv":77480.83}]}
{"op":"mcm","clk":"AMirqwkA3p+cCgDC4J8K","pt":1657540378981,"mc":[{"id":"1.200806927","rc":[{"atl":[[1.12,870.17]],"id":228749}]}]}
{"op":"mcm","clk":"ANCrqwkA6p+cCgDH4J8K","pt":1657540379081,"mc":[{"id":"1.200806927","rc":[{"atb":[[9.4,5.34]],"trd":[[9.4,15.01]],"tv":6408.48,"id":2857977}],"tv":77481.04}]}
{"op":"mcm","clk":"ANqrqwkA+Z+cCgDL4J8K","pt":1657540379187,"mc":[{"id":"1.200806927","rc":[{"trd":[[1.11,13977.21]],"tv":71141.54,"id":228749},{"atl":[[10,165.85]],"trd":[[10,1469.75]],"ltp":10,"tv":6416.14,"id":2857977}],"tv":77557.68}]}
{"op":"mcm","clk":"AOGrqwkAh6CcCgDR4J8K","pt":1657540379290,"mc":[{"id":"1.200806927","rc":[{"atl":[[1.12,870]],"trd":[[1.12,12452.38]],"ltp":1.12,"tv":71141.88,"id":228749}],"tv":77558.02}]}
{"op":"mcm","clk":"APWrqwkArqCcCgDg4J8K","pt":1657540379567,"mc":[{"id":"1.200806927","rc":[{"trd":[[1.11,14578.32]],"ltp":1.11,"tv":71742.99,"id":228749},{"atl":[[10,99.13]],"trd":[[10,1536.47]],"tv":6482.86,"id":2857977}],"tv":78225.85}]}
{"op":"mcm","clk":"AIasqwkAxaCcCgDq4J8K","pt":1657540379769,"mc":[{"id":"1.200806927","rc":[{"atb":[[1.04,2.05]],"id":228749},{"atb":[[9.4,5.16]],"trd":[[9.4,15.36]],"ltp":9.4,"tv":6483.21,"id":2857977}],"tv":78226.2}]}
{"op":"mcm","clk":"AIutqwkA1qGcCgCv4Z8K","pt":1657540381193,"mc":[{"id":"1.200806927","rc":[{"trd":[[1.11,14788.69]],"tv":71953.36,"id":228749},{"atl":[[10,75.78]],"trd":[[10,1559.82]],"ltp":10,"tv":6506.56,"id":2857977}],"tv":78459.92}]}
{"op":"mcm","clk":"ALatqwkAj6KcCgDK4Z8K","pt":1657540381778,"mc":[{"id":"1.200806927","rc":[{"trd":[[1.11,14793.95]],"tv":71958.62,"id":228749},{"atl":[[10,75.2]],"trd":[[10,1560.4]],"tv":6507.14,"id":2857977}],"tv":78465.76}]}
{"op":"mcm","clk":"AMKtqwkAqaKcCgDS4Z8K","pt":1657540381991,"mc":[{"id":"1.200806927","rc":[{"trd":[[1.11,14836.03]],"tv":72000.7,"id":228749},{"atl":[[10,70.53]],"trd":[[10,1565.07]],"tv":6511.81,"id":2857977}],"tv":78512.51}]}
{"op":"mcm","clk":"APWuqwkA96OcCgC+4p8K","pt":1657540384068,"mc":[{"id":"1.200806927","rc":[{"trd":[[1.11,14838.66]],"tv":72003.33,"id":228749},{"atl":[[10,70.24]],"trd":[[10,1565.36]],"tv":6512.1,"id":2857977}],"tv":78515.43}]}
{"op":"mcm","clk":"AP+vqwkAjaWcCgCP458K","pt":1657540385603,"mc":[{"id":"1.200806927","rc":[{"atb":[[9.4,4.38]],"trd":[[9.4,16.92]],"ltp":9.4,"tv":6513.66,"id":2857977}],"tv":78516.99}]}
{"op":"mcm","clk":"APKwqwkAsqacCgDe458K","pt":1657540387165,"mc":[{"id":"1.200806927","rc":[{"trd":[[1.11,14842.87]],"tv":72007.54,"id":228749},{"atl":[[10,69.77]],"trd":[[10,1565.83]],"ltp":10,"tv":6514.13,"id":2857977}],"tv":78521.67}]}
{"op":"mcm","clk":"AIyxqwkA1qacCgDw458K","pt":1657540387497,"mc":[{"id":"1.200806927","rc":[{"atl":[[1.12,867.37]],"id":228749}]}]}
{"op":"mcm","clk":"AJaxqwkA4KacCgD3458K","pt":1657540387600,"mc":[{"id":"1.200806927","rc":[{"trd":[[1.11,15342.87]],"tv":72507.54,"id":228749},{"atl":[[10,14.27]],"trd":[[10,1621.33]],"tv":6569.63,"id":2857977}],"tv":79077.17}]}
{"op":"mcm","clk":"AMSxqwkArqecCgCZ5J8K","pt":1657540388173,"mc":[{"id":"1.200806927","rc":[{"atl":[[1.11,78.55]],"trd":[[1.11,15471.43]],"tv":72636.1,"id":228749},{"atl":[[10,0]],"trd":[[10,1635.6]],"tv":6583.9,"id":2857977}],"tv":79220}]}
{"op":"mcm","clk":"AOmxqwkA4KecCgC45J8K","pt":1657540388678,"mc":[{"id":"1.200806927","rc":[{"atl":[[1.17,1028.47],[1.11,288.92]],"id":228749}]}]}
{"op":"mcm","clk":"AI6yqwkAjqicCgDa5J8K","pt":1657540389166,"mc":[{"id":"1.200806927","rc":[{"atl":[[1.11,418.36]],"id":228749}]}]}
{"op":"mcm","clk":"AKSyqwkAq6icCgDu5J8K","pt":1657540389527,"mc":[{"id":"1.200806927","rc":[{"atl":[[1.11,1040.48]],"id":228749}]}]}
{"op":"mcm","clk":"ALeyqwkAvKicCgD85J8K","pt":1657540389689,"mc":[{"id":"1.200806927","rc":[{"atb":[[1.02,1],[1.03,1],[1.01,1570.18]],"id":2857977}]}]}
{"op":"mcm","clk":"AIuzqwkAlKmcCgCz5Z8K","pt":1657540390579,"mc":[{"id":"1.200806927","rc":[{"atl":[[1000,0.32]],"id":228749}]}]}
{"op":"mcm","clk":"ALWzqwkAvqmcCgDJ5Z8K","pt":1657540390996,"mc":[{"id":"1.200806927","rc":[{"atl":[[1000,0.13]],"id":228749}]}]}
{"op":"mcm","clk":"AOC0qwkAoaucCgC45p8K","pt":1657540393001,"mc":[{"id":"1.200806927","rc":[{"atl":[[1.11,1641.59]],"id":228749}]}]}
{"op":"mcm","clk":"AN+1qwkAvKycCgCM558K","pt":1657540394466,"mc":[{"id":"1.200806927","rc":[{"atl":[[1.11,1846.55]],"trd":[[1.11,15475.73]],"tv":72640.4,"id":228749}],"tv":79224.3}]}
{"op":"mcm","clk":"AJu2qwkAg62cCgC3558K","pt":1657540395185,"mc":[{"id":"1.200806927","rc":[{"atl":[[1.11,1844.24]],"trd":[[1.11,15478.04]],"tv":72642.71,"id":228749},{"trd":[[10,1635.85]],"tv":6584.15,"id":2857977}],"tv":79226.86}]}
{"op":"mcm","clk":"AMK2qwkAsK2cCgDX558K","pt":1657540395593,"mc":[{"id":"1.200806927","rc":[{"atl":[[1.11,1846.87]],"id":228749}]}]}
{"op":"mcm","clk":"AM62qwkAya2cCgDi558K","pt":1657540395756,"mc":[{"id":"1.200806927","rc":[{"atl":[[1.11,1890.73]],"id":228749}]}]}
{"op":"mcm","clk":"AOm2qwkA5K2cCgD6558K","pt":1657540396085,"mc":[{"id":"1.200806927","rc":[{"atl":[[1.11,1890.92]],"id":228749}]}]}
{"op":"mcm","clk":"AKO3qwkArK6cCgCo6J8K","pt":1657540396804,"mc":[{"id":"1.200806927","rc":[{"atl":[[1.11,1890.73]],"id":228749}]}]}
{"op":"mcm","clk":"AJ24qwkAtq+cCgD16J8K","pt":1657540398213,"mc":[{"id":"1.200806927","rc":[{"atb":[[1.1,784.13]],"trd":[[1.1,135.32]],"ltp":1.1,"tv":72653.23,"id":228749}],"tv":79237.38}]}
{"op":"mcm","clk":"AP64qwkAp7CcCgDC6Z8K","pt":1657540399404,"mc":[{"id":"1.200806927","rc":[{"atl":[[1.11,1895.52]],"id":228749}]}]}
{"op":"mcm","clk":"ALu5qwkA+rCcCgDv6Z8K","pt":1657540400245,"mc":[{"id":"1.200806927","rc":[{"atl":[[1.11,1891.64]],"trd":[[1.11,15481.92]],"ltp":1.11,"tv":72657.11,"id":228749},{"trd":[[10,1636.28]],"tv":6584.58,"id":2857977}],"tv":79241.69}]}
{"op":"mcm","clk":"AM25qwkAj7GcCgD86Z8K","pt":1657540400402,"mc":[{"id":"1.200806927","rc":[{"atl":[[1.17,1027.7]],"id":228749}]}]}
{"op":"mcm","clk":"ANa5qwkAnbGcCgCC6p8K","pt":1657540400511,"mc":[{"id":"1.200806927","rc":[{"atl":[[1.11,1762.2]],"id":228749}]}]}
{"op":"mcm","clk":"APy5qwkAxrGcCgCd6p8K","pt":1657540400880,"mc":[{"id":"1.200806927","rc":[{"atl":[[1.11,1758.32]],"trd":[[1.11,15485.8]],"tv":72660.99,"id":228749},{"trd":[[10,1636.71]],"tv":6585.01,"id":2857977}],"tv":79246}]}
{"op":"mcm","clk":"AIW6qwkA0bGcCgCk6p8K","pt":1657540400981,"mc":[{"id":"1.200806927","rc":[{"atb":[[1.1,573.75]],"trd":[[1.1,552.91]],"ltp":1.1,"tv":73078.58,"id":228749}],"tv":79663.59}]}
{"op":"mcm","clk":"AL66qwkAhbKcCgDG6p8K","pt":1657540401611,"mc":[{"id":"1.200806927","rc":[{"atl":[[1.11,1757.36]],"trd":[[1.11,15486.76]],"ltp":1.11,"tv":73079.54,"id":228749},{"trd":[[10,1636.82]],"tv":6585.12,"id":2857977}],"tv":79664.66}]}
{"op":"mcm","clk":"AMy6qwkAlrKcCgDW6p8K","pt":1657540401783,"mc":[{"id":"1.200806927","rc":[{"atl":[[1.11,1135.24]],"id":228749}]}]}
{"op":"mcm","clk":"AIG7qwkA0rKcCgD96p8K","pt":1657540402411,"mc":[{"id":"1.200806927","rc":[{"atl":[[1.11,1134.38]],"trd":[[1.11,15488.48]],"tv":73081.26,"id":228749}],"tv":79666.38}]}
{"op":"mcm","clk":"AJK7qwkA5bKcCgCI658K","pt":1657540402624,"mc":[{"id":"1.200806927","rc":[{"atl":[[1.11,1124.92]],"trd":[[1.11,15497.94]],"tv":73090.72,"id":228749},{"trd":[[10,1637.87]],"tv":6586.17,"id":2857977}],"tv":79676.89}]}
{"op":"mcm","clk":"ANG7qwkAvbOcCgC3658K","pt":1657540403433,"mc":[{"id":"1.200806927","rc":[{"atl":[[1.12,737.93]],"id":228749}]}]}
{"op":"mcm","clk":"AN67qwkA07OcCgDD658K","pt":1657540403572,"mc":[{"id":"1.200806927","rc":[{"atb":[[1.07,207.03]],"id":228749}]}]}
{"op":"mcm","clk":"AOS7qwkA3bOcCgDK658K","pt":1657540403684,"mc":[{"id":"1.200806927","rc":[{"atb":[[1.1,444.31]],"trd":[[1.1,811.79]],"ltp":1.1,"tv":73349.6,"id":228749}],"tv":79935.77}]}
{"op":"mcm","clk":"AIO8qwkAh7ScCgDf658K","pt":1657540404099,"mc":[{"id":"1.200806927","rc":[{"atl":[[1.11,1122.29]],"id":228749}]}]}
{"op":"mcm","clk":"AKm8qwkAt7ScCgD+658K","pt":1657540404611,"mc":[{"id":"1.200806927","rc":[{"atl":[[1.11,1121.33]],"trd":[[1.11,15498.9]],"ltp":1.11,"tv":73350.56,"id":228749},{"trd":[[10,1637.98]],"tv":6586.28,"id":2857977}],"tv":79936.84}]}
{"op":"mcm","clk":"AMO8qwkA3LScCgCR7J8K","pt":1657540404926,"mc":[{"id":"1.200806927","rc":[{"atl":[[1.11,1095.44]],"id":228749}]}]}
{"op":"mcm","clk":"AOO8qwkA/LScCgCk7J8K","pt":1657540405204,"mc":[{"id":"1.200806927","rc":[{"atb":[[9.4,0]],"id":2857977}]}]}
{"op":"mcm","clk":"AMG9qwkA9LWcCgD67J8K","pt":1657540406408,"mc":[{"id":"1.200806927","rc":[{"atl":[[1.11,1087.33]],"trd":[[1.11,15507.01]],"tv":73358.67,"id":228749},{"trd":[[10,1638.88]],"tv":6587.18,"id":2857977}],"tv":79945.85}]}
{"op":"mcm","clk":"AMe9qwkAgbacCgCA7Z8K","pt":1657540406508,"mc":[{"id":"1.200806927","rc":[{"atb":[[1.1,384.53]],"trd":[[1.1,931.34]],"ltp":1.1,"tv":73478.22,"id":228749}],"tv":80065.4}]}
{"op":"mcm","clk":"ANq9qwkAkracCgCL7Z8K","pt":1657540406709,"mc":[{"id":"1.200806927","rc":[{"atl":[[1.11,1085.78]],"trd":[[1.11,15508.56]],"ltp":1.11,"tv":73479.77,"id":228749},{"trd":[[10,1639.05]],"tv":6587.35,"id":2857977}],"tv":80067.12}]}
{"op":"mcm","clk":"ALK+qwkAgLecCgDO7Z8K","pt":1657540407824,"mc":[{"id":"1.200806927","rc":[{"atl":[[1.11,1081.48]],"trd":[[1.11,15517.17]],"tv":73488.38,"id":228749}],"tv":80075.73}]}
{"op":"mcm","clk":"AOy+qwkAubecCgDv7Z8K","pt":1657540408393,"mc":[{"id":"1.200806927","rc":[{"atb":[[1.1,174.16]],"trd":[[1.1,1352.08]],"ltp":1.1,"tv":73909.12,"id":228749}],"tv":80496.47}]}
{"op":"mcm","clk":"AIi/qwkA17ecCgCB7p8K","pt":1657540408719,"mc":[{"id":"1.200806927","rc":[{"atb":[[1.05,328]],"id":228749}]}]}
{"op":"mcm","clk":"AJG/qwkA37ecCgCH7p8K","pt":1657540408817,"mc":[{"id":"1.200806927","rc":[{"atl":[[1.11,1076.71]],"trd":[[1.11,15521.94]],"ltp":1.11,"tv":73913.89,"id":228749},{"trd":[[10,1639.58]],"tv":6587.88,"id":2857977}],"tv":80501.77}]}
{"op":"mcm","clk":"APK/qwkA1ricCgDU7p8K","pt":1657540410113,"mc":[{"id":"1.200806927","rc":[{"atb":[[1.1,0]],"atl":[[1000,0.26],[1.1,36.09]],"trd":[[1.1,1701.47]],"ltp":1.1,"tv":74263.28,"id":228749},{"atl":[[11,0]],"trd":[[11,0.11]],"ltp":11,"tv":6587.99,"id":2857977}],"tv":80851.27}]}
{"op":"mcm","clk":"AI3AqwkA6LicCgDg7p8K","pt":1657540410325,"mc":[{"id":"1.200806927","rc":[{"atl":[[1.1,31.79]],"trd":[[1.1,1705.77]],"tv":74267.58,"id":228749},{"trd":[[11,0.54]],"tv":6588.42,"id":2857977}],"tv":80856}]}
{"op":"mcm","clk":"AJjAqwkA+ricCgDr7p8K","pt":1657540410501,"mc":[{"id":"1.200806927","rc":[{"atl":[[1000,0.13]],"id":228749}]}]}
{"op":"mcm","clk":"AK3AqwkAkrmcCgD27p8K","pt":1657540410707,"mc":[{"id":"1.200806927","rc":[{"atl":[[1.1,32.79]],"id":228749}]}]}
{"op":"mcm","clk":"ALHAqwkAm7mcCgD87p8K","pt":1657540410806,"mc":[{"id":"1.200806927","rc":[{"atl":[[1.1,276.46]],"trd":[[1.1,1706.84]],"tv":74268.65,"id":228749},{"trd":[[11,0.64]],"tv":6588.52,"id":2857977}],"tv":80857.17}]}
{"op":"mcm","clk":"ANPAqwkAt7mcCgCS758K","pt":1657540411113,"mc":[{"id":"1.200806927","rc":[{"atl":[[1.1,275.41]],"id":228749}]}]}
{"op":"mcm","clk":"AL3BqwkAn7qcCgDR758K","pt":1657540412222,"mc":[{"id":"1.200806927","rc":[{"atl":[[1.1,270.15]],"id":228749}]}]}
{"op":"mcm","clk":"AMrBqwkAubqcCgDc758K","pt":1657540412439,"mc":[{"id":"1.200806927","rc":[{"atl":[[1.1,268.57]],"id":228749}]}]}
{"op":"mcm","clk":"ANDBqwkAxbqcCgDi758K","pt":1657540412500,"mc":[{"id":"1.200806927","rc":[{"atl":[[1.1,266.42]],"trd":[[1.1,1708.99]],"tv":74270.8,"id":228749},{"trd":[[11,0.86]],"tv":6588.74,"id":2857977}],"tv":80859.54}]}
{"op":"mcm","clk":"AObBqwkA4bqcCgD3758K","pt":1657540412813,"mc":[{"id":"1.200806927","rc":[{"atl":[[1.1,253.27]],"id":228749}]}]}
{"op":"mcm","clk":"AJrCqwkAm7ucCgCf8J8K","pt":1657540413421,"mc":[{"id":"1.200806927","rc":[{"atl":[[1.1,253.17]],"trd":[[1.1,1709.19]],"tv":74271,"id":228749}],"tv":80859.74}]}
{"op":"mcm","clk":"AKXCqwkAqbucCgCp8J8K","pt":1657540413529,"mc":[{"id":"1.200806927","rc":[{"atb":[[1.06,5.26]],"id":228749}]}]}
{"op":"mcm","clk":"AMPCqwkAz7ucCgDE8J8K","pt":1657540413902,"mc":[{"id":"1.200806927","rc":[{"atl":[[1.1,263.69]],"id":228749}]}]}
{"op":"mcm","clk":"AOHCqwkA8rucCgDW8J8K","pt":1657540414220,"mc":[{"id":"1.200806927","rc":[{"atl":[[1.1,256.5]],"trd":[[1.1,1716.38]],"tv":74278.19,"id":228749},{"trd":[[11,1.58]],"tv":6589.46,"id":2857977}],"tv":80867.65}]}
{"op":"mcm","clk":"APrCqwkAlrycCgDs8J8K","pt":1657540414541,"mc":[{"id":"1.200806927","rc":[{"atl":[[1.1,414.27]],"id":228749}]}]}
{"op":"mcm","clk":"AILDqwkAn7ycCgDu8J8K","pt":1657540414635,"mc":[{"id":"1.200806927","rc":[{"atl":[[1.1,1036.39]],"id":228749}]}]}
{"op":"mcm","clk":"AKDDqwkAyrycCgCD8Z8K","pt":1657540415006,"mc":[{"id":"1.200806927","rc":[{"atl":[[1.1,2839.64]],"id":228749}]}]}
{"op":"mcm","clk":"AMzDqwkAgL2cCgCf8Z8K","pt":1657540415531,"mc":[{"id":"1.200806927","rc":[{"atl":[[1.1,3050.01]],"id":228749}]}]}
{"op":"mcm","clk":"ANPDqwkAiL2cCgCk8Z8K","pt":1657540415638,"mc":[{"id":"1.200806927","rc":[{"atl":[[1.1,2997.55]],"trd":[[1.1,1821.56]],"tv":74383.37,"id":228749}],"tv":80972.83}]}
{"op":"mcm","clk":"AOXDqwkAmr2cCgCx8Z8K","pt":1657540415831,"mc":[{"id":"1.200806927","rc":[{"atl":[[1.1,2997.12]],"trd":[[1.1,1822.42]],"tv":74384.23,"id":228749}],"tv":80973.69}]}
{"op":"mcm","clk":"AJPEqwkAy72cCgDV8Z8K","pt":1657540416321,"mc":[{"id":"1.200806927","rc":[{"atl":[[1.1,2996.99]],"id":228749}]}]}
{"op":"mcm","clk":"AMXEqwkAk76cCgD/8Z8K","pt":1657540416935,"mc":[{"id":"1.200806927","rc":[{"atb":[[11,7]],"id":2857977}]}]}
{"op":"mcm","clk":"AJPFqwkA776cCgC68p8K","pt":1657540417832,"mc":[{"id":"1.200806927","rc":[{"atl":[[1.11,1074.08]],"id":228749}]}]}
{"op":"mcm","clk":"AKvFqwkAi7+cCgDP8p8K","pt":1657540418136,"mc":[{"id":"1.200806927","rc":[{"atb":[[1.09,707.26]],"id":228749}]}]}
{"op":"mcm","clk":"ANHFqwkAvL+cCgDs8p8K","pt":1657540418630,"mc":[{"id":"1.200806927","rc":[{"atl":[[1.1,2986.47]],"trd":[[1.1,1843.46]],"tv":74405.27,"id":228749}],"tv":80994.73}]}
{"op":"mcm","clk":"AJfGqwkA/b+cCgCW858K","pt":1657540419345,"mc":[{"id":"1.200806927","rc":[{"atb":[[11,6.89]],"trd":[[11,1.79]],"tv":6589.67,"id":2857977}],"tv":80994.94}]}
{"op":"mcm","clk":"AN7GqwkA4MCcCgDJ858K","pt":1657540420249,"mc":[{"id":"1.200806927","rc":[{"atl":[[1.1,2975.95]],"id":228749}]}]}
{"op":"mcm","clk":"AO3GqwkA9MCcCgDc858K","pt":1657540420448,"mc":[{"id":"1.200806927","rc":[{"atl":[[1.1,2975.42]],"trd":[[1.1,1844.52]],"tv":74406.33,"id":228749}],"tv":80996}]}
{"op":"mcm","clk":"APbGqwkA/8CcCgDg858K","pt":1657540420514,"mc":[{"id":"1.200806927","rc":[{"atl":[[1.1,2353.3]],"id":228749},{"atb":[[11,6.72]],"trd":[[11,2.14]],"tv":6590.02,"id":2857977}],"tv":80996.35}]}
{"op":"mcm","clk":"ALzHqwkA0cGcCgCX9J8K","pt":1657540421437,"mc":[{"id":"1.200806927","rc":[{"atl":[[1.1,2350.67]],"trd":[[1.1,1849.78]],"tv":74411.59,"id":228749}],"tv":81001.61}]}
{"op":"mcm","clk":"AN7HqwkA/cGcCgCx9J8K","pt":1657540421959,"mc":[{"id":"1.200806927","rc":[{"atb":[[1.09,7.26]],"id":228749}]}]}
{"op":"mcm","clk":"APHHqwkAm8KcCgDG9J8K","pt":1657540422224,"mc":[{"id":"1.200806927","rc":[{"atl":[[1.1,2324.99]],"trd":[[1.1,1901.15]],"tv":74462.96,"id":228749}],"tv":81052.98}]}
{"op":"mcm","clk":"AJrIqwkA1cKcCgDs9J8K","pt":1657540422830,"mc":[{"id":"1.200806927","rc":[{"atl":[[1.1,2322.99]],"trd":[[1.1,1905.15]],"tv":74466.96,"id":228749}],"tv":81056.98}]}
{"op":"mcm","clk":"AKjIqwkA5sKcCgD39J8K","pt":1657540423040,"mc":[{"id":"1.200806927","rc":[{"atl":[[1.1,2317.73]],"trd":[[1.1,1915.67]],"tv":74477.48,"id":228749}],"tv":81067.5}]}
{"op":"mcm","clk":"APjIqwkAwcOcCgCm9Z8K","pt":1657540424040,"mc":[{"id":"1.200806927","rc":[{"atb":[[11,6.52]],"trd":[[11,2.54]],"tv":6590.42,"id":2857977}],"tv":81067.9}]}
{"op":"mcm","clk":"AITJqwkA1sOcCgCx9Z8K","pt":1657540424249,"mc":[{"id":"1.200806927","rc":[{"atb":[[11,6.42]],"trd":[[11,2.74]],"tv":6590.62,"id":2857977}],"tv":81068.1}]}
{"op":"mcm","clk":"AJTJqwkA68OcCgC99Z8K","pt":1657540424431,"mc":[{"id":"1.200806927","rc":[{"atb":[[11,6.22]],"trd":[[11,3.14]],"tv":6591.02,"id":2857977}],"tv":81068.5}]}
{"op":"mcm","clk":"AK3JqwkAjcScCgDU9Z8K","pt":1657540424724,"mc":[{"id":"1.200806927","rc":[{"atb":[[11,0]],"id":2857977}]}]}
{"op":"mcm","clk":"ALTJqwkAl8ScCgDY9Z8K","pt":1657540424816,"mc":[{"id":"1.200806927","rc":[{"atl":[[1.1,2316.66]],"trd":[[1.1,1916.74]],"tv":74478.55,"id":228749},{"trd":[[11,3.24]],"tv":6591.12,"id":2857977}],"tv":81069.67}]}
{"op":"mcm","clk":"ANDJqwkAwMScCgD09Z8K","pt":1657540425250,"mc":[{"id":"1.200806927","rc":[{"atl":[[1.11,1030.22]],"id":228749}]}]}
{"op":"mcm","clk":"ANjJqwkAycScCgD59Z8K","pt":1657540425346,"mc":[{"id":"1.200806927","rc":[{"atl":[[1.1,2311.36]],"trd":[[1.1,1922.04]],"tv":74483.85,"id":228749},{"trd":[[11,3.77]],"tv":6591.65,"id":2857977}],"tv":81075.5}]}
{"op":"mcm","clk":"AO7JqwkA3sScCgCJ9p8K","pt":1657540425643,"mc":[{"id":"1.200806927","rc":[{"atl":[[1.1,2285.06]],"trd":[[1.1,1974.64]],"tv":74536.45,"id":228749}],"tv":81128.1}]}
{"op":"mcm","clk":"ALTKqwkArcWcCgC69p8K","pt":1657540426537,"mc":[{"id":"1.200806927","rc":[{"atl":[[1.1,2281.58]],"trd":[[1.1,1981.6]],"tv":74543.41,"id":228749}],"tv":81135.06}]}
{"op":"mcm","clk":"AM/KqwkA0cWcCgDK9p8K","pt":1657540426934,"mc":[{"id":"1.200806927","rc":[{"atl":[[1.1,2281.47]],"trd":[[1.1,1981.81]],"tv":74543.62,"id":228749}],"tv":81135.27}]}
{"op":"mcm","clk":"AN3KqwkA5sWcCgDU9p8K","pt":1657540427129,"mc":[{"id":"1.200806927","rc":[{"atl":[[1.1,2276.17]],"trd":[[1.1,1987.11]],"tv":74548.92,"id":228749},{"trd":[[11,4.3]],"tv":6592.18,"id":2857977}],"tv":81141.1}]}
{"op":"mcm","clk":"AOfKqwkA8sWcCgDd9p8K","pt":1657540427246,"mc":[{"id":"1.200806927","rc":[{"atl":[[12,0]],"id":2857977}]}]}
{"op":"mcm","clk":"AJTLqwkAscacCgCA958K","pt":1657540427852,"mc":[{"id":"1.200806927","rc":[{"atl":[[1.1,2275.64]],"trd":[[1.1,1988.17]],"tv":74549.98,"id":228749}],"tv":81142.16}]}
{"op":"mcm","clk":"AKLLqwkAxMacCgCP958K","pt":1657540428056,"mc":[{"id":"1.200806927","rc":[{"atl":[[1.1,4497.64]],"id":228749}]}]}
{"op":"mcm","clk":"AK7LqwkA2MacCgCY958K","pt":1657540428228,"mc":[{"id":"1.200806927","rc":[{"atl":[[1.1,4492.38],[1.12,743.19]],"trd":[[1.1,1998.69]],"tv":74560.5,"id":228749}],"tv":81152.68}]}
{"op":"mcm","clk":"AMPLqwkA+MacCgCm958K","pt":1657540428535,"mc":[{"id":"1.200806927","rc":[{"atl":[[1.11,3252.22]],"id":228749}]}]}
{"op":"mcm","clk":"AOrLqwkApsecCgDL958K","pt":1657540429155,"mc":[{"id":"1.200806927","rc":[{"atl":[[1000,0.36]],"id":228749}]}]}
{"op":"mcm","clk":"APDLqwkAq8ecCgDN958K","pt":1657540429174,"mc":[{"id":"1.200806927","rc":[{"atl":[[1.1,4597.56]],"id":228749}]}]}
{"op":"mcm","clk":"AI/MqwkAzsecCgDp958K","pt":1657540429550,"mc":[{"id":"1.200806927","rc":[{"atl":[[1000,0.13]],"id":228749}]}]}
{"op":"mcm","clk":"AKnMqwkA9secCgCG+J8K","pt":1657540429969,"mc":[{"id":"1.200806927","rc":[{"atl":[[1.1,2375.56]],"id":228749}]}]}
{"op":"mcm","clk":"AMHMqwkAl8icCgCd+J8K","pt":1657540430337,"mc":[{"id":"1.200806927","rc":[{"atl":[[1.1,2374.27]],"trd":[[1.1,1999.98]],"tv":74561.79,"id":228749},{"trd":[[11,4.43]],"tv":6592.31,"id":2857977}],"tv":81154.1}]}
{"op":"mcm","clk":"AIvNqwkAgcmcCgDq+J8K","pt":1657540431497,"mc":[{"id":"1.200806927","rc":[{"atl":[[1.11,1030.22]],"id":228749}]}]}
{"op":"mcm","clk":"AMvNqwkAu8mcCgCS+Z8K","pt":1657540432064,"mc":[{"id":"1.200806927","rc":[{"atl":[[1.1,2348.38]],"trd":[[1.1,2051.76]],"tv":74613.57,"id":228749}],"tv":81205.88}]}
{"op":"mcm","clk":"AOnNqwkA4MmcCgCi+Z8K","pt":1657540432366,"mc":[{"id":"1.200806927","rc":[{"atl":[[13,0.92]],"id":2857977}]}]}
{"op":"mcm","clk":"AKzOqwkAu8qcCgDV+Z8K","pt":1657540433163,"mc":[{"id":"1.200806927","rc":[{"atl":[[1.1,2343.08]],"trd":[[1.1,2057.06]],"tv":74618.87,"id":228749},{"trd":[[11,4.96]],"tv":6592.84,"id":2857977}],"tv":81211.71}]}
{"op":"mcm","clk":"ALfOqwkAx8qcCgDZ+Z8K","pt":1657540433265,"mc":[{"id":"1.200806927","rc":[{"atl":[[1.1,2212.22]],"trd":[[1.1,2082.74]],"tv":74644.55,"id":228749},{"trd":[[11,7.53]],"tv":6595.41,"id":2857977}],"tv":81239.96}]}
{"op":"mcm","clk":"AOPOqwkA98qcCgD5+Z8K","pt":1657540433743,"mc":[{"id":"1.200806927","rc":[{"atl":[[1.1,2211.96]],"trd":[[1.1,2083.26]],"tv":74645.07,"id":228749}],"tv":81240.48}]}
{"op":"mcm","clk":"APbOqwkAkMucCgCD+p8K","pt":1657540433954,"mc":[{"id":"1.200806927","rc":[{"atl":[[1.1,2106.78]],"trd":[[1.1,2164.4]],"tv":74726.21,"id":228749}],"tv":81321.62}]}
{"op":"mcm","clk":"AKvPqwkA0MucCgCp+p8K","pt":1657540434565,"mc":[{"id":"1.200806927","rc":[{"atl":[[1.1,2091]],"id":228749}]}]}
{"op":"mcm","clk":"ALHPqwkA2sucCgCv+p8K","pt":1657540434675,"mc":[{"id":"1.200806927","rc":[{"atb":[[1.09,7.03]],"trd":[[1.09,0.46]],"ltp":1.09,"tv":74726.67,"id":228749}],"tv":81322.08}]}
{"op":"mcm","clk":"AM3PqwkA/MucCgDI+p8K","pt":1657540435061,"mc":[{"id":"1.200806927","rc":[{"atl":[[1.1,2089.71]],"trd":[[1.1,2165.69]],"ltp":1.1,"tv":74727.96,"id":228749},{"trd":[[11,7.66]],"tv":6595.54,"id":2857977}],"tv":81323.5}]}
{"op":"mcm","clk":"AIfQqwkAw8ycCgCE+58K","pt":1657540435879,"mc":[{"id":"1.200806927","rc":[{"atl":[[1.1,2013.62]],"id":228749}]}]}
{"op":"mcm","clk":"APjQqwkA282cCgDi+58K","pt":1657540437372,"mc":[{"id":"1.200806927","rc":[{"atb":[[1.09,0]],"trd":[[1.09,40.83]],"ltp":1.09,"tv":74768.33,"id":228749},{"atl":[[11.5,1.65]],"trd":[[11.5,3.49]],"ltp":11.5,"tv":6599.03,"id":2857977}],"tv":81367.36}]}
{"op":"mcm","clk":"AKDRqwkAic6cCgCB/J8K","pt":1657540437872,"mc":[{"id":"1.200806927","rc":[{"atl":[[1.1,2000.47]],"id":228749}]}]}
{"op":"mcm","clk":"APHRqwkA/M6cCgDL/J8K","pt":1657540438978,"mc":[{"id":"1.200806927","rc":[{"atl":[[1.1,1999.2]],"trd":[[1.1,2167.17]],"ltp":1.1,"tv":74769.81,"id":228749},{"atb":[[11.5,5.35]],"atl":[[11.5,0]],"trd":[[11.5,6.79],[11,7.77]],"tv":6602.44,"id":2857977}],"tv":81372.25}]}
{"op":"mcm","clk":"ALTSqwkA68+cCgCN/Z8K","pt":1657540439881,"mc":[{"id":"1.200806927","rc":[{"atb":[[11.5,4.82]],"trd":[[11.5,7.85]],"tv":6603.5,"id":2857977}],"tv":81373.31}]}
{"op":"mcm","clk":"AMXSqwkAhdCcCgCX/Z8K","pt":1657540440097,"mc":[{"id":"1.200806927","rc":[{"atb":[[1.03,67.69]],"atl":[[1.19,52.59]],"id":228749}]}]}
{"op":"mcm","clk":"AO7SqwkAv9CcCgC0/Z8K","pt":1657540440562,"mc":[{"id":"1.200806927","rc":[{"atb":[[1.07,707.03]],"id":228749}]}]}
{"op":"mcm","clk":"AKbTqwkA/dCcCgDU/Z8K","pt":1657540441178,"mc":[{"id":"1.200806927","rc":[{"atb":[[1.06,505.26]],"id":228749}]}]}
{"op":"mcm","clk":"ALvTqwkAjdGcCgDZ/Z8K","pt":1657540441288,"mc":[{"id":"1.200806927","rc":[{"atl":[[1.1,1987.4]],"trd":[[1.1,2178.97]],"tv":74781.61,"id":228749},{"atb":[[11.5,0]],"trd":[[11.5,17.49],[11,8.95]],"ltp":11,"tv":6614.32,"id":2857977}],"tv":81395.93}]}
{"op":"mcm","clk":"AM7TqwkAsdGcCgDs/Z8K","pt":1657540441563,"mc":[{"id":"1.200806927","rc":[{"atl":[[1.1,1986.35]],"id":228749}]}]}
{"op":"mcm","clk":"APHTqwkA3dGcCgCE/p8K","pt":1657540441986,"mc":[{"id":"1.200806927","rc":[{"atb":[[1.05,828]],"id":228749}]}]}
{"op":"mcm","clk":"AMTUqwkAy9KcCgDE/p8K","pt":1657540442978,"mc":[{"id":"1.200806927","rc":[{"atl":[[1.1,1960.05]],"trd":[[1.1,2205.27]],"tv":74807.91,"id":228749},{"trd":[[11,11.58]],"tv":6616.95,"id":2857977}],"tv":81424.86}]}
{"op":"mcm","clk":"AILVqwkAk9OcCgD0/p8K","pt":1657540443557,"mc":[{"id":"1.200806927","rc":[{"atl":[[1.3,130.46]],"id":228749}]}]}
{"op":"mcm","clk":"AJbVqwkAqtOcCgCC/58K","pt":1657540443767,"mc":[{"id":"1.200806927","rc":[{"atl":[[1.1,1957.9]],"trd":[[1.1,2207.42]],"tv":74810.06,"id":228749},{"trd":[[11,11.79]],"tv":6617.16,"id":2857977}],"tv":81427.22}]}
{"op":"mcm","clk":"ALnVqwkA1NOcCgCc/58K","pt":1657540444173,"mc":[{"id":"1.200806927","rc":[{"atl":[[1.11,823.11]],"id":228749}]}]}
{"op":"mcm","clk":"AMHVqwkA4dOcCgCi/58K","pt":1657540444270,"mc":[{"id":"1.200806927","rc":[{"atl":[[1.14,19.49]],"id":228749}]}]}
{"op":"mcm","clk":"AOrVqwkAkdScCgC8/58K","pt":1657540444662,"mc":[{"id":"1.200806927","rc":[{"atl":[[1.1,1957.05]],"trd":[[1.1,2209.11]],"tv":74811.75,"id":228749}],"tv":81428.91}]}
{"op":"mcm","clk":"APnVqwkAp9ScCgDE/58K","pt":1657540444883,"mc":[{"id":"1.200806927","rc":[{"atl":[[1.1,1948.69]],"trd":[[1.1,2225.83]],"tv":74828.47,"id":228749}],"tv":81445.63}]}
{"op":"mcm","clk":"AI7WqwkAy9ScCgDX/58K","pt":1657540445158,"mc":[{"id":"1.200806927","rc":[{"atl":[[1.1,1943.39]],"trd":[[1.1,2231.13]],"tv":74833.77,"id":228749},{"trd":[[11,12.32]],"tv":6617.69,"id":2857977}],"tv":81451.46}]}
{"op":"mcm","clk":"AK3WqwkA79ScCgDq/58K","pt":1657540445465,"mc":[{"id":"1.200806927","rc":[{"atb":[[1.03,67.97]],"id":228749}]}]}
{"op":"mcm","clk":"AMzWqwkAmNWcCgCCgKAK","pt":1657540445885,"mc":[{"id":"1.200806927","rc":[{"atb":[[1.03,67.69]],"id":228749}]}]}
{"op":"mcm","clk":"AMnXqwkArdacCgDMgKAK","pt":1657540447252,"mc":[{"id":"1.200806927","rc":[{"atl":[[1.1,1941.81]],"id":228749}]}]}
{"op":"mcm","clk":"AITYqwkAgtecCgD5gKAK","pt":1657540447982,"mc":[{"id":"1.200806927","rc":[{"atl":[[1.09,10.52]],"id":228749}]}]}
{"op":"mcm","clk":"AInYqwkAkNecCgCAgaAK","pt":1657540448078,"mc":[{"id":"1.200806927","rc":[{"atl":[[1.12,613.75]],"id":228749}]}]}
{"op":"mcm","clk":"AKPYqwkAsNecCgCSgaAK","pt":1657540448355,"mc":[{"id":"1.200806927","rc":[{"atl":[[1.09,5.26]],"id":228749}]}]}
{"op":"mcm","clk":"AI/ZqwkAzticCgDcgaAK","pt":1657540449713,"mc":[{"id":"1.200806927","rc":[{"atl":[[1.1,1933.92],[1.09,0]],"id":228749}]}]}
{"op":"mcm","clk":"AMnZqwkAxdmcCgCVgqAK","pt":1657540450376,"mc":[{"id":"1.200806927","rc":[{"atl":[[1.1,2091.69]],"id":228749}]}]}
{"op":"mcm","clk":"ANXZqwkAztmcCgCbgqAK","pt":1657540450489,"mc":[{"id":"1.200806927","rc":[{"atl":[[1.09,586.05]],"id":228749}]}]}
{"op":"mcm","clk":"APnZqwkA/dmcCgC4gqAK","pt":1657540450867,"mc":[{"id":"1.200806927","rc":[{"atl":[[1.09,583.42]],"id":228749}]}]}
{"op":"mcm","clk":"AIDaqwkAjNqcCgDAgqAK","pt":1657540450968,"mc":[{"id":"1.200806927","rc":[{"atl":[[1.09,583.14]],"trd":[[1.09,41.4]],"ltp":1.09,"tv":74834.34,"id":228749}],"tv":81452.03}]}
{"op":"mcm","clk":"AKjaqwkAt9qcCgDagqAK","pt":1657540451381,"mc":[{"id":"1.200806927","rc":[{"atb":[[1.03,66.85]],"id":228749}]}]}
{"op":"mcm","clk":"ANjaqwkA5dqcCgDsgqAK","pt":1657540451864,"mc":[{"id":"1.200806927","rc":[{"atl":[[1.09,585.77]],"id":228749}]}]}
{"op":"mcm","clk":"AJHcqwkAxdycCgDcg6AK","pt":1657540453966,"mc":[{"id":"1.200806927","rc":[{"atl":[[1.09,571.56]],"trd":[[1.09,55.61]],"tv":74848.55,"id":228749},{"trd":[[12,1.29]],"ltp":12,"tv":6618.98,"id":2857977}],"tv":81467.53}]}
{"op":"mcm","clk":"AL3cqwkAht2cCgD8g6AK","pt":1657540454586,"mc":[{"id":"1.200806927","rc":[{"atl":[[1.09,571.45]],"trd":[[1.09,55.82]],"tv":74848.76,"id":228749}],"tv":81467.74}]}
{"op":"mcm","clk":"AMzcqwkAl92cCgCFhKAK","pt":1657540454780,"mc":[{"id":"1.200806927","rc":[{"atl":[[1.09,569.08]],"trd":[[1.09,58.19]],"tv":74851.13,"id":228749},{"trd":[[12,1.51]],"tv":6619.2,"id":2857977}],"tv":81470.33}]}
{"op":"mcm","clk":"AJ3dqwkAjd6cCgC4hKAK","pt":1657540455673,"mc":[{"id":"1.200806927","rc":[{"atl":[[1.09,547.56]],"trd":[[1.09,101.23]],"tv":74894.17,"id":228749}],"tv":81513.37}]}
{"op":"mcm","clk":"AI7eqwkAnd+cCgCBhaAK","pt":1657540456998,"mc":[{"id":"1.200806927","rc":[{"atl":[[1.09,537.04]],"id":228749}]}]}
{"op":"mcm","clk":"AKHeqwkAsd+cCgCPhaAK","pt":1657540457197,"mc":[{"id":"1.200806927","rc":[{"atl":[[1.09,532.3]],"trd":[[1.09,105.97]],"tv":74898.91,"id":228749},{"trd":[[12,1.94]],"tv":6619.63,"id":2857977}],"tv":81518.54}]}
{"op":"mcm","clk":"AMveqwkAz9+cCgCihaAK","pt":1657540457573,"mc":[{"id":"1.200806927","rc":[{"atb":[[1.08,0]],"atl":[[1.08,746.45]],"trd":[[1.08,2102.47]],"ltp":1.08,"tv":77001.38,"id":228749},{"atl":[[13,0]],"trd":[[13,0.92]],"ltp":13,"tv":6620.55,"id":2857977}],"tv":83621.93}]}
{"op":"mcm","clk":"ANLeqwkA2N+cCgCqhaAK","pt":1657540457677,"mc":[{"id":"1.200806927","rc":[{"atl":[[1.08,735.93]],"id":228749}]}]}
{"op":"mcm","clk":"AIPfqwkAguCcCgDQhaAK","pt":1657540458204,"mc":[{"id":"1.200806927","rc":[{"atl":[[1.08,742.55]],"id":228749}]}]}
{"op":"mcm","clk":"AJffqwkAluCcCgDahaAK","pt":1657540458378,"mc":[{"id":"1.200806927","rc":[{"atl":[[1.1,1881.32]],"id":228749}]}]}
{"op":"mcm","clk":"AJ/fqwkApuCcCgDhhaAK","pt":1657540458473,"mc":[{"id":"1.200806927","rc":[{"atl":[[1.11,612.74]],"id":228749}]}]}
{"op":"mcm","clk":"AIXgqwkAquGcCgCxhqAK","pt":1657540459775,"mc":[{"id":"1.200806927","rc":[{"atl":[[1.08,741.22]],"trd":[[1.08,2103.8]],"tv":77002.71,"id":228749},{"trd":[[13.5,0.11]],"ltp":13.5,"tv":6620.66,"id":2857977}],"tv":83623.37}]}
{"op":"mcm","clk":"AMrgqwkA3eGcCgDYhqAK","pt":1657540460409,"mc":[{"id":"1.200806927","rc":[{"atl":[[1.08,735.96]],"id":228749}]}]}
{"op":"mcm","clk":"ANrgqwkA8OGcCgDihqAK","pt":1657540460574,"mc":[{"id":"1.200806927","rc":[{"atl":[[1.08,735.43]],"id":228749}]}]}
{"op":"mcm","clk":"APbgqwkAluKcCgDthqAK","pt":1657540460883,"mc":[{"id":"1.200806927","rc":[{"atl":[[1.08,734.44]],"id":228749}]}]}
{"op":"mcm","clk":"AIfhqwkAruKcCgD1hqAK","pt":1657540461089,"mc":[{"id":"1.200806927","rc":[{"atl":[[1.08,734.01]],"trd":[[1.08,2104.66]],"tv":77003.57,"id":228749}],"tv":83624.23}]}
{"op":"mcm","clk":"AP/iqwkAxeScCgCbiKAK","pt":1657540463812,"mc":[{"id":"1.200806927","rc":[{"atl":[[1.08,731.38]],"id":228749}]}]}
{"op":"mcm","clk":"AI/jqwkA2+ScCgCliKAK","pt":1657540464018,"mc":[{"id":"1.200806927","rc":[{"atl":[[1.1,1723.55]],"id":228749}]}]}
{"op":"mcm","clk":"AJjjqwkA5eScCgCsiKAK","pt":1657540464095,"mc":[{"id":"1.200806927","rc":[{"atl":[[17.5,52.59]],"id":2857977}]}]}
{"op":"mcm","clk":"AKHjqwkA7+ScCgCxiKAK","pt":1657540464178,"mc":[{"id":"1.200806927","rc":[{"atl":[[1.08,730.59]],"id":228749}]}]}
{"op":"mcm","clk":"AMLjqwkAiuWcCgDBiKAK","pt":1657540464481,"mc":[{"id":"1.200806927","rc":[{"atl":[[1.08,720.07]],"id":228749}]}]}
{"op":"mcm","clk":"ANTjqwkAnOWcCgDQiKAK","pt":1657540464692,"mc":[{"id":"1.200806927","rc":[{"atl":[[1000,0.49]],"id":228749}]}]}
{"op":"mcm","clk":"APzjqwkAwOWcCgDjiKAK","pt":1657540465103,"mc":[{"id":"1.200806927","rc":[{"atl":[[1000,0.13]],"id":228749}]}]}
{"op":"mcm","clk":"AKrkqwkA9OWcCgCRiaAK","pt":1657540465695,"mc":[{"id":"1.200806927","rc":[{"atl":[[1.08,701.19]],"trd":[[1.08,2121.38]],"tv":77020.29,"id":228749}],"tv":83640.95}]}
{"op":"mcm","clk":"AN/kqwkAu+acCgC3iaAK","pt":1657540466337,"mc":[{"id":"1.200806927","rc":[{"atl":[[1.08,688.24]],"id":228749}]}]}
{"op":"mcm","clk":"AJPlqwkAg+ecCgDWiaAK","pt":1657540466914,"mc":[{"id":"1.200806927","rc":[{"atl":[[1.08,687.71]],"id":228749}]}]}
{"op":"mcm","clk":"AJ7mqwkA2OicCgC0iqAK","pt":1657540468787,"mc":[{"id":"1.200806927","rc":[{"atb":[[1.05,824.66]],"id":228749}]}]}
{"op":"mcm","clk":"ALjmqwkAgOmcCgDLiqAK","pt":1657540469196,"mc":[{"id":"1.200806927","rc":[{"atl":[[1.08,681.87]],"trd":[[1.08,2124.59]],"tv":77023.5,"id":228749},{"trd":[[13.5,0.36]],"tv":6620.91,"id":2857977}],"tv":83644.41}]}
{"op":"mcm","clk":"ANXmqwkAmemcCgDhiqAK","pt":1657540469511,"mc":[{"id":"1.200806927","rc":[{"atl":[[1.08,680.07]],"id":228749}]}]}
{"op":"mcm","clk":"APfmqwkAw+mcCgD3iqAK","pt":1657540469882,"mc":[{"id":"1.200806927","rc":[{"atl":[[1.08,677.38]],"trd":[[1.08,2127.28]],"tv":77026.19,"id":228749},{"trd":[[13.5,0.58]],"tv":6621.13,"id":2857977}],"tv":83647.32}]}
{"op":"mcm","clk":"AP/mqwkAzumcCgCAi6AK","pt":1657540469996,"mc":[{"id":"1.200806927","rc":[{"atb":[[1.04,227.46]],"id":228749}]}]}
{"op":"mcm","clk":"AI/nqwkA4emcCgCKi6AK","pt":1657540470201,"mc":[{"id":"1.200806927","rc":[{"atl":[[1.08,673.85]],"id":228749}]}]}
{"op":"mcm","clk":"AJfnqwkA7OmcCgCTi6AK","pt":1657540470301,"mc":[{"id":"1.200806927","rc":[{"atl":[[1.08,667.22]],"trd":[[1.08,2133.91]],"tv":77032.82,"id":228749},{"trd":[[13.5,1.11]],"tv":6621.66,"id":2857977}],"tv":83654.48}]}
{"op":"mcm","clk":"AMXnqwkAp+qcCgC6i6AK","pt":1657540470888,"mc":[{"id":"1.200806927","rc":[{"atl":[[1.08,666.86]],"id":228749}]}]}
{"op":"mcm","clk":"ANbnqwkAwOqcCgDIi6AK","pt":1657540471085,"mc":[{"id":"1.200806927","rc":[{"atl":[[1.08,661.6]],"id":228749}]}]}
{"op":"mcm","clk":"AJvoqwkAneucCgCLjKAK","pt":1657540472033,"mc":[{"id":"1.200806927","rc":[{"atl":[[1.08,661.07]],"id":228749}]}]}
{"op":"mcm","clk":"AI7pqwkAtuycCgD3jKAK","pt":1657540473615,"mc":[{"id":"1.200806927","rc":[{"atl":[[1.08,659.49]],"id":228749}]}]}
{"op":"mcm","clk":"AK3pqwkA4+ycCgCMjaAK","pt":1657540474023,"mc":[{"id":"1.200806927","rc":[{"atl":[[1.08,654.53]],"id":228749}]}]}
{"op":"mcm","clk":"ALbpqwkA7uycCgCPjaAK","pt":1657540474125,"mc":[{"id":"1.200806927","rc":[{"atl":[[1.08,649.27]],"id":228749}]}]}
{"op":"mcm","clk":"ANDpqwkAj+2cCgCfjaAK","pt":1657540474399,"mc":[{"id":"1.200806927","rc":[{"atl":[[1.08,646.68]],"id":228749}]}]}
{"op":"mcm","clk":"AIDqqwkA6+2cCgDIjaAK","pt":1657540475285,"mc":[{"id":"1.200806927","rc":[{"atb":[[1.07,693.06]],"trd":[[1.07,27.94]],"ltp":1.07,"tv":77060.76,"id":228749}],"tv":83682.42}]}
{"op":"mcm","clk":"AN/qqwkA/+6cCgCIjqAK","pt":1657540476594,"mc":[{"id":"1.200806927","rc":[{"atl":[[1.08,646.15]],"id":228749}]}]}
{"op":"mcm","clk":"APHqqwkAku+cCgCSjqAK","pt":1657540476806,"mc":[{"id":"1.200806927","rc":[{"atl":[[1.08,644.82]],"trd":[[1.08,2135.24]],"ltp":1.08,"tv":77062.09,"id":228749},{"trd":[[13.5,1.21]],"tv":6621.76,"id":2857977}],"tv":83683.85}]}
{"op":"mcm","clk":"APXqqwkAne+cCgCbjqAK","pt":1657540476912,"mc":[{"id":"1.200806927","rc":[{"atl":[[1.08,642.19]],"id":228749}]}]}
{"op":"mcm","clk":"AMXrqwkAg/CcCgDNjqAK","pt":1657540477889,"mc":[{"id":"1.200806927","rc":[{"atb":[[1.02,129.04]],"id":228749}]}]}
{"op":"mcm","clk":"ANPrqwkAmPCcCgDZjqAK","pt":1657540478110,"mc":[{"id":"1.200806927","rc":[{"atl":[[1.08,640.86]],"trd":[[1.08,2136.57]],"tv":77063.42,"id":228749},{"trd":[[13.5,1.32]],"tv":6621.87,"id":2857977}],"tv":83685.29}]}
{"op":"mcm","clk":"AOLrqwkAp/CcCgDgjqAK","pt":1657540478299,"mc":[{"id":"1.200806927","rc":[{"atl":[[1.11,605.9]],"id":228749}]}]}
{"op":"mcm","clk":"AOzrqwkAtPCcCgDmjqAK","pt":1657540478436,"mc":[{"id":"1.200806927","rc":[{"atl":[[1.08,605.6]],"trd":[[1.08,2180.19]],"tv":77107.04,"id":228749},{"trd":[[13.5,3.47]],"tv":6624.02,"id":2857977}],"tv":83731.06}]}
{"op":"mcm","clk":"APvrqwkAxvCcCgDvjqAK","pt":1657540478621,"mc":[{"id":"1.200806927","rc":[{"atl":[[1.08,604.55]],"id":228749}]}]}
{"op":"mcm","clk":"AIzsqwkA2fCcCgD2jqAK","pt":1657540478826,"mc":[{"id":"1.200806927","rc":[{"atl":[[1.08,602.39]],"trd":[[1.08,2182.35]],"tv":77109.2,"id":228749},{"trd":[[13.5,3.65]],"tv":6624.2,"id":2857977}],"tv":83733.4}]}
{"op":"mcm","clk":"AJHsqwkA4/CcCgD5jqAK","pt":1657540478915,"mc":[{"id":"1.200806927","rc":[{"atl":[[1.08,597.78]],"trd":[[1.08,2184.33]],"tv":77111.18,"id":228749},{"trd":[[13.5,3.8]],"tv":6624.35,"id":2857977}],"tv":83735.53}]}
{"op":"mcm","clk":"AJXsqwkA7vCcCgD+jqAK","pt":1657540478991,"mc":[{"id":"1.200806927","rc":[{"atl":[[1.08,592.52]],"id":228749}]}]}
{"op":"mcm","clk":"AMnsqwkAo/GcCgCZj6AK","pt":1657540479632,"mc":[{"id":"1.200806927","rc":[{"atl":[[1.12,406.64]],"id":228749}]}]}
{"op":"mcm","clk":"ANrsqwkAtPGcCgCkj6AK","pt":1657540479806,"mc":[{"id":"1.200806927","rc":[{"atl":[[1.08,579.57],[1.09,1370.21]],"id":228749}]}]}
{"op":"mcm","clk":"AI3tqwkA9vGcCgDAj6AK","pt":1657540480436,"mc":[{"id":"1.200806927","rc":[{"atl":[[1.08,49.24]],"id":228749}]}]}
{"op":"mcm","clk":"AJXtqwkAgfKcCgDEj6AK","pt":1657540480531,"mc":[{"id":"1.200806927","rc":[{"atl":[[1.08,29.97]],"trd":[[1.08,2203.6]],"tv":77130.45,"id":228749},{"trd":[[13.5,5.35]],"tv":6625.9,"id":2857977}],"tv":83756.35}]}
{"op":"mcm","clk":"AKztqwkAnfKcCgDQj6AK","pt":1657540480803,"mc":[{"id":"1.200806927","rc":[{"atl":[[1.08,26.85]],"trd":[[1.08,2207.15]],"tv":77134,"id":228749},{"trd":[[13.5,5.56]],"tv":6626.11,"id":2857977}],"tv":83760.11}]}
{"op":"mcm","clk":"ALftqwkAq/KcCgDWj6AK","pt":1657540480894,"mc":[{"id":"1.200806927","rc":[{"atl":[[1.08,17.83]],"id":228749}]}]}
{"op":"mcm","clk":"AMTtqwkAtfKcCgDbj6AK","pt":1657540481016,"mc":[{"id":"1.200806927","rc":[{"atl":[[1.08,17.04]],"id":228749}]}]}
{"op":"mcm","clk":"AIXuqwkAkvOcCgCWkKAK","pt":1657540482009,"mc":[{"id":"1.200806927","rc":[{"atl":[[1.08,16.36]],"id":228749}]}]}
{"op":"mcm","clk":"ALTuqwkA4vOcCgDJkKAK","pt":1657540482839,"mc":[{"id":"1.200806927","rc":[{"atl":[[1.08,13.73]],"id":228749}]}]}
{"op":"mcm","clk":"ANruqwkAiPScCgDikKAK","pt":1657540483206,"mc":[{"id":"1.200806927","rc":[{"atb":[[1.08,0.43]],"atl":[[1.08,0]],"trd":[[1.08,2231.98]],"tv":77158.83,"id":228749}],"tv":83784.94}]}
{"op":"mcm","clk":"AOTuqwkAkvScCgDnkKAK","pt":1657540483308,"mc":[{"id":"1.200806927","rc":[{"atb":[[1.05,825.71]],"id":228749}]}]}
{"op":"mcm","clk":"APDuqwkAnfScCgDtkKAK","pt":1657540483420,"mc":[{"id":"1.200806927","rc":[{"atl":[[1000,0.33]],"id":228749}]}]}
{"op":"mcm","clk":"AI7vqwkAx/ScCgCDkaAK","pt":1657540483821,"mc":[{"id":"1.200806927","rc":[{"atl":[[1000,0.13]],"id":228749}]}]}
{"op":"mcm","clk":"AJ/vqwkA3fScCgCTkaAK","pt":1657540484033,"mc":[{"id":"1.200806927","rc":[{"atl":[[13.5,0.11]],"id":2857977}]}]}
{"op":"mcm","clk":"APTvqwkA0PWcCgDSkaAK","pt":1657540485141,"mc":[{"id":"1.200806927","rc":[{"atb":[[1.08,2.8]],"id":228749}]}]}
{"op":"mcm","clk":"AIHwqwkA4PWcCgDbkaAK","pt":1657540485340,"mc":[{"id":"1.200806927","rc":[{"atb":[[1.06,582.93]],"id":228749}]}]}
{"op":"mcm","clk":"AJDwqwkA9PWcCgDmkaAK","pt":1657540485516,"mc":[{"id":"1.200806927","rc":[{"atb":[[1.08,3.33]],"id":228749}]}]}
{"op":"mcm","clk":"AMrwqwkAufacCgCEkqAK","pt":1657540486337,"mc":[{"id":"1.200806927","rc":[{"atb":[[1.08,3.2]],"trd":[[1.08,2232.24]],"tv":77159.09,"id":228749}],"tv":83785.2}]}
{"op":"mcm","clk":"AJzyqwkAwficCgCmk6AK","pt":1657540488255,"mc":[{"id":"1.200806927","rc":[{"atb":[[1.08,4.04]],"id":228749}]}]}
{"op":"mcm","clk":"AKzyqwkA1ficCgC0k6AK","pt":1657540488444,"mc":[{"id":"1.200806927","rc":[{"atb":[[1.07,694.37]],"id":228749}]}]}
{"op":"mcm","clk":"AL/yqwkA5ficCgC9k6AK","pt":1657540488656,"mc":[{"id":"1.200806927","rc":[{"atb":[[1.08,6.67]],"id":228749}]}]}
{"op":"mcm","clk":"ANHyqwkAhPmcCgDNk6AK","pt":1657540488972,"mc":[{"id":"1.200806927","rc":[{"atb":[[1.08,6.47]],"trd":[[1.08,2232.64]],"tv":77159.49,"id":228749}],"tv":83785.6}]}
{"op":"mcm","clk":"AO3yqwkAsfmcCgDlk6AK","pt":1657540489455,"mc":[{"id":"1.200806927","rc":[{"atb":[[1.08,32.77]],"id":228749}]}]}
{"op":"mcm","clk":"APTyqwkAvvmcCgDvk6AK","pt":1657540489564,"mc":[{"id":"1.200806927","rc":[{"atb":[[1.08,166.52]],"id":228749}]}]}
{"op":"mcm","clk":"AIXzqwkA0PmcCgD5k6AK","pt":1657540489767,"mc":[{"id":"1.200806927","rc":[{"atb":[[1.07,702.73]],"id":228749}]}]}
{"op":"mcm","clk":"AJbzqwkA3/mcCgD/k6AK","pt":1657540489956,"mc":[{"id":"1.200806927","rc":[{"atl":[[13.5,1.15]],"id":2857977}]}]}
{"op":"mcm","clk":"AKfzqwkA8PmcCgCJlKAK","pt":1657540490178,"mc":[{"id":"1.200806927","rc":[{"atl":[[13.5,2.2]],"id":2857977}]}]}
{"op":"mcm","clk":"AKzzqwkA+PmcCgCNlKAK","pt":1657540490279,"mc":[{"id":"1.200806927","rc":[{"atl":[[13.5,4.29]],"id":2857977}]}]}
{"op":"mcm","clk":"ALbzqwkAjvqcCgCWlKAK","pt":1657540490432,"mc":[{"id":"1.200806927","rc":[{"atl":[[1.09,1349.71]],"trd":[[1.09,125.79]],"ltp":1.09,"tv":77179.31,"id":228749},{"trd":[[12,3.74]],"ltp":12,"tv":6627.91,"id":2857977}],"tv":83807.22}]}
{"op":"mcm","clk":"AMTzqwkAovqcCgCklKAK","pt":1657540490653,"mc":[{"id":"1.200806927","rc":[{"atl":[[13.5,4.82]],"id":2857977}]}]}
{"op":"mcm","clk":"ANrzqwkAv/qcCgC2lKAK","pt":1657540490954,"mc":[{"id":"1.200806927","rc":[{"atb":[[1.08,164.15]],"id":228749}]}]}
{"op":"mcm","clk":"AO/zqwkA1vqcCgDClKAK","pt":1657540491166,"mc":[{"id":"1.200806927","rc":[{"atl":[[13.5,4.93]],"id":2857977}]}]}
{"op":"mcm","clk":"AK70qwkAtfucCgDqlKAK","pt":1657540491966,"mc":[{"id":"1.200806927","rc":[{"atb":[[1.02,30.27],[1.03,1]],"id":228749}]}]}
{"op":"mcm","clk":"ALz0qwkA1vucCgD1lKAK","pt":1657540492180,"mc":[{"id":"1.200806927","rc":[{"atb":[[1.08,165.46]],"id":228749}]}]}
{"op":"mcm","clk":"AMT1qwkA8vycCgDHlaAK","pt":1657540493744,"mc":[{"id":"1.200806927","rc":[{"atb":[[1.08,170.72]],"id":228749}]}]}
{"op":"mcm","clk":"APP1qwkArP2cCgDolaAK","pt":1657540494356,"mc":[{"id":"1.200806927","rc":[{"atb":[[1.03,1.84]],"id":228749}]}]}
{"op":"mcm","clk":"AK72qwkA8/2cCgCVlqAK","pt":1657540495143,"mc":[{"id":"1.200806927","rc":[{"atl":[[1.09,1348.13]],"id":228749}]}]}
{"op":"mcm","clk":"AID3qwkAyv6cCgDHlqAK","pt":1657540496080,"mc":[{"id":"1.200806927","rc":[{"atb":[[1.08,173.35]],"id":228749}]}]}
{"op":"mcm","clk":"ALH3qwkAl/+cCgDqlqAK","pt":1657540496750,"mc":[{"id":"1.200806927","rc":[{"atl":[[1.09,1345.93]],"trd":[[1.09,127.99]],"tv":77181.51,"id":228749},{"trd":[[12,3.94]],"tv":6628.11,"id":2857977}],"tv":83809.62}]}
{"op":"mcm","clk":"AMv3qwkAwf+cCgD6lqAK","pt":1657540497071,"mc":[{"id":"1.200806927","rc":[{"atl":[[1.09,1340.1]],"trd":[[1.09,133.82]],"tv":77187.34,"id":228749},{"trd":[[12,4.47]],"tv":6628.64,"id":2857977}],"tv":83815.98}]}
{"op":"mcm","clk":"AOD3qwkA1/+cCgCEl6AK","pt":1657540497284,"mc":[{"id":"1.200806927","rc":[{"atl":[[1.09,1336.93]],"trd":[[1.09,136.99]],"tv":77190.51,"id":228749},{"trd":[[12,4.75]],"tv":6628.92,"id":2857977}],"tv":83819.43}]}
{"op":"mcm","clk":"APT3qwkA8v+cCgCUl6AK","pt":1657540497550,"mc":[{"id":"1.200806927","rc":[{"atl":[[1.09,1334.83]],"id":228749}]}]}
{"op":"mcm","clk":"ALD4qwkArICdCgCwl6AK","pt":1657540498282,"mc":[{"id":"1.200806927","rc":[{"atb":[[1.08,188.76]],"id":228749}]}]}
{"op":"mcm","clk":"AMv4qwkAy4CdCgC6l6AK","pt":1657540498577,"mc":[{"id":"1.200806927","rc":[{"atl":[[1.09,1329]],"trd":[[1.09,142.82]],"tv":77196.34,"id":228749},{"trd":[[12,5.28]],"tv":6629.45,"id":2857977}],"tv":83825.79}]}
{"op":"mcm","clk":"AMb5qwkA+oGdCgCgmKAK","pt":1657540499782,"mc":[{"id":"1.200806927","rc":[{"atb":[[1.03,2.06]],"id":228749}]}]}
{"op":"mcm","clk":"AOP5qwkAn4KdCgC0mKAK","pt":1657540500193,"mc":[{"id":"1.200806927","rc":[{"atb":[[1.03,1.84]],"id":228749}]}]}
{"op":"mcm","clk":"AMz6qwkApYOdCgD5mKAK","pt":1657540501051,"mc":[{"id":"1.200806927","rc":[{"atl":[[1.09,1327.74]],"id":228749}]}]}
{"op":"mcm","clk":"ANX6qwkAsoOdCgD/mKAK","pt":1657540501158,"mc":[{"id":"1.200806927","rc":[{"atl":[[1.09,1323.34]],"trd":[[1.09,147.22]],"tv":77200.74,"id":228749},{"trd":[[12,5.68]],"tv":6629.85,"id":2857977}],"tv":83830.59}]}
{"op":"mcm","clk":"AI/8qwkAw4WdCgCimqAK","pt":1657540502761,"mc":[{"id":"1.200806927","rc":[{"atb":[[1.06,591.29]],"atl":[[1.09,1322.17]],"trd":[[1.09,148.39]],"tv":77201.91,"id":228749},{"trd":[[12,5.79]],"tv":6629.96,"id":2857977}],"tv":83831.87}]}
{"op":"mcm","clk":"ALz8qwkAi4adCgDKmqAK","pt":1657540503359,"mc":[{"id":"1.200806927","rc":[{"atl":[[1.09,1321.07]],"trd":[[1.09,149.49]],"tv":77203.01,"id":228749},{"trd":[[12,5.89]],"tv":6630.06,"id":2857977}],"tv":83833.07}]}
{"op":"mcm","clk":"AMf8qwkAoIadCgDXmqAK","pt":1657540503584,"mc":[{"id":"1.200806927","rc":[{"atl":[[1.09,1315.38]],"trd":[[1.09,155.18]],"tv":77208.7,"id":228749},{"trd":[[12,6.41]],"tv":6630.58,"id":2857977}],"tv":83839.28}]}
{"op":"mcm","clk":"AM38qwkAqoadCgDfmqAK","pt":1657540503710,"mc":[{"id":"1.200806927","rc":[{"atl":[[1.09,1313.82]],"trd":[[1.09,156.74]],"tv":77210.26,"id":228749},{"trd":[[12,6.55]],"tv":6630.72,"id":2857977}],"tv":83840.98}]}
{"op":"mcm","clk":"ANf8qwkAwoadCgDpmqAK","pt":1657540503861,"mc":[{"id":"1.200806927","rc":[{"atl":[[1.09,1311.19]],"id":228749}]}]}
{"op":"mcm","clk":"AIv9qwkAgoedCgCIm6AK","pt":1657540504482,"mc":[{"id":"1.200806927","rc":[{"atb":[[1.05,903.38]],"id":228749}]}]}
{"op":"mcm","clk":"AKP9qwkAs4edCgCom6AK","pt":1657540504975,"mc":[{"id":"1.200806927","rc":[{"atl":[[1.09,1309.61]],"id":228749}]}]}
{"op":"mcm","clk":"ALj9qwkAzYedCgC0m6AK","pt":1657540505208,"mc":[{"id":"1.200806927","rc":[{"atl":[[1.09,1308.82]],"id":228749}]}]}
{"op":"mcm","clk":"AMf9qwkA24edCgC6m6AK","pt":1657540505303,"mc":[{"id":"1.200806927","rc":[{"atl":[[1.09,1308.59]],"trd":[[1.09,157.2]],"tv":77210.72,"id":228749}],"tv":83841.44}]}
{"op":"mcm","clk":"ANH9qwkA5YedCgC+m6AK","pt":1657540505409,"mc":[{"id":"1.200806927","rc":[{"atl":[[1.09,1308.06]],"id":228749}]}]}
{"op":"mcm","clk":"AOz9qwkAjYidCgDWm6AK","pt":1657540505686,"mc":[{"id":"1.200806927","rc":[{"atb":[[1.03,1]],"id":228749}]}]}
{"op":"mcm","clk":"AJT+qwkAvIidCgDvm6AK","pt":1657540506158,"mc":[{"id":"1.200806927","rc":[{"atl":[[1.09,1279.11]],"trd":[[1.09,186.15]],"tv":77239.67,"id":228749},{"trd":[[12,9.18]],"tv":6633.35,"id":2857977}],"tv":83873.02}]}
{"op":"mcm","clk":"AL7/qwkA/4mdCgDdnKAK","pt":1657540507993,"mc":[{"id":"1.200806927","rc":[{"atl":[[1.09,1277.02]],"trd":[[1.09,188.24]],"tv":77241.76,"id":228749},{"trd":[[12,9.37]],"tv":6633.54,"id":2857977}],"tv":83875.3}]}
{"op":"mcm","clk":"ANv/qwkAo4qdCgDxnKAK","pt":1657540508359,"mc":[{"id":"1.200806927","rc":[{"atl":[[1.09,1273.21]],"trd":[[1.09,189.42]],"tv":77242.94,"id":228749},{"trd":[[12,9.48]],"tv":6633.65,"id":2857977}],"tv":83876.59}]}
{"op":"mcm","clk":"AIWArAkA34qdCgCcnaAK","pt":1657540509001,"mc":[{"id":"1.200806927","rc":[{"atb":[[1.08,196.65]],"atl":[[1.09,1270.62]],"id":228749}]}]}
{"op":"mcm","clk":"AKCArAkA+4qdCgCsnaAK","pt":1657540509288,"mc":[{"id":"1.200806927","rc":[{"atl":[[1.09,1269.45]],"trd":[[1.09,190.59]],"tv":77244.11,"id":228749},{"trd":[[12,9.58]],"tv":6633.75,"id":2857977}],"tv":83877.86}]}
{"op":"mcm","clk":"AKKArAkAhYudCgCwnaAK","pt":1657540509388,"mc":[{"id":"1.200806927","rc":[{"atl":[[1.1,0]],"id":228749}]}]}
{"op":"mcm","clk":"AKyArAkAj4udCgC0naAK","pt":1657540509495,"mc":[{"id":"1.200806927","rc":[{"atl":[[13.5,4.82]],"id":2857977}]}]}
{"op":"mcm","clk":"APyArAkAhIydCgD9naAK","pt":1657540510589,"mc":[{"id":"1.200806927","rc":[{"atl":[[1.09,1259.54]],"trd":[[1.09,200.5]],"tv":77254.02,"id":228749},{"trd":[[12,10.48]],"tv":6634.65,"id":2857977}],"tv":83888.67}]}
{"op":"mcm","clk":"ALKBrAkAy4ydCgCenqAK","pt":1657540511281,"mc":[{"id":"1.200806927","rc":[{"atb":[[1.08,181.24]],"id":228749}]}]}
{"op":"mcm","clk":"ALqBrAkA14ydCgCjnqAK","pt":1657540511388,"mc":[{"id":"1.200806927","rc":[{"atb":[[1.08,176.93]],"id":228749}]}]}
{"op":"mcm","clk":"AIWCrAkAto2dCgDWnqAK","pt":1657540512404,"mc":[{"id":"1.200806927","rc":[{"atl":[[1.09,1254.28]],"id":228749}]}]}
{"op":"mcm","clk":"AImCrAkAwo2dCgDbnqAK","pt":1657540512474,"mc":[{"id":"1.200806927","rc":[{"atl":[[1.09,1244.8]],"trd":[[1.09,209.98]],"tv":77263.5,"id":228749},{"trd":[[12,11.34]],"tv":6635.51,"id":2857977}],"tv":83899.01}]}
{"op":"mcm","clk":"AJCCrAkAzo2dCgDgnqAK","pt":1657540512577,"mc":[{"id":"1.200806927","rc":[{"atl":[[1.09,1244.7]],"trd":[[1.09,210.18]],"tv":77263.7,"id":228749}],"tv":83899.21}]}
{"op":"mcm","clk":"AOmCrAkAvo6dCgCOn6AK","pt":1657540513683,"mc":[{"id":"1.200806927","rc":[{"atl":[[14.5,2.63]],"id":2857977}]}]}
{"op":"mcm","clk":"APuCrAkAz46dCgCZn6AK","pt":1657540513893,"mc":[{"id":"1.200806927","rc":[{"atb":[[1.08,0]],"trd":[[1.08,2267.97]],"ltp":1.08,"tv":77299.03,"id":228749},{"atl":[[13.5,2.15]],"trd":[[13.5,8.24]],"ltp":13.5,"tv":6638.19,"id":2857977}],"tv":83937.22}]}
{"op":"mcm","clk":"AJODrAkA9o6dCgCtn6AK","pt":1657540514292,"mc":[{"id":"1.200806927","rc":[{"atl":[[1.09,1243.6]],"trd":[[1.09,211.28]],"ltp":1.09,"tv":77300.13,"id":228749},{"trd":[[12,11.44]],"ltp":12,"tv":6638.29,"id":2857977}],"tv":83938.42}]}
{"op":"mcm","clk":"AIWErAkA/Y+dCgDun6AK","pt":1657540515507,"mc":[{"id":"1.200806927","rc":[{"atb":[[1.07,702.84]],"id":228749}]}]}
{"op":"mcm","clk":"AIaFrAkAs5GdCgCyoKAK","pt":1657540517190,"mc":[{"id":"1.200806927","rc":[{"atb":[[1.05,911.74]],"id":228749}]}]}
{"op":"mcm","clk":"AJqFrAkAy5GdCgC+oKAK","pt":1657540517409,"mc":[{"id":"1.200806927","rc":[{"atl":[[1.09,1242.02]],"trd":[[1.08,2273.34]],"ltp":1.08,"tv":77305.5,"id":228749},{"atl":[[13.5,1.72]],"trd":[[13.5,8.67]],"ltp":13.5,"tv":6638.72,"id":2857977}],"tv":83944.22}]}
{"op":"mcm","clk":"AKWGrAkA4pKdCgCLoaAK","pt":1657540518818,"mc":[{"id":"1.200806927","rc":[{"atl":[[1.09,1241.49]],"id":228749}]}]}
{"op":"mcm","clk":"ALCGrAkA6pKdCgCQoaAK","pt":1657540518882,"mc":[{"id":"1.200806927","rc":[{"atl":[[1.09,1240.96]],"id":228749}]}]}
{"op":"mcm","clk":"ALqGrAkA9JKdCgCWoaAK","pt":1657540518990,"mc":[{"id":"1.200806927","rc":[{"atl":[[1000,0.39]],"id":228749}]}]}
{"op":"mcm","clk":"AOWGrAkAoZOdCgCsoaAK","pt":1657540519420,"mc":[{"id":"1.200806927","rc":[{"atl":[[1000,0.13]],"id":228749}]}]}
{"op":"mcm","clk":"AOqGrAkArZOdCgCwoaAK","pt":1657540519501,"mc":[{"id":"1.200806927","rc":[{"atl":[[1.09,1230.44]],"id":228749}]}]}
{"op":"mcm","clk":"AJ+HrAkA6pOdCgDRoaAK","pt":1657540520099,"mc":[{"id":"1.200806927","rc":[{"atb":[[1.08,8.61]],"id":228749}]}]}
{"op":"mcm","clk":"AL2HrAkAkpSdCgDeoaAK","pt":1657540520417,"mc":[{"id":"1.200806927","rc":[{"atl":[[1.09,837.91]],"id":228749}]}]}
{"op":"mcm","clk":"AOSHrAkAwJSdCgCBoqAK","pt":1657540520818,"mc":[{"id":"1.200806927","rc":[{"atl":[[1.09,832.65]],"trd":[[1.09,221.8]],"ltp":1.09,"tv":77316.02,"id":228749}],"tv":83954.74}]}
{"op":"mcm","clk":"APaHrAkA3ZSdCgCNoqAK","pt":1657540521083,"mc":[{"id":"1.200806927","rc":[{"atl":[[1.09,832.48]],"trd":[[1.09,222.14]],"tv":77316.36,"id":228749}],"tv":83955.08}]}
{"op":"mcm","clk":"AJmIrAkAiZWdCgCpoqAK","pt":1657540521503,"mc":[{"id":"1.200806927","rc":[{"atb":[[1.08,5.98]],"trd":[[1.08,2278.61]],"ltp":1.08,"tv":77321.63,"id":228749}],"tv":83960.35}]}
{"op":"mcm","clk":"ANSIrAkAy5WdCgDRoqAK","pt":1657540522191,"mc":[{"id":"1.200806927","rc":[{"atl":[[1.29,218.54]],"id":228749}]}]}
{"op":"mcm","clk":"AO6IrAkA4JWdCgDloqAK","pt":1657540522514,"mc":[{"id":"1.200806927","rc":[{"atl":[[1.09,831.31]],"trd":[[1.09,223.32]],"ltp":1.09,"tv":77322.81,"id":228749},{"trd":[[12,11.55]],"ltp":12,"tv":6638.83,"id":2857977}],"tv":83961.64}]}
{"op":"mcm","clk":"APaIrAkA7JWdCgDsoqAK","pt":1657540522611,"mc":[{"id":"1.200806927","rc":[{"atl":[[1.09,830.77]],"trd":[[1.09,224.38]],"tv":77323.87,"id":228749}],"tv":83962.7}]}
{"op":"mcm","clk":"AMuJrAkA5ZadCgC2o6AK","pt":1657540523805,"mc":[{"id":"1.200806927","rc":[{"atl":[[1.09,825.29]],"trd":[[1.09,234.16]],"tv":77333.65,"id":228749},{"trd":[[12,11.66]],"tv":6638.94,"id":2857977}],"tv":83972.59}]}
{"op":"mcm","clk":"AOGJrAkAjpedCgDQo6AK","pt":1657540524207,"mc":[{"id":"1.200806927","rc":[{"atb":[[1.08,0]],"atl":[[1.09,605.11]],"trd":[[1.08,2310.88],[1.09,454.35]],"ltp":1.08,"tv":77586.11,"id":228749},{"atl":[[13.5,0.09]],"trd":[[13.5,10.29],[12,31.66]],"ltp":13.5,"tv":6660.56,"id":2857977}],"tv":84246.67}]}
{"op":"mcm","clk":"APCJrAkAopedCgDYo6AK","pt":1657540524416,"mc":[{"id":"1.200806927","rc":[{"atb":[[1.08,23.4]],"id":228749}]}]}
{"op":"mcm","clk":"APiJrAkAq5edCgDZo6AK","pt":1657540524581,"mc":[{"id":"1.200806927","rc":[{"atb":[[1.08,23.13]],"trd":[[1.08,2311.42]],"tv":77586.65,"id":228749}],"tv":84247.21}]}
{"op":"mcm","clk":"AM6KrAkAiZidCgCYpKAK","pt":1657540525517,"mc":[{"id":"1.200806927","rc":[{"atl":[[1.09,602.48]],"trd":[[1.09,459.61]],"ltp":1.09,"tv":77591.91,"id":228749}],"tv":84252.47}]}
{"op":"mcm","clk":"ANaKrAkAlJidCgCkpKAK","pt":1657540525608,"mc":[{"id":"1.200806927","rc":[{"atb":[[1.08,12.61]],"trd":[[1.08,2332.46]],"ltp":1.08,"tv":77612.95,"id":228749}],"tv":84273.51}]}
{"op":"mcm","clk":"AJSLrAkA3pidCgDQpKAK","pt":1657540526400,"mc":[{"id":"1.200806927","rc":[{"atb":[[1.08,0]],"atl":[[1.08,260.24]],"trd":[[1.08,2358.83]],"tv":77639.32,"id":228749},{"atl":[[13.5,0]],"trd":[[13.5,10.38]],"tv":6660.65,"id":2857977}],"tv":84299.97}]}
{"op":"mcm","clk":"AMKMrAkAs5qdCgDMpaAK","pt":1657540528715,"mc":[{"id":"1.200806927","rc":[{"atl":[[1.08,253.61]],"trd":[[1.08,2365.46]],"tv":77645.95,"id":228749},{"trd":[[13.5,10.91]],"tv":6661.18,"id":2857977}],"tv":84307.13}]}
{"op":"mcm","clk":"AOuMrAkA8JqdCgDopaAK","pt":1657540529316,"mc":[{"id":"1.200806927","rc":[{"atl":[[1.08,46.5]],"trd":[[1.08,2779.68]],"tv":78060.17,"id":228749}],"tv":84721.35}]}
{"op":"mcm","clk":"APmMrAkAh5udCgDwpaAK","pt":1657540529517,"mc":[{"id":"1.200806927","rc":[{"atl":[[1.08,43.87]],"trd":[[1.08,2784.94]],"tv":78065.43,"id":228749}],"tv":84726.61}]}
{"op":"mcm","clk":"AIyNrAkAnpudCgD7paAK","pt":1657540529723,"mc":[{"id":"1.200806927","rc":[{"atl":[[1.08,30.87]],"trd":[[1.08,2797.94]],"tv":78078.43,"id":228749},{"trd":[[13.5,11.95]],"tv":6662.22,"id":2857977}],"tv":84740.65}]}
{"op":"mcm","clk":"AJmNrAkAq5udCgCEpqAK","pt":1657540529915,"mc":[{"id":"1.200806927","rc":[{"atb":[[1.03,1.84]],"id":228749}]}]}
{"op":"mcm","clk":"AOCNrAkAipydCgC1pqAK","pt":1657540530999,"mc":[{"id":"1.200806927","rc":[{"atb":[[1.06,596.55]],"id":228749}]}]}
{"op":"mcm","clk":"APSNrAkApZydCgDGpqAK","pt":1657540531310,"mc":[{"id":"1.200806927","rc":[{"atl":[[1.08,29.47]],"trd":[[1.08,2799.34]],"tv":78079.83,"id":228749},{"trd":[[13.5,12.07]],"tv":6662.34,"id":2857977}],"tv":84742.17}]}
{"op":"mcm","clk":"AIWOrAkAupydCgDQpqAK","pt":1657540531520,"mc":[{"id":"1.200806927","rc":[{"atl":[[1.08,34.73]],"id":228749}]}]}
{"op":"mcm","clk":"AImOrAkAxpydCgDUpqAK","pt":1657540531620,"mc":[{"id":"1.200806927","rc":[{"atl":[[1.08,33.4]],"trd":[[1.08,2800.67]],"tv":78081.16,"id":228749},{"trd":[[13.5,12.17]],"tv":6662.44,"id":2857977}],"tv":84743.6}]}
{"op":"mcm","clk":"AJSOrAkA2pydCgDgpqAK","pt":1657540531789,"mc":[{"id":"1.200806927","rc":[{"atl":[[1.08,29.1]],"trd":[[1.08,2809.27]],"tv":78089.76,"id":228749}],"tv":84752.2}]}
{"op":"mcm","clk":"AKuPrAkA852dCgC0p6AK","pt":1657540533404,"mc":[{"id":"1.200806927","rc":[{"atl":[[1.08,26.89]],"trd":[[1.08,2813.69]],"tv":78094.18,"id":228749}],"tv":84756.62}]}
{"op":"mcm","clk":"AOOPrAkAup6dCgDPp6AK","pt":1657540534119,"mc":[{"id":"1.200806927","rc":[{"atb":[[1.08,220.6]],"atl":[[1.08,0]],"trd":[[1.08,2856.95]],"tv":78137.44,"id":228749}],"tv":84799.88}]}
{"op":"mcm","clk":"ALeQrAkA/J6dCgD5p6AK","pt":1657540535041,"mc":[{"id":"1.200806927","rc":[{"atb":[[1.04,240]],"id":228749}]}]}
{"op":"mcm","clk":"ANKQrAkAm5+dCgCGqKAK","pt":1657540535328,"mc":[{"id":"1.200806927","rc":[{"atb":[[1.03,2.15]],"id":228749}]}]}
{"op":"mcm","clk":"AOqQrAkAvp+dCgCbqKAK","pt":1657540535706,"mc":[{"id":"1.200806927","rc":[{"atb":[[1.03,1.84]],"id":228749}]}]}
{"op":"mcm","clk":"AJORrAkA55+dCgC3qKAK","pt":1657540536236,"mc":[{"id":"1.200806927","rc":[{"atb":[[1.08,750.93]],"atl":[[1.09,601.18]],"trd":[[1.09,462.21]],"ltp":1.09,"tv":78140.04,"id":228749},{"atl":[[13.5,0.53]],"id":2857977}],"tv":84802.48}]}
{"op":"mcm","clk":"ALKRrAkAhaCdCgDKqKAK","pt":1657540536638,"mc":[{"id":"1.200806927","rc":[{"atl":[[1.09,599.79]],"trd":[[1.09,463.6]],"tv":78141.43,"id":228749},{"trd":[[12,31.78]],"ltp":12,"tv":6662.56,"id":2857977}],"tv":84803.99}]}
{"op":"mcm","clk":"AOSRrAkAuqCdCgDhqKAK","pt":1657540537217,"mc":[{"id":"1.200806927","rc":[{"atb":[[1.07,703.37]],"id":228749},{"atl":[[13.5,1.81]],"id":2857977}]}]}
{"op":"mcm","clk":"AJGSrAkA6qCdCgD6qKAK","pt":1657540537731,"mc":[{"id":"1.200806927","rc":[{"atb":[[1.08,751.72]],"id":228749}]}]}
{"op":"mcm","clk":"ALmTrAkA9qGdCgDSqaAK","pt":1657540539485,"mc":[{"id":"1.200806927","rc":[{"atb":[[1.08,765.25]],"id":228749}]}]}
{"op":"mcm","clk":"AOGTrAkAmaKdCgDdqaAK","pt":1657540539807,"mc":[{"id":"1.200806927","rc":[{"atb":[[1.08,234.92]],"id":228749}]}]}
{"op":"mcm","clk":"AIuUrAkA0qKdCgD4qaAK","pt":1657540540333,"mc":[{"id":"1.200806927","rc":[{"atb":[[1.08,274.87]],"id":228749}]}]}
{"op":"mcm","clk":"AKqUrAkA9aKdCgCLqqAK","pt":1657540540694,"mc":[{"id":"1.200806927","rc":[{"atl":[[13.5,2.34]],"id":2857977}]}]}
{"op":"mcm","clk":"ALGUrAkA/qKdCgCQqqAK","pt":1657540540816,"mc":[{"id":"1.200806927","rc":[{"atl":[[1.09,599.47]],"trd":[[1.09,464.24]],"tv":78142.07,"id":228749}],"tv":84804.63}]}
{"op":"mcm","clk":"AM6UrAkApaOdCgCoqqAK","pt":1657540541227,"mc":[{"id":"1.200806927","rc":[{"atb":[[1.03,1]],"id":228749}]}]}
{"op":"mcm","clk":"AL6VrAkAm6SdCgDvqqAK","pt":1657540542443,"mc":[{"id":"1.200806927","rc":[{"atl":[[1.09,598.29]],"trd":[[1.09,465.41]],"tv":78143.24,"id":228749},{"trd":[[12,31.89]],"tv":6662.67,"id":2857977}],"tv":84805.91}]}
{"op":"mcm","clk":"AP6WrAkAkKadCgDvq6AK","pt":1657540545048,"mc":[{"id":"1.200806927","rc":[{"atl":[[1.09,597.76]],"trd":[[1.09,466.48]],"tv":78144.31,"id":228749}],"tv":84806.98}]}
{"op":"mcm","clk":"AJ6XrAkAu6adCgCGrKAK","pt":1657540545511,"mc":[{"id":"1.200806927","rc":[{"atl":[[1.09,597.23]],"trd":[[1.09,467.54]],"tv":78145.37,"id":228749}],"tv":84808.04}]}
{"op":"mcm","clk":"AKSXrAkAyaadCgCKrKAK","pt":1657540545621,"mc":[{"id":"1.200806927","rc":[{"atb":[[1.08,275.4]],"id":228749}]}]}
{"op":"mcm","clk":"ALSXrAkA3KadCgCRrKAK","pt":1657540545826,"mc":[{"id":"1.200806927","rc":[{"atl":[[1.09,586.71]],"trd":[[1.09,488.58]],"tv":78166.41,"id":228749}],"tv":84829.08}]}
{"op":"mcm","clk":"AOiXrAkAp6edCgCxrKAK","pt":1657540546638,"mc":[{"id":"1.200806927","rc":[{"atb":[[1.08,1275.4]],"id":228749}]}]}
{"op":"mcm","clk":"APCXrAkAsaedCgC0rKAK","pt":1657540546708,"mc":[{"id":"1.200806927","rc":[{"atl":[[1.5,185.35]],"id":228749}]}]}
{"op":"mcm","clk":"AI2YrAkAz6edCgC9rKAK","pt":1657540547026,"mc":[{"id":"1.200806927","rc":[{"atl":[[1.09,584.86]],"trd":[[1.09,492.26]],"tv":78170.09,"id":228749}],"tv":84832.76}]}
{"op":"mcm","clk":"AN6YrAkAl6idCgDjrKAK","pt":1657540547936,"mc":[{"id":"1.200806927","rc":[{"atl":[[1.17,38.61]],"id":228749}]}]}
{"op":"mcm","clk":"AIKZrAkAvaidCgD/rKAK","pt":1657540548407,"mc":[{"id":"1.200806927","rc":[{"atl":[[1.09,575.84]],"trd":[[1.09,510.31]],"tv":78188.14,"id":228749}],"tv":84850.81}]}
{"op":"mcm","clk":"AI2ZrAkAxqidCgCCraAK","pt":1657540548518,"mc":[{"id":"1.200806927","rc":[{"atl":[[1.09,556.03]],"trd":[[1.09,530.12]],"tv":78207.95,"id":228749},{"trd":[[12,33.69]],"tv":6664.47,"id":2857977}],"tv":84872.42}]}
{"op":"mcm","clk":"ALOZrAkA66idCgCcraAK","pt":1657540549036,"mc":[{"id":"1.200806927","rc":[{"atl":[[1000,0.39]],"id":228749}]}]}
{"op":"mcm","clk":"AMWZrAkA+6idCgCnraAK","pt":1657540549244,"mc":[{"id":"1.200806927","rc":[{"atb":[[1.08,1522.89]],"id":228749}]}]}
{"op":"mcm","clk":"ANOZrAkAjamdCgCwraAK","pt":1657540549390,"mc":[{"id":"1.200806927","rc":[{"atl":[[1000,0.13]],"id":228749}]}]}
{"op":"mcm","clk":"AOCZrAkAmamdCgC2raAK","pt":1657540549499,"mc":[{"id":"1.200806927","rc":[{"atb":[[1.08,1525.48]],"atl":[[1.09,553.2]],"trd":[[1.09,532.94]],"tv":78210.77,"id":228749},{"trd":[[12,33.95]],"tv":6664.73,"id":2857977}],"tv":84875.5}]}
{"op":"mcm","clk":"APKZrAkArKmdCgDBraAK","pt":1657540549733,"mc":[{"id":"1.200806927","rc":[{"atl":[[13.5,1.81]],"id":2857977}]}]}
{"op":"mcm","clk":"AN6arAkAnaqdCgD7raAK","pt":1657540551145,"mc":[{"id":"1.200806927","rc":[{"atb":[[1.06,591.29]],"id":228749}]}]}
{"op":"mcm","clk":"AJebrAkA46qdCgCWrqAK","pt":1657540551837,"mc":[{"id":"1.200806927","rc":[{"atb":[[1.08,1531.26]],"id":228749}]}]}
{"op":"mcm","clk":"AKObrAkA+KqdCgCcrqAK","pt":1657540552038,"mc":[{"id":"1.200806927","rc":[{"atl":[[1.09,548.69]],"trd":[[1.09,541.96]],"tv":78219.79,"id":228749}],"tv":84884.52}]}
{"op":"mcm","clk":"AOGbrAkAuKudCgDCrqAK","pt":1657540552772,"mc":[{"id":"1.200806927","rc":[{"atb":[[1.05,910.69]],"id":228749}]}]}
{"op":"mcm","clk":"AOebrAkAxaudCgDJrqAK","pt":1657540552908,"mc":[{"id":"1.200806927","rc":[{"atb":[[1.03,84.62]],"id":228749}]}]}
{"op":"mcm","clk":"AO2brAkAzaudCgDNrqAK","pt":1657540553003,"mc":[{"id":"1.200806927","rc":[{"atb":[[1.08,542.17]],"trd":[[1.08,4835.13]],"ltp":1.08,"tv":80197.97,"id":228749}],"tv":86862.7}]}
{"op":"mcm","clk":"AOqcrAkA7qydCgClr6AK","pt":1657540554532,"mc":[{"id":"1.200806927","rc":[{"atb":[[1.08,541.9]],"trd":[[1.08,4835.67]],"tv":80198.51,"id":228749}],"tv":86863.24}]}
{"op":"mcm","clk":"AIedrAkAmq2dCgDBr6AK","pt":1657540555046,"mc":[{"id":"1.200806927","rc":[{"atl":[[1.09,546.06]],"trd":[[1.09,547.22]],"ltp":1.09,"tv":80203.77,"id":228749}],"tv":86868.5}]}
{"op":"mcm","clk":"AJudrAkAvK2dCgDTr6AK","pt":1657540555297,"mc":[{"id":"1.200806927","rc":[{"atl":[[1.09,545.53]],"trd":[[1.09,548.28]],"tv":80204.83,"id":228749}],"tv":86869.56}]}
{"op":"mcm","clk":"AO6drAkAoa6dCgCIsKAK","pt":1657540556357,"mc":[{"id":"1.200806927","rc":[{"atl":[[1.09,545.01]],"trd":[[1.09,549.32]],"tv":80205.87,"id":228749}],"tv":86870.6}]}
{"op":"mcm","clk":"ALaerAkA/a6dCgCwsKAK","pt":1657540557256,"mc":[{"id":"1.200806927","rc":[{"atl":[[1.09,539.1]],"trd":[[1.09,555.24]],"tv":80211.79,"id":228749},{"trd":[[12,34.48]],"tv":6665.26,"id":2857977}],"tv":86877.05}]}
{"op":"mcm","clk":"AIugrAkAnLGdCgClsaAK","pt":1657540559881,"mc":[{"id":"1.200806927","rc":[{"atl":[[19.5,52.59]],"id":2857977}]}]}
{"op":"mcm","clk":"AJWgrAkAprGdCgCosaAK","pt":1657540559989,"mc":[{"id":"1.200806927","rc":[{"atb":[[1.03,85.46]],"id":228749}]}]}
{"op":"mcm","clk":"AKigrAkAxLGdCgCvsaAK","pt":1657540560272,"mc":[{"id":"1.200806927","rc":[{"atl":[[13.5,0.53]],"id":2857977}]}]}
{"op":"mcm","clk":"ALehrAkA9rKdCgDvsaAK","pt":1657540561836,"mc":[{"id":"1.200806927","rc":[{"atb":[[1.08,539.27]],"trd":[[1.08,4840.93]],"ltp":1.08,"tv":80217.05,"id":228749}],"tv":86882.31}]}
{"op":"mcm","clk":"ALairAkAobSdCgCosqAK","pt":1657540563200,"mc":[{"id":"1.200806927","rc":[{"atl":[[1.09,517.57]],"trd":[[1.09,598.28]],"ltp":1.09,"tv":80260.09,"id":228749}],"tv":86925.35}]}
{"op":"mcm","clk":"AKWkrAkAqbadCgCYs6AK","pt":1657540565371,"mc":[{"id":"1.200806927","rc":[{"atb":[[1.03,85.77]],"id":228749}]}]}
{"op":"mcm","clk":"ALykrAkA1radCgChs6AK","pt":1657540565715,"mc":[{"id":"1.200806927","rc":[{"atb":[[1.03,85.46]],"id":228749}]}]}
{"op":"mcm","clk":"AM6krAkA67adCgCns6AK","pt":1657540565962,"mc":[{"id":"1.200806927","rc":[{"atb":[[1.08,539.16]],"trd":[[1.08,4841.15]],"ltp":1.08,"tv":80260.31,"id":228749}],"tv":86925.57}]}
{"op":"mcm","clk":"ANqkrAkA9LadCgCrs6AK","pt":1657540566046,"mc":[{"id":"1.200806927","rc":[{"atl":[[1.09,513.27]],"trd":[[1.09,606.89]],"ltp":1.09,"tv":80268.92,"id":228749}],"tv":86934.18}]}
{"op":"mcm","clk":"AKulrAkA9bedCgDTs6AK","pt":1657540567232,"mc":[{"id":"1.200806927","rc":[{"atl":[[1.09,512.27]],"trd":[[1.09,608.88]],"tv":80270.91,"id":228749}],"tv":86936.17}]}
{"op":"mcm","clk":"AJGnrAkAsLqdCgDetKAK","pt":1657540570358,"mc":[{"id":"1.200806927","rc":[{"atl":[[1.09,485.97]],"trd":[[1.09,661.48]],"tv":80323.51,"id":228749}],"tv":86988.77}]}
{"op":"mcm","clk":"AKunrAkA37qdCgD1tKAK","pt":1657540570851,"mc":[{"id":"1.200806927","rc":[{"atl":[[1.09,485.65]],"trd":[[1.09,662.12]],"tv":80324.15,"id":228749}],"tv":86989.41}]}
{"op":"mcm","clk":"AM2nrAkAjLudCgCEtaAK","pt":1657540571251,"mc":[{"id":"1.200806927","rc":[{"atb":[[1.03,84.62]],"id":228749}]}]}
{"op":"mcm","clk":"AJ2orAkAh7ydCgCrtaAK","pt":1657540572250,"mc":[{"id":"1.200806927","rc":[{"atl":[[1.16,1138.93]],"id":228749}]}]}
{"op":"mcm","clk":"AK2orAkAsbydCgC2taAK","pt":1657540572454,"mc":[{"id":"1.200806927","rc":[{"atl":[[1.09,484.6]],"trd":[[1.09,664.22]],"tv":80326.25,"id":228749}],"tv":86991.51}]}
{"op":"mcm","clk":"AISprAkAlb2dCgDhtaAK","pt":1657540573353,"mc":[{"id":"1.200806927","rc":[{"atb":[[1.08,533.9]],"trd":[[1.08,4851.67]],"ltp":1.08,"tv":80336.77,"id":228749}],"tv":87002.03}]}
{"op":"mcm","clk":"AI2prAkAo72dCgDntaAK","pt":1657540573461,"mc":[{"id":"1.200806927","rc":[{"atl":[[1.09,483.42]],"trd":[[1.09,665.4]],"ltp":1.09,"tv":80337.95,"id":228749},{"trd":[[12,34.59]],"tv":6665.37,"id":2857977}],"tv":87003.32}]}
{"op":"mcm","clk":"AJ+prAkAwL2dCgDytaAK","pt":1657540573676,"mc":[{"id":"1.200806927","rc":[{"atl":[[1.09,482.25]],"trd":[[1.09,666.57]],"tv":80339.12,"id":228749},{"trd":[[12,34.7]],"tv":6665.48,"id":2857977}],"tv":87004.6}]}
{"op":"mcm","clk":"AL+prAkA6b2dCgD9taAK","pt":1657540574048,"mc":[{"id":"1.200806927","rc":[{"atl":[[1.09,473.64]],"trd":[[1.09,683.79]],"tv":80356.34,"id":228749}],"tv":87021.82}]}
{"op":"mcm","clk":"APSprAkAub6dCgCitqAK","pt":1657540574765,"mc":[{"id":"1.200806927","rc":[{"atl":[[1.09,471.01]],"trd":[[1.09,689.05]],"tv":80361.6,"id":228749}],"tv":87027.08}]}
{"op":"mcm","clk":"AJOqrAkA4L6dCgCytqAK","pt":1657540575176,"mc":[{"id":"1.200806927","rc":[{"atl":[[1.09,468.64]],"trd":[[1.09,693.79]],"tv":80366.34,"id":228749}],"tv":87031.82}]}
{"op":"mcm","clk":"AJaqrAkA6b6dCgC3tqAK","pt":1657540575274,"mc":[{"id":"1.200806927","rc":[{"atl":[[1.09,457.34]],"trd":[[1.09,705.09]],"tv":80377.64,"id":228749},{"trd":[[12,35.72]],"tv":6666.5,"id":2857977}],"tv":87044.14}]}
{"op":"mcm","clk":"AICrrAkAv7+dCgDYtqAK","pt":1657540576069,"mc":[{"id":"1.200806927","rc":[{"atb":[[1.06,1436.96]],"id":228749}]}]}
{"op":"mcm","clk":"AJusrAkArMGdCgCqt6AK","pt":1657540578058,"mc":[{"id":"1.200806927","rc":[{"atb":[[1.02,155.7]],"id":228749}]}]}
{"op":"mcm","clk":"AM2srAkA88GdCgDCt6AK","pt":1657540578666,"mc":[{"id":"1.200806927","rc":[{"atl":[[1.09,451.5]],"trd":[[1.09,710.93]],"tv":80383.48,"id":228749},{"trd":[[12,36.25]],"tv":6667.03,"id":2857977}],"tv":87050.51}]}
{"op":"mcm","clk":"ANKtrAkA/MKdCgCKuKAK","pt":1657540580190,"mc":[{"id":"1.200806927","rc":[{"atl":[[1.09,440.6]],"trd":[[1.09,721.83]],"tv":80394.38,"id":228749},{"trd":[[12,37.24]],"tv":6668.02,"id":2857977}],"tv":87062.4}]}
{"op":"mcm","clk":"AOatrAkAksOdCgCUuKAK","pt":1657540580387,"mc":[{"id":"1.200806927","rc":[{"atb":[[1.08,533.75]],"trd":[[1.08,4851.96]],"ltp":1.08,"tv":80394.67,"id":228749}],"tv":87062.69}]}
{"op":"mcm","clk":"APmtrAkAucOdCgCjuKAK","pt":1657540580655,"mc":[{"id":"1.200806927","rc":[{"atl":[[1.09,439.5]],"trd":[[1.09,722.93]],"ltp":1.09,"tv":80395.77,"id":228749},{"trd":[[12,37.34]],"tv":6668.12,"id":2857977}],"tv":87063.89}]}
{"op":"mcm","clk":"AOyurAkAqsSdCgDcuKAK","pt":1657540581860,"mc":[{"id":"1.200806927","rc":[{"atl":[[1.09,436.34]],"trd":[[1.09,729.25]],"tv":80402.09,"id":228749}],"tv":87070.21}]}
{"op":"mcm","clk":"APyurAkAv8SdCgDmuKAK","pt":1657540582066,"mc":[{"id":"1.200806927","rc":[{"atl":[[1.09,435.34]],"trd":[[1.09,731.25]],"tv":80404.09,"id":228749}],"tv":87072.21}]}
{"op":"mcm","clk":"AKmvrAkAhMWdCgD5uKAK","pt":1657540582690,"mc":[{"id":"1.200806927","rc":[{"atl":[[1.09,434.29]],"trd":[[1.09,733.35]],"tv":80406.19,"id":228749}],"tv":87074.31}]}
{"op":"mcm","clk":"AJ6xrAkA2MedCgCVuqAK","pt":1657540585894,"mc":[{"id":"1.200806927","rc":[{"atl":[[1000,0.39]],"id":228749}]}]}
{"op":"mcm","clk":"ALuxrAkAhcidCgCiuqAK","pt":1657540586265,"mc":[{"id":"1.200806927","rc":[{"atl":[[1000,0.13]],"id":228749}]}]}
{"op":"mcm","clk":"AMezrAkA8sqdCgC0u6AK","pt":1657540589465,"mc":[{"id":"1.200806927","rc":[{"atl":[[1.09,409.29]],"trd":[[1.09,783.35]],"tv":80456.19,"id":228749}],"tv":87124.31}]}
{"op":"mcm","clk":"APG0rAkA3sydCgCdvKAK","pt":1657540591419,"mc":[{"id":"1.200806927","rc":[{"atb":[[1.08,533.48]],"trd":[[1.08,4852.5]],"ltp":1.08,"tv":80456.73,"id":228749}],"tv":87124.85}]}
{"op":"mcm","clk":"AIC1rAkA/MydCgCkvKAK","pt":1657540591607,"mc":[{"id":"1.200806927","rc":[{"atl":[[1.09,408.12]],"trd":[[1.09,784.52]],"ltp":1.09,"tv":80457.9,"id":228749},{"trd":[[12,37.45]],"tv":6668.23,"id":2857977}],"tv":87126.13}]}
{"op":"mcm","clk":"AK62rAkAm8+dCgCQvaAK","pt":1657540594012,"mc":[{"id":"1.200806927","rc":[{"atl":[[1.09,403.91]],"trd":[[1.09,792.94]],"tv":80466.32,"id":228749}],"tv":87134.55}]}
{"op":"mcm","clk":"AMe2rAkAv8+dCgCgvaAK","pt":1657540594285,"mc":[{"id":"1.200806927","rc":[{"atl":[[1.09,402]],"trd":[[1.09,794.84]],"tv":80468.22,"id":228749},{"trd":[[12,37.62]],"tv":6668.4,"id":2857977}],"tv":87136.62}]}
{"op":"mcm","clk":"AKC3rAkA1tCdCgDcvaAK","pt":1657540595474,"mc":[{"id":"1.200806927","rc":[{"atl":[[1.09,399.37]],"trd":[[1.09,800.1]],"tv":80473.48,"id":228749}],"tv":87141.88}]}
{"op":"mcm","clk":"AMa3rAkAhtGdCgD0vaAK","pt":1657540595909,"mc":[{"id":"1.200806927","rc":[{"atl":[[1.09,397.79]],"trd":[[1.09,803.27]],"tv":80476.65,"id":228749}],"tv":87145.05}]}
{"op":"mcm","clk":"AIm4rAkA2dGdCgCavqAK","pt":1657540596790,"mc":[{"id":"1.200806927","rc":[{"atb":[[1.03,85.46]],"id":228749}]}]}
{"op":"mcm","clk":"AJ64rAkAhNKdCgCjvqAK","pt":1657540597118,"mc":[{"id":"1.200806927","rc":[{"atl":[[1.09,371.49]],"trd":[[1.09,855.87]],"tv":80529.25,"id":228749}],"tv":87197.65}]}
{"op":"mcm","clk":"AOO4rAkA2tKdCgDJvqAK","pt":1657540597992,"mc":[{"id":"1.200806927","rc":[{"atl":[[1.09,366.76]],"trd":[[1.09,860.6]],"tv":80533.98,"id":228749},{"trd":[[12,38.05]],"tv":6668.83,"id":2857977}],"tv":87202.81}]}
{"op":"mcm","clk":"APi4rAkA9dKdCgDXvqAK","pt":1657540598294,"mc":[{"id":"1.200806927","rc":[{"atl":[[1.21,0.39]],"id":228749}]}]}
{"op":"mcm","clk":"AKG5rAkAsdOdCgDrvqAK","pt":1657540598827,"mc":[{"id":"1.200806927","rc":[{"atl":[[1.09,364.33]],"trd":[[1.09,865.46]],"tv":80538.84,"id":228749}],"tv":87207.67}]}
{"op":"mcm","clk":"AOi6rAkAxdWdCgDdv6AK","pt":1657540601238,"mc":[{"id":"1.200806927","rc":[{"atl":[[21,3.6]],"id":2857977}]}]}
{"op":"mcm","clk":"AMO7rAkAwtadCgCFwKAK","pt":1657540602186,"mc":[{"id":"1.200806927","rc":[{"atb":[[1.03,85.77]],"id":228749}]}]}
{"op":"mcm","clk":"ANy7rAkA99adCgCUwKAK","pt":1657540602611,"mc":[{"id":"1.200806927","rc":[{"atb":[[1.03,85.46]],"id":228749}]}]}
{"op":"mcm","clk":"AP67rAkAqNedCgCnwKAK","pt":1657540603023,"mc":[{"id":"1.200806927","rc":[{"atl":[[1.09,361.7]],"trd":[[1.09,870.72]],"tv":80544.1,"id":228749}],"tv":87212.93}]}
{"op":"mcm","clk":"AOK8rAkA5tidCgDtwKAK","pt":1657540604491,"mc":[{"id":"1.200806927","rc":[{"atb":[[1.08,984.29]],"atl":[[1.09,359.07]],"trd":[[1.09,875.98]],"tv":80549.36,"id":228749}],"tv":87218.19}]}
{"op":"mcm","clk":"ALK9rAkA89mdCgCiwaAK","pt":1657540605624,"mc":[{"id":"1.200806927","rc":[{"atl":[[1.09,337.55]],"trd":[[1.09,919.02]],"tv":80592.4,"id":228749}],"tv":87261.23}]}
{"op":"mcm","clk":"AOG9rAkA3NqdCgDMwaAK","pt":1657540606457,"mc":[{"id":"1.200806927","rc":[{"atl":[[1.09,311.25]],"trd":[[1.09,971.62]],"tv":80645,"id":228749}],"tv":87313.83}]}
{"op":"mcm","clk":"AJO+rAkA/NqdCgDYwaAK","pt":1657540606845,"mc":[{"id":"1.200806927","rc":[{"atl":[[1.09,282.29]],"trd":[[1.09,1000.58]],"tv":80673.96,"id":228749},{"trd":[[12,40.68]],"tv":6671.46,"id":2857977}],"tv":87345.42}]}
