{"op":"mcm","clk":"AN6+rAkA2tudCgD/waAK","pt":1657540607736,"mc":[{"id":"1.200806927","rc":[{"atl":[[1.09,281.97]],"trd":[[1.09,1001.21]],"tv":80674.59,"id":228749}],"tv":87346.05}]}
{"op":"mcm","clk":"APy+rAkAhdydCgCQwqAK","pt":1657540608156,"mc":[{"id":"1.200806927","rc":[{"atb":[[1.03,84.62]],"atl":[[1.09,279.07]],"trd":[[1.09,1007.02]],"tv":80680.4,"id":228749}],"tv":87351.86}]}
{"op":"mcm","clk":"AIG/rAkAkNydCgCWwqAK","pt":1657540608205,"mc":[{"id":"1.200806927","rc":[{"atl":[[1.09,252.77]],"trd":[[1.09,1059.62]],"tv":80733,"id":228749}],"tv":87404.46}]}
{"op":"mcm","clk":"AIq/rAkAntydCgCYwqAK","pt":1657540608307,"mc":[{"id":"1.200806927","rc":[{"atb":[[1.08,984.72]],"id":228749}]}]}
{"op":"mcm","clk":"APS/rAkA2t2dCgDiwqAK","pt":1657540609829,"mc":[{"id":"1.200806927","rc":[{"atb":[[1.08,985.25]],"id":228749}]}]}
{"op":"mcm","clk":"AKPArAkAr96dCgCEw6AK","pt":1657540610505,"mc":[{"id":"1.200806927","rc":[{"atl":[[1.09,226.47]],"trd":[[1.09,1112.22]],"tv":80785.6,"id":228749}],"tv":87457.06}]}
{"op":"mcm","clk":"ALrArAkA0d6dCgCSw6AK","pt":1657540610815,"mc":[{"id":"1.200806927","rc":[{"atl":[[1.09,220.16]],"trd":[[1.09,1124.83]],"tv":80798.21,"id":228749}],"tv":87469.67}]}
{"op":"mcm","clk":"AMbArAkA5t6dCgCcw6AK","pt":1657540610965,"mc":[{"id":"1.200806927","rc":[{"atl":[[1.09,218.99]],"trd":[[1.09,1126.01]],"tv":80799.39,"id":228749},{"trd":[[12,40.79]],"tv":6671.57,"id":2857977}],"tv":87470.96}]}
{"op":"mcm","clk":"AIXBrAkAyN+dCgDOw6AK","pt":1657540611938,"mc":[{"id":"1.200806927","rc":[{"atl":[[1.09,214.25]],"trd":[[1.09,1130.75]],"tv":80804.13,"id":228749},{"trd":[[12,41.22]],"tv":6672,"id":2857977}],"tv":87476.13}]}
{"op":"mcm","clk":"AJnBrAkA89+dCgDhw6AK","pt":1657540612334,"mc":[{"id":"1.200806927","rc":[{"atl":[[1.09,213.2]],"trd":[[1.09,1132.84]],"tv":80806.22,"id":228749}],"tv":87478.22}]}
{"op":"mcm","clk":"ANHBrAkA2+CdCgCRxKAK","pt":1657540613327,"mc":[{"id":"1.200806927","rc":[{"atl":[[1.16,1103.59]],"id":228749}]}]}
{"op":"mcm","clk":"AKrCrAkA2OGdCgDNxKAK","pt":1657540614523,"mc":[{"id":"1.200806927","rc":[{"atl":[[1.09,207.94]],"trd":[[1.09,1143.36]],"tv":80816.74,"id":228749}],"tv":87488.74}]}
{"op":"mcm","clk":"ALLCrAkA4eGdCgDPxKAK","pt":1657540614630,"mc":[{"id":"1.200806927","rc":[{"atl":[[1.09,129.05]],"trd":[[1.09,1301.15]],"tv":80974.53,"id":228749}],"tv":87646.53}]}
{"op":"mcm","clk":"ALbCrAkA8OGdCgDWxKAK","pt":1657540614733,"mc":[{"id":"1.200806927","rc":[{"atl":[[1.09,108.14]],"trd":[[1.09,1342.96]],"tv":81016.34,"id":228749}],"tv":87688.34}]}
{"op":"mcm","clk":"AN3DrAkA2eOdCgDJxaAK","pt":1657540616929,"mc":[{"id":"1.200806927","rc":[{"atl":[[1.09,98.66]],"trd":[[1.09,1352.44]],"tv":81025.82,"id":228749},{"trd":[[12,42.08]],"tv":6672.86,"id":2857977}],"tv":87698.68}]}
{"op":"mcm","clk":"AN7ErAkAluWdCgCLxqAK","pt":1657540618656,"mc":[{"id":"1.200806927","rc":[{"atl":[[1.09,98.13]],"trd":[[1.09,1353.5]],"tv":81026.88,"id":228749}],"tv":87699.74}]}
{"op":"mcm","clk":"ALLFrAkAjeadCgDNxqAK","pt":1657540619851,"mc":[{"id":"1.200806927","rc":[{"atl":[[1.09,96.23]],"trd":[[1.09,1355.4]],"tv":81028.78,"id":228749},{"trd":[[12,42.25]],"tv":6673.03,"id":2857977}],"tv":87701.81}]}
{"op":"mcm","clk":"AKnGrAkAqOedCgCTx6AK","pt":1657540621266,"mc":[{"id":"1.200806927","rc":[{"atb":[[1.08,984.82]],"id":228749}]}]}
{"op":"mcm","clk":"ANbGrAkA3OedCgCxx6AK","pt":1657540621752,"mc":[{"id":"1.200806927","rc":[{"atl":[[1.09,94.43]],"trd":[[1.09,1359]],"tv":81032.38,"id":228749}],"tv":87705.41}]}
{"op":"mcm","clk":"AP3GrAkAneidCgDFx6AK","pt":1657540622264,"mc":[{"id":"1.200806927","rc":[{"atl":[[1.09,93.38]],"trd":[[1.09,1361.1]],"tv":81034.48,"id":228749}],"tv":87707.51}]}
{"op":"mcm","clk":"AJnHrAkA0eidCgDZx6AK","pt":1657540622609,"mc":[{"id":"1.200806927","rc":[{"atb":[[1.08,968.35]],"trd":[[1.08,4885.45]],"ltp":1.08,"tv":81067.43,"id":228749}],"tv":87740.46}]}
{"op":"mcm","clk":"AKbHrAkA5eidCgDcx6AK","pt":1657540622739,"mc":[{"id":"1.200806927","rc":[{"atl":[[1.09,97.16]],"id":228749}]}]}
{"op":"mcm","clk":"AOLJrAkAneydCgCZyaAK","pt":1657540626455,"mc":[{"id":"1.200806927","rc":[{"atl":[[1.09,95.06]],"trd":[[1.09,1365.3]],"ltp":1.09,"tv":81071.63,"id":228749}],"tv":87744.66}]}
{"op":"mcm","clk":"AILKrAkAw+ydCgCwyaAK","pt":1657540626883,"mc":[{"id":"1.200806927","rc":[{"atl":[[1.09,94.53]],"trd":[[1.09,1366.36]],"tv":81072.69,"id":228749}],"tv":87745.72}]}
{"op":"mcm","clk":"AJHKrAkA5+ydCgC+yaAK","pt":1657540627139,"mc":[{"id":"1.200806927","rc":[{"atl":[[1.09,89.79]],"trd":[[1.09,1371.1]],"tv":81077.43,"id":228749},{"trd":[[12,42.68]],"tv":6673.46,"id":2857977}],"tv":87750.89}]}
{"op":"mcm","clk":"AMPKrAkAr+2dCgDiyaAK","pt":1657540627790,"mc":[{"id":"1.200806927","rc":[{"atl":[[1.09,84.53]],"trd":[[1.09,1381.62]],"tv":81087.95,"id":228749}],"tv":87761.41}]}
{"op":"mcm","clk":"APPNrAkA6/KdCgCLzKAK","pt":1657540633382,"mc":[{"id":"1.200806927","rc":[{"atl":[[1.16,1138.93]],"id":228749}]}]}
{"op":"mcm","clk":"AJvOrAkAlvOdCgCqzKAK","pt":1657540633674,"mc":[{"id":"1.200806927","rc":[{"atl":[[1.09,66.96]],"trd":[[1.09,1416.76]],"tv":81123.09,"id":228749}],"tv":87796.55}]}
{"op":"mcm","clk":"ALrOrAkAxfOdCgDCzKAK","pt":1657540634093,"mc":[{"id":"1.200806927","rc":[{"atl":[[1.09,61.7]],"trd":[[1.09,1427.28]],"tv":81133.61,"id":228749}],"tv":87807.07}]}
{"op":"mcm","clk":"AIXPrAkAu/SdCgD1zKAK","pt":1657540635098,"mc":[{"id":"1.200806927","rc":[{"atb":[[1.08,400.35]],"trd":[[1.08,6021.45]],"ltp":1.08,"tv":82269.61,"id":228749}],"tv":88943.07}]}
{"op":"mcm","clk":"AObQrAkA0PadCgD8zaAK","pt":1657540637271,"mc":[{"id":"1.200806927","rc":[{"atl":[[1.09,57.19]],"trd":[[1.09,1436.3]],"ltp":1.09,"tv":82278.63,"id":228749}],"tv":88952.09}]}
{"op":"mcm","clk":"AKvRrAkAlfedCgCmzqAK","pt":1657540638005,"mc":[{"id":"1.200806927","rc":[{"atb":[[1.08,395.09]],"id":228749}]}]}
{"op":"mcm","clk":"AK3RrAkAnPedCgCpzqAK","pt":1657540638055,"mc":[{"id":"1.200806927","rc":[{"atl":[[1.09,54.56]],"trd":[[1.09,1441.56]],"tv":82283.89,"id":228749}],"tv":88957.35}]}
{"op":"mcm","clk":"ANbUrAkAxfudCgCi0KAK","pt":1657540643177,"mc":[{"id":"1.200806927","rc":[{"atl":[[1.09,54.39]],"trd":[[1.09,1441.9]],"tv":82284.23,"id":228749}],"tv":88957.69}]}
{"op":"mcm","clk":"ALnWrAkA3f2dCgDB0aAK","pt":1657540645904,"mc":[{"id":"1.200806927","rc":[{"atl":[[1.09,28.09]],"trd":[[1.09,1494.5]],"tv":82336.83,"id":228749}],"tv":89010.29}]}
{"op":"mcm","clk":"AJPXrAkA0/6dCgD60aAK","pt":1657540646969,"mc":[{"id":"1.200806927","rc":[{"atb":[[1.08,369.12]],"trd":[[1.08,6073.39]],"ltp":1.08,"tv":82388.77,"id":228749}],"tv":89062.23}]}
{"op":"mcm","clk":"APLXrAkAuf+dCgCr0qAK","pt":1657540648111,"mc":[{"id":"1.200806927","rc":[{"atl":[[1.3,131.32]],"id":228749}]}]}
{"op":"mcm","clk":"AI/YrAkA3f+dCgC/0qAK","pt":1657540648468,"mc":[{"id":"1.200806927","rc":[{"atl":[[1.09,27.56]],"trd":[[1.09,1495.56]],"ltp":1.09,"tv":82389.83,"id":228749}],"tv":89063.29}]}
{"op":"mcm","clk":"AIXZrAkA1YCeCgCE06AK","pt":1657540649797,"mc":[{"id":"1.200806927","rc":[{"atl":[[1.09,11.78]],"trd":[[1.09,1527.12]],"tv":82421.39,"id":228749}],"tv":89094.85}]}
{"op":"mcm","clk":"AJ3ZrAkA+ICeCgCW06AK","pt":1657540650128,"mc":[{"id":"1.200806927","rc":[{"atl":[[1.09,9.15]],"trd":[[1.09,1532.38]],"tv":82426.65,"id":228749}],"tv":89100.11}]}
{"op":"mcm","clk":"AMbbrAkA3IOeCgC/1KAK","pt":1657540653824,"mc":[{"id":"1.200806927","rc":[{"atb":[[1.07,1604.99]],"id":228749}]}]}
{"op":"mcm","clk":"APDbrAkAmYSeCgDZ1KAK","pt":1657540654386,"mc":[{"id":"1.200806927","rc":[{"atb":[[1.08,369.55]],"atl":[[1.09,8.62]],"trd":[[1.09,1533.45]],"tv":82427.72,"id":228749},{"atl":[[12.5,1.67]],"id":2857977}],"tv":89101.18}]}
{"op":"mcm","clk":"APfbrAkAoYSeCgDd1KAK","pt":1657540654496,"mc":[{"id":"1.200806927","rc":[{"atb":[[1.05,917.16]],"id":228749}]}]}
{"op":"mcm","clk":"AKTcrAkAzYSeCgD41KAK","pt":1657540654913,"mc":[{"id":"1.200806927","rc":[{"atb":[[1.08,359.03]],"id":228749}]}]}
{"op":"mcm","clk":"ANTcrAkAjoWeCgCo1aAK","pt":1657540655596,"mc":[{"id":"1.200806927","rc":[{"atl":[[1.09,3.88]],"trd":[[1.09,1538.18]],"tv":82432.45,"id":228749},{"trd":[[12,43.11]],"tv":6673.89,"id":2857977}],"tv":89106.34}]}
{"op":"mcm","clk":"AOvcrAkAsYWeCgC71aAK","pt":1657540655911,"mc":[{"id":"1.200806927","rc":[{"atb":[[1.08,359.56]],"id":228749}]}]}
{"op":"mcm","clk":"AKHdrAkA8YWeCgDY1aAK","pt":1657540656557,"mc":[{"id":"1.200806927","rc":[{"atl":[[1.09,2.71]],"trd":[[1.09,1539.35]],"tv":82433.62,"id":228749},{"trd":[[12,43.22]],"tv":6674,"id":2857977}],"tv":89107.62}]}
{"op":"mcm","clk":"AIDfrAkA44eeCgDC1qAK","pt":1657540659009,"mc":[{"id":"1.200806927","rc":[{"atl":[[1.09,2.18]],"trd":[[1.09,1540.41]],"tv":82434.68,"id":228749}],"tv":89108.68}]}
{"op":"mcm","clk":"AIrfrAkA8IeeCgDJ1qAK","pt":1657540659123,"mc":[{"id":"1.200806927","rc":[{"atl":[[1.09,0]],"trd":[[1.09,1542.59]],"tv":82436.86,"id":228749},{"atl":[[12,0.33]],"trd":[[12,43.42]],"tv":6674.2,"id":2857977}],"tv":89111.06}]}
{"op":"mcm","clk":"AJbfrAkA+oeeCgDM1qAK","pt":1657540659225,"mc":[{"id":"1.200806927","rc":[{"atb":[[1.05,917.33]],"id":228749}]}]}
{"op":"mcm","clk":"APHfrAkA4oieCgD61qAK","pt":1657540660231,"mc":[{"id":"1.200806927","rc":[{"trd":[[1.09,1542.99]],"tv":82437.26,"id":228749},{"atl":[[12,0.29]],"trd":[[12,43.46]],"tv":6674.24,"id":2857977}],"tv":89111.5}]}
{"op":"mcm","clk":"AIXhrAkAkoqeCgDe16AK","pt":1657540662056,"mc":[{"id":"1.200806927","rc":[{"atb":[[1.08,359.03]],"id":228749}]}]}
{"op":"mcm","clk":"APzhrAkAjoueCgCg2KAK","pt":1657540663560,"mc":[{"id":"1.200806927","rc":[{"trd":[[1.09,1544.88]],"tv":82439.15,"id":228749},{"atl":[[12,0.12]],"trd":[[12,43.63]],"tv":6674.41,"id":2857977}],"tv":89113.56}]}
{"op":"mcm","clk":"AInirAkAoIueCgCm2KAK","pt":1657540663705,"mc":[{"id":"1.200806927","rc":[{"atb":[[1.09,6.84]],"id":228749}]}]}
{"op":"mcm","clk":"AK/jrAkA4IyeCgCJ2aAK","pt":1657540665646,"mc":[{"id":"1.200806927","rc":[{"atb":[[1.09,7.37]],"id":228749}]}]}
{"op":"mcm","clk":"AM/jrAkAiI2eCgCX2aAK","pt":1657540666036,"mc":[{"id":"1.200806927","rc":[{"atb":[[1.04,14.59]],"id":228749}]}]}
{"op":"mcm","clk":"AIDkrAkAx42eCgC22aAK","pt":1657540666616,"mc":[{"id":"1.200806927","rc":[{"atb":[[1.09,8]],"id":228749}]}]}
{"op":"mcm","clk":"AMbkrAkAnY6eCgDf2aAK","pt":1657540667446,"mc":[{"id":"1.200806927","rc":[{"atb":[[1.09,8.58]],"id":228749}]}]}
{"op":"mcm","clk":"AInlrAkA7o6eCgCM2qAK","pt":1657540668256,"mc":[{"id":"1.200806927","rc":[{"atb":[[1.09,3.32]],"id":228749}]}]}
{"op":"mcm","clk":"AK7lrAkAk4+eCgCg2qAK","pt":1657540668614,"mc":[{"id":"1.200806927","rc":[{"atb":[[1.08,358.6]],"id":228749}]}]}
{"op":"mcm","clk":"APXlrAkA4I+eCgDF2qAK","pt":1657540669485,"mc":[{"id":"1.200806927","rc":[{"atl":[[12.5,0]],"id":2857977}]}]}
{"op":"mcm","clk":"AO3mrAkA+ZCeCgCX26AK","pt":1657540670846,"mc":[{"id":"1.200806927","rc":[{"atb":[[1.04,25.69]],"id":228749}]}]}
{"op":"mcm","clk":"AKnnrAkAtpGeCgC326AK","pt":1657540671550,"mc":[{"id":"1.200806927","rc":[{"atl":[[12,0]],"id":2857977}]}]}
{"op":"mcm","clk":"AMTprAkAn5SeCgDY3KAK","pt":1657540674638,"mc":[{"id":"1.200806927","rc":[{"atb":[[1.09,2.74]],"id":228749}]}]}
{"op":"mcm","clk":"AJDqrAkA8JSeCgCL3aAK","pt":1657540675521,"mc":[{"id":"1.200806927","rc":[{"atl":[[1.1,12.95]],"id":228749}]}]}
{"op":"mcm","clk":"APHrrAkAx5aeCgCc3qAK","pt":1657540678440,"mc":[{"id":"1.200806927","rc":[{"atb":[[1.09,0]],"atl":[[1.09,23.56]],"id":228749}]}]}
{"op":"mcm","clk":"APrrrAkA0ZaeCgCj3qAK","pt":1657540678561,"mc":[{"id":"1.200806927","rc":[{"atl":[[1.09,20.93]],"id":228749}]}]}
{"op":"mcm","clk":"ALPurAkA0ZmeCgDi36AK","pt":1657540682442,"mc":[{"id":"1.200806927","rc":[{"atb":[[1.08,403.68]],"id":228749}]}]}
{"op":"mcm","clk":"APburAkAlZqeCgCL4KAK","pt":1657540683236,"mc":[{"id":"1.200806927","rc":[{"atl":[[1.09,15.1]],"trd":[[1.09,1550.71]],"tv":82444.98,"id":228749},{"trd":[[12,44.16]],"tv":6674.94,"id":2857977}],"tv":89119.92}]}
{"op":"mcm","clk":"AK/vrAkAxZqeCgCl4KAK","pt":1657540683752,"mc":[{"id":"1.200806927","rc":[{"atl":[[1.09,12.73]],"trd":[[1.09,1555.45]],"tv":82449.72,"id":228749}],"tv":89124.66}]}
{"op":"mcm","clk":"ALrvrAkA25qeCgCx4KAK","pt":1657540683981,"mc":[{"id":"1.200806927","rc":[{"atl":[[1.09,11.44]],"trd":[[1.09,1558.03]],"tv":82452.3,"id":228749}],"tv":89127.24}]}
{"op":"mcm","clk":"AJrxrAkAsZyeCgC54aAK","pt":1657540686378,"mc":[{"id":"1.200806927","rc":[{"atl":[[1.09,5.61]],"trd":[[1.09,1563.86]],"tv":82458.13,"id":228749},{"trd":[[12,44.69]],"tv":6675.47,"id":2857977}],"tv":89133.6}]}
{"op":"mcm","clk":"AKPxrAkAupyeCgC74aAK","pt":1657540686475,"mc":[{"id":"1.200806927","rc":[{"atl":[[1.09,0.35]],"id":228749}]}]}
{"op":"mcm","clk":"APfzrAkAzJ+eCgCg46AK","pt":1657540690686,"mc":[{"id":"1.200806927","rc":[{"atl":[[1.1,12.11],[1.09,0]],"trd":[[1.1,2231.97],[1.09,1564.21]],"ltp":1.1,"tv":82459.32,"id":228749},{"trd":[[12,44.72],[11,12.41]],"ltp":11,"tv":6675.59,"id":2857977}],"tv":89134.91}]}
{"op":"mcm","clk":"AIb1rAkA1KCeCgDq46AK","pt":1657540692286,"mc":[{"id":"1.200806927","rc":[{"atb":[[1.07,1682.66]],"id":228749}]}]}
{"op":"mcm","clk":"AJX1rAkA6qCeCgD146AK","pt":1657540692454,"mc":[{"id":"1.200806927","rc":[{"atb":[[1.09,1.11]],"atl":[[1.1,11.04]],"trd":[[1.1,2233.04]],"tv":82460.39,"id":228749},{"trd":[[11,12.51]],"tv":6675.69,"id":2857977}],"tv":89136.08}]}
{"op":"mcm","clk":"ALv1rAkAn6GeCgCR5KAK","pt":1657540693006,"mc":[{"id":"1.200806927","rc":[{"atb":[[1.09,1.64]],"id":228749}]}]}
{"op":"mcm","clk":"AOT1rAkAxqGeCgCh5KAK","pt":1657540693484,"mc":[{"id":"1.200806927","rc":[{"atl":[[13.5,0]],"id":2857977}]}]}
{"op":"mcm","clk":"AIn4rAkAj6SeCgDO5aAK","pt":1657540696876,"mc":[{"id":"1.200806927","rc":[{"atb":[[1.09,3.22]],"id":228749}]}]}
{"op":"mcm","clk":"AOn4rAkA/KSeCgCY5qAK","pt":1657540698088,"mc":[{"id":"1.200806927","rc":[{"atb":[[1.09,4.27]],"id":228749}]}]}
{"op":"mcm","clk":"AO/5rAkAsqaeCgDw5qAK","pt":1657540699901,"mc":[{"id":"1.200806927","rc":[{"atb":[[1.09,4.8]],"id":228749}]}]}
{"op":"mcm","clk":"AP35rAkAxaaeCgD85qAK","pt":1657540700110,"mc":[{"id":"1.200806927","rc":[{"atl":[[1.1,5.78]],"id":228749}]}]}
{"op":"mcm","clk":"AIP6rAkA0KaeCgCG56AK","pt":1657540700215,"mc":[{"id":"1.200806927","rc":[{"atb":[[1.09,5.58]],"id":228749}]}]}
{"op":"mcm","clk":"ALn7rAkAm6ieCgDu56AK","pt":1657540702413,"mc":[{"id":"1.200806927","rc":[{"atb":[[1.08,9.26],[1.09,0]],"trd":[[1.08,6862.23],[1.09,1575.37]],"ltp":1.08,"tv":83260.39,"id":228749}],"tv":89936.08}]}
{"op":"mcm","clk":"AI/8rAkA/qieCgCh6KAK","pt":1657540703414,"mc":[{"id":"1.200806927","rc":[{"atl":[[1.09,0.75]],"id":228749}]}]}
{"op":"mcm","clk":"AJz8rAkAkqmeCgCq6KAK","pt":1657540703612,"mc":[{"id":"1.200806927","rc":[{"atl":[[1.1,2.85],[1.09,0]],"trd":[[1.09,1576.87]],"ltp":1.09,"tv":83261.89,"id":228749}],"tv":89937.58}]}
{"op":"mcm","clk":"AM78rAkA0KmeCgDP6KAK","pt":1657540704297,"mc":[{"id":"1.200806927","rc":[{"atl":[[1.1,0.01]],"id":228749}]}]}
{"op":"mcm","clk":"AOr9rAkAl6ueCgC56aAK","pt":1657540706515,"mc":[{"id":"1.200806927","rc":[{"atl":[[11.5,1.67]],"id":2857977}]}]}
{"op":"mcm","clk":"AIf+rAkAzqueCgDX6aAK","pt":1657540706998,"mc":[{"id":"1.200806927","rc":[{"atb":[[1.1,2.62]],"atl":[[1.1,0]],"id":228749}]}]}
{"op":"mcm","clk":"APX+rAkAx6yeCgCb6qAK","pt":1657540708329,"mc":[{"id":"1.200806927","rc":[{"atl":[[11.5,0]],"id":2857977}]}]}
{"op":"mcm","clk":"AJv/rAkA76yeCgCu6qAK","pt":1657540708803,"mc":[{"id":"1.200806927","rc":[{"atb":[[1.1,7.88]],"id":228749}]}]}
{"op":"mcm","clk":"AKaBrQkAj6+eCgD266AK","pt":1657540712325,"mc":[{"id":"1.200806927","rc":[{"atb":[[1.09,0.53]],"id":228749}]}]}
{"op":"mcm","clk":"AIOCrQkA/6+eCgDJ7KAK","pt":1657540713525,"mc":[{"id":"1.200806927","rc":[{"atb":[[1.1,0],[1.09,0]],"atl":[[1.09,36.67]],"id":228749},{"atl":[[17.5,0]],"id":2857977}]}]}
{"op":"mcm","clk":"AJGCrQkAl7CeCgDV7KAK","pt":1657540713724,"mc":[{"id":"1.200806927","rc":[{"atl":[[1.1,601.11]],"id":228749}]}]}
{"op":"mcm","clk":"AMSFrQkAubSeCgCj76AK","pt":1657540719638,"mc":[{"id":"1.200806927","rc":[{"atl":[[1.09,26.15]],"id":228749}]}]}
{"op":"mcm","clk":"AP6FrQkAkLWeCgDV76AK","pt":1657540720527,"mc":[{"id":"1.200806927","rc":[{"atl":[[1.1,808.22]],"id":228749}]}]}
{"op":"mcm","clk":"AJKGrQkAq7WeCgDo76AK","pt":1657540720844,"mc":[{"id":"1.200806927","rc":[{"atl":[[1.09,23.52]],"id":228749}]}]}
{"op":"mcm","clk":"AKSGrQkAu7WeCgD176AK","pt":1657540721045,"mc":[{"id":"1.200806927","rc":[{"atl":[[1.09,20.59]],"trd":[[1.09,1579.8]],"tv":83264.82,"id":228749},{"trd":[[12,44.99]],"ltp":12,"tv":6675.96,"id":2857977}],"tv":89940.78}]}
{"op":"mcm","clk":"AKqGrQkAyrWeCgD476AK","pt":1657540721167,"mc":[{"id":"1.200806927","rc":[{"atl":[[1.1,821.17]],"id":228749}]}]}
{"op":"mcm","clk":"ALSGrQkA1bWeCgD976AK","pt":1657540721256,"mc":[{"id":"1.200806927","rc":[{"atl":[[1.1,787.27],[1.09,0]],"trd":[[1.1,2266.94],[1.09,1600.39]],"ltp":1.1,"tv":83319.31,"id":228749},{"trd":[[12,46.86],[11,15.9]],"ltp":11,"tv":6681.22,"id":2857977}],"tv":90000.53}]}
{"op":"mcm","clk":"APOGrQkAubaeCgCf8KAK","pt":1657540722154,"mc":[{"id":"1.200806927","rc":[{"atl":[[1.1,785.92]],"id":228749}]}]}
{"op":"mcm","clk":"AK2IrQkAkrieCgCK8aAK","pt":1657540724444,"mc":[{"id":"1.200806927","rc":[{"atl":[[1.09,400]],"id":228749}]}]}
{"op":"mcm","clk":"AL2IrQkAo7ieCgCZ8aAK","pt":1657540724655,"mc":[{"id":"1.200806927","rc":[{"atl":[[1.09,399.47]],"trd":[[1.09,1601.45]],"ltp":1.09,"tv":83320.37,"id":228749}],"tv":90001.59}]}
{"op":"mcm","clk":"ANCIrQkAubieCgCl8aAK","pt":1657540724922,"mc":[{"id":"1.200806927","rc":[{"atl":[[1.1,790.43]],"id":228749}]}]}
{"op":"mcm","clk":"AJWJrQkAirmeCgDU8aAK","pt":1657540725844,"mc":[{"id":"1.200806927","rc":[{"atl":[[1.09,398.62]],"trd":[[1.09,1603.14]],"tv":83322.06,"id":228749}],"tv":90003.28}]}
{"op":"mcm","clk":"AMeKrQkAwrqeCgDZ8qAK","pt":1657540728241,"mc":[{"id":"1.200806927","rc":[{"atl":[[1.09,346.03]],"trd":[[1.09,1708.32]],"tv":83427.24,"id":228749}],"tv":90108.46}]}
{"op":"mcm","clk":"AOGKrQkA4bqeCgDz8qAK","pt":1657540728645,"mc":[{"id":"1.200806927","rc":[{"atl":[[1.09,344.86]],"trd":[[1.09,1709.49]],"tv":83428.41,"id":228749},{"trd":[[12,46.97]],"ltp":12,"tv":6681.33,"id":2857977}],"tv":90109.74}]}
{"op":"mcm","clk":"AI+LrQkAnLueCgCO86AK","pt":1657540729249,"mc":[{"id":"1.200806927","rc":[{"atl":[[1.09,342.03]],"trd":[[1.09,1712.32]],"tv":83431.24,"id":228749},{"trd":[[12,47.22]],"tv":6681.58,"id":2857977}],"tv":90112.82}]}
{"op":"mcm","clk":"AMCLrQkA1bueCgC+86AK","pt":1657540729947,"mc":[{"id":"1.200806927","rc":[{"atl":[[1.09,335.67]],"trd":[[1.09,1719.21]],"tv":83438.13,"id":228749},{"trd":[[12,47.75]],"tv":6682.11,"id":2857977}],"tv":90120.24}]}
{"op":"mcm","clk":"AMSMrQkAxbyeCgCF9KAK","pt":1657540731348,"mc":[{"id":"1.200806927","rc":[{"atl":[[1.09,330.41]],"trd":[[1.09,1729.73]],"tv":83448.65,"id":228749}],"tv":90130.76}]}
{"op":"mcm","clk":"AMyMrQkAzryeCgCL9KAK","pt":1657540731457,"mc":[{"id":"1.200806927","rc":[{"atl":[[1.09,329.97]],"trd":[[1.09,1730.61]],"tv":83449.53,"id":228749}],"tv":90131.64}]}
{"op":"mcm","clk":"AOCMrQkA3ryeCgCV9KAK","pt":1657540731632,"mc":[{"id":"1.200806927","rc":[{"atl":[[1.1,785.92]],"id":228749}]}]}
{"op":"mcm","clk":"AOiMrQkA6LyeCgCZ9KAK","pt":1657540731734,"mc":[{"id":"1.200806927","rc":[{"atl":[[1.09,328.8]],"trd":[[1.09,1731.78]],"tv":83450.7,"id":228749},{"trd":[[12,47.86]],"tv":6682.22,"id":2857977}],"tv":90132.92}]}
{"op":"mcm","clk":"AIWNrQkAhL2eCgCn9KAK","pt":1657540732045,"mc":[{"id":"1.200806927","rc":[{"atl":[[1.09,328.27]],"trd":[[1.09,1732.84]],"tv":83451.76,"id":228749}],"tv":90133.98}]}
{"op":"mcm","clk":"AOqNrQkA4L2eCgDs9KAK","pt":1657540733248,"mc":[{"id":"1.200806927","rc":[{"atl":[[1.09,299.99]],"trd":[[1.09,1761.12]],"tv":83480.04,"id":228749},{"trd":[[12,50.43]],"tv":6684.79,"id":2857977}],"tv":90164.83}]}
{"op":"mcm","clk":"AKGOrQkAkr6eCgCM9aAK","pt":1657540733929,"mc":[{"id":"1.200806927","rc":[{"atl":[[1.09,298.82]],"trd":[[1.09,1762.29]],"tv":83481.21,"id":228749},{"trd":[[12,50.53]],"tv":6684.89,"id":2857977}],"tv":90166.1}]}
{"op":"mcm","clk":"AIGPrQkA7b6eCgDX9aAK","pt":1657540735272,"mc":[{"id":"1.200806927","rc":[{"atb":[[1.07,989.6]],"atl":[[1.09,297.77]],"trd":[[1.09,1764.39]],"tv":83483.31,"id":228749}],"tv":90168.2}]}
{"op":"mcm","clk":"AJKPrQkAiL+eCgDi9aAK","pt":1657540735537,"mc":[{"id":"1.200806927","rc":[{"atl":[[1.09,271.47]],"trd":[[1.09,1816.99]],"tv":83535.91,"id":228749}],"tv":90220.8}]}
{"op":"mcm","clk":"AK2PrQkAm7+eCgDt9aAK","pt":1657540735755,"mc":[{"id":"1.200806927","rc":[{"atl":[[1.1,1387.03]],"id":228749}]}]}
{"op":"mcm","clk":"AOKPrQkAy7+eCgCQ9qAK","pt":1657540736377,"mc":[{"id":"1.200806927","rc":[{"atl":[[1.09,270.3]],"trd":[[1.09,1818.16]],"tv":83537.08,"id":228749},{"trd":[[12,50.64]],"tv":6685,"id":2857977}],"tv":90222.08}]}
{"op":"mcm","clk":"AOuPrQkA0b+eCgCQ9qAK","pt":1657540736464,"mc":[{"id":"1.200806927","rc":[{"atl":[[1.09,268.72]],"trd":[[1.09,1821.32]],"tv":83540.24,"id":228749}],"tv":90225.24}]}
{"op":"mcm","clk":"AP+PrQkA4r+eCgCe9qAK","pt":1657540736719,"mc":[{"id":"1.200806927","rc":[{"atl":[[1.09,263.46]],"trd":[[1.09,1831.84]],"tv":83550.76,"id":228749}],"tv":90235.76}]}
{"op":"mcm","clk":"ALaQrQkAkcCeCgC19qAK","pt":1657540737256,"mc":[{"id":"1.200806927","rc":[{"atb":[[1.08,0]],"atl":[[1.08,2186.44]],"trd":[[1.08,6933.35]],"ltp":1.08,"tv":83621.88,"id":228749}],"tv":90306.88}]}
{"op":"mcm","clk":"ANGQrQkAqsCeCgDI9qAK","pt":1657540737557,"mc":[{"id":"1.200806927","rc":[{"atl":[[1.08,2185.94]],"trd":[[1.08,6933.85]],"tv":83622.38,"id":228749},{"trd":[[13.5,12.21]],"ltp":13.5,"tv":6685.04,"id":2857977}],"tv":90307.42}]}
{"op":"mcm","clk":"AOGQrQkAtcCeCgDR9qAK","pt":1657540737761,"mc":[{"id":"1.200806927","rc":[{"atl":[[1.08,2183.25]],"trd":[[1.08,6936.54]],"tv":83625.07,"id":228749},{"trd":[[13.5,12.43]],"tv":6685.26,"id":2857977}],"tv":90310.33}]}
{"op":"mcm","clk":"AO6QrQkAwsCeCgDV9qAK","pt":1657540737879,"mc":[{"id":"1.200806927","rc":[{"atl":[[1.08,0],[1.1,1179.92]],"id":228749}]}]}
{"op":"mcm","clk":"AImRrQkA38CeCgDg9qAK","pt":1657540738133,"mc":[{"id":"1.200806927","rc":[{"atl":[[1.09,258.2]],"trd":[[1.09,1842.36]],"ltp":1.09,"tv":83635.59,"id":228749}],"tv":90320.85}]}
{"op":"mcm","clk":"AJWRrQkA7MCeCgDo9qAK","pt":1657540738270,"mc":[{"id":"1.200806927","rc":[{"atl":[[1.09,2480.2]],"id":228749}]}]}
{"op":"mcm","clk":"AIGSrQkA1cGeCgCX96AK","pt":1657540739450,"mc":[{"id":"1.200806927","rc":[{"atl":[[1.09,2477.3]],"trd":[[1.09,1848.16]],"tv":83641.39,"id":228749}],"tv":90326.65}]}
{"op":"mcm","clk":"ALaSrQkAjcKeCgCm96AK","pt":1657540740070,"mc":[{"id":"1.200806927","rc":[{"atl":[[1.09,2477.1]],"trd":[[1.09,1848.56]],"tv":83641.79,"id":228749}],"tv":90327.05}]}
{"op":"mcm","clk":"ALySrQkAlcKeCgCp96AK","pt":1657540740171,"mc":[{"id":"1.200806927","rc":[{"atl":[[1.09,2476.93]],"trd":[[1.09,1848.9]],"tv":83642.13,"id":228749}],"tv":90327.39}]}
{"op":"mcm","clk":"APuSrQkA0sKeCgDM96AK","pt":1657540740870,"mc":[{"id":"1.200806927","rc":[{"atl":[[1.09,254.93]],"id":228749}]}]}
{"op":"mcm","clk":"AL+TrQkAkcOeCgDu96AK","pt":1657540741591,"mc":[{"id":"1.200806927","rc":[{"atl":[[1.12,407.41]],"id":228749}]}]}
{"op":"mcm","clk":"ANSUrQkAoMSeCgC8+KAK","pt":1657540743150,"mc":[{"id":"1.200806927","rc":[{"atl":[[1.09,249.1]],"trd":[[1.09,1854.73]],"tv":83647.96,"id":228749},{"trd":[[12,51.17]],"ltp":12,"tv":6685.79,"id":2857977}],"tv":90333.75}]}
{"op":"mcm","clk":"AP+UrQkAwsSeCgDT+KAK","pt":1657540743585,"mc":[{"id":"1.200806927","rc":[{"atl":[[1.09,248]],"trd":[[1.09,1855.83]],"tv":83649.06,"id":228749},{"trd":[[12,51.27]],"tv":6685.89,"id":2857977}],"tv":90334.95}]}
{"op":"mcm","clk":"AMmVrQkAjMWeCgD0+KAK","pt":1657540744345,"mc":[{"id":"1.200806927","rc":[{"atl":[[1.09,246.9]],"trd":[[1.09,1856.93]],"tv":83650.16,"id":228749},{"trd":[[12,51.37]],"tv":6685.99,"id":2857977}],"tv":90336.15}]}
{"op":"mcm","clk":"ANOVrQkAmMWeCgD7+KAK","pt":1657540744464,"mc":[{"id":"1.200806927","rc":[{"atl":[[1.09,244.27]],"trd":[[1.09,1862.19]],"tv":83655.42,"id":228749}],"tv":90341.41}]}
{"op":"mcm","clk":"AL+WrQkA8sWeCgCj+aAK","pt":1657540745646,"mc":[{"id":"1.200806927","rc":[{"atl":[[1.09,243.27]],"trd":[[1.09,1864.19]],"tv":83657.42,"id":228749}],"tv":90343.41}]}
{"op":"mcm","clk":"AJGXrQkAx8aeCgDM+aAK","pt":1657540746482,"mc":[{"id":"1.200806927","rc":[{"atl":[[1.08,52]],"id":228749}]}]}
{"op":"mcm","clk":"AJqXrQkA0MaeCgDP+aAK","pt":1657540746578,"mc":[{"id":"1.200806927","rc":[{"atl":[[1.08,32.73]],"trd":[[1.08,6955.81]],"ltp":1.08,"tv":83676.69,"id":228749},{"trd":[[13.5,13.97]],"ltp":13.5,"tv":6687.53,"id":2857977}],"tv":90364.22}]}
{"op":"mcm","clk":"AP+XrQkAs8eeCgCE+qAK","pt":1657540747768,"mc":[{"id":"1.200806927","rc":[{"atl":[[1.08,42.46]],"id":228749}]}]}
{"op":"mcm","clk":"AOybrQkAtcqeCgDj+6AK","pt":1657540752870,"mc":[{"id":"1.200806927","rc":[{"atl":[[1.08,16.16]],"trd":[[1.08,7008.41]],"tv":83729.29,"id":228749}],"tv":90416.82}]}
{"op":"mcm","clk":"AMKcrQkA+sqeCgCP/KAK","pt":1657540753784,"mc":[{"id":"1.200806927","rc":[{"atl":[[1.08,266.16]],"id":228749}]}]}
{"op":"mcm","clk":"ANqcrQkAl8ueCgCX/KAK","pt":1657540754081,"mc":[{"id":"1.200806927","rc":[{"atl":[[1.08,255.64]],"trd":[[1.08,7021.27]],"tv":83742.15,"id":228749}],"tv":90429.68}]}
{"op":"mcm","clk":"AJudrQkAz8ueCgC1/KAK","pt":1657540754764,"mc":[{"id":"1.200806927","rc":[{"atl":[[1.08,254.06]],"id":228749}]}]}
{"op":"mcm","clk":"AKadrQkA1sueCgDA/KAK","pt":1657540754869,"mc":[{"id":"1.200806927","rc":[{"atl":[[1.09,844.38]],"id":228749}]}]}
{"op":"mcm","clk":"AIuerQkAqcyeCgDx/KAK","pt":1657540755891,"mc":[{"id":"1.200806927","rc":[{"atl":[[1.09,1051.49]],"id":228749}]}]}
{"op":"mcm","clk":"AKmerQkAyMyeCgCK/aAK","pt":1657540756269,"mc":[{"id":"1.200806927","rc":[{"atl":[[1.08,248.88]],"trd":[[1.08,7023.51]],"tv":83744.39,"id":228749}],"tv":90431.92}]}
{"op":"mcm","clk":"AIqfrQkAk82eCgCx/aAK","pt":1657540757294,"mc":[{"id":"1.200806927","rc":[{"atl":[[1.08,237.63]],"trd":[[1.08,7034.76]],"tv":83755.64,"id":228749},{"trd":[[13.5,14.87]],"tv":6688.43,"id":2857977}],"tv":90444.07}]}
{"op":"mcm","clk":"ANKfrQkA0s2eCgDY/aAK","pt":1657540757985,"mc":[{"id":"1.200806927","rc":[{"atl":[[1.08,236.3]],"trd":[[1.08,7036.09]],"tv":83756.97,"id":228749},{"trd":[[13.5,14.97]],"tv":6688.53,"id":2857977}],"tv":90445.5}]}
{"op":"mcm","clk":"AL+grQkAlM6eCgD8/aAK","pt":1657540758970,"mc":[{"id":"1.200806927","rc":[{"atb":[[1.07,959.6]],"atl":[[1.08,229.67]],"trd":[[1.07,87.95],[1.08,7042.72]],"tv":83823.61,"id":228749},{"trd":[[13.5,15.5]],"tv":6689.06,"id":2857977}],"tv":90512.67}]}
{"op":"mcm","clk":"AIOhrQkAzM6eCgCT/qAK","pt":1657540759597,"mc":[{"id":"1.200806927","rc":[{"atl":[[1.08,228.62]],"trd":[[1.08,7044.82]],"tv":83825.71,"id":228749}],"tv":90514.77}]}
{"op":"mcm","clk":"AI6hrQkA1M6eCgCZ/qAK","pt":1657540759704,"mc":[{"id":"1.200806927","rc":[{"atl":[[1.08,228.09]],"trd":[[1.08,7045.88]],"tv":83826.77,"id":228749}],"tv":90515.83}]}
{"op":"mcm","clk":"AK2hrQkA6s6eCgCg/qAK","pt":1657540759969,"mc":[{"id":"1.200806927","rc":[{"atb":[[1.07,960.13]],"id":228749}]}]}
{"op":"mcm","clk":"ANKhrQkAg8+eCgCw/qAK","pt":1657540760335,"mc":[{"id":"1.200806927","rc":[{"atl":[[1.08,222.71]],"trd":[[1.08,7051.26]],"tv":83832.15,"id":228749},{"trd":[[13.5,15.94]],"tv":6689.5,"id":2857977}],"tv":90521.65}]}
{"op":"mcm","clk":"AJuirQkAx8+eCgDQ/qAK","pt":1657540761102,"mc":[{"id":"1.200806927","rc":[{"atl":[[1.08,221.13]],"trd":[[1.08,7054.42]],"tv":83835.31,"id":228749}],"tv":90524.81}]}
{"op":"mcm","clk":"AMqirQkA78+eCgDs/qAK","pt":1657540761583,"mc":[{"id":"1.200806927","rc":[{"atl":[[1.08,215.87]],"trd":[[1.08,7064.94]],"tv":83845.83,"id":228749}],"tv":90535.33}]}
{"op":"mcm","clk":"AJCjrQkAntCeCgCL/6AK","pt":1657540762346,"mc":[{"id":"1.200806927","rc":[{"atl":[[1.08,213.18]],"trd":[[1.08,7067.63]],"tv":83848.52,"id":228749},{"trd":[[13.5,16.15]],"tv":6689.71,"id":2857977}],"tv":90538.23}]}
{"op":"mcm","clk":"AKOjrQkAq9CeCgCT/6AK","pt":1657540762500,"mc":[{"id":"1.200806927","rc":[{"atb":[[1.08,688.44]],"atl":[[1.08,0]],"trd":[[1.08,7493.99]],"tv":84274.88,"id":228749}],"tv":90964.59}]}
{"op":"mcm","clk":"ALejrQkAt9CeCgCb/6AK","pt":1657540762687,"mc":[{"id":"1.200806927","rc":[{"atl":[[13.5,0.11]],"id":2857977}]}]}
{"op":"mcm","clk":"AMujrQkAydCeCgCn/6AK","pt":1657540762900,"mc":[{"id":"1.200806927","rc":[{"atb":[[1.08,688.97]],"id":228749}]}]}
{"op":"mcm","clk":"AKKkrQkAidGeCgDf/6AK","pt":1657540763813,"mc":[{"id":"1.200806927","rc":[{"atb":[[1.08,692.13]],"id":228749}]}]}
{"op":"mcm","clk":"AMKkrQkAqdGeCgDw/6AK","pt":1657540764194,"mc":[{"id":"1.200806927","rc":[{"atl":[[13.5,0.32]],"id":2857977}]}]}
{"op":"mcm","clk":"APGkrQkA3NGeCgCKgKEK","pt":1657540764786,"mc":[{"id":"1.200806927","rc":[{"atb":[[1.08,697.39]],"id":228749}]}]}
{"op":"mcm","clk":"APykrQkA4tGeCgCNgKEK","pt":1657540764891,"mc":[{"id":"1.200806927","rc":[{"atl":[[1.11,616.42]],"id":228749}]}]}
{"op":"mcm","clk":"AIilrQkA69GeCgCSgKEK","pt":1657540764994,"mc":[{"id":"1.200806927","rc":[{"atb":[[1.08,698.97]],"id":228749}]}]}
{"op":"mcm","clk":"AKGlrQkA/tGeCgCfgKEK","pt":1657540765306,"mc":[{"id":"1.200806927","rc":[{"atl":[[13.5,0.43]],"id":2857977}]}]}
{"op":"mcm","clk":"AI+mrQkA1dKeCgDNgKEK","pt":1657540766503,"mc":[{"id":"1.200806927","rc":[{"atb":[[1.08,720.49]],"id":228749}]}]}
{"op":"mcm","clk":"AOumrQkAjdOeCgDzgKEK","pt":1657540767282,"mc":[{"id":"1.200806927","rc":[{"atb":[[1.08,729.55]],"id":228749}]}]}
{"op":"mcm","clk":"AIqnrQkAqNOeCgD8gKEK","pt":1657540767590,"mc":[{"id":"1.200806927","rc":[{"atl":[[13.5,0.53]],"id":2857977}]}]}
{"op":"mcm","clk":"AMOnrQkA1tOeCgCSgaEK","pt":1657540768321,"mc":[{"id":"1.200806927","rc":[{"atb":[[1.08,734.81]],"id":228749}]}]}
{"op":"mcm","clk":"ANinrQkA7NOeCgCdgaEK","pt":1657540768616,"mc":[{"id":"1.200806927","rc":[{"atl":[[1.09,1050.96]],"trd":[[1.09,1865.25]],"ltp":1.09,"tv":84275.94,"id":228749},{"atl":[[13.5,0.43]],"id":2857977}],"tv":90965.65}]}
{"op":"mcm","clk":"ALOorQkAu9SeCgDPgaEK","pt":1657540769807,"mc":[{"id":"1.200806927","rc":[{"atb":[[1.08,729.55]],"id":228749}]}]}
{"op":"mcm","clk":"AJaprQkAotWeCgCDgqEK","pt":1657540770916,"mc":[{"id":"1.200806927","rc":[{"atb":[[1.08,740.27]],"trd":[[1.08,7494.19]],"ltp":1.08,"tv":84276.14,"id":228749}],"tv":90965.85}]}
{"op":"mcm","clk":"AJ2prQkAqNWeCgCHgqEK","pt":1657540771002,"mc":[{"id":"1.200806927","rc":[{"atb":[[1.08,738.69]],"id":228749}]}]}
{"op":"mcm","clk":"APGqrQkA6taeCgDwgqEK","pt":1657540773318,"mc":[{"id":"1.200806927","rc":[{"atl":[[13.5,0.53]],"id":2857977}]}]}
{"op":"mcm","clk":"AIWrrQkA/taeCgD6gqEK","pt":1657540773524,"mc":[{"id":"1.200806927","rc":[{"atb":[[1.08,743.95]],"id":228749}]}]}
{"op":"mcm","clk":"AOGsrQkAwtieCgDbg6EK","pt":1657540775894,"mc":[{"id":"1.200806927","rc":[{"atl":[[1.09,1050.43]],"trd":[[1.09,1866.31]],"ltp":1.09,"tv":84277.2,"id":228749}],"tv":90966.91}]}
{"op":"mcm","clk":"AJKtrQkA89ieCgD5g6EK","pt":1657540776523,"mc":[{"id":"1.200806927","rc":[{"atb":[[1.08,483.95]],"trd":[[1.08,8014.19]],"ltp":1.08,"tv":84797.2,"id":228749}],"tv":91486.91}]}
{"op":"mcm","clk":"AMCtrQkAntmeCgCWhKEK","pt":1657540777015,"mc":[{"id":"1.200806927","rc":[{"atl":[[1.09,1024.13]],"trd":[[1.09,1918.91]],"ltp":1.09,"tv":84849.8,"id":228749}],"tv":91539.51}]}
{"op":"mcm","clk":"AOutrQkAydmeCgCrhKEK","pt":1657540777514,"mc":[{"id":"1.200806927","rc":[{"atl":[[13.5,1.54]],"id":2857977}]}]}
{"op":"mcm","clk":"AIuurQkA8dmeCgDChKEK","pt":1657540777931,"mc":[{"id":"1.200806927","rc":[{"atl":[[1.09,971.54]],"trd":[[1.09,2024.09]],"tv":84954.98,"id":228749},{"atl":[[13.5,1.43]],"id":2857977}],"tv":91644.69}]}
{"op":"mcm","clk":"AKmurQkAkNqeCgDPhKEK","pt":1657540778212,"mc":[{"id":"1.200806927","rc":[{"atb":[[1.08,480.79]],"id":228749}]}]}
{"op":"mcm","clk":"AMawrQkAldyeCgDmhaEK","pt":1657540781338,"mc":[{"id":"1.200806927","rc":[{"atl":[[1.09,961.02]],"trd":[[1.09,2045.13]],"tv":84976.02,"id":228749}],"tv":91665.73}]}
{"op":"mcm","clk":"ANCwrQkAndyeCgDqhaEK","pt":1657540781442,"mc":[{"id":"1.200806927","rc":[{"atl":[[1.09,959.2]],"trd":[[1.09,2046.95]],"tv":84977.84,"id":228749},{"trd":[[12,51.54]],"ltp":12,"tv":6689.88,"id":2857977}],"tv":91667.72}]}
{"op":"mcm","clk":"AJW1rQkA8d+eCgDOh6EK","pt":1657540787035,"mc":[{"id":"1.200806927","rc":[{"atl":[[1.09,953.94]],"trd":[[1.09,2057.47]],"tv":84988.36,"id":228749}],"tv":91678.24}]}
{"op":"mcm","clk":"ALC1rQkAhuCeCgDbh6EK","pt":1657540787349,"mc":[{"id":"1.200806927","rc":[{"atl":[[1.09,952.77]],"trd":[[1.09,2058.64]],"tv":84989.53,"id":228749},{"trd":[[12,51.64]],"tv":6689.98,"id":2857977}],"tv":91679.51}]}
{"op":"mcm","clk":"ALa2rQkA+uCeCgCUiKEK","pt":1657540788724,"mc":[{"id":"1.200806927","rc":[{"atb":[[1.08,220.79]],"trd":[[1.08,8534.19]],"ltp":1.08,"tv":85509.53,"id":228749}],"tv":92199.51}]}
{"op":"mcm","clk":"AMq2rQkAi+GeCgCaiKEK","pt":1657540788929,"mc":[{"id":"1.200806927","rc":[{"atb":[[1.08,215.83]],"id":228749}]}]}
{"op":"mcm","clk":"AN+2rQkAn+GeCgCliKEK","pt":1657540789155,"mc":[{"id":"1.200806927","rc":[{"atl":[[1.09,951.6]],"trd":[[1.09,2059.81]],"ltp":1.09,"tv":85510.7,"id":228749},{"trd":[[12,51.75]],"tv":6690.09,"id":2857977}],"tv":92200.79}]}
{"op":"mcm","clk":"AOa2rQkApeGeCgCoiKEK","pt":1657540789244,"mc":[{"id":"1.200806927","rc":[{"atl":[[20,0.36]],"id":2857977}]}]}
{"op":"mcm","clk":"AM63rQkA8OGeCgDZiKEK","pt":1657540790150,"mc":[{"id":"1.200806927","rc":[{"atl":[[1.09,951.4]],"trd":[[1.09,2060.21]],"tv":85511.1,"id":228749}],"tv":92201.19}]}
{"op":"mcm","clk":"AP+3rQkAseKeCgD6iKEK","pt":1657540790843,"mc":[{"id":"1.200806927","rc":[{"atb":[[1.08,5.46]],"trd":[[1.08,8577.22]],"ltp":1.08,"tv":85554.13,"id":228749}],"tv":92244.22}]}
{"op":"mcm","clk":"AOW4rQkAieOeCgCuiaEK","pt":1657540791964,"mc":[{"id":"1.200806927","rc":[{"atl":[[1.09,940.88]],"trd":[[1.09,2081.25]],"ltp":1.09,"tv":85575.17,"id":228749}],"tv":92265.26}]}
{"op":"mcm","clk":"AO+5rQkA+OOeCgDjiaEK","pt":1657540793345,"mc":[{"id":"1.200806927","rc":[{"atl":[[1.09,935.05]],"trd":[[1.09,2087.08]],"tv":85581,"id":228749},{"trd":[[12,52.28]],"tv":6690.62,"id":2857977}],"tv":92271.62}]}
{"op":"mcm","clk":"AMm6rQkAv+SeCgCciqEK","pt":1657540794360,"mc":[{"id":"1.200806927","rc":[{"atl":[[1.09,932.42]],"trd":[[1.09,2092.34]],"tv":85586.26,"id":228749}],"tv":92276.88}]}
{"op":"mcm","clk":"AMa7rQkAquWeCgDbiqEK","pt":1657540795561,"mc":[{"id":"1.200806927","rc":[{"atl":[[1.09,929.89]],"trd":[[1.09,2097.4]],"tv":85591.32,"id":228749}],"tv":92281.94}]}
{"op":"mcm","clk":"AI+8rQkA3eWeCgD+iqEK","pt":1657540796256,"mc":[{"id":"1.200806927","rc":[{"atl":[[1.09,928.72]],"trd":[[1.09,2098.57]],"tv":85592.49,"id":228749},{"trd":[[12,52.39]],"tv":6690.73,"id":2857977}],"tv":92283.22}]}
{"op":"mcm","clk":"AJa+rQkAp+eeCgD1i6EK","pt":1657540798866,"mc":[{"id":"1.200806927","rc":[{"atb":[[1.08,0]],"atl":[[1.08,187.04]],"trd":[[1.08,8595.09]],"ltp":1.08,"tv":85610.36,"id":228749},{"atl":[[13.5,0]],"trd":[[13.5,17.58]],"ltp":13.5,"tv":6692.16,"id":2857977}],"tv":92302.52}]}
{"op":"mcm","clk":"AKa+rQkAvOeeCgD8i6EK","pt":1657540799070,"mc":[{"id":"1.200806927","rc":[{"atl":[[1.08,186.04]],"trd":[[1.08,8597.09]],"tv":85612.36,"id":228749}],"tv":92304.52}]}
{"op":"mcm","clk":"APC+rQkA7eeeCgCZjKEK","pt":1657540799761,"mc":[{"id":"1.200806927","rc":[{"atl":[[1.08,180.78]],"id":228749}]}]}
{"op":"mcm","clk":"AI+/rQkAh+ieCgCkjKEK","pt":1657540800056,"mc":[{"id":"1.200806927","rc":[{"atl":[[1.09,937.74]],"id":228749}]}]}
{"op":"mcm","clk":"AL/BrQkAleqeCgCajaEK","pt":1657540802474,"mc":[{"id":"1.200806927","rc":[{"atl":[[1.08,179.2]],"id":228749}]}]}
{"op":"mcm","clk":"AM3BrQkAoOqeCgCdjaEK","pt":1657540802582,"mc":[{"id":"1.200806927","rc":[{"atl":[[1.08,169.57]],"trd":[[1.08,8606.72]],"tv":85621.99,"id":228749},{"trd":[[13.5,18.35]],"tv":6692.93,"id":2857977}],"tv":92314.92}]}
{"op":"mcm","clk":"AOTBrQkAsOqeCgCujaEK","pt":1657540802750,"mc":[{"id":"1.200806927","rc":[{"atl":[[1.08,168.75]],"trd":[[1.08,8608.36]],"tv":85623.63,"id":228749}],"tv":92316.56}]}
{"op":"mcm","clk":"AJnCrQkA2eqeCgC/jaEK","pt":1657540803154,"mc":[{"id":"1.200806927","rc":[{"atb":[[1.04,25.72],[1.05,917.38],[1.06,1436.69],[1.02,156.03],[1.03,84.8],[1.01,1980.98]],"atl":[[1.66,6.7],[1.3,131.33],[1.11,616.43],[1.08,159.43],[1.14,19.51],[1.78,10.06],[1.7,119.78],[1.44,4.19],[1.12,407.42]],"trd":[[1.07,87.98],[1.29,1661.91],[1.32,516.53],[1.3,847.75],[1.22,875.63],[1.5,22.72],[1.25,1365.11],[1.8,95.96],[1.34,89.13],[1.08,8627],[1.1,2267.17],[1.09,2098.53],[1.23,747.13],[1.14,12364.52],[1.26,679.12],[1.19,91.56],[9,1.34],[1.12,12452.55],[1.38,16.57],[1.24,1621.55],[1.17,3710.55],[1.61,18.06],[1.66,49.51],[1.31,621.42],[1.13,1568.72],[1.11,15522.22],[1.16,5675.14],[1.15,8358.21],[1.27,688.31],[1.41,2.5],[1.4,55.52],[1.7,36.12],[1.68,11.73],[1.21,168.66],[1.45,113.6],[1.43,1.38],[1.28,2092.81],[1.2,23.16],[1.18,377.82]],"tv":85647.32,"id":228749},{"atb":[[1.35,31.84],[1.07,4.41],[2.2,13.41],[1.51,169.08],[2.46,10.14],[3,6.7],[1.45,37.71],[1.01,1573.08],[2,18.44]],"trd":[[8.8,1.68],[7.6,305.26],[4.1,23.59],[9.4,16.94],[13.5,18.38],[13,0.93],[12,52.42],[6.8,190.46],[11.5,17.5],[11,15.91],[5.3,16.3],[10,1639.66],[4.3,274.32],[8,1512.79],[4.8,57.76],[4.7,57.64],[4.2,162.12],[5.7,19.04],[5.2,50.68],[3.95,47.16],[5,15.95],[8.6,49.89],[4.5,40.47],[7.2,825.3],[5.4,14.34],[4.4,34.03],[4.9,63.76],[9.2,1106.15],[6.4,16.4]],"tv":6693.57,"id":2857977}],"tv":92340.89}]}
{"op":"mcm","clk":"AM3CrQkAgOueCgDSjaEK","pt":1657540803579,"mc":[{"id":"1.200806927","rc":[{"atl":[[1.08,156.73]],"trd":[[1.08,8629.7]],"tv":85650.02,"id":228749},{"trd":[[13.5,18.59]],"tv":6693.78,"id":2857977}],"tv":92343.8}]}
{"op":"mcm","clk":"AOPCrQkAj+ueCgDbjaEK","pt":1657540803746,"mc":[{"id":"1.200806927","rc":[{"atl":[[1.08,150.1]],"trd":[[1.08,8636.33]],"tv":85656.65,"id":228749},{"trd":[[13.5,19.12]],"tv":6694.31,"id":2857977}],"tv":92350.96}]}
{"op":"mcm","clk":"AIrDrQkApuueCgDrjaEK","pt":1657540804059,"mc":[{"id":"1.200806927","rc":[{"atl":[[1.08,147.47]],"id":228749}]}]}
{"op":"mcm","clk":"AOXDrQkA8OueCgCPjqEK","pt":1657540804761,"mc":[{"id":"1.200806927","rc":[{"atl":[[1.08,144.77]],"trd":[[1.08,8639.03]],"tv":85659.35,"id":228749},{"trd":[[13.5,19.34]],"tv":6694.53,"id":2857977}],"tv":92353.88}]}
{"op":"mcm","clk":"AKrFrQkAme2eCgDpjqEK","pt":1657540806268,"mc":[{"id":"1.200806927","rc":[{"atl":[[1.3,131.03]],"id":228749}]}]}
{"op":"mcm","clk":"AN7FrQkAye2eCgD9jqEK","pt":1657540806778,"mc":[{"id":"1.200806927","rc":[{"atl":[[1.08,233]],"id":228749}]}]}
{"op":"mcm","clk":"AJbHrQkA1e6eCgDLj6EK","pt":1657540808368,"mc":[{"id":"1.200806927","rc":[{"atl":[[1.08,232.9]],"trd":[[1.08,8639.23]],"tv":85659.55,"id":228749}],"tv":92354.08}]}
{"op":"mcm","clk":"ANnIrQkA6u+eCgCdkKEK","pt":1657540810196,"mc":[{"id":"1.200806927","rc":[{"atl":[[1.08,231.57]],"trd":[[1.08,8640.56]],"tv":85660.88,"id":228749},{"trd":[[13.5,19.44]],"tv":6694.63,"id":2857977}],"tv":92355.51}]}
{"op":"mcm","clk":"AIvJrQkAn/CeCgC0kKEK","pt":1657540810673,"mc":[{"id":"1.200806927","rc":[{"atl":[[1.08,316.11]],"id":228749}]}]}
{"op":"mcm","clk":"AOPJrQkA9vCeCgDgkKEK","pt":1657540811492,"mc":[{"id":"1.200806927","rc":[{"atl":[[1.08,263.52]],"id":228749}]}]}
{"op":"mcm","clk":"AIHKrQkAlPGeCgDrkKEK","pt":1657540811775,"mc":[{"id":"1.200806927","rc":[{"atl":[[1.08,260.89]],"id":228749}]}]}
{"op":"mcm","clk":"AO3KrQkA6vGeCgCakaEK","pt":1657540812670,"mc":[{"id":"1.200806927","rc":[{"atl":[[1.09,942.54]],"id":228749}]}]}
{"op":"mcm","clk":"AJfLrQkAjPKeCgCukaEK","pt":1657540812979,"mc":[{"id":"1.200806927","rc":[{"atl":[[1.08,259.28]],"trd":[[1.08,8642.17]],"tv":85662.49,"id":228749},{"trd":[[13.5,19.57]],"tv":6694.76,"id":2857977}],"tv":92357.25}]}
{"op":"mcm","clk":"AKzLrQkAm/KeCgC3kaEK","pt":1657540813186,"mc":[{"id":"1.200806927","rc":[{"atl":[[1.08,259.17]],"trd":[[1.08,8642.39]],"tv":85662.71,"id":228749}],"tv":92357.47}]}
{"op":"mcm","clk":"AOjMrQkArvOeCgCSkqEK","pt":1657540814866,"mc":[{"id":"1.200806927","rc":[{"atl":[[1.08,248.65]],"id":228749}]}]}
{"op":"mcm","clk":"AKDNrQkA1/OeCgCkkqEK","pt":1657540815282,"mc":[{"id":"1.200806927","rc":[{"atl":[[1.08,247.6]],"id":228749}]}]}
{"op":"mcm","clk":"AKTOrQkA0vSeCgDJkqEK","pt":1657540816312,"mc":[{"id":"1.200806927","rc":[{"atb":[[1.06,1481.77]],"id":228749}]}]}
{"op":"mcm","clk":"AOPOrQkA/fSeCgDgkqEK","pt":1657540816789,"mc":[{"id":"1.200806927","rc":[{"atl":[[1.08,237.08]],"id":228749}]}]}
{"op":"mcm","clk":"AK7PrQkAzPWeCgD7kqEK","pt":1657540817362,"mc":[{"id":"1.200806927","rc":[{"atb":[[1.06,1581.77]],"atl":[[1.08,230.49]],"trd":[[1.08,8643.72]],"tv":85664.04,"id":228749},{"trd":[[13.5,19.68]],"tv":6694.87,"id":2857977}],"tv":92358.91}]}
{"op":"mcm","clk":"ANvQrQkAzfaeCgDQk6EK","pt":1657540818906,"mc":[{"id":"1.200806927","rc":[{"atb":[[1.07,1170.5]],"id":228749}]}]}
{"op":"mcm","clk":"AJ/RrQkA+vaeCgDvk6EK","pt":1657540819471,"mc":[{"id":"1.200806927","rc":[{"atl":[[1.08,229.2]],"trd":[[1.08,8646.31]],"tv":85666.63,"id":228749}],"tv":92361.5}]}
{"op":"mcm","clk":"AMrSrQkA7/eeCgDHlKEK","pt":1657540821075,"mc":[{"id":"1.200806927","rc":[{"atl":[[1.08,202.9]],"id":228749}]}]}
{"op":"mcm","clk":"ANTSrQkA+PeeCgDOlKEK","pt":1657540821182,"mc":[{"id":"1.200806927","rc":[{"atl":[[1.08,202.12]],"id":228749}]}]}
{"op":"mcm","clk":"APXSrQkAmfieCgDglKEK","pt":1657540821501,"mc":[{"id":"1.200806927","rc":[{"atl":[[1.08,199.49]],"id":228749}]}]}
{"op":"mcm","clk":"AJ/TrQkAxfieCgD5lKEK","pt":1657540821884,"mc":[{"id":"1.200806927","rc":[{"atl":[[1.08,110.73]],"id":228749}]}]}
{"op":"mcm","clk":"AMHTrQkA4PieCgCIlaEK","pt":1657540822169,"mc":[{"id":"1.200806927","rc":[{"atl":[[1.08,110.62]],"trd":[[1.08,8646.52]],"tv":85666.84,"id":228749}],"tv":92361.71}]}
{"op":"mcm","clk":"APDTrQkAi/meCgCYlaEK","pt":1657540822570,"mc":[{"id":"1.200806927","rc":[{"atl":[[1.08,110.49]],"trd":[[1.08,8646.78]],"tv":85667.1,"id":228749}],"tv":92361.97}]}
{"op":"mcm","clk":"ALXUrQkAwvmeCgC5laEK","pt":1657540823162,"mc":[{"id":"1.200806927","rc":[{"atl":[[1.08,107.86]],"id":228749}]}]}
{"op":"mcm","clk":"AL/UrQkAzfmeCgC/laEK","pt":1657540823272,"mc":[{"id":"1.200806927","rc":[{"atl":[[1.08,106.53]],"trd":[[1.08,8648.11]],"tv":85668.43,"id":228749},{"trd":[[13.5,19.79]],"tv":6694.98,"id":2857977}],"tv":92363.41}]}
{"op":"mcm","clk":"AMPVrQkAsvqeCgCDlqEK","pt":1657540824492,"mc":[{"id":"1.200806927","rc":[{"atb":[[1.08,153.47]],"atl":[[1.08,0]],"trd":[[1.08,8861.17]],"tv":85881.49,"id":228749}],"tv":92576.47}]}
{"op":"mcm","clk":"ANPWrQkAo/ueCgDJlqEK","pt":1657540825907,"mc":[{"id":"1.200806927","rc":[{"atb":[[1.08,158.73]],"id":228749}]}]}
{"op":"mcm","clk":"AN3WrQkAqfueCgDSlqEK","pt":1657540826008,"mc":[{"id":"1.200806927","rc":[{"atb":[[1.08,159.26],[1.02,159.92]],"id":228749}]}]}
{"op":"mcm","clk":"AOfWrQkAtvueCgDZlqEK","pt":1657540826119,"mc":[{"id":"1.200806927","rc":[{"atb":[[1.08,169.78]],"id":228749}]}]}
{"op":"mcm","clk":"AMzXrQkAsPyeCgCQl6EK","pt":1657540827015,"mc":[{"id":"1.200806927","rc":[{"atb":[[1.08,81.02]],"trd":[[1.08,9038.69]],"tv":86059.01,"id":228749}],"tv":92753.99}]}
{"op":"mcm","clk":"AJfYrQkA7/yeCgC3l6EK","pt":1657540827770,"mc":[{"id":"1.200806927","rc":[{"atb":[[1.08,83.02]],"id":228749}]}]}
{"op":"mcm","clk":"ALXYrQkAoP2eCgDEl6EK","pt":1657540828059,"mc":[{"id":"1.200806927","rc":[{"atb":[[1.08,83.45]],"id":228749}]}]}
{"op":"mcm","clk":"ANfYrQkAuP2eCgDOl6EK","pt":1657540828325,"mc":[{"id":"1.200806927","rc":[{"atb":[[1.08,81.45]],"id":228749}]}]}
{"op":"mcm","clk":"AOrYrQkA0P2eCgDcl6EK","pt":1657540828567,"mc":[{"id":"1.200806927","rc":[{"atb":[[1.08,82.3]],"id":228749}]}]}
{"op":"mcm","clk":"AInZrQkA8v2eCgDql6EK","pt":1657540828880,"mc":[{"id":"1.200806927","rc":[{"atb":[[1.07,1174.81]],"id":228749}]}]}
{"op":"mcm","clk":"ALjZrQkAqP6eCgCEmKEK","pt":1657540829387,"mc":[{"id":"1.200806927","rc":[{"atb":[[1.08,84.93]],"id":228749}]}]}
{"op":"mcm","clk":"APzZrQkA5f6eCgCrmKEK","pt":1657540830088,"mc":[{"id":"1.200806927","rc":[{"atb":[[1.08,102]],"id":228749}]}]}
{"op":"mcm","clk":"AMHarQkApf+eCgDFmKEK","pt":1657540830783,"mc":[{"id":"1.200806927","rc":[{"atb":[[1.08,102.53]],"id":228749}]}]}
{"op":"mcm","clk":"AIzbrQkA1/+eCgDomKEK","pt":1657540831497,"mc":[{"id":"1.200806927","rc":[{"atb":[[1.08,102.1]],"id":228749}]}]}
{"op":"mcm","clk":"ALvbrQkA/P+eCgCEmaEK","pt":1657540832001,"mc":[{"id":"1.200806927","rc":[{"atl":[[14.5,0]],"id":2857977}]}]}
{"op":"mcm","clk":"APrbrQkAtICfCgChmaEK","pt":1657540832614,"mc":[{"id":"1.200806927","rc":[{"atb":[[1.08,103.68]],"id":228749}]}]}
{"op":"mcm","clk":"AI7crQkAyICfCgCpmaEK","pt":1657540832820,"mc":[{"id":"1.200806927","rc":[{"atl":[[13.5,0.53]],"id":2857977}]}]}
{"op":"mcm","clk":"AJjcrQkA0ICfCgCsmaEK","pt":1657540832914,"mc":[{"id":"1.200806927","rc":[{"atl":[[1.16,1103.59]],"id":228749}]}]}
{"op":"mcm","clk":"AKTcrQkA2oCfCgCtmaEK","pt":1657540832979,"mc":[{"id":"1.200806927","rc":[{"atl":[[1.2,0.53]],"id":228749}]}]}
{"op":"mcm","clk":"AJPdrQkAuIGfCgDkmaEK","pt":1657540834015,"mc":[{"id":"1.200806927","rc":[{"atb":[[1.08,109.16]],"id":228749}]}]}
{"op":"mcm","clk":"AMLdrQkA1YGfCgD8maEK","pt":1657540834408,"mc":[{"id":"1.200806927","rc":[{"atl":[[1.3,131.14]],"id":228749}]}]}
{"op":"mcm","clk":"ALDerQkAnIKfCgCnmqEK","pt":1657540835322,"mc":[{"id":"1.200806927","rc":[{"atb":[[1.08,0]],"atl":[[1.08,2106.21]],"trd":[[1.08,9263.64]],"tv":86283.96,"id":228749},{"atl":[[13.5,0]],"trd":[[13.5,20.32]],"tv":6695.51,"id":2857977}],"tv":92979.47}]}
{"op":"mcm","clk":"AJXfrQkA6IKfCgDKmqEK","pt":1657540836319,"mc":[{"id":"1.200806927","rc":[{"atl":[[1.08,2108.8]],"id":228749}]}]}
{"op":"mcm","clk":"AMbfrQkAl4OfCgDlmqEK","pt":1657540836801,"mc":[{"id":"1.200806927","rc":[{"atl":[[1.08,2.59]],"id":228749}]}]}
{"op":"mcm","clk":"AM/hrQkA/oSfCgD2m6EK","pt":1657540839629,"mc":[{"id":"1.200806927","rc":[{"atl":[[1.08,0.59]],"trd":[[1.08,9267.64]],"tv":86287.96,"id":228749}],"tv":92983.47}]}
{"op":"mcm","clk":"AKLirQkA2IWfCgCgnKEK","pt":1657540840513,"mc":[{"id":"1.200806927","rc":[{"atb":[[1.06,1597.55]],"id":228749}]}]}
{"op":"mcm","clk":"AMvirQkAhIafCgCrnKEK","pt":1657540840936,"mc":[{"id":"1.200806927","rc":[{"atl":[[1.08,0],[1.09,939.26]],"trd":[[1.08,9268.23],[1.09,2101.81]],"ltp":1.09,"tv":86291.83,"id":228749},{"trd":[[13.5,20.36],[12,52.71]],"ltp":12,"tv":6695.84,"id":2857977}],"tv":92987.67}]}
{"op":"mcm","clk":"AMbjrQkA+oafCgDpnKEK","pt":1657540842195,"mc":[{"id":"1.200806927","rc":[{"atl":[[1.09,934]],"trd":[[1.09,2112.33]],"tv":86302.35,"id":228749}],"tv":92998.19}]}
{"op":"mcm","clk":"APTjrQkAoYefCgCBnaEK","pt":1657540842728,"mc":[{"id":"1.200806927","rc":[{"atl":[[1.09,932.1]],"trd":[[1.09,2114.23]],"tv":86304.25,"id":228749},{"trd":[[12,52.89]],"tv":6696.02,"id":2857977}],"tv":93000.27}]}
{"op":"mcm","clk":"AKznrQkAmoqfCgCknqEK","pt":1657540847038,"mc":[{"id":"1.200806927","rc":[{"atl":[[1.08,35.34]],"id":228749}]}]}
{"op":"mcm","clk":"ALnorQkAjoufCgDunqEK","pt":1657540848343,"mc":[{"id":"1.200806927","rc":[{"atl":[[1.08,35.24]],"trd":[[1.08,9268.43]],"ltp":1.08,"tv":86304.45,"id":228749}],"tv":93000.47}]}
{"op":"mcm","clk":"AO7orQkAtoufCgD/nqEK","pt":1657540848807,"mc":[{"id":"1.200806927","rc":[{"atb":[[1.03,87.39]],"id":228749}]}]}
{"op":"mcm","clk":"ANbprQkAhYyfCgCtn6EK","pt":1657540849726,"mc":[{"id":"1.200806927","rc":[{"atb":[[1.07,1172.18]],"atl":[[1.08,8.94]],"id":228749}]}]}
{"op":"mcm","clk":"AKrrrQkAn42fCgD9n6EK","pt":1657540851623,"mc":[{"id":"1.200806927","rc":[{"atb":[[1.07,961.81]],"id":228749}]}]}
{"op":"mcm","clk":"APXsrQkAyo6fCgC8oKEK","pt":1657540853533,"mc":[{"id":"1.200806927","rc":[{"atl":[[1.08,258.41]],"id":228749}],"con":true}]}
{"op":"mcm","clk":"AL3urQkA7o+fCgCKoaEK","pt":1657540855540,"mc":[{"id":"1.200806927","rc":[{"atl":[[1.08,255.84]],"trd":[[1.08,9273.58]],"tv":86309.6,"id":228749}],"tv":93005.62}]}
{"op":"mcm","clk":"ANHurQkAgZCfCgCQoaEK","pt":1657540855720,"mc":[{"id":"1.200806927","rc":[{"atl":[[1.16,502.48]],"id":228749}]}]}
{"op":"mcm","clk":"AIPwrQkAj5GfCgDUoaEK","pt":1657540857447,"mc":[{"id":"1.200806927","rc":[{"atb":[[1.07,898.69]],"id":228749}]}]}
{"op":"mcm","clk":"AKrwrQkAsZGfCgDkoaEK","pt":1657540857850,"mc":[{"id":"1.200806927","rc":[{"atl":[[1.08,229.54]],"trd":[[1.08,9314.5]],"tv":86350.52,"id":228749}],"tv":93046.54}]}
{"op":"mcm","clk":"AL7wrQkAv5GfCgDqoaEK","pt":1657540858024,"mc":[{"id":"1.200806927","rc":[{"atl":[[1.08,229.11]],"trd":[[1.08,9315.36]],"tv":86351.38,"id":228749}],"tv":93047.4}]}
{"op":"mcm","clk":"AMnwrQkAyZGfCgDuoaEK","pt":1657540858139,"mc":[{"id":"1.200806927","rc":[{"atl":[[1.08,223.85]],"trd":[[1.08,9325.88]],"tv":86361.9,"id":228749}],"tv":93057.92}]}
{"op":"mcm","clk":"ANPwrQkAz5GfCgD0oaEK","pt":1657540858228,"mc":[{"id":"1.200806927","rc":[{"atl":[[1.15,603.09]],"id":228749}]}]}
{"op":"mcm","clk":"AIXxrQkA+ZGfCgCLoqEK","pt":1657540858773,"mc":[{"id":"1.200806927","rc":[{"atb":[[1.04,27.3]],"id":228749}]}]}
{"op":"mcm","clk":"AJbxrQkAh5KfCgCSoqEK","pt":1657540858945,"mc":[{"id":"1.200806927","rc":[{"atl":[[1.08,223.42]],"trd":[[1.08,9326.74]],"tv":86362.76,"id":228749}],"tv":93058.78}]}
{"op":"mcm","clk":"AJrxrQkAjZKfCgCVoqEK","pt":1657540859058,"mc":[{"id":"1.200806927","rc":[{"atl":[[1.08,433.79]],"id":228749}]}]}
{"op":"mcm","clk":"AOzxrQkA2JKfCgC1oqEK","pt":1657540859864,"mc":[{"id":"1.200806927","rc":[{"atl":[[1.08,433.26]],"trd":[[1.08,9327.8]],"tv":86363.82,"id":228749}],"tv":93059.84}]}
{"op":"mcm","clk":"AIzyrQkA85KfCgC+oqEK","pt":1657540860160,"mc":[{"id":"1.200806927","rc":[{"atl":[[1.08,406.96]],"trd":[[1.08,9380.4]],"tv":86416.42,"id":228749}],"tv":93112.44}]}
{"op":"mcm","clk":"AKXyrQkAj5OfCgDHoqEK","pt":1657540860438,"mc":[{"id":"1.200806927","rc":[{"atl":[[1.15,1.98]],"id":228749}]}]}
{"op":"mcm","clk":"ALzyrQkApZOfCgDRoqEK","pt":1657540860658,"mc":[{"id":"1.200806927","rc":[{"atl":[[1.08,406.62]],"trd":[[1.08,9381.09]],"tv":86417.11,"id":228749}],"tv":93113.13}]}
{"op":"mcm","clk":"AJf0rQkA8JSfCgCko6EK","pt":1657540862671,"mc":[{"id":"1.200806927","rc":[{"atl":[[1.08,404.46]],"trd":[[1.08,9383.25]],"tv":86419.27,"id":228749},{"trd":[[13.5,20.54]],"ltp":13.5,"tv":6696.2,"id":2857977}],"tv":93115.47}]}
{"op":"mcm","clk":"AKz0rQkAhZWfCgCro6EK","pt":1657540862873,"mc":[{"id":"1.200806927","rc":[{"atl":[[1.13,0]],"id":228749}]}]}
{"op":"mcm","clk":"ALr0rQkAkJWfCgCwo6EK","pt":1657540862981,"mc":[{"id":"1.200806927","rc":[{"atl":[[1.08,401.83]],"trd":[[1.08,9388.51]],"tv":86424.53,"id":228749}],"tv":93120.73}]}
{"op":"mcm","clk":"AKX1rQkA6pWfCgDZo6EK","pt":1657540863868,"mc":[{"id":"1.200806927","rc":[{"atl":[[15,2.74]],"id":2857977}]}]}
{"op":"mcm","clk":"AKX2rQkA45afCgCIpKEK","pt":1657540865134,"mc":[{"id":"1.200806927","rc":[{"atl":[[1.08,382.08]],"trd":[[1.08,9408.26]],"tv":86444.28,"id":228749},{"trd":[[13.5,22.12]],"tv":6697.78,"id":2857977}],"tv":93142.06}]}
{"op":"mcm","clk":"AL32rQkA+JafCgCSpKEK","pt":1657540865341,"mc":[{"id":"1.200806927","rc":[{"atl":[[1.12,6.04]],"id":228749}]}]}
{"op":"mcm","clk":"AJT3rQkAxJefCgC9pKEK","pt":1657540866146,"mc":[{"id":"1.200806927","rc":[{"atl":[[20,0.8]],"id":2857977}]}]}
{"op":"mcm","clk":"AMj3rQkA8JefCgDUpKEK","pt":1657540866663,"mc":[{"id":"1.200806927","rc":[{"atl":[[1.08,380.75]],"trd":[[1.08,9409.59]],"tv":86445.61,"id":228749},{"trd":[[13.5,22.22]],"tv":6697.88,"id":2857977}],"tv":93143.49}]}
{"op":"mcm","clk":"APD3rQkAl5ifCgDjpKEK","pt":1657540867056,"mc":[{"id":"1.200806927","rc":[{"atb":[[1.07,893.43]],"id":228749}]}]}
{"op":"mcm","clk":"ALL4rQkA1ZifCgD6pKEK","pt":1657540867679,"mc":[{"id":"1.200806927","rc":[{"atl":[[1.08,328.16]],"trd":[[1.08,9514.77]],"tv":86550.79,"id":228749}],"tv":93248.67}]}
{"op":"mcm","clk":"AL34rQkA3ZifCgCApaEK","pt":1657540867780,"mc":[{"id":"1.200806927","rc":[{"atl":[[1.08,328.24]],"id":228749}]}]}
{"op":"mcm","clk":"AM74rQkA9pifCgCJpaEK","pt":1657540867957,"mc":[{"id":"1.200806927","rc":[{"atl":[[1.08,327.45]],"trd":[[1.08,9516.35]],"tv":86552.37,"id":228749}],"tv":93250.25}]}
{"op":"mcm","clk":"AID5rQkArJmfCgCkpaEK","pt":1657540868581,"mc":[{"id":"1.200806927","rc":[{"atl":[[1.08,326.92]],"trd":[[1.08,9517.41]],"tv":86553.43,"id":228749}],"tv":93251.31}]}
{"op":"mcm","clk":"AIr5rQkAtZmfCgCnpaEK","pt":1657540868673,"mc":[{"id":"1.200806927","rc":[{"atl":[[1.08,325.59]],"trd":[[1.08,9518.74]],"tv":86554.76,"id":228749},{"trd":[[13.5,22.33]],"tv":6697.99,"id":2857977}],"tv":93252.75}]}
{"op":"mcm","clk":"APf5rQkAmZqfCgDhpaEK","pt":1657540869747,"mc":[{"id":"1.200806927","rc":[{"atl":[[1.11,15.32]],"id":228749}]}]}
{"op":"mcm","clk":"AL/6rQkA0pqfCgD3paEK","pt":1657540870477,"mc":[{"id":"1.200806927","rc":[{"atl":[[1.08,322.89]],"trd":[[1.08,9521.44]],"tv":86557.46,"id":228749},{"trd":[[13.5,22.55]],"tv":6698.21,"id":2857977}],"tv":93255.67}]}
{"op":"mcm","clk":"APP6rQkAiZufCgCHpqEK","pt":1657540871042,"mc":[{"id":"1.200806927","rc":[{"atl":[[1.08,322.78]],"trd":[[1.08,9521.65]],"tv":86557.67,"id":228749}],"tv":93255.88}]}
{"op":"mcm","clk":"AIr7rQkAl5ufCgCPpqEK","pt":1657540871260,"mc":[{"id":"1.200806927","rc":[{"atb":[[1.07,683.06]],"id":228749}]}]}
{"op":"mcm","clk":"AJT7rQkAoZufCgCTpqEK","pt":1657540871360,"mc":[{"id":"1.200806927","rc":[{"atl":[[1.08,320.15]],"trd":[[1.08,9526.91]],"tv":86562.93,"id":228749}],"tv":93261.14}]}
{"op":"mcm","clk":"AKf7rQkAs5ufCgCcpqEK","pt":1657540871577,"mc":[{"id":"1.200806927","rc":[{"atl":[[1.08,317.52]],"trd":[[1.08,9532.17]],"tv":86568.19,"id":228749}],"tv":93266.4}]}
{"op":"mcm","clk":"AL/8rQkAv5yfCgDMpqEK","pt":1657540873056,"mc":[{"id":"1.200806927","rc":[{"atl":[[1.08,307]],"trd":[[1.08,9553.21]],"tv":86589.23,"id":228749}],"tv":93287.44}]}
{"op":"mcm","clk":"AMH+rQkAjp6fCgC2p6EK","pt":1657540875668,"mc":[{"id":"1.200806927","rc":[{"atl":[[1.08,306.21]],"trd":[[1.08,9554.79]],"tv":86590.81,"id":228749}],"tv":93289.02}]}
{"op":"mcm","clk":"AOf/rQkAn5+fCgD1p6EK","pt":1657540877365,"mc":[{"id":"1.200806927","rc":[{"atl":[[1.1,578.81]],"id":228749}]}]}
{"op":"mcm","clk":"AOiArgkAg6CfCgCvqKEK","pt":1657540878559,"mc":[{"id":"1.200806927","rc":[{"atb":[[1.07,322.41]],"id":228749}]}]}
{"op":"mcm","clk":"AIyCrgkAlaGfCgDhqKEK","pt":1657540880080,"mc":[{"id":"1.200806927","rc":[{"atl":[[1.09,330.99]],"id":228749}]}]}
{"op":"mcm","clk":"APGCrgkA4qGfCgCOqaEK","pt":1657540880984,"mc":[{"id":"1.200806927","rc":[{"atl":[[1.08,292.52]],"trd":[[1.08,9568.48]],"tv":86604.5,"id":228749},{"trd":[[13.5,23.64]],"tv":6699.3,"id":2857977}],"tv":93303.8}]}
{"op":"mcm","clk":"AKaDrgkAjKKfCgCoqaEK","pt":1657540881493,"mc":[{"id":"1.200806927","rc":[{"atl":[[1.08,291.73]],"trd":[[1.08,9570.06]],"tv":86606.08,"id":228749}],"tv":93305.38}]}
{"op":"mcm","clk":"ALaDrgkAnKKfCgCvqaEK","pt":1657540881657,"mc":[{"id":"1.200806927","rc":[{"atl":[[1.08,290.68]],"trd":[[1.08,9572.16]],"tv":86608.18,"id":228749}],"tv":93307.48}]}
{"op":"mcm","clk":"ANSErgkAoqOfCgDzqaEK","pt":1657540883168,"mc":[{"id":"1.200806927","rc":[{"atl":[[1.08,288.22]],"trd":[[1.08,9577.08]],"tv":86613.1,"id":228749}],"tv":93312.4}]}
{"op":"mcm","clk":"ALiFrgkAhaSfCgClqqEK","pt":1657540884176,"mc":[{"id":"1.200806927","rc":[{"atl":[[1.08,287.69]],"trd":[[1.08,9578.14]],"tv":86614.16,"id":228749}],"tv":93313.46}]}
{"op":"mcm","clk":"APaFrgkAwaSfCgDIqqEK","pt":1657540884882,"mc":[{"id":"1.200806927","rc":[{"atl":[[1.08,286.36]],"trd":[[1.08,9579.47]],"tv":86615.49,"id":228749},{"trd":[[13.5,23.75]],"tv":6699.41,"id":2857977}],"tv":93314.9}]}
{"op":"mcm","clk":"APyFrgkAy6SfCgDKqqEK","pt":1657540884978,"mc":[{"id":"1.200806927","rc":[{"atl":[[1.1,12.95]],"id":228749}]}]}
{"op":"mcm","clk":"AI+GrgkA3qSfCgDUqqEK","pt":1657540885163,"mc":[{"id":"1.200806927","rc":[{"atl":[[1.08,285.03]],"trd":[[1.08,9580.8]],"tv":86616.82,"id":228749},{"trd":[[13.5,23.86]],"tv":6699.52,"id":2857977}],"tv":93316.34}]}
{"op":"mcm","clk":"AMKGrgkAjqWfCgDtqqEK","pt":1657540885787,"mc":[{"id":"1.200806927","rc":[{"atl":[[1.08,262.48]],"trd":[[1.08,9625.9]],"tv":86661.92,"id":228749}],"tv":93361.44}]}
{"op":"mcm","clk":"AJqIrgkAvKafCgDZq6EK","pt":1657540887995,"mc":[{"id":"1.200806927","rc":[{"atl":[[1.08,261.06]],"trd":[[1.08,9628.74]],"tv":86664.76,"id":228749}],"tv":93364.28}]}
{"op":"mcm","clk":"ANqJrgkA1qefCgCvrKEK","pt":1657540890091,"mc":[{"id":"1.200806927","rc":[{"atb":[[1.07,112.04]],"id":228749}]}]}
{"op":"mcm","clk":"AISKrgkA+KefCgC/rKEK","pt":1657540890502,"mc":[{"id":"1.200806927","rc":[{"atl":[[1.08,260.31]],"trd":[[1.08,9630.24]],"tv":86666.26,"id":228749}],"tv":93365.78}]}
{"op":"mcm","clk":"AIOLrgkA4aifCgDzrKEK","pt":1657540891702,"mc":[{"id":"1.200806927","rc":[{"atl":[[1.08,259.31]],"trd":[[1.08,9632.24]],"tv":86668.26,"id":228749}],"tv":93367.78}]}
{"op":"mcm","clk":"AIyLrgkA66ifCgD4rKEK","pt":1657540891768,"mc":[{"id":"1.200806927","rc":[{"atb":[[1.07,110.04]],"trd":[[1.07,91.98]],"ltp":1.07,"tv":86672.26,"id":228749}],"tv":93371.78}]}
{"op":"mcm","clk":"AKGLrgkA/aifCgCFraEK","pt":1657540891971,"mc":[{"id":"1.200806927","rc":[{"atl":[[1.08,256.68]],"trd":[[1.08,9637.5]],"ltp":1.08,"tv":86677.52,"id":228749}],"tv":93377.04}]}
{"op":"mcm","clk":"ANCLrgkAmKmfCgCXraEK","pt":1657540892372,"mc":[{"id":"1.200806927","rc":[{"atl":[[1.1,19.53]],"id":228749}]}]}
{"op":"mcm","clk":"AKaMrgkAz6mfCgC6raEK","pt":1657540893084,"mc":[{"id":"1.200806927","rc":[{"atl":[[1.08,256.51]],"trd":[[1.08,9637.84]],"tv":86677.86,"id":228749}],"tv":93377.38}]}
{"op":"mcm","clk":"ANaMrgkA76mfCgDPraEK","pt":1657540893495,"mc":[{"id":"1.200806927","rc":[{"atb":[[1.07,67.77]],"trd":[[1.07,176.51]],"ltp":1.07,"tv":86762.39,"id":228749}],"tv":93461.91}]}
{"op":"mcm","clk":"APyMrgkAiqqfCgDgraEK","pt":1657540893802,"mc":[{"id":"1.200806927","rc":[{"atl":[[1.08,247.88]],"trd":[[1.08,9655.1]],"ltp":1.08,"tv":86779.65,"id":228749}],"tv":93479.17}]}
{"op":"mcm","clk":"AIiNrgkAnqqfCgDnraEK","pt":1657540893980,"mc":[{"id":"1.200806927","rc":[{"atl":[[1.08,242.62]],"trd":[[1.08,9665.62]],"tv":86790.17,"id":228749}],"tv":93489.69}]}
{"op":"mcm","clk":"AL2NrgkAxKqfCgD5raEK","pt":1657540894395,"mc":[{"id":"1.200806927","rc":[{"atl":[[1.08,241.73]],"trd":[[1.08,9667.4]],"tv":86791.95,"id":228749}],"tv":93491.47}]}
{"op":"mcm","clk":"AI2OrgkA9KqfCgCerqEK","pt":1657540895068,"mc":[{"id":"1.200806927","rc":[{"atl":[[1.08,240.42]],"trd":[[1.08,9670.02]],"tv":86794.57,"id":228749}],"tv":93494.09}]}
{"op":"mcm","clk":"AMmOrgkAoqufCgC7rqEK","pt":1657540895603,"mc":[{"id":"1.200806927","rc":[{"atl":[[1.08,238.26]],"trd":[[1.08,9672.18]],"tv":86796.73,"id":228749},{"trd":[[13.5,24.03]],"tv":6699.69,"id":2857977}],"tv":93496.42}]}
{"op":"mcm","clk":"AJSQrgkAqayfCgCjr6EK","pt":1657540897378,"mc":[{"id":"1.200806927","rc":[{"atl":[[1.08,236.26]],"trd":[[1.08,9676.18]],"tv":86800.73,"id":228749}],"tv":93500.42}]}
{"op":"mcm","clk":"AOCQrgkA5KyfCgDPr6EK","pt":1657540898113,"mc":[{"id":"1.200806927","rc":[{"atl":[[1.1,12.95]],"id":228749}]}]}
{"op":"mcm","clk":"AOmQrgkA76yfCgDVr6EK","pt":1657540898213,"mc":[{"id":"1.200806927","rc":[{"atb":[[1.1,987.05],[1.09,1432.75]],"atl":[[1.08,0],[1.1,0],[1.09,0]],"trd":[[1.08,10148.7],[1.1,2293.07],[1.09,2776.21]],"ltp":1.1,"tv":87961.13,"id":228749}],"tv":94660.82}]}
{"op":"mcm","clk":"APuQrgkA/ayfCgDer6EK","pt":1657540898383,"mc":[{"id":"1.200806927","rc":[{"atb":[[1.08,175.28]],"id":228749}]}]}
{"op":"mcm","clk":"AJeRrgkAnK2fCgDur6EK","pt":1657540898680,"mc":[{"id":"1.200806927","rc":[{"atb":[[1.08,175.71]],"id":228749}]}]}
{"op":"mcm","clk":"AJOSrgkAlq6fCgCwsKEK","pt":1657540899994,"mc":[{"id":"1.200806927","rc":[{"atl":[[1.11,0]],"trd":[[1.11,15537.54]],"ltp":1.11,"tv":87976.45,"id":228749},{"atl":[[12,2398.3]],"trd":[[10,1641.36]],"ltp":10,"tv":6701.39,"id":2857977}],"tv":94677.84}]}
{"op":"mcm","clk":"AK6SrgkAsK6fCgC8sKEK","pt":1657540900266,"mc":[{"id":"1.200806927","rc":[{"atb":[[1.1,776.68]],"trd":[[1.1,2713.81]],"ltp":1.1,"tv":88397.19,"id":228749}],"tv":95098.58}]}
{"op":"mcm","clk":"AO6SrgkA8q6fCgDksKEK","pt":1657540900894,"mc":[{"id":"1.200806927","rc":[{"atb":[[1.08,177.01]],"id":228749}]}]}
{"op":"mcm","clk":"APiSrgkA/K6fCgDssKEK","pt":1657540901005,"mc":[{"id":"1.200806927","rc":[{"atb":[[1.08,178.26]],"id":228749}]}]}
{"op":"mcm","clk":"AICTrgkAg6+fCgDysKEK","pt":1657540901104,"mc":[{"id":"1.200806927","rc":[{"atl":[[12,2399.1]],"id":2857977}]}]}
{"op":"mcm","clk":"AKSTrgkApK+fCgCDsaEK","pt":1657540901384,"mc":[{"id":"1.200806927","rc":[{"atb":[[1.08,188.26]],"id":228749}]}]}
{"op":"mcm","clk":"ANeTrgkAya+fCgCesaEK","pt":1657540901794,"mc":[{"id":"1.200806927","rc":[{"atb":[[1.08,188.36],[1.12,25.99]],"atl":[[1.12,0]],"trd":[[1.12,12464.62]],"ltp":1.12,"tv":88409.26,"id":228749}],"tv":95110.65}]}
{"op":"mcm","clk":"AICUrgkA6K+fCgCysaEK","pt":1657540902206,"mc":[{"id":"1.200806927","rc":[{"atb":[[1.08,191.06]],"id":228749}]}]}
{"op":"mcm","clk":"AJiUrgkAgrCfCgC9saEK","pt":1657540902418,"mc":[{"id":"1.200806927","rc":[{"atb":[[1.08,180.76]],"id":228749}]}]}
{"op":"mcm","clk":"AOKUrgkAxLCfCgDVsaEK","pt":1657540903185,"mc":[{"id":"1.200806927","rc":[{"atl":[[9.6,210.37]],"id":2857977}]}]}
{"op":"mcm","clk":"APKUrgkA1bCfCgDesaEK","pt":1657540903403,"mc":[{"id":"1.200806927","rc":[{"atb":[[1.08,200.76]],"id":228749}]}]}
{"op":"mcm","clk":"APqVrgkAxrGfCgCksqEK","pt":1657540904722,"mc":[{"id":"1.200806927","rc":[{"atb":[[1.08,180.76]],"id":228749}]}]}
{"op":"mcm","clk":"AIqWrgkA1LGfCgCrsqEK","pt":1657540904894,"mc":[{"id":"1.200806927","rc":[{"atl":[[12,0.8]],"id":2857977}]}]}
{"op":"mcm","clk":"AK2WrgkA/7GfCgDJsqEK","pt":1657540905384,"mc":[{"id":"1.200806927","rc":[{"atb":[[1.06,1097.55]],"id":228749}]}]}
{"op":"mcm","clk":"AMmWrgkAmLKfCgDfsqEK","pt":1657540905708,"mc":[{"id":"1.200806927","rc":[{"atb":[[1.05,417.38],[1.08,179.71]],"id":228749}]}]}
{"op":"mcm","clk":"APGXrgkAorOfCgC6s6EK","pt":1657540907438,"mc":[{"id":"1.200806927","rc":[{"atb":[[1.08,179.93]],"id":228749}]}]}
{"op":"mcm","clk":"APyYrgkAj7SfCgCKtKEK","pt":1657540908752,"mc":[{"id":"1.200806927","rc":[{"atb":[[1.11,500]],"id":228749}]}]}
{"op":"mcm","clk":"AI+ZrgkAobSfCgCOtKEK","pt":1657540908906,"mc":[{"id":"1.200806927","rc":[{"atb":[[1.11,1000]],"id":228749}]}]}
{"op":"mcm","clk":"AKyZrgkAurSfCgCctKEK","pt":1657540909219,"mc":[{"id":"1.200806927","rc":[{"atb":[[1.12,525.99]],"id":228749}]}]}
{"op":"mcm","clk":"AL+ZrgkAz7SfCgCqtKEK","pt":1657540909435,"mc":[{"id":"1.200806927","rc":[{"atb":[[1.12,1025.99]],"id":228749},{"atl":[[9.6,0]],"id":2857977}]}]}
{"op":"mcm","clk":"AMmZrgkA2rSfCgCwtKEK","pt":1657540909535,"mc":[{"id":"1.200806927","rc":[{"atb":[[1.07,4.31]],"id":228749}]}]}
{"op":"mcm","clk":"AMyargkAvrWfCgDftKEK","pt":1657540910713,"mc":[{"id":"1.200806927","rc":[{"atb":[[1.1,0],[1.09,0]],"id":228749}]}]}
{"op":"mcm","clk":"APaargkA4LWfCgD7tKEK","pt":1657540911151,"mc":[{"id":"1.200806927","rc":[{"atb":[[1.08,4.65]],"id":228749}]}]}
{"op":"mcm","clk":"ANSbrgkAqrafCgCotaEK","pt":1657540912034,"mc":[{"id":"1.200806927","rc":[{"atb":[[1.08,3.36]],"id":228749}]}]}
{"op":"mcm","clk":"AIicrgkA0rafCgDCtaEK","pt":1657540912515,"mc":[{"id":"1.200806927","rc":[{"atb":[[1.08,2.28]],"id":228749}]}]}
{"op":"mcm","clk":"AM2drgkA37efCgCltqEK","pt":1657540914442,"mc":[{"id":"1.200806927","rc":[{"atb":[[1.12,25.99]],"atl":[[1.15,0]],"id":228749}]}]}
{"op":"mcm","clk":"AN+drgkA77efCgCutqEK","pt":1657540914634,"mc":[{"id":"1.200806927","rc":[{"atl":[[1.13,12.95]],"id":228749}]}]}
{"op":"mcm","clk":"AKeergkArrifCgDVtqEK","pt":1657540915417,"mc":[{"id":"1.200806927","rc":[{"atb":[[1.06,1052.47]],"id":228749}]}]}
{"op":"mcm","clk":"AN2ergkA3rifCgD2tqEK","pt":1657540916043,"mc":[{"id":"1.200806927","rc":[{"atb":[[1.12,0]],"atl":[[1.12,0.31]],"trd":[[1.12,12516.61]],"tv":88461.25,"id":228749}],"tv":95162.64}]}
{"op":"mcm","clk":"ALefrgkArrmfCgCft6EK","pt":1657540916923,"mc":[{"id":"1.200806927","rc":[{"atl":[[1.12,77.98]],"id":228749}]}]}
{"op":"mcm","clk":"AM6frgkAvLmfCgCrt6EK","pt":1657540917139,"mc":[{"id":"1.200806927","rc":[{"atl":[[1.12,235.75]],"id":228749}]}]}
{"op":"mcm","clk":"AOafrgkAzrmfCgC1t6EK","pt":1657540917358,"mc":[{"id":"1.200806927","rc":[{"atl":[[1.12,236.54]],"id":228749}]}]}
{"op":"mcm","clk":"ALegrgkAi7qfCgDXt6EK","pt":1657540918043,"mc":[{"id":"1.200806927","rc":[{"atl":[[1.12,2736.54]],"id":228749}]}]}
{"op":"mcm","clk":"AOGgrgkArbqfCgDot6EK","pt":1657540918452,"mc":[{"id":"1.200806927","rc":[{"atb":[[1.11,989.48]],"trd":[[1.11,15558.58]],"ltp":1.11,"tv":88482.29,"id":228749}],"tv":95183.68}]}
{"op":"mcm","clk":"ALCirgkA0rufCgDMuKEK","pt":1657540920355,"mc":[{"id":"1.200806927","rc":[{"atl":[[1.13,65.54]],"id":228749}]}]}
{"op":"mcm","clk":"ANqirgkA9LufCgDluKEK","pt":1657540920764,"mc":[{"id":"1.200806927","rc":[{"atb":[[1.07,0]],"atl":[[1.12,2741.8]],"id":228749}]}]}
{"op":"mcm","clk":"AIekrgkAgL2fCgChuaEK","pt":1657540922441,"mc":[{"id":"1.200806927","rc":[{"atl":[[1.14,2273.57]],"id":228749}]}]}
{"op":"mcm","clk":"ANGkrgkAx72fCgC/uaEK","pt":1657540923222,"mc":[{"id":"1.200806927","rc":[{"atl":[[1.12,2747.06]],"id":228749}]}]}
{"op":"mcm","clk":"AO6krgkA4b2fCgDRuaEK","pt":1657540923548,"mc":[{"id":"1.200806927","rc":[{"atl":[[1.12,2747.59]],"id":228749}]}]}
{"op":"mcm","clk":"ALSlrgkAm76fCgDtuaEK","pt":1657540924169,"mc":[{"id":"1.200806927","rc":[{"atb":[[9.4,0.53]],"id":2857977}]}]}
{"op":"mcm","clk":"AL2lrgkAo76fCgDxuaEK","pt":1657540924241,"mc":[{"id":"1.200806927","rc":[{"atl":[[1.12,2745.94]],"trd":[[1.12,12518.33]],"ltp":1.12,"tv":88484.01,"id":228749}],"tv":95185.4}]}
{"op":"mcm","clk":"APalrgkA0r6fCgCLuqEK","pt":1657540924765,"mc":[{"id":"1.200806927","rc":[{"atb":[[1.1,500]],"id":228749}]}]}
{"op":"mcm","clk":"AIimrgkA476fCgCTuqEK","pt":1657540924927,"mc":[{"id":"1.200806927","rc":[{"atl":[[1.12,2746.99]],"id":228749}]}]}
{"op":"mcm","clk":"AIumrgkA676fCgCXuqEK","pt":1657540925006,"mc":[{"id":"1.200806927","rc":[{"atl":[[1.13,72.12]],"id":228749}]}]}
{"op":"mcm","clk":"AJqnrgkA57+fCgDCuqEK","pt":1657540926249,"mc":[{"id":"1.200806927","rc":[{"atb":[[1.06,952.47]],"id":228749}]}]}
{"op":"mcm","clk":"ALunrgkAisCfCgDMuqEK","pt":1657540926538,"mc":[{"id":"1.200806927","rc":[{"atl":[[1.12,2748.72]],"id":228749}]}]}
{"op":"mcm","clk":"ANynrgkAqMCfCgDauqEK","pt":1657540926848,"mc":[{"id":"1.200806927","rc":[{"atl":[[1.12,2698.72]],"trd":[[1.12,12618.33]],"tv":88584.01,"id":228749}],"tv":95285.4}]}
{"op":"mcm","clk":"AIKorgkA1cCfCgDluqEK","pt":1657540927222,"mc":[{"id":"1.200806927","rc":[{"atl":[[1.12,2698.19]],"id":228749}]}]}
{"op":"mcm","clk":"AJyorgkA88CfCgDvuqEK","pt":1657540927442,"mc":[{"id":"1.200806927","rc":[{"atb":[[1.1,1000]],"id":228749}]}]}
{"op":"mcm","clk":"AKaorgkA/sCfCgDyuqEK","pt":1657540927546,"mc":[{"id":"1.200806927","rc":[{"atl":[[1.12,2692.93]],"id":228749}]}]}
{"op":"mcm","clk":"AMuorgkAmMGfCgD7uqEK","pt":1657540927855,"mc":[{"id":"1.200806927","rc":[{"atl":[[1.12,2687.67]],"id":228749}]}]}
{"op":"mcm","clk":"AK2prgkA3cGfCgCfu6EK","pt":1657540928762,"mc":[{"id":"1.200806927","rc":[{"atb":[[1.11,986.85]],"atl":[[1.12,2687.52]],"trd":[[1.11,15563.84],[1.12,12618.63]],"tv":88589.57,"id":228749}],"tv":95290.96}]}
{"op":"mcm","clk":"AMuprgkA+8GfCgCtu6EK","pt":1657540929059,"mc":[{"id":"1.200806927","rc":[{"atb":[[1.11,934.26]],"trd":[[1.11,15669.02]],"ltp":1.11,"tv":88694.75,"id":228749}],"tv":95396.14}]}
{"op":"mcm","clk":"APOprgkAosKfCgC5u6EK","pt":1657540929432,"mc":[{"id":"1.200806927","rc":[{"atl":[[1.12,2684.59]],"id":228749}]}]}
{"op":"mcm","clk":"AJmqrgkAvsKfCgDCu6EK","pt":1657540929731,"mc":[{"id":"1.200806927","rc":[{"atl":[[1.13,65.54]],"id":228749}]}]}
{"op":"mcm","clk":"AKCqrgkAxsKfCgDGu6EK","pt":1657540929828,"mc":[{"id":"1.200806927","rc":[{"atl":[[1.12,2682.86]],"id":228749}]}]}
{"op":"mcm","clk":"ANaqrgkA+cKfCgDfu6EK","pt":1657540930372,"mc":[{"id":"1.200806927","rc":[{"atl":[[1.12,2687.59]],"id":228749}]}]}
{"op":"mcm","clk":"AKqsrgkAqsSfCgC0vKEK","pt":1657540932459,"mc":[{"id":"1.200806927","rc":[{"atl":[[1.12,2529.82]],"id":228749}]}]}
{"op":"mcm","clk":"APSsrgkA48SfCgDIvKEK","pt":1657540933160,"mc":[{"id":"1.200806927","rc":[{"atb":[[1.11,931.63]],"trd":[[1.11,15674.28]],"tv":88700.01,"id":228749}],"tv":95401.4}]}
{"op":"mcm","clk":"AO+vrgkApMefCgCPvqEK","pt":1657540936691,"mc":[{"id":"1.200806927","rc":[{"atl":[[15,0.11]],"id":2857977}]}]}
{"op":"mcm","clk":"AKiwrgkAz8efCgCqvqEK","pt":1657540937235,"mc":[{"id":"1.200806927","rc":[{"atb":[[1.08,0.65]],"id":228749}]}]}
{"op":"mcm","clk":"ALGwrgkA1MefCgCsvqEK","pt":1657540937267,"mc":[{"id":"1.200806927","rc":[{"atb":[[1.11,931.09]],"trd":[[1.11,15675.36]],"tv":88701.09,"id":228749}],"tv":95402.48}]}
{"op":"mcm","clk":"AOSwrgkA+8efCgC2vqEK","pt":1657540937706,"mc":[{"id":"1.200806927","rc":[{"atb":[[1.11,930.61]],"trd":[[1.11,15676.32]],"tv":88702.05,"id":228749}],"tv":95403.44}]}
{"op":"mcm","clk":"AKSxrgkAqcifCgDVvqEK","pt":1657540938227,"mc":[{"id":"1.200806927","rc":[{"atb":[[1.11,928.51]],"trd":[[1.11,15680.52]],"tv":88706.25,"id":228749}],"tv":95407.64}]}
{"op":"mcm","clk":"ALGxrgkAtcifCgDXvqEK","pt":1657540938415,"mc":[{"id":"1.200806927","rc":[{"atb":[[1.1,1210.37]],"atl":[[1.12,2527.19]],"id":228749},{"atb":[[9.4,1.06]],"id":2857977}]}]}
{"op":"mcm","clk":"AMGxrgkAx8ifCgDZvqEK","pt":1657540938534,"mc":[{"id":"1.200806927","rc":[{"atb":[[1.11,925.88]],"trd":[[1.11,15685.78]],"tv":88711.51,"id":228749}],"tv":95412.9}]}
{"op":"mcm","clk":"AIWyrgkA8cifCgDwvqEK","pt":1657540939078,"mc":[{"id":"1.200806927","rc":[{"atl":[[1.12,2540.14]],"id":228749}]}]}
{"op":"mcm","clk":"AJCyrgkAgcmfCgDyvqEK","pt":1657540939275,"mc":[{"id":"1.200806927","rc":[{"atb":[[1.11,815.44]],"trd":[[1.11,15906.66]],"tv":88932.39,"id":228749}],"tv":95633.78}]}
{"op":"mcm","clk":"AKOyrgkAjcmfCgD1vqEK","pt":1657540939392,"mc":[{"id":"1.200806927","rc":[{"atl":[[1.12,2538.56]],"id":228749}]}]}
{"op":"mcm","clk":"AMayrgkAn8mfCgCBv6EK","pt":1657540939659,"mc":[{"id":"1.200806927","rc":[{"atl":[[1.12,3188.56]],"id":228749}]}]}
{"op":"mcm","clk":"ANCzrgkAisqfCgDev6EK","pt":1657540940976,"mc":[{"id":"1.200806927","rc":[{"atb":[[9.4,0]],"atl":[[9.4,0.62]],"trd":[[9.4,19.05]],"ltp":9.4,"tv":6703.5,"id":2857977}],"tv":95635.89}]}
{"op":"mcm","clk":"ANizrgkAl8qfCgDhv6EK","pt":1657540941086,"mc":[{"id":"1.200806927","rc":[{"atb":[[1.11,415.44]],"trd":[[1.11,16706.66]],"tv":89732.39,"id":228749}],"tv":96435.89}]}
{"op":"mcm","clk":"AIK0rgkAu8qfCgDyv6EK","pt":1657540941499,"mc":[{"id":"1.200806927","rc":[{"atb":[[1.08,45.73]],"id":228749}]}]}
{"op":"mcm","clk":"AI20rgkAzMqfCgD5v6EK","pt":1657540941624,"mc":[{"id":"1.200806927","rc":[{"atl":[[1.12,3183.83]],"id":228749}]}]}
{"op":"mcm","clk":"AL60rgkA+sqfCgCNwKEK","pt":1657540942091,"mc":[{"id":"1.200806927","rc":[{"atb":[[1.1,1000]],"id":228749}]}]}
{"op":"mcm","clk":"AOK0rgkAoMufCgCiwKEK","pt":1657540942516,"mc":[{"id":"1.200806927","rc":[{"atl":[[1.12,3184.91]],"id":228749}]}]}
{"op":"mcm","clk":"AIa1rgkAu8ufCgCswKEK","pt":1657540942922,"mc":[{"id":"1.200806927","rc":[{"atb":[[1.11,362.85]],"trd":[[1.11,16811.84]],"tv":89837.57,"id":228749}],"tv":96541.07}]}
{"op":"mcm","clk":"ALK1rgkA3sufCgC3wKEK","pt":1657540943289,"mc":[{"id":"1.200806927","rc":[{"atl":[[1.12,3180.7]],"id":228749}]}]}
{"op":"mcm","clk":"ALu1rgkA5sufCgC6wKEK","pt":1657540943378,"mc":[{"id":"1.200806927","rc":[{"atl":[[1.12,3179.65]],"id":228749}]}]}
{"op":"mcm","clk":"AOO1rgkAjcyfCgDSwKEK","pt":1657540943823,"mc":[{"id":"1.200806927","rc":[{"atl":[[15,0.32]],"id":2857977}]}]}
{"op":"mcm","clk":"APu1rgkAn8yfCgDZwKEK","pt":1657540944109,"mc":[{"id":"1.200806927","rc":[{"atb":[[1.11,361.55]],"trd":[[1.11,16814.44]],"tv":89840.17,"id":228749}],"tv":96543.67}]}
{"op":"mcm","clk":"AI22rgkAssyfCgDfwKEK","pt":1657540944284,"mc":[{"id":"1.200806927","rc":[{"atb":[[1.11,358.92]],"trd":[[1.11,16819.7]],"tv":89845.43,"id":228749}],"tv":96548.93}]}
{"op":"mcm","clk":"ALW2rgkA1cyfCgD2wKEK","pt":1657540944736,"mc":[{"id":"1.200806927","rc":[{"atl":[[1.12,3178.77]],"trd":[[1.12,12619.51]],"ltp":1.12,"tv":89846.31,"id":228749},{"trd":[[9.2,1106.26]],"ltp":9.2,"tv":6703.61,"id":2857977}],"tv":96549.92}]}
{"op":"mcm","clk":"AOy2rgkA98yfCgCKwaEK","pt":1657540945212,"mc":[{"id":"1.200806927","rc":[{"atl":[[1.14,19.51]],"id":228749}]}]}
{"op":"mcm","clk":"AIG3rgkAis2fCgCTwaEK","pt":1657540945397,"mc":[{"id":"1.200806927","rc":[{"atl":[[1.12,3173.51]],"id":228749}]}]}
{"op":"mcm","clk":"AJO3rgkAm82fCgCcwaEK","pt":1657540945600,"mc":[{"id":"1.200806927","rc":[{"atb":[[1.11,358.13]],"trd":[[1.11,16821.28]],"ltp":1.11,"tv":89847.89,"id":228749}],"tv":96551.5}]}
{"op":"mcm","clk":"AKW3rgkAr82fCgCpwaEK","pt":1657540945810,"mc":[{"id":"1.200806927","rc":[{"atl":[[9.4,0]],"id":2857977}]}]}
{"op":"mcm","clk":"AM+3rgkA0M2fCgC4waEK","pt":1657540946228,"mc":[{"id":"1.200806927","rc":[{"atl":[[1.12,3177.93]],"id":228749}]}]}
{"op":"mcm","clk":"AOa3rgkA382fCgDBwaEK","pt":1657540946424,"mc":[{"id":"1.200806927","rc":[{"atl":[[1.12,3176.35]],"id":228749}]}]}
{"op":"mcm","clk":"AIa4rgkA+s2fCgDMwaEK","pt":1657540946698,"mc":[{"id":"1.200806927","rc":[{"atb":[[1.09,5.26]],"id":228749}]}]}
{"op":"mcm","clk":"AKK4rgkAls6fCgDYwaEK","pt":1657540947008,"mc":[{"id":"1.200806927","rc":[{"atl":[[1.12,3175.53]],"trd":[[1.12,12620.33]],"ltp":1.12,"tv":89848.71,"id":228749},{"trd":[[9.2,1106.36]],"tv":6703.71,"id":2857977}],"tv":96552.42}]}
{"op":"mcm","clk":"AKy4rgkAoM6fCgDdwaEK","pt":1657540947103,"mc":[{"id":"1.200806927","rc":[{"atl":[[1.12,3172.37]],"id":228749}]}]}
{"op":"mcm","clk":"ALO4rgkApc6fCgDgwaEK","pt":1657540947201,"mc":[{"id":"1.200806927","rc":[{"atl":[[3,11.35]],"id":228749}]}]}
{"op":"mcm","clk":"AMO4rgkAtc6fCgDrwaEK","pt":1657540947321,"mc":[{"id":"1.200806927","rc":[{"atl":[[1.12,3168.83]],"trd":[[1.12,12623.87]],"tv":89852.25,"id":228749},{"trd":[[9.2,1106.79]],"tv":6704.14,"id":2857977}],"tv":96556.39}]}
{"op":"mcm","clk":"AOu4rgkA5M6fCgCKwqEK","pt":1657540947782,"mc":[{"id":"1.200806927","rc":[{"atl":[[1.12,3168.4]],"trd":[[1.12,12624.73]],"tv":89853.11,"id":228749}],"tv":96557.25}]}
{"op":"mcm","clk":"AIC5rgkA986fCgCWwqEK","pt":1657540948006,"mc":[{"id":"1.200806927","rc":[{"atb":[[1.11,147.76]],"trd":[[1.11,17242.02]],"ltp":1.11,"tv":90273.85,"id":228749}],"tv":96977.99}]}
{"op":"mcm","clk":"ANy5rgkAys+fCgDDwqEK","pt":1657540948940,"mc":[{"id":"1.200806927","rc":[{"atl":[[1.12,3170.03]],"id":228749}]}]}
{"op":"mcm","clk":"AOe5rgkA0M+fCgDFwqEK","pt":1657540948996,"mc":[{"id":"1.200806927","rc":[{"atb":[[1.11,147.23]],"trd":[[1.11,17243.08]],"tv":90274.91,"id":228749}],"tv":96979.05}]}
{"op":"mcm","clk":"APG5rgkA08+fCgDJwqEK","pt":1657540949079,"mc":[{"id":"1.200806927","rc":[{"atl":[[1.12,3173.91]],"id":228749}]}]}
{"op":"mcm","clk":"AIa6rgkA6s+fCgDSwqEK","pt":1657540949301,"mc":[{"id":"1.200806927","rc":[{"atl":[[1.12,3172.83]],"id":228749}]}]}
{"op":"mcm","clk":"AK+6rgkAgdCfCgDhwqEK","pt":1657540949710,"mc":[{"id":"1.200806927","rc":[{"atl":[[1.12,3162.31]],"trd":[[1.12,12645.77]],"ltp":1.12,"tv":90295.95,"id":228749}],"tv":97000.09}]}
{"op":"mcm","clk":"AN26rgkAp9CfCgD5wqEK","pt":1657540950143,"mc":[{"id":"1.200806927","rc":[{"atl":[[1.12,3161.91]],"trd":[[1.12,12646.57]],"tv":90296.75,"id":228749}],"tv":97000.89}]}
{"op":"mcm","clk":"AMS7rgkA+dCfCgCdw6EK","pt":1657540951066,"mc":[{"id":"1.200806927","rc":[{"atl":[[1.12,3156.65]],"trd":[[1.12,12657.09]],"tv":90307.27,"id":228749}],"tv":97011.41}]}
{"op":"mcm","clk":"AM27rgkAhtGfCgCjw6EK","pt":1657540951197,"mc":[{"id":"1.200806927","rc":[{"atb":[[1.05,207.06],[1.11,144.07]],"atl":[[1.12,3155.59]],"trd":[[1.11,17249.4],[1.12,12658.15]],"ltp":1.11,"tv":90314.65,"id":228749},{"trd":[[9.2,1106.92]],"tv":6704.27,"id":2857977}],"tv":97018.92}]}
{"op":"mcm","clk":"APG7rgkApNGfCgCxw6EK","pt":1657540951591,"mc":[{"id":"1.200806927","rc":[{"atb":[[1.11,142.34]],"trd":[[1.11,17252.85]],"tv":90318.1,"id":228749}],"tv":97022.37}]}
{"op":"mcm","clk":"AKS8rgkA2NGfCgDLw6EK","pt":1657540952145,"mc":[{"id":"1.200806927","rc":[{"atb":[[1.11,89.75]],"trd":[[1.11,17358.03]],"tv":90423.28,"id":228749}],"tv":97127.55}]}
{"op":"mcm","clk":"AJi9rgkAr9KfCgD3w6EK","pt":1657540953334,"mc":[{"id":"1.200806927","rc":[{"atb":[[1.11,80.81]],"atl":[[1.12,2505.59]],"trd":[[1.11,17375.91]],"tv":90441.16,"id":228749}],"tv":97145.43}]}
{"op":"mcm","clk":"ALy9rgkAz9KfCgCGxKEK","pt":1657540953690,"mc":[{"id":"1.200806927","rc":[{"atl":[[1.12,2505.06]],"trd":[[1.12,12659.21]],"ltp":1.12,"tv":90442.22,"id":228749}],"tv":97146.49}]}
{"op":"mcm","clk":"ANG9rgkA4dKfCgCNxKEK","pt":1657540953904,"mc":[{"id":"1.200806927","rc":[{"atl":[[1.12,2503.43]],"id":228749}]}]}
{"op":"mcm","clk":"AIG+rgkAiNOfCgCnxKEK","pt":1657540954523,"mc":[{"id":"1.200806927","rc":[{"atb":[[1.11,75.81]],"trd":[[1.11,17385.91]],"ltp":1.11,"tv":90452.22,"id":228749}],"tv":97156.49}]}
{"op":"mcm","clk":"AKa+rgkApdOfCgC6xKEK","pt":1657540954917,"mc":[{"id":"1.200806927","rc":[{"atb":[[1.11,75.28]],"trd":[[1.11,17386.97]],"tv":90453.28,"id":228749}],"tv":97157.55}]}
{"op":"mcm","clk":"APe+rgkAztOfCgDYxKEK","pt":1657540955614,"mc":[{"id":"1.200806927","rc":[{"atb":[[1.11,0]],"atl":[[1.11,135.09]],"trd":[[1.11,17537.53]],"tv":90603.84,"id":228749}],"tv":97308.11}]}
{"op":"mcm","clk":"AIfArgkAqtSfCgCRxaEK","pt":1657540957127,"mc":[{"id":"1.200806927","rc":[{"atl":[[19.5,0]],"id":2857977}]}]}
{"op":"mcm","clk":"AK/ArgkAwdSfCgCdxaEK","pt":1657540957555,"mc":[{"id":"1.200806927","rc":[{"atl":[[1.11,134.72],[1.12,3405.05]],"trd":[[1.11,17538.27]],"tv":90604.58,"id":228749}],"tv":97308.85}]}
{"op":"mcm","clk":"AObArgkA7tSfCgCuxaEK","pt":1657540958140,"mc":[{"id":"1.200806927","rc":[{"atl":[[1.11,139.98]],"id":228749}]}]}
{"op":"mcm","clk":"AITBrgkAhNWfCgC3xaEK","pt":1657540958425,"mc":[{"id":"1.200806927","rc":[{"atb":[[1.1,216.76]],"trd":[[1.1,4280.29]],"ltp":1.1,"tv":92171.06,"id":228749}],"tv":98875.33}]}
{"op":"mcm","clk":"AMDBrgkArdWfCgDXxaEK","pt":1657540959045,"mc":[{"id":"1.200806927","rc":[{"atl":[[1.13,12.95]],"id":228749}]}]}
{"op":"mcm","clk":"AO7BrgkAy9WfCgDuxaEK","pt":1657540959522,"mc":[{"id":"1.200806927","rc":[{"atl":[[1.14,6.56]],"id":228749}]}]}
{"op":"mcm","clk":"APnBrgkA09WfCgD0xaEK","pt":1657540959627,"mc":[{"id":"1.200806927","rc":[{"atl":[[1.11,128.32]],"trd":[[1.11,17549.93]],"ltp":1.11,"tv":92182.72,"id":228749},{"trd":[[10,1642.66]],"ltp":10,"tv":6705.57,"id":2857977}],"tv":98888.29}]}
{"op":"mcm","clk":"AIbCrgkA2dWfCgD4xaEK","pt":1657540959728,"mc":[{"id":"1.200806927","rc":[{"atl":[[1.11,127.53]],"id":228749}]}]}
{"op":"mcm","clk":"AMXCrgkAiNafCgCMxqEK","pt":1657540960306,"mc":[{"id":"1.200806927","rc":[{"atl":[[1.11,122.27]],"id":228749}]}]}
{"op":"mcm","clk":"AJ7DrgkAv9afCgC7xqEK","pt":1657540961154,"mc":[{"id":"1.200806927","rc":[{"atl":[[1.19,0]],"id":228749}]}]}
{"op":"mcm","clk":"AInErgkAitefCgDpxqEK","pt":1657540962129,"mc":[{"id":"1.200806927","rc":[{"atl":[[1.11,123.85]],"id":228749}]}]}
{"op":"mcm","clk":"AKzErgkAqdefCgD/xqEK","pt":1657540962461,"mc":[{"id":"1.200806927","rc":[{"atb":[[1.1,0]],"id":228749}]}]}
{"op":"mcm","clk":"AL7ErgkAtdefCgCFx6EK","pt":1657540962598,"mc":[{"id":"1.200806927","rc":[{"atl":[[1.11,122.75]],"id":228749}]}]}
{"op":"mcm","clk":"AOrErgkA2NefCgCjx6EK","pt":1657540963049,"mc":[{"id":"1.200806927","rc":[{"atl":[[1.11,117.49]],"id":228749}]}]}
{"op":"mcm","clk":"ALTGrgkA5tifCgD4x6EK","pt":1657540964911,"mc":[{"id":"1.200806927","rc":[{"atb":[[1.09,505.26]],"id":228749}]}]}
{"op":"mcm","clk":"APPGrgkAn9mfCgCRyKEK","pt":1657540965655,"mc":[{"id":"1.200806927","rc":[{"atl":[[1.11,117.92]],"id":228749}]}]}
{"op":"mcm","clk":"AP/GrgkApdmfCgCVyKEK","pt":1657540965750,"mc":[{"id":"1.200806927","rc":[{"atb":[[1.09,1005.26]],"id":228749}]}]}
{"op":"mcm","clk":"ALvHrgkA1NmfCgCryKEK","pt":1657540966257,"mc":[{"id":"1.200806927","rc":[{"atl":[[1.12,3401.17]],"id":228749}]}]}
{"op":"mcm","clk":"AIbIrgkAitqfCgDGyKEK","pt":1657540966852,"mc":[{"id":"1.200806927","rc":[{"atl":[[1.11,112.66]],"id":228749}]}]}
{"op":"mcm","clk":"AJzIrgkAoNqfCgDSyKEK","pt":1657540967060,"mc":[{"id":"1.200806927","rc":[{"atl":[[1.11,111.7]],"trd":[[1.11,17550.89]],"tv":92183.68,"id":228749},{"trd":[[10,1642.76]],"tv":6705.67,"id":2857977}],"tv":98889.35}]}
{"op":"mcm","clk":"AL/JrgkAn9ufCgCmyaEK","pt":1657540968816,"mc":[{"id":"1.200806927","rc":[{"atl":[[1.11,110.37]],"trd":[[1.11,17552.22]],"tv":92185.01,"id":228749},{"trd":[[10,1642.91]],"tv":6705.82,"id":2857977}],"tv":98890.83}]}
{"op":"mcm","clk":"ANTJrgkAt9ufCgCuyaEK","pt":1657540969032,"mc":[{"id":"1.200806927","rc":[{"atl":[[1.11,108.79]],"id":228749}]}]}
{"op":"mcm","clk":"AIvKrgkA4NufCgDGyaEK","pt":1657540969663,"mc":[{"id":"1.200806927","rc":[{"atl":[[1.11,90.14]],"trd":[[1.11,17570.87]],"tv":92203.66,"id":228749},{"trd":[[10,1644.98]],"tv":6707.89,"id":2857977}],"tv":98911.55}]}
{"op":"mcm","clk":"ALDKrgkA9NufCgDXyaEK","pt":1657540970024,"mc":[{"id":"1.200806927","rc":[{"atl":[[1.11,90.06]],"trd":[[1.11,17571.03]],"tv":92203.82,"id":228749}],"tv":98911.71}]}
{"op":"mcm","clk":"AN/KrgkAltyfCgDxyaEK","pt":1657540970544,"mc":[{"id":"1.200806927","rc":[{"atl":[[1.1,13.13]],"trd":[[1.1,4280.49]],"ltp":1.1,"tv":92204.02,"id":228749}],"tv":98911.91}]}
{"op":"mcm","clk":"AL3LrgkA3dyfCgChyqEK","pt":1657540971441,"mc":[{"id":"1.200806927","rc":[{"atl":[[1.1,18.39]],"id":228749}]}]}
{"op":"mcm","clk":"AInMrgkAit2fCgDByqEK","pt":1657540972147,"mc":[{"id":"1.200806927","rc":[{"atl":[[1.1,7.89]],"trd":[[1.1,4290.99]],"tv":92214.52,"id":228749},{"trd":[[11,16.96]],"ltp":11,"tv":6708.94,"id":2857977}],"tv":98923.46}]}
{"op":"mcm","clk":"AL3NrgkAgd6fCgCGy6EK","pt":1657540973971,"mc":[{"id":"1.200806927","rc":[{"atl":[[1.12,2499.55]],"id":228749}]}]}
{"op":"mcm","clk":"AM3NrgkAjd6fCgCKy6EK","pt":1657540974128,"mc":[{"id":"1.200806927","rc":[{"atl":[[1.12,2495.13]],"id":228749}]}]}
{"op":"mcm","clk":"ANnNrgkAld6fCgCMy6EK","pt":1657540974241,"mc":[{"id":"1.200806927","rc":[{"atb":[[1.09,1215.63]],"id":228749}]}]}
{"op":"mcm","clk":"ANbOrgkA/d6fCgDVy6EK","pt":1657540975633,"mc":[{"id":"1.200806927","rc":[{"atl":[[1.1,5.18]],"trd":[[1.1,4296.25]],"tv":92219.78,"id":228749}],"tv":98928.72}]}
{"op":"mcm","clk":"AMLPrgkAxt+fCgCRzKEK","pt":1657540976843,"mc":[{"id":"1.200806927","rc":[{"atb":[[1.1,22.14]],"atl":[[1.1,0]],"id":228749}]}]}
{"op":"mcm","clk":"AOnRrgkAnOGfCgCozaEK","pt":1657540980050,"mc":[{"id":"1.200806927","rc":[{"atb":[[1.09,1422.74]],"id":228749}]}]}
{"op":"mcm","clk":"ANLSrgkAk+KfCgDyzaEK","pt":1657540981264,"mc":[{"id":"1.200806927","rc":[{"atl":[[1.11,86.17]],"trd":[[1.11,17574.92]],"ltp":1.11,"tv":92223.67,"id":228749},{"trd":[[10,1645.41]],"ltp":10,"tv":6709.37,"id":2857977}],"tv":98933.04}]}
{"op":"mcm","clk":"AOnSrgkAo+KfCgD4zaEK","pt":1657540981455,"mc":[{"id":"1.200806927","rc":[{"atl":[[1.11,85.21]],"trd":[[1.11,17575.88]],"tv":92224.63,"id":228749},{"trd":[[10,1645.52]],"tv":6709.48,"id":2857977}],"tv":98934.11}]}
{"op":"mcm","clk":"AP/SrgkAteKfCgCEzqEK","pt":1657540981678,"mc":[{"id":"1.200806927","rc":[{"atl":[[1.11,84.68]],"id":228749}]}]}
{"op":"mcm","clk":"ANbTrgkAgOOfCgCnzqEK","pt":1657540982571,"mc":[{"id":"1.200806927","rc":[{"atl":[[1.11,84.25]],"id":228749}]}]}
{"op":"mcm","clk":"AN3TrgkAh+OfCgCpzqEK","pt":1657540982671,"mc":[{"id":"1.200806927","rc":[{"atl":[[1.11,82.3]],"trd":[[1.11,17577.83]],"tv":92226.58,"id":228749},{"trd":[[10,1645.74]],"tv":6709.7,"id":2857977}],"tv":98936.28}]}
{"op":"mcm","clk":"AKXUrgkAwOOfCgDOzqEK","pt":1657540983400,"mc":[{"id":"1.200806927","rc":[{"atl":[[12,0]],"id":2857977}]}]}
{"op":"mcm","clk":"AMzUrgkA3eOfCgDhzqEK","pt":1657540983770,"mc":[{"id":"1.200806927","rc":[{"atb":[[1.1,26.87]],"id":228749}]}]}
{"op":"mcm","clk":"ANTUrgkA4+OfCgDozqEK","pt":1657540983867,"mc":[{"id":"1.200806927","rc":[{"atb":[[1.1,32.13]],"id":228749}]}]}
{"op":"mcm","clk":"AOnUrgkA7+OfCgDyzqEK","pt":1657540983990,"mc":[{"id":"1.200806927","rc":[{"atb":[[1.1,33.97]],"id":228749}]}]}
{"op":"mcm","clk":"AKXVrgkAouSfCgCFz6EK","pt":1657540984564,"mc":[{"id":"1.200806927","rc":[{"atb":[[1.1,33.44]],"id":228749}]}]}
{"op":"mcm","clk":"ANPVrgkAyOSfCgCZz6EK","pt":1657540984984,"mc":[{"id":"1.200806927","rc":[{"atb":[[1.09,1633.11]],"id":228749}]}]}
{"op":"mcm","clk":"AOfVrgkA1uSfCgCkz6EK","pt":1657540985186,"mc":[{"id":"1.200806927","rc":[{"atl":[[1.11,81.34]],"trd":[[1.11,17578.79]],"tv":92227.54,"id":228749},{"trd":[[10,1645.84]],"tv":6709.8,"id":2857977}],"tv":98937.34}]}
{"op":"mcm","clk":"AJzWrgkA+OSfCgC4z6EK","pt":1657540985651,"mc":[{"id":"1.200806927","rc":[{"atb":[[1.1,33.97]],"id":228749}]}]}
{"op":"mcm","clk":"ALDWrgkAieWfCgDAz6EK","pt":1657540985859,"mc":[{"id":"1.200806927","rc":[{"atl":[[1.11,85.22]],"id":228749}]}]}
{"op":"mcm","clk":"ANrWrgkAquWfCgDVz6EK","pt":1657540986277,"mc":[{"id":"1.200806927","rc":[{"atb":[[1.1,32.39]],"id":228749}]}]}
{"op":"mcm","clk":"AIbYrgkAw+afCgCf0KEK","pt":1657540987992,"mc":[{"id":"1.200806927","rc":[{"atl":[[1.11,81.33]],"trd":[[1.11,17582.68]],"tv":92231.43,"id":228749},{"trd":[[10,1646.27]],"tv":6710.23,"id":2857977}],"tv":98941.66}]}
{"op":"mcm","clk":"AMHZrgkA3+efCgD00KEK","pt":1657540989962,"mc":[{"id":"1.200806927","rc":[{"atb":[[1.07,77.67]],"id":228749}]}]}
{"op":"mcm","clk":"ANTZrgkA8OefCgCA0aEK","pt":1657540990169,"mc":[{"id":"1.200806927","rc":[{"atl":[[1.11,79.92]],"trd":[[1.11,17584.09]],"tv":92232.84,"id":228749},{"trd":[[10,1646.43]],"tv":6710.39,"id":2857977}],"tv":98943.23}]}
{"op":"mcm","clk":"AJjargkAmuifCgCd0aEK","pt":1657540990796,"mc":[{"id":"1.200806927","rc":[{"atb":[[1.1,31.6]],"id":228749}]}]}
{"op":"mcm","clk":"AIzbrgkA6uifCgDF0aEK","pt":1657540991796,"mc":[{"id":"1.200806927","rc":[{"atl":[[1.11,69.4]],"id":228749}]}]}
{"op":"mcm","clk":"AJbbrgkA9OifCgDK0aEK","pt":1657540991897,"mc":[{"id":"1.200806927","rc":[{"atb":[[1.1,26.87]],"id":228749}]}]}
{"op":"mcm","clk":"APDbrgkAv+mfCgDs0aEK","pt":1657540992868,"mc":[{"id":"1.200806927","rc":[{"atl":[[1.11,68.95]],"trd":[[1.11,17584.54]],"tv":92233.29,"id":228749},{"trd":[[10,1646.48]],"tv":6710.44,"id":2857977}],"tv":98943.73}]}
{"op":"mcm","clk":"APjbrgkAyemfCgDu0aEK","pt":1657540992963,"mc":[{"id":"1.200806927","rc":[{"atb":[[1.09,1422.74]],"id":228749}]}]}
{"op":"mcm","clk":"AIDcrgkA0+mfCgDz0aEK","pt":1657540993076,"mc":[{"id":"1.200806927","rc":[{"atl":[[1.12,14]],"id":228749}]}]}
{"op":"mcm","clk":"AIvcrgkA3OmfCgD50aEK","pt":1657540993197,"mc":[{"id":"1.200806927","rc":[{"atb":[[1.09,1212.37]],"id":228749}]}]}
{"op":"mcm","clk":"ALvcrgkAgOqfCgCI0qEK","pt":1657540993650,"mc":[{"id":"1.200806927","rc":[{"atb":[[1.1,24.5]],"trd":[[1.1,4300.99]],"ltp":1.1,"tv":92238.03,"id":228749}],"tv":98948.47}]}
{"op":"mcm","clk":"ANzcrgkAnOqfCgCT0qEK","pt":1657540994010,"mc":[{"id":"1.200806927","rc":[{"atb":[[1.1,21.87]],"id":228749}]}]}
{"op":"mcm","clk":"AJjdrgkAz+qfCgCw0qEK","pt":1657540994577,"mc":[{"id":"1.200806927","rc":[{"atb":[[1.1,21.34]],"atl":[[1.11,68.42]],"id":228749}]}]}
{"op":"mcm","clk":"AKXdrgkA2OqfCgC10qEK","pt":1657540994682,"mc":[{"id":"1.200806927","rc":[{"atl":[[1.11,72.57]],"id":228749}]}]}
{"op":"mcm","clk":"AOjdrgkAk+ufCgDG0qEK","pt":1657540995394,"mc":[{"id":"1.200806927","rc":[{"atb":[[1.1,19.5]],"id":228749}]}]}
{"op":"mcm","clk":"APXergkA/uufCgCK06EK","pt":1657540997004,"mc":[{"id":"1.200806927","rc":[{"atl":[[1.11,72.14]],"trd":[[1.11,17585.4]],"ltp":1.11,"tv":92238.89,"id":228749}],"tv":98949.33}]}
{"op":"mcm","clk":"AIngrgkA7eyfCgDH06EK","pt":1657540998505,"mc":[{"id":"1.200806927","rc":[{"atb":[[1.1,18.97]],"atl":[[1.11,70.56]],"id":228749}]}]}
{"op":"mcm","clk":"AMfgrgkAme2fCgDo06EK","pt":1657540999266,"mc":[{"id":"1.200806927","rc":[{"atb":[[1.08,576.06]],"id":228749}]}]}
{"op":"mcm","clk":"APDgrgkAr+2fCgDz06EK","pt":1657540999604,"mc":[{"id":"1.200806927","rc":[{"atb":[[1.1,18.8]],"trd":[[1.1,4301.33]],"ltp":1.1,"tv":92239.23,"id":228749}],"tv":98949.67}]}
{"op":"mcm","clk":"AJfhrgkAye2fCgCC1KEK","pt":1657541000098,"mc":[{"id":"1.200806927","rc":[{"atb":[[1.1,18.9]],"id":228749}]}]}
{"op":"mcm","clk":"AL3irgkAyO6fCgDA1KEK","pt":1657541002116,"mc":[{"id":"1.200806927","rc":[{"atb":[[1.1,13.64]],"id":228749}]}]}
{"op":"mcm","clk":"AOXirgkA3+6fCgDL1KEK","pt":1657541002582,"mc":[{"id":"1.200806927","rc":[{"atb":[[1.1,13.56]],"trd":[[1.1,4301.49]],"tv":92239.39,"id":228749}],"tv":98949.83}]}
{"op":"mcm","clk":"AOzirgkA4u6fCgDM1KEK","pt":1657541002669,"mc":[{"id":"1.200806927","rc":[{"atl":[[1.11,69.7]],"trd":[[1.11,17587.12]],"ltp":1.11,"tv":92241.11,"id":228749}],"tv":98951.55}]}
{"op":"mcm","clk":"AIDjrgkA7u6fCgDS1KEK","pt":1657541002888,"mc":[{"id":"1.200806927","rc":[{"atb":[[1.1,13.13]],"trd":[[1.1,4302.35]],"ltp":1.1,"tv":92241.97,"id":228749}],"tv":98952.41}]}
{"op":"mcm","clk":"AI/jrgkA+O6fCgDZ1KEK","pt":1657541003088,"mc":[{"id":"1.200806927","rc":[{"atl":[[1.11,67.9]],"id":228749}]}]}
{"op":"mcm","clk":"ALrjrgkAmO+fCgDq1KEK","pt":1657541003795,"mc":[{"id":"1.200806927","rc":[{"atl":[[1.11,66.94]],"trd":[[1.11,17588.08]],"ltp":1.11,"tv":92242.93,"id":228749},{"trd":[[10,1646.59]],"tv":6710.55,"id":2857977}],"tv":98953.48}]}
{"op":"mcm","clk":"ANLjrgkAqu+fCgD21KEK","pt":1657541004113,"mc":[{"id":"1.200806927","rc":[{"atl":[[1.11,66.09]],"trd":[[1.11,17589.78]],"tv":92244.63,"id":228749}],"tv":98955.18}]}
{"op":"mcm","clk":"AIrkrgkAy++fCgCJ1aEK","pt":1657541004688,"mc":[{"id":"1.200806927","rc":[{"atb":[[1.1,10.92]],"id":228749}]}]}
{"op":"mcm","clk":"ALnlrgkAv/CfCgDA1aEK","pt":1657541006805,"mc":[{"id":"1.200806927","rc":[{"atl":[[1.11,65.01]],"trd":[[1.11,17591.94]],"tv":92246.79,"id":228749}],"tv":98957.34}]}
{"op":"mcm","clk":"AJbprgkA6/OfCgDr16EK","pt":1657541009764,"mc":[{"id":"1.200806927","rc":[{"atl":[[1.11,63.12]],"id":228749}]}]}
{"op":"mcm","clk":"APLqrgkA2vWfCgDh2KEK","pt":1657541011429,"mc":[{"id":"1.200806927","rc":[{"atl":[[1.11,58.97]],"id":228749}]}]}
{"op":"mcm","clk":"ALvtrgkA4fefCgCo2qEK","pt":1657541013611,"mc":[{"id":"1.200806927","rc":[{"atl":[[1.11,54.76]],"id":228749}]}]}
{"op":"mcm","clk":"ANTtrgkA+fefCgC02qEK","pt":1657541013828,"mc":[{"id":"1.200806927","rc":[{"atl":[[1.11,53.2]],"trd":[[1.11,17593.5]],"tv":92248.35,"id":228749},{"trd":[[10,1646.76]],"tv":6710.72,"id":2857977}],"tv":98959.07}]}
{"op":"mcm","clk":"AO/vrgkA+vmfCgDH26EK","pt":1657541016225,"mc":[{"id":"1.200806927","rc":[{"atl":[[1.11,52.67]],"id":228749}]}]}
{"op":"mcm","clk":"AN/wrgkA0vqfCgD226EK","pt":1657541017277,"mc":[{"id":"1.200806927","rc":[{"atb":[[1.1,8.92]],"atl":[[1.11,47.41]],"trd":[[1.1,4306.35]],"ltp":1.1,"tv":92252.35,"id":228749}],"tv":98963.07}]}
{"op":"mcm","clk":"ANjyrgkAqfyfCgDw3KEK","pt":1657541019650,"mc":[{"id":"1.200806927","rc":[{"atb":[[1.1,3.66]],"id":228749}]}]}
{"op":"mcm","clk":"AJbzrgkA3/yfCgCY3aEK","pt":1657541020253,"mc":[{"id":"1.200806927","rc":[{"atl":[[1.11,18.13]],"trd":[[1.11,17622.78]],"ltp":1.11,"tv":92281.63,"id":228749},{"trd":[[10,1650.01]],"tv":6713.97,"id":2857977}],"tv":98995.6}]}
{"op":"mcm","clk":"AKXzrgkA7PyfCgCa3aEK","pt":1657541020342,"mc":[{"id":"1.200806927","rc":[{"atb":[[1.1,3.61]],"trd":[[1.1,4306.45]],"ltp":1.1,"tv":92281.73,"id":228749}],"tv":98995.7}]}
{"op":"mcm","clk":"ALvzrgkAgv2fCgCh3aEK","pt":1657541020569,"mc":[{"id":"1.200806927","rc":[{"atl":[[1.11,17.17]],"trd":[[1.11,17623.74]],"ltp":1.11,"tv":92282.69,"id":228749},{"trd":[[10,1650.12]],"tv":6714.08,"id":2857977}],"tv":98996.77}]}
{"op":"mcm","clk":"AMr0rgkAhv6fCgDx3aEK","pt":1657541022214,"mc":[{"id":"1.200806927","rc":[{"atb":[[1.1,1.54]],"id":228749}]}]}
{"op":"mcm","clk":"AOz0rgkAoP6fCgD93aEK","pt":1657541022542,"mc":[{"id":"1.200806927","rc":[{"atl":[[1.11,7.71]],"trd":[[1.11,17633.2]],"tv":92292.15,"id":228749},{"trd":[[10,1651.17]],"tv":6715.13,"id":2857977}],"tv":99007.28}]}
{"op":"mcm","clk":"AID2rgkAlv+fCgC73qEK","pt":1657541024068,"mc":[{"id":"1.200806927","rc":[{"atb":[[1.1,0]],"atl":[[1.1,8.98]],"trd":[[1.1,4306.65]],"ltp":1.1,"tv":92292.35,"id":228749}],"tv":99007.48}]}
{"op":"mcm","clk":"AK32rgkAv/+fCgDO3qEK","pt":1657541024547,"mc":[{"id":"1.200806927","rc":[{"atl":[[1.1,11.61]],"id":228749}]}]}
{"op":"mcm","clk":"APr2rgkA8f+fCgDi3qEK","pt":1657541025171,"mc":[{"id":"1.200806927","rc":[{"atb":[[11,20]],"id":2857977}]}]}
{"op":"mcm","clk":"AOf4rgkA5YGgCgDk36EK","pt":1657541027257,"mc":[{"id":"1.200806927","rc":[{"atl":[[1.1,14.24]],"id":228749}]}]}
{"op":"mcm","clk":"AI/6rgkA+IKgCgDA4KEK","pt":1657541029034,"mc":[{"id":"1.200806927","rc":[{"atl":[[1.1,5.26]],"trd":[[1.1,4324.61]],"tv":92310.31,"id":228749}],"tv":99025.44}]}
{"op":"mcm","clk":"ANL7rgkApISgCgCr4aEK","pt":1657541031070,"mc":[{"id":"1.200806927","rc":[{"atl":[[1.1,0]],"trd":[[1.1,4487.63]],"tv":92473.33,"id":228749},{"atb":[[11,3.7]],"trd":[[11,33.26]],"ltp":11,"tv":6731.43,"id":2857977}],"tv":99204.76}]}
{"op":"mcm","clk":"AN77rgkArYSgCgCu4aEK","pt":1657541031126,"mc":[{"id":"1.200806927","rc":[{"atb":[[11,3.17]],"trd":[[11,34.32]],"tv":6732.49,"id":2857977}],"tv":99205.82}]}
{"op":"mcm","clk":"AOj7rgkAvYSgCgCy4aEK","pt":1657541031227,"mc":[{"id":"1.200806927","rc":[{"atl":[[20,0.36]],"id":2857977}]}]}
{"op":"mcm","clk":"APb8rgkApYWgCgDe4aEK","pt":1657541032466,"mc":[{"id":"1.200806927","rc":[{"atl":[[1.1,1.58]],"id":228749}]}]}
{"op":"mcm","clk":"ALb9rgkAx4WgCgDy4aEK","pt":1657541032859,"mc":[{"id":"1.200806927","rc":[{"atl":[[1.1,6.84]],"id":228749}]}]}
{"op":"mcm","clk":"AMCArwkA0oegCgDH46EK","pt":1657541036171,"mc":[{"id":"1.200806927","rc":[{"atl":[[1.1,1.58]],"id":228749}]}]}
{"op":"mcm","clk":"AP+BrwkA8YigCgC35KEK","pt":1657541038075,"mc":[{"id":"1.200806927","rc":[{"atl":[[1.1,1.05]],"id":228749}]}]}
{"op":"mcm","clk":"AK+CrwkAmYmgCgDO5KEK","pt":1657541038458,"mc":[{"id":"1.200806927","rc":[{"atb":[[11,2.4]],"trd":[[11,35.87]],"tv":6734.04,"id":2857977}],"tv":99207.37}]}
{"op":"mcm","clk":"ALeCrwkAoYmgCgDR5KEK","pt":1657541038550,"mc":[{"id":"1.200806927","rc":[{"atb":[[11,2.18]],"trd":[[11,36.3]],"tv":6734.47,"id":2857977}],"tv":99207.8}]}
{"op":"mcm","clk":"ALuCrwkAqomgCgDU5KEK","pt":1657541038650,"mc":[{"id":"1.200806927","rc":[{"atl":[[1.11,122.49]],"id":228749},{"atb":[[11,1.92]],"trd":[[11,36.82]],"tv":6734.99,"id":2857977}],"tv":99208.32}]}
{"op":"mcm","clk":"AImDrwkA8ImgCgCC5aEK","pt":1657541039476,"mc":[{"id":"1.200806927","rc":[{"atl":[[1.1,0]],"id":228749}]}]}
{"op":"mcm","clk":"ALiDrwkArIqgCgCb5aEK","pt":1657541039975,"mc":[{"id":"1.200806927","rc":[{"trd":[[1.1,4492.89]],"tv":92478.59,"id":228749},{"atb":[[11,1.39]],"trd":[[11,37.35]],"tv":6735.52,"id":2857977}],"tv":99214.11}]}
{"op":"mcm","clk":"AMCDrwkAtYqgCgCh5aEK","pt":1657541040064,"mc":[{"id":"1.200806927","rc":[{"atb":[[1.1,17.66]],"trd":[[1.1,4506.79]],"tv":92492.49,"id":228749},{"atb":[[11,0]],"trd":[[11,38.74]],"tv":6736.91,"id":2857977}],"tv":99229.4}]}
{"op":"mcm","clk":"ANaDrwkAy4qgCgCo5aEK","pt":1657541040275,"mc":[{"id":"1.200806927","rc":[{"atb":[[1.1,0],[1.09,1201.69]],"trd":[[1.1,4542.11],[1.09,2797.56]],"ltp":1.09,"tv":92549.16,"id":228749}],"tv":99286.07}]}
{"op":"mcm","clk":"AL+IrwkA24+gCgD056EK","pt":1657541046399,"mc":[{"id":"1.200806927","rc":[{"atb":[[1.1,0.05]],"id":228749}]}]}
{"op":"mcm","clk":"APeJrwkAlpGgCgDC6KEK","pt":1657541048388,"mc":[{"id":"1.200806927","rc":[{"atb":[[1.1,5.31]],"id":228749}]}]}
{"op":"mcm","clk":"AL+KrwkA0pGgCgDe6KEK","pt":1657541049165,"mc":[{"id":"1.200806927","rc":[{"atb":[[1.1,15.83]],"id":228749},{"atl":[[11,2.57]],"id":2857977}]}]}
{"op":"mcm","clk":"AMCLrwkAvZKgCgCV6aEK","pt":1657541050582,"mc":[{"id":"1.200806927","rc":[{"atb":[[1.08,576.74]],"id":228749}]}]}
{"op":"mcm","clk":"ANCLrwkAypKgCgCc6aEK","pt":1657541050779,"mc":[{"id":"1.200806927","rc":[{"atl":[[1.12,26.95]],"id":228749}]}]}
{"op":"mcm","clk":"AOSLrwkA35KgCgCm6aEK","pt":1657541050995,"mc":[{"id":"1.200806927","rc":[{"atb":[[1.1,21.09]],"id":228749}]}]}
{"op":"mcm","clk":"ALyNrwkAlZSgCgCP6qEK","pt":1657541053147,"mc":[{"id":"1.200806927","rc":[{"atl":[[1.11,122.33]],"trd":[[1.11,17633.52]],"ltp":1.11,"tv":92549.48,"id":228749}],"tv":99286.39}]}
{"op":"mcm","clk":"AIOOrwkAzpSgCgCq6qEK","pt":1657541053783,"mc":[{"id":"1.200806927","rc":[{"atl":[[1.11,117.07]],"trd":[[1.11,17636.7]],"tv":92552.66,"id":228749}],"tv":99289.57}]}
{"op":"mcm","clk":"AOuOrwkAoJWgCgDT6qEK","pt":1657541054763,"mc":[{"id":"1.200806927","rc":[{"atl":[[11,2.68]],"id":2857977}]}]}
{"op":"mcm","clk":"AOePrwkAmpagCgCK66EK","pt":1657541056091,"mc":[{"id":"1.200806927","rc":[{"atl":[[1.11,116.11]],"trd":[[1.11,17637.66]],"tv":92553.62,"id":228749},{"trd":[[10,1651.27]],"ltp":10,"tv":6737.01,"id":2857977}],"tv":99290.63}]}
{"op":"mcm","clk":"AJmQrwkAx5agCgCe66EK","pt":1657541056572,"mc":[{"id":"1.200806927","rc":[{"atl":[[1.11,105.59]],"trd":[[1.11,17658.7]],"tv":92574.66,"id":228749}],"tv":99311.67}]}
{"op":"mcm","clk":"AJyRrwkAnJegCgDF66EK","pt":1657541057764,"mc":[{"id":"1.200806927","rc":[{"atl":[[1.11,105.06]],"trd":[[1.11,17659.76]],"tv":92575.72,"id":228749}],"tv":99312.73}]}
{"op":"mcm","clk":"AJmSrwkA+5egCgD/66EK","pt":1657541058881,"mc":[{"id":"1.200806927","rc":[{"atb":[[1.1,15.83]],"trd":[[1.1,4542.21]],"ltp":1.1,"tv":92575.82,"id":228749}],"tv":99312.83}]}
{"op":"mcm","clk":"ANySrwkAqZigCgCV7KEK","pt":1657541059602,"mc":[{"id":"1.200806927","rc":[{"atl":[[15,0.55]],"id":2857977}]}]}
{"op":"mcm","clk":"AOuSrwkAsZigCgCY7KEK","pt":1657541059707,"mc":[{"id":"1.200806927","rc":[{"atb":[[2.46,0]],"id":2857977}]}]}
{"op":"mcm","clk":"APSSrwkAupigCgCd7KEK","pt":1657541059812,"mc":[{"id":"1.200806927","rc":[{"atl":[[1.11,104.1]],"trd":[[1.11,17660.72]],"ltp":1.11,"tv":92576.78,"id":228749},{"trd":[[10,1651.38]],"tv":6737.12,"id":2857977}],"tv":99313.9}]}
{"op":"mcm","clk":"AIiUrwkAu5mgCgDT7KEK","pt":1657541061220,"mc":[{"id":"1.200806927","rc":[{"atl":[[1.11,88.32]],"trd":[[1.11,17692.28]],"tv":92608.34,"id":228749}],"tv":99345.46}]}
{"op":"mcm","clk":"AJmUrwkAyJmgCgDZ7KEK","pt":1657541061373,"mc":[{"id":"1.200806927","rc":[{"atb":[[1.1,13.24]],"id":228749}]}]}
{"op":"mcm","clk":"AOeUrwkAhpqgCgD/7KEK","pt":1657541062113,"mc":[{"id":"1.200806927","rc":[{"atl":[[1.11,87.58]],"trd":[[1.11,17693.76]],"tv":92609.82,"id":228749}],"tv":99346.94}]}
{"op":"mcm","clk":"AIuWrwkAiZugCgDa7aEK","pt":1657541063886,"mc":[{"id":"1.200806927","rc":[{"atl":[[1.11,87.48]],"trd":[[1.11,17693.96]],"tv":92610.02,"id":228749}],"tv":99347.14}]}
{"op":"mcm","clk":"AMiZrwkAsZ2gCgDA76EK","pt":1657541067717,"mc":[{"id":"1.200806927","rc":[{"atl":[[1.11,86.95]],"trd":[[1.11,17695.02]],"tv":92611.08,"id":228749}],"tv":99348.2}]}
{"op":"mcm","clk":"AIGarwkA1Z2gCgDY76EK","pt":1657541068277,"mc":[{"id":"1.200806927","rc":[{"atb":[[1.08,577.27]],"id":228749}]}]}
{"op":"mcm","clk":"ANWarwkAl56gCgCR8KEK","pt":1657541069082,"mc":[{"id":"1.200806927","rc":[{"atl":[[1.11,82.18]],"trd":[[1.11,17699.79]],"tv":92615.85,"id":228749},{"trd":[[10,1651.91]],"tv":6737.65,"id":2857977}],"tv":99353.5}]}
{"op":"mcm","clk":"ANGbrwkAl5+gCgDU8KEK","pt":1657541070395,"mc":[{"id":"1.200806927","rc":[{"atl":[[1.11,81.22]],"trd":[[1.11,17700.75]],"tv":92616.81,"id":228749},{"trd":[[10,1652.02]],"tv":6737.76,"id":2857977}],"tv":99354.57}]}
{"op":"mcm","clk":"AMucrwkA9J+gCgCQ8aEK","pt":1657541071581,"mc":[{"id":"1.200806927","rc":[{"atl":[[1.11,75.96]],"trd":[[1.11,17711.27]],"tv":92627.33,"id":228749}],"tv":99365.09}]}
{"op":"mcm","clk":"ANmcrwkA+5+gCgCV8aEK","pt":1657541071702,"mc":[{"id":"1.200806927","rc":[{"atb":[[1.1,0]],"atl":[[1.1,117.72]],"trd":[[1.1,4569.02]],"ltp":1.1,"tv":92654.14,"id":228749},{"atl":[[11,0]],"trd":[[11,41.42]],"ltp":11,"tv":6740.44,"id":2857977}],"tv":99394.58}]}
{"op":"mcm","clk":"APScrwkAkaCgCgCi8aEK","pt":1657541072013,"mc":[{"id":"1.200806927","rc":[{"atl":[[1.1,112.46]],"id":228749}]}]}
{"op":"mcm","clk":"AIidrwkAn6CgCgCt8aEK","pt":1657541072231,"mc":[{"id":"1.200806927","rc":[{"atl":[[1.1,109.83]],"id":228749}]}]}
{"op":"mcm","clk":"AKmerwkAuqGgCgCJ8qEK","pt":1657541073390,"mc":[{"id":"1.200806927","rc":[{"atl":[[1.1,107.2]],"id":228749}]}]}
{"op":"mcm","clk":"AIifrwkAl6KgCgDI8qEK","pt":1657541074195,"mc":[{"id":"1.200806927","rc":[{"atl":[[1.1,101.94]],"id":228749}]}]}
{"op":"mcm","clk":"AL2hrwkA7KOgCgDa86EK","pt":1657541076939,"mc":[{"id":"1.200806927","rc":[{"atl":[[1.1,96.68]],"id":228749}]}]}
{"op":"mcm","clk":"AOahrwkAjaSgCgDw86EK","pt":1657541077338,"mc":[{"id":"1.200806927","rc":[{"atl":[[1.1,96.15]],"id":228749}]}]}
{"op":"mcm","clk":"AJCirwkAt6SgCgCF9KEK","pt":1657541077811,"mc":[{"id":"1.200806927","rc":[{"atl":[[1.1,85.63]],"id":228749}]}]}
{"op":"mcm","clk":"AKmirwkAyKSgCgCJ9KEK","pt":1657541078023,"mc":[{"id":"1.200806927","rc":[{"atb":[[1.08,46.94]],"id":228749}]}]}
{"op":"mcm","clk":"AOGirwkA9KSgCgCp9KEK","pt":1657541078620,"mc":[{"id":"1.200806927","rc":[{"atl":[[1.1,85.53]],"trd":[[1.1,4569.22]],"tv":92654.34,"id":228749}],"tv":99394.78}]}
{"op":"mcm","clk":"AOijrwkA1KWgCgDl9KEK","pt":1657541079990,"mc":[{"id":"1.200806927","rc":[{"atl":[[1.1,83.95]],"id":228749}]}]}
{"op":"mcm","clk":"AJSlrwkA5aagCgC99aEK","pt":1657541081536,"mc":[{"id":"1.200806927","rc":[{"atl":[[11.5,0.35]],"id":2857977}]}]}
{"op":"mcm","clk":"AMqlrwkAl6egCgDX9aEK","pt":1657541081914,"mc":[{"id":"1.200806927","rc":[{"atl":[[1.1,294.32]],"id":228749}]}]}
{"op":"mcm","clk":"AJCmrwkA3KegCgD09aEK","pt":1657541082541,"mc":[{"id":"1.200806927","rc":[{"atl":[[1.1,289.02]],"trd":[[1.1,4574.52]],"tv":92659.64,"id":228749},{"trd":[[11,41.95]],"tv":6740.97,"id":2857977}],"tv":99400.61}]}
{"op":"mcm","clk":"AL6mrwkAhKigCgCI9qEK","pt":1657541082907,"mc":[{"id":"1.200806927","rc":[{"atl":[[1.1,286.95]],"id":228749}]}]}
{"op":"mcm","clk":"AIeorwkAlamgCgD+9qEK","pt":1657541084616,"mc":[{"id":"1.200806927","rc":[{"atl":[[1.1,286.42]],"id":228749}]}]}
{"op":"mcm","clk":"AJmorwkAoKmgCgCH96EK","pt":1657541084754,"mc":[{"id":"1.200806927","rc":[{"atb":[[1.09,1201.16]],"atl":[[1.1,285.89]],"trd":[[1.09,2798.62]],"ltp":1.09,"tv":92660.7,"id":228749}],"tv":99401.67}]}
{"op":"mcm","clk":"AICprwkA86mgCgDJ96EK","pt":1657541085693,"mc":[{"id":"1.200806927","rc":[{"atl":[[1.1,284.09]],"id":228749}]}]}
{"op":"mcm","clk":"AL+qrwkAmqugCgCc+KEK","pt":1657541087383,"mc":[{"id":"1.200806927","rc":[{"atl":[[1.1,271.14]],"id":228749}]}]}
{"op":"mcm","clk":"AMyqrwkAoaugCgCg+KEK","pt":1657541087482,"mc":[{"id":"1.200806927","rc":[{"atb":[[1.09,1200.63]],"trd":[[1.09,2799.68]],"tv":92661.76,"id":228749}],"tv":99402.73}]}
{"op":"mcm","clk":"ALSrrwkAjqygCgDo+KEK","pt":1657541088637,"mc":[{"id":"1.200806927","rc":[{"atl":[[1.1,270.34]],"trd":[[1.1,4576.12]],"ltp":1.1,"tv":92663.36,"id":228749}],"tv":99404.33}]}
{"op":"mcm","clk":"AKmsrwkAwqygCgCV+aEK","pt":1657541089282,"mc":[{"id":"1.200806927","rc":[{"atl":[[1.1,267.71]],"id":228749}]}]}
{"op":"mcm","clk":"ANOtrwkAra2gCgDl+aEK","pt":1657541090671,"mc":[{"id":"1.200806927","rc":[{"atb":[[1.09,1199.63]],"trd":[[1.09,2801.68]],"ltp":1.09,"tv":92665.36,"id":228749}],"tv":99406.33}]}
{"op":"mcm","clk":"AJCurwkA2a2gCgCB+qEK","pt":1657541091167,"mc":[{"id":"1.200806927","rc":[{"atl":[[1.1,265.08]],"id":228749}]}]}
{"op":"mcm","clk":"AJyurwkA5q2gCgCH+qEK","pt":1657541091302,"mc":[{"id":"1.200806927","rc":[{"atl":[[1.1,258.61]],"id":228749}]}]}
{"op":"mcm","clk":"APWurwkAva6gCgCz+qEK","pt":1657541092159,"mc":[{"id":"1.200806927","rc":[{"atl":[[1.1,258.51]],"trd":[[1.1,4576.32]],"ltp":1.1,"tv":92665.56,"id":228749}],"tv":99406.53}]}
{"op":"mcm","clk":"AJqvrwkA2a6gCgDH+qEK","pt":1657541092575,"mc":[{"id":"1.200806927","rc":[{"atl":[[1.1,257.44]],"trd":[[1.1,4577.39]],"tv":92666.63,"id":228749},{"trd":[[11,42.06]],"tv":6741.08,"id":2857977}],"tv":99407.71}]}
{"op":"mcm","clk":"AKGwrwkAv6+gCgD8+qEK","pt":1657541093769,"mc":[{"id":"1.200806927","rc":[{"atb":[[1.09,1178.63]],"trd":[[1.09,2843.68]],"ltp":1.09,"tv":92708.63,"id":228749}],"tv":99449.71}]}
{"op":"mcm","clk":"ALexrwkAn7CgCgC9+6EK","pt":1657541095175,"mc":[{"id":"1.200806927","rc":[{"atb":[[1.09,1178.1]],"trd":[[1.09,2844.74]],"tv":92709.69,"id":228749}],"tv":99450.77}]}
{"op":"mcm","clk":"AM6yrwkA67CgCgDq+6EK","pt":1657541096485,"mc":[{"id":"1.200806927","rc":[{"atl":[[13.5,0.43]],"id":2857977}]}]}
{"op":"mcm","clk":"AOS3rwkAx7SgCgD6/aEK","pt":1657541102510,"mc":[{"id":"1.200806927","rc":[{"atl":[[1.1,257.34]],"trd":[[1.1,4577.59]],"ltp":1.1,"tv":92709.89,"id":228749}],"tv":99450.97}]}
{"op":"mcm","clk":"APC4rwkAmbWgCgCn/qEK","pt":1657541103583,"mc":[{"id":"1.200806927","rc":[{"atl":[[1.1,257.17]],"trd":[[1.1,4577.94]],"tv":92710.24,"id":228749}],"tv":99451.32}]}
{"op":"mcm","clk":"AOW6rwkA4bagCgCS/6EK","pt":1657541105809,"mc":[{"id":"1.200806927","rc":[{"atl":[[1.1,256.64]],"id":228749}]}]}
{"op":"mcm","clk":"AP+6rwkA9bagCgCd/6EK","pt":1657541106092,"mc":[{"id":"1.200806927","rc":[{"atl":[[1.1,251.38]],"id":228749}]}]}
{"op":"mcm","clk":"AKG8rwkA7LegCgDj/6EK","pt":1657541107510,"mc":[{"id":"1.200806927","rc":[{"atl":[[13.5,0]],"id":2857977}]}]}
{"op":"mcm","clk":"APO8rwkAxbigCgCUgKIK","pt":1657541108317,"mc":[{"id":"1.200806927","rc":[{"atl":[[1.1,250.31]],"trd":[[1.1,4579.01]],"tv":92711.31,"id":228749},{"trd":[[11,42.16]],"tv":6741.18,"id":2857977}],"tv":99452.49}]}
{"op":"mcm","clk":"AOC9rwkAq7mgCgDagKIK","pt":1657541109508,"mc":[{"id":"1.200806927","rc":[{"atl":[[1.1,224.01]],"id":228749}]}]}
{"op":"mcm","clk":"APq+rwkAp7qgCgC6gaIK","pt":1657541111195,"mc":[{"id":"1.200806927","rc":[{"atl":[[1.3,131.74]],"id":228749}]}]}
{"op":"mcm","clk":"AIK/rwkAr7qgCgDCgaIK","pt":1657541111302,"mc":[{"id":"1.200806927","rc":[{"atb":[[1.09,1174.94]],"trd":[[1.09,2851.06]],"ltp":1.09,"tv":92717.63,"id":228749}],"tv":99458.81}]}
{"op":"mcm","clk":"AKnArwkAvLugCgCXgqIK","pt":1657541113128,"mc":[{"id":"1.200806927","rc":[{"atl":[[1.1,218.51]],"trd":[[1.1,4584.71]],"ltp":1.1,"tv":92723.33,"id":228749},{"trd":[[11,42.69]],"tv":6741.71,"id":2857977}],"tv":99465.04}]}
{"op":"mcm","clk":"ALLArwkAwbugCgCdgqIK","pt":1657541113202,"mc":[{"id":"1.200806927","rc":[{"atl":[[1.1,301.4]],"id":228749}]}]}
{"op":"mcm","clk":"ALzArwkA0LugCgChgqIK","pt":1657541113324,"mc":[{"id":"1.200806927","rc":[{"atb":[[1.08,46.72]],"id":228749}]}]}
{"op":"mcm","clk":"AMbArwkA1bugCgClgqIK","pt":1657541113422,"mc":[{"id":"1.200806927","rc":[{"atl":[[1.11,275.96]],"id":228749}]}]}
{"op":"mcm","clk":"ANHArwkA4LugCgCpgqIK","pt":1657541113529,"mc":[{"id":"1.200806927","rc":[{"atl":[[1.1,301.3]],"trd":[[1.1,4584.91]],"tv":92723.53,"id":228749}],"tv":99465.24}]}
{"op":"mcm","clk":"AMTBrwkAwLygCgDhgqIK","pt":1657541114811,"mc":[{"id":"1.200806927","rc":[{"atl":[[11.5,2.03]],"id":2857977}]}]}
{"op":"mcm","clk":"AMjCrwkAp72gCgCig6IK","pt":1657541116305,"mc":[{"id":"1.200806927","rc":[{"atl":[[1.1,218.41]],"id":228749}]}]}
{"op":"mcm","clk":"AOvCrwkAz72gCgC7g6IK","pt":1657541116709,"mc":[{"id":"1.200806927","rc":[{"atl":[[1.1,210.37]],"id":228749}]}]}
{"op":"mcm","clk":"AJ3DrwkA8b2gCgDMg6IK","pt":1657541117225,"mc":[{"id":"1.200806927","rc":[{"atl":[[1.1,155.62]],"trd":[[1.1,4587.07]],"tv":92725.69,"id":228749},{"trd":[[11,42.91]],"tv":6741.93,"id":2857977}],"tv":99467.62}]}
{"op":"mcm","clk":"ALDErwkA/L6gCgCrhKIK","pt":1657541118917,"mc":[{"id":"1.200806927","rc":[{"atl":[[1.1,154.55]],"trd":[[1.1,4588.14]],"tv":92726.76,"id":228749},{"trd":[[11,43.02]],"tv":6742.04,"id":2857977}],"tv":99468.8}]}
{"op":"mcm","clk":"AIfGrwkAusCgCgCIhaIK","pt":1657541121045,"mc":[{"id":"1.200806927","rc":[{"atl":[[11.5,0.35]],"id":2857977}]}]}
{"op":"mcm","clk":"AOzJrwkAmsSgCgDnhqIK","pt":1657541126342,"mc":[{"id":"1.200806927","rc":[{"atl":[[1.1,154.45]],"trd":[[1.1,4588.34]],"tv":92726.96,"id":228749}],"tv":99469}]}
{"op":"mcm","clk":"AIrKrwkAs8SgCgDzhqIK","pt":1657541126654,"mc":[{"id":"1.200806927","rc":[{"atb":[[1.09,1173.89]],"trd":[[1.09,2853.16]],"ltp":1.09,"tv":92729.06,"id":228749}],"tv":99471.1}]}
{"op":"mcm","clk":"AKzKrwkAy8SgCgCCh6IK","pt":1657541126945,"mc":[{"id":"1.200806927","rc":[{"atl":[[1.1,152.96]],"trd":[[1.1,4591.32]],"ltp":1.1,"tv":92732.04,"id":228749}],"tv":99474.08}]}
{"op":"mcm","clk":"AK7NrwkAoMegCgCpiKIK","pt":1657541130742,"mc":[{"id":"1.200806927","rc":[{"atb":[[1.09,1166]],"trd":[[1.09,2868.94]],"ltp":1.09,"tv":92747.82,"id":228749}],"tv":99489.86}]}
{"op":"mcm","clk":"AJXOrwkAl8igCgDWiKIK","pt":1657541131758,"mc":[{"id":"1.200806927","rc":[{"atl":[[1.1,107.86]],"trd":[[1.1,4636.42]],"ltp":1.1,"tv":92792.92,"id":228749},{"trd":[[11,47.53]],"tv":6746.55,"id":2857977}],"tv":99539.47}]}
{"op":"mcm","clk":"AKXRrwkA7cqgCgDmiaIK","pt":1657541135167,"mc":[{"id":"1.200806927","rc":[{"atl":[[1.1,102.6]],"id":228749}]}]}
{"op":"mcm","clk":"AMzRrwkAksugCgD5iaIK","pt":1657541135537,"mc":[{"id":"1.200806927","rc":[{"atl":[[1.1,98.29]],"trd":[[1.1,4645.04]],"tv":92801.54,"id":228749}],"tv":99548.09}]}
{"op":"mcm","clk":"AI7SrwkAzsugCgCaiqIK","pt":1657541136148,"mc":[{"id":"1.200806927","rc":[{"atl":[[1.1,97]],"trd":[[1.1,4646.33]],"tv":92802.83,"id":228749},{"trd":[[11,47.65]],"tv":6746.67,"id":2857977}],"tv":99549.5}]}
{"op":"mcm","clk":"AOzSrwkAn8ygCgDGiqIK","pt":1657541136974,"mc":[{"id":"1.200806927","rc":[{"atl":[[1.1,91.7]],"trd":[[1.1,4651.63]],"tv":92808.13,"id":228749},{"trd":[[11,48.18]],"tv":6747.2,"id":2857977}],"tv":99555.33}]}
{"op":"mcm","clk":"AJXTrwkAxMygCgDWiqIK","pt":1657541137350,"mc":[{"id":"1.200806927","rc":[{"atl":[[1.1,89.07]],"id":228749}]}]}
{"op":"mcm","clk":"ANLTrwkA+8ygCgDriqIK","pt":1657541137935,"mc":[{"id":"1.200806927","rc":[{"atl":[[1.1,88.97]],"trd":[[1.1,4651.83]],"tv":92808.33,"id":228749}],"tv":99555.53}]}
{"op":"mcm","clk":"APTTrwkAks2gCgD3iqIK","pt":1657541138249,"mc":[{"id":"1.200806927","rc":[{"atb":[[1.01,1770.66]],"id":228749}]}]}
{"op":"mcm","clk":"AI/VrwkAqM6gCgDEi6IK","pt":1657541139791,"mc":[{"id":"1.200806927","rc":[{"atl":[[1.1,87.92]],"id":228749}]}]}
{"op":"mcm","clk":"APHVrwkA7c6gCgDsi6IK","pt":1657541140766,"mc":[{"id":"1.200806927","rc":[{"atb":[[1.09,1060.82]],"atl":[[1.1,82.66]],"trd":[[1.09,3079.3]],"ltp":1.09,"tv":93018.69,"id":228749}],"tv":99765.89}]}
{"op":"mcm","clk":"AKDXrwkA+8+gCgDGjKIK","pt":1657541142621,"mc":[{"id":"1.200806927","rc":[{"atl":[[1.1,77.36]],"trd":[[1.1,4657.13]],"ltp":1.1,"tv":93023.99,"id":228749},{"trd":[[11,48.71]],"tv":6747.73,"id":2857977}],"tv":99771.72}]}
{"op":"mcm","clk":"AJDYrwkA8dCgCgD3jKIK","pt":1657541143872,"mc":[{"id":"1.200806927","rc":[{"atl":[[1.1,75.78]],"id":228749}]}]}
{"op":"mcm","clk":"AOnYrwkArtGgCgCZjaIK","pt":1657541144783,"mc":[{"id":"1.200806927","rc":[{"atl":[[1.1,325.78]],"id":228749}]}]}
{"op":"mcm","clk":"AIPbrwkAodOgCgCjjqIK","pt":1657541147767,"mc":[{"id":"1.200806927","rc":[{"atl":[[1.1,325.35]],"trd":[[1.1,4657.99]],"tv":93024.85,"id":228749}],"tv":99772.58}]}
{"op":"mcm","clk":"ANPbrwkA6tOgCgDKjqIK","pt":1657541148613,"mc":[{"id":"1.200806927","rc":[{"atl":[[1.1,114.98]],"trd":[[1.1,4928.03]],"tv":93294.89,"id":228749}],"tv":100042.62}]}
{"op":"mcm","clk":"AOHcrwkAgtWgCgCej6IK","pt":1657541150184,"mc":[{"id":"1.200806927","rc":[{"atl":[[1.1,105.98]],"trd":[[1.1,4937.03]],"tv":93303.89,"id":228749},{"trd":[[11,49.61]],"tv":6748.63,"id":2857977}],"tv":100052.52}]}
{"op":"mcm","clk":"APXerwkA9tagCgCXkKIK","pt":1657541152893,"mc":[{"id":"1.200806927","rc":[{"atl":[[1.1,96.98]],"trd":[[1.1,4946.03]],"tv":93312.89,"id":228749},{"trd":[[11,50.51]],"tv":6749.53,"id":2857977}],"tv":100062.42}]}
{"op":"mcm","clk":"ANDgrwkAlNigCgD7kKIK","pt":1657541154930,"mc":[{"id":"1.200806927","rc":[{"atl":[[12,0.53]],"id":2857977}]}]}
{"op":"mcm","clk":"AJLhrwkAzNigCgCdkaIK","pt":1657541155639,"mc":[{"id":"1.200806927","rc":[{"atl":[[1.1,95.91]],"trd":[[1.1,4947.1]],"tv":93313.96,"id":228749},{"trd":[[11,50.62]],"tv":6749.64,"id":2857977}],"tv":100063.6}]}
{"op":"mcm","clk":"APHjrwkA2NqgCgDTkqIK","pt":1657541159023,"mc":[{"id":"1.200806927","rc":[{"atb":[[1.09,1058.19]],"trd":[[1.09,3084.56]],"ltp":1.09,"tv":93319.22,"id":228749}],"tv":100068.86}]}
{"op":"mcm","clk":"AJPkrwkA8NqgCgDYkqIK","pt":1657541159328,"mc":[{"id":"1.200806927","rc":[{"atl":[[1.1,95.38]],"trd":[[1.1,4948.16]],"ltp":1.1,"tv":93320.28,"id":228749}],"tv":100069.92}]}
{"op":"mcm","clk":"ALXkrwkAhNugCgDqkqIK","pt":1657541159638,"mc":[{"id":"1.200806927","rc":[{"atl":[[1.1,42.79]],"trd":[[1.1,5053.34]],"tv":93425.46,"id":228749}],"tv":100175.1}]}
{"op":"mcm","clk":"ANHlrwkA8dugCgCwk6IK","pt":1657541161013,"mc":[{"id":"1.200806927","rc":[{"atb":[[1.1,36.21]],"atl":[[1.1,0]],"trd":[[1.1,5138.92]],"tv":93511.04,"id":228749}],"tv":100260.68}]}
{"op":"mcm","clk":"AOvlrwkAh9ygCgDBk6IK","pt":1657541161315,"mc":[{"id":"1.200806927","rc":[{"atb":[[1.1,35.68]],"trd":[[1.1,5139.98]],"tv":93512.1,"id":228749}],"tv":100261.74}]}
{"op":"mcm","clk":"AJnnrwkAkd2gCgCxlKIK","pt":1657541163145,"mc":[{"id":"1.200806927","rc":[{"atl":[[11,0.11]],"id":2857977}]}]}
{"op":"mcm","clk":"AKHnrwkAmd2gCgC1lKIK","pt":1657541163246,"mc":[{"id":"1.200806927","rc":[{"atb":[[1.1,39.8]],"id":228749}]}]}
{"op":"mcm","clk":"ANnnrwkA0t2gCgDQlKIK","pt":1657541163929,"mc":[{"id":"1.200806927","rc":[{"atb":[[1.1,42.43]],"id":228749}]}]}
{"op":"mcm","clk":"ALjqrwkAgOCgCgCKlqIK","pt":1657541167652,"mc":[{"id":"1.200806927","rc":[{"atb":[[1.1,37.17]],"trd":[[1.1,5150.5]],"tv":93522.62,"id":228749}],"tv":100272.26}]}
{"op":"mcm","clk":"AMrqrwkAj+CgCgCWlqIK","pt":1657541167819,"mc":[{"id":"1.200806927","rc":[{"atl":[[11,1.08]],"id":2857977}]}]}
{"op":"mcm","clk":"AIrrrwkAzOCgCgCxlqIK","pt":1657541168454,"mc":[{"id":"1.200806927","rc":[{"atb":[[1.01,1980.98]],"id":228749}]}]}
{"op":"mcm","clk":"AK7srwkA3uGgCgD9lqIK","pt":1657541170111,"mc":[{"id":"1.200806927","rc":[{"atb":[[1.1,50.32]],"id":228749}]}]}
{"op":"mcm","clk":"ALjtrwkA7eKgCgC/l6IK","pt":1657541171625,"mc":[{"id":"1.200806927","rc":[{"atb":[[1.1,52.95]],"id":228749}]}]}
{"op":"mcm","clk":"AKPurwkA8eOgCgDql6IK","pt":1657541172920,"mc":[{"id":"1.200806927","rc":[{"atb":[[1.1,52.42]],"trd":[[1.1,5151.56]],"tv":93523.68,"id":228749}],"tv":100273.32}]}
{"op":"mcm","clk":"AMDurwkAk+SgCgD0l6IK","pt":1657541173236,"mc":[{"id":"1.200806927","rc":[{"atl":[[11,1.19]],"id":2857977}]}]}
{"op":"mcm","clk":"AIHwrwkAz+WgCgDNmKIK","pt":1657541175323,"mc":[{"id":"1.200806927","rc":[{"atl":[[1.11,273.33]],"trd":[[1.11,17716.53]],"ltp":1.11,"tv":93528.94,"id":228749}],"tv":100278.58}]}
{"op":"mcm","clk":"AJzwrwkA8eWgCgDemKIK","pt":1657541175639,"mc":[{"id":"1.200806927","rc":[{"atl":[[1.11,271.41]],"trd":[[1.11,17720.36]],"tv":93532.77,"id":228749}],"tv":100282.41}]}
{"op":"mcm","clk":"ALXwrwkAi+agCgDtmKIK","pt":1657541175942,"mc":[{"id":"1.200806927","rc":[{"atb":[[1.1,47.24]],"trd":[[1.1,5161.92]],"ltp":1.1,"tv":93543.13,"id":228749}],"tv":100292.77}]}
{"op":"mcm","clk":"ANHwrwkAr+agCgCAmaIK","pt":1657541176318,"mc":[{"id":"1.200806927","rc":[{"atb":[[1.1,46.71]],"trd":[[1.1,5162.98]],"tv":93544.19,"id":228749}],"tv":100293.83}]}
{"op":"mcm","clk":"APDwrwkA1eagCgCVmaIK","pt":1657541176733,"mc":[{"id":"1.200806927","rc":[{"atl":[[11,1.08]],"id":2857977}]}]}
{"op":"mcm","clk":"AJbxrwkA9OagCgCrmaIK","pt":1657541177221,"mc":[{"id":"1.200806927","rc":[{"atb":[[1.1,20.41]],"trd":[[1.1,5215.58]],"tv":93596.79,"id":228749}],"tv":100346.43}]}
{"op":"mcm","clk":"ANrxrwkAruegCgDCmaIK","pt":1657541177954,"mc":[{"id":"1.200806927","rc":[{"atb":[[1.1,17.78]],"trd":[[1.1,5219.58]],"tv":93600.79,"id":228749}],"tv":100350.43}]}
{"op":"mcm","clk":"ALTyrwkA9+egCgDwmaIK","pt":1657541178939,"mc":[{"id":"1.200806927","rc":[{"atb":[[1.1,17.25]],"id":228749}]}]}
{"op":"mcm","clk":"ANPyrwkAjuigCgD5maIK","pt":1657541179243,"mc":[{"id":"1.200806927","rc":[{"atb":[[1.1,14.62]],"id":228749}]}]}
{"op":"mcm","clk":"APnyrwkAuOigCgCMmqIK","pt":1657541179651,"mc":[{"id":"1.200806927","rc":[{"atb":[[1.1,11.6]],"atl":[[1.11,269.08]],"trd":[[1.1,5225.62],[1.11,17722.69]],"ltp":1.11,"tv":93609.16,"id":228749},{"trd":[[10,1652.28]],"ltp":10,"tv":6749.9,"id":2857977}],"tv":100359.06}]}
{"op":"mcm","clk":"AJ30rwkAwumgCgDgmqIK","pt":1657541181228,"mc":[{"id":"1.200806927","rc":[{"atl":[[1.12,14]],"id":228749}]}]}
{"op":"mcm","clk":"AKj0rwkAyOmgCgDomqIK","pt":1657541181330,"mc":[{"id":"1.200806927","rc":[{"atb":[[1.1,6.61]],"id":228749}]}]}
{"op":"mcm","clk":"AMn0rwkA5OmgCgD8mqIK","pt":1657541181740,"mc":[{"id":"1.200806927","rc":[{"atb":[[1.1,2.3]],"trd":[[1.1,5234.24]],"ltp":1.1,"tv":93617.78,"id":228749}],"tv":100367.68}]}
{"op":"mcm","clk":"AO30rwkA9+mgCgCPm6IK","pt":1657541182149,"mc":[{"id":"1.200806927","rc":[{"atl":[[1.11,267.78]],"trd":[[1.11,17725.29]],"ltp":1.11,"tv":93620.38,"id":228749}],"tv":100370.28}]}
{"op":"mcm","clk":"AOj1rwkAyeqgCgCwm6IK","pt":1657541183247,"mc":[{"id":"1.200806927","rc":[{"atb":[[1.1,1.77]],"id":228749}]}]}
{"op":"mcm","clk":"AJz2rwkA/eqgCgDBm6IK","pt":1657541183772,"mc":[{"id":"1.200806927","rc":[{"atb":[[1.1,0.19]],"id":228749}]}]}
{"op":"mcm","clk":"AJT6rwkAje6gCgCpnaIK","pt":1657541189073,"mc":[{"id":"1.200806927","rc":[{"atl":[[1.11,267.25]],"trd":[[1.11,17726.35]],"tv":93621.44,"id":228749}],"tv":100371.34}]}
{"op":"mcm","clk":"AIj8rwkAjfCgCgCknqIK","pt":1657541191976,"mc":[{"id":"1.200806927","rc":[{"atl":[[1.3,342.11]],"id":228749}]}]}
{"op":"mcm","clk":"AJr8rwkApvCgCgCvnqIK","pt":1657541192189,"mc":[{"id":"1.200806927","rc":[{"atl":[[1.11,265.31]],"trd":[[1.11,17728.29]],"tv":93623.38,"id":228749},{"trd":[[10,1652.49]],"tv":6750.11,"id":2857977}],"tv":100373.49}]}
{"op":"mcm","clk":"AKH/rwkAivOgCgDcn6IK","pt":1657541196422,"mc":[{"id":"1.200806927","rc":[{"atl":[[1.11,162.08]],"trd":[[1.11,17832.05]],"tv":93727.14,"id":228749},{"trd":[[10,1663.89]],"tv":6761.51,"id":2857977}],"tv":100488.65}]}
{"op":"mcm","clk":"AIOAsAkA1fOgCgD4n6IK","pt":1657541197501,"mc":[{"id":"1.200806927","rc":[{"atb":[[1.1,0]],"trd":[[1.1,5235.57]],"ltp":1.1,"tv":93728.47,"id":228749},{"atl":[[12,1.39],[11,0.99]],"trd":[[11,50.72]],"ltp":11,"tv":6761.61,"id":2857977}],"tv":100490.08}]}
{"op":"mcm","clk":"AIqAsAkA3POgCgD7n6IK","pt":1657541197549,"mc":[{"id":"1.200806927","rc":[{"atl":[[1.11,161.12]],"trd":[[1.11,17833.01]],"ltp":1.11,"tv":93729.43,"id":228749},{"trd":[[10,1664]],"ltp":10,"tv":6761.72,"id":2857977}],"tv":100491.15}]}
{"op":"mcm","clk":"AJWEsAkA8/agCgDHoaIK","pt":1657541202983,"mc":[{"id":"1.200806927","rc":[{"atl":[[1.11,160.97]],"trd":[[1.11,17833.32]],"tv":93729.74,"id":228749}],"tv":100491.46}]}
{"op":"mcm","clk":"AN+EsAkAsvegCgDjoaIK","pt":1657541203803,"mc":[{"id":"1.200806927","rc":[{"atl":[[1.14,19.51]],"id":228749}]}]}
{"op":"mcm","clk":"AIuFsAkA3/egCgD6oaIK","pt":1657541204237,"mc":[{"id":"1.200806927","rc":[{"atl":[[1.11,154.3]],"trd":[[1.11,17839.99]],"tv":93736.41,"id":228749},{"trd":[[10,1664.74]],"tv":6762.46,"id":2857977}],"tv":100498.87}]}
{"op":"mcm","clk":"AJmFsAkA6vegCgCEoqIK","pt":1657541204380,"mc":[{"id":"1.200806927","rc":[{"atl":[[1.11,153.77]],"trd":[[1.11,17841.05]],"tv":93737.47,"id":228749}],"tv":100499.93}]}
{"op":"mcm","clk":"AOGFsAkAmfigCgCjoqIK","pt":1657541205014,"mc":[{"id":"1.200806927","rc":[{"atb":[[1.08,46.19]],"id":228749}]}]}
{"op":"mcm","clk":"ALyGsAkA5vigCgDMoqIK","pt":1657541205883,"mc":[{"id":"1.200806927","rc":[{"atl":[[1.11,152.81]],"trd":[[1.11,17842.01]],"tv":93738.43,"id":228749},{"trd":[[10,1664.85]],"tv":6762.57,"id":2857977}],"tv":100501}]}
{"op":"mcm","clk":"AKyHsAkA+vmgCgCIo6IK","pt":1657541207294,"mc":[{"id":"1.200806927","rc":[{"atl":[[1.11,151.76]],"trd":[[1.11,17844.11]],"tv":93740.53,"id":228749}],"tv":100503.1}]}
{"op":"mcm","clk":"AOiHsAkAtvqgCgCgo6IK","pt":1657541208012,"mc":[{"id":"1.200806927","rc":[{"atl":[[1.11,143.65]],"trd":[[1.11,17852.22]],"tv":93748.64,"id":228749},{"trd":[[10,1665.75]],"tv":6763.47,"id":2857977}],"tv":100512.11}]}
{"op":"mcm","clk":"AM2IsAkAlfugCgDWo6IK","pt":1657541209205,"mc":[{"id":"1.200806927","rc":[{"atl":[[1.11,140.49]],"trd":[[1.11,17858.54]],"tv":93754.96,"id":228749}],"tv":100518.43}]}
{"op":"mcm","clk":"APCJsAkAo/ygCgCvpKIK","pt":1657541210899,"mc":[{"id":"1.200806927","rc":[{"trd":[[1.1,5237.67]],"ltp":1.1,"tv":93757.06,"id":228749},{"atl":[[11,0.78]],"trd":[[11,50.93]],"ltp":11,"tv":6763.68,"id":2857977}],"tv":100520.74}]}
{"op":"mcm","clk":"AKWOsAkAmoChCgDlpqIK","pt":1657541217263,"mc":[{"id":"1.200806927","rc":[{"atl":[[1.1,202.58]],"trd":[[1.1,5245.46]],"tv":93764.85,"id":228749},{"atl":[[11,0]],"trd":[[11,51.71]],"tv":6764.46,"id":2857977}],"tv":100529.31}]}
{"op":"mcm","clk":"AP2PsAkAgoKhCgDdp6IK","pt":1657541219995,"mc":[{"id":"1.200806927","rc":[{"atl":[[1.1,203.11]],"id":228749}]}]}
{"op":"mcm","clk":"AKyQsAkApoKhCgD5p6IK","pt":1657541220534,"mc":[{"id":"1.200806927","rc":[{"atl":[[1.1,203.64]],"id":228749}]}]}
{"op":"mcm","clk":"AMWQsAkAtYKhCgCJqKIK","pt":1657541220827,"mc":[{"id":"1.200806927","rc":[{"atl":[[1.1,516.64]],"id":228749}]}]}
{"op":"mcm","clk":"AImRsAkA/IKhCgCyqKIK","pt":1657541221637,"mc":[{"id":"1.200806927","rc":[{"atl":[[1.1,514.01]],"id":228749}]}]}
{"op":"mcm","clk":"AP6SsAkA8oShCgDWqaIK","pt":1657541224250,"mc":[{"id":"1.200806927","rc":[{"atl":[[1.1,512.94]],"trd":[[1.1,5246.53]],"tv":93765.92,"id":228749},{"trd":[[11,51.81]],"tv":6764.56,"id":2857977}],"tv":100530.48}]}
{"op":"mcm","clk":"AKGUsAkA/oWhCgCyqqIK","pt":1657541225923,"mc":[{"id":"1.200806927","rc":[{"atl":[[1000,0.45]],"id":228749}]}]}
{"op":"mcm","clk":"AL2UsAkAnIahCgDCqqIK","pt":1657541226321,"mc":[{"id":"1.200806927","rc":[{"atl":[[1000,0.13]],"id":228749}]}]}
{"op":"mcm","clk":"ANWVsAkAnYehCgCUq6IK","pt":1657541228025,"mc":[{"id":"1.200806927","rc":[{"atl":[[1.1,494.94]],"trd":[[1.1,5264.53]],"tv":93783.92,"id":228749},{"trd":[[11,53.61]],"tv":6766.36,"id":2857977}],"tv":100550.28}]}
{"op":"mcm","clk":"AOaVsAkArYehCgCdq6IK","pt":1657541228237,"mc":[{"id":"1.200806927","rc":[{"atl":[[1.1,470.03]],"trd":[[1.1,5314.35]],"tv":93833.74,"id":228749}],"tv":100600.1}]}
{"op":"mcm","clk":"AK+WsAkA7oehCgDNq6IK","pt":1657541229029,"mc":[{"id":"1.200806927","rc":[{"atl":[[1.1,0],[1.11,0],[1.12,0]],"trd":[[1.1,5784.38],[1.11,17999.03],[1.12,12673.21]],"ltp":1.12,"tv":94458.26,"id":228749},{"atl":[[10,1935.71]],"trd":[[11,100.61],[10,1681.34],[9.2,1108.62]],"ltp":9.2,"tv":6830.65,"id":2857977}],"tv":101288.91}]}
{"op":"mcm","clk":"AL2WsAkA/YehCgDYq6IK","pt":1657541229224,"mc":[{"id":"1.200806927","rc":[{"atb":[[1.1,500]],"id":228749}]}]}
{"op":"mcm","clk":"ANiWsAkAkYihCgDtq6IK","pt":1657541229534,"mc":[{"id":"1.200806927","rc":[{"atb":[[1.11,500]],"id":228749}]}]}
{"op":"mcm","clk":"AICXsAkAt4ihCgCArKIK","pt":1657541230008,"mc":[{"id":"1.200806927","rc":[{"atb":[[1.1,500.11]],"id":228749}]}]}
{"op":"mcm","clk":"ANCXsAkAjYmhCgCurKIK","pt":1657541231043,"mc":[{"id":"1.200806927","rc":[{"atl":[[12,0.53]],"id":2857977}]}]}
{"op":"mcm","clk":"APOXsAkAromhCgDErKIK","pt":1657541231423,"mc":[{"id":"1.200806927","rc":[{"atb":[[1.11,500.35]],"trd":[[1.11,17999.68]],"ltp":1.11,"tv":94458.91,"id":228749}],"tv":101289.56}]}
{"op":"mcm","clk":"AKqYsAkA5omhCgDqrKIK","pt":1657541232234,"mc":[{"id":"1.200806927","rc":[{"atb":[[1.1,502.74]],"id":228749}]}]}
{"op":"mcm","clk":"AL6YsAkA9YmhCgDyrKIK","pt":1657541232417,"mc":[{"id":"1.200806927","rc":[{"atl":[[10,2135.56]],"id":2857977}]}]}
{"op":"mcm","clk":"AO6ZsAkAnIuhCgDeraIK","pt":1657541234639,"mc":[{"id":"1.200806927","rc":[{"atl":[[11,1.05]],"id":2857977}]}]}
{"op":"mcm","clk":"AIKasAkArIuhCgDkraIK","pt":1657541234845,"mc":[{"id":"1.200806927","rc":[{"atb":[[1.1,502.63]],"id":228749},{"atl":[[11,1.48]],"id":2857977}]}]}
{"op":"mcm","clk":"AIWasAkAs4uhCgDkraIK","pt":1657541234934,"mc":[{"id":"1.200806927","rc":[{"atb":[[1.1,503.42]],"id":228749}]}]}
{"op":"mcm","clk":"ANCasAkA44uhCgCDrqIK","pt":1657541235755,"mc":[{"id":"1.200806927","rc":[{"atl":[[10,199.85]],"id":2857977}]}]}
{"op":"mcm","clk":"AN2asAkA8IuhCgCIrqIK","pt":1657541235947,"mc":[{"id":"1.200806927","rc":[{"atb":[[1.1,504.47]],"id":228749}]}]}
{"op":"mcm","clk":"ALubsAkAvYyhCgC+rqIK","pt":1657541236844,"mc":[{"id":"1.200806927","rc":[{"atb":[[1.03,88.23]],"id":228749}]}]}
{"op":"mcm","clk":"AOWbsAkA3IyhCgDXrqIK","pt":1657541237358,"mc":[{"id":"1.200806927","rc":[{"atl":[[11,2.38]],"id":2857977}]}]}
{"op":"mcm","clk":"AJSdsAkAzo2hCgCtr6IK","pt":1657541239133,"mc":[{"id":"1.200806927","rc":[{"atb":[[1.13,607.05]],"atl":[[1.13,0]],"trd":[[1.13,1594.62]],"ltp":1.13,"tv":94484.81,"id":228749}],"tv":101315.46}]}
{"op":"mcm","clk":"AIWesAkAkI6hCgDfr6IK","pt":1657541240281,"mc":[{"id":"1.200806927","rc":[{"atl":[[11,2.68]],"id":2857977}]}]}
{"op":"mcm","clk":"AOCesAkA0o6hCgCMsKIK","pt":1657541241238,"mc":[{"id":"1.200806927","rc":[{"atb":[[1.11,501.4]],"id":228749}]}]}
{"op":"mcm","clk":"AM2fsAkAr4+hCgDLsKIK","pt":1657541242274,"mc":[{"id":"1.200806927","rc":[{"atb":[[1.03,88.56]],"id":228749}]}]}
{"op":"mcm","clk":"APOfsAkA1I+hCgDvsKIK","pt":1657541242765,"mc":[{"id":"1.200806927","rc":[{"atb":[[1.03,88.23]],"id":228749}]}]}
{"op":"mcm","clk":"AIigsAkA5o+hCgD+sKIK","pt":1657541243047,"mc":[{"id":"1.200806927","rc":[{"atl":[[10,0]],"id":2857977}]}]}
{"op":"mcm","clk":"AImhsAkAtZChCgDLsaIK","pt":1657541244445,"mc":[{"id":"1.200806927","rc":[{"atb":[[1.11,553.99]],"id":228749}]}]}
{"op":"mcm","clk":"AOmhsAkA/ZChCgD7saIK","pt":1657541245530,"mc":[{"id":"1.200806927","rc":[{"atb":[[1.11,555.36]],"id":228749}]}]}
{"op":"mcm","clk":"AKqjsAkAr5KhCgDosqIK","pt":1657541247477,"mc":[{"id":"1.200806927","rc":[{"atb":[[1.09,207.11]],"id":228749}]}]}
{"op":"mcm","clk":"ALOjsAkAupKhCgDvsqIK","pt":1657541247581,"mc":[{"id":"1.200806927","rc":[{"atl":[[11,1.63]],"id":2857977}]}]}
{"op":"mcm","clk":"ANijsAkAzJKhCgCAs6IK","pt":1657541247844,"mc":[{"id":"1.200806927","rc":[{"atb":[[1.12,0.33]],"id":228749}]}]}
{"op":"mcm","clk":"AImksAkAgpOhCgCps6IK","pt":1657541248470,"mc":[{"id":"1.200806927","rc":[{"atb":[[1.13,605.47]],"trd":[[1.13,1597.78]],"tv":94487.97,"id":228749}],"tv":101318.62}]}
{"op":"mcm","clk":"AMqksAkAv5OhCgDMs6IK","pt":1657541249343,"mc":[{"id":"1.200806927","rc":[{"atb":[[1.13,602.84]],"trd":[[1.13,1603.04]],"tv":94493.23,"id":228749}],"tv":101323.88}]}
{"op":"mcm","clk":"AN+ksAkA0pOhCgDbs6IK","pt":1657541249664,"mc":[{"id":"1.200806927","rc":[{"atl":[[11,0.73]],"id":2857977}]}]}
{"op":"mcm","clk":"AOWlsAkAsZShCgCjtKIK","pt":1657541251461,"mc":[{"id":"1.200806927","rc":[{"atb":[[1.13,576.54]],"trd":[[1.13,1655.64]],"tv":94545.83,"id":228749}],"tv":101376.48}]}
{"op":"mcm","clk":"AIumsAkA05ShCgCytKIK","pt":1657541251844,"mc":[{"id":"1.200806927","rc":[{"atb":[[1.13,687.54]],"id":228749}]}]}
{"op":"mcm","clk":"AMmmsAkA/5ShCgDTtKIK","pt":1657541252578,"mc":[{"id":"1.200806927","rc":[{"atl":[[11,0.3]],"id":2857977}]}]}
{"op":"mcm","clk":"AJansAkAtJWhCgD5tKIK","pt":1657541253443,"mc":[{"id":"1.200806927","rc":[{"atl":[[12,0]],"id":2857977}]}]}
{"op":"mcm","clk":"AJynsAkAu5WhCgCAtaIK","pt":1657541253537,"mc":[{"id":"1.200806927","rc":[{"atb":[[1.12,0]],"id":228749}]}]}
{"op":"mcm","clk":"AMSnsAkA4pWhCgCataIK","pt":1657541254055,"mc":[{"id":"1.200806927","rc":[{"atb":[[1.13,689.22]],"id":228749}]}]}
{"op":"mcm","clk":"ANOnsAkA9pWhCgChtaIK","pt":1657541254280,"mc":[{"id":"1.200806927","rc":[{"atb":[[1.13,663.33]],"trd":[[1.13,1707.42]],"tv":94597.61,"id":228749}],"tv":101428.26}]}
{"op":"mcm","clk":"AKSosAkAyJahCgDRtaIK","pt":1657541255258,"mc":[{"id":"1.200806927","rc":[{"atb":[[1.1,504.58]],"id":228749}]}]}
{"op":"mcm","clk":"AKqosAkA0ZahCgDUtaIK","pt":1657541255368,"mc":[{"id":"1.200806927","rc":[{"atl":[[1.14,18.29]],"trd":[[1.14,12365.73]],"ltp":1.14,"tv":94598.82,"id":228749},{"trd":[[8,1512.96]],"ltp":8,"tv":6830.82,"id":2857977}],"tv":101429.64}]}
{"op":"mcm","clk":"ALKosAkA2JahCgDWtaIK","pt":1657541255452,"mc":[{"id":"1.200806927","rc":[{"atb":[[1.13,661.23]],"trd":[[1.13,1711.62]],"ltp":1.13,"tv":94603.02,"id":228749}],"tv":101433.84}]}
{"op":"mcm","clk":"ANGosAkA9pahCgDktaIK","pt":1657541255779,"mc":[{"id":"1.200806927","rc":[{"atb":[[1.1,503.53]],"id":228749}]}]}
{"op":"mcm","clk":"AISpsAkAqpehCgCDtqIK","pt":1657541256453,"mc":[{"id":"1.200806927","rc":[{"atb":[[8.4,64]],"id":2857977}]}]}
{"op":"mcm","clk":"AJKpsAkAvpehCgCLtqIK","pt":1657541256658,"mc":[{"id":"1.200806927","rc":[{"atb":[[1.13,634.93]],"trd":[[1.13,1764.22]],"tv":94655.62,"id":228749}],"tv":101486.44}]}
{"op":"mcm","clk":"AKCpsAkAyZehCgCPtqIK","pt":1657541256780,"mc":[{"id":"1.200806927","rc":[{"atb":[[1.08,1.11]],"id":228749}]}]}
{"op":"mcm","clk":"AM2psAkAhJihCgCwtqIK","pt":1657541257551,"mc":[{"id":"1.200806927","rc":[{"atb":[[1.13,634.4]],"trd":[[1.13,1765.28]],"tv":94656.68,"id":228749}],"tv":101487.5}]}
{"op":"mcm","clk":"AN6psAkAnpihCgC+tqIK","pt":1657541257852,"mc":[{"id":"1.200806927","rc":[{"atb":[[1.13,630.19]],"trd":[[1.13,1773.7]],"tv":94665.1,"id":228749}],"tv":101495.92}]}
{"op":"mcm","clk":"AI6qsAkAyJihCgDgtqIK","pt":1657541258479,"mc":[{"id":"1.200806927","rc":[{"atb":[[1.08,0.43]],"id":228749}]}]}
{"op":"mcm","clk":"AKyqsAkA45ihCgDotqIK","pt":1657541258749,"mc":[{"id":"1.200806927","rc":[{"atb":[[1.13,629.76]],"trd":[[1.13,1774.56]],"tv":94665.96,"id":228749}],"tv":101496.78}]}
{"op":"mcm","clk":"ALeqsAkA8ZihCgDttqIK","pt":1657541258948,"mc":[{"id":"1.200806927","rc":[{"atb":[[1.03,88.56]],"id":228749}]}]}
{"op":"mcm","clk":"AMGqsAkA+pihCgDztqIK","pt":1657541259069,"mc":[{"id":"1.200806927","rc":[{"atl":[[1.14,8.29]],"trd":[[1.14,12385.74]],"ltp":1.14,"tv":94685.97,"id":228749}],"tv":101516.79}]}
{"op":"mcm","clk":"AM2qsAkAjJmhCgD7tqIK","pt":1657541259267,"mc":[{"id":"1.200806927","rc":[{"atb":[[1.13,625.76]],"trd":[[1.13,1782.56]],"ltp":1.13,"tv":94693.97,"id":228749}],"tv":101524.79}]}
{"op":"mcm","clk":"ANuqsAkAnJmhCgCAt6IK","pt":1657541259476,"mc":[{"id":"1.200806927","rc":[{"atb":[[1.03,88.23]],"id":228749}]}]}
{"op":"mcm","clk":"AIGrsAkAypmhCgCat6IK","pt":1657541260089,"mc":[{"id":"1.200806927","rc":[{"atl":[[11,0]],"id":2857977}]}]}
{"op":"mcm","clk":"ALarsAkAipqhCgC9t6IK","pt":1657541260767,"mc":[{"id":"1.200806927","rc":[{"atb":[[8.4,63.47]],"trd":[[8.4,1.06]],"ltp":8.4,"tv":6831.88,"id":2857977}],"tv":101525.85}]}
{"op":"mcm","clk":"AL+rsAkAk5qhCgDDt6IK","pt":1657541260877,"mc":[{"id":"1.200806927","rc":[{"atb":[[8.4,54.45]],"trd":[[8.4,19.1]],"tv":6849.92,"id":2857977}],"tv":101543.89}]}
{"op":"mcm","clk":"AOersAkAu5qhCgDdt6IK","pt":1657541261381,"mc":[{"id":"1.200806927","rc":[{"atl":[[1.14,16.06]],"id":228749}]}]}
{"op":"mcm","clk":"AI6ssAkA2pqhCgDyt6IK","pt":1657541261764,"mc":[{"id":"1.200806927","rc":[{"atb":[[8.4,53.6]],"trd":[[8.4,20.8]],"tv":6851.62,"id":2857977}],"tv":101545.59}]}
{"op":"mcm","clk":"AJessAkA4JqhCgD2t6IK","pt":1657541261865,"mc":[{"id":"1.200806927","rc":[{"atb":[[1.12,45.08]],"id":228749}]}]}
{"op":"mcm","clk":"AMessAkAkpuhCgCWuKIK","pt":1657541262478,"mc":[{"id":"1.200806927","rc":[{"atb":[[1.13,836.13],[1.1,502.74]],"id":228749}]}]}
{"op":"mcm","clk":"ANKssAkAmZuhCgCduKIK","pt":1657541262592,"mc":[{"id":"1.200806927","rc":[{"atl":[[1.14,0]],"trd":[[1.14,12422.27]],"ltp":1.14,"tv":94730.5,"id":228749},{"atb":[[8.4,48.64]],"trd":[[8.4,25.76]],"tv":6856.58,"id":2857977}],"tv":101587.08}]}
{"op":"mcm","clk":"AP6ssAkAuZuhCgCzuKIK","pt":1657541263126,"mc":[{"id":"1.200806927","rc":[{"trd":[[1.14,12423.85]],"tv":94732.08,"id":228749},{"atb":[[8.4,48.43]],"trd":[[8.4,25.97]],"tv":6856.79,"id":2857977}],"tv":101588.87}]}
{"op":"mcm","clk":"AIOtsAkAv5uhCgC3uKIK","pt":1657541263169,"mc":[{"id":"1.200806927","rc":[{"atb":[[1.13,809.83]],"trd":[[1.13,1835.16]],"ltp":1.13,"tv":94784.68,"id":228749}],"tv":101641.47}]}
{"op":"mcm","clk":"AJCtsAkAzpuhCgC9uKIK","pt":1657541263354,"mc":[{"id":"1.200806927","rc":[{"atl":[[1.14,26.3]],"id":228749}]}]}
{"op":"mcm","clk":"AOetsAkAq5yhCgD3uKIK","pt":1657541264554,"mc":[{"id":"1.200806927","rc":[{"atb":[[1.12,45.41]],"id":228749}]}]}
{"op":"mcm","clk":"APOtsAkAspyhCgD7uKIK","pt":1657541264661,"mc":[{"id":"1.200806927","rc":[{"atb":[[1.11,562.25]],"id":228749}]}]}
{"op":"mcm","clk":"AJeusAkAzpyhCgCRuaIK","pt":1657541265159,"mc":[{"id":"1.200806927","rc":[{"atb":[[1.13,799.08]],"trd":[[1.13,1856.66]],"tv":94806.18,"id":228749}],"tv":101662.97}]}
{"op":"mcm","clk":"ALSusAkA5ZyhCgCeuaIK","pt":1657541265492,"mc":[{"id":"1.200806927","rc":[{"atl":[[1.14,52.6]],"id":228749}]}]}
{"op":"mcm","clk":"AM6usAkA+JyhCgCouaIK","pt":1657541265797,"mc":[{"id":"1.200806927","rc":[{"atb":[[1.13,798.29]],"trd":[[1.13,1858.24]],"tv":94807.76,"id":228749}],"tv":101664.55}]}
{"op":"mcm","clk":"ANOusAkAgp2hCgCruaIK","pt":1657541265892,"mc":[{"id":"1.200806927","rc":[{"atb":[[1.13,587.92]],"id":228749}]}]}
{"op":"mcm","clk":"ANOvsAkAjp6hCgCOuqIK","pt":1657541267671,"mc":[{"id":"1.200806927","rc":[{"atb":[[1.13,587.39]],"trd":[[1.13,1859.3]],"tv":94808.82,"id":228749}],"tv":101665.61}]}
{"op":"mcm","clk":"ANuvsAkAmJ6hCgCTuqIK","pt":1657541267784,"mc":[{"id":"1.200806927","rc":[{"atl":[[1.14,48.09]],"id":228749}]}]}
{"op":"mcm","clk":"AJmwsAkA2J6hCgDDuqIK","pt":1657541268701,"mc":[{"id":"1.200806927","rc":[{"atb":[[1.13,476.39]],"id":228749}]}]}
{"op":"mcm","clk":"AN6wsAkAmJ+hCgDpuqIK","pt":1657541269584,"mc":[{"id":"1.200806927","rc":[{"atb":[[8.4,48.32]],"trd":[[8.4,26.18]],"tv":6857,"id":2857977}],"tv":101665.82}]}
{"op":"mcm","clk":"AOiwsAkAoZ+hCgDtuqIK","pt":1657541269706,"mc":[{"id":"1.200806927","rc":[{"atb":[[1.13,581.57]],"id":228749}]}]}
{"op":"mcm","clk":"APewsAkAuZ+hCgD9uqIK","pt":1657541270012,"mc":[{"id":"1.200806927","rc":[{"atl":[[1.14,69.13]],"id":228749}]}]}
{"op":"mcm","clk":"AIixsAkA1p+hCgCGu6IK","pt":1657541270260,"mc":[{"id":"1.200806927","rc":[{"atb":[[1.03,87.39]],"id":228749}]}]}
{"op":"mcm","clk":"AKiysAkA3qChCgDuu6IK","pt":1657541272194,"mc":[{"id":"1.200806927","rc":[{"atb":[[8.4,47.27]],"trd":[[8.4,28.28]],"tv":6859.1,"id":2857977}],"tv":101667.92}]}
{"op":"mcm","clk":"AMKysAkA/KChCgCAvKIK","pt":1657541272514,"mc":[{"id":"1.200806927","rc":[{"atb":[[1.13,556.57]],"trd":[[1.13,1909.3]],"tv":94858.82,"id":228749}],"tv":101717.92}]}
{"op":"mcm","clk":"APSysAkAvaGhCgCmvKIK","pt":1657541273289,"mc":[{"id":"1.200806927","rc":[{"atb":[[1.14,470.56],[1.11,555.36]],"atl":[[1.14,0]],"trd":[[1.14,12910.42]],"ltp":1.14,"tv":95345.39,"id":228749},{"atb":[[8.4,0]],"trd":[[8.4,75.55]],"tv":6906.37,"id":2857977}],"tv":102251.76}]}
{"op":"mcm","clk":"AIWzsAkA2KGhCgC1vKIK","pt":1657541273509,"mc":[{"id":"1.200806927","rc":[{"atb":[[1.14,466.75]],"trd":[[1.14,12914.23]],"tv":95349.2,"id":228749},{"trd":[[8.2,0.53]],"ltp":8.2,"tv":6906.9,"id":2857977}],"tv":102256.1}]}
{"op":"mcm","clk":"AKOzsAkA+KGhCgDGvKIK","pt":1657541273905,"mc":[{"id":"1.200806927","rc":[{"atb":[[1.14,466.86]],"id":228749}]}]}
{"op":"mcm","clk":"AMCzsAkAnaKhCgDXvKIK","pt":1657541274218,"mc":[{"id":"1.200806927","rc":[{"atl":[[8.4,0.95]],"id":2857977}]}]}
{"op":"mcm","clk":"AOuzsAkAyKKhCgDwvKIK","pt":1657541274670,"mc":[{"id":"1.200806927","rc":[{"atb":[[1.14,467.11]],"trd":[[1.14,12918.23]],"tv":95353.2,"id":228749}],"tv":102260.1}]}
{"op":"mcm","clk":"APOzsAkAz6KhCgD7vKIK","pt":1657541274775,"mc":[{"id":"1.200806927","rc":[{"atb":[[1.13,122.06],[1.14,0]],"trd":[[1.13,2778.32],[1.14,13847.94]],"ltp":1.13,"tv":97151.93,"id":228749}],"tv":104058.83}]}
{"op":"mcm","clk":"AP6zsAkA2aKhCgCAvaIK","pt":1657541274882,"mc":[{"id":"1.200806927","rc":[{"atb":[[1.14,2.8]],"id":228749}]}]}
{"op":"mcm","clk":"AIi0sAkA4aKhCgCJvaIK","pt":1657541274995,"mc":[{"id":"1.200806927","rc":[{"atb":[[1.14,0]],"atl":[[1.14,2.73]],"id":228749}]}]}
{"op":"mcm","clk":"AP+0sAkAx6OhCgDMvaIK","pt":1657541276275,"mc":[{"id":"1.200806927","rc":[{"atl":[[8.4,2.3]],"id":2857977}]}]}
{"op":"mcm","clk":"AKW1sAkA7qOhCgDpvaIK","pt":1657541276778,"mc":[{"id":"1.200806927","rc":[{"atl":[[1.14,1.47]],"id":228749}]}]}
{"op":"mcm","clk":"AK+1sAkA9qOhCgDwvaIK","pt":1657541276895,"mc":[{"id":"1.200806927","rc":[{"atl":[[8.4,1.26]],"id":2857977}]}]}
{"op":"mcm","clk":"AMO1sAkAiaShCgD7vaIK","pt":1657541277100,"mc":[{"id":"1.200806927","rc":[{"atl":[[8.4,5.57]],"id":2857977}]}]}
{"op":"mcm","clk":"ANa1sAkAlaShCgCFvqIK","pt":1657541277306,"mc":[{"id":"1.200806927","rc":[{"atl":[[11.5,0]],"id":2857977}]}]}
{"op":"mcm","clk":"AO21sAkArqShCgCUvqIK","pt":1657541277620,"mc":[{"id":"1.200806927","rc":[{"atl":[[1.18,0]],"id":228749}]}]}
{"op":"mcm","clk":"ALy2sAkA8aShCgDGvqIK","pt":1657541278516,"mc":[{"id":"1.200806927","rc":[{"atb":[[1.13,119.47]],"trd":[[1.13,2783.5]],"tv":97157.11,"id":228749}],"tv":104064.01}]}
{"op":"mcm","clk":"AM22sAkAiaWhCgDUvqIK","pt":1657541278813,"mc":[{"id":"1.200806927","rc":[{"atb":[[1.1,500.11]],"id":228749}]}]}
{"op":"mcm","clk":"AP62sAkAu6WhCgD2vqIK","pt":1657541279490,"mc":[{"id":"1.200806927","rc":[{"atb":[[1.14,58.53]],"atl":[[1.14,0]],"trd":[[1.14,13850.88]],"ltp":1.14,"tv":97160.05,"id":228749}],"tv":104066.95}]}
{"op":"mcm","clk":"AIe3sAkAxqWhCgD6vqIK","pt":1657541279586,"mc":[{"id":"1.200806927","rc":[{"atl":[[8.4,5.68]],"id":2857977}]}]}
{"op":"mcm","clk":"AJC3sAkAyqWhCgD/vqIK","pt":1657541279688,"mc":[{"id":"1.200806927","rc":[{"atb":[[1.11,553.99]],"id":228749}]}]}
{"op":"mcm","clk":"AL63sAkA7KWhCgCZv6IK","pt":1657541280220,"mc":[{"id":"1.200806927","rc":[{"atl":[[8.4,6.56]],"id":2857977}]}]}
{"op":"mcm","clk":"AKW4sAkAyqahCgDov6IK","pt":1657541281514,"mc":[{"id":"1.200806927","rc":[{"atb":[[1.14,64.58]],"id":228749}]}]}
{"op":"mcm","clk":"ANu4sAkAlKehCgCMwKIK","pt":1657541282287,"mc":[{"id":"1.200806927","rc":[{"atl":[[8.4,6.45]],"id":2857977}]}]}
{"op":"mcm","clk":"AJ+5sAkA46ehCgDIwKIK","pt":1657541283199,"mc":[{"id":"1.200806927","rc":[{"atb":[[1.13,739.47]],"id":228749}]}]}
{"op":"mcm","clk":"AI26sAkAy6ihCgCZwaIK","pt":1657541284500,"mc":[{"id":"1.200806927","rc":[{"atb":[[1.14,11.99]],"trd":[[1.14,13956.06]],"tv":97265.23,"id":228749}],"tv":104172.13}]}
{"op":"mcm","clk":"AKe6sAkA36ihCgCowaIK","pt":1657541284788,"mc":[{"id":"1.200806927","rc":[{"atb":[[1.14,12.78]],"id":228749}]}]}
{"op":"mcm","clk":"ALC6sAkA6qihCgCvwaIK","pt":1657541284916,"mc":[{"id":"1.200806927","rc":[{"atl":[[1.15,5.26]],"id":228749}]}]}
{"op":"mcm","clk":"ANC6sAkAgKmhCgC9waIK","pt":1657541285312,"mc":[{"id":"1.200806927","rc":[{"atl":[[8.4,2.14]],"id":2857977}]}]}
{"op":"mcm","clk":"AOa6sAkAmamhCgDSwaIK","pt":1657541285638,"mc":[{"id":"1.200806927","rc":[{"atl":[[8.4,2.36]],"id":2857977}]}]}
{"op":"mcm","clk":"AOa7sAkAlqqhCgCywqIK","pt":1657541287414,"mc":[{"id":"1.200806927","rc":[{"atb":[[1.14,0],[1.12,822.41]],"atl":[[1.14,187.22]],"trd":[[1.14,13981.62]],"tv":97290.79,"id":228749}],"tv":104197.69}]}
{"op":"mcm","clk":"AP67sAkAsKqhCgC7wqIK","pt":1657541287722,"mc":[{"id":"1.200806927","rc":[{"atb":[[1.09,0]],"id":228749}]}]}
{"op":"mcm","clk":"AKa8sAkA46qhCgDTwqIK","pt":1657541288229,"mc":[{"id":"1.200806927","rc":[{"atl":[[1.15,0]],"id":228749}]}]}
{"op":"mcm","clk":"ALq8sAkA+qqhCgDiwqIK","pt":1657541288534,"mc":[{"id":"1.200806927","rc":[{"atl":[[8.4,2.14]],"id":2857977}]}]}
{"op":"mcm","clk":"AO28sAkAtKuhCgCBw6IK","pt":1657541289207,"mc":[{"id":"1.200806927","rc":[{"atl":[[1.14,192.48]],"id":228749}]}]}
{"op":"mcm","clk":"AKC9sAkA3KuhCgCdw6IK","pt":1657541289840,"mc":[{"id":"1.200806927","rc":[{"atl":[[1.14,402.85]],"id":228749}]}]}
{"op":"mcm","clk":"AOy9sAkApKyhCgDcw6IK","pt":1657541290745,"mc":[{"id":"1.200806927","rc":[{"atl":[[1.14,702.85]],"id":228749}]}]}
{"op":"mcm","clk":"AJS+sAkAx6yhCgD9w6IK","pt":1657541291207,"mc":[{"id":"1.200806927","rc":[{"atl":[[1.14,702.1]],"trd":[[1.14,13982.37]],"tv":97291.54,"id":228749},{"trd":[[8,1513.07]],"ltp":8,"tv":6907.01,"id":2857977}],"tv":104198.55}]}
{"op":"mcm","clk":"ANa+sAkA+ayhCgCoxKIK","pt":1657541292047,"mc":[{"id":"1.200806927","rc":[{"atl":[[1.14,703.15]],"id":228749}]}]}
{"op":"mcm","clk":"APe+sAkAma2hCgDFxKIK","pt":1657541292509,"mc":[{"id":"1.200806927","rc":[{"atl":[[1.14,743.18]],"id":228749}]}]}
{"op":"mcm","clk":"AJS/sAkAra2hCgDUxKIK","pt":1657541292831,"mc":[{"id":"1.200806927","rc":[{"atl":[[1.14,740.55]],"trd":[[1.14,13987.63]],"tv":97296.8,"id":228749}],"tv":104203.81}]}
{"op":"mcm","clk":"ANK/sAkAgK6hCgD5xKIK","pt":1657541293818,"mc":[{"id":"1.200806927","rc":[{"atb":[[1.13,731.89]],"trd":[[1.13,2798.66]],"ltp":1.13,"tv":97311.96,"id":228749}],"tv":104218.97}]}
{"op":"mcm","clk":"AKvAsAkA3q6hCgCnxaIK","pt":1657541295046,"mc":[{"id":"1.200806927","rc":[{"atb":[[7.4,5.26]],"id":2857977}]}]}
{"op":"mcm","clk":"ANzAsAkAha+hCgC8xaIK","pt":1657541295574,"mc":[{"id":"1.200806927","rc":[{"atl":[[1.15,1352.43]],"id":228749}]}]}
{"op":"mcm","clk":"AOPBsAkAlLChCgCOxqIK","pt":1657541297237,"mc":[{"id":"1.200806927","rc":[{"atb":[[1.12,45.41]],"atl":[[1.14,742.32]],"id":228749}]}]}
{"op":"mcm","clk":"AI7CsAkAx7ChCgCuxqIK","pt":1657541297805,"mc":[{"id":"1.200806927","rc":[{"atl":[[1.14,740.74]],"trd":[[1.14,13990.79]],"ltp":1.14,"tv":97315.12,"id":228749}],"tv":104222.13}]}
{"op":"mcm","clk":"AJ7CsAkA27ChCgC6xqIK","pt":1657541298103,"mc":[{"id":"1.200806927","rc":[{"atb":[[8.4,0.49]],"atl":[[8.4,0]],"trd":[[8.4,77.31]],"ltp":8.4,"tv":6908.77,"id":2857977}],"tv":104223.89}]}
{"op":"mcm","clk":"AM7CsAkAirGhCgDbxqIK","pt":1657541298750,"mc":[{"id":"1.200806927","rc":[{"atb":[[8.4,0.09]],"trd":[[8.4,78.11]],"tv":6909.57,"id":2857977}],"tv":104224.69}]}
{"op":"mcm","clk":"AOvCsAkArrGhCgDoxqIK","pt":1657541299158,"mc":[{"id":"1.200806927","rc":[{"atl":[[1000,0.35]],"id":228749}]}]}
{"op":"mcm","clk":"AITDsAkAv7GhCgDzxqIK","pt":1657541299412,"mc":[{"id":"1.200806927","rc":[{"atl":[[1.14,739.16]],"trd":[[1.14,13993.95]],"tv":97318.28,"id":228749}],"tv":104227.85}]}
{"op":"mcm","clk":"AIvDsAkAyrGhCgD5xqIK","pt":1657541299528,"mc":[{"id":"1.200806927","rc":[{"atl":[[1000,0.13]],"id":228749}]}]}
{"op":"mcm","clk":"AJnDsAkA27GhCgCEx6IK","pt":1657541299726,"mc":[{"id":"1.200806927","rc":[{"atl":[[1.14,735.32]],"trd":[[1.14,13997.79]],"tv":97322.12,"id":228749},{"atb":[[8.4,0]],"trd":[[8.4,78.29],[8,1513.61]],"ltp":8,"tv":6910.29,"id":2857977}],"tv":104232.41}]}
{"op":"mcm","clk":"ALvDsAkA9bGhCgCSx6IK","pt":1657541300049,"mc":[{"id":"1.200806927","rc":[{"atl":[[1.14,705.05]],"trd":[[1.14,14028.06]],"tv":97352.39,"id":228749},{"trd":[[8,1517.93]],"tv":6914.61,"id":2857977}],"tv":104267}]}
{"op":"mcm","clk":"AIjEsAkAtrKhCgC8x6IK","pt":1657541300958,"mc":[{"id":"1.200806927","rc":[{"atl":[[1.14,699.12]],"trd":[[1.14,14033.99]],"tv":97358.32,"id":228749},{"trd":[[8,1518.77]],"tv":6915.45,"id":2857977}],"tv":104273.77}]}
{"op":"mcm","clk":"AJbEsAkAw7KhCgDEx6IK","pt":1657541301120,"mc":[{"id":"1.200806927","rc":[{"atb":[[1.13,705.59]],"trd":[[1.13,2808.72]],"ltp":1.13,"tv":97368.38,"id":228749}],"tv":104283.83}]}
{"op":"mcm","clk":"AKHEsAkA1bKhCgDax6IK","pt":1657541301316,"mc":[{"id":"1.200806927","rc":[{"atb":[[8.4,0.53]],"id":2857977}]}]}
{"op":"mcm","clk":"AKnEsAkA37KhCgDex6IK","pt":1657541301433,"mc":[{"id":"1.200806927","rc":[{"atl":[[1.14,671.77]],"trd":[[1.14,14088.69]],"ltp":1.14,"tv":97423.08,"id":228749}],"tv":104338.53}]}
{"op":"mcm","clk":"AM7EsAkAjLOhCgD7x6IK","pt":1657541301928,"mc":[{"id":"1.200806927","rc":[{"atb":[[1.13,605.67]],"trd":[[1.13,2837.38]],"ltp":1.13,"tv":97451.74,"id":228749},{"atb":[[8.4,0.42]],"trd":[[8.4,78.51]],"ltp":8.4,"tv":6915.67,"id":2857977}],"tv":104367.41}]}
{"op":"mcm","clk":"AIzFsAkA1LOhCgClyKIK","pt":1657541302821,"mc":[{"id":"1.200806927","rc":[{"atb":[[8.4,0.32]],"trd":[[8.4,78.71]],"tv":6915.87,"id":2857977}],"tv":104367.61}]}
{"op":"mcm","clk":"AM3FsAkAqrShCgDNyKIK","pt":1657541303712,"mc":[{"id":"1.200806927","rc":[{"atl":[[1.14,669.14]],"trd":[[1.14,14093.95]],"ltp":1.14,"tv":97457,"id":228749}],"tv":104372.87}]}
{"op":"mcm","clk":"AJ3GsAkA6rShCgD3yKIK","pt":1657541304665,"mc":[{"id":"1.200806927","rc":[{"atb":[[1.13,605.44]],"trd":[[1.13,2837.84]],"ltp":1.13,"tv":97457.46,"id":228749}],"tv":104373.33}]}
{"op":"mcm","clk":"AK/GsAkA/bShCgCEyaIK","pt":1657541304927,"mc":[{"id":"1.200806927","rc":[{"atb":[[1.13,601.23]],"trd":[[1.13,2846.26]],"tv":97465.88,"id":228749}],"tv":104381.75}]}
{"op":"mcm","clk":"ANbGsAkAnbWhCgCUyaIK","pt":1657541305343,"mc":[{"id":"1.200806927","rc":[{"atl":[[1.14,646.45]],"trd":[[1.14,14117.43]],"ltp":1.14,"tv":97489.36,"id":228749},{"atb":[[8.4,0]],"trd":[[8.4,79.35],[8,1522.12]],"ltp":8,"tv":6919.86,"id":2857977}],"tv":104409.22}]}
{"op":"mcm","clk":"AOfGsAkAqrWhCgCdyaIK","pt":1657541305552,"mc":[{"id":"1.200806927","rc":[{"atl":[[1.17,36.81]],"id":228749}]}]}
{"op":"mcm","clk":"AJTHsAkA27WhCgC4yaIK","pt":1657541306128,"mc":[{"id":"1.200806927","rc":[{"atb":[[1.13,598.64]],"trd":[[1.13,2851.44]],"ltp":1.13,"tv":97494.54,"id":228749}],"tv":104414.4}]}
{"op":"mcm","clk":"ANjIsAkA/LahCgCpyqIK","pt":1657541308138,"mc":[{"id":"1.200806927","rc":[{"atl":[[1.14,644.87]],"trd":[[1.14,14120.59]],"ltp":1.14,"tv":97497.7,"id":228749}],"tv":104417.56}]}
{"op":"mcm","clk":"ALXJsAkAz7ehCgDvyqIK","pt":1657541309228,"mc":[{"id":"1.200806927","rc":[{"atl":[[1.14,642.87]],"trd":[[1.14,14124.59]],"tv":97501.7,"id":228749}],"tv":104421.56}]}
{"op":"mcm","clk":"AN7JsAkA/7ehCgCMy6IK","pt":1657541309755,"mc":[{"id":"1.200806927","rc":[{"atl":[[1.14,648.13]],"id":228749}]}]}
{"op":"mcm","clk":"AOzJsAkAhrihCgCQy6IK","pt":1657541309862,"mc":[{"id":"1.200806927","rc":[{"atb":[[1.13,596.54]],"trd":[[1.13,2855.64]],"ltp":1.13,"tv":97505.9,"id":228749}],"tv":104425.76}]}
{"op":"mcm","clk":"APjJsAkAkbihCgCey6IK","pt":1657541310062,"mc":[{"id":"1.200806927","rc":[{"atb":[[1.03,88.23]],"id":228749}]}]}
{"op":"mcm","clk":"AJHKsAkAqbihCgCyy6IK","pt":1657541310337,"mc":[{"id":"1.200806927","rc":[{"atb":[[1.12,58.36]],"id":228749}]}]}
{"op":"mcm","clk":"ANHKsAkA8rihCgDZy6IK","pt":1657541311261,"mc":[{"id":"1.200806927","rc":[{"atb":[[1.13,595.33]],"trd":[[1.13,2858.06]],"tv":97508.32,"id":228749}],"tv":104428.18}]}
{"op":"mcm","clk":"AOnKsAkAjbmhCgDny6IK","pt":1657541311525,"mc":[{"id":"1.200806927","rc":[{"atl":[[1.14,644.41]],"trd":[[1.14,14128.31]],"ltp":1.14,"tv":97512.04,"id":228749},{"trd":[[8,1522.65]],"tv":6920.39,"id":2857977}],"tv":104432.43}]}
{"op":"mcm","clk":"AIHMsAkAjrqhCgCxzKIK","pt":1657541313195,"mc":[{"id":"1.200806927","rc":[{"atl":[[1.14,639.15]],"id":228749}]}]}
{"op":"mcm","clk":"AIzMsAkAmrqhCgC1zKIK","pt":1657541313294,"mc":[{"id":"1.200806927","rc":[{"atl":[[1.14,638.24]],"trd":[[1.14,14129.22]],"tv":97512.95,"id":228749},{"trd":[[8,1522.78]],"tv":6920.52,"id":2857977}],"tv":104433.47}]}
{"op":"mcm","clk":"ALDNsAkAz7uhCgCpzaIK","pt":1657541315131,"mc":[{"id":"1.200806927","rc":[{"atl":[[1.14,635.61]],"trd":[[1.14,14134.48]],"tv":97518.21,"id":228749}],"tv":104438.73}]}
{"op":"mcm","clk":"ANvNsAkAgryhCgDCzaIK","pt":1657541315413,"mc":[{"id":"1.200806927","rc":[{"atb":[[1.03,88.5]],"id":228749}]}]}
{"op":"mcm","clk":"AKnOsAkA07yhCgCOzqIK","pt":1657541315857,"mc":[{"id":"1.200806927","rc":[{"atb":[[1.03,88.23]],"id":228749}]}]}
{"op":"mcm","clk":"AMbOsAkA+LyhCgCgzqIK","pt":1657541315948,"mc":[{"id":"1.200806927","rc":[{"atl":[[1.14,625.09]],"trd":[[1.14,14155.52]],"tv":97539.25,"id":228749}],"tv":104459.77}]}
{"op":"mcm","clk":"ALTQsAkA9L6hCgDLz6IK","pt":1657541317705,"mc":[{"id":"1.200806927","rc":[{"atb":[[1.13,594.8]],"trd":[[1.13,2859.12]],"ltp":1.13,"tv":97540.31,"id":228749}],"tv":104460.83}]}
{"op":"mcm","clk":"AMPQsAkA/L6hCgDOz6IK","pt":1657541317816,"mc":[{"id":"1.200806927","rc":[{"atl":[[1.14,598.79]],"trd":[[1.14,14208.12]],"ltp":1.14,"tv":97592.91,"id":228749}],"tv":104513.43}]}
{"op":"mcm","clk":"AOzQsAkApr+hCgDmz6IK","pt":1657541318243,"mc":[{"id":"1.200806927","rc":[{"atb":[[1.13,592.64]],"trd":[[1.13,2863.43]],"ltp":1.13,"tv":97597.22,"id":228749}],"tv":104517.74}]}
{"op":"mcm","clk":"AIrSsAkA4cChCgDH0KIK","pt":1657541320216,"mc":[{"id":"1.200806927","rc":[{"atl":[[1.14,558.76]],"id":228749}]}]}
{"op":"mcm","clk":"ALDSsAkAj8GhCgDj0KIK","pt":1657541320727,"mc":[{"id":"1.200806927","rc":[{"atb":[[1.13,592.11]],"atl":[[1.14,600.84],[1.15,1752.43]],"trd":[[1.13,2864.49]],"tv":97598.28,"id":228749}],"tv":104518.8}]}
{"op":"mcm","clk":"AL7SsAkAmsGhCgDo0KIK","pt":1657541320840,"mc":[{"id":"1.200806927","rc":[{"atb":[[1.13,589.48]],"trd":[[1.13,2869.75]],"tv":97603.54,"id":228749}],"tv":104524.06}]}
{"op":"mcm","clk":"AMjSsAkApcGhCgDt0KIK","pt":1657541320950,"mc":[{"id":"1.200806927","rc":[{"atl":[[1.14,598.99]],"trd":[[1.14,14211.82]],"ltp":1.14,"tv":97607.24,"id":228749}],"tv":104527.76}]}
{"op":"mcm","clk":"ANnSsAkAtMGhCgD10KIK","pt":1657541321147,"mc":[{"id":"1.200806927","rc":[{"atb":[[1.13,586.85]],"trd":[[1.13,2875.01]],"ltp":1.13,"tv":97612.5,"id":228749}],"tv":104533.02}]}
{"op":"mcm","clk":"AOjSsAkAxMGhCgD+0KIK","pt":1657541321336,"mc":[{"id":"1.200806927","rc":[{"atb":[[1.03,87.39]],"atl":[[1.14,598.24]],"trd":[[1.14,14212.57]],"ltp":1.14,"tv":97613.25,"id":228749},{"trd":[[8,1522.88]],"tv":6920.62,"id":2857977}],"tv":104533.87}]}
{"op":"mcm","clk":"AI/UsAkA9MKhCgDR0aIK","pt":1657541323033,"mc":[{"id":"1.200806927","rc":[{"atl":[[11,0.35]],"id":2857977}]}]}
{"op":"mcm","clk":"AKDVsAkAg8ShCgCe0qIK","pt":1657541324807,"mc":[{"id":"1.200806927","rc":[{"atl":[[1.14,596.47]],"id":228749}]}]}
{"op":"mcm","clk":"AKvVsAkAk8ShCgCm0qIK","pt":1657541324921,"mc":[{"id":"1.200806927","rc":[{"atb":[[1.13,580.54]],"trd":[[1.13,2887.63]],"ltp":1.13,"tv":97625.87,"id":228749}],"tv":104546.49}]}
{"op":"mcm","clk":"ANzVsAkAyMShCgDB0qIK","pt":1657541325538,"mc":[{"id":"1.200806927","rc":[{"atb":[[1.13,575.28]],"trd":[[1.13,2898.15]],"tv":97636.39,"id":228749}],"tv":104557.01}]}
{"op":"mcm","clk":"APvVsAkA5MShCgDY0qIK","pt":1657541325912,"mc":[{"id":"1.200806927","rc":[{"atl":[[1.14,595.62]],"trd":[[1.14,14213.42]],"ltp":1.14,"tv":97637.24,"id":228749},{"trd":[[8,1523]],"tv":6920.74,"id":2857977}],"tv":104557.98}]}
{"op":"mcm","clk":"AJXWsAkAgMWhCgDz0qIK","pt":1657541326322,"mc":[{"id":"1.200806927","rc":[{"atl":[[1.14,594.83]],"id":228749}]}]}
{"op":"mcm","clk":"AJ/XsAkA/cWhCgDM06IK","pt":1657541328120,"mc":[{"id":"1.200806927","rc":[{"atl":[[1.14,593.78]],"id":228749}]}]}
{"op":"mcm","clk":"ALXZsAkA6MehCgDi1KIK","pt":1657541331357,"mc":[{"id":"1.200806927","rc":[{"atb":[[1.13,561.75]],"trd":[[1.13,2925.21]],"ltp":1.13,"tv":97664.3,"id":228749}],"tv":104585.04}]}
{"op":"mcm","clk":"AODZsAkAlcihCgD61KIK","pt":1657541331818,"mc":[{"id":"1.200806927","rc":[{"atl":[[1000,0.35]],"id":228749}]}]}
{"op":"mcm","clk":"APPZsAkArcihCgCM1aIK","pt":1657541332129,"mc":[{"id":"1.200806927","rc":[{"atl":[[1.14,551.7]],"id":228749}]}]}
{"op":"mcm","clk":"AP7ZsAkAtcihCgCT1aIK","pt":1657541332247,"mc":[{"id":"1.200806927","rc":[{"atl":[[1000,0.13]],"id":228749}]}]}
{"op":"mcm","clk":"AIPasAkAvMihCgCV1aIK","pt":1657541332330,"mc":[{"id":"1.200806927","rc":[{"atl":[[1.14,549.45]],"trd":[[1.14,14217.92]],"ltp":1.14,"tv":97668.8,"id":228749}],"tv":104589.54}]}
{"op":"mcm","clk":"AJfbsAkAqMmhCgD31aIK","pt":1657541333956,"mc":[{"id":"1.200806927","rc":[{"atl":[[1.14,547.65]],"trd":[[1.14,14221.52]],"tv":97672.4,"id":228749}],"tv":104593.14}]}
{"op":"mcm","clk":"AMXcsAkAwcqhCgDj1qIK","pt":1657541335954,"mc":[{"id":"1.200806927","rc":[{"atb":[[1.13,351.38]],"trd":[[1.13,3345.95]],"ltp":1.13,"tv":98093.14,"id":228749}],"tv":105013.88}]}
{"op":"mcm","clk":"AObcsAkA3MqhCgDx1qIK","pt":1657541336256,"mc":[{"id":"1.200806927","rc":[{"atb":[[1.13,350.85]],"trd":[[1.13,3347.01]],"tv":98094.2,"id":228749}],"tv":105014.94}]}
{"op":"mcm","clk":"AMrdsAkA08uhCgDC16IK","pt":1657541337355,"mc":[{"id":"1.200806927","rc":[{"atb":[[1.13,350.62]],"trd":[[1.13,3347.47]],"tv":98094.66,"id":228749}],"tv":105015.4}]}
{"op":"mcm","clk":"ANLesAkA48yhCgCK2KIK","pt":1657541338769,"mc":[{"id":"1.200806927","rc":[{"atl":[[1.14,521.35]],"trd":[[1.14,14274.12]],"ltp":1.14,"tv":98147.26,"id":228749}],"tv":105068}]}
{"op":"mcm","clk":"AJXhsAkAp8+hCgDk2aIK","pt":1657541342075,"mc":[{"id":"1.200806927","rc":[{"atb":[[1.13,341.15]],"trd":[[1.13,3366.41]],"ltp":1.13,"tv":98166.2,"id":228749}],"tv":105086.94}]}
{"op":"mcm","clk":"AL/hsAkAz8+hCgD+2aIK","pt":1657541342454,"mc":[{"id":"1.200806927","rc":[{"atl":[[1.24,0.54]],"id":228749}]}]}
{"op":"mcm","clk":"AMvhsAkA2c+hCgCH2qIK","pt":1657541342567,"mc":[{"id":"1.200806927","rc":[{"atb":[[1.13,301.12]],"trd":[[1.13,3446.47]],"tv":98246.26,"id":228749}],"tv":105167}]}
{"op":"mcm","clk":"ANzhsAkA7s+hCgCY2qIK","pt":1657541342775,"mc":[{"id":"1.200806927","rc":[{"atb":[[1.03,88.23]],"id":228749}]}]}
{"op":"mcm","clk":"AILisAkAlNChCgCw2qIK","pt":1657541343183,"mc":[{"id":"1.200806927","rc":[{"atb":[[1.13,89.7]],"trd":[[1.13,3869.31]],"tv":98669.1,"id":228749}],"tv":105589.84}]}
{"op":"mcm","clk":"AKLisAkAttChCgDG2qIK","pt":1657541343448,"mc":[{"id":"1.200806927","rc":[{"atl":[[1.14,515.93]],"trd":[[1.14,14284.96]],"ltp":1.14,"tv":98679.94,"id":228749}],"tv":105600.68}]}
{"op":"mcm","clk":"APrisAkAitGhCgCF26IK","pt":1657541344344,"mc":[{"id":"1.200806927","rc":[{"atl":[[1.14,513.3]],"trd":[[1.14,14285.56]],"tv":98680.54,"id":228749}],"tv":105601.28}]}
{"op":"mcm","clk":"AJ/jsAkArtGhCgCi26IK","pt":1657541344772,"mc":[{"id":"1.200806927","rc":[{"atb":[[1.13,82.86]],"trd":[[1.13,3882.99]],"ltp":1.13,"tv":98694.22,"id":228749}],"tv":105614.96}]}
{"op":"mcm","clk":"ALbjsAkAwNGhCgCx26IK","pt":1657541344989,"mc":[{"id":"1.200806927","rc":[{"atl":[[1.14,500.15]],"id":228749}]}]}
{"op":"mcm","clk":"AKDksAkAkdKhCgD726IK","pt":1657541345974,"mc":[{"id":"1.200806927","rc":[{"atl":[[1.14,547.9]],"id":228749}]}]}
{"op":"mcm","clk":"AP3ksAkA59KhCgC93KIK","pt":1657541346962,"mc":[{"id":"1.200806927","rc":[{"atl":[[1.14,542.49]],"id":228749}]}]}
{"op":"mcm","clk":"AMDlsAkAsdOhCgDq3KIK","pt":1657541347697,"mc":[{"id":"1.200806927","rc":[{"atl":[[1.14,541.91]],"id":228749}]}]}
{"op":"mcm","clk":"AM7lsAkAudOhCgDw3KIK","pt":1657541347781,"mc":[{"id":"1.200806927","rc":[{"atl":[[1.14,594.5]],"id":228749}]}]}
{"op":"mcm","clk":"APblsAkA39OhCgCH3aIK","pt":1657541348166,"mc":[{"id":"1.200806927","rc":[{"atb":[[1.03,88.5]],"id":228749}]}]}
{"op":"mcm","clk":"AIzmsAkA+NOhCgCS3aIK","pt":1657541348382,"mc":[{"id":"1.200806927","rc":[{"atl":[[1.14,599.76]],"id":228749}]}]}
{"op":"mcm","clk":"AJ3msAkAidShCgCj3aIK","pt":1657541348586,"mc":[{"id":"1.200806927","rc":[{"atb":[[1.03,88.23]],"id":228749}]}]}
{"op":"mcm","clk":"AOrmsAkA0NShCgDz3aIK","pt":1657541349378,"mc":[{"id":"1.200806927","rc":[{"atb":[[1.13,82.69]],"trd":[[1.13,3883.34]],"tv":98694.57,"id":228749}],"tv":105615.31}]}
{"op":"mcm","clk":"AL/nsAkAntWhCgCg3qIK","pt":1657541350167,"mc":[{"id":"1.200806927","rc":[{"atl":[[1.14,594.5]],"id":228749},{"atb":[[5,0]],"id":2857977}]}]}
{"op":"mcm","clk":"AMXnsAkAqtWhCgCo3qIK","pt":1657541350262,"mc":[{"id":"1.200806927","rc":[{"atb":[[7.4,0]],"id":2857977}]}]}
{"op":"mcm","clk":"ANrosAkAutahCgCK36IK","pt":1657541351883,"mc":[{"id":"1.200806927","rc":[{"atl":[[1.14,589.24]],"id":228749}]}]}
{"op":"mcm","clk":"AL3psAkAtdehCgDQ36IK","pt":1657541353092,"mc":[{"id":"1.200806927","rc":[{"atl":[[1.14,584.73]],"id":228749}]}]}
{"op":"mcm","clk":"AOTpsAkA6dehCgDm36IK","pt":1657541353567,"mc":[{"id":"1.200806927","rc":[{"atb":[[1.13,81.06]],"trd":[[1.13,3886.6]],"tv":98697.83,"id":228749}],"tv":105618.57}]}
{"op":"mcm","clk":"AO3psAkA99ehCgDv36IK","pt":1657541353679,"mc":[{"id":"1.200806927","rc":[{"atl":[[1.14,584.46]],"trd":[[1.14,14286.1]],"ltp":1.14,"tv":98698.37,"id":228749}],"tv":105619.11}]}
{"op":"mcm","clk":"AJHqsAkAptihCgCH4KIK","pt":1657541354089,"mc":[{"id":"1.200806927","rc":[{"atb":[[1.03,87.39]],"id":228749}]}]}
{"op":"mcm","clk":"AL3qsAkA4dihCgCl4KIK","pt":1657541354673,"mc":[{"id":"1.200806927","rc":[{"atb":[[1.13,80.63]],"trd":[[1.13,3887.46]],"ltp":1.13,"tv":98699.23,"id":228749}],"tv":105619.97}]}
{"op":"mcm","clk":"AM/ssAkA8NqhCgC34aIK","pt":1657541357359,"mc":[{"id":"1.200806927","rc":[{"atl":[[11,0.78]],"id":2857977}]}]}
{"op":"mcm","clk":"AJTtsAkAr9uhCgDg4aIK","pt":1657541358102,"mc":[{"id":"1.200806927","rc":[{"atb":[[1.13,78.9]],"trd":[[1.13,3890.91]],"tv":98702.68,"id":228749}],"tv":105623.42}]}
{"op":"mcm","clk":"AM/tsAkA4NuhCgCD4qIK","pt":1657541358782,"mc":[{"id":"1.200806927","rc":[{"atb":[[1.11,553.31]],"id":228749}]}]}
{"op":"mcm","clk":"ALHvsAkAst2hCgDq4qIK","pt":1657541361181,"mc":[{"id":"1.200806927","rc":[{"atb":[[1.13,69.88]],"trd":[[1.13,3908.95]],"tv":98720.72,"id":228749}],"tv":105641.46}]}
{"op":"mcm","clk":"AMnvsAkAyt2hCgD14qIK","pt":1657541361486,"mc":[{"id":"1.200806927","rc":[{"atl":[[1.14,582.66]],"id":228749}]}]}
{"op":"mcm","clk":"AN3vsAkA492hCgCA46IK","pt":1657541361721,"mc":[{"id":"1.200806927","rc":[{"atb":[[1.13,59.36]],"trd":[[1.13,3929.99]],"tv":98741.76,"id":228749}],"tv":105662.5}]}
{"op":"mcm","clk":"AOLvsAkA7N2hCgCI46IK","pt":1657541361804,"mc":[{"id":"1.200806927","rc":[{"atl":[[1000,0.35]],"id":228749}]}]}
{"op":"mcm","clk":"AIfwsAkAjN6hCgCf46IK","pt":1657541362174,"mc":[{"id":"1.200806927","rc":[{"atl":[[1000,0.13]],"id":228749}]}]}
{"op":"mcm","clk":"AK3wsAkAvt6hCgC746IK","pt":1657541362695,"mc":[{"id":"1.200806927","rc":[{"atb":[[1.13,58.83]],"trd":[[1.13,3931.05]],"tv":98742.82,"id":228749}],"tv":105663.56}]}
{"op":"mcm","clk":"APXwsAkAmN+hCgDk46IK","pt":1657541363594,"mc":[{"id":"1.200806927","rc":[{"atl":[[1.14,580.41]],"id":228749}]}]}
{"op":"mcm","clk":"ANnxsAkA+t+hCgCl5KIK","pt":1657541364685,"mc":[{"id":"1.200806927","rc":[{"atb":[[1.13,54.1]],"trd":[[1.13,3940.51]],"tv":98752.28,"id":228749}],"tv":105673.02}]}
{"op":"mcm","clk":"ALzysAkA2+ChCgDe5KIK","pt":1657541365842,"mc":[{"id":"1.200806927","rc":[{"atb":[[1.13,52.46]],"trd":[[1.13,3943.79]],"tv":98755.56,"id":228749}],"tv":105676.3}]}
{"op":"mcm","clk":"AL3zsAkA0+GhCgCu5aIK","pt":1657541366997,"mc":[{"id":"1.200806927","rc":[{"atb":[[1.13,0]],"atl":[[1.13,0.13]],"trd":[[1.13,4048.71]],"tv":98860.48,"id":228749}],"tv":105781.22}]}
{"op":"mcm","clk":"AMvzsAkA5OGhCgC35aIK","pt":1657541367195,"mc":[{"id":"1.200806927","rc":[{"atb":[[8.2,5.26]],"id":2857977}]}]}
{"op":"mcm","clk":"ANPzsAkA7uGhCgC55aIK","pt":1657541367289,"mc":[{"id":"1.200806927","rc":[{"atl":[[1.13,0.36]],"id":228749}]}]}
{"op":"mcm","clk":"AJ30sAkAt+KhCgDp5aIK","pt":1657541367972,"mc":[{"id":"1.200806927","rc":[{"atl":[[1.13,0.13]],"id":228749}]}]}
{"op":"mcm","clk":"AMz1sAkA7eOhCgDT5qIK","pt":1657541369997,"mc":[{"id":"1.200806927","rc":[{"atl":[[1.13,4.5]],"id":228749}]}]}
{"op":"mcm","clk":"AIz2sAkAuuShCgD95qIK","pt":1657541370784,"mc":[{"id":"1.200806927","rc":[{"atl":[[1.13,3.69]],"trd":[[1.13,4049.52]],"tv":98861.29,"id":228749},{"trd":[[8.6,50]],"ltp":8.6,"tv":6920.85,"id":2857977}],"tv":105782.14}]}
{"op":"mcm","clk":"AJj2sAkAxeShCgCF56IK","pt":1657541370905,"mc":[{"id":"1.200806927","rc":[{"atl":[[1.13,29.99]],"id":228749}]}]}
{"op":"mcm","clk":"AKX2sAkA2eShCgCS56IK","pt":1657541371110,"mc":[{"id":"1.200806927","rc":[{"atl":[[11,0.43]],"id":2857977}]}]}
{"op":"mcm","clk":"ALf2sAkA6uShCgCc56IK","pt":1657541371319,"mc":[{"id":"1.200806927","rc":[{"atl":[[1.13,25.96]],"trd":[[1.13,4053.55]],"tv":98865.32,"id":228749},{"trd":[[8.6,50.53]],"tv":6921.38,"id":2857977}],"tv":105786.7}]}
{"op":"mcm","clk":"ALD3sAkA4uWhCgDZ56IK","pt":1657541372613,"mc":[{"id":"1.200806927","rc":[{"atl":[[1.13,24.64]],"trd":[[1.13,4054.87]],"tv":98866.64,"id":228749},{"trd":[[8.6,50.7]],"tv":6921.55,"id":2857977}],"tv":105788.19}]}
{"op":"mcm","clk":"ANX4sAkA7eehCgDW6KIK","pt":1657541375199,"mc":[{"id":"1.200806927","rc":[{"atl":[[1.13,27.27]],"id":228749}]}]}
{"op":"mcm","clk":"APf4sAkAneihCgDp6KIK","pt":1657541375721,"mc":[{"id":"1.200806927","rc":[{"atb":[[1.11,53.64]],"atl":[[1.13,27.8]],"id":228749}]}]}
{"op":"mcm","clk":"AIz6sAkAvOmhCgDG6aIK","pt":1657541377440,"mc":[{"id":"1.200806927","rc":[{"atb":[[1.12,33.45]],"trd":[[1.12,12723.03]],"ltp":1.12,"tv":98916.46,"id":228749}],"tv":105838.01}]}
{"op":"mcm","clk":"ALL6sAkA7OmhCgDd6aIK","pt":1657541377900,"mc":[{"id":"1.200806927","rc":[{"atl":[[1.14,585.67]],"id":228749}]}]}
{"op":"mcm","clk":"ALv7sAkAh+uhCgCf6qIK","pt":1657541379715,"mc":[{"id":"1.200806927","rc":[{"atb":[[1.1,0.11]],"id":228749}]}]}
{"op":"mcm","clk":"AMX7sAkAm+uhCgCm6qIK","pt":1657541379925,"mc":[{"id":"1.200806927","rc":[{"atl":[[1.13,25.17]],"id":228749}]}]}
{"op":"mcm","clk":"AOn7sAkAw+uhCgCx6qIK","pt":1657541380332,"mc":[{"id":"1.200806927","rc":[{"atb":[[1.13,19.91]],"atl":[[1.13,0]],"id":228749}]}]}
{"op":"mcm","clk":"AKb8sAkAleyhCgDR6qIK","pt":1657541381220,"mc":[{"id":"1.200806927","rc":[{"atb":[[1.13,0]],"atl":[[1.13,480.09],[1.14,580.41]],"trd":[[1.13,4094.69]],"ltp":1.13,"tv":98956.28,"id":228749}],"tv":105877.83}]}
{"op":"mcm","clk":"ALT8sAkAvOyhCgDe6qIK","pt":1657541381533,"mc":[{"id":"1.200806927","rc":[{"atl":[[1.13,980.09]],"id":228749}]}]}
{"op":"mcm","clk":"AMb8sAkA0+yhCgDo6qIK","pt":1657541381832,"mc":[{"id":"1.200806927","rc":[{"atl":[[1.13,1480.09]],"id":228749}]}]}
{"op":"mcm","clk":"ANb8sAkA5OyhCgDv6qIK","pt":1657541382050,"mc":[{"id":"1.200806927","rc":[{"atl":[[1.13,0]],"trd":[[1.13,4098.15]],"tv":98959.74,"id":228749}],"tv":105881.29}]}
{"op":"mcm","clk":"AOP8sAkA/uyhCgD56qIK","pt":1657541382342,"mc":[{"id":"1.200806927","rc":[{"atl":[[1.22,0]],"id":228749}]}]}
{"op":"mcm","clk":"AP78sAkArO2hCgCM66IK","pt":1657541382817,"mc":[{"id":"1.200806927","rc":[{"atl":[[1.14,579.88]],"id":228749}]}]}
{"op":"mcm","clk":"AJD9sAkAx+2hCgCT66IK","pt":1657541383033,"mc":[{"id":"1.200806927","rc":[{"atb":[[8.2,5.04]],"trd":[[8.2,0.97]],"ltp":8.2,"tv":6921.99,"id":2857977}],"tv":105881.73}]}
{"op":"mcm","clk":"ALb+sAkAue+hCgCY7KIK","pt":1657541385036,"mc":[{"id":"1.200806927","rc":[{"atb":[[1.13,5.26]],"id":228749}]}]}
{"op":"mcm","clk":"AM3+sAkA4u+hCgCt7KIK","pt":1657541385419,"mc":[{"id":"1.200806927","rc":[{"atb":[[1.13,8.87]],"id":228749}]}]}
{"op":"mcm","clk":"AOL+sAkA/++hCgDB7KIK","pt":1657541385734,"mc":[{"id":"1.200806927","rc":[{"atb":[[1.13,0],[1.12,0]],"atl":[[1.12,364.38]],"trd":[[1.13,4115.88],[1.12,12789.92]],"ltp":1.12,"tv":99044.36,"id":228749}],"tv":105966.35}]}
{"op":"mcm","clk":"AOz+sAkAmPChCgDM7KIK","pt":1657541385945,"mc":[{"id":"1.200806927","rc":[{"atl":[[11,0]],"id":2857977}]}]}
{"op":"mcm","clk":"AIr/sAkA1fChCgDk7KIK","pt":1657541386552,"mc":[{"id":"1.200806927","rc":[{"atl":[[1.12,358.54]],"trd":[[1.12,12801.6]],"tv":99056.04,"id":228749}],"tv":105978.03}]}
{"op":"mcm","clk":"ANX/sAkAwvGhCgCf7aIK","pt":1657541387733,"mc":[{"id":"1.200806927","rc":[{"atl":[[1.12,357.66]],"trd":[[1.12,12802.48]],"tv":99056.92,"id":228749},{"trd":[[9.2,1108.73]],"ltp":9.2,"tv":6922.1,"id":2857977}],"tv":105979.02}]}
{"op":"mcm","clk":"APD/sAkA6/GhCgCw7aIK","pt":1657541388131,"mc":[{"id":"1.200806927","rc":[{"atl":[[1.12,355.03]],"trd":[[1.12,12807.74]],"tv":99062.18,"id":228749}],"tv":105984.28}]}
{"op":"mcm","clk":"AJyAsQkAqPKhCgDT7aIK","pt":1657541388849,"mc":[{"id":"1.200806927","rc":[{"atb":[[1.01,2885.4]],"id":2857977}]}]}
{"op":"mcm","clk":"AKqAsQkAwfKhCgDj7aIK","pt":1657541389130,"mc":[{"id":"1.200806927","rc":[{"atb":[[1.1,0.74]],"id":228749}]}]}
{"op":"mcm","clk":"ALKAsQkAx/KhCgDo7aIK","pt":1657541389226,"mc":[{"id":"1.200806927","rc":[{"atl":[[1.12,357.66]],"id":228749}]}]}
{"op":"mcm","clk":"ALaAsQkA0fKhCgDq7aIK","pt":1657541389323,"mc":[{"id":"1.200806927","rc":[{"atl":[[1.12,378.7]],"id":228749}]}]}
{"op":"mcm","clk":"AL+AsQkA4/KhCgD07aIK","pt":1657541389530,"mc":[{"id":"1.200806927","rc":[{"atl":[[1.12,386.04]],"id":228749}]}]}
{"op":"mcm","clk":"AOqAsQkAofOhCgCV7qIK","pt":1657541390252,"mc":[{"id":"1.200806927","rc":[{"atl":[[1.14,400.34]],"id":228749}]}]}
{"op":"mcm","clk":"ALWBsQkAkvShCgDM7qIK","pt":1657541391361,"mc":[{"id":"1.200806927","rc":[{"atl":[[1.12,378.7]],"id":228749}]}]}
{"op":"mcm","clk":"ALiCsQkAh/ahCgC076IK","pt":1657541393649,"mc":[{"id":"1.200806927","rc":[{"atb":[[1.1,4.63]],"id":228749}]}]}
{"op":"mcm","clk":"ALSDsQkA5PehCgCi8KIK","pt":1657541395661,"mc":[{"id":"1.200806927","rc":[{"atl":[[1.13,45.08]],"id":228749}]}]}
{"op":"mcm","clk":"AOCDsQkAofihCgC98KIK","pt":1657541396252,"mc":[{"id":"1.200806927","rc":[{"atl":[[1.12,292.29]],"trd":[[1.12,12894.15]],"tv":99148.59,"id":228749},{"trd":[[9.2,1119.25]],"tv":6932.62,"id":2857977}],"tv":106081.21}]}
{"op":"mcm","clk":"AKGEsQkAgPmhCgDy8KIK","pt":1657541397266,"mc":[{"id":"1.200806927","rc":[{"atl":[[1.12,289.66]],"trd":[[1.12,12899.41]],"tv":99153.85,"id":228749}],"tv":106086.47}]}
{"op":"mcm","clk":"ANWEsQkA3/mhCgCj8aIK","pt":1657541398255,"mc":[{"id":"1.200806927","rc":[{"atb":[[1.11,1.05]],"id":228749}]}]}
{"op":"mcm","clk":"AN+EsQkA+fmhCgCv8aIK","pt":1657541398461,"mc":[{"id":"1.200806927","rc":[{"atl":[[1.12,285.31]],"trd":[[1.12,12903.77]],"tv":99158.21,"id":228749},{"trd":[[9.2,1119.78]],"tv":6933.15,"id":2857977}],"tv":106091.36}]}
{"op":"mcm","clk":"ALaFsQkA9vqhCgDs8aIK","pt":1657541399451,"mc":[{"id":"1.200806927","rc":[{"atl":[[1.12,274.79]],"trd":[[1.12,12924.81]],"tv":99179.25,"id":228749}],"tv":106112.4}]}
{"op":"mcm","clk":"AO2GsQkApf2hCgCd86IK","pt":1657541401066,"mc":[{"id":"1.200806927","rc":[{"atl":[[1000,0.25]],"id":228749}]}]}
{"op":"mcm","clk":"AIaHsQkAxP2hCgCx86IK","pt":1657541401471,"mc":[{"id":"1.200806927","rc":[{"atl":[[1000,0.13]],"id":228749}]}]}
{"op":"mcm","clk":"AI2IsQkAjf+hCgCt9KIK","pt":1657541402891,"mc":[{"id":"1.200806927","rc":[{"atl":[[1.12,248.49]],"trd":[[1.12,12977.41]],"tv":99231.85,"id":228749}],"tv":106165}]}
{"op":"mcm","clk":"AI+JsQkApYCiCgCG9aIK","pt":1657541404472,"mc":[{"id":"1.200806927","rc":[{"atl":[[10,0.35]],"id":2857977}]}]}
{"op":"mcm","clk":"AKqJsQkAx4CiCgCS9aIK","pt":1657541404764,"mc":[{"id":"1.200806927","rc":[{"atl":[[1.12,247.96]],"trd":[[1.12,12978.47]],"tv":99232.91,"id":228749}],"tv":106166.06}]}
{"op":"mcm","clk":"AL6JsQkA64CiCgCg9aIK","pt":1657541405078,"mc":[{"id":"1.200806927","rc":[{"atl":[[1.12,247.86]],"trd":[[1.12,12978.67]],"tv":99233.11,"id":228749}],"tv":106166.26}]}
{"op":"mcm","clk":"APeJsQkAx4GiCgDM9aIK","pt":1657541406065,"mc":[{"id":"1.200806927","rc":[{"atl":[[1.12,237.34]],"trd":[[1.12,12999.71]],"tv":99254.15,"id":228749}],"tv":106187.3}]}
{"op":"mcm","clk":"AIyKsQkA4oGiCgDX9aIK","pt":1657541406389,"mc":[{"id":"1.200806927","rc":[{"atl":[[1.12,217.87]],"trd":[[1.12,13019.18]],"tv":99273.62,"id":228749},{"trd":[[9.2,1122.15]],"tv":6935.52,"id":2857977}],"tv":106209.14}]}
{"op":"mcm","clk":"AJ2KsQkA/YGiCgDi9aIK","pt":1657541406588,"mc":[{"id":"1.200806927","rc":[{"atb":[[1.11,0.92]],"trd":[[1.11,17999.94]],"ltp":1.11,"tv":99273.88,"id":228749}],"tv":106209.4}]}
{"op":"mcm","clk":"AMKKsQkAwoKiCgD+9aIK","pt":1657541407160,"mc":[{"id":"1.200806927","rc":[{"atb":[[1.11,211.29]],"id":228749}]}]}
{"op":"mcm","clk":"AMqKsQkA1IKiCgCA9qIK","pt":1657541407315,"mc":[{"id":"1.200806927","rc":[{"atl":[[1.14,402.97]],"id":228749}]}]}
{"op":"mcm","clk":"AP6KsQkApoOiCgCo9qIK","pt":1657541408001,"mc":[{"id":"1.200806927","rc":[{"atl":[[11,0.53]],"id":2857977}]}]}
{"op":"mcm","clk":"APyMsQkAjIaiCgDo96IK","pt":1657541411595,"mc":[{"id":"1.200806927","rc":[{"atb":[[1.11,158.7]],"id":228749}]}]}
{"op":"mcm","clk":"AIiNsQkAooaiCgDx96IK","pt":1657541411787,"mc":[{"id":"1.200806927","rc":[{"atl":[[1.12,204.89]],"trd":[[1.12,13032.15]],"ltp":1.12,"tv":99286.85,"id":228749},{"trd":[[9.2,1123.73]],"tv":6937.1,"id":2857977}],"tv":106223.95}]}
{"op":"mcm","clk":"AJONsQkAuIaiCgD796IK","pt":1657541411996,"mc":[{"id":"1.200806927","rc":[{"atb":[[1.04,28.14]],"id":228749}]}]}
{"op":"mcm","clk":"AKqNsQkA5YaiCgCV+KIK","pt":1657541412380,"mc":[{"id":"1.200806927","rc":[{"atl":[[1.12,110.77]],"trd":[[1.12,13128.43]],"tv":99383.13,"id":228749},{"trd":[[9.2,1134.92]],"tv":6948.29,"id":2857977}],"tv":106331.42}]}
{"op":"mcm","clk":"AN6NsQkAqIeiCgC3+KIK","pt":1657541413111,"mc":[{"id":"1.200806927","rc":[{"atl":[[1.12,94.99]],"trd":[[1.12,13159.99]],"tv":99414.69,"id":228749}],"tv":106362.98}]}
{"op":"mcm","clk":"APqNsQkA1oeiCgDP+KIK","pt":1657541413507,"mc":[{"id":"1.200806927","rc":[{"atl":[[1.12,94.11]],"trd":[[1.12,13160.87]],"tv":99415.57,"id":228749},{"trd":[[9.2,1135.03]],"tv":6948.4,"id":2857977}],"tv":106363.97}]}
{"op":"mcm","clk":"ALqOsQkAoYiiCgDw+KIK","pt":1657541414386,"mc":[{"id":"1.200806927","rc":[{"atl":[[1.12,92.81]],"trd":[[1.12,13163.47]],"tv":99418.17,"id":228749}],"tv":106366.57}]}
{"op":"mcm","clk":"AMOOsQkAqoiiCgDy+KIK","pt":1657541414511,"mc":[{"id":"1.200806927","rc":[{"atl":[[1.12,91.93]],"trd":[[1.12,13164.35]],"tv":99419.05,"id":228749},{"trd":[[9.2,1135.14]],"tv":6948.51,"id":2857977}],"tv":106367.56}]}
{"op":"mcm","clk":"APqPsQkAuoqiCgCJ+qIK","pt":1657541417296,"mc":[{"id":"1.200806927","rc":[{"atb":[[1.11,156.6]],"id":228749}]}]}
{"op":"mcm","clk":"AIWQsQkAxIqiCgCM+qIK","pt":1657541417402,"mc":[{"id":"1.200806927","rc":[{"atb":[[1.04,28.31]],"atl":[[1.12,91.83]],"trd":[[1.12,13164.55]],"tv":99419.25,"id":228749}],"tv":106367.76}]}
{"op":"mcm","clk":"AIqQsQkAzoqiCgCS+qIK","pt":1657541417516,"mc":[{"id":"1.200806927","rc":[{"atl":[[1.14,102.97]],"id":228749}]}]}
{"op":"mcm","clk":"AKGQsQkA7YqiCgCp+qIK","pt":1657541417892,"mc":[{"id":"1.200806927","rc":[{"atb":[[1.04,28.14]],"atl":[[1.14,100.34]],"id":228749}]}]}
{"op":"mcm","clk":"AMiQsQkAnouiCgDI+qIK","pt":1657541418513,"mc":[{"id":"1.200806927","rc":[{"atb":[[1.11,145.75]],"trd":[[1.11,18021.64]],"ltp":1.11,"tv":99440.95,"id":228749}],"tv":106389.46}]}
{"op":"mcm","clk":"ALiRsQkAgoyiCgCP+6IK","pt":1657541419915,"mc":[{"id":"1.200806927","rc":[{"atl":[[1.12,84.75]],"trd":[[1.12,13171.63]],"ltp":1.12,"tv":99448.03,"id":228749},{"trd":[[9.2,1136]],"tv":6949.37,"id":2857977}],"tv":106397.4}]}
{"op":"mcm","clk":"AKySsQkAno2iCgDb+6IK","pt":1657541421396,"mc":[{"id":"1.200806927","rc":[{"atb":[[1.11,124.71]],"id":228749}]}]}
{"op":"mcm","clk":"ALiSsQkAqo2iCgDf+6IK","pt":1657541421493,"mc":[{"id":"1.200806927","rc":[{"atl":[[1.12,83.87]],"trd":[[1.12,13172.51]],"tv":99448.91,"id":228749},{"trd":[[9.2,1136.11]],"tv":6949.48,"id":2857977}],"tv":106398.39}]}
{"op":"mcm","clk":"AM2SsQkA1I2iCgDv+6IK","pt":1657541421899,"mc":[{"id":"1.200806927","rc":[{"atl":[[1.12,83.81]],"trd":[[1.12,13172.63]],"tv":99449.03,"id":228749}],"tv":106398.51}]}
{"op":"mcm","clk":"AIGTsQkAlY6iCgCJ/KIK","pt":1657541422616,"mc":[{"id":"1.200806927","rc":[{"atl":[[1.8,0]],"id":228749}]}]}
{"op":"mcm","clk":"AJmTsQkAvY6iCgCg/KIK","pt":1657541422999,"mc":[{"id":"1.200806927","rc":[{"atl":[[1.12,83.65]],"trd":[[1.12,13172.96]],"tv":99449.36,"id":228749}],"tv":106398.84}]}
{"op":"mcm","clk":"ALiTsQkA246iCgCr/KIK","pt":1657541423323,"mc":[{"id":"1.200806927","rc":[{"atl":[[1.12,82.7]],"trd":[[1.12,13174.86]],"tv":99451.26,"id":228749}],"tv":106400.74}]}
{"op":"mcm","clk":"AMCTsQkA4o6iCgCt/KIK","pt":1657541423406,"mc":[{"id":"1.200806927","rc":[{"atb":[[1.04,27.3]],"id":228749}]}]}
{"op":"mcm","clk":"AM+TsQkAgY+iCgCy/KIK","pt":1657541423611,"mc":[{"id":"1.200806927","rc":[{"atl":[[1.2,13.48]],"id":228749}]}]}
{"op":"mcm","clk":"AI2UsQkA4I+iCgDd/KIK","pt":1657541424519,"mc":[{"id":"1.200806927","rc":[{"atb":[[1.1,4]],"id":228749}]}]}
{"op":"mcm","clk":"APyUsQkA/JCiCgCc/aIK","pt":1657541426117,"mc":[{"id":"1.200806927","rc":[{"atl":[[14,5.26]],"id":2857977}]}]}
{"op":"mcm","clk":"AKCVsQkAtpGiCgC1/aIK","pt":1657541426733,"mc":[{"id":"1.200806927","rc":[{"atl":[[1.12,81.85]],"trd":[[1.12,13176.55]],"tv":99452.95,"id":228749}],"tv":106402.43}]}
{"op":"mcm","clk":"AJ6WsQkAi5OiCgCV/qIK","pt":1657541429035,"mc":[{"id":"1.200806927","rc":[{"atl":[[1.12,79.22]],"trd":[[1.12,13181.81]],"tv":99458.21,"id":228749}],"tv":106407.69}]}
{"op":"mcm","clk":"APSXsQkAgZaiCgDY/6IK","pt":1657541432775,"mc":[{"id":"1.200806927","rc":[{"atl":[[1000,0.39]],"id":228749}]}]}
{"op":"mcm","clk":"APiXsQkAjpaiCgDf/6IK","pt":1657541432903,"mc":[{"id":"1.200806927","rc":[{"atl":[[1000,0.13]],"id":228749}]}]}
{"op":"mcm","clk":"AMqYsQkAhJeiCgCbgKMK","pt":1657541434023,"mc":[{"id":"1.200806927","rc":[{"atl":[[1.12,64.43]],"trd":[[1.12,13196.6]],"tv":99473,"id":228749},{"trd":[[9.2,1137.91]],"tv":6951.28,"id":2857977}],"tv":106424.28}]}
{"op":"mcm","clk":"ANiYsQkAopeiCgCngKMK","pt":1657541434222,"mc":[{"id":"1.200806927","rc":[{"atl":[[1.15,1352.43],[1.12,63.9]],"trd":[[1.12,13197.66]],"tv":99474.06,"id":228749}],"tv":106425.34}]}
{"op":"mcm","clk":"AImZsQkA7ZeiCgDIgKMK","pt":1657541434946,"mc":[{"id":"1.200806927","rc":[{"atl":[[1.12,63.03]],"trd":[[1.12,13198.53]],"tv":99474.93,"id":228749},{"trd":[[9.2,1138.01]],"tv":6951.38,"id":2857977}],"tv":106426.31}]}
{"op":"mcm","clk":"AOiasQkApZqiCgDXgaMK","pt":1657541438039,"mc":[{"id":"1.200806927","rc":[{"atb":[[1.11,124.44]],"trd":[[1.11,18022.18]],"ltp":1.11,"tv":99475.47,"id":228749}],"tv":106426.85}]}
{"op":"mcm","clk":"AM6bsQkArpuiCgClgqMK","pt":1657541439552,"mc":[{"id":"1.200806927","rc":[{"atb":[[1.11,123.68]],"trd":[[1.11,18023.7]],"tv":99476.99,"id":228749}],"tv":106428.37}]}
{"op":"mcm","clk":"ANabsQkAu5uiCgCrgqMK","pt":1657541439665,"mc":[{"id":"1.200806927","rc":[{"atl":[[1.12,61.26]],"trd":[[1.12,13200.31]],"ltp":1.12,"tv":99478.77,"id":228749},{"trd":[[9.2,1138.23]],"tv":6951.6,"id":2857977}],"tv":106430.37}]}
{"op":"mcm","clk":"ANmbsQkAx5uiCgCugqMK","pt":1657541439721,"mc":[{"id":"1.200806927","rc":[{"atl":[[1.12,61.13]],"trd":[[1.12,13200.56]],"tv":99479.02,"id":228749}],"tv":106430.62}]}
{"op":"mcm","clk":"AOSbsQkA3JuiCgCzgqMK","pt":1657541439930,"mc":[{"id":"1.200806927","rc":[{"atl":[[1.12,34.83]],"trd":[[1.12,13253.16]],"tv":99531.62,"id":228749}],"tv":106483.22}]}
{"op":"mcm","clk":"AN6csQkAvJ2iCgCQg6MK","pt":1657541442038,"mc":[{"id":"1.200806927","rc":[{"atb":[[1.11,115.49]],"trd":[[1.11,18040.08]],"ltp":1.11,"tv":99548,"id":228749}],"tv":106499.6}]}
{"op":"mcm","clk":"AKKdsQkAo56iCgC+g6MK","pt":1657541443032,"mc":[{"id":"1.200806927","rc":[{"atl":[[1.12,34.3]],"trd":[[1.12,13254.22]],"ltp":1.12,"tv":99549.06,"id":228749}],"tv":106500.66}]}
{"op":"mcm","clk":"AL2dsQkAyJ6iCgDIg6MK","pt":1657541443431,"mc":[{"id":"1.200806927","rc":[{"atb":[[1.03,88.23]],"id":228749}]}]}
{"op":"mcm","clk":"AJmesQkAxJ+iCgCChKMK","pt":1657541444930,"mc":[{"id":"1.200806927","rc":[{"atb":[[1.11,114.37]],"atl":[[1.12,33.42]],"trd":[[1.11,18042.32],[1.12,13255.1]],"ltp":1.11,"tv":99552.18,"id":228749},{"trd":[[9.2,1138.34]],"tv":6951.71,"id":2857977}],"tv":106503.89}]}
{"op":"mcm","clk":"AMiesQkA/5+iCgCmhKMK","pt":1657541445674,"mc":[{"id":"1.200806927","rc":[{"atl":[[1.12,32.89]],"trd":[[1.12,13256.16]],"ltp":1.12,"tv":99553.24,"id":228749}],"tv":106504.95}]}
{"op":"mcm","clk":"ANeesQkAk6CiCgCuhKMK","pt":1657541445847,"mc":[{"id":"1.200806927","rc":[{"atl":[[14,6.31]],"id":2857977}]}]}
{"op":"mcm","clk":"AOSesQkAp6CiCgC8hKMK","pt":1657541446096,"mc":[{"id":"1.200806927","rc":[{"atl":[[1.12,30.26]],"trd":[[1.12,13261.42]],"tv":99558.5,"id":228749}],"tv":106510.21}]}
{"op":"mcm","clk":"AKCfsQkA8qCiCgDfhKMK","pt":1657541446766,"mc":[{"id":"1.200806927","rc":[{"atl":[[1.14,52.59]],"id":228749}]}]}
{"op":"mcm","clk":"AIOgsQkAhqKiCgCvhaMK","pt":1657541448371,"mc":[{"id":"1.200806927","rc":[{"atb":[[1.11,1041.96]],"id":228749}]}]}
{"op":"mcm","clk":"AJ+gsQkAsaKiCgDMhaMK","pt":1657541448855,"mc":[{"id":"1.200806927","rc":[{"atb":[[1.03,88.54]],"id":228749}]}]}
{"op":"mcm","clk":"AMCgsQkA4KKiCgDbhaMK","pt":1657541449358,"mc":[{"id":"1.200806927","rc":[{"atb":[[1.03,88.23]],"id":228749}]}]}
{"op":"mcm","clk":"AO6gsQkAlaOiCgDwhaMK","pt":1657541449982,"mc":[{"id":"1.200806927","rc":[{"atl":[[1.12,28.95]],"trd":[[1.12,13264.04]],"tv":99561.12,"id":228749}],"tv":106512.83}]}
{"op":"mcm","clk":"ANSisQkA6aWiCgCMh6MK","pt":1657541453365,"mc":[{"id":"1.200806927","rc":[{"atb":[[1.11,1041.88]],"trd":[[1.11,18042.48]],"ltp":1.11,"tv":99561.28,"id":228749}],"tv":106512.99}]}
{"op":"mcm","clk":"APOisQkAlKaiCgCdh6MK","pt":1657541453785,"mc":[{"id":"1.200806927","rc":[{"atl":[[1.15,0]],"id":228749}]}]}
{"op":"mcm","clk":"AI2jsQkAzqaiCgDIh6MK","pt":1657541454372,"mc":[{"id":"1.200806927","rc":[{"atb":[[1.11,1039.25]],"id":228749}]}]}
{"op":"mcm","clk":"AJOjsQkA1qaiCgDRh6MK","pt":1657541454472,"mc":[{"id":"1.200806927","rc":[{"atl":[[1.12,28.64]],"trd":[[1.12,13264.66]],"ltp":1.12,"tv":99561.9,"id":228749}],"tv":106513.61}]}
{"op":"mcm","clk":"AKyjsQkA+6aiCgDkh6MK","pt":1657541454893,"mc":[{"id":"1.200806927","rc":[{"atb":[[1.03,87.39]],"id":228749}]}]}
{"op":"mcm","clk":"ALGjsQkAiKeiCgDph6MK","pt":1657541454985,"mc":[{"id":"1.200806927","rc":[{"atl":[[1.12,27.77]],"trd":[[1.12,13265.54]],"tv":99562.78,"id":228749},{"trd":[[9.2,1138.44]],"tv":6951.81,"id":2857977}],"tv":106514.59}]}
{"op":"mcm","clk":"AIiksQkAoqiiCgCriKMK","pt":1657541456505,"mc":[{"id":"1.200806927","rc":[{"atb":[[8.2,0]],"id":2857977}]}]}
{"op":"mcm","clk":"AJeksQkAuaiiCgCyiKMK","pt":1657541456718,"mc":[{"id":"1.200806927","rc":[{"atl":[[1.12,27.24]],"trd":[[1.12,13266.59]],"tv":99563.83,"id":228749}],"tv":106515.64}]}
{"op":"mcm","clk":"AMGksQkAkamiCgDRiKMK","pt":1657541457485,"mc":[{"id":"1.200806927","rc":[{"atl":[[1.12,21.98]],"trd":[[1.12,13273.73]],"tv":99570.97,"id":228749}],"tv":106522.78}]}
{"op":"mcm","clk":"ANWksQkAuamiCgDkiKMK","pt":1657541457902,"mc":[{"id":"1.200806927","rc":[{"atb":[[1.1,4.68]],"id":228749}]}]}
{"op":"mcm","clk":"ANuksQkAxamiCgDpiKMK","pt":1657541458022,"mc":[{"id":"1.200806927","rc":[{"atl":[[14,1.05]],"id":2857977}]}]}
{"op":"mcm","clk":"ANqmsQkAt6yiCgCXiqMK","pt":1657541461601,"mc":[{"id":"1.200806927","rc":[{"atl":[[1.12,19.35]],"id":228749}]}]}
{"op":"mcm","clk":"AOqmsQkAy6yiCgCiiqMK","pt":1657541461798,"mc":[{"id":"1.200806927","rc":[{"atb":[[1.12,33.24]],"atl":[[1.12,0]],"id":228749}]}]}
{"op":"mcm","clk":"AJCnsQkA+6yiCgCxiqMK","pt":1657541462187,"mc":[{"id":"1.200806927","rc":[{"atb":[[1.12,27.98]],"id":228749}]}]}
{"op":"mcm","clk":"AL+psQkAoLCiCgD/i6MK","pt":1657541466574,"mc":[{"id":"1.200806927","rc":[{"atl":[[9.2,0.22]],"id":2857977}]}]}
{"op":"mcm","clk":"AJWqsQkAjLGiCgC5jKMK","pt":1657541467611,"mc":[{"id":"1.200806927","rc":[{"atb":[[1.11,1021.25],[1.12,0]],"trd":[[1.12,13275.5]],"tv":99572.74,"id":228749},{"atl":[[9.2,0]],"trd":[[9.2,1138.66]],"tv":6952.03,"id":2857977}],"tv":106524.77}]}
{"op":"mcm","clk":"AJmqsQkAl7GiCgC8jKMK","pt":1657541467688,"mc":[{"id":"1.200806927","rc":[{"atb":[[1.11,1018.62]],"id":228749}]}]}
{"op":"mcm","clk":"APqqsQkAnbKiCgD8jKMK","pt":1657541469099,"mc":[{"id":"1.200806927","rc":[{"atl":[[1.13,97.67]],"id":228749}]}]}
{"op":"mcm","clk":"AKWrsQkA3rKiCgCXjaMK","pt":1657541469819,"mc":[{"id":"1.200806927","rc":[{"atl":[[9.2,0.43]],"id":2857977}]}]}
{"op":"mcm","clk":"ANGrsQkAnbOiCgCyjaMK","pt":1657541470499,"mc":[{"id":"1.200806927","rc":[{"atl":[[9.2,0.65]],"id":2857977}]}]}
{"op":"mcm","clk":"APassQkA8rSiCgCPjqMK","pt":1657541472539,"mc":[{"id":"1.200806927","rc":[{"atb":[[1.12,23.66]],"id":228749}]}]}
{"op":"mcm","clk":"APatsQkAjLaiCgDYjqMK","pt":1657541474130,"mc":[{"id":"1.200806927","rc":[{"atl":[[1.14,0]],"id":228749}]}]}
{"op":"mcm","clk":"AP6tsQkAlbaiCgDcjqMK","pt":1657541474205,"mc":[{"id":"1.200806927","rc":[{"atb":[[7,0.86]],"id":2857977}]}]}
{"op":"mcm","clk":"AJyvsQkA7reiCgDWj6MK","pt":1657541476433,"mc":[{"id":"1.200806927","rc":[{"atb":[[1.12,0]],"atl":[[1.12,11.01]],"trd":[[1.12,13328.14]],"tv":99625.38,"id":228749},{"atl":[[9.2,0]],"trd":[[9.2,1139.3]],"tv":6952.67,"id":2857977}],"tv":106578.05}]}
{"op":"mcm","clk":"AKqvsQkAgLiiCgDcj6MK","pt":1657541476621,"mc":[{"id":"1.200806927","rc":[{"atl":[[1.12,11.54]],"id":228749}]}]}
{"op":"mcm","clk":"ALWwsQkA4bmiCgCwkKMK","pt":1657541478598,"mc":[{"id":"1.200806927","rc":[{"atl":[[1.12,1634.47]],"id":228749}]}]}
{"op":"mcm","clk":"AIyxsQkA2LqiCgDzkKMK","pt":1657541479830,"mc":[{"id":"1.200806927","rc":[{"atl":[[1.12,1631.84]],"trd":[[1.12,13333.4]],"tv":99630.64,"id":228749}],"tv":106583.31}]}
{"op":"mcm","clk":"AJSysQkAnryiCgDTkaMK","pt":1657541481630,"mc":[{"id":"1.200806927","rc":[{"atl":[[1.13,99.25]],"id":228749}]}]}
{"op":"mcm","clk":"AJqysQkApLyiCgDYkaMK","pt":1657541481738,"mc":[{"id":"1.200806927","rc":[{"atb":[[9.4,1.29]],"id":2857977}]}]}
{"op":"mcm","clk":"ANaysQkA97yiCgCDkqMK","pt":1657541482600,"mc":[{"id":"1.200806927","rc":[{"atl":[[1.12,1633.42]],"id":228749}]}]}
{"op":"mcm","clk":"AJG0sQkAk7+iCgCOk6MK","pt":1657541485641,"mc":[{"id":"1.200806927","rc":[{"atb":[[9.4,1.19]],"trd":[[9.4,19.25]],"ltp":9.4,"tv":6952.87,"id":2857977}],"tv":106583.51}]}
{"op":"mcm","clk":"APm0sQkAncCiCgDQk6MK","pt":1657541487345,"mc":[{"id":"1.200806927","rc":[{"atl":[[1.12,1631.84]],"id":228749}]}]}
{"op":"mcm","clk":"ALS1sQkAgcGiCgD7k6MK","pt":1657541488257,"mc":[{"id":"1.200806927","rc":[{"atl":[[1.13,97.67]],"id":228749}]}]}
{"op":"mcm","clk":"APS1sQkA5MGiCgColKMK","pt":1657541489470,"mc":[{"id":"1.200806927","rc":[{"atl":[[1000,0.32]],"id":228749}]}]}
{"op":"mcm","clk":"AIe2sQkAhcKiCgC1lKMK","pt":1657541489752,"mc":[{"id":"1.200806927","rc":[{"atl":[[1.12,1631.05]],"trd":[[1.12,13334.98]],"tv":99632.22,"id":228749}],"tv":106585.09}]}
{"op":"mcm","clk":"AI62sQkAkcKiCgC2lKMK","pt":1657541489853,"mc":[{"id":"1.200806927","rc":[{"atl":[[1000,0.13]],"id":228749}]}]}
{"op":"mcm","clk":"AKu2sQkAvMKiCgDKlKMK","pt":1657541490269,"mc":[{"id":"1.200806927","rc":[{"atb":[[9.4,0]],"id":2857977}]}]}
{"op":"mcm","clk":"AMW2sQkA4MKiCgDZlKMK","pt":1657541490654,"mc":[{"id":"1.200806927","rc":[{"atl":[[1.12,1630.52]],"id":228749}]}]}
{"op":"mcm","clk":"AJK3sQkA/cOiCgCSlaMK","pt":1657541492146,"mc":[{"id":"1.200806927","rc":[{"atl":[[1.12,1628.27]],"trd":[[1.12,13339.47]],"tv":99636.71,"id":228749}],"tv":106589.58}]}
{"op":"mcm","clk":"ALK3sQkAs8SiCgCplaMK","pt":1657541492659,"mc":[{"id":"1.200806927","rc":[{"atl":[[1.12,1615.12]],"trd":[[1.12,13350.16]],"tv":99647.4,"id":228749}],"tv":106600.27}]}
{"op":"mcm","clk":"AMu4sQkAg8aiCgCVlqMK","pt":1657541494755,"mc":[{"id":"1.200806927","rc":[{"atl":[[1.12,1614.59]],"id":228749}]}]}
{"op":"mcm","clk":"ANm4sQkAksaiCgCelqMK","pt":1657541494955,"mc":[{"id":"1.200806927","rc":[{"atb":[[1.11,1018.43]],"trd":[[1.11,18042.87]],"ltp":1.11,"tv":99647.79,"id":228749}],"tv":106600.66}]}
{"op":"mcm","clk":"AOG4sQkAocaiCgChlqMK","pt":1657541495058,"mc":[{"id":"1.200806927","rc":[{"atl":[[1.12,1613.01]],"id":228749}]}]}
{"op":"mcm","clk":"AJ65sQkAiseiCgDUlqMK","pt":1657541496056,"mc":[{"id":"1.200806927","rc":[{"atl":[[1.12,1613.54]],"id":228749}]}]}
{"op":"mcm","clk":"ALq5sQkAtMeiCgDtlqMK","pt":1657541496478,"mc":[{"id":"1.200806927","rc":[{"atl":[[1.12,1600.56]],"trd":[[1.12,13363.14]],"ltp":1.12,"tv":99660.77,"id":228749},{"trd":[[9.2,1140.88]],"ltp":9.2,"tv":6954.45,"id":2857977}],"tv":106615.22}]}
{"op":"mcm","clk":"AL65sQkAwceiCgDylqMK","pt":1657541496541,"mc":[{"id":"1.200806927","rc":[{"atl":[[1.12,1599.51]],"id":228749}]}]}
{"op":"mcm","clk":"AMm5sQkA28eiCgD9lqMK","pt":1657541496756,"mc":[{"id":"1.200806927","rc":[{"atl":[[1.12,1597.96]],"id":228749}]}]}
{"op":"mcm","clk":"APm5sQkAqMiiCgCel6MK","pt":1657541497477,"mc":[{"id":"1.200806927","rc":[{"atl":[[1.12,1597.14]],"trd":[[1.12,13363.96]],"tv":99661.59,"id":228749},{"trd":[[9.2,1140.98]],"tv":6954.55,"id":2857977}],"tv":106616.14}]}
{"op":"mcm","clk":"ANS7sQkAyMqiCgCImKMK","pt":1657541500365,"mc":[{"id":"1.200806927","rc":[{"atb":[[1.03,88.23]],"id":228749}]}]}
{"op":"mcm","clk":"AIe9sQkA5cyiCgCImaMK","pt":1657541503059,"mc":[{"id":"1.200806927","rc":[{"atl":[[1.12,1596.32]],"trd":[[1.12,13364.78]],"tv":99662.41,"id":228749},{"trd":[[9.2,1141.08]],"tv":6954.65,"id":2857977}],"tv":106617.06}]}
{"op":"mcm","clk":"AP69sQkAo86iCgDgmaMK","pt":1657541504971,"mc":[{"id":"1.200806927","rc":[{"atl":[[1.12,1595.5]],"trd":[[1.12,13365.6]],"tv":99663.23,"id":228749},{"trd":[[9.2,1141.18]],"tv":6954.75,"id":2857977}],"tv":106617.98}]}
{"op":"mcm","clk":"AJC+sQkAv86iCgDrmaMK","pt":1657541505191,"mc":[{"id":"1.200806927","rc":[{"atb":[[1.11,1016.85]],"atl":[[1.12,1592.87]],"id":228749}]}]}
{"op":"mcm","clk":"AKy+sQkA686iCgD6maMK","pt":1657541505600,"mc":[{"id":"1.200806927","rc":[{"atl":[[1.12,1591.87]],"trd":[[1.12,13367.6]],"tv":99665.23,"id":228749}],"tv":106619.98}]}
{"op":"mcm","clk":"AMC+sQkA+86iCgCGmqMK","pt":1657541505767,"mc":[{"id":"1.200806927","rc":[{"atb":[[1.03,88.47]],"id":228749}]}]}
{"op":"mcm","clk":"AOO+sQkAoc+iCgCamqMK","pt":1657541506172,"mc":[{"id":"1.200806927","rc":[{"atb":[[1.03,88.23]],"id":228749}]}]}
{"op":"mcm","clk":"ALC/sQkAkNCiCgDUmqMK","pt":1657541507370,"mc":[{"id":"1.200806927","rc":[{"atl":[[1.12,1586.61]],"id":228749}]}]}
{"op":"mcm","clk":"AI/AsQkAn9GiCgCXm6MK","pt":1657541508789,"mc":[{"id":"1.200806927","rc":[{"atl":[[1.12,1570.83]],"id":228749}]}]}
{"op":"mcm","clk":"AMbAsQkA6tGiCgC2m6MK","pt":1657541509581,"mc":[{"id":"1.200806927","rc":[{"atb":[[1.11,1016.75]],"trd":[[1.11,18043.07]],"ltp":1.11,"tv":99665.43,"id":228749}],"tv":106620.18}]}
{"op":"mcm","clk":"APDAsQkAnNKiCgDPm6MK","pt":1657541510095,"mc":[{"id":"1.200806927","rc":[{"atl":[[1.12,1569.19]],"trd":[[1.12,13369.24]],"ltp":1.12,"tv":99667.07,"id":228749},{"trd":[[9.2,1141.38]],"tv":6954.95,"id":2857977}],"tv":106622.02}]}
{"op":"mcm","clk":"AJzBsQkA5NKiCgD2m6MK","pt":1657541510874,"mc":[{"id":"1.200806927","rc":[{"atl":[[1.12,1568.11]],"id":228749}]}]}
{"op":"mcm","clk":"ALzBsQkAiNOiCgCPnKMK","pt":1657541511296,"mc":[{"id":"1.200806927","rc":[{"atl":[[1.12,1567.87]],"trd":[[1.12,13369.72]],"tv":99667.55,"id":228749}],"tv":106622.5}]}
{"op":"mcm","clk":"ANPBsQkArNOiCgClnKMK","pt":1657541511704,"mc":[{"id":"1.200806927","rc":[{"atb":[[1.03,87.39]],"id":228749}]}]}
{"op":"mcm","clk":"ANzBsQkAt9OiCgCpnKMK","pt":1657541511799,"mc":[{"id":"1.200806927","rc":[{"atl":[[1.13,100.3]],"id":228749}]}]}
{"op":"mcm","clk":"APzBsQkA7tOiCgDDnKMK","pt":1657541512281,"mc":[{"id":"1.200806927","rc":[{"atl":[[1.12,1567.77]],"trd":[[1.12,13369.92]],"tv":99667.75,"id":228749}],"tv":106622.7}]}
{"op":"mcm","clk":"AIHDsQkAltWiCgCNnaMK","pt":1657541513999,"mc":[{"id":"1.200806927","rc":[{"atl":[[1.12,1567.67]],"trd":[[1.12,13370.12]],"tv":99667.95,"id":228749}],"tv":106622.9}]}
{"op":"mcm","clk":"AK7DsQkA2NWiCgCmnaMK","pt":1657541514607,"mc":[{"id":"1.200806927","rc":[{"atl":[[1.12,1558.48]],"trd":[[1.12,13377.21]],"tv":99675.04,"id":228749},{"trd":[[9.2,1142.25]],"tv":6955.82,"id":2857977}],"tv":106630.86}]}
{"op":"mcm","clk":"AO7DsQkAttaiCgDWnaMK","pt":1657541515504,"mc":[{"id":"1.200806927","rc":[{"atb":[[1.11,1016.22]],"id":228749},{"atl":[[11,0.97]],"id":2857977}]}]}
{"op":"mcm","clk":"AK/EsQkAodeiCgCCnqMK","pt":1657541516500,"mc":[{"id":"1.200806927","rc":[{"atl":[[1.12,1505.89]],"id":228749}]}]}
{"op":"mcm","clk":"AInFsQkAzNiiCgDDnqMK","pt":1657541517915,"mc":[{"id":"1.200806927","rc":[{"atl":[[1.12,1503.26]],"id":228749}]}]}
{"op":"mcm","clk":"ALnFsQkAldmiCgDpnqMK","pt":1657541518488,"mc":[{"id":"1.200806927","rc":[{"atl":[[1.12,1502.73]],"id":228749}]}]}
{"op":"mcm","clk":"ANnFsQkAtNmiCgD5nqMK","pt":1657541518813,"mc":[{"id":"1.200806927","rc":[{"atl":[[11,1.08]],"id":2857977}]}]}
{"op":"mcm","clk":"AK3IsQkAj92iCgDAoKMK","pt":1657541522951,"mc":[{"id":"1.200806927","rc":[{"atl":[[1.12,1500.27]],"trd":[[1.12,13379.67]],"tv":99677.5,"id":228749},{"trd":[[9.2,1142.55]],"tv":6956.12,"id":2857977}],"tv":106633.62}]}
{"op":"mcm","clk":"AOPIsQkA2t2iCgDpoKMK","pt":1657541523541,"mc":[{"id":"1.200806927","rc":[{"atb":[[1.11,1015.7]],"id":228749}]}]}
{"op":"mcm","clk":"ALbJsQkA1d6iCgCuoaMK","pt":1657541524588,"mc":[{"id":"1.200806927","rc":[{"atl":[[1000,0.39]],"id":228749}]}]}
{"op":"mcm","clk":"ANXJsQkAhd+iCgC7oaMK","pt":1657541524999,"mc":[{"id":"1.200806927","rc":[{"atl":[[1000,0.13],[1.12,1499.39]],"trd":[[1.12,13380.55]],"tv":99678.38,"id":228749},{"trd":[[9.2,1142.65]],"tv":6956.22,"id":2857977}],"tv":106634.6}]}
{"op":"mcm","clk":"ALXMsQkAjuOiCgCPo6MK","pt":1657541529610,"mc":[{"id":"1.200806927","rc":[{"atl":[[1.12,1494.13]],"id":228749}]}]}
{"op":"mcm","clk":"ANTMsQkAyeOiCgCio6MK","pt":1657541530080,"mc":[{"id":"1.200806927","rc":[{"atb":[[1.11,1015.43]],"trd":[[1.11,18043.61]],"ltp":1.11,"tv":99678.92,"id":228749}],"tv":106635.14}]}
{"op":"mcm","clk":"APXMsQkAgOSiCgC4o6MK","pt":1657541530603,"mc":[{"id":"1.200806927","rc":[{"atl":[[1.12,1492.55]],"id":228749}]}]}
{"op":"mcm","clk":"ALjOsQkAseaiCgDBpKMK","pt":1657541533610,"mc":[{"id":"1.200806927","rc":[{"atl":[[1.12,1489.96]],"id":228749}]}]}
{"op":"mcm","clk":"AP3OsQkAmeeiCgDmpKMK","pt":1657541534505,"mc":[{"id":"1.200806927","rc":[{"atl":[[1.12,1474.18]],"id":228749}]}]}
{"op":"mcm","clk":"AK7PsQkA8+eiCgCRpaMK","pt":1657541535217,"mc":[{"id":"1.200806927","rc":[{"atl":[[1.12,1389.6]],"trd":[[1.12,13465.13]],"ltp":1.12,"tv":99763.5,"id":228749},{"trd":[[9.2,1152.95]],"tv":6966.52,"id":2857977}],"tv":106730.02}]}
{"op":"mcm","clk":"ALTPsQkA/+eiCgCYpaMK","pt":1657541535317,"mc":[{"id":"1.200806927","rc":[{"atl":[[1.12,1389.2]],"trd":[[1.12,13465.93]],"tv":99764.3,"id":228749}],"tv":106730.82}]}
{"op":"mcm","clk":"AMbPsQkAmOiiCgCgpaMK","pt":1657541535526,"mc":[{"id":"1.200806927","rc":[{"atb":[[1.03,88.23]],"id":228749}]}]}
{"op":"mcm","clk":"AIbRsQkAqeqiCgCWpqMK","pt":1657541538095,"mc":[{"id":"1.200806927","rc":[{"atl":[[1.12,1388.32]],"trd":[[1.12,13466.81]],"tv":99765.18,"id":228749},{"trd":[[9.2,1153.06]],"tv":6966.63,"id":2857977}],"tv":106731.81}]}
{"op":"mcm","clk":"AInTsQkA/eyiCgCIp6MK","pt":1657541541120,"mc":[{"id":"1.200806927","rc":[{"atb":[[1.03,88.54]],"id":228749}]}]}
{"op":"mcm","clk":"AK/TsQkAt+2iCgDMp6MK","pt":1657541541551,"mc":[{"id":"1.200806927","rc":[{"atb":[[1.03,88.23]],"id":228749}]}]}
{"op":"mcm","clk":"AP7TsQkAm+6iCgD2p6MK","pt":1657541542424,"mc":[{"id":"1.200806927","rc":[{"atl":[[1.12,1386.32]],"trd":[[1.12,13470.81]],"tv":99769.18,"id":228749}],"tv":106735.81}]}
{"op":"mcm","clk":"AO7WsQkA2fGiCgD4qaMK","pt":1657541546609,"mc":[{"id":"1.200806927","rc":[{"atl":[[1.12,1385.16]],"trd":[[1.12,13473.13]],"tv":99771.5,"id":228749}],"tv":106738.13}]}
{"op":"mcm","clk":"AI7XsQkAhPKiCgCHqqMK","pt":1657541547032,"mc":[{"id":"1.200806927","rc":[{"atb":[[1.03,87.39]],"id":228749}]}]}
{"op":"mcm","clk":"AMnXsQkAxfKiCgCrqqMK","pt":1657541547711,"mc":[{"id":"1.200806927","rc":[{"atl":[[1.12,1383.04]],"trd":[[1.12,13475.25]],"tv":99773.62,"id":228749},{"trd":[[9.2,1153.32]],"tv":6966.89,"id":2857977}],"tv":106740.51}]}
{"op":"mcm","clk":"ALfYsQkA6fOiCgD9qqMK","pt":1657541549228,"mc":[{"id":"1.200806927","rc":[{"atl":[[1.12,1380.93]],"trd":[[1.12,13477.36]],"tv":99775.73,"id":228749},{"trd":[[9.2,1153.57]],"tv":6967.14,"id":2857977}],"tv":106742.87}]}
{"op":"mcm","clk":"AJjasQkAuPaiCgCarKMK","pt":1657541552310,"mc":[{"id":"1.200806927","rc":[{"atl":[[1.12,1354.63]],"id":228749}]}]}
{"op":"mcm","clk":"AJ3asQkAxPaiCgCirKMK","pt":1657541552407,"mc":[{"id":"1.200806927","rc":[{"atl":[[1.12,1349.37]],"id":228749}]}]}
{"op":"mcm","clk":"AOHasQkAmPeiCgDZrKMK","pt":1657541553208,"mc":[{"id":"1.200806927","rc":[{"atl":[[1.12,1346.74]],"id":228749}]}]}
{"op":"mcm","clk":"APHasQkAsfeiCgDjrKMK","pt":1657541553422,"mc":[{"id":"1.200806927","rc":[{"atl":[[1.12,1345.44]],"id":228749}]}]}
{"op":"mcm","clk":"ALjbsQkA9veiCgCPraMK","pt":1657541554114,"mc":[{"id":"1.200806927","rc":[{"atb":[[1.11,1011.33]],"trd":[[1.11,18051.8]],"ltp":1.11,"tv":99783.92,"id":228749}],"tv":106751.06}]}
{"op":"mcm","clk":"AOXbsQkAr/iiCgCpraMK","pt":1657541554640,"mc":[{"id":"1.200806927","rc":[{"atl":[[1.12,1343.67]],"trd":[[1.12,13479.13]],"ltp":1.12,"tv":99785.69,"id":228749},{"trd":[[9.2,1153.79]],"tv":6967.36,"id":2857977}],"tv":106753.05}]}
{"op":"mcm","clk":"AIbcsQkA7PiiCgDAraMK","pt":1657541555057,"mc":[{"id":"1.200806927","rc":[{"atb":[[1.11,1006.07]],"id":228749}]}]}
{"op":"mcm","clk":"ALTcsQkArPmiCgDTraMK","pt":1657541555596,"mc":[{"id":"1.200806927","rc":[{"atl":[[1.12,1342.09]],"id":228749}]}]}
{"op":"mcm","clk":"AKXdsQkA3fqiCgC7rqMK","pt":1657541557118,"mc":[{"id":"1.200806927","rc":[{"atb":[[1.11,0]],"atl":[[1.11,47.69]],"trd":[[1.11,20067.12]],"ltp":1.11,"tv":101801.01,"id":228749},{"atl":[[10,0]],"trd":[[10,1681.69]],"ltp":10,"tv":6967.71,"id":2857977}],"tv":108768.72}]}
{"op":"mcm","clk":"ALXdsQkA8fqiCgDLrqMK","pt":1657541557291,"mc":[{"id":"1.200806927","rc":[{"atl":[[1.11,46.79]],"trd":[[1.11,20068.02]],"tv":101801.91,"id":228749},{"trd":[[10,1681.79]],"tv":6967.81,"id":2857977}],"tv":108769.72}]}
{"op":"mcm","clk":"AO7dsQkAzvuiCgD4rqMK","pt":1657541558135,"mc":[{"id":"1.200806927","rc":[{"atl":[[1.11,46.26]],"trd":[[1.11,20069.08]],"tv":101802.97,"id":228749}],"tv":108770.78}]}
{"op":"mcm","clk":"AKvesQkAnvyiCgCqr6MK","pt":1657541558895,"mc":[{"id":"1.200806927","rc":[{"atl":[[1000,0.32]],"id":228749}]}]}
{"op":"mcm","clk":"ANLesQkAzPyiCgDDr6MK","pt":1657541559314,"mc":[{"id":"1.200806927","rc":[{"atl":[[1000,0.13]],"id":228749}]}]}
{"op":"mcm","clk":"AJzfsQkAwv2iCgDqr6MK","pt":1657541560119,"mc":[{"id":"1.200806927","rc":[{"atl":[[1.13,55.22]],"id":228749}]}]}
{"op":"mcm","clk":"APvfsQkAxf6iCgCbsKMK","pt":1657541561222,"mc":[{"id":"1.200806927","rc":[{"atl":[[1.11,19.96]],"trd":[[1.11,20121.68]],"tv":101855.57,"id":228749}],"tv":108823.38}]}
{"op":"mcm","clk":"AKbgsQkA+v6iCgC1sKMK","pt":1657541561734,"mc":[{"id":"1.200806927","rc":[{"atl":[[1.11,25.65]],"id":228749}]}]}
{"op":"mcm","clk":"AMHhsQkAoYCjCgCQsaMK","pt":1657541563519,"mc":[{"id":"1.200806927","rc":[{"atl":[[1.11,24.07]],"trd":[[1.11,20124.84]],"tv":101858.73,"id":228749}],"tv":108826.54}]}
{"op":"mcm","clk":"AOHhsQkAy4CjCgCisaMK","pt":1657541563952,"mc":[{"id":"1.200806927","rc":[{"atl":[[1.11,17.6]],"trd":[[1.11,20137.78]],"tv":101871.67,"id":228749}],"tv":108839.48}]}
{"op":"mcm","clk":"AIzisQkA94CjCgC4saMK","pt":1657541564417,"mc":[{"id":"1.200806927","rc":[{"atl":[[1.11,17.8]],"id":228749}]}]}
{"op":"mcm","clk":"AJfisQkAgYGjCgC+saMK","pt":1657541564521,"mc":[{"id":"1.200806927","rc":[{"atl":[[1.11,12.54]],"trd":[[1.11,20148.3]],"tv":101882.19,"id":228749}],"tv":108850}]}
{"op":"mcm","clk":"AM3isQkAvYGjCgDdsaMK","pt":1657541565151,"mc":[{"id":"1.200806927","rc":[{"atl":[[1.11,20.23]],"id":228749}]}]}
{"op":"mcm","clk":"ANHisQkAyIGjCgDgsaMK","pt":1657541565243,"mc":[{"id":"1.200806927","rc":[{"atl":[[1.11,65.31]],"id":228749}]}]}
{"op":"mcm","clk":"AM/jsQkA94KjCgCxsqMK","pt":1657541566859,"mc":[{"id":"1.200806927","rc":[{"atl":[[1.11,25.46]],"trd":[[1.11,20228.01]],"tv":101961.9,"id":228749}],"tv":108929.71}]}
{"op":"mcm","clk":"AO/jsQkApYOjCgC+sqMK","pt":1657541567226,"mc":[{"id":"1.200806927","rc":[{"atl":[[1.15,15.75]],"id":228749}]}]}
{"op":"mcm","clk":"AIfksQkAv4OjCgDOsqMK","pt":1657541567437,"mc":[{"id":"1.200806927","rc":[{"atl":[[1.13,0],[1.11,0],[1.12,0]],"trd":[[1.13,4171.1],[1.11,20253.47],[1.12,14821.22]],"ltp":1.13,"tv":103384.67,"id":228749},{"atl":[[8.6,36.9]],"trd":[[9.2,1317.17],[10,1684.62],[8.6,57.96]],"ltp":8.6,"tv":7141.28,"id":2857977}],"tv":110525.95}]}
{"op":"mcm","clk":"AKzlsQkAuYWjCgC2s6MK","pt":1657541569074,"mc":[{"id":"1.200806927","rc":[{"atb":[[1.13,2222]],"id":228749}]}]}
{"op":"mcm","clk":"AMvlsQkA5oWjCgDOs6MK","pt":1657541569338,"mc":[{"id":"1.200806927","rc":[{"atb":[[1.12,0.53]],"id":228749}]}]}
{"op":"mcm","clk":"AOXmsQkApIejCgCmtKMK","pt":1657541570773,"mc":[{"id":"1.200806927","rc":[{"atb":[[1.12,3.16]],"id":228749},{"atl":[[10,1000]],"id":2857977}]}]}
{"op":"mcm","clk":"ALHnsQkAioijCgDPtKMK","pt":1657541571647,"mc":[{"id":"1.200806927","rc":[{"atb":[[1.13,0]],"id":228749}]}]}
{"op":"mcm","clk":"ALfnsQkAmIijCgDWtKMK","pt":1657541571764,"mc":[{"id":"1.200806927","rc":[{"atb":[[1.11,5.26]],"id":228749}]}]}
{"op":"mcm","clk":"AI3osQkAi4mjCgCStaMK","pt":1657541572829,"mc":[{"id":"1.200806927","rc":[{"atl":[[10,1000.11]],"id":2857977}]}]}
{"op":"mcm","clk":"AI7osQkAlomjCgCZtaMK","pt":1657541572845,"mc":[{"id":"1.200806927","rc":[{"atl":[[10,0.11]],"id":2857977}]}]}
{"op":"mcm","clk":"APzosQkAqoqjCgDdtaMK","pt":1657541574089,"mc":[{"id":"1.200806927","rc":[{"trd":[[1.13,4223.69]],"tv":103437.26,"id":228749},{"atl":[[8.6,29.99]],"trd":[[8.6,64.87]],"tv":7148.19,"id":2857977}],"tv":110585.45}]}
{"op":"mcm","clk":"AKXpsQkA1YqjCgDrtaMK","pt":1657541574473,"mc":[{"id":"1.200806927","rc":[{"atb":[[1.11,31.56]],"id":228749}]}]}
{"op":"mcm","clk":"AMPpsQkA+IqjCgD3taMK","pt":1657541574742,"mc":[{"id":"1.200806927","rc":[{"atl":[[1.24,0]],"id":228749}]}]}
{"op":"mcm","clk":"APPpsQkAuIujCgCRtqMK","pt":1657541575256,"mc":[{"id":"1.200806927","rc":[{"trd":[[1.13,4249.99]],"tv":103463.56,"id":228749},{"atl":[[8.6,26.53]],"trd":[[8.6,68.33]],"tv":7151.65,"id":2857977}],"tv":110615.21}]}
{"op":"mcm","clk":"AK/qsQkAi4yjCgC3tqMK","pt":1657541575945,"mc":[{"id":"1.200806927","rc":[{"atl":[[8.6,0]],"id":2857977}]}]}
{"op":"mcm","clk":"AMLrsQkAs42jCgD5tqMK","pt":1657541577653,"mc":[{"id":"1.200806927","rc":[{"atb":[[1.11,32.09]],"id":228749}]}]}
{"op":"mcm","clk":"AL/tsQkA6Y+jCgCuuKMK","pt":1657541580782,"mc":[{"id":"1.200806927","rc":[{"atb":[[1.12,203.16]],"id":228749}]}]}
{"op":"mcm","clk":"AMXtsQkA9Y+jCgC1uKMK","pt":1657541580885,"mc":[{"id":"1.200806927","rc":[{"atb":[[1.15,184.1]],"atl":[[1.15,0]],"trd":[[1.15,8389.71]],"ltp":1.15,"tv":103495.06,"id":228749}],"tv":110646.71}]}
{"op":"mcm","clk":"ANPtsQkAjZCjCgDAuKMK","pt":1657541581039,"mc":[{"id":"1.200806927","rc":[{"atb":[[1.1,204.68]],"id":228749}]}]}
{"op":"mcm","clk":"ANntsQkAnpCjCgDFuKMK","pt":1657541581156,"mc":[{"id":"1.200806927","rc":[{"atb":[[1.12,202.63]],"id":228749}]}]}
{"op":"mcm","clk":"ALHusQkAk5GjCgCEuaMK","pt":1657541582238,"mc":[{"id":"1.200806927","rc":[{"atb":[[1.15,185.15]],"id":228749}]}]}
{"op":"mcm","clk":"APbusQkA6pGjCgCtuaMK","pt":1657541583069,"mc":[{"id":"1.200806927","rc":[{"atb":[[1.15,184.07]],"trd":[[1.15,8391.87]],"tv":103497.22,"id":228749}],"tv":110648.87}]}
{"op":"mcm","clk":"AI7vsQkAj5KjCgC+uaMK","pt":1657541583350,"mc":[{"id":"1.200806927","rc":[{"atb":[[1.15,189.33]],"id":228749}]}]}
{"op":"mcm","clk":"AMHvsQkAwpKjCgDiuaMK","pt":1657541583880,"mc":[{"id":"1.200806927","rc":[{"atb":[[1.16,1499.12]],"atl":[[1.16,0]],"trd":[[1.16,6675.14]],"ltp":1.16,"tv":104497.22,"id":228749}],"tv":111648.87}]}
{"op":"mcm","clk":"APrvsQkAjpOjCgCEuqMK","pt":1657541584546,"mc":[{"id":"1.200806927","rc":[{"atl":[[1.18,5.26]],"id":228749}]}]}
{"op":"mcm","clk":"AO3wsQkAs5SjCgDYuqMK","pt":1657541586050,"mc":[{"id":"1.200806927","rc":[{"atb":[[1.11,77.17],[1.16,1488.95]],"trd":[[1.16,6692.32]],"tv":104514.4,"id":228749}],"tv":111666.05}]}
{"op":"mcm","clk":"AInysQkA8pWjCgC7u6MK","pt":1657541587982,"mc":[{"id":"1.200806927","rc":[{"atb":[[1.15,188.28]],"id":228749}]}]}
{"op":"mcm","clk":"AL7ysQkAtJajCgDWu6MK","pt":1657541588666,"mc":[{"id":"1.200806927","rc":[{"atb":[[1.16,1699.32]],"id":228749}]}]}
{"op":"mcm","clk":"ANvzsQkAhpijCgC4vKMK","pt":1657541590799,"mc":[{"id":"1.200806927","rc":[{"atb":[[1.01,2880.14]],"id":2857977}]}]}
{"op":"mcm","clk":"AOv0sQkAnZmjCgCOvaMK","pt":1657541592456,"mc":[{"id":"1.200806927","rc":[{"atb":[[1.11,71.91]],"id":228749}]}]}
{"op":"mcm","clk":"AKL1sQkA4JmjCgC4vaMK","pt":1657541593178,"mc":[{"id":"1.200806927","rc":[{"atb":[[1.13,10.52]],"id":228749}]}]}
{"op":"mcm","clk":"ALz1sQkA/ZmjCgDJvaMK","pt":1657541593452,"mc":[{"id":"1.200806927","rc":[{"atb":[[1.11,45.61]],"id":228749}]}]}
{"op":"mcm","clk":"ANb1sQkAnZqjCgDbvaMK","pt":1657541593781,"mc":[{"id":"1.200806927","rc":[{"atl":[[1.29,8.22]],"id":228749}]}]}
{"op":"mcm","clk":"AOf1sQkArJqjCgDivaMK","pt":1657541593970,"mc":[{"id":"1.200806927","rc":[{"atb":[[1.01,1770.66]],"id":228749}]}]}
{"op":"mcm","clk":"AJr2sQkA6ZqjCgD6vaMK","pt":1657541594611,"mc":[{"id":"1.200806927","rc":[{"atb":[[1.16,1696.69]],"id":228749}]}]}
{"op":"mcm","clk":"AKz2sQkA/5qjCgD/vaMK","pt":1657541594821,"mc":[{"id":"1.200806927","rc":[{"atb":[[1.16,1670.39]],"id":228749}]}]}
{"op":"mcm","clk":"AJP3sQkA5ZujCgCuvqMK","pt":1657541595839,"mc":[{"id":"1.200806927","rc":[{"atb":[[1.17,402.03],[1.16,1659.87]],"atl":[[1000,0.21],[1.17,0]],"trd":[[1.17,3789.33]],"ltp":1.17,"tv":104593.18,"id":228749},{"atb":[[7,0]],"trd":[[7,2.66]],"ltp":7,"tv":7152.51,"id":2857977}],"tv":111745.69}]}
{"op":"mcm","clk":"ALT3sQkAj5yjCgDDvqMK","pt":1657541596233,"mc":[{"id":"1.200806927","rc":[{"atl":[[1000,0.13]],"id":228749}]}]}
{"op":"mcm","clk":"AO/3sQkA1ZyjCgDrvqMK","pt":1657541596916,"mc":[{"id":"1.200806927","rc":[{"atb":[[1.17,386.25]],"trd":[[1.17,3820.89]],"tv":104624.74,"id":228749}],"tv":111777.25}]}
{"op":"mcm","clk":"ALT4sQkAp52jCgCTv6MK","pt":1657541597638,"mc":[{"id":"1.200806927","rc":[{"atb":[[1.17,596.62]],"id":228749}]}]}
{"op":"mcm","clk":"AOD4sQkA252jCgCrv6MK","pt":1657541598122,"mc":[{"id":"1.200806927","rc":[{"atb":[[1.17,594.46]],"trd":[[1.17,3825.21]],"tv":104629.06,"id":228749}],"tv":111781.57}]}
{"op":"mcm","clk":"AOL4sQkA5p2jCgCwv6MK","pt":1657541598216,"mc":[{"id":"1.200806927","rc":[{"atb":[[1.04,43.05]],"id":228749}]}]}
{"op":"mcm","clk":"AO34sQkA7p2jCgC1v6MK","pt":1657541598321,"mc":[{"id":"1.200806927","rc":[{"atb":[[1.17,585.32]],"trd":[[1.17,3843.49]],"tv":104647.34,"id":228749}],"tv":111799.85}]}
{"op":"mcm","clk":"AJr5sQkAqZ6jCgDdv6MK","pt":1657541598902,"mc":[{"id":"1.200806927","rc":[{"atb":[[1.17,583.97]],"trd":[[1.17,3846.19]],"tv":104650.04,"id":228749}],"tv":111802.55}]}
{"op":"mcm","clk":"AKL5sQkAtJ6jCgDhv6MK","pt":1657541599005,"mc":[{"id":"1.200806927","rc":[{"atb":[[1.11,45.08]],"id":228749}]}]}
{"op":"mcm","clk":"AOb5sQkAjJ+jCgCTwKMK","pt":1657541599938,"mc":[{"id":"1.200806927","rc":[{"atb":[[1.17,582.97]],"trd":[[1.17,3848.19]],"tv":104652.04,"id":228749}],"tv":111804.55}]}
{"op":"mcm","clk":"AJD6sQkAuJ+jCgCnwKMK","pt":1657541600304,"mc":[{"id":"1.200806927","rc":[{"atb":[[1.17,579.65]],"trd":[[1.17,3854.83]],"tv":104658.68,"id":228749}],"tv":111811.19}]}
{"op":"mcm","clk":"ANH6sQkAiqCjCgDPwKMK","pt":1657541601129,"mc":[{"id":"1.200806927","rc":[{"atb":[[1.17,553.35]],"trd":[[1.17,3907.43]],"tv":104711.28,"id":228749}],"tv":111863.79}]}
{"op":"mcm","clk":"AOb6sQkAoKCjCgDawKMK","pt":1657541601306,"mc":[{"id":"1.200806927","rc":[{"atb":[[1.17,553.27]],"trd":[[1.17,3907.59]],"tv":104711.44,"id":228749}],"tv":111863.95}]}
{"op":"mcm","clk":"APT6sQkAqaCjCgDfwKMK","pt":1657541601460,"mc":[{"id":"1.200806927","rc":[{"atb":[[1.17,551.69]],"trd":[[1.17,3910.75]],"tv":104714.6,"id":228749}],"tv":111867.11}]}
{"op":"mcm","clk":"AJP7sQkA0KCjCgDxwKMK","pt":1657541601813,"mc":[{"id":"1.200806927","rc":[{"atb":[[1.17,541.17]],"trd":[[1.17,3931.79]],"tv":104735.64,"id":228749}],"tv":111888.15}]}
{"op":"mcm","clk":"AKf7sQkA56CjCgCAwaMK","pt":1657541602029,"mc":[{"id":"1.200806927","rc":[{"atb":[[1.17,1071.5]],"id":228749}]}]}
{"op":"mcm","clk":"AN/7sQkAvKGjCgCrwaMK","pt":1657541602820,"mc":[{"id":"1.200806927","rc":[{"atb":[[1.17,1076.76]],"id":228749}]}]}
{"op":"mcm","clk":"AOr7sQkAzKGjCgCvwaMK","pt":1657541602988,"mc":[{"id":"1.200806927","rc":[{"atb":[[1.17,1073.45]],"trd":[[1.17,3938.41]],"tv":104742.26,"id":228749}],"tv":111894.77}]}
